{
  "version": 8,
  "blockIdVersion": 11,
  "anchorX": 0,
  "anchorY": 0,
  "anchorZ": 0,
  "blocks": [
    {
      "x": -7,
      "y": 0,
      "z": -5,
      "name": "Plant_Bush_Green"
    },
    {
      "x": -7,
      "y": 0,
      "z": -2,
      "name": "Soil_Grass_Full"
    },
    {
      "x": -7,
      "y": 0,
      "z": -1,
      "name": "Soil_Grass_Full"
    },
    {
      "x": -7,
      "y": 1,
      "z": -1,
      "name": "Plant_Bush_Green"
    },
    {
      "x": -7,
      "y": 0,
      "z": 0,
      "name": "Soil_Grass_Full"
    },
    {
      "x": -7,
      "y": 0,
      "z": 1,
      "name": "Soil_Grass_Full"
    },
    {
      "x": -7,
      "y": 1,
      "z": 1,
      "name": "*Plant_Crop_Berry_Block_State_Definitions_StageFinal"
    },
    {
      "x": -7,
      "y": 0,
      "z": 2,
      "name": "Rock_Quartzite",
      "rotation": 1
    },
    {
      "x": -7,
      "y": 0,
      "z": 3,
      "name": "Rock_Quartzite_Cobble",
      "rotation": 1
    },
    {
      "x": -7,
      "y": 1,
      "z": 3,
      "name": "Rock_Quartzite_Cobble",
      "rotation": 1
    },
    {
      "x": -7,
      "y": 2,
      "z": 3,
      "name": "Rock_Quartzite_Cobble",
      "rotation": 1
    },
    {
      "x": -7,
      "y": 3,
      "z": 3,
      "name": "Soil_Dirt",
      "rotation": 1
    },
    {
      "x": -7,
      "y": 4,
      "z": 3,
      "name": "Soil_Grass",
      "rotation": 1
    },
    {
      "x": -7,
      "y": 5,
      "z": 3,
      "name": "Plant_Grass_Sharp",
      "rotation": 1
    },
    {
      "x": -7,
      "y": 0,
      "z": 4,
      "name": "Rock_Quartzite_Cobble",
      "rotation": 1
    },
    {
      "x": -7,
      "y": 1,
      "z": 4,
      "name": "Rock_Quartzite_Cobble",
      "rotation": 1
    },
    {
      "x": -7,
      "y": 2,
      "z": 4,
      "name": "Rock_Quartzite_Cobble",
      "rotation": 1
    },
    {
      "x": -7,
      "y": 3,
      "z": 4,
      "name": "Soil_Grass",
      "rotation": 1
    },
    {
      "x": -7,
      "y": 4,
      "z": 4,
      "name": "Plant_Grass_Sharp_Tall",
      "rotation": 1
    },
    {
      "x": -7,
      "y": 5,
      "z": 4,
      "name": "Plant_Grass_Sharp_Tall",
      "filler": 1024,
      "rotation": 1
    },
    {
      "x": -7,
      "y": 0,
      "z": 5,
      "name": "Rock_Quartzite_Cobble",
      "rotation": 1
    },
    {
      "x": -7,
      "y": 1,
      "z": 5,
      "name": "Rock_Quartzite_Cobble",
      "rotation": 1
    },
    {
      "x": -7,
      "y": 2,
      "z": 5,
      "name": "Rock_Quartzite_Cobble_Stairs"
    },
    {
      "x": -7,
      "y": 0,
      "z": 6,
      "name": "Rock_Quartzite",
      "rotation": 1
    },
    {
      "x": -7,
      "y": 1,
      "z": 6,
      "name": "Plant_Bush_Green"
    },
    {
      "x": -7,
      "y": 0,
      "z": 7,
      "name": "Soil_Grass_Full"
    },
    {
      "x": -6,
      "y": 0,
      "z": -2,
      "name": "Soil_Grass_Full"
    },
    {
      "x": -6,
      "y": 0,
      "z": -1,
      "name": "Soil_Grass_Full"
    },
    {
      "x": -6,
      "y": 0,
      "z": 0,
      "name": "Soil_Grass_Full"
    },
    {
      "x": -6,
      "y": 1,
      "z": 0,
      "name": "Plant_Bush_Green"
    },
    {
      "x": -6,
      "y": 0,
      "z": 1,
      "name": "Soil_Grass_Full"
    },
    {
      "x": -6,
      "y": 0,
      "z": 2,
      "name": "Soil_Grass_Full"
    },
    {
      "x": -6,
      "y": 0,
      "z": 3,
      "name": "Rock_Quartzite",
      "rotation": 1
    },
    {
      "x": -6,
      "y": 1,
      "z": 3,
      "name": "Rock_Quartzite_Brick",
      "rotation": 1
    },
    {
      "x": -6,
      "y": 2,
      "z": 3,
      "name": "Rock_Quartzite",
      "rotation": 1
    },
    {
      "x": -6,
      "y": 3,
      "z": 3,
      "name": "Rock_Quartzite",
      "rotation": 1
    },
    {
      "x": -6,
      "y": 4,
      "z": 3,
      "name": "Rock_Quartzite",
      "rotation": 1
    },
    {
      "x": -6,
      "y": 5,
      "z": 3,
      "name": "Soil_Dirt",
      "rotation": 1
    },
    {
      "x": -6,
      "y": 6,
      "z": 3,
      "name": "Soil_Grass",
      "rotation": 1
    },
    {
      "x": -6,
      "y": 7,
      "z": 3,
      "name": "Plant_Grass_Lush",
      "rotation": 1
    },
    {
      "x": -6,
      "y": 0,
      "z": 4,
      "name": "Rock_Quartzite",
      "rotation": 1
    },
    {
      "x": -6,
      "y": 1,
      "z": 4,
      "name": "Rock_Quartzite_Brick",
      "rotation": 1
    },
    {
      "x": -6,
      "y": 2,
      "z": 4,
      "name": "Rock_Quartzite",
      "rotation": 1
    },
    {
      "x": -6,
      "y": 3,
      "z": 4,
      "name": "Rock_Quartzite",
      "rotation": 1
    },
    {
      "x": -6,
      "y": 4,
      "z": 4,
      "name": "Soil_Dirt",
      "rotation": 1
    },
    {
      "x": -6,
      "y": 5,
      "z": 4,
      "name": "Soil_Dirt",
      "rotation": 1
    },
    {
      "x": -6,
      "y": 6,
      "z": 4,
      "name": "Soil_Grass",
      "rotation": 1
    },
    {
      "x": -6,
      "y": 7,
      "z": 4,
      "name": "Plant_Grass_Sharp",
      "rotation": 1
    },
    {
      "x": -6,
      "y": 0,
      "z": 5,
      "name": "Rock_Quartzite",
      "rotation": 1
    },
    {
      "x": -6,
      "y": 1,
      "z": 5,
      "name": "Rock_Quartzite_Cobble",
      "rotation": 1
    },
    {
      "x": -6,
      "y": 2,
      "z": 5,
      "name": "Rock_Quartzite_Cobble_Stairs"
    },
    {
      "x": -6,
      "y": 3,
      "z": 5,
      "name": "Rock_Quartzite_Cobble_Half",
      "rotation": 4
    },
    {
      "x": -6,
      "y": 4,
      "z": 5,
      "name": "Soil_Dirt",
      "rotation": 1
    },
    {
      "x": -6,
      "y": 5,
      "z": 5,
      "name": "Soil_Grass",
      "rotation": 1
    },
    {
      "x": -6,
      "y": 6,
      "z": 5,
      "name": "Plant_Grass_Lush_Short",
      "rotation": 1
    },
    {
      "x": -6,
      "y": 0,
      "z": 6,
      "name": "Rock_Quartzite",
      "rotation": 1
    },
    {
      "x": -6,
      "y": 0,
      "z": 7,
      "name": "Soil_Grass_Full"
    },
    {
      "x": -5,
      "y": 0,
      "z": -4,
      "name": "Plant_Bush_Green"
    },
    {
      "x": -5,
      "y": 0,
      "z": -2,
      "name": "Soil_Grass_Full"
    },
    {
      "x": -5,
      "y": 1,
      "z": -2,
      "name": "Plant_Bush_Green"
    },
    {
      "x": -5,
      "y": 0,
      "z": -1,
      "name": "Soil_Grass_Full"
    },
    {
      "x": -5,
      "y": 0,
      "z": 0,
      "name": "Soil_Grass_Full"
    },
    {
      "x": -5,
      "y": 1,
      "z": 0,
      "name": "Nat20_Npc_Spawn"
    },
    {
      "x": -5,
      "y": 0,
      "z": 1,
      "name": "Soil_Grass_Full"
    },
    {
      "x": -5,
      "y": 0,
      "z": 2,
      "name": "Soil_Dirt"
    },
    {
      "x": -5,
      "y": 1,
      "z": 2,
      "name": "Rock_Quartzite_Brick",
      "rotation": 1
    },
    {
      "x": -5,
      "y": 2,
      "z": 2,
      "name": "Rock_Quartzite_Brick_Half",
      "rotation": 7
    },
    {
      "x": -5,
      "y": 3,
      "z": 2,
      "name": "Rock_Quartzite_Brick_Half",
      "rotation": 7
    },
    {
      "x": -5,
      "y": 4,
      "z": 2,
      "name": "Rock_Quartzite_Brick_Half",
      "rotation": 7
    },
    {
      "x": -5,
      "y": 5,
      "z": 2,
      "name": "Rock_Quartzite_Brick_Half",
      "rotation": 7
    },
    {
      "x": -5,
      "y": 0,
      "z": 3,
      "name": "Rock_Quartzite",
      "rotation": 1
    },
    {
      "x": -5,
      "y": 1,
      "z": 3,
      "name": "Rock_Quartzite_Cobble",
      "rotation": 1
    },
    {
      "x": -5,
      "y": 2,
      "z": 3,
      "name": "Rock_Quartzite",
      "rotation": 1
    },
    {
      "x": -5,
      "y": 3,
      "z": 3,
      "name": "Rock_Quartzite",
      "rotation": 1
    },
    {
      "x": -5,
      "y": 4,
      "z": 3,
      "name": "Rock_Quartzite",
      "rotation": 1
    },
    {
      "x": -5,
      "y": 5,
      "z": 3,
      "name": "Rock_Quartzite",
      "rotation": 1
    },
    {
      "x": -5,
      "y": 6,
      "z": 3,
      "name": "Soil_Grass",
      "rotation": 1
    },
    {
      "x": -5,
      "y": 7,
      "z": 3,
      "name": "Plant_Grass_Sharp_Tall",
      "rotation": 1
    },
    {
      "x": -5,
      "y": 8,
      "z": 3,
      "name": "Plant_Grass_Sharp_Tall",
      "filler": 1024,
      "rotation": 1
    },
    {
      "x": -5,
      "y": 0,
      "z": 4,
      "name": "Rock_Quartzite",
      "rotation": 1
    },
    {
      "x": -5,
      "y": 1,
      "z": 4,
      "name": "Rock_Quartzite_Brick",
      "rotation": 1
    },
    {
      "x": -5,
      "y": 2,
      "z": 4,
      "name": "Rock_Quartzite",
      "rotation": 1
    },
    {
      "x": -5,
      "y": 3,
      "z": 4,
      "name": "Rock_Quartzite",
      "rotation": 1
    },
    {
      "x": -5,
      "y": 4,
      "z": 4,
      "name": "Rock_Quartzite",
      "rotation": 1
    },
    {
      "x": -5,
      "y": 5,
      "z": 4,
      "name": "Rock_Quartzite",
      "rotation": 1
    },
    {
      "x": -5,
      "y": 6,
      "z": 4,
      "name": "Rock_Quartzite",
      "rotation": 1
    },
    {
      "x": -5,
      "y": 7,
      "z": 4,
      "name": "Soil_Grass",
      "rotation": 1
    },
    {
      "x": -5,
      "y": 0,
      "z": 5,
      "name": "Rock_Quartzite",
      "rotation": 1
    },
    {
      "x": -5,
      "y": 1,
      "z": 5,
      "name": "Rock_Quartzite_Brick",
      "rotation": 1
    },
    {
      "x": -5,
      "y": 2,
      "z": 5,
      "name": "Rock_Quartzite_Cobble",
      "rotation": 1
    },
    {
      "x": -5,
      "y": 3,
      "z": 5,
      "name": "Rock_Quartzite",
      "rotation": 1
    },
    {
      "x": -5,
      "y": 4,
      "z": 5,
      "name": "Rock_Quartzite",
      "rotation": 1
    },
    {
      "x": -5,
      "y": 5,
      "z": 5,
      "name": "Rock_Quartzite",
      "rotation": 1
    },
    {
      "x": -5,
      "y": 6,
      "z": 5,
      "name": "Rock_Quartzite",
      "rotation": 1
    },
    {
      "x": -5,
      "y": 7,
      "z": 5,
      "name": "Soil_Dirt",
      "rotation": 1
    },
    {
      "x": -5,
      "y": 8,
      "z": 5,
      "name": "Soil_Grass",
      "rotation": 1
    },
    {
      "x": -5,
      "y": 9,
      "z": 5,
      "name": "Plant_Grass_Lush_Short",
      "rotation": 1
    },
    {
      "x": -5,
      "y": 0,
      "z": 6,
      "name": "Rock_Quartzite",
      "rotation": 1
    },
    {
      "x": -5,
      "y": 1,
      "z": 6,
      "name": "Rock_Quartzite_Brick",
      "rotation": 1
    },
    {
      "x": -5,
      "y": 2,
      "z": 6,
      "name": "Rock_Quartzite_Brick_Half",
      "rotation": 7
    },
    {
      "x": -5,
      "y": 3,
      "z": 6,
      "name": "Rock_Quartzite_Brick_Half",
      "rotation": 7
    },
    {
      "x": -5,
      "y": 4,
      "z": 6,
      "name": "Rock_Quartzite_Brick_Half",
      "rotation": 7
    },
    {
      "x": -5,
      "y": 5,
      "z": 6,
      "name": "Rock_Quartzite_Brick_Half",
      "rotation": 7
    },
    {
      "x": -5,
      "y": 6,
      "z": 6,
      "name": "Rock_Quartzite_Brick_Half",
      "rotation": 7
    },
    {
      "x": -5,
      "y": 7,
      "z": 6,
      "name": "Rock_Quartzite_Brick_Half",
      "rotation": 7
    },
    {
      "x": -5,
      "y": 8,
      "z": 6,
      "name": "Rock_Quartzite_Brick_Stairs",
      "rotation": 9
    },
    {
      "x": -5,
      "y": 0,
      "z": 7,
      "name": "Soil_Grass_Full"
    },
    {
      "x": -4,
      "y": 0,
      "z": -2,
      "name": "Soil_Grass_Full"
    },
    {
      "x": -4,
      "y": 1,
      "z": -2,
      "name": "Plant_Grass_Lush_Short"
    },
    {
      "x": -4,
      "y": 0,
      "z": -1,
      "name": "Soil_Grass_Full"
    },
    {
      "x": -4,
      "y": 1,
      "z": -1,
      "name": "Plant_Grass_Lush_Short"
    },
    {
      "x": -4,
      "y": 0,
      "z": 0,
      "name": "Soil_Grass_Full"
    },
    {
      "x": -4,
      "y": 1,
      "z": 0,
      "name": "Plant_Grass_Lush_Short"
    },
    {
      "x": -4,
      "y": 0,
      "z": 1,
      "name": "Soil_Grass_Full"
    },
    {
      "x": -4,
      "y": 0,
      "z": 2,
      "name": "Rock_Quartzite",
      "rotation": 1
    },
    {
      "x": -4,
      "y": 1,
      "z": 2,
      "name": "Rock_Quartzite_Brick",
      "rotation": 1
    },
    {
      "x": -4,
      "y": 2,
      "z": 2,
      "name": "Rock_Quartzite_Brick_Half",
      "rotation": 5
    },
    {
      "x": -4,
      "y": 6,
      "z": 2,
      "name": "Plant_Vine_Wall",
      "rotation": 2
    },
    {
      "x": -4,
      "y": 7,
      "z": 2,
      "name": "Plant_Vine",
      "rotation": 2
    },
    {
      "x": -4,
      "y": 8,
      "z": 2,
      "name": "Plant_Vine",
      "rotation": 2
    },
    {
      "x": -4,
      "y": 0,
      "z": 3,
      "name": "Rock_Quartzite",
      "rotation": 1
    },
    {
      "x": -4,
      "y": 1,
      "z": 3,
      "name": "Rock_Quartzite_Cobble",
      "rotation": 1
    },
    {
      "x": -4,
      "y": 6,
      "z": 3,
      "name": "Rock_Quartzite_Cobble_Stairs",
      "rotation": 8
    },
    {
      "x": -4,
      "y": 7,
      "z": 3,
      "name": "Soil_Dirt",
      "rotation": 1
    },
    {
      "x": -4,
      "y": 8,
      "z": 3,
      "name": "Soil_Grass",
      "rotation": 1
    },
    {
      "x": -4,
      "y": 9,
      "z": 3,
      "name": "Plant_Grass_Sharp",
      "rotation": 1
    },
    {
      "x": -4,
      "y": 0,
      "z": 4,
      "name": "Rock_Quartzite",
      "rotation": 1
    },
    {
      "x": -4,
      "y": 1,
      "z": 4,
      "name": "Rock_Quartzite_Brick",
      "rotation": 1
    },
    {
      "x": -4,
      "y": 2,
      "z": 4,
      "name": "Rock_Quartzite",
      "rotation": 1
    },
    {
      "x": -4,
      "y": 3,
      "z": 4,
      "name": "Rock_Quartzite",
      "rotation": 1
    },
    {
      "x": -4,
      "y": 4,
      "z": 4,
      "name": "Rock_Quartzite_Cobble",
      "rotation": 1
    },
    {
      "x": -4,
      "y": 5,
      "z": 4,
      "name": "Rock_Quartzite_Cobble",
      "rotation": 1
    },
    {
      "x": -4,
      "y": 6,
      "z": 4,
      "name": "Rock_Quartzite_Cobble",
      "rotation": 1
    },
    {
      "x": -4,
      "y": 7,
      "z": 4,
      "name": "Rock_Quartzite",
      "rotation": 1
    },
    {
      "x": -4,
      "y": 8,
      "z": 4,
      "name": "Soil_Grass",
      "rotation": 1
    },
    {
      "x": -4,
      "y": 9,
      "z": 4,
      "name": "Plant_Grass_Sharp",
      "rotation": 1
    },
    {
      "x": -4,
      "y": 0,
      "z": 5,
      "name": "Rock_Quartzite",
      "rotation": 1
    },
    {
      "x": -4,
      "y": 1,
      "z": 5,
      "name": "Rock_Quartzite_Brick",
      "rotation": 1
    },
    {
      "x": -4,
      "y": 2,
      "z": 5,
      "name": "Rock_Quartzite",
      "rotation": 1
    },
    {
      "x": -4,
      "y": 3,
      "z": 5,
      "name": "Rock_Quartzite",
      "rotation": 1
    },
    {
      "x": -4,
      "y": 4,
      "z": 5,
      "name": "Rock_Quartzite",
      "rotation": 1
    },
    {
      "x": -4,
      "y": 5,
      "z": 5,
      "name": "Rock_Quartzite",
      "rotation": 1
    },
    {
      "x": -4,
      "y": 6,
      "z": 5,
      "name": "Rock_Quartzite_Cobble",
      "rotation": 1
    },
    {
      "x": -4,
      "y": 7,
      "z": 5,
      "name": "Rock_Quartzite_Cobble",
      "rotation": 1
    },
    {
      "x": -4,
      "y": 8,
      "z": 5,
      "name": "Soil_Grass",
      "rotation": 1
    },
    {
      "x": -4,
      "y": 0,
      "z": 6,
      "name": "Rock_Quartzite",
      "rotation": 1
    },
    {
      "x": -4,
      "y": 1,
      "z": 6,
      "name": "Rock_Quartzite_Brick",
      "rotation": 1
    },
    {
      "x": -4,
      "y": 2,
      "z": 6,
      "name": "Rock_Quartzite_Brick_Half",
      "rotation": 5
    },
    {
      "x": -4,
      "y": 3,
      "z": 6,
      "name": "Rock_Quartzite_Brick_Half",
      "rotation": 5
    },
    {
      "x": -4,
      "y": 4,
      "z": 6,
      "name": "Rock_Quartzite_Brick_Half",
      "rotation": 5
    },
    {
      "x": -4,
      "y": 5,
      "z": 6,
      "name": "Rock_Quartzite_Brick_Half",
      "rotation": 5
    },
    {
      "x": -4,
      "y": 6,
      "z": 6,
      "name": "Rock_Quartzite_Brick_Half",
      "rotation": 5
    },
    {
      "x": -4,
      "y": 7,
      "z": 6,
      "name": "Rock_Quartzite_Brick_Half",
      "rotation": 5
    },
    {
      "x": -4,
      "y": 8,
      "z": 6,
      "name": "Rock_Quartzite_Brick_Stairs",
      "rotation": 11
    },
    {
      "x": -4,
      "y": 9,
      "z": 6,
      "name": "Rock_Quartzite_Brick",
      "rotation": 1
    },
    {
      "x": -4,
      "y": 10,
      "z": 6,
      "name": "Rock_Stone_Brick_Smooth",
      "rotation": 1
    },
    {
      "x": -4,
      "y": 11,
      "z": 6,
      "name": "Rock_Stone_Brick_Smooth_Half",
      "rotation": 7
    },
    {
      "x": -4,
      "y": 0,
      "z": 7,
      "name": "Soil_Grass_Full"
    },
    {
      "x": -4,
      "y": 1,
      "z": 7,
      "name": "Plant_Grass_Lush_Short"
    },
    {
      "x": -3,
      "y": 0,
      "z": -7,
      "name": "Plant_Bush"
    },
    {
      "x": -3,
      "y": 0,
      "z": -6,
      "name": "Plant_Bush"
    },
    {
      "x": -3,
      "y": 0,
      "z": -2,
      "name": "Soil_Grass_Full"
    },
    {
      "x": -3,
      "y": 1,
      "z": -2,
      "name": "Plant_Grass_Lush_Short"
    },
    {
      "x": -3,
      "y": 0,
      "z": -1,
      "name": "Soil_Grass_Full"
    },
    {
      "x": -3,
      "y": 0,
      "z": 0,
      "name": "Soil_Grass_Full"
    },
    {
      "x": -3,
      "y": 0,
      "z": 1,
      "name": "Soil_Grass_Full"
    },
    {
      "x": -3,
      "y": 1,
      "z": 1,
      "name": "Plant_Grass_Lush_Short"
    },
    {
      "x": -3,
      "y": 0,
      "z": 2,
      "name": "Rock_Quartzite",
      "rotation": 1
    },
    {
      "x": -3,
      "y": 1,
      "z": 2,
      "name": "Plant_Grass_Sharp_Short"
    },
    {
      "x": -3,
      "y": 7,
      "z": 2,
      "name": "Plant_Vine",
      "rotation": 2
    },
    {
      "x": -3,
      "y": 8,
      "z": 2,
      "name": "Rock_Quartzite_Brick_Half",
      "rotation": 9
    },
    {
      "x": -3,
      "y": 0,
      "z": 3,
      "name": "Rock_Quartzite",
      "rotation": 1
    },
    {
      "x": -3,
      "y": 1,
      "z": 3,
      "name": "Rock_Quartzite_Cobble",
      "rotation": 1
    },
    {
      "x": -3,
      "y": 2,
      "z": 3,
      "name": "Rock_Quartzite_Cobble",
      "rotation": 1
    },
    {
      "x": -3,
      "y": 6,
      "z": 3,
      "name": "Rock_Quartzite_Cobble_Half",
      "rotation": 9
    },
    {
      "x": -3,
      "y": 7,
      "z": 3,
      "name": "Soil_Dirt",
      "rotation": 1
    },
    {
      "x": -3,
      "y": 8,
      "z": 3,
      "name": "Soil_Grass",
      "rotation": 1
    },
    {
      "x": -3,
      "y": 9,
      "z": 3,
      "name": "Plant_Grass_Sharp_Tall",
      "rotation": 1
    },
    {
      "x": -3,
      "y": 10,
      "z": 3,
      "name": "Plant_Grass_Sharp_Tall",
      "filler": 1024,
      "rotation": 1
    },
    {
      "x": -3,
      "y": 0,
      "z": 4,
      "name": "Rock_Quartzite",
      "rotation": 1
    },
    {
      "x": -3,
      "y": 1,
      "z": 4,
      "name": "Rock_Quartzite_Brick",
      "rotation": 1
    },
    {
      "x": -3,
      "y": 2,
      "z": 4,
      "name": "Rock_Quartzite",
      "rotation": 1
    },
    {
      "x": -3,
      "y": 3,
      "z": 4,
      "name": "Rock_Quartzite",
      "rotation": 1
    },
    {
      "x": -3,
      "y": 4,
      "z": 4,
      "name": "Rock_Quartzite",
      "rotation": 1
    },
    {
      "x": -3,
      "y": 5,
      "z": 4,
      "name": "Rock_Quartzite_Cobble",
      "rotation": 1
    },
    {
      "x": -3,
      "y": 6,
      "z": 4,
      "name": "Rock_Quartzite_Cobble",
      "rotation": 1
    },
    {
      "x": -3,
      "y": 7,
      "z": 4,
      "name": "Rock_Quartzite",
      "rotation": 1
    },
    {
      "x": -3,
      "y": 8,
      "z": 4,
      "name": "Rock_Quartzite",
      "rotation": 1
    },
    {
      "x": -3,
      "y": 9,
      "z": 4,
      "name": "Soil_Grass",
      "rotation": 1
    },
    {
      "x": -3,
      "y": 10,
      "z": 4,
      "name": "Plant_Grass_Lush_Short",
      "rotation": 1
    },
    {
      "x": -3,
      "y": 0,
      "z": 5,
      "name": "Rock_Quartzite",
      "rotation": 1
    },
    {
      "x": -3,
      "y": 1,
      "z": 5,
      "name": "Rock_Quartzite_Brick",
      "rotation": 1
    },
    {
      "x": -3,
      "y": 2,
      "z": 5,
      "name": "Rock_Quartzite",
      "rotation": 1
    },
    {
      "x": -3,
      "y": 3,
      "z": 5,
      "name": "Rock_Quartzite",
      "rotation": 1
    },
    {
      "x": -3,
      "y": 4,
      "z": 5,
      "name": "Rock_Quartzite",
      "rotation": 1
    },
    {
      "x": -3,
      "y": 5,
      "z": 5,
      "name": "Rock_Quartzite",
      "rotation": 1
    },
    {
      "x": -3,
      "y": 6,
      "z": 5,
      "name": "Rock_Quartzite_Cobble",
      "rotation": 1
    },
    {
      "x": -3,
      "y": 7,
      "z": 5,
      "name": "Rock_Quartzite",
      "rotation": 1
    },
    {
      "x": -3,
      "y": 8,
      "z": 5,
      "name": "Rock_Quartzite",
      "rotation": 1
    },
    {
      "x": -3,
      "y": 9,
      "z": 5,
      "name": "Soil_Grass",
      "rotation": 1
    },
    {
      "x": -3,
      "y": 10,
      "z": 5,
      "name": "Plant_Fern_Winter",
      "rotation": 1
    },
    {
      "x": -3,
      "y": 0,
      "z": 6,
      "name": "Rock_Quartzite",
      "rotation": 1
    },
    {
      "x": -3,
      "y": 8,
      "z": 6,
      "name": "Rock_Quartzite_Brick_Half",
      "rotation": 9
    },
    {
      "x": -3,
      "y": 9,
      "z": 6,
      "name": "Rock_Quartzite_Brick",
      "rotation": 1
    },
    {
      "x": -3,
      "y": 10,
      "z": 6,
      "name": "Rock_Stone_Brick_Smooth",
      "rotation": 1
    },
    {
      "x": -3,
      "y": 11,
      "z": 6,
      "name": "Rock_Stone_Brick_Smooth_Half",
      "rotation": 9
    },
    {
      "x": -3,
      "y": 12,
      "z": 6,
      "name": "Plant_Moss_Rug_Green",
      "rotation": 1
    },
    {
      "x": -3,
      "y": 0,
      "z": 7,
      "name": "Soil_Grass_Full"
    },
    {
      "x": -2,
      "y": 0,
      "z": -6,
      "name": "Rock_Quartzite",
      "rotation": 1
    },
    {
      "x": -2,
      "y": 8,
      "z": -6,
      "name": "Rock_Quartzite_Brick_Stairs",
      "rotation": 10
    },
    {
      "x": -2,
      "y": 9,
      "z": -6,
      "name": "Rock_Quartzite_Brick",
      "rotation": 1
    },
    {
      "x": -2,
      "y": 10,
      "z": -6,
      "name": "Rock_Stone_Brick_Smooth",
      "rotation": 1
    },
    {
      "x": -2,
      "y": 11,
      "z": -6,
      "name": "Rock_Stone_Brick_Smooth_Half",
      "rotation": 6
    },
    {
      "x": -2,
      "y": 0,
      "z": -5,
      "name": "Rock_Quartzite",
      "rotation": 1
    },
    {
      "x": -2,
      "y": 8,
      "z": -5,
      "name": "Rock_Quartzite_Brick_Half",
      "rotation": 9
    },
    {
      "x": -2,
      "y": 9,
      "z": -5,
      "name": "Rock_Quartzite_Brick",
      "rotation": 1
    },
    {
      "x": -2,
      "y": 10,
      "z": -5,
      "name": "Rock_Stone_Brick_Smooth",
      "rotation": 1
    },
    {
      "x": -2,
      "y": 11,
      "z": -5,
      "name": "Rock_Stone_Brick_Smooth_Half",
      "rotation": 9
    },
    {
      "x": -2,
      "y": 12,
      "z": -5,
      "name": "Plant_Moss_Rug_Green",
      "rotation": 1
    },
    {
      "x": -2,
      "y": 0,
      "z": -4,
      "name": "Rock_Quartzite",
      "rotation": 1
    },
    {
      "x": -2,
      "y": 1,
      "z": -4,
      "name": "Rock_Quartzite_Brick",
      "rotation": 1
    },
    {
      "x": -2,
      "y": 2,
      "z": -4,
      "name": "Rock_Quartzite_Brick_Half",
      "rotation": 6
    },
    {
      "x": -2,
      "y": 3,
      "z": -4,
      "name": "Rock_Quartzite_Brick_Half",
      "rotation": 6
    },
    {
      "x": -2,
      "y": 4,
      "z": -4,
      "name": "Rock_Quartzite_Brick_Half",
      "rotation": 6
    },
    {
      "x": -2,
      "y": 5,
      "z": -4,
      "name": "Rock_Quartzite_Brick_Half",
      "rotation": 6
    },
    {
      "x": -2,
      "y": 6,
      "z": -4,
      "name": "Rock_Quartzite_Brick_Half",
      "rotation": 6
    },
    {
      "x": -2,
      "y": 7,
      "z": -4,
      "name": "Rock_Quartzite_Brick_Half",
      "rotation": 6
    },
    {
      "x": -2,
      "y": 8,
      "z": -4,
      "name": "Rock_Quartzite_Brick_Stairs",
      "rotation": 8
    },
    {
      "x": -2,
      "y": 9,
      "z": -4,
      "name": "Rock_Quartzite_Brick",
      "rotation": 1
    },
    {
      "x": -2,
      "y": 10,
      "z": -4,
      "name": "Rock_Stone_Brick_Smooth",
      "rotation": 1
    },
    {
      "x": -2,
      "y": 11,
      "z": -4,
      "name": "Rock_Stone_Brick_Smooth_Half",
      "rotation": 4
    },
    {
      "x": -2,
      "y": 0,
      "z": -3,
      "name": "Rock_Quartzite",
      "rotation": 1
    },
    {
      "x": -2,
      "y": 1,
      "z": -3,
      "name": "Rock_Quartzite_Brick",
      "rotation": 1
    },
    {
      "x": -2,
      "y": 2,
      "z": -3,
      "name": "Rock_Quartzite_Brick_Half",
      "rotation": 4
    },
    {
      "x": -2,
      "y": 3,
      "z": -3,
      "name": "Rock_Quartzite_Brick_Half",
      "rotation": 4
    },
    {
      "x": -2,
      "y": 4,
      "z": -3,
      "name": "Rock_Quartzite_Brick_Half",
      "rotation": 4
    },
    {
      "x": -2,
      "y": 5,
      "z": -3,
      "name": "Rock_Quartzite_Brick_Half",
      "rotation": 4
    },
    {
      "x": -2,
      "y": 8,
      "z": -3,
      "name": "Rock_Quartzite_Brick_Stairs",
      "rotation": 10
    },
    {
      "x": -2,
      "y": 9,
      "z": -3,
      "name": "Rock_Quartzite_Brick",
      "rotation": 1
    },
    {
      "x": -2,
      "y": 10,
      "z": -3,
      "name": "Rock_Stone_Brick_Smooth_Half",
      "rotation": 1
    },
    {
      "x": -2,
      "y": 0,
      "z": -2,
      "name": "Soil_Grass_Full"
    },
    {
      "x": -2,
      "y": 0,
      "z": -1,
      "name": "Soil_Grass_Full"
    },
    {
      "x": -2,
      "y": 1,
      "z": -1,
      "name": "Plant_Grass_Lush_Short"
    },
    {
      "x": -2,
      "y": 0,
      "z": 0,
      "name": "Soil_Grass_Full"
    },
    {
      "x": -2,
      "y": 8,
      "z": 0,
      "name": "Rock_Quartzite_Brick_Stairs",
      "rotation": 10
    },
    {
      "x": -2,
      "y": 9,
      "z": 0,
      "name": "Rock_Quartzite_Brick",
      "rotation": 1
    },
    {
      "x": -2,
      "y": 10,
      "z": 0,
      "name": "Rock_Stone_Brick_Smooth_Half",
      "rotation": 6
    },
    {
      "x": -2,
      "y": 11,
      "z": 0,
      "name": "Rock_Stone_Brick_Smooth_Half",
      "rotation": 6
    },
    {
      "x": -2,
      "y": 0,
      "z": 1,
      "name": "Soil_Grass_Full"
    },
    {
      "x": -2,
      "y": 8,
      "z": 1,
      "name": "Rock_Quartzite_Brick_Half",
      "rotation": 9
    },
    {
      "x": -2,
      "y": 9,
      "z": 1,
      "name": "Rock_Quartzite_Brick",
      "rotation": 1
    },
    {
      "x": -2,
      "y": 10,
      "z": 1,
      "name": "Rock_Stone_Brick_Smooth",
      "rotation": 1
    },
    {
      "x": -2,
      "y": 11,
      "z": 1,
      "name": "Rock_Stone_Brick_Smooth_Half",
      "rotation": 9
    },
    {
      "x": -2,
      "y": 0,
      "z": 2,
      "name": "Soil_Grass_Full"
    },
    {
      "x": -2,
      "y": 1,
      "z": 2,
      "name": "Plant_Grass_Lush_Short"
    },
    {
      "x": -2,
      "y": 7,
      "z": 2,
      "name": "Plant_Vine_Wall",
      "rotation": 2
    },
    {
      "x": -2,
      "y": 8,
      "z": 2,
      "name": "Rock_Quartzite_Brick_Half",
      "rotation": 9
    },
    {
      "x": -2,
      "y": 9,
      "z": 2,
      "name": "Rock_Quartzite_Brick",
      "rotation": 1
    },
    {
      "x": -2,
      "y": 10,
      "z": 2,
      "name": "Rock_Stone_Brick_Smooth",
      "rotation": 1
    },
    {
      "x": -2,
      "y": 11,
      "z": 2,
      "name": "Rock_Stone_Brick_Smooth_Half",
      "rotation": 4
    },
    {
      "x": -2,
      "y": 0,
      "z": 3,
      "name": "Rock_Quartzite",
      "rotation": 1
    },
    {
      "x": -2,
      "y": 1,
      "z": 3,
      "name": "Rock_Quartzite_Cobble",
      "rotation": 1
    },
    {
      "x": -2,
      "y": 2,
      "z": 3,
      "name": "Rock_Quartzite_Cobble",
      "rotation": 1
    },
    {
      "x": -2,
      "y": 3,
      "z": 3,
      "name": "Rock_Quartzite",
      "rotation": 1
    },
    {
      "x": -2,
      "y": 4,
      "z": 3,
      "name": "Rock_Quartzite",
      "rotation": 1
    },
    {
      "x": -2,
      "y": 5,
      "z": 3,
      "name": "Rock_Quartzite",
      "rotation": 1
    },
    {
      "x": -2,
      "y": 6,
      "z": 3,
      "name": "Rock_Quartzite",
      "rotation": 1
    },
    {
      "x": -2,
      "y": 7,
      "z": 3,
      "name": "Rock_Quartzite",
      "rotation": 1
    },
    {
      "x": -2,
      "y": 8,
      "z": 3,
      "name": "Rock_Quartzite",
      "rotation": 1
    },
    {
      "x": -2,
      "y": 9,
      "z": 3,
      "name": "Soil_Grass",
      "rotation": 1
    },
    {
      "x": -2,
      "y": 0,
      "z": 4,
      "name": "Rock_Quartzite",
      "rotation": 1
    },
    {
      "x": -2,
      "y": 1,
      "z": 4,
      "name": "Rock_Quartzite_Brick",
      "rotation": 1
    },
    {
      "x": -2,
      "y": 2,
      "z": 4,
      "name": "Rock_Quartzite",
      "rotation": 1
    },
    {
      "x": -2,
      "y": 3,
      "z": 4,
      "name": "Rock_Quartzite",
      "rotation": 1
    },
    {
      "x": -2,
      "y": 4,
      "z": 4,
      "name": "Rock_Quartzite",
      "rotation": 1
    },
    {
      "x": -2,
      "y": 5,
      "z": 4,
      "name": "Rock_Quartzite",
      "rotation": 1
    },
    {
      "x": -2,
      "y": 6,
      "z": 4,
      "name": "Rock_Quartzite",
      "rotation": 1
    },
    {
      "x": -2,
      "y": 7,
      "z": 4,
      "name": "Rock_Quartzite",
      "rotation": 1
    },
    {
      "x": -2,
      "y": 8,
      "z": 4,
      "name": "Rock_Quartzite",
      "rotation": 1
    },
    {
      "x": -2,
      "y": 9,
      "z": 4,
      "name": "Soil_Grass",
      "rotation": 1
    },
    {
      "x": -2,
      "y": 0,
      "z": 5,
      "name": "Rock_Quartzite",
      "rotation": 1
    },
    {
      "x": -2,
      "y": 1,
      "z": 5,
      "name": "Rock_Quartzite_Brick",
      "rotation": 1
    },
    {
      "x": -2,
      "y": 2,
      "z": 5,
      "name": "Rock_Quartzite",
      "rotation": 1
    },
    {
      "x": -2,
      "y": 3,
      "z": 5,
      "name": "Rock_Quartzite",
      "rotation": 1
    },
    {
      "x": -2,
      "y": 4,
      "z": 5,
      "name": "Rock_Quartzite",
      "rotation": 1
    },
    {
      "x": -2,
      "y": 5,
      "z": 5,
      "name": "Rock_Quartzite",
      "rotation": 1
    },
    {
      "x": -2,
      "y": 6,
      "z": 5,
      "name": "Rock_Quartzite",
      "rotation": 1
    },
    {
      "x": -2,
      "y": 7,
      "z": 5,
      "name": "Rock_Quartzite",
      "rotation": 1
    },
    {
      "x": -2,
      "y": 8,
      "z": 5,
      "name": "Rock_Quartzite",
      "rotation": 1
    },
    {
      "x": -2,
      "y": 9,
      "z": 5,
      "name": "Soil_Grass",
      "rotation": 1
    },
    {
      "x": -2,
      "y": 0,
      "z": 6,
      "name": "Soil_Grass_Full"
    },
    {
      "x": -2,
      "y": 8,
      "z": 6,
      "name": "Rock_Quartzite_Brick_Stairs",
      "rotation": 9
    },
    {
      "x": -2,
      "y": 9,
      "z": 6,
      "name": "Rock_Quartzite_Brick",
      "rotation": 1
    },
    {
      "x": -2,
      "y": 10,
      "z": 6,
      "name": "Rock_Stone_Brick_Smooth",
      "rotation": 1
    },
    {
      "x": -2,
      "y": 11,
      "z": 6,
      "name": "Rock_Stone_Brick_Smooth_Half",
      "rotation": 5
    },
    {
      "x": -2,
      "y": 0,
      "z": 7,
      "name": "Soil_Grass_Full"
    },
    {
      "x": -1,
      "y": 0,
      "z": -6,
      "name": "Rock_Quartzite",
      "rotation": 1
    },
    {
      "x": -1,
      "y": 1,
      "z": -6,
      "name": "Rock_Quartzite_Brick",
      "rotation": 1
    },
    {
      "x": -1,
      "y": 2,
      "z": -6,
      "name": "Rock_Quartzite",
      "rotation": 1
    },
    {
      "x": -1,
      "y": 3,
      "z": -6,
      "name": "Rock_Quartzite",
      "rotation": 1
    },
    {
      "x": -1,
      "y": 4,
      "z": -6,
      "name": "Rock_Quartzite",
      "rotation": 1
    },
    {
      "x": -1,
      "y": 5,
      "z": -6,
      "name": "Rock_Quartzite_Cobble_Half",
      "rotation": 7
    },
    {
      "x": -1,
      "y": 6,
      "z": -6,
      "name": "Rock_Quartzite_Cobble",
      "rotation": 1
    },
    {
      "x": -1,
      "y": 7,
      "z": -6,
      "name": "Soil_Dirt",
      "rotation": 1
    },
    {
      "x": -1,
      "y": 8,
      "z": -6,
      "name": "Soil_Dirt",
      "rotation": 1
    },
    {
      "x": -1,
      "y": 9,
      "z": -6,
      "name": "Soil_Grass",
      "rotation": 1
    },
    {
      "x": -1,
      "y": 0,
      "z": -5,
      "name": "Rock_Quartzite",
      "rotation": 1
    },
    {
      "x": -1,
      "y": 1,
      "z": -5,
      "name": "Rock_Quartzite_Brick",
      "rotation": 1
    },
    {
      "x": -1,
      "y": 2,
      "z": -5,
      "name": "Rock_Quartzite",
      "rotation": 1
    },
    {
      "x": -1,
      "y": 3,
      "z": -5,
      "name": "Rock_Quartzite_Cobble_Half",
      "rotation": 7
    },
    {
      "x": -1,
      "y": 4,
      "z": -5,
      "name": "Rock_Quartzite_Cobble_Half",
      "rotation": 7
    },
    {
      "x": -1,
      "y": 5,
      "z": -5,
      "name": "Rock_Quartzite_Cobble_Half",
      "rotation": 7
    },
    {
      "x": -1,
      "y": 6,
      "z": -5,
      "name": "Rock_Quartzite_Cobble_Stairs",
      "rotation": 9
    },
    {
      "x": -1,
      "y": 7,
      "z": -5,
      "name": "Rock_Quartzite_Cobble",
      "rotation": 1
    },
    {
      "x": -1,
      "y": 8,
      "z": -5,
      "name": "Rock_Quartzite_Cobble",
      "rotation": 1
    },
    {
      "x": -1,
      "y": 9,
      "z": -5,
      "name": "Soil_Grass",
      "rotation": 1
    },
    {
      "x": -1,
      "y": 10,
      "z": -5,
      "name": "Plant_Grass_Lush_Short",
      "rotation": 1
    },
    {
      "x": -1,
      "y": 0,
      "z": -4,
      "name": "Rock_Quartzite",
      "rotation": 1
    },
    {
      "x": -1,
      "y": 1,
      "z": -4,
      "name": "Rock_Quartzite_Brick",
      "rotation": 1
    },
    {
      "x": -1,
      "y": 2,
      "z": -4,
      "name": "Rock_Quartzite",
      "rotation": 1
    },
    {
      "x": -1,
      "y": 3,
      "z": -4,
      "name": "Rock_Quartzite",
      "rotation": 1
    },
    {
      "x": -1,
      "y": 4,
      "z": -4,
      "name": "Rock_Quartzite_Cobble",
      "rotation": 1
    },
    {
      "x": -1,
      "y": 5,
      "z": -4,
      "name": "Rock_Quartzite_Cobble",
      "rotation": 1
    },
    {
      "x": -1,
      "y": 6,
      "z": -4,
      "name": "Rock_Quartzite_Cobble",
      "rotation": 1
    },
    {
      "x": -1,
      "y": 7,
      "z": -4,
      "name": "Rock_Quartzite_Cobble",
      "rotation": 1
    },
    {
      "x": -1,
      "y": 8,
      "z": -4,
      "name": "Rock_Quartzite_Cobble",
      "rotation": 1
    },
    {
      "x": -1,
      "y": 9,
      "z": -4,
      "name": "Soil_Grass",
      "rotation": 1
    },
    {
      "x": -1,
      "y": 0,
      "z": -3,
      "name": "Rock_Quartzite",
      "rotation": 1
    },
    {
      "x": -1,
      "y": 1,
      "z": -3,
      "name": "Rock_Quartzite_Brick",
      "rotation": 1
    },
    {
      "x": -1,
      "y": 2,
      "z": -3,
      "name": "Rock_Quartzite",
      "rotation": 1
    },
    {
      "x": -1,
      "y": 3,
      "z": -3,
      "name": "Rock_Quartzite",
      "rotation": 1
    },
    {
      "x": -1,
      "y": 4,
      "z": -3,
      "name": "Rock_Quartzite_Cobble_Half",
      "rotation": 4
    },
    {
      "x": -1,
      "y": 7,
      "z": -3,
      "name": "Plant_Roots_Cave",
      "rotation": 9
    },
    {
      "x": -1,
      "y": 8,
      "z": -3,
      "name": "Soil_Dirt",
      "rotation": 1
    },
    {
      "x": -1,
      "y": 9,
      "z": -3,
      "name": "Soil_Grass",
      "rotation": 1
    },
    {
      "x": -1,
      "y": 0,
      "z": -2,
      "name": "Rock_Quartzite",
      "rotation": 1
    },
    {
      "x": -1,
      "y": 1,
      "z": -2,
      "name": "Rock_Quartzite_Brick",
      "rotation": 1
    },
    {
      "x": -1,
      "y": 2,
      "z": -2,
      "name": "Rock_Quartzite",
      "rotation": 1
    },
    {
      "x": -1,
      "y": 3,
      "z": -2,
      "name": "Rock_Quartzite",
      "rotation": 1
    },
    {
      "x": -1,
      "y": 0,
      "z": -1,
      "name": "Rock_Quartzite",
      "rotation": 1
    },
    {
      "x": -1,
      "y": 1,
      "z": -1,
      "name": "Rock_Quartzite_Brick",
      "rotation": 1
    },
    {
      "x": -1,
      "y": 2,
      "z": -1,
      "name": "Rock_Quartzite",
      "rotation": 1
    },
    {
      "x": -1,
      "y": 3,
      "z": -1,
      "name": "Rock_Quartzite",
      "rotation": 1
    },
    {
      "x": -1,
      "y": 4,
      "z": -1,
      "name": "Rock_Quartzite",
      "rotation": 1
    },
    {
      "x": -1,
      "y": 0,
      "z": 0,
      "name": "Rock_Quartzite_Cobble",
      "rotation": 1
    },
    {
      "x": -1,
      "y": 1,
      "z": 0,
      "name": "Rock_Quartzite_Brick",
      "rotation": 1
    },
    {
      "x": -1,
      "y": 2,
      "z": 0,
      "name": "Rock_Quartzite",
      "rotation": 1
    },
    {
      "x": -1,
      "y": 3,
      "z": 0,
      "name": "Rock_Quartzite",
      "rotation": 1
    },
    {
      "x": -1,
      "y": 4,
      "z": 0,
      "name": "Rock_Quartzite",
      "rotation": 1
    },
    {
      "x": -1,
      "y": 5,
      "z": 0,
      "name": "Rock_Quartzite",
      "rotation": 1
    },
    {
      "x": -1,
      "y": 6,
      "z": 0,
      "name": "Rock_Quartzite_Cobble_Half",
      "rotation": 7
    },
    {
      "x": -1,
      "y": 7,
      "z": 0,
      "name": "Rock_Quartzite_Cobble_Stairs",
      "rotation": 9
    },
    {
      "x": -1,
      "y": 8,
      "z": 0,
      "name": "Soil_Dirt",
      "rotation": 1
    },
    {
      "x": -1,
      "y": 9,
      "z": 0,
      "name": "Soil_Grass",
      "rotation": 1
    },
    {
      "x": -1,
      "y": 10,
      "z": 0,
      "name": "Plant_Moss_Rug_Green",
      "rotation": 1
    },
    {
      "x": -1,
      "y": 0,
      "z": 1,
      "name": "Rock_Quartzite_Cobble",
      "rotation": 1
    },
    {
      "x": -1,
      "y": 1,
      "z": 1,
      "name": "Rock_Quartzite_Cobble",
      "rotation": 1
    },
    {
      "x": -1,
      "y": 2,
      "z": 1,
      "name": "Rock_Quartzite_Cobble",
      "rotation": 1
    },
    {
      "x": -1,
      "y": 3,
      "z": 1,
      "name": "Rock_Quartzite",
      "rotation": 1
    },
    {
      "x": -1,
      "y": 4,
      "z": 1,
      "name": "Rock_Quartzite",
      "rotation": 1
    },
    {
      "x": -1,
      "y": 5,
      "z": 1,
      "name": "Rock_Quartzite",
      "rotation": 1
    },
    {
      "x": -1,
      "y": 6,
      "z": 1,
      "name": "Rock_Quartzite",
      "rotation": 1
    },
    {
      "x": -1,
      "y": 7,
      "z": 1,
      "name": "Rock_Quartzite",
      "rotation": 1
    },
    {
      "x": -1,
      "y": 8,
      "z": 1,
      "name": "Rock_Quartzite",
      "rotation": 1
    },
    {
      "x": -1,
      "y": 9,
      "z": 1,
      "name": "Soil_Grass",
      "rotation": 1
    },
    {
      "x": -1,
      "y": 10,
      "z": 1,
      "name": "Plant_Moss_Rug_Green",
      "rotation": 1
    },
    {
      "x": -1,
      "y": 0,
      "z": 2,
      "name": "Rock_Quartzite_Cobble",
      "rotation": 1
    },
    {
      "x": -1,
      "y": 1,
      "z": 2,
      "name": "Rock_Quartzite_Cobble",
      "rotation": 1
    },
    {
      "x": -1,
      "y": 2,
      "z": 2,
      "name": "Rock_Quartzite_Cobble",
      "rotation": 1
    },
    {
      "x": -1,
      "y": 3,
      "z": 2,
      "name": "Rock_Quartzite_Cobble",
      "rotation": 1
    },
    {
      "x": -1,
      "y": 4,
      "z": 2,
      "name": "Rock_Quartzite_Cobble",
      "rotation": 1
    },
    {
      "x": -1,
      "y": 5,
      "z": 2,
      "name": "Rock_Quartzite_Cobble",
      "rotation": 1
    },
    {
      "x": -1,
      "y": 6,
      "z": 2,
      "name": "Rock_Quartzite",
      "rotation": 1
    },
    {
      "x": -1,
      "y": 7,
      "z": 2,
      "name": "Rock_Quartzite",
      "rotation": 1
    },
    {
      "x": -1,
      "y": 8,
      "z": 2,
      "name": "Rock_Quartzite_Cobble",
      "rotation": 1
    },
    {
      "x": -1,
      "y": 9,
      "z": 2,
      "name": "Soil_Grass",
      "rotation": 1
    },
    {
      "x": -1,
      "y": 10,
      "z": 2,
      "name": "Plant_Grass_Lush",
      "rotation": 1
    },
    {
      "x": -1,
      "y": 0,
      "z": 3,
      "name": "Rock_Quartzite",
      "rotation": 1
    },
    {
      "x": -1,
      "y": 1,
      "z": 3,
      "name": "Rock_Quartzite_Brick",
      "rotation": 1
    },
    {
      "x": -1,
      "y": 2,
      "z": 3,
      "name": "Rock_Quartzite",
      "rotation": 1
    },
    {
      "x": -1,
      "y": 3,
      "z": 3,
      "name": "Rock_Quartzite",
      "rotation": 1
    },
    {
      "x": -1,
      "y": 4,
      "z": 3,
      "name": "Rock_Quartzite",
      "rotation": 1
    },
    {
      "x": -1,
      "y": 5,
      "z": 3,
      "name": "Rock_Quartzite",
      "rotation": 1
    },
    {
      "x": -1,
      "y": 6,
      "z": 3,
      "name": "Rock_Quartzite",
      "rotation": 1
    },
    {
      "x": -1,
      "y": 7,
      "z": 3,
      "name": "Rock_Quartzite",
      "rotation": 1
    },
    {
      "x": -1,
      "y": 8,
      "z": 3,
      "name": "Rock_Quartzite",
      "rotation": 1
    },
    {
      "x": -1,
      "y": 9,
      "z": 3,
      "name": "Soil_Grass",
      "rotation": 1
    },
    {
      "x": -1,
      "y": 0,
      "z": 4,
      "name": "Rock_Quartzite",
      "rotation": 1
    },
    {
      "x": -1,
      "y": 1,
      "z": 4,
      "name": "Rock_Quartzite_Brick",
      "rotation": 1
    },
    {
      "x": -1,
      "y": 2,
      "z": 4,
      "name": "Rock_Quartzite",
      "rotation": 1
    },
    {
      "x": -1,
      "y": 3,
      "z": 4,
      "name": "Rock_Quartzite",
      "rotation": 1
    },
    {
      "x": -1,
      "y": 4,
      "z": 4,
      "name": "Rock_Quartzite",
      "rotation": 1
    },
    {
      "x": -1,
      "y": 5,
      "z": 4,
      "name": "Rock_Quartzite",
      "rotation": 1
    },
    {
      "x": -1,
      "y": 6,
      "z": 4,
      "name": "Rock_Quartzite",
      "rotation": 1
    },
    {
      "x": -1,
      "y": 7,
      "z": 4,
      "name": "Rock_Quartzite",
      "rotation": 1
    },
    {
      "x": -1,
      "y": 8,
      "z": 4,
      "name": "Rock_Quartzite",
      "rotation": 1
    },
    {
      "x": -1,
      "y": 9,
      "z": 4,
      "name": "Soil_Grass",
      "rotation": 1
    },
    {
      "x": -1,
      "y": 0,
      "z": 5,
      "name": "Rock_Quartzite",
      "rotation": 1
    },
    {
      "x": -1,
      "y": 1,
      "z": 5,
      "name": "Rock_Quartzite_Brick",
      "rotation": 1
    },
    {
      "x": -1,
      "y": 2,
      "z": 5,
      "name": "Rock_Quartzite",
      "rotation": 1
    },
    {
      "x": -1,
      "y": 3,
      "z": 5,
      "name": "Rock_Quartzite",
      "rotation": 1
    },
    {
      "x": -1,
      "y": 4,
      "z": 5,
      "name": "Rock_Quartzite",
      "rotation": 1
    },
    {
      "x": -1,
      "y": 5,
      "z": 5,
      "name": "Rock_Quartzite",
      "rotation": 1
    },
    {
      "x": -1,
      "y": 6,
      "z": 5,
      "name": "Rock_Quartzite_Cobble_Half",
      "rotation": 4
    },
    {
      "x": -1,
      "y": 7,
      "z": 5,
      "name": "Rock_Quartzite",
      "rotation": 1
    },
    {
      "x": -1,
      "y": 8,
      "z": 5,
      "name": "Rock_Quartzite",
      "rotation": 1
    },
    {
      "x": -1,
      "y": 9,
      "z": 5,
      "name": "Soil_Grass",
      "rotation": 1
    },
    {
      "x": -1,
      "y": 10,
      "z": 5,
      "name": "Plant_Grass_Lush_Short",
      "rotation": 1
    },
    {
      "x": -1,
      "y": 0,
      "z": 6,
      "name": "Rock_Quartzite",
      "rotation": 1
    },
    {
      "x": -1,
      "y": 1,
      "z": 6,
      "name": "Plant_Grass_Sharp_Short"
    },
    {
      "x": -1,
      "y": 8,
      "z": 6,
      "name": "Rock_Quartzite_Brick_Stairs",
      "rotation": 11
    },
    {
      "x": -1,
      "y": 9,
      "z": 6,
      "name": "Rock_Quartzite_Brick",
      "rotation": 1
    },
    {
      "x": -1,
      "y": 10,
      "z": 6,
      "name": "Rock_Stone_Brick_Smooth",
      "rotation": 1
    },
    {
      "x": -1,
      "y": 11,
      "z": 6,
      "name": "Rock_Stone_Brick_Smooth_Half",
      "rotation": 7
    },
    {
      "x": -1,
      "y": 0,
      "z": 7,
      "name": "Rock_Quartzite",
      "rotation": 1
    },
    {
      "x": -1,
      "y": 1,
      "z": 7,
      "name": "Plant_Grass_Sharp"
    },
    {
      "x": 0,
      "y": 9,
      "z": -7,
      "name": "Plant_Vine",
      "rotation": 2
    },
    {
      "x": 0,
      "y": 0,
      "z": -6,
      "name": "Rock_Quartzite",
      "rotation": 1
    },
    {
      "x": 0,
      "y": 1,
      "z": -6,
      "name": "Rock_Quartzite_Brick",
      "rotation": 1
    },
    {
      "x": 0,
      "y": 2,
      "z": -6,
      "name": "Rock_Quartzite",
      "rotation": 1
    },
    {
      "x": 0,
      "y": 3,
      "z": -6,
      "name": "Rock_Quartzite",
      "rotation": 1
    },
    {
      "x": 0,
      "y": 4,
      "z": -6,
      "name": "Rock_Quartzite",
      "rotation": 1
    },
    {
      "x": 0,
      "y": 5,
      "z": -6,
      "name": "Rock_Quartzite",
      "rotation": 1
    },
    {
      "x": 0,
      "y": 6,
      "z": -6,
      "name": "Rock_Quartzite",
      "rotation": 1
    },
    {
      "x": 0,
      "y": 7,
      "z": -6,
      "name": "Soil_Dirt",
      "rotation": 1
    },
    {
      "x": 0,
      "y": 8,
      "z": -6,
      "name": "Soil_Dirt",
      "rotation": 1
    },
    {
      "x": 0,
      "y": 9,
      "z": -6,
      "name": "Soil_Grass",
      "rotation": 1
    },
    {
      "x": 0,
      "y": 10,
      "z": -6,
      "name": "Plant_Grass_Lush_Short",
      "rotation": 1
    },
    {
      "x": 0,
      "y": 0,
      "z": -5,
      "name": "Rock_Quartzite",
      "rotation": 1
    },
    {
      "x": 0,
      "y": 1,
      "z": -5,
      "name": "Rock_Quartzite_Brick",
      "rotation": 1
    },
    {
      "x": 0,
      "y": 2,
      "z": -5,
      "name": "Rock_Quartzite",
      "rotation": 1
    },
    {
      "x": 0,
      "y": 3,
      "z": -5,
      "name": "Rock_Quartzite",
      "rotation": 1
    },
    {
      "x": 0,
      "y": 4,
      "z": -5,
      "name": "Rock_Quartzite",
      "rotation": 1
    },
    {
      "x": 0,
      "y": 5,
      "z": -5,
      "name": "Rock_Quartzite",
      "rotation": 1
    },
    {
      "x": 0,
      "y": 6,
      "z": -5,
      "name": "Rock_Quartzite",
      "rotation": 1
    },
    {
      "x": 0,
      "y": 7,
      "z": -5,
      "name": "Rock_Quartzite",
      "rotation": 1
    },
    {
      "x": 0,
      "y": 8,
      "z": -5,
      "name": "Rock_Quartzite",
      "rotation": 1
    },
    {
      "x": 0,
      "y": 9,
      "z": -5,
      "name": "Soil_Grass",
      "rotation": 1
    },
    {
      "x": 0,
      "y": 10,
      "z": -5,
      "name": "Plant_Grass_Sharp_Tall",
      "rotation": 1
    },
    {
      "x": 0,
      "y": 11,
      "z": -5,
      "name": "Plant_Grass_Sharp_Tall",
      "filler": 1024,
      "rotation": 1
    },
    {
      "x": 0,
      "y": 0,
      "z": -4,
      "name": "Rock_Quartzite",
      "rotation": 1
    },
    {
      "x": 0,
      "y": 1,
      "z": -4,
      "name": "Rock_Quartzite_Brick",
      "rotation": 1
    },
    {
      "x": 0,
      "y": 2,
      "z": -4,
      "name": "Rock_Quartzite",
      "rotation": 1
    },
    {
      "x": 0,
      "y": 3,
      "z": -4,
      "name": "Rock_Quartzite",
      "rotation": 1
    },
    {
      "x": 0,
      "y": 4,
      "z": -4,
      "name": "Rock_Quartzite",
      "rotation": 1
    },
    {
      "x": 0,
      "y": 5,
      "z": -4,
      "name": "Rock_Quartzite",
      "rotation": 1
    },
    {
      "x": 0,
      "y": 6,
      "z": -4,
      "name": "Rock_Quartzite_Cobble",
      "rotation": 1
    },
    {
      "x": 0,
      "y": 7,
      "z": -4,
      "name": "Rock_Quartzite",
      "rotation": 1
    },
    {
      "x": 0,
      "y": 8,
      "z": -4,
      "name": "Rock_Quartzite",
      "rotation": 1
    },
    {
      "x": 0,
      "y": 9,
      "z": -4,
      "name": "Soil_Grass",
      "rotation": 1
    },
    {
      "x": 0,
      "y": 0,
      "z": -3,
      "name": "Rock_Quartzite",
      "rotation": 1
    },
    {
      "x": 0,
      "y": 1,
      "z": -3,
      "name": "Rock_Quartzite_Brick",
      "rotation": 1
    },
    {
      "x": 0,
      "y": 2,
      "z": -3,
      "name": "Rock_Quartzite",
      "rotation": 1
    },
    {
      "x": 0,
      "y": 3,
      "z": -3,
      "name": "Rock_Quartzite",
      "rotation": 1
    },
    {
      "x": 0,
      "y": 4,
      "z": -3,
      "name": "Rock_Quartzite_Cobble",
      "rotation": 1
    },
    {
      "x": 0,
      "y": 5,
      "z": -3,
      "name": "Rock_Quartzite_Cobble_Stairs"
    },
    {
      "x": 0,
      "y": 8,
      "z": -3,
      "name": "Soil_Dirt",
      "rotation": 1
    },
    {
      "x": 0,
      "y": 9,
      "z": -3,
      "name": "Soil_Grass",
      "rotation": 1
    },
    {
      "x": 0,
      "y": 10,
      "z": -3,
      "name": "Plant_Grass_Lush",
      "rotation": 1
    },
    {
      "x": 0,
      "y": 0,
      "z": -2,
      "name": "Rock_Quartzite",
      "rotation": 1
    },
    {
      "x": 0,
      "y": 1,
      "z": -2,
      "name": "Rock_Quartzite_Brick",
      "rotation": 1
    },
    {
      "x": 0,
      "y": 2,
      "z": -2,
      "name": "Rock_Quartzite",
      "rotation": 1
    },
    {
      "x": 0,
      "y": 3,
      "z": -2,
      "name": "Rock_Quartzite",
      "rotation": 1
    },
    {
      "x": 0,
      "y": 9,
      "z": -2,
      "name": "Plant_Vine_Wall"
    },
    {
      "x": 0,
      "y": 0,
      "z": -1,
      "name": "Rock_Quartzite",
      "rotation": 1
    },
    {
      "x": 0,
      "y": 1,
      "z": -1,
      "name": "Rock_Quartzite_Brick",
      "rotation": 1
    },
    {
      "x": 0,
      "y": 2,
      "z": -1,
      "name": "Rock_Quartzite",
      "rotation": 1
    },
    {
      "x": 0,
      "y": 3,
      "z": -1,
      "name": "Rock_Quartzite",
      "rotation": 1
    },
    {
      "x": 0,
      "y": 4,
      "z": -1,
      "name": "Rock_Quartzite",
      "rotation": 1
    },
    {
      "x": 0,
      "y": 0,
      "z": 0,
      "name": "Rock_Quartzite",
      "rotation": 1
    },
    {
      "x": 0,
      "y": 1,
      "z": 0,
      "name": "Rock_Quartzite_Brick",
      "rotation": 1
    },
    {
      "x": 0,
      "y": 2,
      "z": 0,
      "name": "Rock_Quartzite",
      "rotation": 1
    },
    {
      "x": 0,
      "y": 3,
      "z": 0,
      "name": "Rock_Quartzite",
      "rotation": 1
    },
    {
      "x": 0,
      "y": 4,
      "z": 0,
      "name": "Rock_Quartzite",
      "rotation": 1
    },
    {
      "x": 0,
      "y": 5,
      "z": 0,
      "name": "Rock_Quartzite",
      "rotation": 1
    },
    {
      "x": 0,
      "y": 6,
      "z": 0,
      "name": "Rock_Quartzite",
      "rotation": 1
    },
    {
      "x": 0,
      "y": 7,
      "z": 0,
      "name": "Soil_Dirt",
      "rotation": 1
    },
    {
      "x": 0,
      "y": 8,
      "z": 0,
      "name": "Soil_Grass",
      "rotation": 1
    },
    {
      "x": 0,
      "y": 9,
      "z": 0,
      "name": "Plant_Grass_Sharp_Tall",
      "rotation": 1
    },
    {
      "x": 0,
      "y": 10,
      "z": 0,
      "name": "Plant_Grass_Sharp_Tall",
      "filler": 1024,
      "rotation": 1
    },
    {
      "x": 0,
      "y": 0,
      "z": 1,
      "name": "Rock_Quartzite",
      "rotation": 1
    },
    {
      "x": 0,
      "y": 1,
      "z": 1,
      "name": "Rock_Quartzite_Brick",
      "rotation": 1
    },
    {
      "x": 0,
      "y": 2,
      "z": 1,
      "name": "Rock_Quartzite",
      "rotation": 1
    },
    {
      "x": 0,
      "y": 3,
      "z": 1,
      "name": "Rock_Quartzite",
      "rotation": 1
    },
    {
      "x": 0,
      "y": 4,
      "z": 1,
      "name": "Rock_Quartzite",
      "rotation": 1
    },
    {
      "x": 0,
      "y": 5,
      "z": 1,
      "name": "Rock_Quartzite",
      "rotation": 1
    },
    {
      "x": 0,
      "y": 6,
      "z": 1,
      "name": "Rock_Quartzite",
      "rotation": 1
    },
    {
      "x": 0,
      "y": 7,
      "z": 1,
      "name": "Rock_Quartzite",
      "rotation": 1
    },
    {
      "x": 0,
      "y": 8,
      "z": 1,
      "name": "Rock_Quartzite",
      "rotation": 1
    },
    {
      "x": 0,
      "y": 9,
      "z": 1,
      "name": "Soil_Grass",
      "rotation": 1
    },
    {
      "x": 0,
      "y": 10,
      "z": 1,
      "name": "Nat20_Mob_Group_Spawn"
    },
    {
      "x": 0,
      "y": 0,
      "z": 2,
      "name": "Rock_Quartzite",
      "rotation": 1
    },
    {
      "x": 0,
      "y": 1,
      "z": 2,
      "name": "Rock_Quartzite_Brick",
      "rotation": 1
    },
    {
      "x": 0,
      "y": 2,
      "z": 2,
      "name": "Rock_Quartzite",
      "rotation": 1
    },
    {
      "x": 0,
      "y": 3,
      "z": 2,
      "name": "Rock_Quartzite",
      "rotation": 1
    },
    {
      "x": 0,
      "y": 4,
      "z": 2,
      "name": "Rock_Quartzite",
      "rotation": 1
    },
    {
      "x": 0,
      "y": 5,
      "z": 2,
      "name": "Rock_Quartzite",
      "rotation": 1
    },
    {
      "x": 0,
      "y": 6,
      "z": 2,
      "name": "Rock_Quartzite",
      "rotation": 1
    },
    {
      "x": 0,
      "y": 7,
      "z": 2,
      "name": "Rock_Quartzite",
      "rotation": 1
    },
    {
      "x": 0,
      "y": 8,
      "z": 2,
      "name": "Soil_Dirt",
      "rotation": 1
    },
    {
      "x": 0,
      "y": 9,
      "z": 2,
      "name": "Soil_Grass",
      "rotation": 1
    },
    {
      "x": 0,
      "y": 10,
      "z": 2,
      "name": "Plant_Grass_Lush_Short",
      "rotation": 1
    },
    {
      "x": 0,
      "y": 0,
      "z": 3,
      "name": "Rock_Quartzite",
      "rotation": 1
    },
    {
      "x": 0,
      "y": 1,
      "z": 3,
      "name": "Rock_Quartzite_Brick",
      "rotation": 1
    },
    {
      "x": 0,
      "y": 2,
      "z": 3,
      "name": "Rock_Quartzite",
      "rotation": 1
    },
    {
      "x": 0,
      "y": 3,
      "z": 3,
      "name": "Rock_Quartzite",
      "rotation": 1
    },
    {
      "x": 0,
      "y": 4,
      "z": 3,
      "name": "Rock_Quartzite",
      "rotation": 1
    },
    {
      "x": 0,
      "y": 5,
      "z": 3,
      "name": "Rock_Quartzite",
      "rotation": 1
    },
    {
      "x": 0,
      "y": 6,
      "z": 3,
      "name": "Rock_Quartzite",
      "rotation": 1
    },
    {
      "x": 0,
      "y": 7,
      "z": 3,
      "name": "Rock_Quartzite",
      "rotation": 1
    },
    {
      "x": 0,
      "y": 8,
      "z": 3,
      "name": "Rock_Quartzite",
      "rotation": 1
    },
    {
      "x": 0,
      "y": 9,
      "z": 3,
      "name": "Soil_Grass",
      "rotation": 1
    },
    {
      "x": 0,
      "y": 10,
      "z": 3,
      "name": "Plant_Bush",
      "rotation": 1
    },
    {
      "x": 0,
      "y": 0,
      "z": 4,
      "name": "Rock_Quartzite",
      "rotation": 1
    },
    {
      "x": 0,
      "y": 1,
      "z": 4,
      "name": "Rock_Quartzite_Brick",
      "rotation": 1
    },
    {
      "x": 0,
      "y": 2,
      "z": 4,
      "name": "Rock_Quartzite",
      "rotation": 1
    },
    {
      "x": 0,
      "y": 3,
      "z": 4,
      "name": "Rock_Quartzite",
      "rotation": 1
    },
    {
      "x": 0,
      "y": 4,
      "z": 4,
      "name": "Rock_Quartzite",
      "rotation": 1
    },
    {
      "x": 0,
      "y": 5,
      "z": 4,
      "name": "Rock_Quartzite",
      "rotation": 1
    },
    {
      "x": 0,
      "y": 6,
      "z": 4,
      "name": "Rock_Quartzite",
      "rotation": 1
    },
    {
      "x": 0,
      "y": 7,
      "z": 4,
      "name": "Rock_Quartzite",
      "rotation": 1
    },
    {
      "x": 0,
      "y": 8,
      "z": 4,
      "name": "Rock_Quartzite",
      "rotation": 1
    },
    {
      "x": 0,
      "y": 9,
      "z": 4,
      "name": "Soil_Grass",
      "rotation": 1
    },
    {
      "x": 0,
      "y": 10,
      "z": 4,
      "name": "Plant_Grass_Lush",
      "rotation": 1
    },
    {
      "x": 0,
      "y": 0,
      "z": 5,
      "name": "Rock_Quartzite",
      "rotation": 1
    },
    {
      "x": 0,
      "y": 1,
      "z": 5,
      "name": "Rock_Quartzite_Brick",
      "rotation": 1
    },
    {
      "x": 0,
      "y": 2,
      "z": 5,
      "name": "Rock_Quartzite",
      "rotation": 1
    },
    {
      "x": 0,
      "y": 3,
      "z": 5,
      "name": "Rock_Quartzite",
      "rotation": 1
    },
    {
      "x": 0,
      "y": 4,
      "z": 5,
      "name": "Rock_Quartzite",
      "rotation": 1
    },
    {
      "x": 0,
      "y": 5,
      "z": 5,
      "name": "Rock_Quartzite",
      "rotation": 1
    },
    {
      "x": 0,
      "y": 6,
      "z": 5,
      "name": "Rock_Quartzite_Cobble_Half",
      "rotation": 4
    },
    {
      "x": 0,
      "y": 7,
      "z": 5,
      "name": "Rock_Quartzite",
      "rotation": 1
    },
    {
      "x": 0,
      "y": 8,
      "z": 5,
      "name": "Rock_Quartzite",
      "rotation": 1
    },
    {
      "x": 0,
      "y": 9,
      "z": 5,
      "name": "Soil_Grass",
      "rotation": 1
    },
    {
      "x": 0,
      "y": 10,
      "z": 5,
      "name": "Nat20_Chest_Spawn"
    },
    {
      "x": 0,
      "y": 0,
      "z": 6,
      "name": "Rock_Quartzite",
      "rotation": 1
    },
    {
      "x": 0,
      "y": 1,
      "z": 6,
      "name": "Plant_Grass_Lush_Short"
    },
    {
      "x": 0,
      "y": 8,
      "z": 6,
      "name": "Rock_Quartzite_Brick_Half",
      "rotation": 9
    },
    {
      "x": 0,
      "y": 9,
      "z": 6,
      "name": "Rock_Quartzite_Brick",
      "rotation": 1
    },
    {
      "x": 0,
      "y": 10,
      "z": 6,
      "name": "Rock_Stone_Brick_Smooth",
      "rotation": 1
    },
    {
      "x": 0,
      "y": 11,
      "z": 6,
      "name": "Rock_Stone_Brick_Smooth_Half",
      "rotation": 9
    },
    {
      "x": 0,
      "y": 0,
      "z": 7,
      "name": "Rock_Quartzite",
      "rotation": 1
    },
    {
      "x": 0,
      "y": 1,
      "z": 7,
      "name": "Plant_Grass_Sharp"
    },
    {
      "x": 1,
      "y": 7,
      "z": -7,
      "name": "Plant_Vine_Wall",
      "rotation": 2
    },
    {
      "x": 1,
      "y": 8,
      "z": -7,
      "name": "Plant_Vine",
      "rotation": 2
    },
    {
      "x": 1,
      "y": 9,
      "z": -7,
      "name": "Plant_Vine",
      "rotation": 2
    },
    {
      "x": 1,
      "y": 0,
      "z": -6,
      "name": "Rock_Quartzite",
      "rotation": 1
    },
    {
      "x": 1,
      "y": 1,
      "z": -6,
      "name": "Rock_Quartzite_Brick",
      "rotation": 1
    },
    {
      "x": 1,
      "y": 2,
      "z": -6,
      "name": "Rock_Quartzite",
      "rotation": 1
    },
    {
      "x": 1,
      "y": 3,
      "z": -6,
      "name": "Rock_Quartzite",
      "rotation": 1
    },
    {
      "x": 1,
      "y": 4,
      "z": -6,
      "name": "Rock_Quartzite",
      "rotation": 1
    },
    {
      "x": 1,
      "y": 5,
      "z": -6,
      "name": "Rock_Quartzite",
      "rotation": 1
    },
    {
      "x": 1,
      "y": 6,
      "z": -6,
      "name": "Rock_Quartzite_Cobble_Stairs",
      "rotation": 1
    },
    {
      "x": 1,
      "y": 7,
      "z": -6,
      "name": "Rock_Quartzite_Cobble",
      "rotation": 1
    },
    {
      "x": 1,
      "y": 8,
      "z": -6,
      "name": "Soil_Dirt",
      "rotation": 1
    },
    {
      "x": 1,
      "y": 9,
      "z": -6,
      "name": "Soil_Grass",
      "rotation": 1
    },
    {
      "x": 1,
      "y": 0,
      "z": -5,
      "name": "Rock_Quartzite",
      "rotation": 1
    },
    {
      "x": 1,
      "y": 1,
      "z": -5,
      "name": "Rock_Quartzite_Brick",
      "rotation": 1
    },
    {
      "x": 1,
      "y": 2,
      "z": -5,
      "name": "Rock_Quartzite",
      "rotation": 1
    },
    {
      "x": 1,
      "y": 3,
      "z": -5,
      "name": "Rock_Quartzite",
      "rotation": 1
    },
    {
      "x": 1,
      "y": 4,
      "z": -5,
      "name": "Rock_Quartzite",
      "rotation": 1
    },
    {
      "x": 1,
      "y": 5,
      "z": -5,
      "name": "Rock_Quartzite",
      "rotation": 1
    },
    {
      "x": 1,
      "y": 6,
      "z": -5,
      "name": "Rock_Quartzite_Cobble_Half",
      "rotation": 5
    },
    {
      "x": 1,
      "y": 7,
      "z": -5,
      "name": "Rock_Quartzite_Cobble_Half",
      "rotation": 5
    },
    {
      "x": 1,
      "y": 8,
      "z": -5,
      "name": "Rock_Quartzite_Cobble",
      "rotation": 1
    },
    {
      "x": 1,
      "y": 9,
      "z": -5,
      "name": "Soil_Grass",
      "rotation": 1
    },
    {
      "x": 1,
      "y": 10,
      "z": -5,
      "name": "Plant_Grass_Sharp_Tall",
      "rotation": 1
    },
    {
      "x": 1,
      "y": 11,
      "z": -5,
      "name": "Plant_Grass_Sharp_Tall",
      "filler": 1024,
      "rotation": 1
    },
    {
      "x": 1,
      "y": 0,
      "z": -4,
      "name": "Rock_Quartzite",
      "rotation": 1
    },
    {
      "x": 1,
      "y": 1,
      "z": -4,
      "name": "Rock_Quartzite_Brick",
      "rotation": 1
    },
    {
      "x": 1,
      "y": 2,
      "z": -4,
      "name": "Rock_Quartzite",
      "rotation": 1
    },
    {
      "x": 1,
      "y": 3,
      "z": -4,
      "name": "Rock_Quartzite",
      "rotation": 1
    },
    {
      "x": 1,
      "y": 4,
      "z": -4,
      "name": "Rock_Quartzite",
      "rotation": 1
    },
    {
      "x": 1,
      "y": 5,
      "z": -4,
      "name": "Rock_Quartzite",
      "rotation": 1
    },
    {
      "x": 1,
      "y": 6,
      "z": -4,
      "name": "Rock_Quartzite",
      "rotation": 1
    },
    {
      "x": 1,
      "y": 7,
      "z": -4,
      "name": "Rock_Quartzite",
      "rotation": 1
    },
    {
      "x": 1,
      "y": 8,
      "z": -4,
      "name": "Rock_Quartzite_Cobble",
      "rotation": 1
    },
    {
      "x": 1,
      "y": 9,
      "z": -4,
      "name": "Soil_Grass",
      "rotation": 1
    },
    {
      "x": 1,
      "y": 10,
      "z": -4,
      "name": "Plant_Grass_Sharp",
      "rotation": 1
    },
    {
      "x": 1,
      "y": 0,
      "z": -3,
      "name": "Rock_Quartzite",
      "rotation": 1
    },
    {
      "x": 1,
      "y": 1,
      "z": -3,
      "name": "Rock_Quartzite_Brick",
      "rotation": 1
    },
    {
      "x": 1,
      "y": 2,
      "z": -3,
      "name": "Rock_Quartzite",
      "rotation": 1
    },
    {
      "x": 1,
      "y": 3,
      "z": -3,
      "name": "Rock_Quartzite",
      "rotation": 1
    },
    {
      "x": 1,
      "y": 4,
      "z": -3,
      "name": "Rock_Quartzite",
      "rotation": 1
    },
    {
      "x": 1,
      "y": 5,
      "z": -3,
      "name": "Rock_Quartzite",
      "rotation": 1
    },
    {
      "x": 1,
      "y": 6,
      "z": -3,
      "name": "Rock_Quartzite",
      "rotation": 1
    },
    {
      "x": 1,
      "y": 7,
      "z": -3,
      "name": "Soil_Dirt",
      "rotation": 1
    },
    {
      "x": 1,
      "y": 8,
      "z": -3,
      "name": "Soil_Grass",
      "rotation": 1
    },
    {
      "x": 1,
      "y": 9,
      "z": -3,
      "name": "Plant_Moss_Rug_Green",
      "rotation": 1
    },
    {
      "x": 1,
      "y": 0,
      "z": -2,
      "name": "Rock_Quartzite",
      "rotation": 1
    },
    {
      "x": 1,
      "y": 1,
      "z": -2,
      "name": "Rock_Quartzite_Brick",
      "rotation": 1
    },
    {
      "x": 1,
      "y": 2,
      "z": -2,
      "name": "Rock_Quartzite",
      "rotation": 1
    },
    {
      "x": 1,
      "y": 6,
      "z": -2,
      "name": "Plant_Vine_Wall"
    },
    {
      "x": 1,
      "y": 7,
      "z": -2,
      "name": "Plant_Vine"
    },
    {
      "x": 1,
      "y": 8,
      "z": -2,
      "name": "Plant_Vine"
    },
    {
      "x": 1,
      "y": 0,
      "z": -1,
      "name": "Rock_Quartzite",
      "rotation": 1
    },
    {
      "x": 1,
      "y": 1,
      "z": -1,
      "name": "Rock_Quartzite_Brick",
      "rotation": 1
    },
    {
      "x": 1,
      "y": 2,
      "z": -1,
      "name": "Rock_Quartzite_Cobble",
      "rotation": 1
    },
    {
      "x": 1,
      "y": 3,
      "z": -1,
      "name": "Rock_Quartzite_Cobble_Stairs",
      "rotation": 1
    },
    {
      "x": 1,
      "y": 0,
      "z": 0,
      "name": "Rock_Quartzite",
      "rotation": 1
    },
    {
      "x": 1,
      "y": 1,
      "z": 0,
      "name": "Rock_Quartzite_Brick",
      "rotation": 1
    },
    {
      "x": 1,
      "y": 2,
      "z": 0,
      "name": "Rock_Quartzite_Cobble",
      "rotation": 1
    },
    {
      "x": 1,
      "y": 3,
      "z": 0,
      "name": "Rock_Quartzite_Cobble",
      "rotation": 1
    },
    {
      "x": 1,
      "y": 4,
      "z": 0,
      "name": "Rock_Quartzite_Cobble_Half",
      "rotation": 5
    },
    {
      "x": 1,
      "y": 5,
      "z": 0,
      "name": "Rock_Quartzite_Cobble_Half",
      "rotation": 5
    },
    {
      "x": 1,
      "y": 6,
      "z": 0,
      "name": "Rock_Quartzite_Cobble",
      "rotation": 1
    },
    {
      "x": 1,
      "y": 7,
      "z": 0,
      "name": "Soil_Dirt",
      "rotation": 1
    },
    {
      "x": 1,
      "y": 8,
      "z": 0,
      "name": "Soil_Grass",
      "rotation": 1
    },
    {
      "x": 1,
      "y": 9,
      "z": 0,
      "name": "Plant_Grass_Sharp",
      "rotation": 1
    },
    {
      "x": 1,
      "y": 0,
      "z": 1,
      "name": "Rock_Quartzite",
      "rotation": 1
    },
    {
      "x": 1,
      "y": 1,
      "z": 1,
      "name": "Rock_Quartzite_Brick",
      "rotation": 1
    },
    {
      "x": 1,
      "y": 2,
      "z": 1,
      "name": "Rock_Quartzite",
      "rotation": 1
    },
    {
      "x": 1,
      "y": 3,
      "z": 1,
      "name": "Rock_Quartzite",
      "rotation": 1
    },
    {
      "x": 1,
      "y": 4,
      "z": 1,
      "name": "Rock_Quartzite",
      "rotation": 1
    },
    {
      "x": 1,
      "y": 5,
      "z": 1,
      "name": "Rock_Quartzite",
      "rotation": 1
    },
    {
      "x": 1,
      "y": 6,
      "z": 1,
      "name": "Rock_Quartzite_Cobble",
      "rotation": 1
    },
    {
      "x": 1,
      "y": 7,
      "z": 1,
      "name": "Rock_Quartzite_Cobble",
      "rotation": 1
    },
    {
      "x": 1,
      "y": 8,
      "z": 1,
      "name": "Soil_Dirt",
      "rotation": 1
    },
    {
      "x": 1,
      "y": 9,
      "z": 1,
      "name": "Soil_Grass",
      "rotation": 1
    },
    {
      "x": 1,
      "y": 0,
      "z": 2,
      "name": "Rock_Quartzite",
      "rotation": 1
    },
    {
      "x": 1,
      "y": 1,
      "z": 2,
      "name": "Rock_Quartzite_Brick",
      "rotation": 1
    },
    {
      "x": 1,
      "y": 2,
      "z": 2,
      "name": "Rock_Quartzite",
      "rotation": 1
    },
    {
      "x": 1,
      "y": 3,
      "z": 2,
      "name": "Rock_Quartzite",
      "rotation": 1
    },
    {
      "x": 1,
      "y": 4,
      "z": 2,
      "name": "Rock_Quartzite",
      "rotation": 1
    },
    {
      "x": 1,
      "y": 5,
      "z": 2,
      "name": "Rock_Quartzite",
      "rotation": 1
    },
    {
      "x": 1,
      "y": 6,
      "z": 2,
      "name": "Rock_Quartzite",
      "rotation": 1
    },
    {
      "x": 1,
      "y": 7,
      "z": 2,
      "name": "Rock_Quartzite",
      "rotation": 1
    },
    {
      "x": 1,
      "y": 8,
      "z": 2,
      "name": "Soil_Dirt",
      "rotation": 1
    },
    {
      "x": 1,
      "y": 9,
      "z": 2,
      "name": "Soil_Grass",
      "rotation": 1
    },
    {
      "x": 1,
      "y": 0,
      "z": 3,
      "name": "Rock_Quartzite",
      "rotation": 1
    },
    {
      "x": 1,
      "y": 1,
      "z": 3,
      "name": "Rock_Quartzite_Brick",
      "rotation": 1
    },
    {
      "x": 1,
      "y": 2,
      "z": 3,
      "name": "Rock_Quartzite",
      "rotation": 1
    },
    {
      "x": 1,
      "y": 3,
      "z": 3,
      "name": "Rock_Quartzite",
      "rotation": 1
    },
    {
      "x": 1,
      "y": 4,
      "z": 3,
      "name": "Rock_Quartzite",
      "rotation": 1
    },
    {
      "x": 1,
      "y": 5,
      "z": 3,
      "name": "Rock_Quartzite",
      "rotation": 1
    },
    {
      "x": 1,
      "y": 6,
      "z": 3,
      "name": "Rock_Quartzite",
      "rotation": 1
    },
    {
      "x": 1,
      "y": 7,
      "z": 3,
      "name": "Rock_Quartzite",
      "rotation": 1
    },
    {
      "x": 1,
      "y": 8,
      "z": 3,
      "name": "Rock_Quartzite",
      "rotation": 1
    },
    {
      "x": 1,
      "y": 9,
      "z": 3,
      "name": "Soil_Grass",
      "rotation": 1
    },
    {
      "x": 1,
      "y": 10,
      "z": 3,
      "name": "Plant_Bush",
      "rotation": 1
    },
    {
      "x": 1,
      "y": 0,
      "z": 4,
      "name": "Rock_Quartzite",
      "rotation": 1
    },
    {
      "x": 1,
      "y": 1,
      "z": 4,
      "name": "Rock_Quartzite_Brick",
      "rotation": 1
    },
    {
      "x": 1,
      "y": 2,
      "z": 4,
      "name": "Rock_Quartzite",
      "rotation": 1
    },
    {
      "x": 1,
      "y": 3,
      "z": 4,
      "name": "Rock_Quartzite",
      "rotation": 1
    },
    {
      "x": 1,
      "y": 4,
      "z": 4,
      "name": "Rock_Quartzite",
      "rotation": 1
    },
    {
      "x": 1,
      "y": 5,
      "z": 4,
      "name": "Rock_Quartzite",
      "rotation": 1
    },
    {
      "x": 1,
      "y": 6,
      "z": 4,
      "name": "Rock_Quartzite",
      "rotation": 1
    },
    {
      "x": 1,
      "y": 7,
      "z": 4,
      "name": "Rock_Quartzite",
      "rotation": 1
    },
    {
      "x": 1,
      "y": 8,
      "z": 4,
      "name": "Rock_Quartzite",
      "rotation": 1
    },
    {
      "x": 1,
      "y": 9,
      "z": 4,
      "name": "Soil_Grass",
      "rotation": 1
    },
    {
      "x": 1,
      "y": 10,
      "z": 4,
      "name": "Plant_Grass_Sharp",
      "rotation": 1
    },
    {
      "x": 1,
      "y": 0,
      "z": 5,
      "name": "Rock_Quartzite",
      "rotation": 1
    },
    {
      "x": 1,
      "y": 1,
      "z": 5,
      "name": "Rock_Quartzite_Brick",
      "rotation": 1
    },
    {
      "x": 1,
      "y": 2,
      "z": 5,
      "name": "Rock_Quartzite",
      "rotation": 1
    },
    {
      "x": 1,
      "y": 3,
      "z": 5,
      "name": "Rock_Quartzite",
      "rotation": 1
    },
    {
      "x": 1,
      "y": 4,
      "z": 5,
      "name": "Rock_Quartzite",
      "rotation": 1
    },
    {
      "x": 1,
      "y": 5,
      "z": 5,
      "name": "Rock_Quartzite",
      "rotation": 1
    },
    {
      "x": 1,
      "y": 6,
      "z": 5,
      "name": "Rock_Quartzite_Cobble_Half",
      "rotation": 4
    },
    {
      "x": 1,
      "y": 7,
      "z": 5,
      "name": "Rock_Quartzite_Cobble_Stairs",
      "rotation": 10
    },
    {
      "x": 1,
      "y": 8,
      "z": 5,
      "name": "Rock_Quartzite_Cobble",
      "rotation": 1
    },
    {
      "x": 1,
      "y": 9,
      "z": 5,
      "name": "Soil_Grass",
      "rotation": 1
    },
    {
      "x": 1,
      "y": 0,
      "z": 6,
      "name": "Rock_Quartzite",
      "rotation": 1
    },
    {
      "x": 1,
      "y": 1,
      "z": 6,
      "name": "Plant_Grass_Sharp"
    },
    {
      "x": 1,
      "y": 8,
      "z": 6,
      "name": "Rock_Quartzite_Brick_Stairs",
      "rotation": 9
    },
    {
      "x": 1,
      "y": 9,
      "z": 6,
      "name": "Rock_Quartzite_Brick",
      "rotation": 1
    },
    {
      "x": 1,
      "y": 10,
      "z": 6,
      "name": "Rock_Stone_Brick_Smooth",
      "rotation": 1
    },
    {
      "x": 1,
      "y": 11,
      "z": 6,
      "name": "Rock_Stone_Brick_Smooth_Half",
      "rotation": 5
    },
    {
      "x": 1,
      "y": 0,
      "z": 7,
      "name": "Rock_Quartzite",
      "rotation": 1
    },
    {
      "x": 1,
      "y": 1,
      "z": 7,
      "name": "Plant_Grass_Sharp"
    },
    {
      "x": 2,
      "y": 9,
      "z": -7,
      "name": "Plant_Vine_Wall",
      "rotation": 2
    },
    {
      "x": 2,
      "y": 0,
      "z": -6,
      "name": "Rock_Quartzite",
      "rotation": 1
    },
    {
      "x": 2,
      "y": 8,
      "z": -6,
      "name": "Rock_Quartzite_Brick_Stairs",
      "rotation": 10
    },
    {
      "x": 2,
      "y": 9,
      "z": -6,
      "name": "Rock_Quartzite_Brick",
      "rotation": 1
    },
    {
      "x": 2,
      "y": 10,
      "z": -6,
      "name": "Rock_Stone_Brick_Smooth",
      "rotation": 1
    },
    {
      "x": 2,
      "y": 11,
      "z": -6,
      "name": "Rock_Stone_Brick_Smooth_Half",
      "rotation": 6
    },
    {
      "x": 2,
      "y": 0,
      "z": -5,
      "name": "Rock_Quartzite",
      "rotation": 1
    },
    {
      "x": 2,
      "y": 8,
      "z": -5,
      "name": "Rock_Quartzite_Brick_Half",
      "rotation": 9
    },
    {
      "x": 2,
      "y": 9,
      "z": -5,
      "name": "Rock_Quartzite_Brick",
      "rotation": 1
    },
    {
      "x": 2,
      "y": 10,
      "z": -5,
      "name": "Rock_Stone_Brick_Smooth",
      "rotation": 1
    },
    {
      "x": 2,
      "y": 11,
      "z": -5,
      "name": "Rock_Stone_Brick_Smooth_Half",
      "rotation": 9
    },
    {
      "x": 2,
      "y": 0,
      "z": -4,
      "name": "Rock_Quartzite",
      "rotation": 1
    },
    {
      "x": 2,
      "y": 1,
      "z": -4,
      "name": "Rock_Quartzite_Brick",
      "rotation": 1
    },
    {
      "x": 2,
      "y": 2,
      "z": -4,
      "name": "Rock_Quartzite_Brick_Half",
      "rotation": 6
    },
    {
      "x": 2,
      "y": 3,
      "z": -4,
      "name": "Rock_Quartzite_Brick_Half",
      "rotation": 6
    },
    {
      "x": 2,
      "y": 4,
      "z": -4,
      "name": "Rock_Quartzite_Brick_Half",
      "rotation": 6
    },
    {
      "x": 2,
      "y": 5,
      "z": -4,
      "name": "Rock_Quartzite_Brick_Half",
      "rotation": 6
    },
    {
      "x": 2,
      "y": 6,
      "z": -4,
      "name": "Rock_Quartzite_Brick_Half",
      "rotation": 6
    },
    {
      "x": 2,
      "y": 7,
      "z": -4,
      "name": "Rock_Quartzite_Brick_Half",
      "rotation": 6
    },
    {
      "x": 2,
      "y": 8,
      "z": -4,
      "name": "Rock_Quartzite_Brick_Stairs",
      "rotation": 8
    },
    {
      "x": 2,
      "y": 9,
      "z": -4,
      "name": "Rock_Quartzite_Brick",
      "rotation": 1
    },
    {
      "x": 2,
      "y": 10,
      "z": -4,
      "name": "Rock_Stone_Brick_Smooth",
      "rotation": 1
    },
    {
      "x": 2,
      "y": 11,
      "z": -4,
      "name": "Rock_Stone_Brick_Smooth_Half",
      "rotation": 4
    },
    {
      "x": 2,
      "y": 0,
      "z": -3,
      "name": "Rock_Quartzite",
      "rotation": 1
    },
    {
      "x": 2,
      "y": 1,
      "z": -3,
      "name": "Rock_Quartzite_Brick",
      "rotation": 1
    },
    {
      "x": 2,
      "y": 2,
      "z": -3,
      "name": "Rock_Quartzite_Brick_Half",
      "rotation": 4
    },
    {
      "x": 2,
      "y": 3,
      "z": -3,
      "name": "Rock_Quartzite_Brick_Half",
      "rotation": 4
    },
    {
      "x": 2,
      "y": 7,
      "z": -3,
      "name": "Rock_Quartzite_Brick_Half",
      "rotation": 4
    },
    {
      "x": 2,
      "y": 8,
      "z": -3,
      "name": "Rock_Quartzite_Brick_Stairs",
      "rotation": 10
    },
    {
      "x": 2,
      "y": 9,
      "z": -3,
      "name": "Plant_Moss_Rug_Green",
      "rotation": 1
    },
    {
      "x": 2,
      "y": 0,
      "z": -2,
      "name": "Rock_Quartzite",
      "rotation": 1
    },
    {
      "x": 2,
      "y": 0,
      "z": -1,
      "name": "Rock_Quartzite",
      "rotation": 1
    },
    {
      "x": 2,
      "y": 0,
      "z": 0,
      "name": "Rock_Quartzite_Cobble",
      "rotation": 1
    },
    {
      "x": 2,
      "y": 8,
      "z": 0,
      "name": "Rock_Quartzite_Brick_Stairs",
      "rotation": 10
    },
    {
      "x": 2,
      "y": 0,
      "z": 1,
      "name": "Rock_Quartzite",
      "rotation": 1
    },
    {
      "x": 2,
      "y": 7,
      "z": 1,
      "name": "Nat20_Force_Empty"
    },
    {
      "x": 2,
      "y": 8,
      "z": 1,
      "name": "Rock_Quartzite_Brick_Half",
      "rotation": 9
    },
    {
      "x": 2,
      "y": 9,
      "z": 1,
      "name": "Rock_Quartzite_Brick",
      "rotation": 1
    },
    {
      "x": 2,
      "y": 10,
      "z": 1,
      "name": "Rock_Stone_Brick_Smooth",
      "rotation": 1
    },
    {
      "x": 2,
      "y": 0,
      "z": 2,
      "name": "Rock_Quartzite_Cobble",
      "rotation": 1
    },
    {
      "x": 2,
      "y": 5,
      "z": 2,
      "name": "Nat20_Force_Empty"
    },
    {
      "x": 2,
      "y": 6,
      "z": 2,
      "name": "Nat20_Force_Empty"
    },
    {
      "x": 2,
      "y": 7,
      "z": 2,
      "name": "Nat20_Force_Empty"
    },
    {
      "x": 2,
      "y": 8,
      "z": 2,
      "name": "Rock_Quartzite_Brick_Half",
      "rotation": 9
    },
    {
      "x": 2,
      "y": 9,
      "z": 2,
      "name": "Rock_Quartzite_Brick",
      "rotation": 1
    },
    {
      "x": 2,
      "y": 10,
      "z": 2,
      "name": "Rock_Stone_Brick_Smooth",
      "rotation": 1
    },
    {
      "x": 2,
      "y": 11,
      "z": 2,
      "name": "Rock_Stone_Brick_Smooth_Half",
      "rotation": 4
    },
    {
      "x": 2,
      "y": 12,
      "z": 2,
      "name": "Plant_Moss_Rug_Green",
      "rotation": 1
    },
    {
      "x": 2,
      "y": 0,
      "z": 3,
      "name": "Rock_Quartzite_Cobble",
      "rotation": 1
    },
    {
      "x": 2,
      "y": 3,
      "z": 3,
      "name": "Rock_Quartzite_Cobble_Half",
      "rotation": 6
    },
    {
      "x": 2,
      "y": 4,
      "z": 3,
      "name": "Rock_Quartzite",
      "rotation": 1
    },
    {
      "x": 2,
      "y": 5,
      "z": 3,
      "name": "Rock_Quartzite",
      "rotation": 1
    },
    {
      "x": 2,
      "y": 6,
      "z": 3,
      "name": "Rock_Quartzite",
      "rotation": 1
    },
    {
      "x": 2,
      "y": 7,
      "z": 3,
      "name": "Rock_Quartzite",
      "rotation": 1
    },
    {
      "x": 2,
      "y": 8,
      "z": 3,
      "name": "Rock_Quartzite",
      "rotation": 1
    },
    {
      "x": 2,
      "y": 9,
      "z": 3,
      "name": "Soil_Grass",
      "rotation": 1
    },
    {
      "x": 2,
      "y": 10,
      "z": 3,
      "name": "Plant_Fern_Winter",
      "rotation": 1
    },
    {
      "x": 2,
      "y": 0,
      "z": 4,
      "name": "Rock_Quartzite",
      "rotation": 1
    },
    {
      "x": 2,
      "y": 1,
      "z": 4,
      "name": "Rock_Quartzite_Brick",
      "rotation": 1
    },
    {
      "x": 2,
      "y": 2,
      "z": 4,
      "name": "Rock_Quartzite",
      "rotation": 1
    },
    {
      "x": 2,
      "y": 3,
      "z": 4,
      "name": "Rock_Quartzite",
      "rotation": 1
    },
    {
      "x": 2,
      "y": 4,
      "z": 4,
      "name": "Rock_Quartzite",
      "rotation": 1
    },
    {
      "x": 2,
      "y": 5,
      "z": 4,
      "name": "Rock_Quartzite",
      "rotation": 1
    },
    {
      "x": 2,
      "y": 6,
      "z": 4,
      "name": "Rock_Quartzite",
      "rotation": 1
    },
    {
      "x": 2,
      "y": 7,
      "z": 4,
      "name": "Soil_Dirt",
      "rotation": 1
    },
    {
      "x": 2,
      "y": 8,
      "z": 4,
      "name": "Soil_Dirt",
      "rotation": 1
    },
    {
      "x": 2,
      "y": 9,
      "z": 4,
      "name": "Soil_Grass",
      "rotation": 1
    },
    {
      "x": 2,
      "y": 10,
      "z": 4,
      "name": "Plant_Moss_Rug_Green",
      "rotation": 1
    },
    {
      "x": 2,
      "y": 0,
      "z": 5,
      "name": "Rock_Quartzite",
      "rotation": 1
    },
    {
      "x": 2,
      "y": 1,
      "z": 5,
      "name": "Rock_Quartzite_Brick",
      "rotation": 1
    },
    {
      "x": 2,
      "y": 2,
      "z": 5,
      "name": "Rock_Quartzite",
      "rotation": 1
    },
    {
      "x": 2,
      "y": 3,
      "z": 5,
      "name": "Rock_Quartzite",
      "rotation": 1
    },
    {
      "x": 2,
      "y": 4,
      "z": 5,
      "name": "Rock_Quartzite_Cobble",
      "rotation": 1
    },
    {
      "x": 2,
      "y": 5,
      "z": 5,
      "name": "Rock_Quartzite_Cobble",
      "rotation": 1
    },
    {
      "x": 2,
      "y": 6,
      "z": 5,
      "name": "Rock_Quartzite_Cobble",
      "rotation": 1
    },
    {
      "x": 2,
      "y": 7,
      "z": 5,
      "name": "Rock_Quartzite_Cobble",
      "rotation": 1
    },
    {
      "x": 2,
      "y": 8,
      "z": 5,
      "name": "Soil_Dirt",
      "rotation": 1
    },
    {
      "x": 2,
      "y": 9,
      "z": 5,
      "name": "Soil_Grass",
      "rotation": 1
    },
    {
      "x": 2,
      "y": 0,
      "z": 6,
      "name": "Rock_Quartzite",
      "rotation": 1
    },
    {
      "x": 2,
      "y": 8,
      "z": 6,
      "name": "Rock_Quartzite_Brick_Stairs",
      "rotation": 11
    },
    {
      "x": 2,
      "y": 9,
      "z": 6,
      "name": "Rock_Quartzite_Brick",
      "rotation": 1
    },
    {
      "x": 2,
      "y": 10,
      "z": 6,
      "name": "Rock_Stone_Brick_Smooth",
      "rotation": 1
    },
    {
      "x": 2,
      "y": 0,
      "z": 7,
      "name": "Rock_Quartzite",
      "rotation": 1
    },
    {
      "x": 3,
      "y": 0,
      "z": -4,
      "name": "Nat20_Npc_Spawn"
    },
    {
      "x": 3,
      "y": 0,
      "z": -2,
      "name": "Plant_Flower_Flax_Blue"
    },
    {
      "x": 3,
      "y": 8,
      "z": 2,
      "name": "Rock_Quartzite_Brick_Half",
      "rotation": 9
    },
    {
      "x": 3,
      "y": 9,
      "z": 2,
      "name": "Rock_Quartzite_Brick",
      "rotation": 1
    },
    {
      "x": 3,
      "y": 10,
      "z": 2,
      "name": "Rock_Stone_Brick_Smooth",
      "rotation": 1
    },
    {
      "x": 3,
      "y": 11,
      "z": 2,
      "name": "Rock_Stone_Brick_Smooth_Half",
      "rotation": 9
    },
    {
      "x": 3,
      "y": 12,
      "z": 2,
      "name": "Plant_Moss_Rug_Green",
      "rotation": 1
    },
    {
      "x": 3,
      "y": 0,
      "z": 3,
      "name": "Rock_Quartzite",
      "rotation": 1
    },
    {
      "x": 3,
      "y": 3,
      "z": 3,
      "name": "Rock_Quartzite_Cobble_Half",
      "rotation": 6
    },
    {
      "x": 3,
      "y": 4,
      "z": 3,
      "name": "Rock_Quartzite_Cobble_Half",
      "rotation": 6
    },
    {
      "x": 3,
      "y": 5,
      "z": 3,
      "name": "Rock_Quartzite_Cobble",
      "rotation": 1
    },
    {
      "x": 3,
      "y": 6,
      "z": 3,
      "name": "Rock_Quartzite_Cobble",
      "rotation": 1
    },
    {
      "x": 3,
      "y": 7,
      "z": 3,
      "name": "Soil_Dirt",
      "rotation": 1
    },
    {
      "x": 3,
      "y": 8,
      "z": 3,
      "name": "Soil_Dirt",
      "rotation": 1
    },
    {
      "x": 3,
      "y": 9,
      "z": 3,
      "name": "Soil_Grass",
      "rotation": 1
    },
    {
      "x": 3,
      "y": 10,
      "z": 3,
      "name": "Plant_Moss_Rug_Green",
      "rotation": 1
    },
    {
      "x": 3,
      "y": 0,
      "z": 4,
      "name": "Rock_Quartzite",
      "rotation": 1
    },
    {
      "x": 3,
      "y": 1,
      "z": 4,
      "name": "Rock_Quartzite_Brick",
      "rotation": 1
    },
    {
      "x": 3,
      "y": 2,
      "z": 4,
      "name": "Rock_Quartzite",
      "rotation": 1
    },
    {
      "x": 3,
      "y": 3,
      "z": 4,
      "name": "Rock_Quartzite",
      "rotation": 1
    },
    {
      "x": 3,
      "y": 4,
      "z": 4,
      "name": "Rock_Quartzite",
      "rotation": 1
    },
    {
      "x": 3,
      "y": 5,
      "z": 4,
      "name": "Rock_Quartzite",
      "rotation": 1
    },
    {
      "x": 3,
      "y": 6,
      "z": 4,
      "name": "Soil_Grass",
      "rotation": 1
    },
    {
      "x": 3,
      "y": 7,
      "z": 4,
      "name": "Plant_Grass_Sharp",
      "rotation": 1
    },
    {
      "x": 3,
      "y": 8,
      "z": 4,
      "name": "Plant_Vine_Wall"
    },
    {
      "x": 3,
      "y": 9,
      "z": 4,
      "name": "Plant_Vine"
    },
    {
      "x": 3,
      "y": 0,
      "z": 5,
      "name": "Rock_Quartzite",
      "rotation": 1
    },
    {
      "x": 3,
      "y": 1,
      "z": 5,
      "name": "Rock_Quartzite_Brick",
      "rotation": 1
    },
    {
      "x": 3,
      "y": 2,
      "z": 5,
      "name": "Rock_Quartzite",
      "rotation": 1
    },
    {
      "x": 3,
      "y": 3,
      "z": 5,
      "name": "Rock_Quartzite",
      "rotation": 1
    },
    {
      "x": 3,
      "y": 4,
      "z": 5,
      "name": "Soil_Dirt",
      "rotation": 1
    },
    {
      "x": 3,
      "y": 5,
      "z": 5,
      "name": "Soil_Grass",
      "rotation": 1
    },
    {
      "x": 3,
      "y": 6,
      "z": 5,
      "name": "Plant_Grass_Sharp_Tall",
      "rotation": 1
    },
    {
      "x": 3,
      "y": 7,
      "z": 5,
      "name": "Plant_Grass_Sharp_Tall",
      "filler": 1024,
      "rotation": 1
    },
    {
      "x": 3,
      "y": 0,
      "z": 6,
      "name": "Rock_Quartzite",
      "rotation": 1
    },
    {
      "x": 4,
      "y": 0,
      "z": 2,
      "name": "Rock_Quartzite",
      "rotation": 1
    },
    {
      "x": 4,
      "y": 1,
      "z": 2,
      "name": "Rock_Quartzite_Brick",
      "rotation": 1
    },
    {
      "x": 4,
      "y": 2,
      "z": 2,
      "name": "Rock_Quartzite_Brick_Half",
      "rotation": 7
    },
    {
      "x": 4,
      "y": 3,
      "z": 2,
      "name": "Rock_Quartzite_Brick_Half",
      "rotation": 7
    },
    {
      "x": 4,
      "y": 4,
      "z": 2,
      "name": "Rock_Quartzite_Brick_Half",
      "rotation": 7
    },
    {
      "x": 4,
      "y": 5,
      "z": 2,
      "name": "Rock_Quartzite_Brick_Half",
      "rotation": 7
    },
    {
      "x": 4,
      "y": 6,
      "z": 2,
      "name": "Rock_Quartzite_Brick_Half",
      "rotation": 7
    },
    {
      "x": 4,
      "y": 7,
      "z": 2,
      "name": "Rock_Quartzite_Brick_Half",
      "rotation": 7
    },
    {
      "x": 4,
      "y": 8,
      "z": 2,
      "name": "Rock_Quartzite_Brick_Stairs",
      "rotation": 9
    },
    {
      "x": 4,
      "y": 9,
      "z": 2,
      "name": "Rock_Quartzite_Brick",
      "rotation": 1
    },
    {
      "x": 4,
      "y": 10,
      "z": 2,
      "name": "Rock_Stone_Brick_Smooth",
      "rotation": 1
    },
    {
      "x": 4,
      "y": 11,
      "z": 2,
      "name": "Rock_Stone_Brick_Smooth_Half",
      "rotation": 5
    },
    {
      "x": 4,
      "y": 0,
      "z": 3,
      "name": "Rock_Quartzite",
      "rotation": 1
    },
    {
      "x": 4,
      "y": 1,
      "z": 3,
      "name": "Rock_Quartzite_Cobble",
      "rotation": 1
    },
    {
      "x": 4,
      "y": 2,
      "z": 3,
      "name": "Rock_Quartzite_Cobble",
      "rotation": 1
    },
    {
      "x": 4,
      "y": 3,
      "z": 3,
      "name": "Rock_Quartzite_Cobble",
      "rotation": 1
    },
    {
      "x": 4,
      "y": 4,
      "z": 3,
      "name": "Rock_Quartzite_Cobble",
      "rotation": 1
    },
    {
      "x": 4,
      "y": 5,
      "z": 3,
      "name": "Rock_Quartzite_Cobble",
      "rotation": 1
    },
    {
      "x": 4,
      "y": 6,
      "z": 3,
      "name": "Rock_Quartzite_Cobble",
      "rotation": 1
    },
    {
      "x": 4,
      "y": 7,
      "z": 3,
      "name": "Soil_Dirt",
      "rotation": 1
    },
    {
      "x": 4,
      "y": 8,
      "z": 3,
      "name": "Soil_Grass",
      "rotation": 1
    },
    {
      "x": 4,
      "y": 9,
      "z": 3,
      "name": "Plant_Grass_Sharp_Tall",
      "rotation": 1
    },
    {
      "x": 4,
      "y": 10,
      "z": 3,
      "name": "Plant_Grass_Sharp_Tall",
      "filler": 1024,
      "rotation": 1
    },
    {
      "x": 4,
      "y": 0,
      "z": 4,
      "name": "Rock_Quartzite",
      "rotation": 1
    },
    {
      "x": 4,
      "y": 1,
      "z": 4,
      "name": "Rock_Quartzite_Brick",
      "rotation": 1
    },
    {
      "x": 4,
      "y": 2,
      "z": 4,
      "name": "Rock_Quartzite",
      "rotation": 1
    },
    {
      "x": 4,
      "y": 3,
      "z": 4,
      "name": "Rock_Quartzite",
      "rotation": 1
    },
    {
      "x": 4,
      "y": 4,
      "z": 4,
      "name": "Rock_Quartzite",
      "rotation": 1
    },
    {
      "x": 4,
      "y": 5,
      "z": 4,
      "name": "Soil_Dirt",
      "rotation": 1
    },
    {
      "x": 4,
      "y": 6,
      "z": 4,
      "name": "Soil_Grass",
      "rotation": 1
    },
    {
      "x": 4,
      "y": 7,
      "z": 4,
      "name": "Plant_Grass_Sharp",
      "rotation": 1
    },
    {
      "x": 4,
      "y": 8,
      "z": 4,
      "name": "Plant_Vine"
    },
    {
      "x": 4,
      "y": 0,
      "z": 5,
      "name": "Rock_Quartzite",
      "rotation": 1
    },
    {
      "x": 4,
      "y": 1,
      "z": 5,
      "name": "Rock_Quartzite_Brick",
      "rotation": 1
    },
    {
      "x": 4,
      "y": 0,
      "z": 6,
      "name": "Rock_Quartzite",
      "rotation": 1
    },
    {
      "x": 4,
      "y": 1,
      "z": 6,
      "name": "Rock_Quartzite_Brick",
      "rotation": 1
    },
    {
      "x": 4,
      "y": 2,
      "z": 6,
      "name": "Rock_Quartzite_Brick_Half",
      "rotation": 7
    },
    {
      "x": 4,
      "y": 3,
      "z": 6,
      "name": "Rock_Quartzite_Brick_Half",
      "rotation": 7
    },
    {
      "x": 5,
      "y": 0,
      "z": -1,
      "name": "Plant_Bush"
    },
    {
      "x": 5,
      "y": 0,
      "z": 2,
      "name": "Rock_Quartzite",
      "rotation": 1
    },
    {
      "x": 5,
      "y": 1,
      "z": 2,
      "name": "Rock_Quartzite_Brick",
      "rotation": 1
    },
    {
      "x": 5,
      "y": 2,
      "z": 2,
      "name": "Rock_Quartzite_Brick_Half",
      "rotation": 5
    },
    {
      "x": 5,
      "y": 3,
      "z": 2,
      "name": "Rock_Quartzite_Brick_Half",
      "rotation": 5
    },
    {
      "x": 5,
      "y": 4,
      "z": 2,
      "name": "Rock_Quartzite_Brick_Half",
      "rotation": 5
    },
    {
      "x": 5,
      "y": 5,
      "z": 2,
      "name": "Rock_Quartzite_Brick_Half",
      "rotation": 5
    },
    {
      "x": 5,
      "y": 6,
      "z": 2,
      "name": "Rock_Quartzite_Brick_Half",
      "rotation": 5
    },
    {
      "x": 5,
      "y": 7,
      "z": 2,
      "name": "Rock_Quartzite_Brick_Half",
      "rotation": 5
    },
    {
      "x": 5,
      "y": 8,
      "z": 2,
      "name": "Rock_Quartzite_Brick_Stairs",
      "rotation": 11
    },
    {
      "x": 5,
      "y": 9,
      "z": 2,
      "name": "Rock_Quartzite_Brick",
      "rotation": 1
    },
    {
      "x": 5,
      "y": 10,
      "z": 2,
      "name": "Rock_Stone_Brick_Smooth",
      "rotation": 1
    },
    {
      "x": 5,
      "y": 11,
      "z": 2,
      "name": "Rock_Stone_Brick_Smooth_Half",
      "rotation": 7
    },
    {
      "x": 5,
      "y": 0,
      "z": 3,
      "name": "Rock_Quartzite",
      "rotation": 1
    },
    {
      "x": 5,
      "y": 1,
      "z": 3,
      "name": "Rock_Quartzite_Brick",
      "rotation": 1
    },
    {
      "x": 5,
      "y": 2,
      "z": 3,
      "name": "Rock_Quartzite",
      "rotation": 1
    },
    {
      "x": 5,
      "y": 3,
      "z": 3,
      "name": "Rock_Quartzite",
      "rotation": 1
    },
    {
      "x": 5,
      "y": 4,
      "z": 3,
      "name": "Rock_Quartzite",
      "rotation": 1
    },
    {
      "x": 5,
      "y": 5,
      "z": 3,
      "name": "Rock_Quartzite",
      "rotation": 1
    },
    {
      "x": 5,
      "y": 6,
      "z": 3,
      "name": "Rock_Quartzite",
      "rotation": 1
    },
    {
      "x": 5,
      "y": 7,
      "z": 3,
      "name": "Rock_Quartzite",
      "rotation": 1
    },
    {
      "x": 5,
      "y": 8,
      "z": 3,
      "name": "Rock_Quartzite",
      "rotation": 1
    },
    {
      "x": 5,
      "y": 9,
      "z": 3,
      "name": "Soil_Grass",
      "rotation": 1
    },
    {
      "x": 5,
      "y": 0,
      "z": 4,
      "name": "Rock_Quartzite",
      "rotation": 1
    },
    {
      "x": 5,
      "y": 1,
      "z": 4,
      "name": "Rock_Quartzite_Brick",
      "rotation": 1
    },
    {
      "x": 5,
      "y": 2,
      "z": 4,
      "name": "Rock_Quartzite",
      "rotation": 1
    },
    {
      "x": 5,
      "y": 3,
      "z": 4,
      "name": "Rock_Quartzite",
      "rotation": 1
    },
    {
      "x": 5,
      "y": 4,
      "z": 4,
      "name": "Rock_Quartzite",
      "rotation": 1
    },
    {
      "x": 5,
      "y": 5,
      "z": 4,
      "name": "Rock_Quartzite",
      "rotation": 1
    },
    {
      "x": 5,
      "y": 6,
      "z": 4,
      "name": "Rock_Quartzite",
      "rotation": 1
    },
    {
      "x": 5,
      "y": 7,
      "z": 4,
      "name": "Rock_Quartzite",
      "rotation": 1
    },
    {
      "x": 5,
      "y": 8,
      "z": 4,
      "name": "Rock_Quartzite",
      "rotation": 1
    },
    {
      "x": 5,
      "y": 9,
      "z": 4,
      "name": "Soil_Grass",
      "rotation": 1
    },
    {
      "x": 5,
      "y": 0,
      "z": 5,
      "name": "Rock_Quartzite",
      "rotation": 1
    },
    {
      "x": 5,
      "y": 1,
      "z": 5,
      "name": "Rock_Quartzite_Brick",
      "rotation": 1
    },
    {
      "x": 5,
      "y": 2,
      "z": 5,
      "name": "Rock_Quartzite",
      "rotation": 1
    },
    {
      "x": 5,
      "y": 3,
      "z": 5,
      "name": "Rock_Quartzite",
      "rotation": 1
    },
    {
      "x": 5,
      "y": 4,
      "z": 5,
      "name": "Rock_Quartzite",
      "rotation": 1
    },
    {
      "x": 5,
      "y": 5,
      "z": 5,
      "name": "Rock_Quartzite",
      "rotation": 1
    },
    {
      "x": 5,
      "y": 6,
      "z": 5,
      "name": "Rock_Quartzite",
      "rotation": 1
    },
    {
      "x": 5,
      "y": 7,
      "z": 5,
      "name": "Rock_Quartzite",
      "rotation": 1
    },
    {
      "x": 5,
      "y": 8,
      "z": 5,
      "name": "Rock_Quartzite",
      "rotation": 1
    },
    {
      "x": 5,
      "y": 9,
      "z": 5,
      "name": "Soil_Grass",
      "rotation": 1
    },
    {
      "x": 5,
      "y": 0,
      "z": 6,
      "name": "Rock_Quartzite",
      "rotation": 1
    },
    {
      "x": 5,
      "y": 1,
      "z": 6,
      "name": "Rock_Quartzite_Brick",
      "rotation": 1
    },
    {
      "x": 5,
      "y": 2,
      "z": 6,
      "name": "Rock_Quartzite_Brick_Half",
      "rotation": 5
    },
    {
      "x": 5,
      "y": 3,
      "z": 6,
      "name": "Rock_Quartzite_Brick_Half",
      "rotation": 5
    },
    {
      "x": 5,
      "y": 4,
      "z": 6,
      "name": "Rock_Quartzite_Brick_Half",
      "rotation": 5
    },
    {
      "x": 5,
      "y": 5,
      "z": 6,
      "name": "Rock_Quartzite_Brick_Half",
      "rotation": 5
    },
    {
      "x": 5,
      "y": 6,
      "z": 6,
      "name": "Rock_Quartzite_Brick_Half",
      "rotation": 5
    },
    {
      "x": 5,
      "y": 7,
      "z": 6,
      "name": "Rock_Quartzite_Brick_Half",
      "rotation": 5
    },
    {
      "x": 5,
      "y": 8,
      "z": 6,
      "name": "Rock_Quartzite_Brick_Stairs",
      "rotation": 11
    },
    {
      "x": 5,
      "y": 9,
      "z": 6,
      "name": "Rock_Quartzite_Brick",
      "rotation": 1
    },
    {
      "x": 5,
      "y": 10,
      "z": 6,
      "name": "Rock_Stone_Brick_Smooth",
      "rotation": 1
    },
    {
      "x": 5,
      "y": 11,
      "z": 6,
      "name": "Rock_Stone_Brick_Smooth_Half",
      "rotation": 7
    },
    {
      "x": 6,
      "y": 0,
      "z": 0,
      "name": "Plant_Grass_Sharp_Tall"
    },
    {
      "x": 6,
      "y": 0,
      "z": 1,
      "name": "Plant_Grass_Sharp"
    },
    {
      "x": 6,
      "y": 0,
      "z": 2,
      "name": "Rock_Quartzite",
      "rotation": 1
    },
    {
      "x": 6,
      "y": 8,
      "z": 2,
      "name": "Rock_Quartzite_Brick_Half",
      "rotation": 9
    },
    {
      "x": 6,
      "y": 9,
      "z": 2,
      "name": "Rock_Quartzite_Brick",
      "rotation": 1
    },
    {
      "x": 6,
      "y": 10,
      "z": 2,
      "name": "Rock_Stone_Brick_Smooth",
      "rotation": 1
    },
    {
      "x": 6,
      "y": 11,
      "z": 2,
      "name": "Rock_Stone_Brick_Smooth_Half",
      "rotation": 9
    },
    {
      "x": 6,
      "y": 0,
      "z": 3,
      "name": "Rock_Quartzite",
      "rotation": 1
    },
    {
      "x": 6,
      "y": 1,
      "z": 3,
      "name": "Rock_Quartzite_Brick",
      "rotation": 1
    },
    {
      "x": 6,
      "y": 2,
      "z": 3,
      "name": "Rock_Quartzite",
      "rotation": 1
    },
    {
      "x": 6,
      "y": 3,
      "z": 3,
      "name": "Rock_Quartzite",
      "rotation": 1
    },
    {
      "x": 6,
      "y": 4,
      "z": 3,
      "name": "Rock_Quartzite",
      "rotation": 1
    },
    {
      "x": 6,
      "y": 5,
      "z": 3,
      "name": "Rock_Quartzite",
      "rotation": 1
    },
    {
      "x": 6,
      "y": 6,
      "z": 3,
      "name": "Rock_Quartzite_Cobble",
      "rotation": 1
    },
    {
      "x": 6,
      "y": 7,
      "z": 3,
      "name": "Rock_Quartzite",
      "rotation": 1
    },
    {
      "x": 6,
      "y": 8,
      "z": 3,
      "name": "Soil_Dirt",
      "rotation": 1
    },
    {
      "x": 6,
      "y": 9,
      "z": 3,
      "name": "Soil_Grass",
      "rotation": 1
    },
    {
      "x": 6,
      "y": 10,
      "z": 3,
      "name": "Plant_Grass_Lush_Short",
      "rotation": 1
    },
    {
      "x": 6,
      "y": 0,
      "z": 4,
      "name": "Rock_Quartzite",
      "rotation": 1
    },
    {
      "x": 6,
      "y": 1,
      "z": 4,
      "name": "Rock_Quartzite_Brick",
      "rotation": 1
    },
    {
      "x": 6,
      "y": 2,
      "z": 4,
      "name": "Rock_Quartzite",
      "rotation": 1
    },
    {
      "x": 6,
      "y": 3,
      "z": 4,
      "name": "Rock_Quartzite",
      "rotation": 1
    },
    {
      "x": 6,
      "y": 4,
      "z": 4,
      "name": "Rock_Quartzite",
      "rotation": 1
    },
    {
      "x": 6,
      "y": 5,
      "z": 4,
      "name": "Rock_Quartzite",
      "rotation": 1
    },
    {
      "x": 6,
      "y": 6,
      "z": 4,
      "name": "Rock_Quartzite_Cobble",
      "rotation": 1
    },
    {
      "x": 6,
      "y": 7,
      "z": 4,
      "name": "Rock_Quartzite_Cobble",
      "rotation": 1
    },
    {
      "x": 6,
      "y": 8,
      "z": 4,
      "name": "Rock_Quartzite",
      "rotation": 1
    },
    {
      "x": 6,
      "y": 9,
      "z": 4,
      "name": "Soil_Grass",
      "rotation": 1
    },
    {
      "x": 6,
      "y": 0,
      "z": 5,
      "name": "Rock_Quartzite",
      "rotation": 1
    },
    {
      "x": 6,
      "y": 1,
      "z": 5,
      "name": "Rock_Quartzite_Brick",
      "rotation": 1
    },
    {
      "x": 6,
      "y": 2,
      "z": 5,
      "name": "Rock_Quartzite",
      "rotation": 1
    },
    {
      "x": 6,
      "y": 3,
      "z": 5,
      "name": "Rock_Quartzite",
      "rotation": 1
    },
    {
      "x": 6,
      "y": 4,
      "z": 5,
      "name": "Rock_Quartzite",
      "rotation": 1
    },
