{
  "version": 8,
  "blockIdVersion": 11,
  "anchorX": 0,
  "anchorY": 0,
  "anchorZ": 0,
  "blocks": [
    {
      "x": -6,
      "y": 0,
      "z": -5,
      "name": "Wood_Deadwood_Planks",
      "rotation": 1
    },
    {
      "x": -6,
      "y": 1,
      "z": -5,
      "name": "Nat20_Force_Empty"
    },
    {
      "x": -6,
      "y": 2,
      "z": -5,
      "name": "Nat20_Force_Empty"
    },
    {
      "x": -6,
      "y": 3,
      "z": -5,
      "name": "Nat20_Force_Empty"
    },
    {
      "x": -6,
      "y": 4,
      "z": -5,
      "name": "Nat20_Force_Empty"
    },
    {
      "x": -6,
      "y": 5,
      "z": -5,
      "name": "Nat20_Force_Empty"
    },
    {
      "x": -6,
      "y": 6,
      "z": -5,
      "name": "Nat20_Force_Empty"
    },
    {
      "x": -6,
      "y": 7,
      "z": -5,
      "name": "Nat20_Force_Empty"
    },
    {
      "x": -6,
      "y": 8,
      "z": -5,
      "name": "Nat20_Force_Empty"
    },
    {
      "x": -6,
      "y": 9,
      "z": -5,
      "name": "Nat20_Force_Empty"
    },
    {
      "x": -6,
      "y": 10,
      "z": -5,
      "name": "Nat20_Force_Empty"
    },
    {
      "x": -6,
      "y": 0,
      "z": -4,
      "name": "Wood_Deadwood_Planks",
      "rotation": 1
    },
    {
      "x": -6,
      "y": 1,
      "z": -4,
      "name": "Wood_Redwood_Branch_Long",
      "rotation": 1
    },
    {
      "x": -6,
      "y": 2,
      "z": -4,
      "name": "Wood_Redwood_Branch_Long",
      "rotation": 1
    },
    {
      "x": -6,
      "y": 3,
      "z": -4,
      "name": "Wood_Deadwood_Roof_Flat",
      "rotation": 1
    },
    {
      "x": -6,
      "y": 4,
      "z": -4,
      "name": "Nat20_Force_Empty"
    },
    {
      "x": -6,
      "y": 5,
      "z": -4,
      "name": "Nat20_Force_Empty"
    },
    {
      "x": -6,
      "y": 6,
      "z": -4,
      "name": "Nat20_Force_Empty"
    },
    {
      "x": -6,
      "y": 7,
      "z": -4,
      "name": "Nat20_Force_Empty"
    },
    {
      "x": -6,
      "y": 8,
      "z": -4,
      "name": "Nat20_Force_Empty"
    },
    {
      "x": -6,
      "y": 9,
      "z": -4,
      "name": "Nat20_Force_Empty"
    },
    {
      "x": -6,
      "y": 10,
      "z": -4,
      "name": "Nat20_Force_Empty"
    },
    {
      "x": -6,
      "y": 0,
      "z": -3,
      "name": "Wood_Deadwood_Planks",
      "rotation": 1
    },
    {
      "x": -6,
      "y": 1,
      "z": -3,
      "name": "Nat20_Force_Empty",
      "rotation": 1
    },
    {
      "x": -6,
      "y": 2,
      "z": -3,
      "name": "Nat20_Force_Empty",
      "rotation": 1
    },
    {
      "x": -6,
      "y": 3,
      "z": -3,
      "name": "Wood_Deadwood_Roof_Flat",
      "rotation": 1
    },
    {
      "x": -6,
      "y": 4,
      "z": -3,
      "name": "Nat20_Force_Empty"
    },
    {
      "x": -6,
      "y": 5,
      "z": -3,
      "name": "Nat20_Force_Empty"
    },
    {
      "x": -6,
      "y": 6,
      "z": -3,
      "name": "Nat20_Force_Empty"
    },
    {
      "x": -6,
      "y": 7,
      "z": -3,
      "name": "Nat20_Force_Empty"
    },
    {
      "x": -6,
      "y": 8,
      "z": -3,
      "name": "Nat20_Force_Empty"
    },
    {
      "x": -6,
      "y": 9,
      "z": -3,
      "name": "Nat20_Force_Empty"
    },
    {
      "x": -6,
      "y": 10,
      "z": -3,
      "name": "Nat20_Force_Empty"
    },
    {
      "x": -6,
      "y": 0,
      "z": -2,
      "name": "Wood_Deadwood_Planks",
      "rotation": 1
    },
    {
      "x": -6,
      "y": 1,
      "z": -2,
      "name": "Wood_Redwood_Branch_Long",
      "rotation": 1
    },
    {
      "x": -6,
      "y": 2,
      "z": -2,
      "name": "Wood_Redwood_Branch_Long",
      "rotation": 1
    },
    {
      "x": -6,
      "y": 3,
      "z": -2,
      "name": "Wood_Redwood_Branch_Long",
      "rotation": 1
    },
    {
      "x": -6,
      "y": 4,
      "z": -2,
      "name": "Wood_Redwood_Trunk",
      "rotation": 5
    },
    {
      "x": -6,
      "y": 5,
      "z": -2,
      "name": "Nat20_Force_Empty"
    },
    {
      "x": -6,
      "y": 6,
      "z": -2,
      "name": "Nat20_Force_Empty"
    },
    {
      "x": -6,
      "y": 7,
      "z": -2,
      "name": "Nat20_Force_Empty"
    },
    {
      "x": -6,
      "y": 8,
      "z": -2,
      "name": "Nat20_Force_Empty"
    },
    {
      "x": -6,
      "y": 9,
      "z": -2,
      "name": "Nat20_Force_Empty"
    },
    {
      "x": -6,
      "y": 10,
      "z": -2,
      "name": "Nat20_Force_Empty"
    },
    {
      "x": -6,
      "y": 0,
      "z": -1,
      "name": "Wood_Deadwood_Planks",
      "rotation": 1
    },
    {
      "x": -6,
      "y": 1,
      "z": -1,
      "name": "Nat20_Force_Empty",
      "rotation": 1
    },
    {
      "x": -6,
      "y": 2,
      "z": -1,
      "name": "Nat20_Force_Empty",
      "rotation": 1
    },
    {
      "x": -6,
      "y": 3,
      "z": -1,
      "name": "Nat20_Force_Empty",
      "rotation": 1
    },
    {
      "x": -6,
      "y": 4,
      "z": -1,
      "name": "Nat20_Force_Empty",
      "rotation": 1
    },
    {
      "x": -6,
      "y": 5,
      "z": -1,
      "name": "Nat20_Force_Empty"
    },
    {
      "x": -6,
      "y": 6,
      "z": -1,
      "name": "Nat20_Force_Empty"
    },
    {
      "x": -6,
      "y": 7,
      "z": -1,
      "name": "Nat20_Force_Empty"
    },
    {
      "x": -6,
      "y": 8,
      "z": -1,
      "name": "Nat20_Force_Empty"
    },
    {
      "x": -6,
      "y": 9,
      "z": -1,
      "name": "Nat20_Force_Empty"
    },
    {
      "x": -6,
      "y": 10,
      "z": -1,
      "name": "Nat20_Force_Empty"
    },
    {
      "x": -6,
      "y": 0,
      "z": 0,
      "name": "Wood_Deadwood_Planks",
      "rotation": 1
    },
    {
      "x": -6,
      "y": 1,
      "z": 0,
      "name": "Nat20_Direction"
    },
    {
      "x": -6,
      "y": 2,
      "z": 0,
      "name": "Nat20_Force_Empty",
      "rotation": 1
    },
    {
      "x": -6,
      "y": 3,
      "z": 0,
      "name": "Nat20_Force_Empty",
      "rotation": 1
    },
    {
      "x": -6,
      "y": 4,
      "z": 0,
      "name": "Nat20_Force_Empty",
      "rotation": 1
    },
    {
      "x": -6,
      "y": 5,
      "z": 0,
      "name": "Nat20_Force_Empty",
      "rotation": 1
    },
    {
      "x": -6,
      "y": 6,
      "z": 0,
      "name": "Nat20_Force_Empty"
    },
    {
      "x": -6,
      "y": 7,
      "z": 0,
      "name": "Nat20_Force_Empty"
    },
    {
      "x": -6,
      "y": 8,
      "z": 0,
      "name": "Nat20_Force_Empty"
    },
    {
      "x": -6,
      "y": 9,
      "z": 0,
      "name": "Nat20_Force_Empty"
    },
    {
      "x": -6,
      "y": 10,
      "z": 0,
      "name": "Nat20_Force_Empty"
    },
    {
      "x": -6,
      "y": 0,
      "z": 1,
      "name": "Wood_Deadwood_Planks",
      "rotation": 1
    },
    {
      "x": -6,
      "y": 1,
      "z": 1,
      "name": "Nat20_Force_Empty",
      "rotation": 1
    },
    {
      "x": -6,
      "y": 2,
      "z": 1,
      "name": "Nat20_Force_Empty",
      "rotation": 1
    },
    {
      "x": -6,
      "y": 3,
      "z": 1,
      "name": "Nat20_Force_Empty",
      "rotation": 1
    },
    {
      "x": -6,
      "y": 4,
      "z": 1,
      "name": "Nat20_Force_Empty",
      "rotation": 1
    },
    {
      "x": -6,
      "y": 5,
      "z": 1,
      "name": "Nat20_Force_Empty",
      "rotation": 1
    },
    {
      "x": -6,
      "y": 6,
      "z": 1,
      "name": "Wood_Redwood_Stairs",
      "rotation": 9
    },
    {
      "x": -6,
      "y": 7,
      "z": 1,
      "name": "Wood_Redwood_Trunk",
      "rotation": 5
    },
    {
      "x": -6,
      "y": 8,
      "z": 1,
      "name": "Nat20_Force_Empty"
    },
    {
      "x": -6,
      "y": 9,
      "z": 1,
      "name": "Nat20_Force_Empty"
    },
    {
      "x": -6,
      "y": 10,
      "z": 1,
      "name": "Nat20_Force_Empty"
    },
    {
      "x": -6,
      "y": 0,
      "z": 2,
      "name": "Wood_Deadwood_Planks",
      "rotation": 1
    },
    {
      "x": -6,
      "y": 1,
      "z": 2,
      "name": "Nat20_Force_Empty",
      "rotation": 1
    },
    {
      "x": -6,
      "y": 2,
      "z": 2,
      "name": "Nat20_Force_Empty",
      "rotation": 1
    },
    {
      "x": -6,
      "y": 3,
      "z": 2,
      "name": "Nat20_Force_Empty",
      "rotation": 1
    },
    {
      "x": -6,
      "y": 4,
      "z": 2,
      "name": "Nat20_Force_Empty",
      "rotation": 1
    },
    {
      "x": -6,
      "y": 5,
      "z": 2,
      "name": "Nat20_Force_Empty",
      "rotation": 1
    },
    {
      "x": -6,
      "y": 6,
      "z": 2,
      "name": "Nat20_Force_Empty"
    },
    {
      "x": -6,
      "y": 7,
      "z": 2,
      "name": "Nat20_Force_Empty"
    },
    {
      "x": -6,
      "y": 8,
      "z": 2,
      "name": "Nat20_Force_Empty"
    },
    {
      "x": -6,
      "y": 9,
      "z": 2,
      "name": "Nat20_Force_Empty"
    },
    {
      "x": -6,
      "y": 10,
      "z": 2,
      "name": "Nat20_Force_Empty"
    },
    {
      "x": -6,
      "y": 0,
      "z": 3,
      "name": "Wood_Deadwood_Planks",
      "rotation": 1
    },
    {
      "x": -6,
      "y": 1,
      "z": 3,
      "name": "Nat20_Force_Empty"
    },
    {
      "x": -6,
      "y": 2,
      "z": 3,
      "name": "Nat20_Force_Empty",
      "rotation": 1
    },
    {
      "x": -6,
      "y": 3,
      "z": 3,
      "name": "Nat20_Force_Empty",
      "rotation": 1
    },
    {
      "x": -6,
      "y": 4,
      "z": 3,
      "name": "Nat20_Force_Empty",
      "rotation": 1
    },
    {
      "x": -6,
      "y": 5,
      "z": 3,
      "name": "Nat20_Force_Empty"
    },
    {
      "x": -6,
      "y": 6,
      "z": 3,
      "name": "Nat20_Force_Empty"
    },
    {
      "x": -6,
      "y": 7,
      "z": 3,
      "name": "Nat20_Force_Empty"
    },
    {
      "x": -6,
      "y": 8,
      "z": 3,
      "name": "Nat20_Force_Empty"
    },
    {
      "x": -6,
      "y": 9,
      "z": 3,
      "name": "Nat20_Force_Empty"
    },
    {
      "x": -6,
      "y": 10,
      "z": 3,
      "name": "Nat20_Force_Empty"
    },
    {
      "x": -6,
      "y": 0,
      "z": 4,
      "name": "Wood_Deadwood_Planks",
      "rotation": 1
    },
    {
      "x": -6,
      "y": 1,
      "z": 4,
      "name": "Nat20_Force_Empty"
    },
    {
      "x": -6,
      "y": 2,
      "z": 4,
      "name": "Nat20_Force_Empty"
    },
    {
      "x": -6,
      "y": 3,
      "z": 4,
      "name": "Nat20_Force_Empty"
    },
    {
      "x": -6,
      "y": 4,
      "z": 4,
      "name": "Wood_Redwood_Trunk",
      "rotation": 5
    },
    {
      "x": -6,
      "y": 5,
      "z": 4,
      "name": "Nat20_Force_Empty"
    },
    {
      "x": -6,
      "y": 6,
      "z": 4,
      "name": "Nat20_Force_Empty"
    },
    {
      "x": -6,
      "y": 7,
      "z": 4,
      "name": "Nat20_Force_Empty"
    },
    {
      "x": -6,
      "y": 8,
      "z": 4,
      "name": "Nat20_Force_Empty"
    },
    {
      "x": -6,
      "y": 9,
      "z": 4,
      "name": "Nat20_Force_Empty"
    },
    {
      "x": -6,
      "y": 10,
      "z": 4,
      "name": "Nat20_Force_Empty"
    },
    {
      "x": -6,
      "y": 0,
      "z": 5,
      "name": "Wood_Deadwood_Planks",
      "rotation": 1
    },
    {
      "x": -6,
      "y": 1,
      "z": 5,
      "name": "Nat20_Force_Empty"
    },
    {
      "x": -6,
      "y": 2,
      "z": 5,
      "name": "Nat20_Force_Empty"
    },
    {
      "x": -6,
      "y": 3,
      "z": 5,
      "name": "Nat20_Force_Empty"
    },
    {
      "x": -6,
      "y": 4,
      "z": 5,
      "name": "Nat20_Force_Empty"
    },
    {
      "x": -6,
      "y": 5,
      "z": 5,
      "name": "Nat20_Force_Empty"
    },
    {
      "x": -6,
      "y": 6,
      "z": 5,
      "name": "Nat20_Force_Empty"
    },
    {
      "x": -6,
      "y": 7,
      "z": 5,
      "name": "Nat20_Force_Empty"
    },
    {
      "x": -6,
      "y": 8,
      "z": 5,
      "name": "Nat20_Force_Empty"
    },
    {
      "x": -6,
      "y": 9,
      "z": 5,
      "name": "Nat20_Force_Empty"
    },
    {
      "x": -6,
      "y": 10,
      "z": 5,
      "name": "Nat20_Force_Empty"
    },
    {
      "x": -6,
      "y": 0,
      "z": 6,
      "name": "Wood_Deadwood_Planks",
      "rotation": 1
    },
    {
      "x": -6,
      "y": 1,
      "z": 6,
      "name": "Nat20_Force_Empty"
    },
    {
      "x": -6,
      "y": 2,
      "z": 6,
      "name": "Nat20_Force_Empty"
    },
    {
      "x": -6,
      "y": 3,
      "z": 6,
      "name": "Nat20_Force_Empty"
    },
    {
      "x": -6,
      "y": 4,
      "z": 6,
      "name": "Nat20_Force_Empty"
    },
    {
      "x": -6,
      "y": 5,
      "z": 6,
      "name": "Nat20_Force_Empty"
    },
    {
      "x": -6,
      "y": 6,
      "z": 6,
      "name": "Nat20_Force_Empty"
    },
    {
      "x": -6,
      "y": 7,
      "z": 6,
      "name": "Nat20_Force_Empty"
    },
    {
      "x": -6,
      "y": 8,
      "z": 6,
      "name": "Nat20_Force_Empty"
    },
    {
      "x": -6,
      "y": 9,
      "z": 6,
      "name": "Nat20_Force_Empty"
    },
    {
      "x": -6,
      "y": 10,
      "z": 6,
      "name": "Nat20_Force_Empty"
    },
    {
      "x": -5,
      "y": 0,
      "z": -5,
      "name": "Wood_Deadwood_Planks",
      "rotation": 1
    },
    {
      "x": -5,
      "y": 1,
      "z": -5,
      "name": "Wood_Redwood_Trunk",
      "rotation": 5
    },
    {
      "x": -5,
      "y": 2,
      "z": -5,
      "name": "Wood_Deadwood_Roof",
      "rotation": 2
    },
    {
      "x": -5,
      "y": 3,
      "z": -5,
      "name": "Nat20_Force_Empty"
    },
    {
      "x": -5,
      "y": 4,
      "z": -5,
      "name": "Nat20_Force_Empty"
    },
    {
      "x": -5,
      "y": 5,
      "z": -5,
      "name": "Nat20_Force_Empty"
    },
    {
      "x": -5,
      "y": 6,
      "z": -5,
      "name": "Nat20_Force_Empty"
    },
    {
      "x": -5,
      "y": 7,
      "z": -5,
      "name": "Nat20_Force_Empty"
    },
    {
      "x": -5,
      "y": 8,
      "z": -5,
      "name": "Nat20_Force_Empty"
    },
    {
      "x": -5,
      "y": 9,
      "z": -5,
      "name": "Nat20_Force_Empty"
    },
    {
      "x": -5,
      "y": 10,
      "z": -5,
      "name": "Nat20_Force_Empty"
    },
    {
      "x": -5,
      "y": 0,
      "z": -4,
      "name": "Wood_Deadwood_Planks",
      "rotation": 1
    },
    {
      "x": -5,
      "y": 1,
      "z": -4,
      "name": "Wood_Redwood_Stairs",
      "rotation": 10
    },
    {
      "x": -5,
      "y": 2,
      "z": -4,
      "name": "Wood_Redwood_Planks",
      "rotation": 1
    },
    {
      "x": -5,
      "y": 3,
      "z": -4,
      "name": "Wood_Deadwood_Roof",
      "rotation": 2
    },
    {
      "x": -5,
      "y": 4,
      "z": -4,
      "name": "Nat20_Force_Empty"
    },
    {
      "x": -5,
      "y": 5,
      "z": -4,
      "name": "Nat20_Force_Empty"
    },
    {
      "x": -5,
      "y": 6,
      "z": -4,
      "name": "Nat20_Force_Empty"
    },
    {
      "x": -5,
      "y": 7,
      "z": -4,
      "name": "Nat20_Force_Empty"
    },
    {
      "x": -5,
      "y": 8,
      "z": -4,
      "name": "Nat20_Force_Empty"
    },
    {
      "x": -5,
      "y": 9,
      "z": -4,
      "name": "Nat20_Force_Empty"
    },
    {
      "x": -5,
      "y": 10,
      "z": -4,
      "name": "Nat20_Force_Empty"
    },
    {
      "x": -5,
      "y": 0,
      "z": -3,
      "name": "Wood_Deadwood_Planks",
      "rotation": 1
    },
    {
      "x": -5,
      "y": 1,
      "z": -3,
      "name": "Nat20_Force_Empty",
      "rotation": 1
    },
    {
      "x": -5,
      "y": 2,
      "z": -3,
      "name": "Nat20_Force_Empty",
      "rotation": 1
    },
    {
      "x": -5,
      "y": 3,
      "z": -3,
      "name": "Wood_Redwood_Stairs",
      "rotation": 2
    },
    {
      "x": -5,
      "y": 4,
      "z": -3,
      "name": "Nat20_Force_Empty"
    },
    {
      "x": -5,
      "y": 5,
      "z": -3,
      "name": "Nat20_Force_Empty"
    },
    {
      "x": -5,
      "y": 6,
      "z": -3,
      "name": "Nat20_Force_Empty"
    },
    {
      "x": -5,
      "y": 7,
      "z": -3,
      "name": "Nat20_Force_Empty"
    },
    {
      "x": -5,
      "y": 8,
      "z": -3,
      "name": "Nat20_Force_Empty"
    },
    {
      "x": -5,
      "y": 9,
      "z": -3,
      "name": "Nat20_Force_Empty"
    },
    {
      "x": -5,
      "y": 10,
      "z": -3,
      "name": "Nat20_Force_Empty"
    },
    {
      "x": -5,
      "y": 0,
      "z": -2,
      "name": "Wood_Deadwood_Planks",
      "rotation": 1
    },
    {
      "x": -5,
      "y": 1,
      "z": -2,
      "name": "Nat20_Force_Empty",
      "rotation": 1
    },
    {
      "x": -5,
      "y": 2,
      "z": -2,
      "name": "Nat20_Force_Empty",
      "rotation": 1
    },
    {
      "x": -5,
      "y": 3,
      "z": -2,
      "name": "Wood_Redwood_Stairs",
      "rotation": 10
    },
    {
      "x": -5,
      "y": 4,
      "z": -2,
      "name": "Wood_Redwood_Trunk",
      "rotation": 5
    },
    {
      "x": -5,
      "y": 5,
      "z": -2,
      "name": "Wood_Deadwood_Roof",
      "rotation": 2
    },
    {
      "x": -5,
      "y": 6,
      "z": -2,
      "name": "Nat20_Force_Empty"
    },
    {
      "x": -5,
      "y": 7,
      "z": -2,
      "name": "Nat20_Force_Empty"
    },
    {
      "x": -5,
      "y": 8,
      "z": -2,
      "name": "Nat20_Force_Empty"
    },
    {
      "x": -5,
      "y": 9,
      "z": -2,
      "name": "Nat20_Force_Empty"
    },
    {
      "x": -5,
      "y": 10,
      "z": -2,
      "name": "Nat20_Force_Empty"
    },
    {
      "x": -5,
      "y": 0,
      "z": -1,
      "name": "Wood_Deadwood_Planks",
      "rotation": 1
    },
    {
      "x": -5,
      "y": 1,
      "z": -1,
      "name": "Nat20_Force_Empty",
      "rotation": 1
    },
    {
      "x": -5,
      "y": 2,
      "z": -1,
      "name": "Nat20_Force_Empty",
      "rotation": 1
    },
    {
      "x": -5,
      "y": 3,
      "z": -1,
      "name": "Nat20_Force_Empty",
      "rotation": 1
    },
    {
      "x": -5,
      "y": 4,
      "z": -1,
      "name": "Wood_Redwood_Stairs",
      "rotation": 10
    },
    {
      "x": -5,
      "y": 5,
      "z": -1,
      "name": "Wood_Redwood_Stairs",
      "rotation": 2
    },
    {
      "x": -5,
      "y": 6,
      "z": -1,
      "name": "Nat20_Force_Empty"
    },
    {
      "x": -5,
      "y": 7,
      "z": -1,
      "name": "Nat20_Force_Empty"
    },
    {
      "x": -5,
      "y": 8,
      "z": -1,
      "name": "Nat20_Force_Empty"
    },
    {
      "x": -5,
      "y": 9,
      "z": -1,
      "name": "Nat20_Force_Empty"
    },
    {
      "x": -5,
      "y": 10,
      "z": -1,
      "name": "Nat20_Force_Empty"
    },
    {
      "x": -5,
      "y": 0,
      "z": 0,
      "name": "Wood_Deadwood_Planks",
      "rotation": 1
    },
    {
      "x": -5,
      "y": 1,
      "z": 0,
      "name": "Nat20_Anchor"
    },
    {
      "x": -5,
      "y": 2,
      "z": 0,
      "name": "Nat20_Force_Empty",
      "rotation": 1
    },
    {
      "x": -5,
      "y": 3,
      "z": 0,
      "name": "Nat20_Force_Empty",
      "rotation": 1
    },
    {
      "x": -5,
      "y": 4,
      "z": 0,
      "name": "Nat20_Force_Empty",
      "rotation": 1
    },
    {
      "x": -5,
      "y": 5,
      "z": 0,
      "name": "Wood_Redwood_Stairs",
      "rotation": 10
    },
    {
      "x": -5,
      "y": 6,
      "z": 0,
      "name": "Wood_Redwood_Stairs",
      "rotation": 2
    },
    {
      "x": -5,
      "y": 7,
      "z": 0,
      "name": "Nat20_Force_Empty"
    },
    {
      "x": -5,
      "y": 8,
      "z": 0,
      "name": "Nat20_Force_Empty"
    },
    {
      "x": -5,
      "y": 9,
      "z": 0,
      "name": "Nat20_Force_Empty"
    },
    {
      "x": -5,
      "y": 10,
      "z": 0,
      "name": "Nat20_Force_Empty"
    },
    {
      "x": -5,
      "y": 0,
      "z": 1,
      "name": "Wood_Deadwood_Planks",
      "rotation": 1
    },
    {
      "x": -5,
      "y": 1,
      "z": 1,
      "name": "Nat20_Force_Empty",
      "rotation": 1
    },
    {
      "x": -5,
      "y": 2,
      "z": 1,
      "name": "Wood_Torch_Wall",
      "rotation": 3
    },
    {
      "x": -5,
      "y": 3,
      "z": 1,
      "name": "Nat20_Force_Empty",
      "rotation": 1
    },
    {
      "x": -5,
      "y": 4,
      "z": 1,
      "name": "Nat20_Force_Empty",
      "rotation": 1
    },
    {
      "x": -5,
      "y": 5,
      "z": 1,
      "name": "Nat20_Force_Empty",
      "rotation": 1
    },
    {
      "x": -5,
      "y": 6,
      "z": 1,
      "name": "Wood_Redwood_Planks",
      "rotation": 1
    },
    {
      "x": -5,
      "y": 7,
      "z": 1,
      "name": "Wood_Redwood_Trunk",
      "rotation": 5
    },
    {
      "x": -5,
      "y": 8,
      "z": 1,
      "name": "Nat20_Force_Empty"
    },
    {
      "x": -5,
      "y": 9,
      "z": 1,
      "name": "Nat20_Force_Empty"
    },
    {
      "x": -5,
      "y": 10,
      "z": 1,
      "name": "Nat20_Force_Empty"
    },
    {
      "x": -5,
      "y": 0,
      "z": 2,
      "name": "Wood_Deadwood_Planks",
      "rotation": 1
    },
    {
      "x": -5,
      "y": 1,
      "z": 2,
      "name": "Nat20_Force_Empty",
      "rotation": 1
    },
    {
      "x": -5,
      "y": 2,
      "z": 2,
      "name": "Nat20_Force_Empty",
      "rotation": 1
    },
    {
      "x": -5,
      "y": 3,
      "z": 2,
      "name": "Nat20_Force_Empty",
      "rotation": 1
    },
    {
      "x": -5,
      "y": 4,
      "z": 2,
      "name": "Nat20_Force_Empty",
      "rotation": 1
    },
    {
      "x": -5,
      "y": 5,
      "z": 2,
      "name": "Wood_Redwood_Stairs",
      "rotation": 8
    },
    {
      "x": -5,
      "y": 6,
      "z": 2,
      "name": "Wood_Redwood_Stairs"
    },
    {
      "x": -5,
      "y": 7,
      "z": 2,
      "name": "Nat20_Force_Empty"
    },
    {
      "x": -5,
      "y": 8,
      "z": 2,
      "name": "Nat20_Force_Empty"
    },
    {
      "x": -5,
      "y": 9,
      "z": 2,
      "name": "Nat20_Force_Empty"
    },
    {
      "x": -5,
      "y": 10,
      "z": 2,
      "name": "Nat20_Force_Empty"
    },
    {
      "x": -5,
      "y": 0,
      "z": 3,
      "name": "Wood_Deadwood_Planks",
      "rotation": 1
    },
    {
      "x": -5,
      "y": 1,
      "z": 3,
      "name": "Nat20_Force_Empty",
      "rotation": 1
    },
    {
      "x": -5,
      "y": 2,
      "z": 3,
      "name": "Nat20_Force_Empty",
      "rotation": 1
    },
    {
      "x": -5,
      "y": 3,
      "z": 3,
      "name": "Nat20_Force_Empty",
      "rotation": 1
    },
    {
      "x": -5,
      "y": 4,
      "z": 3,
      "name": "Wood_Redwood_Stairs",
      "rotation": 8
    },
    {
      "x": -5,
      "y": 5,
      "z": 3,
      "name": "Wood_Redwood_Planks",
      "rotation": 1
    },
    {
      "x": -5,
      "y": 6,
      "z": 3,
      "name": "Wood_Deadwood_Roof"
    },
    {
      "x": -5,
      "y": 7,
      "z": 3,
      "name": "Nat20_Force_Empty"
    },
    {
      "x": -5,
      "y": 8,
      "z": 3,
      "name": "Nat20_Force_Empty"
    },
    {
      "x": -5,
      "y": 9,
      "z": 3,
      "name": "Nat20_Force_Empty"
    },
    {
      "x": -5,
      "y": 10,
      "z": 3,
      "name": "Nat20_Force_Empty"
    },
    {
      "x": -5,
      "y": 0,
      "z": 4,
      "name": "Wood_Deadwood_Planks",
      "rotation": 1
    },
    {
      "x": -5,
      "y": 1,
      "z": 4,
      "name": "Nat20_Force_Empty"
    },
    {
      "x": -5,
      "y": 2,
      "z": 4,
      "name": "Nat20_Force_Empty"
    },
    {
      "x": -5,
      "y": 3,
      "z": 4,
      "name": "Wood_Redwood_Stairs",
      "rotation": 9
    },
    {
      "x": -5,
      "y": 4,
      "z": 4,
      "name": "Wood_Redwood_Trunk",
      "rotation": 5
    },
    {
      "x": -5,
      "y": 5,
      "z": 4,
      "name": "Wood_Deadwood_Roof"
    },
    {
      "x": -5,
      "y": 6,
      "z": 4,
      "name": "Nat20_Force_Empty"
    },
    {
      "x": -5,
      "y": 7,
      "z": 4,
      "name": "Nat20_Force_Empty"
    },
    {
      "x": -5,
      "y": 8,
      "z": 4,
      "name": "Nat20_Force_Empty"
    },
    {
      "x": -5,
      "y": 9,
      "z": 4,
      "name": "Nat20_Force_Empty"
    },
    {
      "x": -5,
      "y": 10,
      "z": 4,
      "name": "Nat20_Force_Empty"
    },
    {
      "x": -5,
      "y": 0,
      "z": 5,
      "name": "Wood_Deadwood_Planks",
      "rotation": 1
    },
    {
      "x": -5,
      "y": 1,
      "z": 5,
      "name": "Nat20_Force_Empty"
    },
    {
      "x": -5,
      "y": 2,
      "z": 5,
      "name": "Nat20_Force_Empty"
    },
    {
      "x": -5,
      "y": 3,
      "z": 5,
      "name": "Nat20_Force_Empty"
    },
    {
      "x": -5,
      "y": 4,
      "z": 5,
      "name": "Nat20_Force_Empty"
    },
    {
      "x": -5,
      "y": 5,
      "z": 5,
      "name": "Nat20_Force_Empty"
    },
    {
      "x": -5,
      "y": 6,
      "z": 5,
      "name": "Nat20_Force_Empty"
    },
    {
      "x": -5,
      "y": 7,
      "z": 5,
      "name": "Nat20_Force_Empty"
    },
    {
      "x": -5,
      "y": 8,
      "z": 5,
      "name": "Nat20_Force_Empty"
    },
    {
      "x": -5,
      "y": 9,
      "z": 5,
      "name": "Nat20_Force_Empty"
    },
    {
      "x": -5,
      "y": 10,
      "z": 5,
      "name": "Nat20_Force_Empty"
    },
    {
      "x": -5,
      "y": 0,
      "z": 6,
      "name": "Wood_Deadwood_Planks",
      "rotation": 1
    },
    {
      "x": -5,
      "y": 1,
      "z": 6,
      "name": "Nat20_Force_Empty"
    },
    {
      "x": -5,
      "y": 2,
      "z": 6,
      "name": "Nat20_Force_Empty"
    },
    {
      "x": -5,
      "y": 3,
      "z": 6,
      "name": "Nat20_Force_Empty"
    },
    {
      "x": -5,
      "y": 4,
      "z": 6,
      "name": "Nat20_Force_Empty"
    },
    {
      "x": -5,
      "y": 5,
      "z": 6,
      "name": "Nat20_Force_Empty"
    },
    {
      "x": -5,
      "y": 6,
      "z": 6,
      "name": "Nat20_Force_Empty"
    },
    {
      "x": -5,
      "y": 7,
      "z": 6,
      "name": "Nat20_Force_Empty"
    },
    {
      "x": -5,
      "y": 8,
      "z": 6,
      "name": "Nat20_Force_Empty"
    },
    {
      "x": -5,
      "y": 9,
      "z": 6,
      "name": "Nat20_Force_Empty"
    },
    {
      "x": -5,
      "y": 10,
      "z": 6,
      "name": "Nat20_Force_Empty"
    },
    {
      "x": -4,
      "y": 0,
      "z": -5,
      "name": "Wood_Deadwood_Planks",
      "rotation": 1
    },
    {
      "x": -4,
      "y": 1,
      "z": -5,
      "name": "Wood_Redwood_Trunk",
      "rotation": 5
    },
    {
      "x": -4,
      "y": 2,
      "z": -5,
      "name": "Wood_Deadwood_Roof",
      "rotation": 2
    },
    {
      "x": -4,
      "y": 3,
      "z": -5,
      "name": "Nat20_Force_Empty"
    },
    {
      "x": -4,
      "y": 4,
      "z": -5,
      "name": "Nat20_Force_Empty"
    },
    {
      "x": -4,
      "y": 5,
      "z": -5,
      "name": "Nat20_Force_Empty"
    },
    {
      "x": -4,
      "y": 6,
      "z": -5,
      "name": "Nat20_Force_Empty"
    },
    {
      "x": -4,
      "y": 7,
      "z": -5,
      "name": "Nat20_Force_Empty"
    },
    {
      "x": -4,
      "y": 8,
      "z": -5,
      "name": "Nat20_Force_Empty"
    },
    {
      "x": -4,
      "y": 9,
      "z": -5,
      "name": "Nat20_Force_Empty"
    },
    {
      "x": -4,
      "y": 10,
      "z": -5,
      "name": "Nat20_Force_Empty"
    },
    {
      "x": -4,
      "y": 0,
      "z": -4,
      "name": "Wood_Deadwood_Planks",
      "rotation": 1
    },
    {
      "x": -4,
      "y": 1,
      "z": -4,
      "name": "Furniture_Ancient_Barrel",
      "rotation": 1
    },
    {
      "x": -4,
      "y": 2,
      "z": -4,
      "name": "Wood_Redwood_Planks",
      "rotation": 1
    },
    {
      "x": -4,
      "y": 3,
      "z": -4,
      "name": "Wood_Deadwood_Roof",
      "rotation": 2
    },
    {
      "x": -4,
      "y": 4,
      "z": -4,
      "name": "Nat20_Force_Empty"
    },
    {
      "x": -4,
      "y": 5,
      "z": -4,
      "name": "Nat20_Force_Empty"
    },
    {
      "x": -4,
      "y": 6,
      "z": -4,
      "name": "Nat20_Force_Empty"
    },
    {
      "x": -4,
      "y": 7,
      "z": -4,
      "name": "Nat20_Force_Empty"
    },
    {
      "x": -4,
      "y": 8,
      "z": -4,
      "name": "Nat20_Force_Empty"
    },
    {
      "x": -4,
      "y": 9,
      "z": -4,
      "name": "Nat20_Force_Empty"
    },
    {
      "x": -4,
      "y": 10,
      "z": -4,
      "name": "Nat20_Force_Empty"
    },
    {
      "x": -4,
      "y": 0,
      "z": -3,
      "name": "Wood_Deadwood_Planks",
      "rotation": 1
    },
    {
      "x": -4,
      "y": 1,
      "z": -3,
      "name": "Nat20_Force_Empty",
      "rotation": 1
    },
    {
      "x": -4,
      "y": 2,
      "z": -3,
      "name": "Nat20_Force_Empty",
      "rotation": 1
    },
    {
      "x": -4,
      "y": 3,
      "z": -3,
      "name": "Wood_Redwood_Planks",
      "rotation": 1
    },
    {
      "x": -4,
      "y": 4,
      "z": -3,
      "name": "Wood_Deadwood_Roof",
      "rotation": 2
    },
    {
      "x": -4,
      "y": 5,
      "z": -3,
      "name": "Nat20_Force_Empty"
    },
    {
      "x": -4,
      "y": 6,
      "z": -3,
      "name": "Nat20_Force_Empty"
    },
    {
      "x": -4,
      "y": 7,
      "z": -3,
      "name": "Nat20_Force_Empty"
    },
    {
      "x": -4,
      "y": 8,
      "z": -3,
      "name": "Nat20_Force_Empty"
    },
    {
      "x": -4,
      "y": 9,
      "z": -3,
      "name": "Nat20_Force_Empty"
    },
    {
      "x": -4,
      "y": 10,
      "z": -3,
      "name": "Nat20_Force_Empty"
    },
    {
      "x": -4,
      "y": 0,
      "z": -2,
      "name": "Wood_Deadwood_Planks",
      "rotation": 1
    },
    {
      "x": -4,
      "y": 1,
      "z": -2,
      "name": "Rock_Shale_Brick_Half",
      "rotation": 6
    },
    {
      "x": -4,
      "y": 2,
      "z": -2,
      "name": "Rock_Shale_Brick_Half",
      "rotation": 6
    },
    {
      "x": -4,
      "y": 3,
      "z": -2,
      "name": "Rock_Shale_Brick",
      "rotation": 1
    },
    {
      "x": -4,
      "y": 4,
      "z": -2,
      "name": "Wood_Redwood_Trunk",
      "rotation": 5
    },
    {
      "x": -4,
      "y": 5,
      "z": -2,
      "name": "Wood_Deadwood_Roof",
      "rotation": 2
    },
    {
      "x": -4,
      "y": 6,
      "z": -2,
      "name": "Nat20_Force_Empty"
    },
    {
      "x": -4,
      "y": 7,
      "z": -2,
      "name": "Nat20_Force_Empty"
    },
    {
      "x": -4,
      "y": 8,
      "z": -2,
      "name": "Nat20_Force_Empty"
    },
    {
      "x": -4,
      "y": 9,
      "z": -2,
      "name": "Nat20_Force_Empty"
    },
    {
      "x": -4,
      "y": 10,
      "z": -2,
      "name": "Nat20_Force_Empty"
    },
    {
      "x": -4,
      "y": 0,
      "z": -1,
      "name": "Wood_Deadwood_Planks",
      "rotation": 1
    },
    {
      "x": -4,
      "y": 1,
      "z": -1,
      "name": "Rock_Shale_Brick",
      "rotation": 1
    },
    {
      "x": -4,
      "y": 2,
      "z": -1,
      "name": "Rock_Shale_Brick",
      "rotation": 1
    },
    {
      "x": -4,
      "y": 3,
      "z": -1,
      "name": "Rock_Shale_Brick",
      "rotation": 1
    },
    {
      "x": -4,
      "y": 4,
      "z": -1,
      "name": "Wood_Redwood_Trunk",
      "rotation": 6
    },
    {
      "x": -4,
      "y": 5,
      "z": -1,
      "name": "Wood_Redwood_Planks",
      "rotation": 1
    },
    {
      "x": -4,
      "y": 6,
      "z": -1,
      "name": "Wood_Deadwood_Roof",
      "rotation": 2
    },
    {
      "x": -4,
      "y": 7,
      "z": -1,
      "name": "Nat20_Force_Empty"
    },
    {
      "x": -4,
      "y": 8,
      "z": -1,
      "name": "Nat20_Force_Empty"
    },
    {
      "x": -4,
      "y": 9,
      "z": -1,
      "name": "Nat20_Force_Empty"
    },
    {
      "x": -4,
      "y": 10,
      "z": -1,
      "name": "Nat20_Force_Empty"
    },
    {
      "x": -4,
      "y": 0,
      "z": 0,
      "name": "Wood_Deadwood_Planks",
      "rotation": 1
    },
    {
      "x": -4,
      "y": 1,
      "z": 0,
      "name": "Furniture_Lumberjack_Door",
      "rotation": 3
    },
    {
      "x": -4,
      "y": 2,
      "z": 0,
      "name": "Furniture_Lumberjack_Door",
      "filler": 1024,
      "rotation": 3
    },
    {
      "x": -4,
      "y": 3,
      "z": 0,
      "name": "Rock_Shale_Brick",
      "rotation": 1
    },
    {
      "x": -4,
      "y": 4,
      "z": 0,
      "name": "Wood_Redwood_Trunk",
      "rotation": 6
    },
    {
      "x": -4,
      "y": 5,
      "z": 0,
      "name": "Wood_Redwood_Planks",
      "rotation": 1
    },
    {
      "x": -4,
      "y": 6,
      "z": 0,
      "name": "Wood_Redwood_Planks",
      "rotation": 1
    },
    {
      "x": -4,
      "y": 7,
      "z": 0,
      "name": "Wood_Deadwood_Roof",
      "rotation": 2
    },
    {
      "x": -4,
      "y": 8,
      "z": 0,
      "name": "Nat20_Force_Empty"
    },
    {
      "x": -4,
      "y": 9,
      "z": 0,
      "name": "Nat20_Force_Empty"
    },
    {
      "x": -4,
      "y": 10,
      "z": 0,
      "name": "Nat20_Force_Empty"
    },
    {
      "x": -4,
      "y": 0,
      "z": 1,
      "name": "Wood_Deadwood_Planks",
      "rotation": 1
    },
    {
      "x": -4,
      "y": 1,
      "z": 1,
      "name": "Rock_Shale_Brick",
      "rotation": 1
    },
    {
      "x": -4,
      "y": 2,
      "z": 1,
      "name": "Rock_Shale_Brick",
      "rotation": 1
    },
    {
      "x": -4,
      "y": 3,
      "z": 1,
      "name": "Rock_Shale_Brick",
      "rotation": 1
    },
    {
      "x": -4,
      "y": 4,
      "z": 1,
      "name": "Wood_Redwood_Trunk",
      "rotation": 6
    },
    {
      "x": -4,
      "y": 5,
      "z": 1,
      "name": "Furniture_Lumberjack_Window",
      "rotation": 1
    },
    {
      "x": -4,
      "y": 6,
      "z": 1,
      "name": "Wood_Redwood_Trunk",
      "rotation": 6
    },
    {
      "x": -4,
      "y": 7,
      "z": 1,
      "name": "Wood_Redwood_Trunk",
      "rotation": 5
    },
    {
      "x": -4,
      "y": 8,
      "z": 1,
      "name": "Wood_Deadwood_Roof_Flat",
      "rotation": 2
    },
    {
      "x": -4,
      "y": 9,
      "z": 1,
      "name": "Nat20_Force_Empty"
    },
    {
      "x": -4,
      "y": 10,
      "z": 1,
      "name": "Nat20_Force_Empty"
    },
    {
      "x": -4,
      "y": 0,
      "z": 2,
      "name": "Wood_Deadwood_Planks",
      "rotation": 1
    },
    {
      "x": -4,
      "y": 1,
      "z": 2,
      "name": "Rock_Shale",
      "rotation": 1
    },
    {
      "x": -4,
      "y": 2,
      "z": 2,
      "name": "Furniture_Lumberjack_Window",
      "rotation": 1
    },
    {
      "x": -4,
      "y": 3,
      "z": 2,
      "name": "Rock_Shale_Brick",
      "rotation": 1
    },
    {
      "x": -4,
      "y": 4,
      "z": 2,
      "name": "Wood_Redwood_Trunk",
      "rotation": 6
    },
    {
      "x": -4,
      "y": 5,
      "z": 2,
      "name": "Wood_Redwood_Planks",
      "rotation": 1
    },
    {
      "x": -4,
      "y": 6,
      "z": 2,
      "name": "Wood_Redwood_Planks",
      "rotation": 1
    },
    {
      "x": -4,
      "y": 7,
      "z": 2,
      "name": "Wood_Deadwood_Roof"
    },
    {
      "x": -4,
      "y": 8,
      "z": 2,
      "name": "Nat20_Force_Empty"
    },
    {
      "x": -4,
      "y": 9,
      "z": 2,
      "name": "Nat20_Force_Empty"
    },
    {
      "x": -4,
      "y": 10,
      "z": 2,
      "name": "Nat20_Force_Empty"
    },
    {
      "x": -4,
      "y": 0,
      "z": 3,
      "name": "Wood_Deadwood_Planks",
      "rotation": 1
    },
    {
      "x": -4,
      "y": 1,
      "z": 3,
      "name": "Rock_Shale",
      "rotation": 1
    },
    {
      "x": -4,
      "y": 2,
      "z": 3,
      "name": "Rock_Shale",
      "rotation": 1
    },
    {
      "x": -4,
      "y": 3,
      "z": 3,
      "name": "Rock_Shale_Brick",
      "rotation": 1
    },
    {
      "x": -4,
      "y": 4,
      "z": 3,
      "name": "Wood_Redwood_Trunk",
      "rotation": 6
    },
    {
      "x": -4,
      "y": 5,
      "z": 3,
      "name": "Wood_Redwood_Planks",
      "rotation": 1
    },
    {
      "x": -4,
      "y": 6,
      "z": 3,
      "name": "Wood_Deadwood_Roof"
    },
    {
      "x": -4,
      "y": 7,
      "z": 3,
      "name": "Nat20_Force_Empty"
    },
    {
      "x": -4,
      "y": 8,
      "z": 3,
      "name": "Nat20_Force_Empty"
    },
    {
      "x": -4,
      "y": 9,
      "z": 3,
      "name": "Nat20_Force_Empty"
    },
    {
      "x": -4,
      "y": 10,
      "z": 3,
      "name": "Nat20_Force_Empty"
    },
    {
      "x": -4,
      "y": 0,
      "z": 4,
      "name": "Wood_Deadwood_Planks",
      "rotation": 1
    },
    {
      "x": -4,
      "y": 1,
      "z": 4,
      "name": "Rock_Shale_Brick_Half",
      "rotation": 4
    },
    {
      "x": -4,
      "y": 2,
      "z": 4,
      "name": "Rock_Shale_Brick_Half",
      "rotation": 4
    },
    {
      "x": -4,
      "y": 3,
      "z": 4,
      "name": "Rock_Shale_Brick_Half",
      "rotation": 4
    },
    {
      "x": -4,
      "y": 4,
      "z": 4,
      "name": "Wood_Redwood_Trunk",
      "rotation": 5
    },
    {
      "x": -4,
      "y": 5,
      "z": 4,
      "name": "Wood_Deadwood_Roof"
    },
    {
      "x": -4,
      "y": 6,
      "z": 4,
      "name": "Nat20_Force_Empty"
    },
    {
      "x": -4,
      "y": 7,
      "z": 4,
      "name": "Nat20_Force_Empty"
    },
    {
      "x": -4,
      "y": 8,
      "z": 4,
      "name": "Nat20_Force_Empty"
    },
    {
      "x": -4,
      "y": 9,
      "z": 4,
      "name": "Nat20_Force_Empty"
    },
    {
      "x": -4,
      "y": 10,
      "z": 4,
      "name": "Nat20_Force_Empty"
    },
    {
      "x": -4,
      "y": 0,
      "z": 5,
      "name": "Wood_Deadwood_Planks",
      "rotation": 1
    },
    {
      "x": -4,
      "y": 1,
      "z": 5,
      "name": "Nat20_Force_Empty"
    },
    {
      "x": -4,
      "y": 2,
      "z": 5,
      "name": "Nat20_Force_Empty"
    },
    {
      "x": -4,
      "y": 3,
      "z": 5,
      "name": "Nat20_Force_Empty"
    },
    {
      "x": -4,
      "y": 4,
      "z": 5,
      "name": "Nat20_Force_Empty"
    },
    {
      "x": -4,
      "y": 5,
      "z": 5,
      "name": "Nat20_Force_Empty"
    },
    {
      "x": -4,
      "y": 6,
      "z": 5,
      "name": "Nat20_Force_Empty"
    },
    {
      "x": -4,
      "y": 7,
      "z": 5,
      "name": "Nat20_Force_Empty"
    },
    {
      "x": -4,
      "y": 8,
      "z": 5,
      "name": "Nat20_Force_Empty"
    },
    {
      "x": -4,
      "y": 9,
      "z": 5,
      "name": "Nat20_Force_Empty"
    },
    {
      "x": -4,
      "y": 10,
      "z": 5,
      "name": "Nat20_Force_Empty"
    },
    {
      "x": -4,
      "y": 0,
      "z": 6,
      "name": "Wood_Fir_Trunk",
      "rotation": 1
    },
    {
      "x": -4,
      "y": 1,
      "z": 6,
      "name": "Wood_Fir_Trunk",
      "rotation": 1
    },
    {
      "x": -4,
      "y": 2,
      "z": 6,
      "name": "Wood_Fir_Trunk_Full",
      "rotation": 1
    },
    {
      "x": -4,
      "y": 3,
      "z": 6,
      "name": "Nat20_Force_Empty"
    },
    {
      "x": -4,
      "y": 4,
      "z": 6,
      "name": "Nat20_Force_Empty"
    },
    {
      "x": -4,
      "y": 5,
      "z": 6,
      "name": "Nat20_Force_Empty"
    },
    {
      "x": -4,
      "y": 6,
      "z": 6,
      "name": "Nat20_Force_Empty"
    },
    {
      "x": -4,
      "y": 7,
      "z": 6,
      "name": "Nat20_Force_Empty"
    },
    {
      "x": -4,
      "y": 8,
      "z": 6,
      "name": "Nat20_Force_Empty"
    },
    {
      "x": -4,
      "y": 9,
      "z": 6,
      "name": "Nat20_Force_Empty"
    },
    {
      "x": -4,
      "y": 10,
      "z": 6,
      "name": "Nat20_Force_Empty"
    },
    {
      "x": -3,
      "y": 0,
      "z": -5,
      "name": "Wood_Deadwood_Planks",
      "rotation": 1
    },
    {
      "x": -3,
      "y": 1,
      "z": -5,
      "name": "Wood_Redwood_Trunk",
      "rotation": 5
    },
    {
      "x": -3,
      "y": 2,
      "z": -5,
      "name": "Wood_Deadwood_Roof",
      "rotation": 2
    },
    {
      "x": -3,
      "y": 3,
      "z": -5,
      "name": "Nat20_Force_Empty"
    },
    {
      "x": -3,
      "y": 4,
      "z": -5,
      "name": "Nat20_Force_Empty"
    },
    {
      "x": -3,
      "y": 5,
      "z": -5,
      "name": "Nat20_Force_Empty"
    },
    {
      "x": -3,
      "y": 6,
      "z": -5,
      "name": "Nat20_Force_Empty"
    },
    {
      "x": -3,
      "y": 7,
      "z": -5,
      "name": "Nat20_Force_Empty"
    },
    {
      "x": -3,
      "y": 8,
      "z": -5,
      "name": "Nat20_Force_Empty"
    },
    {
      "x": -3,
      "y": 9,
      "z": -5,
      "name": "Nat20_Force_Empty"
    },
    {
      "x": -3,
      "y": 10,
      "z": -5,
      "name": "Nat20_Force_Empty"
    },
    {
      "x": -3,
      "y": 0,
      "z": -4,
      "name": "Wood_Deadwood_Planks",
      "rotation": 1
    },
    {
      "x": -3,
      "y": 1,
      "z": -4,
      "name": "Nat20_Force_Empty",
      "rotation": 1
    },
    {
      "x": -3,
      "y": 2,
      "z": -4,
      "name": "Wood_Redwood_Planks",
      "rotation": 1
    },
    {
      "x": -3,
      "y": 3,
      "z": -4,
      "name": "Wood_Deadwood_Roof",
      "rotation": 2
    },
    {
      "x": -3,
      "y": 4,
      "z": -4,
      "name": "Nat20_Force_Empty"
    },
    {
      "x": -3,
      "y": 5,
      "z": -4,
      "name": "Nat20_Force_Empty"
    },
    {
      "x": -3,
      "y": 6,
      "z": -4,
      "name": "Nat20_Force_Empty"
    },
    {
      "x": -3,
      "y": 7,
      "z": -4,
      "name": "Nat20_Force_Empty"
    },
    {
      "x": -3,
      "y": 8,
      "z": -4,
      "name": "Nat20_Force_Empty"
    },
    {
      "x": -3,
      "y": 9,
      "z": -4,
      "name": "Nat20_Force_Empty"
    },
    {
      "x": -3,
      "y": 10,
      "z": -4,
      "name": "Nat20_Force_Empty"
    },
    {
      "x": -3,
      "y": 0,
      "z": -3,
      "name": "Wood_Deadwood_Planks",
      "rotation": 1
    },
    {
      "x": -3,
      "y": 1,
      "z": -3,
      "name": "Nat20_Force_Empty",
      "rotation": 1
    },
    {
      "x": -3,
      "y": 2,
      "z": -3,
      "name": "Nat20_Force_Empty",
      "rotation": 1
    },
    {
      "x": -3,
      "y": 3,
      "z": -3,
      "name": "Wood_Redwood_Planks",
      "rotation": 1
    },
    {
      "x": -3,
      "y": 4,
      "z": -3,
      "name": "Wood_Deadwood_Roof",
      "rotation": 2
    },
    {
      "x": -3,
      "y": 5,
      "z": -3,
      "name": "Wood_Deadwood_Roof",
      "rotation": 3
    },
    {
      "x": -3,
      "y": 6,
      "z": -3,
      "name": "Nat20_Force_Empty"
    },
    {
      "x": -3,
      "y": 7,
      "z": -3,
      "name": "Nat20_Force_Empty"
    },
    {
      "x": -3,
      "y": 8,
      "z": -3,
      "name": "Nat20_Force_Empty"
    },
    {
      "x": -3,
      "y": 9,
      "z": -3,
      "name": "Nat20_Force_Empty"
    },
    {
      "x": -3,
      "y": 10,
      "z": -3,
      "name": "Nat20_Force_Empty"
    },
    {
      "x": -3,
      "y": 0,
      "z": -2,
      "name": "Wood_Deadwood_Planks",
      "rotation": 1
    },
    {
      "x": -3,
      "y": 1,
      "z": -2,
      "name": "Rock_Shale_Brick_Half",
      "rotation": 6
    },
    {
      "x": -3,
      "y": 2,
      "z": -2,
      "name": "Rock_Shale_Brick",
      "rotation": 1
    },
    {
      "x": -3,
      "y": 3,
      "z": -2,
      "name": "Rock_Shale_Brick",
      "rotation": 1
    },
    {
      "x": -3,
      "y": 4,
      "z": -2,
      "name": "Wood_Redwood_Trunk",
      "rotation": 5
    },
    {
      "x": -3,
      "y": 5,
      "z": -2,
      "name": "*Wood_Deadwood_Roof_State_Definitions_Inverted_Corner_Right",
      "rotation": 3
    },
    {
      "x": -3,
      "y": 6,
      "z": -2,
      "name": "Nat20_Force_Empty"
    },
    {
      "x": -3,
      "y": 7,
      "z": -2,
      "name": "Nat20_Force_Empty"
    },
    {
      "x": -3,
      "y": 8,
      "z": -2,
      "name": "Nat20_Force_Empty"
    },
    {
      "x": -3,
      "y": 9,
      "z": -2,
      "name": "Nat20_Force_Empty"
    },
    {
      "x": -3,
      "y": 10,
      "z": -2,
      "name": "Nat20_Force_Empty"
    },
    {
      "x": -3,
      "y": 0,
      "z": -1,
      "name": "Wood_Deadwood_Planks",
      "rotation": 1
    },
    {
      "x": -3,
      "y": 1,
      "z": -1,
      "name": "Nat20_Force_Empty",
      "rotation": 1
    },
    {
      "x": -3,
      "y": 2,
      "z": -1,
      "name": "Nat20_Force_Empty",
      "rotation": 1
    },
    {
      "x": -3,
      "y": 3,
      "z": -1,
      "name": "Furniture_Lumberjack_Platform",
      "rotation": 1
    },
    {
      "x": -3,
      "y": 4,
      "z": -1,
      "name": "Nat20_Force_Empty",
      "rotation": 1
    },
    {
      "x": -3,
      "y": 5,
      "z": -1,
      "name": "Wood_Redwood_Planks",
      "rotation": 1
    },
    {
      "x": -3,
      "y": 6,
      "z": -1,
      "name": "Wood_Deadwood_Roof",
      "rotation": 2
    },
    {
      "x": -3,
      "y": 7,
      "z": -1,
      "name": "Nat20_Force_Empty"
    },
    {
      "x": -3,
      "y": 8,
      "z": -1,
      "name": "Nat20_Force_Empty"
    },
    {
      "x": -3,
      "y": 9,
      "z": -1,
      "name": "Nat20_Force_Empty"
    },
    {
      "x": -3,
      "y": 10,
      "z": -1,
      "name": "Nat20_Force_Empty"
    },
    {
      "x": -3,
      "y": 0,
      "z": 0,
      "name": "Wood_Deadwood_Planks",
      "rotation": 1
    },
    {
      "x": -3,
      "y": 1,
      "z": 0,
      "name": "Nat20_Force_Empty",
      "rotation": 1
    },
    {
      "x": -3,
      "y": 2,
      "z": 0,
      "name": "Nat20_Force_Empty",
      "rotation": 1
    },
    {
      "x": -3,
      "y": 3,
      "z": 0,
      "name": "Furniture_Lumberjack_Platform",
      "rotation": 1
    },
    {
      "x": -3,
      "y": 4,
      "z": 0,
      "name": "Furniture_Human_Ruins_Chest_Small",
      "components": {
        "Components": {
          "ItemContainerBlock": {
            "ItemContainer": {
              "Capacity": 18,
              "Items": {
                "15": {
                  "Id": "Ingredient_Fabric_Scrap_Shadoweave",
                  "Quantity": 2,
                  "Durability": 0.0,
                  "MaxDurability": 0.0,
                  "OverrideDroppedItemAnimation": false
                },
                "14": {
                  "Id": "Ingredient_Fabric_Scrap_Shadoweave",
                  "Quantity": 1,
                  "Durability": 0.0,
                  "MaxDurability": 0.0,
                  "OverrideDroppedItemAnimation": false
                },
                "2": {
                  "Id": "Ingredient_Hide_Medium",
                  "Quantity": 1,
                  "Durability": 0.0,
                  "MaxDurability": 0.0,
                  "OverrideDroppedItemAnimation": false
                },
                "6": {
                  "Id": "Plant_Seeds_Tomato",
                  "Quantity": 1,
                  "Durability": 0.0,
                  "MaxDurability": 0.0,
                  "OverrideDroppedItemAnimation": false
                },
                "4": {
                  "Id": "Wood_Poisoned_Trunk",
                  "Quantity": 7,
                  "Durability": 0.0,
                  "MaxDurability": 0.0,
                  "OverrideDroppedItemAnimation": false
                },
                "5": {
                  "Id": "Weapon_Mace_Copper",
                  "Quantity": 1,
                  "Durability": 100.0,
                  "MaxDurability": 100.0,
                  "OverrideDroppedItemAnimation": false
                }
              }
            },
            "Capacity": 20
          }
        }
      },
      "rotation": 1
    },
    {
      "x": -3,
      "y": 5,
      "z": 0,
      "name": "Nat20_Force_Empty",
      "rotation": 1
    },
    {
      "x": -3,
      "y": 6,
      "z": 0,
      "name": "Wood_Redwood_Planks",
      "rotation": 1
    },
    {
      "x": -3,
      "y": 7,
      "z": 0,
      "name": "Wood_Deadwood_Roof",
      "rotation": 2
    },
    {
      "x": -3,
      "y": 8,
      "z": 0,
      "name": "Nat20_Force_Empty"
    },
    {
      "x": -3,
      "y": 9,
      "z": 0,
      "name": "Nat20_Force_Empty"
    },
    {
      "x": -3,
      "y": 10,
      "z": 0,
      "name": "Nat20_Force_Empty"
    },
    {
      "x": -3,
      "y": 0,
      "z": 1,
      "name": "Wood_Deadwood_Planks",
      "rotation": 1
    },
    {
      "x": -3,
      "y": 1,
      "z": 1,
      "name": "Nat20_Force_Empty",
      "rotation": 1
    },
    {
      "x": -3,
      "y": 2,
      "z": 1,
      "name": "Nat20_Force_Empty",
      "rotation": 1
    },
    {
      "x": -3,
      "y": 3,
      "z": 1,
      "name": "Furniture_Lumberjack_Platform",
      "rotation": 1
    },
    {
      "x": -3,
      "y": 4,
      "z": 1,
      "name": "Nat20_Force_Empty",
      "rotation": 1
    },
    {
      "x": -3,
      "y": 5,
      "z": 1,
      "name": "Nat20_Force_Empty",
      "rotation": 1
    },
    {
      "x": -3,
      "y": 6,
      "z": 1,
      "name": "Nat20_Force_Empty",
      "rotation": 1
    },
    {
      "x": -3,
      "y": 7,
      "z": 1,
      "name": "Wood_Redwood_Trunk",
      "rotation": 5
    },
    {
      "x": -3,
      "y": 8,
      "z": 1,
      "name": "Wood_Deadwood_Roof_Flat",
      "rotation": 2
    },
    {
      "x": -3,
      "y": 9,
      "z": 1,
      "name": "Nat20_Force_Empty"
    },
    {
      "x": -3,
      "y": 10,
      "z": 1,
      "name": "Nat20_Force_Empty"
    },
    {
      "x": -3,
      "y": 0,
      "z": 2,
      "name": "Wood_Deadwood_Planks",
      "rotation": 1
    },
    {
      "x": -3,
      "y": 1,
      "z": 2,
      "name": "Nat20_Force_Empty",
      "rotation": 1
    },
    {
      "x": -3,
      "y": 2,
      "z": 2,
      "name": "Nat20_Force_Empty",
      "rotation": 1
    },
    {
      "x": -3,
      "y": 3,
      "z": 2,
      "name": "Furniture_Lumberjack_Platform",
      "rotation": 1
    },
    {
      "x": -3,
      "y": 4,
      "z": 2,
      "name": "Furniture_Faun_Stool",
      "rotation": 1
    },
    {
      "x": -3,
      "y": 5,
      "z": 2,
      "name": "Nat20_Force_Empty",
      "rotation": 1
    },
    {
      "x": -3,
      "y": 6,
      "z": 2,
      "name": "Wood_Redwood_Planks",
      "rotation": 1
    },
    {
      "x": -3,
      "y": 7,
      "z": 2,
      "name": "Wood_Deadwood_Roof"
    },
    {
      "x": -3,
      "y": 8,
      "z": 2,
      "name": "Nat20_Force_Empty"
    },
    {
      "x": -3,
      "y": 9,
      "z": 2,
      "name": "Nat20_Force_Empty"
    },
    {
      "x": -3,
      "y": 10,
      "z": 2,
      "name": "Nat20_Force_Empty"
    },
    {
      "x": -3,
      "y": 0,
      "z": 3,
      "name": "Wood_Deadwood_Planks",
      "rotation": 1
    },
    {
      "x": -3,
      "y": 1,
      "z": 3,
      "name": "Furniture_Village_Counter",
      "rotation": 2
    },
    {
      "x": -3,
      "y": 2,
      "z": 3,
      "name": "Furniture_Ancient_Candle",
      "rotation": 1
    },
    {
      "x": -3,
      "y": 3,
      "z": 3,
      "name": "Nat20_Force_Empty",
      "rotation": 1
    },
    {
      "x": -3,
      "y": 4,
      "z": 3,
      "name": "Wood_Redwood_Planks",
      "rotation": 1
    },
    {
      "x": -3,
      "y": 5,
      "z": 3,
      "name": "Wood_Redwood_Planks",
      "rotation": 1
    },
    {
      "x": -3,
      "y": 6,
      "z": 3,
      "name": "Wood_Deadwood_Roof"
    },
    {
      "x": -3,
      "y": 7,
      "z": 3,
      "name": "Nat20_Force_Empty"
    },
    {
      "x": -3,
      "y": 8,
      "z": 3,
      "name": "Nat20_Force_Empty"
    },
    {
      "x": -3,
      "y": 9,
      "z": 3,
      "name": "Nat20_Force_Empty"
    },
    {
      "x": -3,
      "y": 10,
      "z": 3,
      "name": "Nat20_Force_Empty"
    },
    {
      "x": -3,
      "y": 0,
      "z": 4,
      "name": "Wood_Deadwood_Planks",
      "rotation": 1
    },
    {
      "x": -3,
      "y": 1,
      "z": 4,
      "name": "Rock_Shale_Brick_Half",
      "rotation": 4
    },
    {
      "x": -3,
      "y": 2,
      "z": 4,
      "name": "Rock_Shale_Brick_Half",
      "rotation": 4
    },
    {
      "x": -3,
      "y": 3,
      "z": 4,
      "name": "Rock_Shale_Brick_Half",
      "rotation": 4
    },
    {
      "x": -3,
      "y": 4,
      "z": 4,
      "name": "Wood_Redwood_Trunk",
      "rotation": 5
    },
    {
      "x": -3,
      "y": 5,
      "z": 4,
      "name": "*Wood_Deadwood_Roof_State_Definitions_Inverted_Corner_Right"
    },
    {
      "x": -3,
      "y": 6,
      "z": 4,
      "name": "Nat20_Force_Empty"
    },
    {
      "x": -3,
      "y": 7,
      "z": 4,
      "name": "Nat20_Force_Empty"
    },
    {
      "x": -3,
      "y": 8,
      "z": 4,
      "name": "Nat20_Force_Empty"
    },
    {
      "x": -3,
      "y": 9,
      "z": 4,
      "name": "Nat20_Force_Empty"
    },
    {
      "x": -3,
      "y": 10,
      "z": 4,
      "name": "Nat20_Force_Empty"
    },
    {
      "x": -3,
      "y": 0,
      "z": 5,
      "name": "Wood_Deadwood_Planks",
      "rotation": 1
    },
    {
      "x": -3,
      "y": 1,
      "z": 5,
      "name": "Nat20_Force_Empty"
    },
    {
      "x": -3,
      "y": 2,
      "z": 5,
      "name": "Nat20_Force_Empty"
    },
    {
      "x": -3,
      "y": 3,
      "z": 5,
      "name": "Nat20_Force_Empty"
    },
    {
      "x": -3,
      "y": 4,
      "z": 5,
      "name": "Wood_Redwood_Trunk",
      "rotation": 6
    },
    {
      "x": -3,
      "y": 5,
      "z": 5,
      "name": "Wood_Deadwood_Roof",
      "rotation": 3
    },
    {
      "x": -3,
      "y": 6,
      "z": 5,
      "name": "Nat20_Force_Empty"
    },
    {
      "x": -3,
      "y": 7,
      "z": 5,
      "name": "Nat20_Force_Empty"
    },
    {
      "x": -3,
      "y": 8,
      "z": 5,
      "name": "Nat20_Force_Empty"
    },
    {
      "x": -3,
      "y": 9,
      "z": 5,
      "name": "Nat20_Force_Empty"
    },
    {
      "x": -3,
      "y": 10,
      "z": 5,
      "name": "Nat20_Force_Empty"
    },
    {
      "x": -3,
      "y": 0,
      "z": 6,
      "name": "Wood_Fir_Trunk",
      "rotation": 1
    },
    {
      "x": -3,
      "y": 1,
      "z": 6,
      "name": "Wood_Fir_Trunk",
      "rotation": 1
    },
    {
      "x": -3,
      "y": 2,
      "z": 6,
      "name": "Wood_Fir_Trunk_Full",
      "rotation": 1
    },
    {
      "x": -3,
      "y": 3,
      "z": 6,
      "name": "Nat20_Force_Empty"
    },
    {
      "x": -3,
      "y": 4,
      "z": 6,
      "name": "Wood_Redwood_Trunk",
      "rotation": 6
    },
    {
      "x": -3,
      "y": 5,
      "z": 6,
      "name": "Nat20_Force_Empty"
    },
    {
      "x": -3,
      "y": 6,
      "z": 6,
      "name": "Nat20_Force_Empty"
    },
    {
      "x": -3,
      "y": 7,
      "z": 6,
      "name": "Nat20_Force_Empty"
    },
    {
      "x": -3,
      "y": 8,
      "z": 6,
      "name": "Nat20_Force_Empty"
    },
    {
      "x": -3,
      "y": 9,
      "z": 6,
      "name": "Nat20_Force_Empty"
    },
    {
      "x": -3,
      "y": 10,
      "z": 6,
      "name": "Nat20_Force_Empty"
    },
    {
      "x": -2,
      "y": 0,
      "z": -5,
      "name": "Wood_Deadwood_Planks",
      "rotation": 1
    },
    {
      "x": -2,
      "y": 1,
      "z": -5,
      "name": "Wood_Redwood_Trunk",
      "rotation": 5
    },
    {
      "x": -2,
      "y": 2,
      "z": -5,
      "name": "Wood_Deadwood_Roof",
      "rotation": 2
    },
    {
      "x": -2,
      "y": 3,
      "z": -5,
      "name": "Nat20_Force_Empty"
    },
    {
      "x": -2,
      "y": 4,
      "z": -5,
      "name": "Nat20_Force_Empty"
    },
    {
      "x": -2,
      "y": 5,
      "z": -5,
      "name": "Nat20_Force_Empty"
    },
    {
      "x": -2,
      "y": 6,
      "z": -5,
      "name": "Nat20_Force_Empty"
    },
    {
      "x": -2,
      "y": 7,
      "z": -5,
      "name": "Nat20_Force_Empty"
    },
    {
      "x": -2,
      "y": 8,
      "z": -5,
      "name": "Nat20_Force_Empty"
    },
    {
      "x": -2,
      "y": 9,
      "z": -5,
      "name": "Nat20_Force_Empty"
    },
    {
      "x": -2,
      "y": 10,
      "z": -5,
      "name": "Nat20_Force_Empty"
    },
    {
      "x": -2,
      "y": 0,
      "z": -4,
      "name": "Wood_Deadwood_Planks",
      "rotation": 1
    },
    {
      "x": -2,
      "y": 1,
      "z": -4,
      "name": "Nat20_Force_Empty",
      "rotation": 1
    },
    {
      "x": -2,
      "y": 2,
      "z": -4,
      "name": "Wood_Redwood_Planks",
      "rotation": 1
    },
    {
      "x": -2,
      "y": 3,
      "z": -4,
      "name": "Wood_Deadwood_Roof",
      "rotation": 2
    },
    {
      "x": -2,
      "y": 4,
      "z": -4,
      "name": "Nat20_Force_Empty"
    },
    {
      "x": -2,
      "y": 5,
      "z": -4,
      "name": "Nat20_Force_Empty"
    },
    {
      "x": -2,
      "y": 6,
      "z": -4,
      "name": "Nat20_Force_Empty"
    },
    {
      "x": -2,
      "y": 7,
      "z": -4,
      "name": "Nat20_Force_Empty"
    },
    {
      "x": -2,
      "y": 8,
      "z": -4,
      "name": "Nat20_Force_Empty"
    },
    {
      "x": -2,
      "y": 9,
      "z": -4,
      "name": "Nat20_Force_Empty"
    },
    {
      "x": -2,
      "y": 10,
      "z": -4,
      "name": "Nat20_Force_Empty"
    },
    {
      "x": -2,
      "y": 0,
      "z": -3,
      "name": "Wood_Deadwood_Planks",
      "rotation": 1
    },
    {
      "x": -2,
      "y": 1,
      "z": -3,
      "name": "Nat20_Force_Empty",
      "rotation": 1
    },
    {
      "x": -2,
      "y": 2,
      "z": -3,
      "name": "Nat20_Force_Empty",
      "rotation": 1
    },
    {
      "x": -2,
      "y": 3,
      "z": -3,
      "name": "Wood_Redwood_Planks",
      "rotation": 1
    },
    {
      "x": -2,
      "y": 4,
      "z": -3,
      "name": "Wood_Deadwood_Roof",
      "rotation": 2
    },
    {
      "x": -2,
      "y": 5,
      "z": -3,
      "name": "Wood_Redwood_Trunk",
      "rotation": 6
    },
    {
      "x": -2,
      "y": 6,
      "z": -3,
      "name": "Nat20_Force_Empty"
    },
    {
      "x": -2,
      "y": 7,
      "z": -3,
      "name": "Nat20_Force_Empty"
    },
    {
      "x": -2,
      "y": 8,
      "z": -3,
      "name": "Nat20_Force_Empty"
    },
    {
      "x": -2,
      "y": 9,
      "z": -3,
      "name": "Nat20_Force_Empty"
    },
    {
      "x": -2,
      "y": 10,
      "z": -3,
      "name": "Nat20_Force_Empty"
    },
    {
      "x": -2,
      "y": 0,
      "z": -2,
      "name": "Wood_Deadwood_Planks",
      "rotation": 1
    },
    {
      "x": -2,
      "y": 1,
      "z": -2,
      "name": "Rock_Shale_Brick",
      "rotation": 1
    },
    {
      "x": -2,
      "y": 2,
      "z": -2,
      "name": "Rock_Shale_Brick",
      "rotation": 1
    },
    {
      "x": -2,
      "y": 3,
      "z": -2,
      "name": "Rock_Shale_Brick",
      "rotation": 1
    },
    {
      "x": -2,
      "y": 4,
      "z": -2,
      "name": "Wood_Redwood_Trunk",
      "rotation": 5
    },
    {
      "x": -2,
      "y": 5,
      "z": -2,
      "name": "Wood_Redwood_Trunk",
      "rotation": 6
    },
    {
      "x": -2,
      "y": 6,
      "z": -2,
      "name": "Wood_Deadwood_Roof",
      "rotation": 3
    },
    {
      "x": -2,
      "y": 7,
      "z": -2,
      "name": "Nat20_Force_Empty"
    },
    {
      "x": -2,
      "y": 8,
      "z": -2,
      "name": "Nat20_Force_Empty"
    },
    {
      "x": -2,
      "y": 9,
      "z": -2,
      "name": "Nat20_Force_Empty"
    },
    {
      "x": -2,
      "y": 10,
      "z": -2,
      "name": "Nat20_Force_Empty"
    },
    {
      "x": -2,
      "y": 0,
      "z": -1,
      "name": "Wood_Deadwood_Planks",
      "rotation": 1
    },
    {
      "x": -2,
      "y": 1,
      "z": -1,
      "name": "Nat20_Force_Empty",
      "rotation": 1
    },
    {
      "x": -2,
      "y": 2,
      "z": -1,
      "name": "Nat20_Force_Empty",
      "rotation": 1
    },
    {
      "x": -2,
      "y": 3,
      "z": -1,
      "name": "Furniture_Lumberjack_Platform",
      "rotation": 1
    },
    {
      "x": -2,
      "y": 4,
      "z": -1,
      "name": "Furniture_Village_Crate",
      "rotation": 1
    },
    {
      "x": -2,
      "y": 5,
      "z": -1,
      "name": "Wood_Redwood_Planks",
      "rotation": 1
    },
    {
      "x": -2,
      "y": 6,
      "z": -1,
      "name": "*Wood_Deadwood_Roof_State_Definitions_Inverted_Corner_Right",
      "rotation": 3
    },
    {
      "x": -2,
      "y": 7,
      "z": -1,
      "name": "Nat20_Force_Empty"
    },
    {
      "x": -2,
      "y": 8,
      "z": -1,
      "name": "Nat20_Force_Empty"
    },
    {
      "x": -2,
      "y": 9,
      "z": -1,
      "name": "Nat20_Force_Empty"
    },
    {
      "x": -2,
      "y": 10,
      "z": -1,
      "name": "Nat20_Force_Empty"
    },
    {
      "x": -2,
      "y": 0,
      "z": 0,
      "name": "Wood_Deadwood_Planks",
      "rotation": 1
    },
    {
      "x": -2,
      "y": 1,
      "z": 0,
      "name": "Nat20_Force_Empty",
      "rotation": 1
    },
    {
      "x": -2,
      "y": 2,
      "z": 0,
      "name": "Nat20_Force_Empty",
      "rotation": 1
    },
    {
      "x": -2,
      "y": 3,
      "z": 0,
      "name": "Furniture_Lumberjack_Platform",
      "rotation": 1
    },
    {
      "x": -2,
      "y": 4,
      "z": 0,
      "name": "Nat20_Force_Empty",
      "rotation": 1
    },
    {
      "x": -2,
      "y": 5,
      "z": 0,
      "name": "Nat20_Force_Empty",
      "rotation": 1
    },
    {
      "x": -2,
      "y": 6,
      "z": 0,
      "name": "Wood_Redwood_Planks",
      "rotation": 1
    },
    {
      "x": -2,
      "y": 7,
      "z": 0,
      "name": "Wood_Deadwood_Roof",
      "rotation": 2
    },
    {
      "x": -2,
      "y": 8,
      "z": 0,
      "name": "Nat20_Force_Empty"
    },
    {
      "x": -2,
      "y": 9,
      "z": 0,
      "name": "Nat20_Force_Empty"
    },
    {
      "x": -2,
      "y": 10,
      "z": 0,
      "name": "Nat20_Force_Empty"
    },
    {
      "x": -2,
      "y": 0,
      "z": 1,
      "name": "Wood_Deadwood_Planks",
      "rotation": 1
    },
    {
      "x": -2,
      "y": 1,
      "z": 1,
      "name": "Nat20_Force_Empty",
      "rotation": 1
    },
    {
      "x": -2,
      "y": 2,
      "z": 1,
      "name": "Nat20_Force_Empty",
      "rotation": 1
    },
    {
      "x": -2,
      "y": 3,
      "z": 1,
      "name": "Furniture_Lumberjack_Platform",
      "rotation": 1
    },
    {
      "x": -2,
      "y": 4,
      "z": 1,
      "name": "Nat20_Force_Empty",
      "rotation": 1
    },
    {
      "x": -2,
      "y": 5,
      "z": 1,
      "name": "Nat20_Force_Empty",
      "rotation": 1
    },
    {
      "x": -2,
      "y": 6,
      "z": 1,
      "name": "Nat20_Force_Empty",
      "rotation": 1
    },
    {
      "x": -2,
      "y": 7,
      "z": 1,
      "name": "Wood_Redwood_Trunk",
      "rotation": 5
    },
    {
      "x": -2,
      "y": 8,
      "z": 1,
      "name": "Wood_Deadwood_Roof_Flat",
      "rotation": 2
    },
    {
      "x": -2,
      "y": 9,
      "z": 1,
      "name": "Nat20_Force_Empty"
    },
    {
      "x": -2,
      "y": 10,
      "z": 1,
      "name": "Nat20_Force_Empty"
    },
    {
      "x": -2,
      "y": 0,
      "z": 2,
      "name": "Wood_Deadwood_Planks",
      "rotation": 1
    },
    {
      "x": -2,
      "y": 1,
      "z": 2,
      "name": "Nat20_Force_Empty",
      "rotation": 1
    },
    {
      "x": -2,
      "y": 2,
      "z": 2,
      "name": "Nat20_Force_Empty",
      "rotation": 1
    },
    {
      "x": -2,
      "y": 3,
      "z": 2,
      "name": "Furniture_Lumberjack_Platform",
      "rotation": 1
    },
    {
      "x": -2,
      "y": 4,
      "z": 2,
      "name": "Nat20_Force_Empty",
      "rotation": 1
    },
    {
      "x": -2,
      "y": 5,
      "z": 2,
      "name": "Nat20_Force_Empty",
      "rotation": 1
    },
    {
      "x": -2,
      "y": 6,
      "z": 2,
      "name": "Wood_Redwood_Planks",
      "rotation": 1
    },
    {
      "x": -2,
      "y": 7,
      "z": 2,
      "name": "Wood_Deadwood_Roof"
    },
    {
      "x": -2,
      "y": 8,
      "z": 2,
      "name": "Nat20_Force_Empty"
    },
    {
      "x": -2,
      "y": 9,
      "z": 2,
      "name": "Nat20_Force_Empty"
    },
    {
      "x": -2,
      "y": 10,
      "z": 2,
      "name": "Nat20_Force_Empty"
    },
    {
      "x": -2,
      "y": 0,
      "z": 3,
      "name": "Wood_Deadwood_Planks",
      "rotation": 1
    },
    {
      "x": -2,
      "y": 1,
      "z": 3,
      "name": "Furniture_Village_Counter",
      "filler": 1,
      "rotation": 2
    },
    {
      "x": -2,
      "y": 2,
      "z": 3,
      "name": "Nat20_Force_Empty",
      "rotation": 1
    },
    {
      "x": -2,
      "y": 3,
      "z": 3,
      "name": "Nat20_Force_Empty",
      "rotation": 1
    },
    {
      "x": -2,
      "y": 4,
      "z": 3,
      "name": "Wood_Redwood_Planks",
      "rotation": 1
    },
    {
      "x": -2,
      "y": 5,
      "z": 3,
      "name": "Wood_Redwood_Planks",
      "rotation": 1
    },
    {
      "x": -2,
      "y": 6,
      "z": 3,
      "name": "*Wood_Deadwood_Roof_State_Definitions_Inverted_Corner_Right"
    },
    {
      "x": -2,
      "y": 7,
      "z": 3,
      "name": "Nat20_Force_Empty"
    },
    {
      "x": -2,
      "y": 8,
      "z": 3,
      "name": "Nat20_Force_Empty"
    },
    {
      "x": -2,
      "y": 9,
      "z": 3,
      "name": "Nat20_Force_Empty"
    },
    {
      "x": -2,
      "y": 10,
      "z": 3,
      "name": "Nat20_Force_Empty"
    },
    {
      "x": -2,
      "y": 0,
      "z": 4,
      "name": "Wood_Deadwood_Planks",
      "rotation": 1
    },
    {
      "x": -2,
      "y": 1,
      "z": 4,
      "name": "Rock_Shale_Brick",
      "rotation": 1
    },
    {
      "x": -2,
      "y": 2,
      "z": 4,
      "name": "Rock_Shale_Brick",
      "rotation": 1
    },
    {
      "x": -2,
      "y": 3,
      "z": 4,
      "name": "Rock_Shale_Brick",
      "rotation": 1
    },
    {
      "x": -2,
      "y": 4,
      "z": 4,
      "name": "Wood_Redwood_Trunk",
      "rotation": 5
    },
    {
      "x": -2,
      "y": 5,
      "z": 4,
      "name": "Wood_Redwood_Planks",
      "rotation": 1
    },
    {
      "x": -2,
      "y": 6,
      "z": 4,
      "name": "Wood_Deadwood_Roof",
      "rotation": 3
    },
    {
      "x": -2,
      "y": 7,
      "z": 4,
      "name": "Nat20_Force_Empty"
    },
    {
      "x": -2,
      "y": 8,
      "z": 4,
      "name": "Nat20_Force_Empty"
    },
    {
      "x": -2,
      "y": 9,
      "z": 4,
      "name": "Nat20_Force_Empty"
    },
    {
      "x": -2,
      "y": 10,
      "z": 4,
      "name": "Nat20_Force_Empty"
    },
    {
      "x": -2,
      "y": 0,
      "z": 5,
      "name": "Wood_Deadwood_Planks",
      "rotation": 1
    },
    {
      "x": -2,
      "y": 1,
      "z": 5,
      "name": "Nat20_Force_Empty"
    },
    {
      "x": -2,
      "y": 2,
      "z": 5,
      "name": "Nat20_Force_Empty"
    },
    {
      "x": -2,
      "y": 3,
      "z": 5,
      "name": "Nat20_Force_Empty"
    },
    {
      "x": -2,
      "y": 4,
      "z": 5,
      "name": "Wood_Redwood_Stairs",
      "rotation": 11
    },
    {
      "x": -2,
      "y": 5,
      "z": 5,
      "name": "Wood_Redwood_Stairs",
      "rotation": 3
    },
    {
      "x": -2,
      "y": 6,
      "z": 5,
      "name": "Nat20_Force_Empty"
    },
    {
      "x": -2,
      "y": 7,
      "z": 5,
      "name": "Nat20_Force_Empty"
    },
    {
      "x": -2,
      "y": 8,
      "z": 5,
      "name": "Nat20_Force_Empty"
    },
    {
      "x": -2,
      "y": 9,
      "z": 5,
      "name": "Nat20_Force_Empty"
    },
    {
      "x": -2,
      "y": 10,
      "z": 5,
      "name": "Nat20_Force_Empty"
    },
    {
      "x": -2,
      "y": 0,
      "z": 6,
      "name": "Wood_Deadwood_Planks",
      "rotation": 1
    },
    {
      "x": -2,
      "y": 1,
      "z": 6,
      "name": "Nat20_Force_Empty"
    },
    {
      "x": -2,
      "y": 2,
      "z": 6,
      "name": "Nat20_Force_Empty"
    },
    {
      "x": -2,
      "y": 3,
      "z": 6,
      "name": "Nat20_Force_Empty"
    },
    {
      "x": -2,
      "y": 4,
      "z": 6,
      "name": "Nat20_Force_Empty"
    },
    {
      "x": -2,
      "y": 5,
      "z": 6,
      "name": "Nat20_Force_Empty"
    },
    {
      "x": -2,
      "y": 6,
      "z": 6,
      "name": "Nat20_Force_Empty"
    },
    {
      "x": -2,
      "y": 7,
      "z": 6,
      "name": "Nat20_Force_Empty"
    },
    {
      "x": -2,
      "y": 8,
      "z": 6,
      "name": "Nat20_Force_Empty"
    },
    {
      "x": -2,
      "y": 9,
      "z": 6,
      "name": "Nat20_Force_Empty"
    },
    {
      "x": -2,
      "y": 10,
      "z": 6,
      "name": "Nat20_Force_Empty"
    },
    {
      "x": -1,
      "y": 0,
      "z": -5,
      "name": "Wood_Deadwood_Planks",
      "rotation": 1
    },
    {
      "x": -1,
      "y": 1,
      "z": -5,
      "name": "Wood_Redwood_Trunk",
      "rotation": 5
    },
    {
      "x": -1,
      "y": 2,
      "z": -5,
      "name": "Wood_Deadwood_Roof",
      "rotation": 2
    },
    {
      "x": -1,
      "y": 3,
      "z": -5,
      "name": "Nat20_Force_Empty"
    },
    {
      "x": -1,
      "y": 4,
      "z": -5,
      "name": "Nat20_Force_Empty"
    },
    {
      "x": -1,
      "y": 5,
      "z": -5,
      "name": "Nat20_Force_Empty"
    },
    {
      "x": -1,
      "y": 6,
      "z": -5,
      "name": "Nat20_Force_Empty"
    },
    {
      "x": -1,
      "y": 7,
      "z": -5,
      "name": "Nat20_Force_Empty"
    },
    {
      "x": -1,
      "y": 8,
      "z": -5,
      "name": "Nat20_Force_Empty"
    },
    {
      "x": -1,
      "y": 9,
      "z": -5,
      "name": "Nat20_Force_Empty"
    },
    {
      "x": -1,
      "y": 10,
      "z": -5,
      "name": "Nat20_Force_Empty"
    },
    {
      "x": -1,
      "y": 0,
      "z": -4,
      "name": "Wood_Deadwood_Planks",
      "rotation": 1
    },
    {
      "x": -1,
      "y": 1,
      "z": -4,
      "name": "Furniture_Village_Crate",
      "rotation": 1
    },
    {
      "x": -1,
      "y": 2,
      "z": -4,
      "name": "Wood_Redwood_Planks",
      "rotation": 1
    },
    {
      "x": -1,
      "y": 3,
      "z": -4,
      "name": "Wood_Deadwood_Roof",
      "rotation": 2
    },
    {
      "x": -1,
      "y": 4,
      "z": -4,
      "name": "Nat20_Force_Empty"
    },
    {
      "x": -1,
      "y": 5,
      "z": -4,
      "name": "Nat20_Force_Empty"
    },
    {
      "x": -1,
      "y": 6,
      "z": -4,
      "name": "Nat20_Force_Empty"
    },
    {
      "x": -1,
      "y": 7,
      "z": -4,
      "name": "Nat20_Force_Empty"
    },
    {
      "x": -1,
      "y": 8,
      "z": -4,
      "name": "Nat20_Force_Empty"
    },
    {
      "x": -1,
      "y": 9,
      "z": -4,
      "name": "Nat20_Force_Empty"
    },
    {
      "x": -1,
      "y": 10,
      "z": -4,
      "name": "Nat20_Force_Empty"
    },
    {
      "x": -1,
      "y": 0,
      "z": -3,
      "name": "Wood_Deadwood_Planks",
      "rotation": 1
    },
    {
      "x": -1,
      "y": 1,
      "z": -3,
      "name": "Nat20_Force_Empty",
      "rotation": 1
    },
    {
      "x": -1,
      "y": 2,
      "z": -3,
      "name": "Nat20_Force_Empty",
      "rotation": 1
    },
    {
      "x": -1,
      "y": 3,
      "z": -3,
      "name": "Wood_Redwood_Planks",
      "rotation": 1
    },
    {
      "x": -1,
      "y": 4,
      "z": -3,
      "name": "Wood_Redwood_Trunk",
      "rotation": 5
    },
    {
      "x": -1,
      "y": 5,
      "z": -3,
      "name": "Wood_Redwood_Stairs",
      "rotation": 11
    },
    {
      "x": -1,
      "y": 6,
      "z": -3,
      "name": "Wood_Redwood_Stairs",
      "rotation": 3
    },
    {
      "x": -1,
      "y": 7,
      "z": -3,
      "name": "Nat20_Force_Empty"
    },
    {
      "x": -1,
      "y": 8,
      "z": -3,
      "name": "Nat20_Force_Empty"
    },
    {
      "x": -1,
      "y": 9,
      "z": -3,
      "name": "Nat20_Force_Empty"
    },
    {
      "x": -1,
      "y": 10,
      "z": -3,
      "name": "Nat20_Force_Empty"
    },
    {
      "x": -1,
      "y": 0,
      "z": -2,
      "name": "Wood_Deadwood_Planks",
      "rotation": 1
    },
    {
      "x": -1,
      "y": 1,
      "z": -2,
      "name": "Rock_Shale_Brick",
      "rotation": 1
    },
    {
      "x": -1,
      "y": 2,
      "z": -2,
      "name": "Rock_Shale_Brick",
      "rotation": 1
    },
    {
      "x": -1,
      "y": 3,
      "z": -2,
      "name": "Rock_Shale_Brick",
      "rotation": 1
    },
    {
      "x": -1,
      "y": 4,
      "z": -2,
      "name": "Wood_Redwood_Trunk",
      "rotation": 5
    },
    {
      "x": -1,
      "y": 5,
      "z": -2,
      "name": "Wood_Redwood_Planks",
      "rotation": 1
    },
    {
      "x": -1,
      "y": 6,
      "z": -2,
      "name": "Wood_Redwood_Planks",
      "rotation": 1
    },
    {
      "x": -1,
      "y": 7,
      "z": -2,
      "name": "Wood_Deadwood_Roof",
      "rotation": 3
    },
    {
      "x": -1,
      "y": 8,
      "z": -2,
      "name": "Nat20_Force_Empty"
    },
    {
      "x": -1,
      "y": 9,
      "z": -2,
      "name": "Nat20_Force_Empty"
    },
    {
      "x": -1,
      "y": 10,
      "z": -2,
      "name": "Nat20_Force_Empty"
    },
    {
      "x": -1,
      "y": 0,
      "z": -1,
      "name": "Wood_Deadwood_Planks",
      "rotation": 1
    },
    {
      "x": -1,
      "y": 1,
      "z": -1,
      "name": "Furniture_Village_Crate",
      "rotation": 1
    },
    {
      "x": -1,
      "y": 2,
      "z": -1,
      "name": "Nat20_Force_Empty",
      "rotation": 1
    },
    {
      "x": -1,
      "y": 3,
      "z": -1,
      "name": "Furniture_Lumberjack_Platform",
      "rotation": 1
    },
    {
      "x": -1,
      "y": 4,
      "z": -1,
      "name": "Furniture_Village_Crate",
      "rotation": 1
    },
    {
      "x": -1,
      "y": 5,
      "z": -1,
      "name": "Wood_Redwood_Planks",
      "rotation": 1
    },
    {
      "x": -1,
      "y": 6,
      "z": -1,
      "name": "Wood_Redwood_Planks",
      "rotation": 1
    },
    {
      "x": -1,
      "y": 7,
      "z": -1,
      "name": "Wood_Deadwood_Roof",
      "rotation": 3
    },
    {
      "x": -1,
      "y": 8,
      "z": -1,
      "name": "Nat20_Force_Empty"
    },
    {
      "x": -1,
      "y": 9,
      "z": -1,
      "name": "Nat20_Force_Empty"
    },
    {
      "x": -1,
      "y": 10,
      "z": -1,
      "name": "Nat20_Force_Empty"
    },
    {
      "x": -1,
      "y": 0,
      "z": 0,
      "name": "Wood_Deadwood_Planks",
      "rotation": 1
    },
    {
      "x": -1,
      "y": 1,
      "z": 0,
      "name": "Nat20_Force_Empty",
      "rotation": 1
    },
    {
      "x": -1,
      "y": 2,
      "z": 0,
      "name": "Nat20_Force_Empty",
      "rotation": 1
    },
    {
      "x": -1,
      "y": 3,
      "z": 0,
      "name": "Furniture_Lumberjack_Platform",
      "rotation": 1
    },
    {
      "x": -1,
      "y": 4,
      "z": 0,
      "name": "Furniture_Ancient_Barrel",
      "rotation": 1
    },
    {
      "x": -1,
      "y": 5,
      "z": 0,
      "name": "Nat20_Force_Empty",
      "rotation": 1
    },
    {
      "x": -1,
      "y": 6,
      "z": 0,
      "name": "Wood_Redwood_Planks",
      "rotation": 1
    },
    {
      "x": -1,
      "y": 7,
      "z": 0,
      "name": "*Wood_Deadwood_Roof_State_Definitions_Inverted_Corner_Right",
      "rotation": 3
    },
    {
      "x": -1,
      "y": 8,
      "z": 0,
      "name": "Nat20_Force_Empty"
    },
    {
      "x": -1,
      "y": 9,
      "z": 0,
      "name": "Nat20_Force_Empty"
    },
    {
      "x": -1,
      "y": 10,
      "z": 0,
      "name": "Nat20_Force_Empty"
    },
    {
      "x": -1,
      "y": 0,
      "z": 1,
      "name": "Wood_Deadwood_Planks",
      "rotation": 1
    },
    {
      "x": -1,
      "y": 1,
      "z": 1,
      "name": "Nat20_Npc_Spawn"
    },
    {
      "x": -1,
      "y": 2,
      "z": 1,
      "name": "Nat20_Force_Empty",
      "rotation": 1
    },
    {
      "x": -1,
      "y": 3,
      "z": 1,
      "name": "Furniture_Lumberjack_Platform",
      "rotation": 1
    },
    {
      "x": -1,
      "y": 4,
      "z": 1,
      "name": "Nat20_Force_Empty",
      "rotation": 1
    },
    {
      "x": -1,
      "y": 5,
      "z": 1,
      "name": "Nat20_Force_Empty",
      "rotation": 1
    },
    {
      "x": -1,
      "y": 6,
      "z": 1,
      "name": "Nat20_Force_Empty",
      "rotation": 1
    },
    {
      "x": -1,
      "y": 7,
      "z": 1,
      "name": "Wood_Redwood_Trunk",
      "rotation": 5
    },
    {
      "x": -1,
      "y": 8,
      "z": 1,
      "name": "Wood_Deadwood_Roof_Flat",
      "rotation": 2
    },
    {
      "x": -1,
      "y": 9,
      "z": 1,
      "name": "Nat20_Force_Empty"
    },
    {
      "x": -1,
      "y": 10,
      "z": 1,
      "name": "Nat20_Force_Empty"
    },
    {
      "x": -1,
      "y": 0,
      "z": 2,
      "name": "Wood_Deadwood_Planks",
      "rotation": 1
    },
    {
      "x": -1,
      "y": 1,
      "z": 2,
      "name": "Nat20_Force_Empty",
      "rotation": 1
    },
    {
      "x": -1,
      "y": 2,
      "z": 2,
      "name": "Nat20_Force_Empty",
      "rotation": 1
    },
    {
      "x": -1,
      "y": 3,
      "z": 2,
      "name": "Furniture_Lumberjack_Platform",
      "rotation": 1
    },
    {
      "x": -1,
      "y": 4,
      "z": 2,
      "name": "Nat20_Force_Empty",
      "rotation": 1
    },
    {
      "x": -1,
      "y": 5,
      "z": 2,
      "name": "Nat20_Force_Empty",
      "rotation": 1
    },
    {
      "x": -1,
      "y": 6,
      "z": 2,
      "name": "Wood_Redwood_Planks",
      "rotation": 1
    },
    {
      "x": -1,
      "y": 7,
      "z": 2,
      "name": "*Wood_Deadwood_Roof_State_Definitions_Inverted_Corner_Right"
    },
    {
      "x": -1,
      "y": 8,
      "z": 2,
      "name": "Nat20_Force_Empty"
    },
    {
      "x": -1,
      "y": 9,
      "z": 2,
      "name": "Nat20_Force_Empty"
    },
    {
      "x": -1,
      "y": 10,
      "z": 2,
      "name": "Nat20_Force_Empty"
    },
    {
      "x": -1,
      "y": 0,
      "z": 3,
      "name": "Wood_Deadwood_Planks",
      "rotation": 1
    },
    {
      "x": -1,
      "y": 1,
      "z": 3,
      "name": "Furniture_Lumberjack_Shelf",
      "rotation": 2
    },
    {
      "x": -1,
      "y": 2,
      "z": 3,
      "name": "Nat20_Force_Empty",
      "rotation": 1
    },
    {
      "x": -1,
      "y": 3,
      "z": 3,
      "name": "Furniture_Lumberjack_Platform",
      "rotation": 1
    },
    {
      "x": -1,
      "y": 4,
      "z": 3,
      "name": "Nat20_Force_Empty",
      "rotation": 1
    },
    {
      "x": -1,
      "y": 5,
      "z": 3,
      "name": "Nat20_Force_Empty",
      "rotation": 1
    },
    {
      "x": -1,
      "y": 6,
      "z": 3,
      "name": "Wood_Redwood_Planks",
      "rotation": 1
    },
    {
      "x": -1,
      "y": 7,
      "z": 3,
      "name": "Wood_Deadwood_Roof",
      "rotation": 3
    },
    {
      "x": -1,
      "y": 8,
      "z": 3,
      "name": "Nat20_Force_Empty"
    },
    {
      "x": -1,
      "y": 9,
      "z": 3,
      "name": "Nat20_Force_Empty"
    },
    {
      "x": -1,
      "y": 10,
      "z": 3,
      "name": "Nat20_Force_Empty"
    },
    {
      "x": -1,
      "y": 0,
      "z": 4,
      "name": "Wood_Deadwood_Planks",
      "rotation": 1
    },
    {
      "x": -1,
      "y": 1,
      "z": 4,
      "name": "Rock_Shale",
      "rotation": 1
    },
    {
      "x": -1,
      "y": 2,
      "z": 4,
      "name": "Rock_Shale_Brick",
      "rotation": 1
    },
    {
      "x": -1,
      "y": 3,
      "z": 4,
      "name": "Rock_Shale_Brick",
      "rotation": 1
    },
    {
      "x": -1,
      "y": 4,
      "z": 4,
      "name": "Wood_Redwood_Trunk",
      "rotation": 5
    },
    {
      "x": -1,
      "y": 5,
      "z": 4,
      "name": "Wood_Redwood_Trunk",
      "rotation": 5
    },
    {
      "x": -1,
      "y": 6,
      "z": 4,
      "name": "Wood_Redwood_Planks",
      "rotation": 1
    },
    {
      "x": -1,
      "y": 7,
      "z": 4,
      "name": "Wood_Deadwood_Roof",
      "rotation": 3
    },
    {
      "x": -1,
      "y": 8,
      "z": 4,
      "name": "Nat20_Force_Empty"
    },
    {
      "x": -1,
      "y": 9,
      "z": 4,
      "name": "Nat20_Force_Empty"
    },
    {
      "x": -1,
      "y": 10,
      "z": 4,
      "name": "Nat20_Force_Empty"
    },
    {
      "x": -1,
      "y": 0,
      "z": 5,
      "name": "Wood_Deadwood_Planks",
      "rotation": 1
    },
    {
      "x": -1,
      "y": 1,
      "z": 5,
      "name": "Nat20_Force_Empty",
      "rotation": 1
    },
    {
      "x": -1,
      "y": 2,
      "z": 5,
      "name": "Nat20_Force_Empty",
      "rotation": 1
    },
    {
      "x": -1,
      "y": 3,
      "z": 5,
      "name": "Nat20_Force_Empty",
      "rotation": 1
    },
    {
      "x": -1,
      "y": 4,
      "z": 5,
      "name": "Wood_Deadwood_Roof_Flat",
      "rotation": 2
    },
    {
      "x": -1,
      "y": 5,
      "z": 5,
      "name": "Wood_Redwood_Stairs",
      "rotation": 11
    },
    {
      "x": -1,
      "y": 6,
      "z": 5,
      "name": "Wood_Redwood_Stairs",
      "rotation": 3
    },
    {
      "x": -1,
      "y": 7,
      "z": 5,
      "name": "Wood_Deadwood_Roof",
      "rotation": 3
    },
    {
      "x": -1,
      "y": 8,
      "z": 5,
      "name": "Nat20_Force_Empty"
    },
    {
      "x": -1,
      "y": 9,
      "z": 5,
      "name": "Nat20_Force_Empty"
    },
    {
      "x": -1,
      "y": 10,
      "z": 5,
      "name": "Nat20_Force_Empty"
    },
    {
      "x": -1,
      "y": 0,
      "z": 6,
      "name": "Wood_Deadwood_Planks",
      "rotation": 1
    },
    {
      "x": -1,
      "y": 1,
      "z": 6,
      "name": "Wood_Redwood_Branch_Long",
      "rotation": 1
    },
    {
      "x": -1,
      "y": 2,
      "z": 6,
      "name": "Wood_Redwood_Branch_Long",
      "rotation": 1
    },
    {
      "x": -1,
      "y": 3,
      "z": 6,
      "name": "Wood_Redwood_Branch_Long",
      "rotation": 1
    },
    {
      "x": -1,
      "y": 4,
      "z": 6,
      "name": "Wood_Deadwood_Roof_Flat",
      "rotation": 2
    },
    {
      "x": -1,
      "y": 5,
      "z": 6,
      "name": "Nat20_Force_Empty"
    },
    {
      "x": -1,
      "y": 6,
      "z": 6,
      "name": "Nat20_Force_Empty"
    },
    {
      "x": -1,
      "y": 7,
      "z": 6,
      "name": "Nat20_Force_Empty"
    },
    {
      "x": -1,
      "y": 8,
      "z": 6,
      "name": "Nat20_Force_Empty"
    },
    {
      "x": -1,
      "y": 9,
      "z": 6,
      "name": "Nat20_Force_Empty"
    },
    {
      "x": -1,
      "y": 10,
      "z": 6,
      "name": "Nat20_Force_Empty"
    },
    {
      "x": 0,
      "y": 0,
      "z": -5,
      "name": "Wood_Deadwood_Planks",
      "rotation": 1
    },
    {
      "x": 0,
      "y": 1,
      "z": -5,
      "name": "Wood_Redwood_Trunk",
      "rotation": 5
    },
    {
      "x": 0,
      "y": 2,
      "z": -5,
      "name": "Wood_Deadwood_Roof",
      "rotation": 2
    },
    {
      "x": 0,
      "y": 3,
      "z": -5,
      "name": "Nat20_Force_Empty"
    },
    {
      "x": 0,
      "y": 4,
      "z": -5,
      "name": "Nat20_Force_Empty"
    },
    {
      "x": 0,
      "y": 5,
      "z": -5,
      "name": "Nat20_Force_Empty"
    },
    {
      "x": 0,
      "y": 6,
      "z": -5,
      "name": "Nat20_Force_Empty"
    },
    {
      "x": 0,
      "y": 7,
      "z": -5,
      "name": "Nat20_Force_Empty"
    },
    {
      "x": 0,
      "y": 8,
      "z": -5,
      "name": "Nat20_Force_Empty"
    },
    {
      "x": 0,
      "y": 9,
      "z": -5,
      "name": "Nat20_Force_Empty"
    },
    {
      "x": 0,
      "y": 10,
      "z": -5,
      "name": "Nat20_Force_Empty"
    },
    {
      "x": 0,
      "y": 0,
      "z": -4,
      "name": "Wood_Deadwood_Planks",
      "rotation": 1
    },
    {
      "x": 0,
      "y": 1,
      "z": -4,
      "name": "Furniture_Village_Crate",
      "rotation": 1
    },
    {
      "x": 0,
      "y": 2,
      "z": -4,
      "name": "Wood_Redwood_Planks",
      "rotation": 1
    },
    {
      "x": 0,
      "y": 3,
      "z": -4,
      "name": "Wood_Deadwood_Roof",
      "rotation": 2
    },
    {
      "x": 0,
      "y": 4,
      "z": -4,
      "name": "Nat20_Force_Empty"
    },
    {
      "x": 0,
      "y": 5,
      "z": -4,
      "name": "Nat20_Force_Empty"
    },
    {
      "x": 0,
      "y": 6,
      "z": -4,
      "name": "Nat20_Force_Empty"
    },
    {
      "x": 0,
      "y": 7,
      "z": -4,
      "name": "Nat20_Force_Empty"
    },
    {
      "x": 0,
      "y": 8,
      "z": -4,
      "name": "Nat20_Force_Empty"
    },
    {
      "x": 0,
      "y": 9,
      "z": -4,
      "name": "Nat20_Force_Empty"
    },
    {
      "x": 0,
      "y": 10,
      "z": -4,
      "name": "Nat20_Force_Empty"
    },
    {
      "x": 0,
      "y": 0,
      "z": -3,
      "name": "Wood_Deadwood_Planks",
      "rotation": 1
    },
    {
      "x": 0,
      "y": 1,
      "z": -3,
      "name": "Nat20_Force_Empty",
      "rotation": 1
    },
    {
      "x": 0,
      "y": 2,
      "z": -3,
      "name": "Nat20_Force_Empty",
      "rotation": 1
    },
    {
      "x": 0,
      "y": 3,
      "z": -3,
      "name": "Wood_Redwood_Planks",
      "rotation": 1
    },
    {
      "x": 0,
      "y": 4,
      "z": -3,
      "name": "Wood_Redwood_Trunk",
      "rotation": 5
    },
    {
      "x": 0,
      "y": 5,
      "z": -3,
      "name": "Nat20_Force_Empty"
    },
    {
      "x": 0,
      "y": 6,
      "z": -3,
      "name": "Wood_Redwood_Stairs",
      "rotation": 11
    },
    {
      "x": 0,
      "y": 7,
      "z": -3,
      "name": "Wood_Redwood_Stairs",
      "rotation": 3
    },
    {
      "x": 0,
      "y": 8,
      "z": -3,
      "name": "Nat20_Force_Empty"
    },
    {
      "x": 0,
      "y": 9,
      "z": -3,
      "name": "Nat20_Force_Empty"
    },
    {
      "x": 0,
      "y": 10,
      "z": -3,
      "name": "Nat20_Force_Empty"
    },
    {
      "x": 0,
      "y": 0,
      "z": -2,
      "name": "Wood_Deadwood_Planks",
      "rotation": 1
    },
    {
      "x": 0,
      "y": 1,
      "z": -2,
      "name": "Rock_Shale_Brick",
      "rotation": 1
    },
    {
      "x": 0,
      "y": 2,
      "z": -2,
      "name": "Rock_Shale_Brick",
      "rotation": 1
    },
    {
      "x": 0,
      "y": 3,
      "z": -2,
      "name": "Rock_Shale_Brick",
      "rotation": 1
    },
    {
      "x": 0,
      "y": 4,
      "z": -2,
      "name": "Wood_Redwood_Trunk",
      "rotation": 5
    },
    {
      "x": 0,
      "y": 5,
      "z": -2,
      "name": "Wood_Redwood_Planks",
      "rotation": 1
    },
    {
      "x": 0,
      "y": 6,
      "z": -2,
      "name": "Wood_Redwood_Trunk",
      "rotation": 5
    },
    {
      "x": 0,
      "y": 7,
      "z": -2,
      "name": "Wood_Redwood_Planks",
      "rotation": 1
    },
    {
      "x": 0,
      "y": 8,
      "z": -2,
      "name": "Wood_Deadwood_Roof",
      "rotation": 3
    },
    {
      "x": 0,
      "y": 9,
      "z": -2,
      "name": "Nat20_Force_Empty"
    },
    {
      "x": 0,
      "y": 10,
      "z": -2,
      "name": "Nat20_Force_Empty"
    },
    {
      "x": 0,
      "y": 0,
      "z": -1,
      "name": "Wood_Deadwood_Planks",
      "rotation": 1
    },
    {
      "x": 0,
      "y": 1,
      "z": -1,
      "name": "Wood_Redwood_Trunk",
      "rotation": 1
    },
    {
      "x": 0,
      "y": 2,
      "z": -1,
      "name": "Wood_Redwood_Trunk",
      "rotation": 1
    },
    {
      "x": 0,
      "y": 3,
      "z": -1,
      "name": "Wood_Redwood_Trunk",
      "rotation": 1
    },
    {
      "x": 0,
      "y": 4,
      "z": -1,
      "name": "Wood_Redwood_Trunk",
      "rotation": 1
    },
    {
      "x": 0,
      "y": 5,
      "z": -1,
      "name": "Wood_Redwood_Trunk",
      "rotation": 1
    },
    {
      "x": 0,
      "y": 6,
      "z": -1,
      "name": "Wood_Redwood_Trunk",
      "rotation": 1
    },
    {
      "x": 0,
      "y": 7,
      "z": -1,
      "name": "Wood_Redwood_Planks",
      "rotation": 1
    },
    {
      "x": 0,
      "y": 8,
      "z": -1,
      "name": "Wood_Deadwood_Roof",
      "rotation": 3
    },
    {
      "x": 0,
      "y": 9,
      "z": -1,
      "name": "Nat20_Force_Empty"
    },
    {
      "x": 0,
      "y": 10,
      "z": -1,
      "name": "Nat20_Force_Empty"
    },
    {
      "x": 0,
      "y": 0,
      "z": 0,
      "name": "Wood_Deadwood_Planks"
    },
    {
      "x": 0,
      "y": 1,
      "z": 0,
      "name": "Wood_Softwood_Fence",
      "rotation": 3
    },
    {
      "x": 0,
      "y": 2,
      "z": 0,
      "name": "Wood_Softwood_Fence",
      "rotation": 3
    },
    {
      "x": 0,
      "y": 3,
      "z": 0,
      "name": "Wood_Redwood_Trunk",
      "rotation": 6
    },
    {
      "x": 0,
      "y": 4,
      "z": 0,
      "name": "Nat20_Force_Empty",
      "rotation": 1
    },
    {
      "x": 0,
      "y": 5,
      "z": 0,
      "name": "Nat20_Force_Empty",
      "rotation": 1
    },
    {
      "x": 0,
      "y": 6,
      "z": 0,
      "name": "Nat20_Force_Empty",
      "rotation": 1
    },
    {
      "x": 0,
      "y": 7,
      "z": 0,
      "name": "Wood_Redwood_Planks",
      "rotation": 1
    },
    {
      "x": 0,
      "y": 8,
      "z": 0,
      "name": "Wood_Deadwood_Roof",
      "rotation": 3
    },
    {
      "x": 0,
      "y": 9,
      "z": 0,
      "name": "Nat20_Force_Empty"
    },
    {
      "x": 0,
      "y": 10,
      "z": 0,
      "name": "Nat20_Force_Empty"
    },
    {
      "x": 0,
      "y": 0,
      "z": 1,
      "name": "Wood_Deadwood_Planks",
      "rotation": 1
    },
    {
      "x": 0,
      "y": 1,
      "z": 1,
      "name": "Nat20_Force_Empty",
      "rotation": 1
    },
    {
      "x": 0,
      "y": 2,
      "z": 1,
      "name": "Nat20_Force_Empty",
      "rotation": 1
    },
    {
      "x": 0,
      "y": 3,
      "z": 1,
      "name": "Wood_Redwood_Trunk",
      "rotation": 6
    },
    {
      "x": 0,
      "y": 4,
      "z": 1,
      "name": "Nat20_Force_Empty",
      "rotation": 1
    },
    {
      "x": 0,
      "y": 5,
      "z": 1,
      "name": "Nat20_Force_Empty",
      "rotation": 1
    },
    {
      "x": 0,
      "y": 6,
      "z": 1,
      "name": "Nat20_Force_Empty",
      "rotation": 1
    },
    {
      "x": 0,
      "y": 7,
      "z": 1,
      "name": "Wood_Redwood_Trunk",
      "rotation": 5
    },
    {
      "x": 0,
      "y": 8,
      "z": 1,
      "name": "Wood_Deadwood_Roof",
      "rotation": 3
    },
    {
      "x": 0,
      "y": 9,
      "z": 1,
      "name": "Nat20_Force_Empty"
    },
    {
      "x": 0,
      "y": 10,
      "z": 1,
      "name": "Nat20_Force_Empty"
    },
    {
      "x": 0,
      "y": 0,
      "z": 2,
      "name": "Wood_Deadwood_Planks",
      "rotation": 1
    },
    {
      "x": 0,
      "y": 1,
      "z": 2,
      "name": "Nat20_Force_Empty",
      "rotation": 1
    },
    {
      "x": 0,
      "y": 2,
      "z": 2,
      "name": "Nat20_Force_Empty",
      "rotation": 1
    },
    {
      "x": 0,
      "y": 3,
      "z": 2,
      "name": "Wood_Redwood_Trunk",
      "rotation": 6
    },
    {
      "x": 0,
      "y": 4,
      "z": 2,
      "name": "Nat20_Force_Empty",
      "rotation": 1
    },
    {
      "x": 0,
      "y": 5,
      "z": 2,
      "name": "Nat20_Force_Empty",
      "rotation": 1
    },
    {
      "x": 0,
      "y": 6,
      "z": 2,
      "name": "Nat20_Force_Empty",
      "rotation": 1
    },
    {
      "x": 0,
      "y": 7,
      "z": 2,
      "name": "Wood_Redwood_Planks",
      "rotation": 1
    },
    {
      "x": 0,
      "y": 8,
      "z": 2,
      "name": "Wood_Deadwood_Roof",
      "rotation": 3
    },
    {
      "x": 0,
      "y": 9,
      "z": 2,
      "name": "Nat20_Force_Empty"
    },
    {
      "x": 0,
      "y": 10,
      "z": 2,
      "name": "Nat20_Force_Empty"
    },
    {
      "x": 0,
      "y": 0,
      "z": 3,
      "name": "Wood_Deadwood_Planks",
      "rotation": 1
    },
    {
      "x": 0,
      "y": 1,
      "z": 3,
      "name": "Nat20_Force_Empty",
      "rotation": 1
    },
    {
      "x": 0,
      "y": 2,
      "z": 3,
      "name": "Nat20_Force_Empty",
      "rotation": 1
    },
    {
      "x": 0,
      "y": 3,
      "z": 3,
      "name": "Wood_Redwood_Trunk",
      "rotation": 6
    },
    {
      "x": 0,
      "y": 4,
      "z": 3,
      "name": "Nat20_Force_Empty",
      "rotation": 1
    },
    {
      "x": 0,
      "y": 5,
      "z": 3,
      "name": "Nat20_Force_Empty",
      "rotation": 1
    },
    {
      "x": 0,
      "y": 6,
      "z": 3,
      "name": "Nat20_Force_Empty",
      "rotation": 1
    },
    {
      "x": 0,
      "y": 7,
      "z": 3,
      "name": "Wood_Redwood_Planks",
      "rotation": 1
    },
    {
      "x": 0,
      "y": 8,
      "z": 3,
      "name": "Wood_Deadwood_Roof",
      "rotation": 3
    },
    {
      "x": 0,
      "y": 9,
      "z": 3,
      "name": "Nat20_Force_Empty"
    },
    {
      "x": 0,
      "y": 10,
      "z": 3,
      "name": "Nat20_Force_Empty"
    },
    {
      "x": 0,
      "y": 0,
      "z": 4,
      "name": "Wood_Deadwood_Planks",
      "rotation": 1
    },
    {
      "x": 0,
      "y": 1,
      "z": 4,
      "name": "Rock_Shale",
      "rotation": 1
    },
    {
      "x": 0,
      "y": 2,
      "z": 4,
      "name": "Rock_Shale_Brick",
      "rotation": 1
    },
    {
      "x": 0,
      "y": 3,
      "z": 4,
      "name": "Rock_Shale_Brick",
      "rotation": 1
    },
    {
      "x": 0,
      "y": 4,
      "z": 4,
      "name": "Wood_Redwood_Trunk",
      "rotation": 5
    },
    {
      "x": 0,
      "y": 5,
      "z": 4,
      "name": "Wood_Redwood_Trunk",
      "rotation": 5
    },
    {
      "x": 0,
      "y": 6,
      "z": 4,
      "name": "Wood_Redwood_Trunk",
      "rotation": 5
    },
    {
      "x": 0,
      "y": 7,
      "z": 4,
      "name": "Wood_Redwood_Planks",
      "rotation": 1
    },
    {
      "x": 0,
      "y": 8,
      "z": 4,
      "name": "Wood_Deadwood_Roof",
      "rotation": 3
    },
    {
      "x": 0,
      "y": 9,
      "z": 4,
      "name": "Nat20_Force_Empty"
    },
    {
      "x": 0,
      "y": 10,
      "z": 4,
      "name": "Nat20_Force_Empty"
    },
    {
      "x": 0,
      "y": 0,
      "z": 5,
      "name": "Wood_Deadwood_Planks",
      "rotation": 1
    },
    {
      "x": 0,
      "y": 1,
      "z": 5,
      "name": "Nat20_Force_Empty",
      "rotation": 1
    },
    {
      "x": 0,
      "y": 2,
      "z": 5,
      "name": "Wood_Torch_Wall"
    },
    {
      "x": 0,
      "y": 3,
      "z": 5,
      "name": "Nat20_Force_Empty",
      "rotation": 1
    },
    {
      "x": 0,
      "y": 4,
      "z": 5,
      "name": "Wood_Deadwood_Roof"
    },
    {
      "x": 0,
      "y": 5,
      "z": 5,
      "name": "Nat20_Force_Empty"
    },
    {
      "x": 0,
      "y": 6,
      "z": 5,
      "name": "Wood_Redwood_Stairs",
      "rotation": 11
    },
    {
      "x": 0,
      "y": 7,
      "z": 5,
      "name": "Wood_Redwood_Stairs",
      "rotation": 3
    },
    {
      "x": 0,
      "y": 8,
      "z": 5,
      "name": "Wood_Deadwood_Roof",
      "rotation": 3
    },
    {
      "x": 0,
      "y": 9,
      "z": 5,
      "name": "Nat20_Force_Empty"
    },
    {
      "x": 0,
      "y": 10,
      "z": 5,
      "name": "Nat20_Force_Empty"
    },
    {
      "x": 0,
      "y": 0,
      "z": 6,
      "name": "Wood_Deadwood_Planks",
      "rotation": 1
    },
    {
      "x": 0,
      "y": 1,
      "z": 6,
      "name": "Nat20_Force_Empty",
      "rotation": 1
    },
    {
      "x": 0,
      "y": 2,
      "z": 6,
      "name": "Nat20_Force_Empty",
      "rotation": 1
    },
    {
      "x": 0,
      "y": 3,
      "z": 6,
      "name": "Nat20_Force_Empty",
      "rotation": 1
    },
    {
      "x": 0,
      "y": 4,
      "z": 6,
      "name": "Wood_Deadwood_Roof_Flat",
      "rotation": 2
    },
    {
      "x": 0,
      "y": 5,
      "z": 6,
      "name": "Nat20_Force_Empty"
    },
    {
      "x": 0,
      "y": 6,
      "z": 6,
      "name": "Nat20_Force_Empty"
    },
    {
      "x": 0,
      "y": 7,
      "z": 6,
      "name": "Nat20_Force_Empty"
    },
    {
      "x": 0,
      "y": 8,
      "z": 6,
      "name": "Nat20_Force_Empty"
    },
    {
      "x": 0,
      "y": 9,
      "z": 6,
      "name": "Nat20_Force_Empty"
    },
    {
      "x": 0,
      "y": 10,
      "z": 6,
      "name": "Nat20_Force_Empty"
    },
    {
      "x": 1,
      "y": 0,
      "z": -5,
      "name": "Wood_Deadwood_Planks",
      "rotation": 1
    },
    {
      "x": 1,
      "y": 1,
      "z": -5,
      "name": "Wood_Redwood_Trunk",
      "rotation": 5
    },
    {
      "x": 1,
      "y": 2,
      "z": -5,
      "name": "Wood_Deadwood_Roof",
      "rotation": 2
    },
    {
      "x": 1,
      "y": 3,
      "z": -5,
      "name": "Nat20_Force_Empty"
    },
    {
      "x": 1,
      "y": 4,
      "z": -5,
      "name": "Nat20_Force_Empty"
    },
    {
      "x": 1,
      "y": 5,
      "z": -5,
      "name": "Nat20_Force_Empty"
    },
    {
      "x": 1,
      "y": 6,
      "z": -5,
      "name": "Nat20_Force_Empty"
    },
    {
      "x": 1,
      "y": 7,
      "z": -5,
      "name": "Nat20_Force_Empty"
    },
    {
      "x": 1,
      "y": 8,
      "z": -5,
      "name": "Nat20_Force_Empty"
    },
    {
      "x": 1,
      "y": 9,
      "z": -5,
      "name": "Nat20_Force_Empty"
    },
    {
      "x": 1,
      "y": 10,
      "z": -5,
      "name": "Nat20_Force_Empty"
    },
    {
      "x": 1,
      "y": 0,
      "z": -4,
      "name": "Wood_Deadwood_Planks",
      "rotation": 1
    },
    {
      "x": 1,
      "y": 1,
      "z": -4,
      "name": "Nat20_Force_Empty",
      "rotation": 1
    },
    {
      "x": 1,
      "y": 2,
      "z": -4,
      "name": "Wood_Redwood_Planks",
      "rotation": 1
    },
    {
      "x": 1,
      "y": 3,
      "z": -4,
      "name": "Wood_Deadwood_Roof",
      "rotation": 2
    },
    {
      "x": 1,
      "y": 4,
      "z": -4,
      "name": "Nat20_Force_Empty"
    },
    {
      "x": 1,
      "y": 5,
      "z": -4,
      "name": "Nat20_Force_Empty"
    },
    {
      "x": 1,
      "y": 6,
      "z": -4,
      "name": "Nat20_Force_Empty"
    },
    {
      "x": 1,
      "y": 7,
      "z": -4,
      "name": "Wood_Redwood_Stairs",
      "rotation": 8
    },
    {
      "x": 1,
      "y": 8,
      "z": -4,
      "name": "Wood_Redwood_Trunk",
      "rotation": 6
    },
    {
      "x": 1,
      "y": 9,
      "z": -4,
      "name": "Nat20_Force_Empty"
    },
    {
      "x": 1,
      "y": 10,
      "z": -4,
      "name": "Nat20_Force_Empty"
    },
    {
      "x": 1,
      "y": 0,
      "z": -3,
      "name": "Wood_Deadwood_Planks",
      "rotation": 1
    },
    {
      "x": 1,
      "y": 1,
      "z": -3,
      "name": "Nat20_Force_Empty",
      "rotation": 1
    },
    {
      "x": 1,
      "y": 2,
      "z": -3,
      "name": "Nat20_Force_Empty",
      "rotation": 1
    },
    {
      "x": 1,
      "y": 3,
      "z": -3,
      "name": "Wood_Redwood_Planks",
      "rotation": 1
    },
    {
      "x": 1,
      "y": 4,
      "z": -3,
      "name": "Wood_Redwood_Trunk",
      "rotation": 5
    },
    {
      "x": 1,
      "y": 5,
      "z": -3,
      "name": "Nat20_Force_Empty"
    },
    {
      "x": 1,
      "y": 6,
      "z": -3,
      "name": "Nat20_Force_Empty"
    },
    {
      "x": 1,
      "y": 7,
      "z": -3,
      "name": "Wood_Redwood_Planks",
      "rotation": 1
    },
    {
      "x": 1,
      "y": 8,
      "z": -3,
      "name": "Wood_Redwood_Trunk",
      "rotation": 6
    },
    {
      "x": 1,
      "y": 9,
      "z": -3,
      "name": "Nat20_Force_Empty"
    },
    {
      "x": 1,
      "y": 10,
      "z": -3,
      "name": "Nat20_Force_Empty"
    },
    {
      "x": 1,
      "y": 0,
      "z": -2,
      "name": "Wood_Deadwood_Planks",
      "rotation": 1
    },
    {
      "x": 1,
      "y": 1,
      "z": -2,
      "name": "Rock_Shale_Brick",
      "rotation": 1
    },
    {
      "x": 1,
      "y": 2,
