{
  "version": 8,
  "blockIdVersion": 11,
  "anchorX": 0,
  "anchorY": 0,
  "anchorZ": 0,
  "blocks": [
    {
      "x": -10,
      "y": 3,
      "z": -11,
      "name": "Nat20_Force_Empty"
    },
    {
      "x": -10,
      "y": 4,
      "z": -11,
      "name": "Nat20_Force_Empty"
    },
    {
      "x": -10,
      "y": 5,
      "z": -11,
      "name": "Nat20_Force_Empty"
    },
    {
      "x": -10,
      "y": 6,
      "z": -11,
      "name": "Nat20_Force_Empty"
    },
    {
      "x": -10,
      "y": 7,
      "z": -11,
      "name": "Nat20_Force_Empty"
    },
    {
      "x": -10,
      "y": 8,
      "z": -11,
      "name": "Nat20_Force_Empty"
    },
    {
      "x": -10,
      "y": 9,
      "z": -11,
      "name": "Nat20_Force_Empty"
    },
    {
      "x": -10,
      "y": 10,
      "z": -11,
      "name": "Nat20_Force_Empty"
    },
    {
      "x": -10,
      "y": 11,
      "z": -11,
      "name": "Nat20_Force_Empty"
    },
    {
      "x": -10,
      "y": 12,
      "z": -11,
      "name": "Nat20_Force_Empty"
    },
    {
      "x": -10,
      "y": 13,
      "z": -11,
      "name": "Nat20_Force_Empty"
    },
    {
      "x": -10,
      "y": 14,
      "z": -11,
      "name": "Nat20_Force_Empty"
    },
    {
      "x": -10,
      "y": 15,
      "z": -11,
      "name": "Nat20_Force_Empty"
    },
    {
      "x": -10,
      "y": 16,
      "z": -11,
      "name": "Nat20_Force_Empty"
    },
    {
      "x": -10,
      "y": 3,
      "z": -10,
      "name": "Nat20_Force_Empty"
    },
    {
      "x": -10,
      "y": 4,
      "z": -10,
      "name": "Nat20_Force_Empty"
    },
    {
      "x": -10,
      "y": 5,
      "z": -10,
      "name": "Nat20_Force_Empty"
    },
    {
      "x": -10,
      "y": 6,
      "z": -10,
      "name": "Nat20_Force_Empty"
    },
    {
      "x": -10,
      "y": 7,
      "z": -10,
      "name": "Nat20_Force_Empty"
    },
    {
      "x": -10,
      "y": 8,
      "z": -10,
      "name": "Nat20_Force_Empty"
    },
    {
      "x": -10,
      "y": 9,
      "z": -10,
      "name": "Nat20_Force_Empty"
    },
    {
      "x": -10,
      "y": 10,
      "z": -10,
      "name": "Nat20_Force_Empty"
    },
    {
      "x": -10,
      "y": 11,
      "z": -10,
      "name": "Nat20_Force_Empty"
    },
    {
      "x": -10,
      "y": 12,
      "z": -10,
      "name": "Nat20_Force_Empty"
    },
    {
      "x": -10,
      "y": 13,
      "z": -10,
      "name": "Nat20_Force_Empty"
    },
    {
      "x": -10,
      "y": 14,
      "z": -10,
      "name": "Nat20_Force_Empty"
    },
    {
      "x": -10,
      "y": 15,
      "z": -10,
      "name": "Nat20_Force_Empty"
    },
    {
      "x": -10,
      "y": 16,
      "z": -10,
      "name": "Nat20_Force_Empty"
    },
    {
      "x": -10,
      "y": 3,
      "z": -9,
      "name": "Nat20_Force_Empty"
    },
    {
      "x": -10,
      "y": 4,
      "z": -9,
      "name": "Nat20_Force_Empty"
    },
    {
      "x": -10,
      "y": 5,
      "z": -9,
      "name": "Nat20_Force_Empty"
    },
    {
      "x": -10,
      "y": 6,
      "z": -9,
      "name": "Nat20_Force_Empty"
    },
    {
      "x": -10,
      "y": 7,
      "z": -9,
      "name": "Nat20_Force_Empty"
    },
    {
      "x": -10,
      "y": 8,
      "z": -9,
      "name": "Nat20_Force_Empty"
    },
    {
      "x": -10,
      "y": 9,
      "z": -9,
      "name": "Nat20_Force_Empty"
    },
    {
      "x": -10,
      "y": 10,
      "z": -9,
      "name": "Nat20_Force_Empty"
    },
    {
      "x": -10,
      "y": 11,
      "z": -9,
      "name": "Nat20_Force_Empty"
    },
    {
      "x": -10,
      "y": 12,
      "z": -9,
      "name": "Nat20_Force_Empty"
    },
    {
      "x": -10,
      "y": 13,
      "z": -9,
      "name": "Nat20_Force_Empty"
    },
    {
      "x": -10,
      "y": 14,
      "z": -9,
      "name": "Nat20_Force_Empty"
    },
    {
      "x": -10,
      "y": 15,
      "z": -9,
      "name": "Nat20_Force_Empty"
    },
    {
      "x": -10,
      "y": 16,
      "z": -9,
      "name": "Nat20_Force_Empty"
    },
    {
      "x": -10,
      "y": 3,
      "z": -8,
      "name": "Nat20_Force_Empty"
    },
    {
      "x": -10,
      "y": 4,
      "z": -8,
      "name": "Nat20_Force_Empty"
    },
    {
      "x": -10,
      "y": 5,
      "z": -8,
      "name": "Nat20_Force_Empty"
    },
    {
      "x": -10,
      "y": 6,
      "z": -8,
      "name": "Nat20_Force_Empty"
    },
    {
      "x": -10,
      "y": 7,
      "z": -8,
      "name": "Nat20_Force_Empty"
    },
    {
      "x": -10,
      "y": 8,
      "z": -8,
      "name": "Nat20_Force_Empty"
    },
    {
      "x": -10,
      "y": 9,
      "z": -8,
      "name": "Nat20_Force_Empty"
    },
    {
      "x": -10,
      "y": 10,
      "z": -8,
      "name": "Nat20_Force_Empty"
    },
    {
      "x": -10,
      "y": 11,
      "z": -8,
      "name": "Nat20_Force_Empty"
    },
    {
      "x": -10,
      "y": 12,
      "z": -8,
      "name": "Nat20_Force_Empty"
    },
    {
      "x": -10,
      "y": 13,
      "z": -8,
      "name": "Nat20_Force_Empty"
    },
    {
      "x": -10,
      "y": 14,
      "z": -8,
      "name": "Nat20_Force_Empty"
    },
    {
      "x": -10,
      "y": 15,
      "z": -8,
      "name": "Nat20_Force_Empty"
    },
    {
      "x": -10,
      "y": 16,
      "z": -8,
      "name": "Nat20_Force_Empty"
    },
    {
      "x": -10,
      "y": 3,
      "z": -7,
      "name": "Nat20_Force_Empty"
    },
    {
      "x": -10,
      "y": 4,
      "z": -7,
      "name": "Nat20_Force_Empty"
    },
    {
      "x": -10,
      "y": 5,
      "z": -7,
      "name": "Nat20_Force_Empty"
    },
    {
      "x": -10,
      "y": 6,
      "z": -7,
      "name": "Nat20_Force_Empty"
    },
    {
      "x": -10,
      "y": 7,
      "z": -7,
      "name": "Nat20_Force_Empty"
    },
    {
      "x": -10,
      "y": 8,
      "z": -7,
      "name": "Nat20_Force_Empty"
    },
    {
      "x": -10,
      "y": 9,
      "z": -7,
      "name": "Nat20_Force_Empty"
    },
    {
      "x": -10,
      "y": 10,
      "z": -7,
      "name": "Nat20_Force_Empty"
    },
    {
      "x": -10,
      "y": 11,
      "z": -7,
      "name": "Nat20_Force_Empty"
    },
    {
      "x": -10,
      "y": 12,
      "z": -7,
      "name": "Nat20_Force_Empty"
    },
    {
      "x": -10,
      "y": 13,
      "z": -7,
      "name": "Nat20_Force_Empty"
    },
    {
      "x": -10,
      "y": 14,
      "z": -7,
      "name": "Nat20_Force_Empty"
    },
    {
      "x": -10,
      "y": 15,
      "z": -7,
      "name": "Nat20_Force_Empty"
    },
    {
      "x": -10,
      "y": 16,
      "z": -7,
      "name": "Nat20_Force_Empty"
    },
    {
      "x": -10,
      "y": 3,
      "z": -6,
      "name": "Nat20_Force_Empty"
    },
    {
      "x": -10,
      "y": 4,
      "z": -6,
      "name": "Nat20_Force_Empty"
    },
    {
      "x": -10,
      "y": 5,
      "z": -6,
      "name": "Nat20_Force_Empty"
    },
    {
      "x": -10,
      "y": 6,
      "z": -6,
      "name": "Nat20_Force_Empty"
    },
    {
      "x": -10,
      "y": 7,
      "z": -6,
      "name": "Nat20_Force_Empty"
    },
    {
      "x": -10,
      "y": 8,
      "z": -6,
      "name": "Nat20_Force_Empty"
    },
    {
      "x": -10,
      "y": 9,
      "z": -6,
      "name": "Nat20_Force_Empty"
    },
    {
      "x": -10,
      "y": 10,
      "z": -6,
      "name": "Nat20_Force_Empty"
    },
    {
      "x": -10,
      "y": 11,
      "z": -6,
      "name": "Nat20_Force_Empty"
    },
    {
      "x": -10,
      "y": 12,
      "z": -6,
      "name": "Nat20_Force_Empty"
    },
    {
      "x": -10,
      "y": 13,
      "z": -6,
      "name": "Nat20_Force_Empty"
    },
    {
      "x": -10,
      "y": 14,
      "z": -6,
      "name": "Nat20_Force_Empty"
    },
    {
      "x": -10,
      "y": 15,
      "z": -6,
      "name": "Nat20_Force_Empty"
    },
    {
      "x": -10,
      "y": 16,
      "z": -6,
      "name": "Nat20_Force_Empty"
    },
    {
      "x": -10,
      "y": 3,
      "z": -5,
      "name": "Nat20_Force_Empty"
    },
    {
      "x": -10,
      "y": 4,
      "z": -5,
      "name": "Nat20_Force_Empty"
    },
    {
      "x": -10,
      "y": 5,
      "z": -5,
      "name": "Nat20_Force_Empty"
    },
    {
      "x": -10,
      "y": 6,
      "z": -5,
      "name": "Nat20_Force_Empty"
    },
    {
      "x": -10,
      "y": 7,
      "z": -5,
      "name": "Nat20_Force_Empty"
    },
    {
      "x": -10,
      "y": 8,
      "z": -5,
      "name": "Nat20_Force_Empty"
    },
    {
      "x": -10,
      "y": 9,
      "z": -5,
      "name": "Nat20_Force_Empty"
    },
    {
      "x": -10,
      "y": 10,
      "z": -5,
      "name": "Nat20_Force_Empty"
    },
    {
      "x": -10,
      "y": 11,
      "z": -5,
      "name": "Nat20_Force_Empty"
    },
    {
      "x": -10,
      "y": 12,
      "z": -5,
      "name": "Nat20_Force_Empty"
    },
    {
      "x": -10,
      "y": 13,
      "z": -5,
      "name": "Nat20_Force_Empty"
    },
    {
      "x": -10,
      "y": 14,
      "z": -5,
      "name": "Nat20_Force_Empty"
    },
    {
      "x": -10,
      "y": 15,
      "z": -5,
      "name": "Nat20_Force_Empty"
    },
    {
      "x": -10,
      "y": 16,
      "z": -5,
      "name": "Nat20_Force_Empty"
    },
    {
      "x": -10,
      "y": 0,
      "z": -4,
      "name": "Wood_Beech_Trunk",
      "support": 15
    },
    {
      "x": -10,
      "y": 1,
      "z": -4,
      "name": "Wood_Beech_Trunk",
      "support": 15
    },
    {
      "x": -10,
      "y": 2,
      "z": -4,
      "name": "Wood_Beech_Trunk",
      "support": 15
    },
    {
      "x": -10,
      "y": 3,
      "z": -4,
      "name": "Wood_Beech_Trunk",
      "support": 15
    },
    {
      "x": -10,
      "y": 4,
      "z": -4,
      "name": "Wood_Beech_Trunk",
      "support": 15
    },
    {
      "x": -10,
      "y": 5,
      "z": -4,
      "name": "Wood_Beech_Trunk",
      "support": 15
    },
    {
      "x": -10,
      "y": 6,
      "z": -4,
      "name": "Wood_Deadwood_Roof_Shallow",
      "rotation": 3
    },
    {
      "x": -10,
      "y": 7,
      "z": -4,
      "name": "Nat20_Force_Empty"
    },
    {
      "x": -10,
      "y": 8,
      "z": -4,
      "name": "Nat20_Force_Empty"
    },
    {
      "x": -10,
      "y": 9,
      "z": -4,
      "name": "Nat20_Force_Empty"
    },
    {
      "x": -10,
      "y": 10,
      "z": -4,
      "name": "Nat20_Force_Empty"
    },
    {
      "x": -10,
      "y": 11,
      "z": -4,
      "name": "Nat20_Force_Empty"
    },
    {
      "x": -10,
      "y": 12,
      "z": -4,
      "name": "Nat20_Force_Empty"
    },
    {
      "x": -10,
      "y": 13,
      "z": -4,
      "name": "Nat20_Force_Empty"
    },
    {
      "x": -10,
      "y": 14,
      "z": -4,
      "name": "Nat20_Force_Empty"
    },
    {
      "x": -10,
      "y": 15,
      "z": -4,
      "name": "Nat20_Force_Empty"
    },
    {
      "x": -10,
      "y": 16,
      "z": -4,
      "name": "Nat20_Force_Empty"
    },
    {
      "x": -10,
      "y": 2,
      "z": -3,
      "name": "Rock_Stone_Cobble"
    },
    {
      "x": -10,
      "y": 3,
      "z": -3,
      "name": "Wood_Softwood_Stairs"
    },
    {
      "x": -10,
      "y": 4,
      "z": -3,
      "name": "Nat20_Force_Empty"
    },
    {
      "x": -10,
      "y": 5,
      "z": -3,
      "name": "Wood_Softwood_Planks"
    },
    {
      "x": -10,
      "y": 6,
      "z": -3,
      "name": "Wood_Deadwood_Roof_Shallow",
      "rotation": 3
    },
    {
      "x": -10,
      "y": 7,
      "z": -3,
      "name": "Nat20_Force_Empty"
    },
    {
      "x": -10,
      "y": 8,
      "z": -3,
      "name": "Nat20_Force_Empty"
    },
    {
      "x": -10,
      "y": 9,
      "z": -3,
      "name": "Nat20_Force_Empty"
    },
    {
      "x": -10,
      "y": 10,
      "z": -3,
      "name": "Nat20_Force_Empty"
    },
    {
      "x": -10,
      "y": 11,
      "z": -3,
      "name": "Nat20_Force_Empty"
    },
    {
      "x": -10,
      "y": 12,
      "z": -3,
      "name": "Nat20_Force_Empty"
    },
    {
      "x": -10,
      "y": 13,
      "z": -3,
      "name": "Nat20_Force_Empty"
    },
    {
      "x": -10,
      "y": 14,
      "z": -3,
      "name": "Nat20_Force_Empty"
    },
    {
      "x": -10,
      "y": 15,
      "z": -3,
      "name": "Nat20_Force_Empty"
    },
    {
      "x": -10,
      "y": 16,
      "z": -3,
      "name": "Nat20_Force_Empty"
    },
    {
      "x": -10,
      "y": 2,
      "z": -2,
      "name": "Rock_Stone_Cobble"
    },
    {
      "x": -10,
      "y": 3,
      "z": -2,
      "name": "Wood_Softwood_Beam",
      "rotation": 4
    },
    {
      "x": -10,
      "y": 4,
      "z": -2,
      "name": "Nat20_Force_Empty"
    },
    {
      "x": -10,
      "y": 5,
      "z": -2,
      "name": "Wood_Softwood_Fence",
      "rotation": 3
    },
    {
      "x": -10,
      "y": 6,
      "z": -2,
      "name": "Wood_Deadwood_Roof_Shallow",
      "rotation": 3
    },
    {
      "x": -10,
      "y": 7,
      "z": -2,
      "name": "Nat20_Force_Empty"
    },
    {
      "x": -10,
      "y": 8,
      "z": -2,
      "name": "Nat20_Force_Empty"
    },
    {
      "x": -10,
      "y": 9,
      "z": -2,
      "name": "Nat20_Force_Empty"
    },
    {
      "x": -10,
      "y": 10,
      "z": -2,
      "name": "Nat20_Force_Empty"
    },
    {
      "x": -10,
      "y": 11,
      "z": -2,
      "name": "Nat20_Force_Empty"
    },
    {
      "x": -10,
      "y": 12,
      "z": -2,
      "name": "Nat20_Force_Empty"
    },
    {
      "x": -10,
      "y": 13,
      "z": -2,
      "name": "Nat20_Force_Empty"
    },
    {
      "x": -10,
      "y": 14,
      "z": -2,
      "name": "Nat20_Force_Empty"
    },
    {
      "x": -10,
      "y": 15,
      "z": -2,
      "name": "Nat20_Force_Empty"
    },
    {
      "x": -10,
      "y": 16,
      "z": -2,
      "name": "Nat20_Force_Empty"
    },
    {
      "x": -10,
      "y": 2,
      "z": -1,
      "name": "Rock_Stone_Cobble"
    },
    {
      "x": -10,
      "y": 3,
      "z": -1,
      "name": "Wood_Softwood_Planks"
    },
    {
      "x": -10,
      "y": 4,
      "z": -1,
      "name": "Wood_Softwood_Fence",
      "rotation": 3
    },
    {
      "x": -10,
      "y": 5,
      "z": -1,
      "name": "Wood_Softwood_Fence",
      "rotation": 3
    },
    {
      "x": -10,
      "y": 6,
      "z": -1,
      "name": "Wood_Deadwood_Roof_Shallow",
      "rotation": 3
    },
    {
      "x": -10,
      "y": 7,
      "z": -1,
      "name": "Nat20_Force_Empty"
    },
    {
      "x": -10,
      "y": 8,
      "z": -1,
      "name": "Nat20_Force_Empty"
    },
    {
      "x": -10,
      "y": 9,
      "z": -1,
      "name": "Nat20_Force_Empty"
    },
    {
      "x": -10,
      "y": 10,
      "z": -1,
      "name": "Nat20_Force_Empty"
    },
    {
      "x": -10,
      "y": 11,
      "z": -1,
      "name": "Nat20_Force_Empty"
    },
    {
      "x": -10,
      "y": 12,
      "z": -1,
      "name": "Nat20_Force_Empty"
    },
    {
      "x": -10,
      "y": 13,
      "z": -1,
      "name": "Nat20_Force_Empty"
    },
    {
      "x": -10,
      "y": 14,
      "z": -1,
      "name": "Nat20_Force_Empty"
    },
    {
      "x": -10,
      "y": 15,
      "z": -1,
      "name": "Nat20_Force_Empty"
    },
    {
      "x": -10,
      "y": 16,
      "z": -1,
      "name": "Nat20_Force_Empty"
    },
    {
      "x": -10,
      "y": 0,
      "z": 0,
      "name": "Wood_Beech_Trunk",
      "support": 15
    },
    {
      "x": -10,
      "y": 1,
      "z": 0,
      "name": "Wood_Beech_Trunk",
      "support": 15
    },
    {
      "x": -10,
      "y": 2,
      "z": 0,
      "name": "Wood_Beech_Trunk",
      "support": 15
    },
    {
      "x": -10,
      "y": 3,
      "z": 0,
      "name": "Wood_Beech_Trunk",
      "support": 15
    },
    {
      "x": -10,
      "y": 4,
      "z": 0,
      "name": "Wood_Beech_Trunk",
      "support": 15
    },
    {
      "x": -10,
      "y": 5,
      "z": 0,
      "name": "Wood_Beech_Trunk",
      "support": 15
    },
    {
      "x": -10,
      "y": 6,
      "z": 0,
      "name": "Wood_Deadwood_Roof_Shallow",
      "rotation": 3
    },
    {
      "x": -10,
      "y": 7,
      "z": 0,
      "name": "Nat20_Force_Empty"
    },
    {
      "x": -10,
      "y": 8,
      "z": 0,
      "name": "Nat20_Force_Empty"
    },
    {
      "x": -10,
      "y": 9,
      "z": 0,
      "name": "Nat20_Force_Empty"
    },
    {
      "x": -10,
      "y": 10,
      "z": 0,
      "name": "Nat20_Force_Empty"
    },
    {
      "x": -10,
      "y": 11,
      "z": 0,
      "name": "Nat20_Force_Empty"
    },
    {
      "x": -10,
      "y": 12,
      "z": 0,
      "name": "Nat20_Force_Empty"
    },
    {
      "x": -10,
      "y": 13,
      "z": 0,
      "name": "Nat20_Force_Empty"
    },
    {
      "x": -10,
      "y": 14,
      "z": 0,
      "name": "Nat20_Force_Empty"
    },
    {
      "x": -10,
      "y": 15,
      "z": 0,
      "name": "Nat20_Force_Empty"
    },
    {
      "x": -10,
      "y": 16,
      "z": 0,
      "name": "Nat20_Force_Empty"
    },
    {
      "x": -10,
      "y": 2,
      "z": 1,
      "name": "Rock_Stone_Cobble"
    },
    {
      "x": -10,
      "y": 3,
      "z": 1,
      "name": "Wood_Softwood_Planks"
    },
    {
      "x": -10,
      "y": 4,
      "z": 1,
      "name": "Wood_Softwood_Decorative"
    },
    {
      "x": -10,
      "y": 5,
      "z": 1,
      "name": "Wood_Softwood_Decorative"
    },
    {
      "x": -10,
      "y": 6,
      "z": 1,
      "name": "Wood_Deadwood_Roof_Shallow",
      "rotation": 3
    },
    {
      "x": -10,
      "y": 7,
      "z": 1,
      "name": "Nat20_Force_Empty"
    },
    {
      "x": -10,
      "y": 8,
      "z": 1,
      "name": "Nat20_Force_Empty"
    },
    {
      "x": -10,
      "y": 9,
      "z": 1,
      "name": "Nat20_Force_Empty"
    },
    {
      "x": -10,
      "y": 10,
      "z": 1,
      "name": "Nat20_Force_Empty"
    },
    {
      "x": -10,
      "y": 11,
      "z": 1,
      "name": "Nat20_Force_Empty"
    },
    {
      "x": -10,
      "y": 12,
      "z": 1,
      "name": "Nat20_Force_Empty"
    },
    {
      "x": -10,
      "y": 13,
      "z": 1,
      "name": "Nat20_Force_Empty"
    },
    {
      "x": -10,
      "y": 14,
      "z": 1,
      "name": "Nat20_Force_Empty"
    },
    {
      "x": -10,
      "y": 15,
      "z": 1,
      "name": "Nat20_Force_Empty"
    },
    {
      "x": -10,
      "y": 16,
      "z": 1,
      "name": "Nat20_Force_Empty"
    },
    {
      "x": -10,
      "y": 2,
      "z": 2,
      "name": "Rock_Stone_Cobble"
    },
    {
      "x": -10,
      "y": 3,
      "z": 2,
      "name": "Furniture_Crude_Door",
      "rotation": 1
    },
    {
      "x": -10,
      "y": 4,
      "z": 2,
      "name": "Furniture_Crude_Door",
      "filler": 1024,
      "rotation": 1
    },
    {
      "x": -10,
      "y": 5,
      "z": 2,
      "name": "Wood_Softwood_Decorative"
    },
    {
      "x": -10,
      "y": 6,
      "z": 2,
      "name": "Wood_Deadwood_Roof_Shallow",
      "rotation": 3
    },
    {
      "x": -10,
      "y": 7,
      "z": 2,
      "name": "Nat20_Force_Empty"
    },
    {
      "x": -10,
      "y": 8,
      "z": 2,
      "name": "Nat20_Force_Empty"
    },
    {
      "x": -10,
      "y": 9,
      "z": 2,
      "name": "Nat20_Force_Empty"
    },
    {
      "x": -10,
      "y": 10,
      "z": 2,
      "name": "Nat20_Force_Empty"
    },
    {
      "x": -10,
      "y": 11,
      "z": 2,
      "name": "Nat20_Force_Empty"
    },
    {
      "x": -10,
      "y": 12,
      "z": 2,
      "name": "Nat20_Force_Empty"
    },
    {
      "x": -10,
      "y": 13,
      "z": 2,
      "name": "Nat20_Force_Empty"
    },
    {
      "x": -10,
      "y": 14,
      "z": 2,
      "name": "Nat20_Force_Empty"
    },
    {
      "x": -10,
      "y": 15,
      "z": 2,
      "name": "Nat20_Force_Empty"
    },
    {
      "x": -10,
      "y": 16,
      "z": 2,
      "name": "Nat20_Force_Empty"
    },
    {
      "x": -10,
      "y": 2,
      "z": 3,
      "name": "Rock_Stone_Cobble"
    },
    {
      "x": -10,
      "y": 3,
      "z": 3,
      "name": "Wood_Softwood_Planks"
    },
    {
      "x": -10,
      "y": 4,
      "z": 3,
      "name": "Wood_Softwood_Planks"
    },
    {
      "x": -10,
      "y": 5,
      "z": 3,
      "name": "Wood_Softwood_Planks"
    },
    {
      "x": -10,
      "y": 6,
      "z": 3,
      "name": "Wood_Deadwood_Roof_Shallow",
      "rotation": 3
    },
    {
      "x": -10,
      "y": 7,
      "z": 3,
      "name": "Nat20_Force_Empty"
    },
    {
      "x": -10,
      "y": 8,
      "z": 3,
      "name": "Nat20_Force_Empty"
    },
    {
      "x": -10,
      "y": 9,
      "z": 3,
      "name": "Nat20_Force_Empty"
    },
    {
      "x": -10,
      "y": 10,
      "z": 3,
      "name": "Nat20_Force_Empty"
    },
    {
      "x": -10,
      "y": 11,
      "z": 3,
      "name": "Nat20_Force_Empty"
    },
    {
      "x": -10,
      "y": 12,
      "z": 3,
      "name": "Nat20_Force_Empty"
    },
    {
      "x": -10,
      "y": 13,
      "z": 3,
      "name": "Nat20_Force_Empty"
    },
    {
      "x": -10,
      "y": 14,
      "z": 3,
      "name": "Nat20_Force_Empty"
    },
    {
      "x": -10,
      "y": 15,
      "z": 3,
      "name": "Nat20_Force_Empty"
    },
    {
      "x": -10,
      "y": 16,
      "z": 3,
      "name": "Nat20_Force_Empty"
    },
    {
      "x": -10,
      "y": 0,
      "z": 4,
      "name": "Wood_Beech_Trunk",
      "support": 15
    },
    {
      "x": -10,
      "y": 1,
      "z": 4,
      "name": "Wood_Beech_Trunk",
      "support": 15
    },
    {
      "x": -10,
      "y": 2,
      "z": 4,
      "name": "Wood_Beech_Trunk",
      "support": 15
    },
    {
      "x": -10,
      "y": 3,
      "z": 4,
      "name": "Wood_Beech_Trunk",
      "support": 15
    },
    {
      "x": -10,
      "y": 4,
      "z": 4,
      "name": "Wood_Beech_Trunk",
      "support": 15
    },
    {
      "x": -10,
      "y": 5,
      "z": 4,
      "name": "Wood_Beech_Trunk",
      "support": 15
    },
    {
      "x": -10,
      "y": 6,
      "z": 4,
      "name": "Wood_Deadwood_Roof_Shallow",
      "rotation": 3
    },
    {
      "x": -10,
      "y": 7,
      "z": 4,
      "name": "Nat20_Force_Empty"
    },
    {
      "x": -10,
      "y": 8,
      "z": 4,
      "name": "Nat20_Force_Empty"
    },
    {
      "x": -10,
      "y": 9,
      "z": 4,
      "name": "Nat20_Force_Empty"
    },
    {
      "x": -10,
      "y": 10,
      "z": 4,
      "name": "Nat20_Force_Empty"
    },
    {
      "x": -10,
      "y": 11,
      "z": 4,
      "name": "Nat20_Force_Empty"
    },
    {
      "x": -10,
      "y": 12,
      "z": 4,
      "name": "Nat20_Force_Empty"
    },
    {
      "x": -10,
      "y": 13,
      "z": 4,
      "name": "Nat20_Force_Empty"
    },
    {
      "x": -10,
      "y": 14,
      "z": 4,
      "name": "Nat20_Force_Empty"
    },
    {
      "x": -10,
      "y": 15,
      "z": 4,
      "name": "Nat20_Force_Empty"
    },
    {
      "x": -10,
      "y": 16,
      "z": 4,
      "name": "Nat20_Force_Empty"
    },
    {
      "x": -10,
      "y": 3,
      "z": 5,
      "name": "Nat20_Force_Empty"
    },
    {
      "x": -10,
      "y": 4,
      "z": 5,
      "name": "Nat20_Force_Empty"
    },
    {
      "x": -10,
      "y": 5,
      "z": 5,
      "name": "Nat20_Force_Empty"
    },
    {
      "x": -10,
      "y": 6,
      "z": 5,
      "name": "Nat20_Force_Empty"
    },
    {
      "x": -10,
      "y": 7,
      "z": 5,
      "name": "Nat20_Force_Empty"
    },
    {
      "x": -10,
      "y": 8,
      "z": 5,
      "name": "Nat20_Force_Empty"
    },
    {
      "x": -10,
      "y": 9,
      "z": 5,
      "name": "Nat20_Force_Empty"
    },
    {
      "x": -10,
      "y": 10,
      "z": 5,
      "name": "Nat20_Force_Empty"
    },
    {
      "x": -10,
      "y": 11,
      "z": 5,
      "name": "Nat20_Force_Empty"
    },
    {
      "x": -10,
      "y": 12,
      "z": 5,
      "name": "Nat20_Force_Empty"
    },
    {
      "x": -10,
      "y": 13,
      "z": 5,
      "name": "Nat20_Force_Empty"
    },
    {
      "x": -10,
      "y": 14,
      "z": 5,
      "name": "Nat20_Force_Empty"
    },
    {
      "x": -10,
      "y": 15,
      "z": 5,
      "name": "Nat20_Force_Empty"
    },
    {
      "x": -10,
      "y": 16,
      "z": 5,
      "name": "Nat20_Force_Empty"
    },
    {
      "x": -10,
      "y": 3,
      "z": 6,
      "name": "Nat20_Force_Empty"
    },
    {
      "x": -10,
      "y": 4,
      "z": 6,
      "name": "Nat20_Force_Empty"
    },
    {
      "x": -10,
      "y": 5,
      "z": 6,
      "name": "Nat20_Force_Empty"
    },
    {
      "x": -10,
      "y": 6,
      "z": 6,
      "name": "Nat20_Force_Empty"
    },
    {
      "x": -10,
      "y": 7,
      "z": 6,
      "name": "Nat20_Force_Empty"
    },
    {
      "x": -10,
      "y": 8,
      "z": 6,
      "name": "Nat20_Force_Empty"
    },
    {
      "x": -10,
      "y": 9,
      "z": 6,
      "name": "Nat20_Force_Empty"
    },
    {
      "x": -10,
      "y": 10,
      "z": 6,
      "name": "Nat20_Force_Empty"
    },
    {
      "x": -10,
      "y": 11,
      "z": 6,
      "name": "Nat20_Force_Empty"
    },
    {
      "x": -10,
      "y": 12,
      "z": 6,
      "name": "Nat20_Force_Empty"
    },
    {
      "x": -10,
      "y": 13,
      "z": 6,
      "name": "Nat20_Force_Empty"
    },
    {
      "x": -10,
      "y": 14,
      "z": 6,
      "name": "Nat20_Force_Empty"
    },
    {
      "x": -10,
      "y": 15,
      "z": 6,
      "name": "Nat20_Force_Empty"
    },
    {
      "x": -10,
      "y": 16,
      "z": 6,
      "name": "Nat20_Force_Empty"
    },
    {
      "x": -10,
      "y": 3,
      "z": 7,
      "name": "Nat20_Force_Empty"
    },
    {
      "x": -10,
      "y": 4,
      "z": 7,
      "name": "Nat20_Force_Empty"
    },
    {
      "x": -10,
      "y": 5,
      "z": 7,
      "name": "Nat20_Force_Empty"
    },
    {
      "x": -10,
      "y": 6,
      "z": 7,
      "name": "Nat20_Force_Empty"
    },
    {
      "x": -10,
      "y": 7,
      "z": 7,
      "name": "Nat20_Force_Empty"
    },
    {
      "x": -10,
      "y": 8,
      "z": 7,
      "name": "Nat20_Force_Empty"
    },
    {
      "x": -10,
      "y": 9,
      "z": 7,
      "name": "Nat20_Force_Empty"
    },
    {
      "x": -10,
      "y": 10,
      "z": 7,
      "name": "Nat20_Force_Empty"
    },
    {
      "x": -10,
      "y": 11,
      "z": 7,
      "name": "Nat20_Force_Empty"
    },
    {
      "x": -10,
      "y": 12,
      "z": 7,
      "name": "Nat20_Force_Empty"
    },
    {
      "x": -10,
      "y": 13,
      "z": 7,
      "name": "Nat20_Force_Empty"
    },
    {
      "x": -10,
      "y": 14,
      "z": 7,
      "name": "Nat20_Force_Empty"
    },
    {
      "x": -10,
      "y": 15,
      "z": 7,
      "name": "Nat20_Force_Empty"
    },
    {
      "x": -10,
      "y": 16,
      "z": 7,
      "name": "Nat20_Force_Empty"
    },
    {
      "x": -10,
      "y": 3,
      "z": 8,
      "name": "Nat20_Force_Empty"
    },
    {
      "x": -10,
      "y": 4,
      "z": 8,
      "name": "Nat20_Force_Empty"
    },
    {
      "x": -10,
      "y": 5,
      "z": 8,
      "name": "Nat20_Force_Empty"
    },
    {
      "x": -10,
      "y": 6,
      "z": 8,
      "name": "Nat20_Force_Empty"
    },
    {
      "x": -10,
      "y": 7,
      "z": 8,
      "name": "Nat20_Force_Empty"
    },
    {
      "x": -10,
      "y": 8,
      "z": 8,
      "name": "Nat20_Force_Empty"
    },
    {
      "x": -10,
      "y": 9,
      "z": 8,
      "name": "Nat20_Force_Empty"
    },
    {
      "x": -10,
      "y": 10,
      "z": 8,
      "name": "Nat20_Force_Empty"
    },
    {
      "x": -10,
      "y": 11,
      "z": 8,
      "name": "Nat20_Force_Empty"
    },
    {
      "x": -10,
      "y": 12,
      "z": 8,
      "name": "Nat20_Force_Empty"
    },
    {
      "x": -10,
      "y": 13,
      "z": 8,
      "name": "Nat20_Force_Empty"
    },
    {
      "x": -10,
      "y": 14,
      "z": 8,
      "name": "Nat20_Force_Empty"
    },
    {
      "x": -10,
      "y": 15,
      "z": 8,
      "name": "Nat20_Force_Empty"
    },
    {
      "x": -10,
      "y": 16,
      "z": 8,
      "name": "Nat20_Force_Empty"
    },
    {
      "x": -10,
      "y": 3,
      "z": 9,
      "name": "Nat20_Force_Empty"
    },
    {
      "x": -10,
      "y": 4,
      "z": 9,
      "name": "Nat20_Force_Empty"
    },
    {
      "x": -10,
      "y": 5,
      "z": 9,
      "name": "Nat20_Force_Empty"
    },
    {
      "x": -10,
      "y": 6,
      "z": 9,
      "name": "Nat20_Force_Empty"
    },
    {
      "x": -10,
      "y": 7,
      "z": 9,
      "name": "Nat20_Force_Empty"
    },
    {
      "x": -10,
      "y": 8,
      "z": 9,
      "name": "Nat20_Force_Empty"
    },
    {
      "x": -10,
      "y": 9,
      "z": 9,
      "name": "Nat20_Force_Empty"
    },
    {
      "x": -10,
      "y": 10,
      "z": 9,
      "name": "Nat20_Force_Empty"
    },
    {
      "x": -10,
      "y": 11,
      "z": 9,
      "name": "Nat20_Force_Empty"
    },
    {
      "x": -10,
      "y": 12,
      "z": 9,
      "name": "Nat20_Force_Empty"
    },
    {
      "x": -10,
      "y": 13,
      "z": 9,
      "name": "Nat20_Force_Empty"
    },
    {
      "x": -10,
      "y": 14,
      "z": 9,
      "name": "Nat20_Force_Empty"
    },
    {
      "x": -10,
      "y": 15,
      "z": 9,
      "name": "Nat20_Force_Empty"
    },
    {
      "x": -10,
      "y": 16,
      "z": 9,
      "name": "Nat20_Force_Empty"
    },
    {
      "x": -10,
      "y": 3,
      "z": 10,
      "name": "Nat20_Force_Empty"
    },
    {
      "x": -10,
      "y": 4,
      "z": 10,
      "name": "Nat20_Force_Empty"
    },
    {
      "x": -10,
      "y": 5,
      "z": 10,
      "name": "Nat20_Force_Empty"
    },
    {
      "x": -10,
      "y": 6,
      "z": 10,
      "name": "Nat20_Force_Empty"
    },
    {
      "x": -10,
      "y": 7,
      "z": 10,
      "name": "Nat20_Force_Empty"
    },
    {
      "x": -10,
      "y": 8,
      "z": 10,
      "name": "Nat20_Force_Empty"
    },
    {
      "x": -10,
      "y": 9,
      "z": 10,
      "name": "Nat20_Force_Empty"
    },
    {
      "x": -10,
      "y": 10,
      "z": 10,
      "name": "Nat20_Force_Empty"
    },
    {
      "x": -10,
      "y": 11,
      "z": 10,
      "name": "Nat20_Force_Empty"
    },
    {
      "x": -10,
      "y": 12,
      "z": 10,
      "name": "Nat20_Force_Empty"
    },
    {
      "x": -10,
      "y": 13,
      "z": 10,
      "name": "Nat20_Force_Empty"
    },
    {
      "x": -10,
      "y": 14,
      "z": 10,
      "name": "Nat20_Force_Empty"
    },
    {
      "x": -10,
      "y": 15,
      "z": 10,
      "name": "Nat20_Force_Empty"
    },
    {
      "x": -10,
      "y": 16,
      "z": 10,
      "name": "Nat20_Force_Empty"
    },
    {
      "x": -10,
      "y": 3,
      "z": 11,
      "name": "Nat20_Force_Empty"
    },
    {
      "x": -10,
      "y": 4,
      "z": 11,
      "name": "Nat20_Force_Empty"
    },
    {
      "x": -10,
      "y": 5,
      "z": 11,
      "name": "Nat20_Force_Empty"
    },
    {
      "x": -10,
      "y": 6,
      "z": 11,
      "name": "Nat20_Force_Empty"
    },
    {
      "x": -10,
      "y": 7,
      "z": 11,
      "name": "Nat20_Force_Empty"
    },
    {
      "x": -10,
      "y": 8,
      "z": 11,
      "name": "Nat20_Force_Empty"
    },
    {
      "x": -10,
      "y": 9,
      "z": 11,
      "name": "Nat20_Force_Empty"
    },
    {
      "x": -10,
      "y": 10,
      "z": 11,
      "name": "Nat20_Force_Empty"
    },
    {
      "x": -10,
      "y": 11,
      "z": 11,
      "name": "Nat20_Force_Empty"
    },
    {
      "x": -10,
      "y": 12,
      "z": 11,
      "name": "Nat20_Force_Empty"
    },
    {
      "x": -10,
      "y": 13,
      "z": 11,
      "name": "Nat20_Force_Empty"
    },
    {
      "x": -10,
      "y": 14,
      "z": 11,
      "name": "Nat20_Force_Empty"
    },
    {
      "x": -10,
      "y": 15,
      "z": 11,
      "name": "Nat20_Force_Empty"
    },
    {
      "x": -10,
      "y": 16,
      "z": 11,
      "name": "Nat20_Force_Empty"
    },
    {
      "x": -10,
      "y": 3,
      "z": 12,
      "name": "Nat20_Force_Empty"
    },
    {
      "x": -10,
      "y": 4,
      "z": 12,
      "name": "Nat20_Force_Empty"
    },
    {
      "x": -10,
      "y": 5,
      "z": 12,
      "name": "Nat20_Force_Empty"
    },
    {
      "x": -10,
      "y": 6,
      "z": 12,
      "name": "Nat20_Force_Empty"
    },
    {
      "x": -10,
      "y": 7,
      "z": 12,
      "name": "Nat20_Force_Empty"
    },
    {
      "x": -10,
      "y": 8,
      "z": 12,
      "name": "Nat20_Force_Empty"
    },
    {
      "x": -10,
      "y": 9,
      "z": 12,
      "name": "Nat20_Force_Empty"
    },
    {
      "x": -10,
      "y": 10,
      "z": 12,
      "name": "Nat20_Force_Empty"
    },
    {
      "x": -10,
      "y": 11,
      "z": 12,
      "name": "Nat20_Force_Empty"
    },
    {
      "x": -10,
      "y": 12,
      "z": 12,
      "name": "Nat20_Force_Empty"
    },
    {
      "x": -10,
      "y": 13,
      "z": 12,
      "name": "Nat20_Force_Empty"
    },
    {
      "x": -10,
      "y": 14,
      "z": 12,
      "name": "Nat20_Force_Empty"
    },
    {
      "x": -10,
      "y": 15,
      "z": 12,
      "name": "Nat20_Force_Empty"
    },
    {
      "x": -10,
      "y": 16,
      "z": 12,
      "name": "Nat20_Force_Empty"
    },
    {
      "x": -9,
      "y": 3,
      "z": -11,
      "name": "Nat20_Force_Empty"
    },
    {
      "x": -9,
      "y": 4,
      "z": -11,
      "name": "Nat20_Force_Empty"
    },
    {
      "x": -9,
      "y": 5,
      "z": -11,
      "name": "Nat20_Force_Empty"
    },
    {
      "x": -9,
      "y": 6,
      "z": -11,
      "name": "Nat20_Force_Empty"
    },
    {
      "x": -9,
      "y": 7,
      "z": -11,
      "name": "Nat20_Force_Empty"
    },
    {
      "x": -9,
      "y": 8,
      "z": -11,
      "name": "Nat20_Force_Empty"
    },
    {
      "x": -9,
      "y": 9,
      "z": -11,
      "name": "Nat20_Force_Empty"
    },
    {
      "x": -9,
      "y": 10,
      "z": -11,
      "name": "Nat20_Force_Empty"
    },
    {
      "x": -9,
      "y": 11,
      "z": -11,
      "name": "Nat20_Force_Empty"
    },
    {
      "x": -9,
      "y": 12,
      "z": -11,
      "name": "Nat20_Force_Empty"
    },
    {
      "x": -9,
      "y": 13,
      "z": -11,
      "name": "Nat20_Force_Empty"
    },
    {
      "x": -9,
      "y": 14,
      "z": -11,
      "name": "Nat20_Force_Empty"
    },
    {
      "x": -9,
      "y": 15,
      "z": -11,
      "name": "Nat20_Force_Empty"
    },
    {
      "x": -9,
      "y": 16,
      "z": -11,
      "name": "Nat20_Force_Empty"
    },
    {
      "x": -9,
      "y": 3,
      "z": -10,
      "name": "Nat20_Force_Empty"
    },
    {
      "x": -9,
      "y": 4,
      "z": -10,
      "name": "Nat20_Force_Empty"
    },
    {
      "x": -9,
      "y": 5,
      "z": -10,
      "name": "Nat20_Force_Empty"
    },
    {
      "x": -9,
      "y": 6,
      "z": -10,
      "name": "Nat20_Force_Empty"
    },
    {
      "x": -9,
      "y": 7,
      "z": -10,
      "name": "Nat20_Force_Empty"
    },
    {
      "x": -9,
      "y": 8,
      "z": -10,
      "name": "Nat20_Force_Empty"
    },
    {
      "x": -9,
      "y": 9,
      "z": -10,
      "name": "Nat20_Force_Empty"
    },
    {
      "x": -9,
      "y": 10,
      "z": -10,
      "name": "Nat20_Force_Empty"
    },
    {
      "x": -9,
      "y": 11,
      "z": -10,
      "name": "Nat20_Force_Empty"
    },
    {
      "x": -9,
      "y": 12,
      "z": -10,
      "name": "Nat20_Force_Empty"
    },
    {
      "x": -9,
      "y": 13,
      "z": -10,
      "name": "Nat20_Force_Empty"
    },
    {
      "x": -9,
      "y": 14,
      "z": -10,
      "name": "Nat20_Force_Empty"
    },
    {
      "x": -9,
      "y": 15,
      "z": -10,
      "name": "Nat20_Force_Empty"
    },
    {
      "x": -9,
      "y": 16,
      "z": -10,
      "name": "Nat20_Force_Empty"
    },
    {
      "x": -9,
      "y": 3,
      "z": -9,
      "name": "Nat20_Force_Empty"
    },
    {
      "x": -9,
      "y": 4,
      "z": -9,
      "name": "Nat20_Force_Empty"
    },
    {
      "x": -9,
      "y": 5,
      "z": -9,
      "name": "Nat20_Force_Empty"
    },
    {
      "x": -9,
      "y": 6,
      "z": -9,
      "name": "Nat20_Force_Empty"
    },
    {
      "x": -9,
      "y": 7,
      "z": -9,
      "name": "Nat20_Force_Empty"
    },
    {
      "x": -9,
      "y": 8,
      "z": -9,
      "name": "Nat20_Force_Empty"
    },
    {
      "x": -9,
      "y": 9,
      "z": -9,
      "name": "Nat20_Force_Empty"
    },
    {
      "x": -9,
      "y": 10,
      "z": -9,
      "name": "Nat20_Force_Empty"
    },
    {
      "x": -9,
      "y": 11,
      "z": -9,
      "name": "Nat20_Force_Empty"
    },
    {
      "x": -9,
      "y": 12,
      "z": -9,
      "name": "Nat20_Force_Empty"
    },
    {
      "x": -9,
      "y": 13,
      "z": -9,
      "name": "Nat20_Force_Empty"
    },
    {
      "x": -9,
      "y": 14,
      "z": -9,
      "name": "Nat20_Force_Empty"
    },
    {
      "x": -9,
      "y": 15,
      "z": -9,
      "name": "Nat20_Force_Empty"
    },
    {
      "x": -9,
      "y": 16,
      "z": -9,
      "name": "Nat20_Force_Empty"
    },
    {
      "x": -9,
      "y": 3,
      "z": -8,
      "name": "Nat20_Force_Empty"
    },
    {
      "x": -9,
      "y": 4,
      "z": -8,
      "name": "Nat20_Force_Empty"
    },
    {
      "x": -9,
      "y": 5,
      "z": -8,
      "name": "Nat20_Force_Empty"
    },
    {
      "x": -9,
      "y": 6,
      "z": -8,
      "name": "Nat20_Force_Empty"
    },
    {
      "x": -9,
      "y": 7,
      "z": -8,
      "name": "Nat20_Force_Empty"
    },
    {
      "x": -9,
      "y": 8,
      "z": -8,
      "name": "Nat20_Force_Empty"
    },
    {
      "x": -9,
      "y": 9,
      "z": -8,
      "name": "Nat20_Force_Empty"
    },
    {
      "x": -9,
      "y": 10,
      "z": -8,
      "name": "Nat20_Force_Empty"
    },
    {
      "x": -9,
      "y": 11,
      "z": -8,
      "name": "Nat20_Force_Empty"
    },
    {
      "x": -9,
      "y": 12,
      "z": -8,
      "name": "Nat20_Force_Empty"
    },
    {
      "x": -9,
      "y": 13,
      "z": -8,
      "name": "Nat20_Force_Empty"
    },
    {
      "x": -9,
      "y": 14,
      "z": -8,
      "name": "Nat20_Force_Empty"
    },
    {
      "x": -9,
      "y": 15,
      "z": -8,
      "name": "Nat20_Force_Empty"
    },
    {
      "x": -9,
      "y": 16,
      "z": -8,
      "name": "Nat20_Force_Empty"
    },
    {
      "x": -9,
      "y": 3,
      "z": -7,
      "name": "Nat20_Force_Empty"
    },
    {
      "x": -9,
      "y": 4,
      "z": -7,
      "name": "Nat20_Force_Empty"
    },
    {
      "x": -9,
      "y": 5,
      "z": -7,
      "name": "Nat20_Force_Empty"
    },
    {
      "x": -9,
      "y": 6,
      "z": -7,
      "name": "Nat20_Force_Empty"
    },
    {
      "x": -9,
      "y": 7,
      "z": -7,
      "name": "Nat20_Force_Empty"
    },
    {
      "x": -9,
      "y": 8,
      "z": -7,
      "name": "Nat20_Force_Empty"
    },
    {
      "x": -9,
      "y": 9,
      "z": -7,
      "name": "Nat20_Force_Empty"
    },
    {
      "x": -9,
      "y": 10,
      "z": -7,
      "name": "Nat20_Force_Empty"
    },
    {
      "x": -9,
      "y": 11,
      "z": -7,
      "name": "Nat20_Force_Empty"
    },
    {
      "x": -9,
      "y": 12,
      "z": -7,
      "name": "Nat20_Force_Empty"
    },
    {
      "x": -9,
      "y": 13,
      "z": -7,
      "name": "Nat20_Force_Empty"
    },
    {
      "x": -9,
      "y": 14,
      "z": -7,
      "name": "Nat20_Force_Empty"
    },
    {
      "x": -9,
      "y": 15,
      "z": -7,
      "name": "Nat20_Force_Empty"
    },
    {
      "x": -9,
      "y": 16,
      "z": -7,
      "name": "Nat20_Force_Empty"
    },
    {
      "x": -9,
      "y": 3,
      "z": -6,
      "name": "Nat20_Force_Empty"
    },
    {
      "x": -9,
      "y": 4,
      "z": -6,
      "name": "Nat20_Force_Empty"
    },
    {
      "x": -9,
      "y": 5,
      "z": -6,
      "name": "Nat20_Force_Empty"
    },
    {
      "x": -9,
      "y": 6,
      "z": -6,
      "name": "Nat20_Force_Empty"
    },
    {
      "x": -9,
      "y": 7,
      "z": -6,
      "name": "Nat20_Force_Empty"
    },
    {
      "x": -9,
      "y": 8,
      "z": -6,
      "name": "Nat20_Force_Empty"
    },
    {
      "x": -9,
      "y": 9,
      "z": -6,
      "name": "Nat20_Force_Empty"
    },
    {
      "x": -9,
      "y": 10,
      "z": -6,
      "name": "Nat20_Force_Empty"
    },
    {
      "x": -9,
      "y": 11,
      "z": -6,
      "name": "Nat20_Force_Empty"
    },
    {
      "x": -9,
      "y": 12,
      "z": -6,
      "name": "Nat20_Force_Empty"
    },
    {
      "x": -9,
      "y": 13,
      "z": -6,
      "name": "Nat20_Force_Empty"
    },
    {
      "x": -9,
      "y": 14,
      "z": -6,
      "name": "Nat20_Force_Empty"
    },
    {
      "x": -9,
      "y": 15,
      "z": -6,
      "name": "Nat20_Force_Empty"
    },
    {
      "x": -9,
      "y": 16,
      "z": -6,
      "name": "Nat20_Force_Empty"
    },
    {
      "x": -9,
      "y": 3,
      "z": -5,
      "name": "Nat20_Force_Empty"
    },
    {
      "x": -9,
      "y": 4,
      "z": -5,
      "name": "Nat20_Force_Empty"
    },
    {
      "x": -9,
      "y": 5,
      "z": -5,
      "name": "Nat20_Force_Empty"
    },
    {
      "x": -9,
      "y": 6,
      "z": -5,
      "name": "Nat20_Force_Empty"
    },
    {
      "x": -9,
      "y": 7,
      "z": -5,
      "name": "Nat20_Force_Empty"
    },
    {
      "x": -9,
      "y": 8,
      "z": -5,
      "name": "Nat20_Force_Empty"
    },
    {
      "x": -9,
      "y": 9,
      "z": -5,
      "name": "Nat20_Force_Empty"
    },
    {
      "x": -9,
      "y": 10,
      "z": -5,
      "name": "Nat20_Force_Empty"
    },
    {
      "x": -9,
      "y": 11,
      "z": -5,
      "name": "Nat20_Force_Empty"
    },
    {
      "x": -9,
      "y": 12,
      "z": -5,
      "name": "Nat20_Force_Empty"
    },
    {
      "x": -9,
      "y": 13,
      "z": -5,
      "name": "Nat20_Force_Empty"
    },
    {
      "x": -9,
      "y": 14,
      "z": -5,
      "name": "Nat20_Force_Empty"
    },
    {
      "x": -9,
      "y": 15,
      "z": -5,
      "name": "Nat20_Force_Empty"
    },
    {
      "x": -9,
      "y": 16,
      "z": -5,
      "name": "Nat20_Force_Empty"
    },
    {
      "x": -9,
      "y": 2,
      "z": -4,
      "name": "Rock_Stone_Cobble"
    },
    {
      "x": -9,
      "y": 3,
      "z": -4,
      "name": "Wood_Softwood_Decorative"
    },
    {
      "x": -9,
      "y": 4,
      "z": -4,
      "name": "Wood_Softwood_Beam",
      "rotation": 5
    },
    {
      "x": -9,
      "y": 5,
      "z": -4,
      "name": "Wood_Softwood_Decorative"
    },
    {
      "x": -9,
      "y": 6,
      "z": -4,
      "name": "Wood_Deadwood_Roof_Shallow",
      "filler": 1,
      "rotation": 3
    },
    {
      "x": -9,
      "y": 7,
      "z": -4,
      "name": "Nat20_Force_Empty"
    },
    {
      "x": -9,
      "y": 8,
      "z": -4,
      "name": "Nat20_Force_Empty"
    },
    {
      "x": -9,
      "y": 9,
      "z": -4,
      "name": "Nat20_Force_Empty"
    },
    {
      "x": -9,
      "y": 10,
      "z": -4,
      "name": "Nat20_Force_Empty"
    },
    {
      "x": -9,
      "y": 11,
      "z": -4,
      "name": "Nat20_Force_Empty"
    },
    {
      "x": -9,
      "y": 12,
      "z": -4,
      "name": "Nat20_Force_Empty"
    },
    {
      "x": -9,
      "y": 13,
      "z": -4,
      "name": "Nat20_Force_Empty"
    },
    {
      "x": -9,
      "y": 14,
      "z": -4,
      "name": "Nat20_Force_Empty"
    },
    {
      "x": -9,
      "y": 15,
      "z": -4,
      "name": "Nat20_Force_Empty"
    },
    {
      "x": -9,
      "y": 16,
      "z": -4,
      "name": "Nat20_Force_Empty"
    },
    {
      "x": -9,
      "y": 2,
      "z": -3,
      "name": "Rock_Stone_Cobble"
    },
    {
      "x": -9,
      "y": 3,
      "z": -3,
      "name": "Nat20_Force_Empty"
    },
    {
      "x": -9,
      "y": 4,
      "z": -3,
      "name": "Nat20_Force_Empty"
    },
    {
      "x": -9,
      "y": 5,
      "z": -3,
      "name": "Plant_Moss_Cave_Green",
      "rotation": 8
    },
    {
      "x": -9,
      "y": 6,
      "z": -3,
      "name": "Wood_Deadwood_Roof_Shallow",
      "filler": 1,
      "rotation": 3
    },
    {
      "x": -9,
      "y": 7,
      "z": -3,
      "name": "Nat20_Force_Empty"
    },
    {
      "x": -9,
      "y": 8,
      "z": -3,
      "name": "Nat20_Force_Empty"
    },
    {
      "x": -9,
      "y": 9,
      "z": -3,
      "name": "Nat20_Force_Empty"
    },
    {
      "x": -9,
      "y": 10,
      "z": -3,
      "name": "Nat20_Force_Empty"
    },
    {
      "x": -9,
      "y": 11,
      "z": -3,
      "name": "Nat20_Force_Empty"
    },
    {
      "x": -9,
      "y": 12,
      "z": -3,
      "name": "Nat20_Force_Empty"
    },
    {
      "x": -9,
      "y": 13,
      "z": -3,
      "name": "Nat20_Force_Empty"
    },
    {
      "x": -9,
      "y": 14,
      "z": -3,
      "name": "Nat20_Force_Empty"
    },
    {
      "x": -9,
      "y": 15,
      "z": -3,
      "name": "Nat20_Force_Empty"
    },
    {
      "x": -9,
      "y": 16,
      "z": -3,
      "name": "Nat20_Force_Empty"
    },
    {
      "x": -9,
      "y": 2,
      "z": -2,
      "name": "Rock_Stone_Cobble"
    },
    {
      "x": -9,
      "y": 3,
      "z": -2,
      "name": "Nat20_Force_Empty"
    },
    {
      "x": -9,
      "y": 4,
      "z": -2,
      "name": "Nat20_Force_Empty"
    },
    {
      "x": -9,
      "y": 5,
      "z": -2,
      "name": "Nat20_Force_Empty"
    },
    {
      "x": -9,
      "y": 6,
      "z": -2,
      "name": "Wood_Deadwood_Roof_Shallow",
      "filler": 1,
      "rotation": 3
    },
    {
      "x": -9,
      "y": 7,
      "z": -2,
      "name": "Nat20_Force_Empty"
    },
    {
      "x": -9,
      "y": 8,
      "z": -2,
      "name": "Nat20_Force_Empty"
    },
    {
      "x": -9,
      "y": 9,
      "z": -2,
      "name": "Nat20_Force_Empty"
    },
    {
      "x": -9,
      "y": 10,
      "z": -2,
      "name": "Nat20_Force_Empty"
    },
    {
      "x": -9,
      "y": 11,
      "z": -2,
      "name": "Nat20_Force_Empty"
    },
    {
      "x": -9,
      "y": 12,
      "z": -2,
      "name": "Nat20_Force_Empty"
    },
    {
      "x": -9,
      "y": 13,
      "z": -2,
      "name": "Nat20_Force_Empty"
    },
    {
      "x": -9,
      "y": 14,
      "z": -2,
      "name": "Nat20_Force_Empty"
    },
    {
      "x": -9,
      "y": 15,
      "z": -2,
      "name": "Nat20_Force_Empty"
    },
    {
      "x": -9,
      "y": 16,
      "z": -2,
      "name": "Nat20_Force_Empty"
    },
    {
      "x": -9,
      "y": 2,
      "z": -1,
      "name": "Rock_Stone_Cobble"
    },
    {
      "x": -9,
      "y": 3,
      "z": -1,
      "name": "Nat20_Force_Empty"
    },
    {
      "x": -9,
      "y": 4,
      "z": -1,
      "name": "Nat20_Force_Empty"
    },
    {
      "x": -9,
      "y": 5,
      "z": -1,
      "name": "Nat20_Force_Empty"
    },
    {
      "x": -9,
      "y": 6,
      "z": -1,
      "name": "Wood_Deadwood_Roof_Shallow",
      "filler": 1,
      "rotation": 3
    },
    {
      "x": -9,
      "y": 7,
      "z": -1,
      "name": "Nat20_Force_Empty"
    },
    {
      "x": -9,
      "y": 8,
      "z": -1,
      "name": "Nat20_Force_Empty"
    },
    {
      "x": -9,
      "y": 9,
      "z": -1,
      "name": "Nat20_Force_Empty"
    },
    {
      "x": -9,
      "y": 10,
      "z": -1,
      "name": "Nat20_Force_Empty"
    },
    {
      "x": -9,
      "y": 11,
      "z": -1,
      "name": "Nat20_Force_Empty"
    },
    {
      "x": -9,
      "y": 12,
      "z": -1,
      "name": "Nat20_Force_Empty"
    },
    {
      "x": -9,
      "y": 13,
      "z": -1,
      "name": "Nat20_Force_Empty"
    },
    {
      "x": -9,
      "y": 14,
      "z": -1,
      "name": "Nat20_Force_Empty"
    },
    {
      "x": -9,
      "y": 15,
      "z": -1,
      "name": "Nat20_Force_Empty"
    },
    {
      "x": -9,
      "y": 16,
      "z": -1,
      "name": "Nat20_Force_Empty"
    },
    {
      "x": -9,
      "y": 2,
      "z": 0,
      "name": "Rock_Stone_Cobble"
    },
    {
      "x": -9,
      "y": 3,
      "z": 0,
      "name": "Nat20_Force_Empty"
    },
    {
      "x": -9,
      "y": 4,
      "z": 0,
      "name": "Nat20_Force_Empty"
    },
    {
      "x": -9,
      "y": 5,
      "z": 0,
      "name": "Nat20_Force_Empty"
    },
    {
      "x": -9,
      "y": 6,
      "z": 0,
      "name": "Wood_Deadwood_Roof_Shallow",
      "filler": 1,
      "rotation": 3
    },
    {
      "x": -9,
      "y": 7,
      "z": 0,
      "name": "Nat20_Force_Empty"
    },
    {
      "x": -9,
      "y": 8,
      "z": 0,
      "name": "Nat20_Force_Empty"
    },
    {
      "x": -9,
      "y": 9,
      "z": 0,
      "name": "Nat20_Force_Empty"
    },
    {
      "x": -9,
      "y": 10,
      "z": 0,
      "name": "Nat20_Force_Empty"
    },
    {
      "x": -9,
      "y": 11,
      "z": 0,
      "name": "Nat20_Force_Empty"
    },
    {
      "x": -9,
      "y": 12,
      "z": 0,
      "name": "Nat20_Force_Empty"
    },
    {
      "x": -9,
      "y": 13,
      "z": 0,
      "name": "Nat20_Force_Empty"
    },
    {
      "x": -9,
      "y": 14,
      "z": 0,
      "name": "Nat20_Force_Empty"
    },
    {
      "x": -9,
      "y": 15,
      "z": 0,
      "name": "Nat20_Force_Empty"
    },
    {
      "x": -9,
      "y": 16,
      "z": 0,
      "name": "Nat20_Force_Empty"
    },
    {
      "x": -9,
      "y": 2,
      "z": 1,
      "name": "Rock_Stone_Cobble"
    },
    {
      "x": -9,
      "y": 3,
      "z": 1,
      "name": "Nat20_Force_Empty"
    },
    {
      "x": -9,
      "y": 4,
      "z": 1,
      "name": "Nat20_Force_Empty"
    },
    {
      "x": -9,
      "y": 5,
      "z": 1,
      "name": "Nat20_Force_Empty"
    },
    {
      "x": -9,
      "y": 6,
      "z": 1,
      "name": "Wood_Deadwood_Roof_Shallow",
      "filler": 1,
      "rotation": 3
    },
    {
      "x": -9,
      "y": 7,
      "z": 1,
      "name": "Nat20_Force_Empty"
    },
    {
      "x": -9,
      "y": 8,
      "z": 1,
      "name": "Nat20_Force_Empty"
    },
    {
      "x": -9,
      "y": 9,
      "z": 1,
      "name": "Nat20_Force_Empty"
    },
    {
      "x": -9,
      "y": 10,
      "z": 1,
      "name": "Nat20_Force_Empty"
    },
    {
      "x": -9,
      "y": 11,
      "z": 1,
      "name": "Nat20_Force_Empty"
    },
    {
      "x": -9,
      "y": 12,
      "z": 1,
      "name": "Nat20_Force_Empty"
    },
    {
      "x": -9,
      "y": 13,
      "z": 1,
      "name": "Nat20_Force_Empty"
    },
    {
      "x": -9,
      "y": 14,
      "z": 1,
      "name": "Nat20_Force_Empty"
    },
    {
      "x": -9,
      "y": 15,
      "z": 1,
      "name": "Nat20_Force_Empty"
    },
    {
      "x": -9,
      "y": 16,
      "z": 1,
      "name": "Nat20_Force_Empty"
    },
    {
      "x": -9,
      "y": 2,
      "z": 2,
      "name": "Rock_Stone_Cobble"
    },
    {
      "x": -9,
      "y": 3,
      "z": 2,
      "name": "Nat20_Force_Empty"
    },
    {
      "x": -9,
      "y": 4,
      "z": 2,
      "name": "Nat20_Force_Empty"
    },
    {
      "x": -9,
      "y": 5,
      "z": 2,
      "name": "Nat20_Force_Empty"
    },
    {
      "x": -9,
      "y": 6,
      "z": 2,
      "name": "Wood_Deadwood_Roof_Shallow",
      "filler": 1,
      "rotation": 3
    },
    {
      "x": -9,
      "y": 7,
      "z": 2,
      "name": "Nat20_Force_Empty"
    },
    {
      "x": -9,
      "y": 8,
      "z": 2,
      "name": "Nat20_Force_Empty"
    },
    {
      "x": -9,
      "y": 9,
      "z": 2,
      "name": "Nat20_Force_Empty"
    },
    {
      "x": -9,
      "y": 10,
      "z": 2,
      "name": "Nat20_Force_Empty"
    },
    {
      "x": -9,
      "y": 11,
      "z": 2,
      "name": "Nat20_Force_Empty"
    },
    {
      "x": -9,
      "y": 12,
      "z": 2,
      "name": "Nat20_Force_Empty"
    },
    {
      "x": -9,
      "y": 13,
      "z": 2,
      "name": "Nat20_Force_Empty"
    },
    {
      "x": -9,
      "y": 14,
      "z": 2,
      "name": "Nat20_Force_Empty"
    },
    {
      "x": -9,
      "y": 15,
      "z": 2,
      "name": "Nat20_Force_Empty"
    },
    {
      "x": -9,
      "y": 16,
      "z": 2,
      "name": "Nat20_Force_Empty"
    },
    {
      "x": -9,
      "y": 2,
      "z": 3,
      "name": "Rock_Stone_Cobble"
    },
    {
      "x": -9,
      "y": 3,
      "z": 3,
      "name": "Nat20_Force_Empty"
    },
    {
      "x": -9,
      "y": 4,
      "z": 3,
      "name": "Nat20_Force_Empty"
    },
    {
      "x": -9,
      "y": 5,
      "z": 3,
      "name": "Nat20_Force_Empty"
    },
    {
      "x": -9,
      "y": 6,
      "z": 3,
      "name": "Wood_Deadwood_Roof_Shallow",
      "filler": 1,
      "rotation": 3
    },
    {
      "x": -9,
      "y": 7,
      "z": 3,
      "name": "Nat20_Force_Empty"
    },
    {
      "x": -9,
      "y": 8,
      "z": 3,
      "name": "Nat20_Force_Empty"
    },
    {
      "x": -9,
      "y": 9,
      "z": 3,
      "name": "Nat20_Force_Empty"
    },
    {
      "x": -9,
      "y": 10,
      "z": 3,
      "name": "Nat20_Force_Empty"
    },
    {
      "x": -9,
      "y": 11,
      "z": 3,
      "name": "Nat20_Force_Empty"
    },
    {
      "x": -9,
      "y": 12,
      "z": 3,
      "name": "Nat20_Force_Empty"
    },
    {
      "x": -9,
      "y": 13,
      "z": 3,
      "name": "Nat20_Force_Empty"
    },
    {
      "x": -9,
      "y": 14,
      "z": 3,
      "name": "Nat20_Force_Empty"
    },
    {
      "x": -9,
      "y": 15,
      "z": 3,
      "name": "Nat20_Force_Empty"
    },
    {
      "x": -9,
      "y": 16,
      "z": 3,
      "name": "Nat20_Force_Empty"
    },
    {
      "x": -9,
      "y": 2,
      "z": 4,
      "name": "Rock_Stone_Cobble"
    },
    {
      "x": -9,
      "y": 3,
      "z": 4,
      "name": "Wood_Softwood_Planks"
    },
    {
      "x": -9,
      "y": 4,
      "z": 4,
      "name": "Wood_Softwood_Decorative"
    },
    {
      "x": -9,
      "y": 5,
      "z": 4,
      "name": "Wood_Softwood_Planks"
    },
    {
      "x": -9,
      "y": 6,
      "z": 4,
      "name": "Wood_Deadwood_Roof_Shallow",
      "filler": 1,
      "rotation": 3
    },
    {
      "x": -9,
      "y": 7,
      "z": 4,
      "name": "Nat20_Force_Empty"
    },
    {
      "x": -9,
      "y": 8,
      "z": 4,
      "name": "Nat20_Force_Empty"
    },
    {
      "x": -9,
      "y": 9,
      "z": 4,
      "name": "Nat20_Force_Empty"
    },
    {
      "x": -9,
      "y": 10,
      "z": 4,
      "name": "Nat20_Force_Empty"
    },
    {
      "x": -9,
      "y": 11,
      "z": 4,
      "name": "Nat20_Force_Empty"
    },
    {
      "x": -9,
      "y": 12,
      "z": 4,
      "name": "Nat20_Force_Empty"
    },
    {
      "x": -9,
      "y": 13,
      "z": 4,
      "name": "Nat20_Force_Empty"
    },
    {
      "x": -9,
      "y": 14,
      "z": 4,
      "name": "Nat20_Force_Empty"
    },
    {
      "x": -9,
      "y": 15,
      "z": 4,
      "name": "Nat20_Force_Empty"
    },
    {
      "x": -9,
      "y": 16,
      "z": 4,
      "name": "Nat20_Force_Empty"
    },
    {
      "x": -9,
      "y": 2,
      "z": 5,
      "name": "Rock_Stone_Cobble"
    },
    {
      "x": -9,
      "y": 3,
      "z": 5,
      "name": "Rock_Stone_Cobble_Half",
      "rotation": 7
    },
    {
      "x": -9,
      "y": 4,
      "z": 5,
      "name": "Rock_Stone_Cobble_Half",
      "rotation": 7
    },
    {
      "x": -9,
      "y": 5,
      "z": 5,
      "name": "Plant_Moss_Wall_Green",
      "rotation": 3
    },
    {
      "x": -9,
      "y": 6,
      "z": 5,
      "name": "Nat20_Force_Empty"
    },
    {
      "x": -9,
      "y": 7,
      "z": 5,
      "name": "Plant_Moss_Wall_Green",
      "rotation": 3
    },
    {
      "x": -9,
      "y": 8,
      "z": 5,
      "name": "Nat20_Force_Empty"
    },
    {
      "x": -9,
      "y": 9,
      "z": 5,
      "name": "Nat20_Force_Empty"
    },
    {
      "x": -9,
      "y": 10,
      "z": 5,
      "name": "Nat20_Force_Empty"
    },
    {
      "x": -9,
      "y": 11,
      "z": 5,
      "name": "Nat20_Force_Empty"
    },
    {
      "x": -9,
      "y": 12,
      "z": 5,
      "name": "Nat20_Force_Empty"
    },
    {
      "x": -9,
      "y": 13,
      "z": 5,
      "name": "Nat20_Force_Empty"
    },
    {
      "x": -9,
      "y": 14,
      "z": 5,
      "name": "Nat20_Force_Empty"
    },
    {
      "x": -9,
      "y": 15,
      "z": 5,
      "name": "Nat20_Force_Empty"
    },
    {
      "x": -9,
      "y": 16,
      "z": 5,
      "name": "Nat20_Force_Empty"
    },
    {
      "x": -9,
      "y": 2,
      "z": 6,
      "name": "Rock_Stone_Cobble"
    },
    {
      "x": -9,
      "y": 3,
      "z": 6,
      "name": "Rock_Stone_Cobble_Half",
      "rotation": 7
    },
    {
      "x": -9,
      "y": 4,
      "z": 6,
      "name": "Rock_Stone_Cobble_Half",
      "rotation": 7
    },
    {
      "x": -9,
      "y": 5,
      "z": 6,
      "name": "Rock_Stone_Cobble_Half",
      "rotation": 7
    },
    {
      "x": -9,
      "y": 6,
      "z": 6,
      "name": "Plant_Moss_Wall_Green",
      "rotation": 3
    },
    {
      "x": -9,
      "y": 7,
      "z": 6,
      "name": "Nat20_Force_Empty"
    },
    {
      "x": -9,
      "y": 8,
      "z": 6,
      "name": "Nat20_Force_Empty"
    },
    {
      "x": -9,
      "y": 9,
      "z": 6,
      "name": "Nat20_Force_Empty"
    },
    {
      "x": -9,
      "y": 10,
      "z": 6,
      "name": "Nat20_Force_Empty"
    },
    {
      "x": -9,
      "y": 11,
      "z": 6,
      "name": "Nat20_Force_Empty"
    },
    {
      "x": -9,
      "y": 12,
      "z": 6,
      "name": "Nat20_Force_Empty"
    },
    {
      "x": -9,
      "y": 13,
      "z": 6,
      "name": "Nat20_Force_Empty"
    },
    {
      "x": -9,
      "y": 14,
      "z": 6,
      "name": "Nat20_Force_Empty"
    },
    {
      "x": -9,
      "y": 15,
      "z": 6,
      "name": "Nat20_Force_Empty"
    },
    {
      "x": -9,
      "y": 16,
      "z": 6,
      "name": "Nat20_Force_Empty"
    },
    {
      "x": -9,
      "y": 2,
      "z": 7,
      "name": "Rock_Stone_Cobble"
    },
    {
      "x": -9,
      "y": 3,
      "z": 7,
      "name": "Rock_Stone_Cobble_Half",
      "rotation": 7
    },
    {
      "x": -9,
      "y": 4,
      "z": 7,
      "name": "Nat20_Force_Empty"
    },
    {
      "x": -9,
      "y": 5,
      "z": 7,
      "name": "Nat20_Force_Empty"
    },
    {
      "x": -9,
      "y": 6,
      "z": 7,
      "name": "Nat20_Force_Empty"
    },
    {
      "x": -9,
      "y": 7,
      "z": 7,
      "name": "Nat20_Force_Empty"
    },
    {
      "x": -9,
      "y": 8,
      "z": 7,
      "name": "Nat20_Force_Empty"
    },
    {
      "x": -9,
      "y": 9,
      "z": 7,
      "name": "Nat20_Force_Empty"
    },
    {
      "x": -9,
      "y": 10,
      "z": 7,
      "name": "Plant_Moss_Wall_Green",
      "rotation": 3
    },
    {
      "x": -9,
      "y": 11,
      "z": 7,
      "name": "Plant_Moss_Wall_Green",
      "rotation": 3
    },
    {
      "x": -9,
      "y": 12,
      "z": 7,
      "name": "Nat20_Force_Empty"
    },
    {
      "x": -9,
      "y": 13,
      "z": 7,
      "name": "Nat20_Force_Empty"
    },
    {
      "x": -9,
      "y": 14,
      "z": 7,
      "name": "Nat20_Force_Empty"
    },
    {
      "x": -9,
      "y": 15,
      "z": 7,
      "name": "Nat20_Force_Empty"
    },
    {
      "x": -9,
      "y": 16,
      "z": 7,
      "name": "Nat20_Force_Empty"
    },
    {
      "x": -9,
      "y": 3,
      "z": 8,
      "name": "Nat20_Force_Empty"
    },
    {
      "x": -9,
      "y": 4,
      "z": 8,
      "name": "Nat20_Force_Empty"
    },
    {
      "x": -9,
      "y": 5,
      "z": 8,
      "name": "Nat20_Force_Empty"
    },
    {
      "x": -9,
      "y": 6,
      "z": 8,
      "name": "Nat20_Force_Empty"
    },
    {
      "x": -9,
      "y": 7,
      "z": 8,
      "name": "Nat20_Force_Empty"
    },
    {
      "x": -9,
      "y": 8,
      "z": 8,
      "name": "Nat20_Force_Empty"
    },
    {
      "x": -9,
      "y": 9,
      "z": 8,
      "name": "Nat20_Force_Empty"
    },
    {
      "x": -9,
      "y": 10,
      "z": 8,
      "name": "Nat20_Force_Empty"
    },
    {
      "x": -9,
      "y": 11,
      "z": 8,
      "name": "Nat20_Force_Empty"
    },
    {
      "x": -9,
      "y": 12,
      "z": 8,
      "name": "Nat20_Force_Empty"
    },
    {
      "x": -9,
      "y": 13,
      "z": 8,
      "name": "Nat20_Force_Empty"
    },
    {
      "x": -9,
      "y": 14,
      "z": 8,
      "name": "Nat20_Force_Empty"
    },
    {
      "x": -9,
      "y": 15,
      "z": 8,
      "name": "Nat20_Force_Empty"
    },
    {
      "x": -9,
      "y": 16,
      "z": 8,
      "name": "Nat20_Force_Empty"
    },
    {
      "x": -9,
      "y": 3,
      "z": 9,
      "name": "Nat20_Force_Empty"
    },
    {
      "x": -9,
      "y": 4,
      "z": 9,
      "name": "Nat20_Force_Empty"
    },
    {
      "x": -9,
      "y": 5,
      "z": 9,
      "name": "Nat20_Force_Empty"
    },
    {
      "x": -9,
      "y": 6,
      "z": 9,
      "name": "Nat20_Force_Empty"
    },
    {
      "x": -9,
      "y": 7,
      "z": 9,
      "name": "Nat20_Force_Empty"
    },
    {
      "x": -9,
      "y": 8,
      "z": 9,
      "name": "Nat20_Force_Empty"
    },
    {
      "x": -9,
      "y": 9,
      "z": 9,
      "name": "Nat20_Force_Empty"
    },
    {
      "x": -9,
      "y": 10,
      "z": 9,
      "name": "Nat20_Force_Empty"
    },
    {
      "x": -9,
      "y": 11,
      "z": 9,
      "name": "Nat20_Force_Empty"
    },
    {
      "x": -9,
      "y": 12,
      "z": 9,
      "name": "Nat20_Force_Empty"
    },
    {
      "x": -9,
      "y": 13,
      "z": 9,
      "name": "Nat20_Force_Empty"
    },
    {
      "x": -9,
      "y": 14,
      "z": 9,
      "name": "Nat20_Force_Empty"
    },
    {
      "x": -9,
      "y": 15,
      "z": 9,
      "name": "Nat20_Force_Empty"
    },
    {
      "x": -9,
      "y": 16,
      "z": 9,
      "name": "Nat20_Force_Empty"
    },
    {
      "x": -9,
      "y": 3,
      "z": 10,
      "name": "Nat20_Force_Empty"
    },
    {
      "x": -9,
      "y": 4,
      "z": 10,
      "name": "Nat20_Force_Empty"
    },
    {
      "x": -9,
      "y": 5,
      "z": 10,
      "name": "Nat20_Force_Empty"
    },
    {
      "x": -9,
      "y": 6,
      "z": 10,
      "name": "Nat20_Force_Empty"
    },
    {
      "x": -9,
      "y": 7,
      "z": 10,
      "name": "Nat20_Force_Empty"
    },
    {
      "x": -9,
      "y": 8,
      "z": 10,
      "name": "Nat20_Force_Empty"
    },
    {
      "x": -9,
      "y": 9,
      "z": 10,
      "name": "Nat20_Force_Empty"
    },
    {
      "x": -9,
      "y": 10,
      "z": 10,
      "name": "Nat20_Force_Empty"
    },
    {
      "x": -9,
      "y": 11,
      "z": 10,
      "name": "Nat20_Force_Empty"
    },
    {
      "x": -9,
      "y": 12,
      "z": 10,
      "name": "Nat20_Force_Empty"
    },
    {
      "x": -9,
      "y": 13,
      "z": 10,
      "name": "Nat20_Force_Empty"
    },
    {
      "x": -9,
      "y": 14,
      "z": 10,
      "name": "Nat20_Force_Empty"
    },
    {
      "x": -9,
      "y": 15,
      "z": 10,
      "name": "Nat20_Force_Empty"
    },
    {
      "x": -9,
      "y": 16,
      "z": 10,
      "name": "Nat20_Force_Empty"
    },
    {
      "x": -9,
      "y": 3,
      "z": 11,
      "name": "Nat20_Force_Empty"
    },
    {
      "x": -9,
      "y": 4,
      "z": 11,
      "name": "Nat20_Force_Empty"
    },
    {
      "x": -9,
      "y": 5,
      "z": 11,
      "name": "Nat20_Force_Empty"
    },
    {
      "x": -9,
      "y": 6,
      "z": 11,
      "name": "Nat20_Force_Empty"
    },
    {
      "x": -9,
      "y": 7,
      "z": 11,
      "name": "Nat20_Force_Empty"
    },
    {
      "x": -9,
      "y": 8,
      "z": 11,
      "name": "Nat20_Force_Empty"
    },
    {
      "x": -9,
      "y": 9,
      "z": 11,
      "name": "Nat20_Force_Empty"
    },
    {
      "x": -9,
      "y": 10,
      "z": 11,
      "name": "Nat20_Force_Empty"
    },
    {
      "x": -9,
      "y": 11,
      "z": 11,
      "name": "Nat20_Force_Empty"
    },
    {
      "x": -9,
      "y": 12,
      "z": 11,
      "name": "Nat20_Force_Empty"
    },
    {
      "x": -9,
      "y": 13,
      "z": 11,
      "name": "Nat20_Force_Empty"
    },
    {
      "x": -9,
      "y": 14,
      "z": 11,
      "name": "Nat20_Force_Empty"
    },
    {
      "x": -9,
      "y": 15,
      "z": 11,
      "name": "Nat20_Force_Empty"
    },
    {
      "x": -9,
      "y": 16,
      "z": 11,
      "name": "Nat20_Force_Empty"
    },
    {
      "x": -9,
      "y": 3,
      "z": 12,
      "name": "Nat20_Force_Empty"
    },
    {
      "x": -9,
      "y": 4,
      "z": 12,
      "name": "Nat20_Force_Empty"
    },
    {
      "x": -9,
      "y": 5,
      "z": 12,
      "name": "Nat20_Force_Empty"
    },
    {
      "x": -9,
      "y": 6,
      "z": 12,
      "name": "Nat20_Force_Empty"
    },
    {
      "x": -9,
      "y": 7,
      "z": 12,
      "name": "Nat20_Force_Empty"
    },
    {
      "x": -9,
      "y": 8,
      "z": 12,
      "name": "Nat20_Force_Empty"
    },
    {
      "x": -9,
      "y": 9,
      "z": 12,
      "name": "Nat20_Force_Empty"
    },
    {
      "x": -9,
      "y": 10,
      "z": 12,
      "name": "Nat20_Force_Empty"
    },
    {
      "x": -9,
      "y": 11,
      "z": 12,
      "name": "Nat20_Force_Empty"
    },
    {
      "x": -9,
      "y": 12,
      "z": 12,
      "name": "Nat20_Force_Empty"
    },
    {
      "x": -9,
      "y": 13,
      "z": 12,
      "name": "Nat20_Force_Empty"
    },
    {
      "x": -9,
      "y": 14,
      "z": 12,
      "name": "Nat20_Force_Empty"
    },
    {
      "x": -9,
      "y": 15,
      "z": 12,
      "name": "Nat20_Force_Empty"
    },
    {
      "x": -9,
      "y": 16,
      "z": 12,
      "name": "Nat20_Force_Empty"
    },
    {
      "x": -8,
      "y": 3,
      "z": -11,
      "name": "Nat20_Force_Empty"
    },
    {
      "x": -8,
      "y": 4,
      "z": -11,
      "name": "Nat20_Force_Empty"
    },
    {
      "x": -8,
      "y": 5,
      "z": -11,
      "name": "Nat20_Force_Empty"
    },
    {
      "x": -8,
      "y": 6,
      "z": -11,
      "name": "Nat20_Force_Empty"
    },
    {
      "x": -8,
      "y": 7,
      "z": -11,
      "name": "Nat20_Force_Empty"
    },
    {
      "x": -8,
      "y": 8,
      "z": -11,
      "name": "Nat20_Force_Empty"
    },
    {
      "x": -8,
      "y": 9,
      "z": -11,
      "name": "Nat20_Force_Empty"
    },
    {
      "x": -8,
      "y": 10,
      "z": -11,
      "name": "Nat20_Force_Empty"
    },
    {
      "x": -8,
      "y": 11,
      "z": -11,
      "name": "Nat20_Force_Empty"
    },
    {
      "x": -8,
      "y": 12,
      "z": -11,
      "name": "Nat20_Force_Empty"
    },
    {
      "x": -8,
      "y": 13,
      "z": -11,
      "name": "Nat20_Force_Empty"
    },
    {
      "x": -8,
      "y": 14,
      "z": -11,
      "name": "Nat20_Force_Empty"
    },
    {
      "x": -8,
      "y": 15,
      "z": -11,
      "name": "Nat20_Force_Empty"
    },
    {
      "x": -8,
      "y": 16,
      "z": -11,
      "name": "Nat20_Force_Empty"
    },
    {
      "x": -8,
      "y": 3,
      "z": -10,
      "name": "Nat20_Force_Empty"
    },
    {
      "x": -8,
      "y": 4,
      "z": -10,
      "name": "Nat20_Force_Empty"
    },
    {
      "x": -8,
      "y": 5,
      "z": -10,
      "name": "Nat20_Force_Empty"
    },
    {
      "x": -8,
      "y": 6,
      "z": -10,
      "name": "Nat20_Force_Empty"
    },
    {
      "x": -8,
      "y": 7,
      "z": -10,
      "name": "Nat20_Force_Empty"
    },
    {
      "x": -8,
      "y": 8,
      "z": -10,
      "name": "Nat20_Force_Empty"
    },
    {
      "x": -8,
      "y": 9,
      "z": -10,
      "name": "Nat20_Force_Empty"
    },
    {
      "x": -8,
      "y": 10,
      "z": -10,
      "name": "Nat20_Force_Empty"
    },
    {
      "x": -8,
      "y": 11,
      "z": -10,
      "name": "Nat20_Force_Empty"
    },
    {
      "x": -8,
      "y": 12,
      "z": -10,
      "name": "Nat20_Force_Empty"
    },
    {
      "x": -8,
      "y": 13,
      "z": -10,
      "name": "Nat20_Force_Empty"
    },
    {
      "x": -8,
      "y": 14,
      "z": -10,
      "name": "Nat20_Force_Empty"
    },
    {
      "x": -8,
      "y": 15,
      "z": -10,
      "name": "Nat20_Force_Empty"
    },
    {
      "x": -8,
      "y": 16,
      "z": -10,
      "name": "Nat20_Force_Empty"
    },
    {
      "x": -8,
      "y": 3,
      "z": -9,
      "name": "Nat20_Force_Empty"
    },
    {
      "x": -8,
      "y": 4,
      "z": -9,
      "name": "Nat20_Force_Empty"
    },
    {
      "x": -8,
      "y": 5,
      "z": -9,
      "name": "Nat20_Force_Empty"
    },
    {
      "x": -8,
      "y": 6,
      "z": -9,
      "name": "Nat20_Force_Empty"
    },
    {
      "x": -8,
      "y": 7,
      "z": -9,
      "name": "Nat20_Force_Empty"
    },
    {
      "x": -8,
      "y": 8,
      "z": -9,
      "name": "Nat20_Force_Empty"
    },
    {
      "x": -8,
      "y": 9,
      "z": -9,
      "name": "Nat20_Force_Empty"
    },
    {
      "x": -8,
      "y": 10,
      "z": -9,
      "name": "Nat20_Force_Empty"
    },
    {
      "x": -8,
      "y": 11,
      "z": -9,
      "name": "Nat20_Force_Empty"
    },
    {
      "x": -8,
      "y": 12,
      "z": -9,
      "name": "Nat20_Force_Empty"
    },
    {
      "x": -8,
      "y": 13,
      "z": -9,
      "name": "Nat20_Force_Empty"
    },
    {
      "x": -8,
      "y": 14,
      "z": -9,
      "name": "Nat20_Force_Empty"
    },
    {
      "x": -8,
      "y": 15,
      "z": -9,
      "name": "Nat20_Force_Empty"
    },
    {
      "x": -8,
      "y": 16,
      "z": -9,
      "name": "Nat20_Force_Empty"
    },
    {
      "x": -8,
      "y": 3,
      "z": -8,
      "name": "Nat20_Force_Empty"
    },
    {
      "x": -8,
      "y": 4,
      "z": -8,
      "name": "Nat20_Force_Empty"
    },
    {
      "x": -8,
      "y": 5,
      "z": -8,
      "name": "Nat20_Force_Empty"
    },
    {
      "x": -8,
      "y": 6,
      "z": -8,
      "name": "Nat20_Force_Empty"
    },
    {
      "x": -8,
      "y": 7,
      "z": -8,
      "name": "Nat20_Force_Empty"
    },
    {
      "x": -8,
      "y": 8,
      "z": -8,
      "name": "Nat20_Force_Empty"
    },
    {
      "x": -8,
      "y": 9,
      "z": -8,
      "name": "Nat20_Force_Empty"
    },
    {
      "x": -8,
      "y": 10,
      "z": -8,
      "name": "Nat20_Force_Empty"
    },
    {
      "x": -8,
      "y": 11,
      "z": -8,
      "name": "Nat20_Force_Empty"
    },
    {
      "x": -8,
      "y": 12,
      "z": -8,
      "name": "Nat20_Force_Empty"
    },
    {
      "x": -8,
      "y": 13,
      "z": -8,
      "name": "Nat20_Force_Empty"
    },
    {
      "x": -8,
      "y": 14,
      "z": -8,
      "name": "Nat20_Force_Empty"
    },
    {
      "x": -8,
      "y": 15,
      "z": -8,
      "name": "Nat20_Force_Empty"
    },
    {
      "x": -8,
      "y": 16,
      "z": -8,
      "name": "Nat20_Force_Empty"
    },
    {
      "x": -8,
      "y": 3,
      "z": -7,
      "name": "Nat20_Force_Empty"
    },
    {
      "x": -8,
      "y": 4,
      "z": -7,
      "name": "Nat20_Force_Empty"
    },
    {
      "x": -8,
      "y": 5,
      "z": -7,
      "name": "Nat20_Force_Empty"
    },
    {
      "x": -8,
      "y": 6,
      "z": -7,
      "name": "Nat20_Force_Empty"
    },
    {
      "x": -8,
      "y": 7,
      "z": -7,
      "name": "Nat20_Force_Empty"
    },
    {
      "x": -8,
      "y": 8,
      "z": -7,
      "name": "Nat20_Force_Empty"
    },
    {
      "x": -8,
      "y": 9,
      "z": -7,
      "name": "Nat20_Force_Empty"
    },
    {
      "x": -8,
      "y": 10,
      "z": -7,
      "name": "Nat20_Force_Empty"
    },
    {
      "x": -8,
      "y": 11,
      "z": -7,
      "name": "Nat20_Force_Empty"
    },
    {
      "x": -8,
      "y": 12,
      "z": -7,
      "name": "Nat20_Force_Empty"
    },
    {
      "x": -8,
      "y": 13,
      "z": -7,
      "name": "Nat20_Force_Empty"
    },
    {
      "x": -8,
      "y": 14,
      "z": -7,
      "name": "Nat20_Force_Empty"
    },
    {
      "x": -8,
      "y": 15,
      "z": -7,
      "name": "Nat20_Force_Empty"
    },
    {
      "x": -8,
      "y": 16,
      "z": -7,
      "name": "Nat20_Force_Empty"
    },
    {
      "x": -8,
      "y": 3,
      "z": -6,
      "name": "Nat20_Force_Empty"
    },
    {
      "x": -8,
      "y": 4,
      "z": -6,
      "name": "Nat20_Force_Empty"
    },
    {
      "x": -8,
      "y": 5,
      "z": -6,
      "name": "Nat20_Force_Empty"
    },
    {
      "x": -8,
      "y": 6,
      "z": -6,
      "name": "Nat20_Force_Empty"
    },
    {
      "x": -8,
      "y": 7,
      "z": -6,
      "name": "Nat20_Force_Empty"
    },
    {
      "x": -8,
      "y": 8,
      "z": -6,
      "name": "Nat20_Force_Empty"
    },
    {
      "x": -8,
      "y": 9,
      "z": -6,
      "name": "Nat20_Force_Empty"
    },
    {
      "x": -8,
      "y": 10,
      "z": -6,
      "name": "Nat20_Force_Empty"
    },
    {
      "x": -8,
      "y": 11,
      "z": -6,
      "name": "Nat20_Force_Empty"
    },
    {
      "x": -8,
      "y": 12,
      "z": -6,
      "name": "Nat20_Force_Empty"
    },
    {
      "x": -8,
      "y": 13,
      "z": -6,
      "name": "Nat20_Force_Empty"
    },
    {
      "x": -8,
      "y": 14,
      "z": -6,
      "name": "Nat20_Force_Empty"
    },
    {
      "x": -8,
      "y": 15,
      "z": -6,
      "name": "Nat20_Force_Empty"
    },
    {
      "x": -8,
      "y": 16,
      "z": -6,
      "name": "Nat20_Force_Empty"
    },
    {
      "x": -8,
      "y": 3,
      "z": -5,
      "name": "Nat20_Force_Empty"
    },
    {
      "x": -8,
      "y": 4,
      "z": -5,
      "name": "Nat20_Force_Empty"
    },
    {
      "x": -8,
      "y": 5,
      "z": -5,
      "name": "Nat20_Force_Empty"
    },
    {
      "x": -8,
      "y": 6,
      "z": -5,
      "name": "Nat20_Force_Empty"
    },
    {
      "x": -8,
      "y": 7,
      "z": -5,
      "name": "Nat20_Force_Empty"
    },
    {
      "x": -8,
      "y": 8,
      "z": -5,
      "name": "Nat20_Force_Empty"
    },
    {
      "x": -8,
      "y": 9,
      "z": -5,
      "name": "Nat20_Force_Empty"
    },
    {
      "x": -8,
      "y": 10,
      "z": -5,
      "name": "Nat20_Force_Empty"
    },
    {
      "x": -8,
      "y": 11,
      "z": -5,
      "name": "Nat20_Force_Empty"
    },
    {
      "x": -8,
      "y": 12,
      "z": -5,
      "name": "Nat20_Force_Empty"
    },
    {
      "x": -8,
      "y": 13,
      "z": -5,
      "name": "Nat20_Force_Empty"
    },
    {
      "x": -8,
      "y": 14,
      "z": -5,
      "name": "Nat20_Force_Empty"
    },
    {
      "x": -8,
      "y": 15,
      "z": -5,
      "name": "Nat20_Force_Empty"
    },
    {
      "x": -8,
      "y": 16,
      "z": -5,
      "name": "Nat20_Force_Empty"
    },
    {
      "x": -8,
      "y": 2,
      "z": -4,
      "name": "Rock_Stone_Cobble"
    },
    {
      "x": -8,
      "y": 3,
      "z": -4,
      "name": "Wood_Softwood_Decorative"
    },
    {
      "x": -8,
      "y": 4,
      "z": -4,
      "name": "Wood_Softwood_Beam",
      "rotation": 5
    },
    {
      "x": -8,
      "y": 5,
      "z": -4,
      "name": "Wood_Softwood_Beam",
      "rotation": 5
    },
    {
      "x": -8,
      "y": 6,
      "z": -4,
      "name": "Wood_Softwood_Planks"
    },
    {
      "x": -8,
      "y": 7,
      "z": -4,
      "name": "Wood_Deadwood_Roof_Shallow",
      "rotation": 3
    },
    {
      "x": -8,
      "y": 8,
      "z": -4,
      "name": "Nat20_Force_Empty"
    },
    {
      "x": -8,
      "y": 9,
      "z": -4,
      "name": "Nat20_Force_Empty"
    },
    {
      "x": -8,
      "y": 10,
      "z": -4,
      "name": "Nat20_Force_Empty"
    },
    {
      "x": -8,
      "y": 11,
      "z": -4,
      "name": "Nat20_Force_Empty"
    },
    {
      "x": -8,
      "y": 12,
      "z": -4,
      "name": "Nat20_Force_Empty"
    },
    {
      "x": -8,
      "y": 13,
      "z": -4,
      "name": "Nat20_Force_Empty"
    },
    {
      "x": -8,
      "y": 14,
      "z": -4,
      "name": "Nat20_Force_Empty"
    },
    {
      "x": -8,
      "y": 15,
      "z": -4,
      "name": "Nat20_Force_Empty"
    },
    {
      "x": -8,
      "y": 16,
      "z": -4,
      "name": "Nat20_Force_Empty"
    },
    {
      "x": -8,
      "y": 2,
      "z": -3,
      "name": "Rock_Stone_Cobble"
    },
    {
      "x": -8,
      "y": 3,
      "z": -3,
      "name": "Plant_Moss_Wall_Green"
    },
    {
      "x": -8,
      "y": 4,
      "z": -3,
      "name": "Nat20_Force_Empty"
    },
    {
      "x": -8,
      "y": 5,
      "z": -3,
      "name": "Nat20_Force_Empty"
    },
    {
      "x": -8,
      "y": 6,
      "z": -3,
      "name": "Wood_Softwood_Planks_Half",
      "rotation": 8
    },
    {
      "x": -8,
      "y": 7,
      "z": -3,
      "name": "Wood_Deadwood_Roof_Shallow",
      "rotation": 3
    },
    {
      "x": -8,
      "y": 8,
      "z": -3,
      "name": "Nat20_Force_Empty"
    },
    {
      "x": -8,
      "y": 9,
      "z": -3,
      "name": "Nat20_Force_Empty"
    },
    {
      "x": -8,
      "y": 10,
      "z": -3,
      "name": "Nat20_Force_Empty"
    },
    {
      "x": -8,
      "y": 11,
      "z": -3,
      "name": "Nat20_Force_Empty"
    },
    {
      "x": -8,
      "y": 12,
      "z": -3,
      "name": "Nat20_Force_Empty"
    },
    {
      "x": -8,
      "y": 13,
      "z": -3,
      "name": "Nat20_Force_Empty"
    },
    {
      "x": -8,
      "y": 14,
      "z": -3,
      "name": "Nat20_Force_Empty"
    },
    {
      "x": -8,
      "y": 15,
      "z": -3,
      "name": "Nat20_Force_Empty"
    },
    {
      "x": -8,
      "y": 16,
      "z": -3,
      "name": "Nat20_Force_Empty"
    },
    {
      "x": -8,
      "y": 2,
      "z": -2,
      "name": "Rock_Stone_Cobble"
    },
    {
      "x": -8,
      "y": 3,
      "z": -2,
      "name": "*Rail_State_Definitions_Corner_Left",
      "rotation": 1
    },
    {
      "x": -8,
      "y": 4,
      "z": -2,
      "name": "Nat20_Force_Empty"
    },
    {
      "x": -8,
      "y": 5,
      "z": -2,
      "name": "Nat20_Force_Empty"
    },
    {
      "x": -8,
      "y": 6,
      "z": -2,
      "name": "Wood_Softwood_Planks_Half",
      "rotation": 8
    },
    {
      "x": -8,
      "y": 7,
      "z": -2,
      "name": "Wood_Deadwood_Roof_Shallow",
      "rotation": 3
    },
    {
      "x": -8,
      "y": 8,
      "z": -2,
      "name": "Nat20_Force_Empty"
    },
    {
      "x": -8,
      "y": 9,
      "z": -2,
      "name": "Nat20_Force_Empty"
    },
    {
      "x": -8,
      "y": 10,
      "z": -2,
      "name": "Nat20_Force_Empty"
    },
    {
      "x": -8,
      "y": 11,
      "z": -2,
      "name": "Nat20_Force_Empty"
    },
    {
      "x": -8,
      "y": 12,
      "z": -2,
      "name": "Nat20_Force_Empty"
    },
    {
      "x": -8,
      "y": 13,
      "z": -2,
      "name": "Nat20_Force_Empty"
    },
    {
      "x": -8,
      "y": 14,
      "z": -2,
      "name": "Nat20_Force_Empty"
    },
    {
      "x": -8,
      "y": 15,
      "z": -2,
      "name": "Nat20_Force_Empty"
    },
    {
      "x": -8,
      "y": 16,
      "z": -2,
      "name": "Nat20_Force_Empty"
    },
    {
      "x": -8,
      "y": 2,
      "z": -1,
      "name": "Rock_Stone_Cobble"
    },
    {
      "x": -8,
      "y": 3,
      "z": -1,
      "name": "Rail",
      "rotation": 2
    },
    {
      "x": -8,
      "y": 4,
      "z": -1,
      "name": "Nat20_Force_Empty"
    },
    {
      "x": -8,
      "y": 5,
      "z": -1,
      "name": "Nat20_Force_Empty"
    },
    {
      "x": -8,
      "y": 6,
      "z": -1,
      "name": "Wood_Softwood_Planks_Half",
      "rotation": 8
    },
    {
      "x": -8,
      "y": 7,
      "z": -1,
      "name": "Wood_Deadwood_Roof_Shallow",
      "rotation": 3
    },
    {
      "x": -8,
      "y": 8,
      "z": -1,
      "name": "Nat20_Force_Empty"
    },
    {
      "x": -8,
      "y": 9,
      "z": -1,
      "name": "Nat20_Force_Empty"
    },
    {
      "x": -8,
      "y": 10,
      "z": -1,
      "name": "Nat20_Force_Empty"
    },
    {
      "x": -8,
      "y": 11,
      "z": -1,
      "name": "Nat20_Force_Empty"
    },
    {
      "x": -8,
      "y": 12,
      "z": -1,
      "name": "Nat20_Force_Empty"
    },
    {
      "x": -8,
      "y": 13,
      "z": -1,
      "name": "Nat20_Force_Empty"
    },
    {
      "x": -8,
      "y": 14,
      "z": -1,
      "name": "Nat20_Force_Empty"
    },
    {
      "x": -8,
      "y": 15,
      "z": -1,
      "name": "Nat20_Force_Empty"
    },
    {
      "x": -8,
      "y": 16,
      "z": -1,
      "name": "Nat20_Force_Empty"
    },
    {
      "x": -8,
      "y": 2,
      "z": 0,
      "name": "Rock_Stone_Cobble"
    },
    {
      "x": -8,
      "y": 3,
      "z": 0,
      "name": "Rail",
      "rotation": 2
    },
    {
      "x": -8,
      "y": 4,
      "z": 0,
      "name": "Nat20_Force_Empty"
    },
    {
      "x": -8,
      "y": 5,
      "z": 0,
      "name": "Nat20_Force_Empty"
    },
    {
      "x": -8,
      "y": 6,
      "z": 0,
      "name": "Wood_Softwood_Planks_Half",
      "rotation": 8
    },
    {
      "x": -8,
      "y": 7,
      "z": 0,
      "name": "Wood_Deadwood_Roof_Shallow",
      "rotation": 3
    },
    {
      "x": -8,
      "y": 8,
      "z": 0,
      "name": "Nat20_Force_Empty"
    },
    {
      "x": -8,
      "y": 9,
      "z": 0,
      "name": "Nat20_Force_Empty"
    },
    {
      "x": -8,
      "y": 10,
      "z": 0,
      "name": "Nat20_Force_Empty"
    },
    {
      "x": -8,
      "y": 11,
      "z": 0,
      "name": "Nat20_Force_Empty"
    },
    {
      "x": -8,
      "y": 12,
      "z": 0,
      "name": "Nat20_Force_Empty"
    },
    {
      "x": -8,
      "y": 13,
      "z": 0,
      "name": "Nat20_Force_Empty"
    },
    {
      "x": -8,
      "y": 14,
      "z": 0,
      "name": "Nat20_Force_Empty"
    },
    {
      "x": -8,
      "y": 15,
      "z": 0,
      "name": "Nat20_Force_Empty"
    },
    {
      "x": -8,
      "y": 16,
      "z": 0,
      "name": "Nat20_Force_Empty"
    },
    {
      "x": -8,
      "y": 2,
      "z": 1,
      "name": "Rock_Stone_Cobble"
    },
    {
      "x": -8,
      "y": 3,
      "z": 1,
      "name": "Nat20_Force_Empty"
    },
    {
      "x": -8,
      "y": 4,
      "z": 1,
      "name": "Nat20_Force_Empty"
    },
    {
      "x": -8,
      "y": 5,
      "z": 1,
      "name": "Nat20_Force_Empty"
    },
    {
      "x": -8,
      "y": 6,
      "z": 1,
      "name": "Wood_Softwood_Planks_Half",
      "rotation": 8
    },
    {
      "x": -8,
      "y": 7,
      "z": 1,
      "name": "Wood_Deadwood_Roof_Shallow",
      "rotation": 3
    },
    {
      "x": -8,
      "y": 8,
      "z": 1,
      "name": "Nat20_Force_Empty"
    },
    {
      "x": -8,
      "y": 9,
      "z": 1,
      "name": "Nat20_Force_Empty"
    },
    {
      "x": -8,
      "y": 10,
      "z": 1,
      "name": "Nat20_Force_Empty"
    },
    {
      "x": -8,
      "y": 11,
      "z": 1,
      "name": "Nat20_Force_Empty"
    },
    {
      "x": -8,
      "y": 12,
      "z": 1,
      "name": "Nat20_Force_Empty"
    },
    {
      "x": -8,
      "y": 13,
      "z": 1,
      "name": "Nat20_Force_Empty"
    },
    {
      "x": -8,
      "y": 14,
      "z": 1,
      "name": "Nat20_Force_Empty"
    },
    {
      "x": -8,
      "y": 15,
      "z": 1,
      "name": "Nat20_Force_Empty"
    },
    {
      "x": -8,
      "y": 16,
      "z": 1,
      "name": "Nat20_Force_Empty"
    },
    {
      "x": -8,
      "y": 2,
      "z": 2,
      "name": "Rock_Stone_Cobble"
    },
    {
      "x": -8,
      "y": 3,
      "z": 2,
      "name": "Nat20_Force_Empty"
    },
    {
      "x": -8,
      "y": 4,
      "z": 2,
      "name": "Nat20_Force_Empty"
    },
    {
      "x": -8,
      "y": 5,
      "z": 2,
      "name": "Nat20_Force_Empty"
    },
    {
      "x": -8,
      "y": 6,
      "z": 2,
      "name": "Wood_Softwood_Planks_Half",
      "rotation": 8
    },
    {
      "x": -8,
      "y": 7,
      "z": 2,
      "name": "Wood_Deadwood_Roof_Shallow",
      "rotation": 3
    },
    {
      "x": -8,
      "y": 8,
      "z": 2,
      "name": "Nat20_Force_Empty"
    },
    {
      "x": -8,
      "y": 9,
      "z": 2,
      "name": "Nat20_Force_Empty"
    },
    {
      "x": -8,
      "y": 10,
      "z": 2,
      "name": "Nat20_Force_Empty"
    },
    {
      "x": -8,
      "y": 11,
      "z": 2,
      "name": "Nat20_Force_Empty"
    },
    {
      "x": -8,
      "y": 12,
      "z": 2,
      "name": "Nat20_Force_Empty"
    },
    {
      "x": -8,
      "y": 13,
      "z": 2,
      "name": "Nat20_Force_Empty"
    },
    {
      "x": -8,
      "y": 14,
      "z": 2,
      "name": "Nat20_Force_Empty"
    },
    {
      "x": -8,
      "y": 15,
      "z": 2,
      "name": "Nat20_Force_Empty"
    },
    {
      "x": -8,
      "y": 16,
      "z": 2,
      "name": "Nat20_Force_Empty"
    },
    {
      "x": -8,
      "y": 2,
      "z": 3,
      "name": "Rock_Stone_Cobble"
    },
    {
      "x": -8,
      "y": 3,
      "z": 3,
      "name": "Nat20_Force_Empty"
    },
    {
      "x": -8,
      "y": 4,
      "z": 3,
      "name": "Nat20_Force_Empty"
    },
    {
      "x": -8,
      "y": 5,
      "z": 3,
      "name": "Nat20_Force_Empty"
    },
    {
      "x": -8,
      "y": 6,
      "z": 3,
      "name": "Wood_Softwood_Planks_Half",
      "rotation": 8
    },
    {
      "x": -8,
      "y": 7,
      "z": 3,
      "name": "Wood_Deadwood_Roof_Shallow",
      "rotation": 3
    },
    {
      "x": -8,
      "y": 8,
      "z": 3,
      "name": "Nat20_Force_Empty"
    },
    {
      "x": -8,
      "y": 9,
      "z": 3,
      "name": "Nat20_Force_Empty"
    },
    {
      "x": -8,
      "y": 10,
      "z": 3,
      "name": "Nat20_Force_Empty"
    },
    {
      "x": -8,
      "y": 11,
      "z": 3,
      "name": "Nat20_Force_Empty"
    },
    {
      "x": -8,
      "y": 12,
      "z": 3,
      "name": "Nat20_Force_Empty"
    },
    {
      "x": -8,
      "y": 13,
      "z": 3,
      "name": "Nat20_Force_Empty"
    },
    {
      "x": -8,
      "y": 14,
      "z": 3,
      "name": "Nat20_Force_Empty"
    },
    {
      "x": -8,
      "y": 15,
      "z": 3,
      "name": "Nat20_Force_Empty"
    },
    {
      "x": -8,
      "y": 16,
      "z": 3,
      "name": "Nat20_Force_Empty"
    },
    {
      "x": -8,
      "y": 2,
      "z": 4,
      "name": "Rock_Stone_Cobble"
    },
    {
      "x": -8,
      "y": 3,
      "z": 4,
      "name": "Wood_Softwood_Decorative"
    },
    {
      "x": -8,
      "y": 4,
      "z": 4,
      "name": "Wood_Softwood_Planks"
    },
    {
      "x": -8,
      "y": 5,
      "z": 4,
      "name": "Wood_Softwood_Planks"
    },
    {
      "x": -8,
      "y": 6,
      "z": 4,
      "name": "Wood_Softwood_Planks"
    },
    {
      "x": -8,
      "y": 7,
      "z": 4,
      "name": "Wood_Deadwood_Roof_Shallow",
      "rotation": 3
    },
    {
      "x": -8,
      "y": 8,
      "z": 4,
      "name": "Nat20_Force_Empty"
    },
    {
      "x": -8,
      "y": 9,
      "z": 4,
      "name": "Nat20_Force_Empty"
    },
    {
      "x": -8,
      "y": 10,
      "z": 4,
      "name": "Nat20_Force_Empty"
    },
    {
      "x": -8,
      "y": 11,
      "z": 4,
      "name": "Nat20_Force_Empty"
    },
    {
      "x": -8,
      "y": 12,
      "z": 4,
      "name": "Nat20_Force_Empty"
    },
    {
      "x": -8,
      "y": 13,
      "z": 4,
      "name": "Nat20_Force_Empty"
    },
    {
      "x": -8,
      "y": 14,
      "z": 4,
      "name": "Nat20_Force_Empty"
    },
    {
      "x": -8,
      "y": 15,
      "z": 4,
      "name": "Nat20_Force_Empty"
    },
    {
      "x": -8,
      "y": 16,
      "z": 4,
      "name": "Nat20_Force_Empty"
    },
    {
      "x": -8,
      "y": 2,
      "z": 5,
      "name": "Rock_Stone_Cobble"
    },
    {
      "x": -8,
      "y": 3,
      "z": 5,
      "name": "Rock_Stone_Cobble"
    },
    {
      "x": -8,
      "y": 4,
      "z": 5,
      "name": "Rock_Stone_Cobble"
    },
    {
      "x": -8,
      "y": 5,
      "z": 5,
      "name": "Rock_Stone_Cobble_Mossy"
    },
    {
      "x": -8,
      "y": 6,
      "z": 5,
      "name": "Rock_Stone_Cobble"
    },
    {
      "x": -8,
      "y": 7,
      "z": 5,
      "name": "Rock_Stone_Cobble"
    },
    {
      "x": -8,
      "y": 8,
      "z": 5,
      "name": "Rock_Stone_Cobble"
    },
    {
      "x": -8,
      "y": 9,
      "z": 5,
      "name": "Rock_Stone_Cobble"
    },
    {
      "x": -8,
      "y": 10,
      "z": 5,
      "name": "Rock_Stone_Cobble"
    },
    {
      "x": -8,
      "y": 11,
      "z": 5,
      "name": "Rock_Stone_Cobble_Half",
      "rotation": 6
    },
    {
      "x": -8,
      "y": 12,
      "z": 5,
      "name": "Rock_Stone_Cobble_Half",
      "rotation": 6
    },
    {
      "x": -8,
      "y": 13,
      "z": 5,
      "name": "Rock_Stone_Cobble_Half",
      "rotation": 6
    },
    {
      "x": -8,
      "y": 14,
      "z": 5,
      "name": "Nat20_Force_Empty"
    },
    {
      "x": -8,
      "y": 15,
      "z": 5,
      "name": "Nat20_Force_Empty"
    },
    {
      "x": -8,
      "y": 16,
      "z": 5,
      "name": "Nat20_Force_Empty"
    },
    {
      "x": -8,
      "y": 2,
      "z": 6,
      "name": "Rock_Stone_Cobble"
    },
    {
      "x": -8,
      "y": 3,
      "z": 6,
      "name": "Rock_Stone_Cobble"
    },
    {
      "x": -8,
      "y": 4,
      "z": 6,
      "name": "Rock_Stone_Cobble"
    },
    {
      "x": -8,
      "y": 5,
      "z": 6,
      "name": "Rock_Stone_Cobble"
    },
    {
      "x": -8,
      "y": 6,
      "z": 6,
      "name": "Rock_Stone_Cobble_Mossy"
    },
    {
      "x": -8,
      "y": 7,
      "z": 6,
      "name": "Rock_Stone_Cobble"
    },
    {
      "x": -8,
      "y": 8,
      "z": 6,
      "name": "Rock_Stone_Cobble"
    },
    {
      "x": -8,
      "y": 9,
      "z": 6,
      "name": "Rock_Stone_Cobble"
    },
    {
      "x": -8,
      "y": 10,
      "z": 6,
      "name": "Rock_Stone_Cobble"
    },
    {
      "x": -8,
      "y": 11,
      "z": 6,
      "name": "Rock_Stone_Cobble_Mossy"
    },
    {
      "x": -8,
      "y": 12,
      "z": 6,
      "name": "Rock_Stone_Cobble"
    },
    {
      "x": -8,
      "y": 13,
      "z": 6,
      "name": "Rock_Stone_Cobble"
    },
    {
      "x": -8,
      "y": 14,
      "z": 6,
      "name": "Rock_Stone_Cobble"
    },
    {
      "x": -8,
      "y": 15,
      "z": 6,
      "name": "Rock_Stone_Cobble_Mossy"
    },
    {
      "x": -8,
      "y": 16,
      "z": 6,
      "name": "Nat20_Force_Empty"
    },
    {
      "x": -8,
      "y": 2,
      "z": 7,
      "name": "Rock_Stone_Cobble"
    },
    {
      "x": -8,
      "y": 3,
      "z": 7,
      "name": "Rock_Stone_Cobble"
    },
    {
      "x": -8,
      "y": 4,
      "z": 7,
      "name": "Rock_Stone_Cobble_Mossy"
    },
    {
      "x": -8,
      "y": 5,
      "z": 7,
      "name": "Rock_Stone_Cobble"
    },
    {
      "x": -8,
      "y": 6,
      "z": 7,
      "name": "Rock_Stone_Cobble"
    },
    {
      "x": -8,
      "y": 7,
      "z": 7,
      "name": "Rock_Stone_Cobble"
    },
    {
      "x": -8,
      "y": 8,
      "z": 7,
      "name": "Rock_Stone_Cobble"
    },
    {
      "x": -8,
      "y": 9,
      "z": 7,
      "name": "Rock_Stone_Cobble_Mossy"
    },
    {
      "x": -8,
      "y": 10,
      "z": 7,
      "name": "Rock_Stone_Cobble_Mossy"
    },
    {
      "x": -8,
      "y": 11,
      "z": 7,
      "name": "Rock_Stone_Cobble_Mossy"
    },
    {
      "x": -8,
      "y": 12,
      "z": 7,
      "name": "Rock_Stone_Cobble_Half",
      "rotation": 4
    },
    {
      "x": -8,
      "y": 13,
      "z": 7,
      "name": "Rock_Stone_Cobble_Half",
      "rotation": 4
    },
    {
      "x": -8,
      "y": 14,
      "z": 7,
      "name": "Rock_Stone_Cobble_Half",
      "rotation": 4
    },
    {
      "x": -8,
      "y": 15,
      "z": 7,
      "name": "Nat20_Force_Empty"
    },
    {
      "x": -8,
      "y": 16,
      "z": 7,
      "name": "Nat20_Force_Empty"
    },
    {
      "x": -8,
      "y": 2,
      "z": 8,
      "name": "Rock_Stone_Cobble"
    },
    {
      "x": -8,
      "y": 3,
      "z": 8,
      "name": "Rock_Stone_Cobble_Half",
      "rotation": 4
    },
    {
      "x": -8,
      "y": 4,
      "z": 8,
      "name": "Nat20_Force_Empty"
    },
    {
      "x": -8,
      "y": 5,
      "z": 8,
      "name": "Nat20_Force_Empty"
    },
    {
      "x": -8,
      "y": 6,
      "z": 8,
      "name": "Nat20_Force_Empty"
    },
    {
      "x": -8,
      "y": 7,
      "z": 8,
      "name": "Nat20_Force_Empty"
    },
    {
      "x": -8,
      "y": 8,
      "z": 8,
      "name": "Nat20_Force_Empty"
    },
    {
      "x": -8,
      "y": 9,
      "z": 8,
      "name": "Nat20_Force_Empty"
    },
    {
      "x": -8,
      "y": 10,
      "z": 8,
      "name": "Nat20_Force_Empty"
    },
    {
      "x": -8,
      "y": 11,
      "z": 8,
      "name": "Nat20_Force_Empty"
    },
    {
      "x": -8,
      "y": 12,
      "z": 8,
      "name": "Nat20_Force_Empty"
    },
    {
      "x": -8,
      "y": 13,
      "z": 8,
      "name": "Nat20_Force_Empty"
    },
    {
      "x": -8,
      "y": 14,
      "z": 8,
      "name": "Nat20_Force_Empty"
    },
    {
      "x": -8,
      "y": 15,
      "z": 8,
      "name": "Nat20_Force_Empty"
    },
    {
      "x": -8,
      "y": 16,
      "z": 8,
      "name": "Nat20_Force_Empty"
    },
    {
      "x": -8,
      "y": 3,
      "z": 9,
      "name": "Nat20_Force_Empty"
    },
    {
      "x": -8,
      "y": 4,
      "z": 9,
      "name": "Nat20_Force_Empty"
    },
    {
      "x": -8,
      "y": 5,
      "z": 9,
      "name": "Nat20_Force_Empty"
    },
    {
      "x": -8,
      "y": 6,
      "z": 9,
      "name": "Nat20_Force_Empty"
    },
    {
      "x": -8,
      "y": 7,
      "z": 9,
      "name": "Nat20_Force_Empty"
    },
    {
      "x": -8,
      "y": 8,
      "z": 9,
      "name": "Nat20_Force_Empty"
    },
    {
      "x": -8,
      "y": 9,
      "z": 9,
      "name": "Nat20_Force_Empty"
    },
    {
      "x": -8,
      "y": 10,
      "z": 9,
      "name": "Nat20_Force_Empty"
    },
    {
      "x": -8,
      "y": 11,
      "z": 9,
      "name": "Nat20_Force_Empty"
    },
    {
      "x": -8,
      "y": 12,
      "z": 9,
      "name": "Nat20_Force_Empty"
    },
    {
      "x": -8,
      "y": 13,
      "z": 9,
      "name": "Nat20_Force_Empty"
    },
    {
      "x": -8,
      "y": 14,
      "z": 9,
      "name": "Nat20_Force_Empty"
    },
    {
      "x": -8,
      "y": 15,
      "z": 9,
      "name": "Nat20_Force_Empty"
    },
    {
      "x": -8,
      "y": 16,
      "z": 9,
      "name": "Nat20_Force_Empty"
    },
    {
      "x": -8,
      "y": 3,
      "z": 10,
      "name": "Nat20_Force_Empty"
    },
    {
      "x": -8,
      "y": 4,
      "z": 10,
      "name": "Nat20_Force_Empty"
    },
    {
      "x": -8,
      "y": 5,
      "z": 10,
      "name": "Nat20_Force_Empty"
    },
    {
      "x": -8,
      "y": 6,
      "z": 10,
      "name": "Nat20_Force_Empty"
    },
    {
      "x": -8,
      "y": 7,
      "z": 10,
      "name": "Nat20_Force_Empty"
    },
    {
      "x": -8,
      "y": 8,
      "z": 10,
      "name": "Nat20_Force_Empty"
    },
    {
      "x": -8,
      "y": 9,
      "z": 10,
      "name": "Nat20_Force_Empty"
    },
    {
      "x": -8,
      "y": 10,
      "z": 10,
      "name": "Nat20_Force_Empty"
    },
    {
      "x": -8,
      "y": 11,
      "z": 10,
      "name": "Nat20_Force_Empty"
    },
    {
      "x": -8,
      "y": 12,
      "z": 10,
      "name": "Nat20_Force_Empty"
    },
    {
      "x": -8,
      "y": 13,
      "z": 10,
      "name": "Nat20_Force_Empty"
    },
    {
      "x": -8,
      "y": 14,
      "z": 10,
      "name": "Nat20_Force_Empty"
    },
    {
      "x": -8,
      "y": 15,
      "z": 10,
      "name": "Nat20_Force_Empty"
    },
    {
      "x": -8,
      "y": 16,
      "z": 10,
      "name": "Nat20_Force_Empty"
    },
    {
      "x": -8,
      "y": 3,
      "z": 11,
      "name": "Nat20_Force_Empty"
    },
    {
      "x": -8,
      "y": 4,
      "z": 11,
      "name": "Nat20_Force_Empty"
    },
    {
      "x": -8,
      "y": 5,
      "z": 11,
      "name": "Nat20_Force_Empty"
    },
    {
      "x": -8,
      "y": 6,
      "z": 11,
      "name": "Nat20_Force_Empty"
    },
    {
      "x": -8,
      "y": 7,
      "z": 11,
      "name": "Nat20_Force_Empty"
    },
    {
      "x": -8,
      "y": 8,
      "z": 11,
      "name": "Nat20_Force_Empty"
    },
    {
      "x": -8,
      "y": 9,
      "z": 11,
      "name": "Nat20_Force_Empty"
    },
    {
      "x": -8,
      "y": 10,
      "z": 11,
      "name": "Nat20_Force_Empty"
    },
    {
      "x": -8,
      "y": 11,
      "z": 11,
      "name": "Nat20_Force_Empty"
    },
    {
      "x": -8,
      "y": 12,
      "z": 11,
      "name": "Nat20_Force_Empty"
    },
    {
      "x": -8,
      "y": 13,
      "z": 11,
      "name": "Nat20_Force_Empty"
    },
    {
      "x": -8,
      "y": 14,
      "z": 11,
      "name": "Nat20_Force_Empty"
    },
    {
      "x": -8,
      "y": 15,
      "z": 11,
      "name": "Nat20_Force_Empty"
    },
    {
      "x": -8,
      "y": 16,
      "z": 11,
      "name": "Nat20_Force_Empty"
    },
    {
      "x": -8,
      "y": 3,
      "z": 12,
      "name": "Nat20_Force_Empty"
    },
    {
      "x": -8,
      "y": 4,
      "z": 12,
      "name": "Nat20_Force_Empty"
    },
    {
      "x": -8,
      "y": 5,
      "z": 12,
      "name": "Nat20_Force_Empty"
    },
    {
      "x": -8,
      "y": 6,
      "z": 12,
      "name": "Nat20_Force_Empty"
    },
    {
      "x": -8,
      "y": 7,
      "z": 12,
      "name": "Nat20_Force_Empty"
    },
    {
      "x": -8,
      "y": 8,
      "z": 12,
      "name": "Nat20_Force_Empty"
    },
    {
      "x": -8,
      "y": 9,
      "z": 12,
      "name": "Nat20_Force_Empty"
    },
    {
      "x": -8,
      "y": 10,
      "z": 12,
      "name": "Nat20_Force_Empty"
    },
    {
      "x": -8,
      "y": 11,
      "z": 12,
      "name": "Nat20_Force_Empty"
    },
    {
      "x": -8,
      "y": 12,
      "z": 12,
      "name": "Nat20_Force_Empty"
    },
    {
      "x": -8,
      "y": 13,
      "z": 12,
      "name": "Nat20_Force_Empty"
    },
    {
      "x": -8,
      "y": 14,
      "z": 12,
      "name": "Nat20_Force_Empty"
    },
    {
      "x": -8,
      "y": 15,
      "z": 12,
      "name": "Nat20_Force_Empty"
    },
    {
      "x": -8,
      "y": 16,
      "z": 12,
      "name": "Nat20_Force_Empty"
    },
    {
      "x": -7,
      "y": 2,
      "z": -11,
      "name": "Rock_Stone_Cobble"
    },
    {
      "x": -7,
      "y": 3,
      "z": -11,
      "name": "Nat20_Force_Empty"
    },
    {
      "x": -7,
      "y": 4,
      "z": -11,
      "name": "Nat20_Force_Empty"
    },
    {
      "x": -7,
      "y": 5,
      "z": -11,
      "name": "Nat20_Force_Empty"
    },
    {
      "x": -7,
      "y": 6,
      "z": -11,
      "name": "Nat20_Force_Empty"
    },
    {
      "x": -7,
      "y": 7,
      "z": -11,
      "name": "Nat20_Force_Empty"
    },
    {
      "x": -7,
      "y": 8,
      "z": -11,
      "name": "Nat20_Force_Empty"
    },
    {
      "x": -7,
      "y": 9,
      "z": -11,
      "name": "Nat20_Force_Empty"
    },
    {
      "x": -7,
      "y": 10,
      "z": -11,
      "name": "Nat20_Force_Empty"
    },
    {
      "x": -7,
      "y": 11,
      "z": -11,
      "name": "Nat20_Force_Empty"
    },
    {
      "x": -7,
      "y": 12,
      "z": -11,
      "name": "Nat20_Force_Empty"
    },
    {
      "x": -7,
      "y": 13,
      "z": -11,
      "name": "Nat20_Force_Empty"
    },
    {
      "x": -7,
      "y": 14,
      "z": -11,
      "name": "Nat20_Force_Empty"
    },
    {
      "x": -7,
      "y": 15,
      "z": -11,
      "name": "Nat20_Force_Empty"
    },
    {
      "x": -7,
      "y": 16,
      "z": -11,
      "name": "Nat20_Force_Empty"
    },
    {
      "x": -7,
      "y": 2,
      "z": -10,
      "name": "Rock_Stone_Cobble"
    },
    {
      "x": -7,
      "y": 3,
      "z": -10,
      "name": "Nat20_Force_Empty"
    },
