{
  "version": 8,
  "blockIdVersion": 11,
  "anchorX": 0,
  "anchorY": 0,
  "anchorZ": 0,
  "blocks": [
    {
      "x": -12,
      "y": 1,
      "z": -7,
      "name": "Nat20_Force_Empty"
    },
    {
      "x": -12,
      "y": 2,
      "z": -7,
      "name": "Nat20_Force_Empty"
    },
    {
      "x": -12,
      "y": 3,
      "z": -7,
      "name": "Nat20_Force_Empty"
    },
    {
      "x": -12,
      "y": 4,
      "z": -7,
      "name": "Nat20_Force_Empty"
    },
    {
      "x": -12,
      "y": 5,
      "z": -7,
      "name": "Nat20_Force_Empty"
    },
    {
      "x": -12,
      "y": 6,
      "z": -7,
      "name": "Nat20_Force_Empty"
    },
    {
      "x": -12,
      "y": 7,
      "z": -7,
      "name": "Nat20_Force_Empty"
    },
    {
      "x": -12,
      "y": 8,
      "z": -7,
      "name": "Nat20_Force_Empty"
    },
    {
      "x": -12,
      "y": 9,
      "z": -7,
      "name": "Nat20_Force_Empty"
    },
    {
      "x": -12,
      "y": 10,
      "z": -7,
      "name": "Nat20_Force_Empty"
    },
    {
      "x": -12,
      "y": 11,
      "z": -7,
      "name": "Nat20_Force_Empty"
    },
    {
      "x": -12,
      "y": 12,
      "z": -7,
      "name": "Nat20_Force_Empty"
    },
    {
      "x": -12,
      "y": 13,
      "z": -7,
      "name": "Nat20_Force_Empty"
    },
    {
      "x": -12,
      "y": 14,
      "z": -7,
      "name": "Nat20_Force_Empty"
    },
    {
      "x": -12,
      "y": 15,
      "z": -7,
      "name": "Nat20_Force_Empty"
    },
    {
      "x": -12,
      "y": 16,
      "z": -7,
      "name": "Nat20_Force_Empty"
    },
    {
      "x": -12,
      "y": 17,
      "z": -7,
      "name": "Nat20_Force_Empty"
    },
    {
      "x": -12,
      "y": 18,
      "z": -7,
      "name": "Nat20_Force_Empty"
    },
    {
      "x": -12,
      "y": 19,
      "z": -7,
      "name": "Nat20_Force_Empty"
    },
    {
      "x": -12,
      "y": 1,
      "z": -6,
      "name": "Nat20_Force_Empty"
    },
    {
      "x": -12,
      "y": 2,
      "z": -6,
      "name": "Nat20_Force_Empty"
    },
    {
      "x": -12,
      "y": 3,
      "z": -6,
      "name": "Nat20_Force_Empty"
    },
    {
      "x": -12,
      "y": 4,
      "z": -6,
      "name": "Nat20_Force_Empty"
    },
    {
      "x": -12,
      "y": 5,
      "z": -6,
      "name": "Nat20_Force_Empty"
    },
    {
      "x": -12,
      "y": 6,
      "z": -6,
      "name": "Nat20_Force_Empty"
    },
    {
      "x": -12,
      "y": 7,
      "z": -6,
      "name": "Nat20_Force_Empty"
    },
    {
      "x": -12,
      "y": 8,
      "z": -6,
      "name": "Nat20_Force_Empty"
    },
    {
      "x": -12,
      "y": 9,
      "z": -6,
      "name": "Nat20_Force_Empty"
    },
    {
      "x": -12,
      "y": 10,
      "z": -6,
      "name": "Nat20_Force_Empty"
    },
    {
      "x": -12,
      "y": 11,
      "z": -6,
      "name": "Nat20_Force_Empty"
    },
    {
      "x": -12,
      "y": 12,
      "z": -6,
      "name": "Nat20_Force_Empty"
    },
    {
      "x": -12,
      "y": 13,
      "z": -6,
      "name": "Nat20_Force_Empty"
    },
    {
      "x": -12,
      "y": 14,
      "z": -6,
      "name": "Nat20_Force_Empty"
    },
    {
      "x": -12,
      "y": 15,
      "z": -6,
      "name": "Nat20_Force_Empty"
    },
    {
      "x": -12,
      "y": 16,
      "z": -6,
      "name": "Nat20_Force_Empty"
    },
    {
      "x": -12,
      "y": 17,
      "z": -6,
      "name": "Nat20_Force_Empty"
    },
    {
      "x": -12,
      "y": 18,
      "z": -6,
      "name": "Nat20_Force_Empty"
    },
    {
      "x": -12,
      "y": 19,
      "z": -6,
      "name": "Nat20_Force_Empty"
    },
    {
      "x": -12,
      "y": 1,
      "z": -5,
      "name": "Nat20_Force_Empty"
    },
    {
      "x": -12,
      "y": 2,
      "z": -5,
      "name": "Nat20_Force_Empty"
    },
    {
      "x": -12,
      "y": 3,
      "z": -5,
      "name": "Nat20_Force_Empty"
    },
    {
      "x": -12,
      "y": 4,
      "z": -5,
      "name": "Nat20_Force_Empty"
    },
    {
      "x": -12,
      "y": 5,
      "z": -5,
      "name": "Nat20_Force_Empty"
    },
    {
      "x": -12,
      "y": 6,
      "z": -5,
      "name": "Nat20_Force_Empty"
    },
    {
      "x": -12,
      "y": 7,
      "z": -5,
      "name": "Nat20_Force_Empty"
    },
    {
      "x": -12,
      "y": 8,
      "z": -5,
      "name": "Nat20_Force_Empty"
    },
    {
      "x": -12,
      "y": 9,
      "z": -5,
      "name": "Nat20_Force_Empty"
    },
    {
      "x": -12,
      "y": 10,
      "z": -5,
      "name": "Nat20_Force_Empty"
    },
    {
      "x": -12,
      "y": 11,
      "z": -5,
      "name": "Nat20_Force_Empty"
    },
    {
      "x": -12,
      "y": 12,
      "z": -5,
      "name": "Nat20_Force_Empty"
    },
    {
      "x": -12,
      "y": 13,
      "z": -5,
      "name": "Nat20_Force_Empty"
    },
    {
      "x": -12,
      "y": 14,
      "z": -5,
      "name": "Nat20_Force_Empty"
    },
    {
      "x": -12,
      "y": 15,
      "z": -5,
      "name": "Nat20_Force_Empty"
    },
    {
      "x": -12,
      "y": 16,
      "z": -5,
      "name": "Nat20_Force_Empty"
    },
    {
      "x": -12,
      "y": 17,
      "z": -5,
      "name": "Nat20_Force_Empty"
    },
    {
      "x": -12,
      "y": 18,
      "z": -5,
      "name": "Nat20_Force_Empty"
    },
    {
      "x": -12,
      "y": 19,
      "z": -5,
      "name": "Nat20_Force_Empty"
    },
    {
      "x": -12,
      "y": 1,
      "z": -4,
      "name": "Nat20_Force_Empty"
    },
    {
      "x": -12,
      "y": 2,
      "z": -4,
      "name": "Nat20_Force_Empty"
    },
    {
      "x": -12,
      "y": 3,
      "z": -4,
      "name": "Nat20_Force_Empty"
    },
    {
      "x": -12,
      "y": 4,
      "z": -4,
      "name": "Nat20_Force_Empty"
    },
    {
      "x": -12,
      "y": 5,
      "z": -4,
      "name": "Nat20_Force_Empty"
    },
    {
      "x": -12,
      "y": 6,
      "z": -4,
      "name": "Nat20_Force_Empty"
    },
    {
      "x": -12,
      "y": 7,
      "z": -4,
      "name": "Nat20_Force_Empty"
    },
    {
      "x": -12,
      "y": 8,
      "z": -4,
      "name": "Nat20_Force_Empty"
    },
    {
      "x": -12,
      "y": 9,
      "z": -4,
      "name": "Nat20_Force_Empty"
    },
    {
      "x": -12,
      "y": 10,
      "z": -4,
      "name": "Nat20_Force_Empty"
    },
    {
      "x": -12,
      "y": 11,
      "z": -4,
      "name": "Nat20_Force_Empty"
    },
    {
      "x": -12,
      "y": 12,
      "z": -4,
      "name": "Nat20_Force_Empty"
    },
    {
      "x": -12,
      "y": 13,
      "z": -4,
      "name": "Nat20_Force_Empty"
    },
    {
      "x": -12,
      "y": 14,
      "z": -4,
      "name": "Nat20_Force_Empty"
    },
    {
      "x": -12,
      "y": 15,
      "z": -4,
      "name": "Nat20_Force_Empty"
    },
    {
      "x": -12,
      "y": 16,
      "z": -4,
      "name": "Nat20_Force_Empty"
    },
    {
      "x": -12,
      "y": 17,
      "z": -4,
      "name": "Nat20_Force_Empty"
    },
    {
      "x": -12,
      "y": 18,
      "z": -4,
      "name": "Nat20_Force_Empty"
    },
    {
      "x": -12,
      "y": 19,
      "z": -4,
      "name": "Nat20_Force_Empty"
    },
    {
      "x": -12,
      "y": 0,
      "z": -3,
      "name": "Wood_Beech_Trunk"
    },
    {
      "x": -12,
      "y": 1,
      "z": -3,
      "name": "Wood_Beech_Trunk"
    },
    {
      "x": -12,
      "y": 2,
      "z": -3,
      "name": "Wood_Beech_Trunk"
    },
    {
      "x": -12,
      "y": 3,
      "z": -3,
      "name": "Wood_Beech_Trunk"
    },
    {
      "x": -12,
      "y": 4,
      "z": -3,
      "name": "Wood_Deadwood_Roof",
      "rotation": 3
    },
    {
      "x": -12,
      "y": 5,
      "z": -3,
      "name": "Nat20_Force_Empty"
    },
    {
      "x": -12,
      "y": 6,
      "z": -3,
      "name": "Nat20_Force_Empty"
    },
    {
      "x": -12,
      "y": 7,
      "z": -3,
      "name": "Nat20_Force_Empty"
    },
    {
      "x": -12,
      "y": 8,
      "z": -3,
      "name": "Nat20_Force_Empty"
    },
    {
      "x": -12,
      "y": 9,
      "z": -3,
      "name": "Nat20_Force_Empty"
    },
    {
      "x": -12,
      "y": 10,
      "z": -3,
      "name": "Nat20_Force_Empty"
    },
    {
      "x": -12,
      "y": 11,
      "z": -3,
      "name": "Nat20_Force_Empty"
    },
    {
      "x": -12,
      "y": 12,
      "z": -3,
      "name": "Nat20_Force_Empty"
    },
    {
      "x": -12,
      "y": 13,
      "z": -3,
      "name": "Nat20_Force_Empty"
    },
    {
      "x": -12,
      "y": 14,
      "z": -3,
      "name": "Nat20_Force_Empty"
    },
    {
      "x": -12,
      "y": 15,
      "z": -3,
      "name": "Nat20_Force_Empty"
    },
    {
      "x": -12,
      "y": 16,
      "z": -3,
      "name": "Nat20_Force_Empty"
    },
    {
      "x": -12,
      "y": 17,
      "z": -3,
      "name": "Nat20_Force_Empty"
    },
    {
      "x": -12,
      "y": 18,
      "z": -3,
      "name": "Nat20_Force_Empty"
    },
    {
      "x": -12,
      "y": 19,
      "z": -3,
      "name": "Nat20_Force_Empty"
    },
    {
      "x": -12,
      "y": 0,
      "z": -2,
      "name": "Wood_Beech_Trunk",
      "support": 1,
      "rotation": 4
    },
    {
      "x": -12,
      "y": 1,
      "z": -2,
      "name": "Wood_Softwood_Decorative"
    },
    {
      "x": -12,
      "y": 2,
      "z": -2,
      "name": "Wood_Softwood_Decorative"
    },
    {
      "x": -12,
      "y": 3,
      "z": -2,
      "name": "Wood_Softwood_Decorative"
    },
    {
      "x": -12,
      "y": 4,
      "z": -2,
      "name": "Wood_Deadwood_Roof",
      "rotation": 3
    },
    {
      "x": -12,
      "y": 5,
      "z": -2,
      "name": "Nat20_Force_Empty"
    },
    {
      "x": -12,
      "y": 6,
      "z": -2,
      "name": "Nat20_Force_Empty"
    },
    {
      "x": -12,
      "y": 7,
      "z": -2,
      "name": "Nat20_Force_Empty"
    },
    {
      "x": -12,
      "y": 8,
      "z": -2,
      "name": "Nat20_Force_Empty"
    },
    {
      "x": -12,
      "y": 9,
      "z": -2,
      "name": "Nat20_Force_Empty"
    },
    {
      "x": -12,
      "y": 10,
      "z": -2,
      "name": "Nat20_Force_Empty"
    },
    {
      "x": -12,
      "y": 11,
      "z": -2,
      "name": "Nat20_Force_Empty"
    },
    {
      "x": -12,
      "y": 12,
      "z": -2,
      "name": "Nat20_Force_Empty"
    },
    {
      "x": -12,
      "y": 13,
      "z": -2,
      "name": "Nat20_Force_Empty"
    },
    {
      "x": -12,
      "y": 14,
      "z": -2,
      "name": "Nat20_Force_Empty"
    },
    {
      "x": -12,
      "y": 15,
      "z": -2,
      "name": "Nat20_Force_Empty"
    },
    {
      "x": -12,
      "y": 16,
      "z": -2,
      "name": "Nat20_Force_Empty"
    },
    {
      "x": -12,
      "y": 17,
      "z": -2,
      "name": "Nat20_Force_Empty"
    },
    {
      "x": -12,
      "y": 18,
      "z": -2,
      "name": "Nat20_Force_Empty"
    },
    {
      "x": -12,
      "y": 19,
      "z": -2,
      "name": "Nat20_Force_Empty"
    },
    {
      "x": -12,
      "y": 0,
      "z": -1,
      "name": "Wood_Beech_Trunk",
      "support": 2,
      "rotation": 4
    },
    {
      "x": -12,
      "y": 1,
      "z": -1,
      "name": "Wood_Softwood_Planks"
    },
    {
      "x": -12,
      "y": 2,
      "z": -1,
      "name": "Furniture_Crude_Window"
    },
    {
      "x": -12,
      "y": 3,
      "z": -1,
      "name": "Wood_Softwood_Planks"
    },
    {
      "x": -12,
      "y": 4,
      "z": -1,
      "name": "Wood_Deadwood_Roof",
      "rotation": 3
    },
    {
      "x": -12,
      "y": 5,
      "z": -1,
      "name": "Nat20_Force_Empty"
    },
    {
      "x": -12,
      "y": 6,
      "z": -1,
      "name": "Nat20_Force_Empty"
    },
    {
      "x": -12,
      "y": 7,
      "z": -1,
      "name": "Nat20_Force_Empty"
    },
    {
      "x": -12,
      "y": 8,
      "z": -1,
      "name": "Nat20_Force_Empty"
    },
    {
      "x": -12,
      "y": 9,
      "z": -1,
      "name": "Nat20_Force_Empty"
    },
    {
      "x": -12,
      "y": 10,
      "z": -1,
      "name": "Nat20_Force_Empty"
    },
    {
      "x": -12,
      "y": 11,
      "z": -1,
      "name": "Nat20_Force_Empty"
    },
    {
      "x": -12,
      "y": 12,
      "z": -1,
      "name": "Nat20_Force_Empty"
    },
    {
      "x": -12,
      "y": 13,
      "z": -1,
      "name": "Nat20_Force_Empty"
    },
    {
      "x": -12,
      "y": 14,
      "z": -1,
      "name": "Nat20_Force_Empty"
    },
    {
      "x": -12,
      "y": 15,
      "z": -1,
      "name": "Nat20_Force_Empty"
    },
    {
      "x": -12,
      "y": 16,
      "z": -1,
      "name": "Nat20_Force_Empty"
    },
    {
      "x": -12,
      "y": 17,
      "z": -1,
      "name": "Nat20_Force_Empty"
    },
    {
      "x": -12,
      "y": 18,
      "z": -1,
      "name": "Nat20_Force_Empty"
    },
    {
      "x": -12,
      "y": 19,
      "z": -1,
      "name": "Nat20_Force_Empty"
    },
    {
      "x": -12,
      "y": 0,
      "z": 0,
      "name": "Wood_Beech_Trunk",
      "support": 3,
      "rotation": 4
    },
    {
      "x": -12,
      "y": 1,
      "z": 0,
      "name": "Wood_Softwood_Planks"
    },
    {
      "x": -12,
      "y": 2,
      "z": 0,
      "name": "Furniture_Crude_Window"
    },
    {
      "x": -12,
      "y": 3,
      "z": 0,
      "name": "Wood_Softwood_Planks"
    },
    {
      "x": -12,
      "y": 4,
      "z": 0,
      "name": "Wood_Deadwood_Roof",
      "rotation": 3
    },
    {
      "x": -12,
      "y": 5,
      "z": 0,
      "name": "Nat20_Force_Empty"
    },
    {
      "x": -12,
      "y": 6,
      "z": 0,
      "name": "Nat20_Force_Empty"
    },
    {
      "x": -12,
      "y": 7,
      "z": 0,
      "name": "Nat20_Force_Empty"
    },
    {
      "x": -12,
      "y": 8,
      "z": 0,
      "name": "Nat20_Force_Empty"
    },
    {
      "x": -12,
      "y": 9,
      "z": 0,
      "name": "Nat20_Force_Empty"
    },
    {
      "x": -12,
      "y": 10,
      "z": 0,
      "name": "Nat20_Force_Empty"
    },
    {
      "x": -12,
      "y": 11,
      "z": 0,
      "name": "Nat20_Force_Empty"
    },
    {
      "x": -12,
      "y": 12,
      "z": 0,
      "name": "Nat20_Force_Empty"
    },
    {
      "x": -12,
      "y": 13,
      "z": 0,
      "name": "Nat20_Force_Empty"
    },
    {
      "x": -12,
      "y": 14,
      "z": 0,
      "name": "Nat20_Force_Empty"
    },
    {
      "x": -12,
      "y": 15,
      "z": 0,
      "name": "Nat20_Force_Empty"
    },
    {
      "x": -12,
      "y": 16,
      "z": 0,
      "name": "Nat20_Force_Empty"
    },
    {
      "x": -12,
      "y": 17,
      "z": 0,
      "name": "Nat20_Force_Empty"
    },
    {
      "x": -12,
      "y": 18,
      "z": 0,
      "name": "Nat20_Force_Empty"
    },
    {
      "x": -12,
      "y": 19,
      "z": 0,
      "name": "Nat20_Force_Empty"
    },
    {
      "x": -12,
      "y": 0,
      "z": 1,
      "name": "Wood_Beech_Trunk",
      "support": 4,
      "rotation": 4
    },
    {
      "x": -12,
      "y": 1,
      "z": 1,
      "name": "Wood_Softwood_Planks"
    },
    {
      "x": -12,
      "y": 2,
      "z": 1,
      "name": "Wood_Softwood_Planks"
    },
    {
      "x": -12,
      "y": 3,
      "z": 1,
      "name": "Wood_Softwood_Planks"
    },
    {
      "x": -12,
      "y": 4,
      "z": 1,
      "name": "Wood_Deadwood_Roof",
      "rotation": 3
    },
    {
      "x": -12,
      "y": 5,
      "z": 1,
      "name": "Nat20_Force_Empty"
    },
    {
      "x": -12,
      "y": 6,
      "z": 1,
      "name": "Nat20_Force_Empty"
    },
    {
      "x": -12,
      "y": 7,
      "z": 1,
      "name": "Nat20_Force_Empty"
    },
    {
      "x": -12,
      "y": 8,
      "z": 1,
      "name": "Nat20_Force_Empty"
    },
    {
      "x": -12,
      "y": 9,
      "z": 1,
      "name": "Nat20_Force_Empty"
    },
    {
      "x": -12,
      "y": 10,
      "z": 1,
      "name": "Nat20_Force_Empty"
    },
    {
      "x": -12,
      "y": 11,
      "z": 1,
      "name": "Nat20_Force_Empty"
    },
    {
      "x": -12,
      "y": 12,
      "z": 1,
      "name": "Nat20_Force_Empty"
    },
    {
      "x": -12,
      "y": 13,
      "z": 1,
      "name": "Nat20_Force_Empty"
    },
    {
      "x": -12,
      "y": 14,
      "z": 1,
      "name": "Nat20_Force_Empty"
    },
    {
      "x": -12,
      "y": 15,
      "z": 1,
      "name": "Nat20_Force_Empty"
    },
    {
      "x": -12,
      "y": 16,
      "z": 1,
      "name": "Nat20_Force_Empty"
    },
    {
      "x": -12,
      "y": 17,
      "z": 1,
      "name": "Nat20_Force_Empty"
    },
    {
      "x": -12,
      "y": 18,
      "z": 1,
      "name": "Nat20_Force_Empty"
    },
    {
      "x": -12,
      "y": 19,
      "z": 1,
      "name": "Nat20_Force_Empty"
    },
    {
      "x": -12,
      "y": 0,
      "z": 2,
      "name": "Wood_Beech_Trunk",
      "support": 5,
      "rotation": 4
    },
    {
      "x": -12,
      "y": 1,
      "z": 2,
      "name": "Wood_Softwood_Planks"
    },
    {
      "x": -12,
      "y": 2,
      "z": 2,
      "name": "Wood_Softwood_Planks"
    },
    {
      "x": -12,
      "y": 3,
      "z": 2,
      "name": "Wood_Softwood_Planks"
    },
    {
      "x": -12,
      "y": 4,
      "z": 2,
      "name": "Wood_Deadwood_Roof",
      "rotation": 3
    },
    {
      "x": -12,
      "y": 5,
      "z": 2,
      "name": "Nat20_Force_Empty"
    },
    {
      "x": -12,
      "y": 6,
      "z": 2,
      "name": "Nat20_Force_Empty"
    },
    {
      "x": -12,
      "y": 7,
      "z": 2,
      "name": "Nat20_Force_Empty"
    },
    {
      "x": -12,
      "y": 8,
      "z": 2,
      "name": "Nat20_Force_Empty"
    },
    {
      "x": -12,
      "y": 9,
      "z": 2,
      "name": "Nat20_Force_Empty"
    },
    {
      "x": -12,
      "y": 10,
      "z": 2,
      "name": "Nat20_Force_Empty"
    },
    {
      "x": -12,
      "y": 11,
      "z": 2,
      "name": "Nat20_Force_Empty"
    },
    {
      "x": -12,
      "y": 12,
      "z": 2,
      "name": "Nat20_Force_Empty"
    },
    {
      "x": -12,
      "y": 13,
      "z": 2,
      "name": "Nat20_Force_Empty"
    },
    {
      "x": -12,
      "y": 14,
      "z": 2,
      "name": "Nat20_Force_Empty"
    },
    {
      "x": -12,
      "y": 15,
      "z": 2,
      "name": "Nat20_Force_Empty"
    },
    {
      "x": -12,
      "y": 16,
      "z": 2,
      "name": "Nat20_Force_Empty"
    },
    {
      "x": -12,
      "y": 17,
      "z": 2,
      "name": "Nat20_Force_Empty"
    },
    {
      "x": -12,
      "y": 18,
      "z": 2,
      "name": "Nat20_Force_Empty"
    },
    {
      "x": -12,
      "y": 19,
      "z": 2,
      "name": "Nat20_Force_Empty"
    },
    {
      "x": -12,
      "y": 0,
      "z": 3,
      "name": "Wood_Beech_Trunk",
      "support": 5,
      "rotation": 4
    },
    {
      "x": -12,
      "y": 1,
      "z": 3,
      "name": "Wood_Softwood_Planks"
    },
    {
      "x": -12,
      "y": 2,
      "z": 3,
      "name": "Wood_Softwood_Fence",
      "rotation": 3
    },
    {
      "x": -12,
      "y": 3,
      "z": 3,
      "name": "Wood_Softwood_Planks"
    },
    {
      "x": -12,
      "y": 4,
      "z": 3,
      "name": "Wood_Deadwood_Roof",
      "rotation": 3
    },
    {
      "x": -12,
      "y": 5,
      "z": 3,
      "name": "Nat20_Force_Empty"
    },
    {
      "x": -12,
      "y": 6,
      "z": 3,
      "name": "Nat20_Force_Empty"
    },
    {
      "x": -12,
      "y": 7,
      "z": 3,
      "name": "Nat20_Force_Empty"
    },
    {
      "x": -12,
      "y": 8,
      "z": 3,
      "name": "Nat20_Force_Empty"
    },
    {
      "x": -12,
      "y": 9,
      "z": 3,
      "name": "Nat20_Force_Empty"
    },
    {
      "x": -12,
      "y": 10,
      "z": 3,
      "name": "Nat20_Force_Empty"
    },
    {
      "x": -12,
      "y": 11,
      "z": 3,
      "name": "Nat20_Force_Empty"
    },
    {
      "x": -12,
      "y": 12,
      "z": 3,
      "name": "Nat20_Force_Empty"
    },
    {
      "x": -12,
      "y": 13,
      "z": 3,
      "name": "Nat20_Force_Empty"
    },
    {
      "x": -12,
      "y": 14,
      "z": 3,
      "name": "Nat20_Force_Empty"
    },
    {
      "x": -12,
      "y": 15,
      "z": 3,
      "name": "Nat20_Force_Empty"
    },
    {
      "x": -12,
      "y": 16,
      "z": 3,
      "name": "Nat20_Force_Empty"
    },
    {
      "x": -12,
      "y": 17,
      "z": 3,
      "name": "Nat20_Force_Empty"
    },
    {
      "x": -12,
      "y": 18,
      "z": 3,
      "name": "Nat20_Force_Empty"
    },
    {
      "x": -12,
      "y": 19,
      "z": 3,
      "name": "Nat20_Force_Empty"
    },
    {
      "x": -12,
      "y": 0,
      "z": 4,
      "name": "Wood_Beech_Trunk",
      "support": 4,
      "rotation": 4
    },
    {
      "x": -12,
      "y": 1,
      "z": 4,
      "name": "Wood_Softwood_Planks"
    },
    {
      "x": -12,
      "y": 2,
      "z": 4,
      "name": "Wood_Softwood_Planks"
    },
    {
      "x": -12,
      "y": 3,
      "z": 4,
      "name": "Wood_Softwood_Planks"
    },
    {
      "x": -12,
      "y": 4,
      "z": 4,
      "name": "Wood_Deadwood_Roof",
      "rotation": 3
    },
    {
      "x": -12,
      "y": 5,
      "z": 4,
      "name": "Nat20_Force_Empty"
    },
    {
      "x": -12,
      "y": 6,
      "z": 4,
      "name": "Nat20_Force_Empty"
    },
    {
      "x": -12,
      "y": 7,
      "z": 4,
      "name": "Nat20_Force_Empty"
    },
    {
      "x": -12,
      "y": 8,
      "z": 4,
      "name": "Nat20_Force_Empty"
    },
    {
      "x": -12,
      "y": 9,
      "z": 4,
      "name": "Nat20_Force_Empty"
    },
    {
      "x": -12,
      "y": 10,
      "z": 4,
      "name": "Nat20_Force_Empty"
    },
    {
      "x": -12,
      "y": 11,
      "z": 4,
      "name": "Nat20_Force_Empty"
    },
    {
      "x": -12,
      "y": 12,
      "z": 4,
      "name": "Nat20_Force_Empty"
    },
    {
      "x": -12,
      "y": 13,
      "z": 4,
      "name": "Nat20_Force_Empty"
    },
    {
      "x": -12,
      "y": 14,
      "z": 4,
      "name": "Nat20_Force_Empty"
    },
    {
      "x": -12,
      "y": 15,
      "z": 4,
      "name": "Nat20_Force_Empty"
    },
    {
      "x": -12,
      "y": 16,
      "z": 4,
      "name": "Nat20_Force_Empty"
    },
    {
      "x": -12,
      "y": 17,
      "z": 4,
      "name": "Nat20_Force_Empty"
    },
    {
      "x": -12,
      "y": 18,
      "z": 4,
      "name": "Nat20_Force_Empty"
    },
    {
      "x": -12,
      "y": 19,
      "z": 4,
      "name": "Nat20_Force_Empty"
    },
    {
      "x": -12,
      "y": 0,
      "z": 5,
      "name": "Wood_Beech_Trunk",
      "support": 3,
      "rotation": 4
    },
    {
      "x": -12,
      "y": 1,
      "z": 5,
      "name": "Nat20_Direction"
    },
    {
      "x": -12,
      "y": 2,
      "z": 5,
      "name": "Nat20_Force_Empty"
    },
    {
      "x": -12,
      "y": 3,
      "z": 5,
      "name": "Wood_Softwood_Planks"
    },
    {
      "x": -12,
      "y": 4,
      "z": 5,
      "name": "Wood_Deadwood_Roof",
      "rotation": 3
    },
    {
      "x": -12,
      "y": 5,
      "z": 5,
      "name": "Nat20_Force_Empty"
    },
    {
      "x": -12,
      "y": 6,
      "z": 5,
      "name": "Nat20_Force_Empty"
    },
    {
      "x": -12,
      "y": 7,
      "z": 5,
      "name": "Nat20_Force_Empty"
    },
    {
      "x": -12,
      "y": 8,
      "z": 5,
      "name": "Nat20_Force_Empty"
    },
    {
      "x": -12,
      "y": 9,
      "z": 5,
      "name": "Nat20_Force_Empty"
    },
    {
      "x": -12,
      "y": 10,
      "z": 5,
      "name": "Nat20_Force_Empty"
    },
    {
      "x": -12,
      "y": 11,
      "z": 5,
      "name": "Nat20_Force_Empty"
    },
    {
      "x": -12,
      "y": 12,
      "z": 5,
      "name": "Nat20_Force_Empty"
    },
    {
      "x": -12,
      "y": 13,
      "z": 5,
      "name": "Nat20_Force_Empty"
    },
    {
      "x": -12,
      "y": 14,
      "z": 5,
      "name": "Nat20_Force_Empty"
    },
    {
      "x": -12,
      "y": 15,
      "z": 5,
      "name": "Nat20_Force_Empty"
    },
    {
      "x": -12,
      "y": 16,
      "z": 5,
      "name": "Nat20_Force_Empty"
    },
    {
      "x": -12,
      "y": 17,
      "z": 5,
      "name": "Nat20_Force_Empty"
    },
    {
      "x": -12,
      "y": 18,
      "z": 5,
      "name": "Nat20_Force_Empty"
    },
    {
      "x": -12,
      "y": 19,
      "z": 5,
      "name": "Nat20_Force_Empty"
    },
    {
      "x": -12,
      "y": 0,
      "z": 6,
      "name": "Wood_Beech_Trunk",
      "support": 2,
      "rotation": 4
    },
    {
      "x": -12,
      "y": 1,
      "z": 6,
      "name": "Wood_Softwood_Planks"
    },
    {
      "x": -12,
      "y": 2,
      "z": 6,
      "name": "Wood_Softwood_Planks"
    },
    {
      "x": -12,
      "y": 3,
      "z": 6,
      "name": "Wood_Softwood_Planks"
    },
    {
      "x": -12,
      "y": 4,
      "z": 6,
      "name": "Wood_Deadwood_Roof",
      "rotation": 3
    },
    {
      "x": -12,
      "y": 5,
      "z": 6,
      "name": "Nat20_Force_Empty"
    },
    {
      "x": -12,
      "y": 6,
      "z": 6,
      "name": "Nat20_Force_Empty"
    },
    {
      "x": -12,
      "y": 7,
      "z": 6,
      "name": "Nat20_Force_Empty"
    },
    {
      "x": -12,
      "y": 8,
      "z": 6,
      "name": "Nat20_Force_Empty"
    },
    {
      "x": -12,
      "y": 9,
      "z": 6,
      "name": "Nat20_Force_Empty"
    },
    {
      "x": -12,
      "y": 10,
      "z": 6,
      "name": "Nat20_Force_Empty"
    },
    {
      "x": -12,
      "y": 11,
      "z": 6,
      "name": "Nat20_Force_Empty"
    },
    {
      "x": -12,
      "y": 12,
      "z": 6,
      "name": "Nat20_Force_Empty"
    },
    {
      "x": -12,
      "y": 13,
      "z": 6,
      "name": "Nat20_Force_Empty"
    },
    {
      "x": -12,
      "y": 14,
      "z": 6,
      "name": "Nat20_Force_Empty"
    },
    {
      "x": -12,
      "y": 15,
      "z": 6,
      "name": "Nat20_Force_Empty"
    },
    {
      "x": -12,
      "y": 16,
      "z": 6,
      "name": "Nat20_Force_Empty"
    },
    {
      "x": -12,
      "y": 17,
      "z": 6,
      "name": "Nat20_Force_Empty"
    },
    {
      "x": -12,
      "y": 18,
      "z": 6,
      "name": "Nat20_Force_Empty"
    },
    {
      "x": -12,
      "y": 19,
      "z": 6,
      "name": "Nat20_Force_Empty"
    },
    {
      "x": -12,
      "y": 0,
      "z": 7,
      "name": "Wood_Beech_Trunk",
      "support": 1,
      "rotation": 4
    },
    {
      "x": -12,
      "y": 1,
      "z": 7,
      "name": "Wood_Softwood_Decorative"
    },
    {
      "x": -12,
      "y": 2,
      "z": 7,
      "name": "Wood_Softwood_Decorative"
    },
    {
      "x": -12,
      "y": 3,
      "z": 7,
      "name": "Wood_Softwood_Decorative"
    },
    {
      "x": -12,
      "y": 4,
      "z": 7,
      "name": "Wood_Deadwood_Roof",
      "rotation": 3
    },
    {
      "x": -12,
      "y": 5,
      "z": 7,
      "name": "Nat20_Force_Empty"
    },
    {
      "x": -12,
      "y": 6,
      "z": 7,
      "name": "Nat20_Force_Empty"
    },
    {
      "x": -12,
      "y": 7,
      "z": 7,
      "name": "Nat20_Force_Empty"
    },
    {
      "x": -12,
      "y": 8,
      "z": 7,
      "name": "Nat20_Force_Empty"
    },
    {
      "x": -12,
      "y": 9,
      "z": 7,
      "name": "Nat20_Force_Empty"
    },
    {
      "x": -12,
      "y": 10,
      "z": 7,
      "name": "Nat20_Force_Empty"
    },
    {
      "x": -12,
      "y": 11,
      "z": 7,
      "name": "Nat20_Force_Empty"
    },
    {
      "x": -12,
      "y": 12,
      "z": 7,
      "name": "Nat20_Force_Empty"
    },
    {
      "x": -12,
      "y": 13,
      "z": 7,
      "name": "Nat20_Force_Empty"
    },
    {
      "x": -12,
      "y": 14,
      "z": 7,
      "name": "Nat20_Force_Empty"
    },
    {
      "x": -12,
      "y": 15,
      "z": 7,
      "name": "Nat20_Force_Empty"
    },
    {
      "x": -12,
      "y": 16,
      "z": 7,
      "name": "Nat20_Force_Empty"
    },
    {
      "x": -12,
      "y": 17,
      "z": 7,
      "name": "Nat20_Force_Empty"
    },
    {
      "x": -12,
      "y": 18,
      "z": 7,
      "name": "Nat20_Force_Empty"
    },
    {
      "x": -12,
      "y": 19,
      "z": 7,
      "name": "Nat20_Force_Empty"
    },
    {
      "x": -12,
      "y": 0,
      "z": 8,
      "name": "Wood_Beech_Trunk"
    },
    {
      "x": -12,
      "y": 1,
      "z": 8,
      "name": "Wood_Beech_Trunk"
    },
    {
      "x": -12,
      "y": 2,
      "z": 8,
      "name": "Wood_Beech_Trunk"
    },
    {
      "x": -12,
      "y": 3,
      "z": 8,
      "name": "Wood_Beech_Trunk"
    },
    {
      "x": -12,
      "y": 4,
      "z": 8,
      "name": "Wood_Deadwood_Roof",
      "rotation": 3
    },
    {
      "x": -12,
      "y": 5,
      "z": 8,
      "name": "Nat20_Force_Empty"
    },
    {
      "x": -12,
      "y": 6,
      "z": 8,
      "name": "Nat20_Force_Empty"
    },
    {
      "x": -12,
      "y": 7,
      "z": 8,
      "name": "Nat20_Force_Empty"
    },
    {
      "x": -12,
      "y": 8,
      "z": 8,
      "name": "Nat20_Force_Empty"
    },
    {
      "x": -12,
      "y": 9,
      "z": 8,
      "name": "Nat20_Force_Empty"
    },
    {
      "x": -12,
      "y": 10,
      "z": 8,
      "name": "Nat20_Force_Empty"
    },
    {
      "x": -12,
      "y": 11,
      "z": 8,
      "name": "Nat20_Force_Empty"
    },
    {
      "x": -12,
      "y": 12,
      "z": 8,
      "name": "Nat20_Force_Empty"
    },
    {
      "x": -12,
      "y": 13,
      "z": 8,
      "name": "Nat20_Force_Empty"
    },
    {
      "x": -12,
      "y": 14,
      "z": 8,
      "name": "Nat20_Force_Empty"
    },
    {
      "x": -12,
      "y": 15,
      "z": 8,
      "name": "Nat20_Force_Empty"
    },
    {
      "x": -12,
      "y": 16,
      "z": 8,
      "name": "Nat20_Force_Empty"
    },
    {
      "x": -12,
      "y": 17,
      "z": 8,
      "name": "Nat20_Force_Empty"
    },
    {
      "x": -12,
      "y": 18,
      "z": 8,
      "name": "Nat20_Force_Empty"
    },
    {
      "x": -12,
      "y": 19,
      "z": 8,
      "name": "Nat20_Force_Empty"
    },
    {
      "x": -11,
      "y": 1,
      "z": -7,
      "name": "Nat20_Force_Empty"
    },
    {
      "x": -11,
      "y": 2,
      "z": -7,
      "name": "Nat20_Force_Empty"
    },
    {
      "x": -11,
      "y": 3,
      "z": -7,
      "name": "Nat20_Force_Empty"
    },
    {
      "x": -11,
      "y": 4,
      "z": -7,
      "name": "Nat20_Force_Empty"
    },
    {
      "x": -11,
      "y": 5,
      "z": -7,
      "name": "Nat20_Force_Empty"
    },
    {
      "x": -11,
      "y": 6,
      "z": -7,
      "name": "Nat20_Force_Empty"
    },
    {
      "x": -11,
      "y": 7,
      "z": -7,
      "name": "Nat20_Force_Empty"
    },
    {
      "x": -11,
      "y": 8,
      "z": -7,
      "name": "Nat20_Force_Empty"
    },
    {
      "x": -11,
      "y": 9,
      "z": -7,
      "name": "Nat20_Force_Empty"
    },
    {
      "x": -11,
      "y": 10,
      "z": -7,
      "name": "Nat20_Force_Empty"
    },
    {
      "x": -11,
      "y": 11,
      "z": -7,
      "name": "Nat20_Force_Empty"
    },
    {
      "x": -11,
      "y": 12,
      "z": -7,
      "name": "Nat20_Force_Empty"
    },
    {
      "x": -11,
      "y": 13,
      "z": -7,
      "name": "Nat20_Force_Empty"
    },
    {
      "x": -11,
      "y": 14,
      "z": -7,
      "name": "Nat20_Force_Empty"
    },
    {
      "x": -11,
      "y": 15,
      "z": -7,
      "name": "Nat20_Force_Empty"
    },
    {
      "x": -11,
      "y": 16,
      "z": -7,
      "name": "Nat20_Force_Empty"
    },
    {
      "x": -11,
      "y": 17,
      "z": -7,
      "name": "Nat20_Force_Empty"
    },
    {
      "x": -11,
      "y": 18,
      "z": -7,
      "name": "Nat20_Force_Empty"
    },
    {
      "x": -11,
      "y": 19,
      "z": -7,
      "name": "Nat20_Force_Empty"
    },
    {
      "x": -11,
      "y": 1,
      "z": -6,
      "name": "Nat20_Force_Empty"
    },
    {
      "x": -11,
      "y": 2,
      "z": -6,
      "name": "Nat20_Force_Empty"
    },
    {
      "x": -11,
      "y": 3,
      "z": -6,
      "name": "Nat20_Force_Empty"
    },
    {
      "x": -11,
      "y": 4,
      "z": -6,
      "name": "Nat20_Force_Empty"
    },
    {
      "x": -11,
      "y": 5,
      "z": -6,
      "name": "Nat20_Force_Empty"
    },
    {
      "x": -11,
      "y": 6,
      "z": -6,
      "name": "Nat20_Force_Empty"
    },
    {
      "x": -11,
      "y": 7,
      "z": -6,
      "name": "Nat20_Force_Empty"
    },
    {
      "x": -11,
      "y": 8,
      "z": -6,
      "name": "Nat20_Force_Empty"
    },
    {
      "x": -11,
      "y": 9,
      "z": -6,
      "name": "Nat20_Force_Empty"
    },
    {
      "x": -11,
      "y": 10,
      "z": -6,
      "name": "Nat20_Force_Empty"
    },
    {
      "x": -11,
      "y": 11,
      "z": -6,
      "name": "Nat20_Force_Empty"
    },
    {
      "x": -11,
      "y": 12,
      "z": -6,
      "name": "Nat20_Force_Empty"
    },
    {
      "x": -11,
      "y": 13,
      "z": -6,
      "name": "Nat20_Force_Empty"
    },
    {
      "x": -11,
      "y": 14,
      "z": -6,
      "name": "Nat20_Force_Empty"
    },
    {
      "x": -11,
      "y": 15,
      "z": -6,
      "name": "Nat20_Force_Empty"
    },
    {
      "x": -11,
      "y": 16,
      "z": -6,
      "name": "Nat20_Force_Empty"
    },
    {
      "x": -11,
      "y": 17,
      "z": -6,
      "name": "Nat20_Force_Empty"
    },
    {
      "x": -11,
      "y": 18,
      "z": -6,
      "name": "Nat20_Force_Empty"
    },
    {
      "x": -11,
      "y": 19,
      "z": -6,
      "name": "Nat20_Force_Empty"
    },
    {
      "x": -11,
      "y": 1,
      "z": -5,
      "name": "Nat20_Force_Empty"
    },
    {
      "x": -11,
      "y": 2,
      "z": -5,
      "name": "Nat20_Force_Empty"
    },
    {
      "x": -11,
      "y": 3,
      "z": -5,
      "name": "Nat20_Force_Empty"
    },
    {
      "x": -11,
      "y": 4,
      "z": -5,
      "name": "Nat20_Force_Empty"
    },
    {
      "x": -11,
      "y": 5,
      "z": -5,
      "name": "Nat20_Force_Empty"
    },
    {
      "x": -11,
      "y": 6,
      "z": -5,
      "name": "Nat20_Force_Empty"
    },
    {
      "x": -11,
      "y": 7,
      "z": -5,
      "name": "Nat20_Force_Empty"
    },
    {
      "x": -11,
      "y": 8,
      "z": -5,
      "name": "Nat20_Force_Empty"
    },
    {
      "x": -11,
      "y": 9,
      "z": -5,
      "name": "Nat20_Force_Empty"
    },
    {
      "x": -11,
      "y": 10,
      "z": -5,
      "name": "Nat20_Force_Empty"
    },
    {
      "x": -11,
      "y": 11,
      "z": -5,
      "name": "Nat20_Force_Empty"
    },
    {
      "x": -11,
      "y": 12,
      "z": -5,
      "name": "Nat20_Force_Empty"
    },
    {
      "x": -11,
      "y": 13,
      "z": -5,
      "name": "Nat20_Force_Empty"
    },
    {
      "x": -11,
      "y": 14,
      "z": -5,
      "name": "Nat20_Force_Empty"
    },
    {
      "x": -11,
      "y": 15,
      "z": -5,
      "name": "Nat20_Force_Empty"
    },
    {
      "x": -11,
      "y": 16,
      "z": -5,
      "name": "Nat20_Force_Empty"
    },
    {
      "x": -11,
      "y": 17,
      "z": -5,
      "name": "Nat20_Force_Empty"
    },
    {
      "x": -11,
      "y": 18,
      "z": -5,
      "name": "Nat20_Force_Empty"
    },
    {
      "x": -11,
      "y": 19,
      "z": -5,
      "name": "Nat20_Force_Empty"
    },
    {
      "x": -11,
      "y": 1,
      "z": -4,
      "name": "Nat20_Force_Empty"
    },
    {
      "x": -11,
      "y": 2,
      "z": -4,
      "name": "Nat20_Force_Empty"
    },
    {
      "x": -11,
      "y": 3,
      "z": -4,
      "name": "Nat20_Force_Empty"
    },
    {
      "x": -11,
      "y": 4,
      "z": -4,
      "name": "Nat20_Force_Empty"
    },
    {
      "x": -11,
      "y": 5,
      "z": -4,
      "name": "Nat20_Force_Empty"
    },
    {
      "x": -11,
      "y": 6,
      "z": -4,
      "name": "Nat20_Force_Empty"
    },
    {
      "x": -11,
      "y": 7,
      "z": -4,
      "name": "Nat20_Force_Empty"
    },
    {
      "x": -11,
      "y": 8,
      "z": -4,
      "name": "Nat20_Force_Empty"
    },
    {
      "x": -11,
      "y": 9,
      "z": -4,
      "name": "Nat20_Force_Empty"
    },
    {
      "x": -11,
      "y": 10,
      "z": -4,
      "name": "Nat20_Force_Empty"
    },
    {
      "x": -11,
      "y": 11,
      "z": -4,
      "name": "Nat20_Force_Empty"
    },
    {
      "x": -11,
      "y": 12,
      "z": -4,
      "name": "Nat20_Force_Empty"
    },
    {
      "x": -11,
      "y": 13,
      "z": -4,
      "name": "Nat20_Force_Empty"
    },
    {
      "x": -11,
      "y": 14,
      "z": -4,
      "name": "Nat20_Force_Empty"
    },
    {
      "x": -11,
      "y": 15,
      "z": -4,
      "name": "Nat20_Force_Empty"
    },
    {
      "x": -11,
      "y": 16,
      "z": -4,
      "name": "Nat20_Force_Empty"
    },
    {
      "x": -11,
      "y": 17,
      "z": -4,
      "name": "Nat20_Force_Empty"
    },
    {
      "x": -11,
      "y": 18,
      "z": -4,
      "name": "Nat20_Force_Empty"
    },
    {
      "x": -11,
      "y": 19,
      "z": -4,
      "name": "Nat20_Force_Empty"
    },
    {
      "x": -11,
      "y": 0,
      "z": -3,
      "name": "Wood_Beech_Trunk",
      "support": 1,
      "rotation": 5
    },
    {
      "x": -11,
      "y": 1,
      "z": -3,
      "name": "Plant_Moss_Rug_Green"
    },
    {
      "x": -11,
      "y": 2,
      "z": -3,
      "name": "Nat20_Force_Empty"
    },
    {
      "x": -11,
      "y": 3,
      "z": -3,
      "name": "Nat20_Force_Empty"
    },
    {
      "x": -11,
      "y": 4,
      "z": -3,
      "name": "Nat20_Force_Empty"
    },
    {
      "x": -11,
      "y": 5,
      "z": -3,
      "name": "Wood_Deadwood_Roof_Flat",
      "rotation": 1
    },
    {
      "x": -11,
      "y": 6,
      "z": -3,
      "name": "Nat20_Force_Empty"
    },
    {
      "x": -11,
      "y": 7,
      "z": -3,
      "name": "Nat20_Force_Empty"
    },
    {
      "x": -11,
      "y": 8,
      "z": -3,
      "name": "Nat20_Force_Empty"
    },
    {
      "x": -11,
      "y": 9,
      "z": -3,
      "name": "Nat20_Force_Empty"
    },
    {
      "x": -11,
      "y": 10,
      "z": -3,
      "name": "Nat20_Force_Empty"
    },
    {
      "x": -11,
      "y": 11,
      "z": -3,
      "name": "Nat20_Force_Empty"
    },
    {
      "x": -11,
      "y": 12,
      "z": -3,
      "name": "Nat20_Force_Empty"
    },
    {
      "x": -11,
      "y": 13,
      "z": -3,
      "name": "Nat20_Force_Empty"
    },
    {
      "x": -11,
      "y": 14,
      "z": -3,
      "name": "Nat20_Force_Empty"
    },
    {
      "x": -11,
      "y": 15,
      "z": -3,
      "name": "Nat20_Force_Empty"
    },
    {
      "x": -11,
      "y": 16,
      "z": -3,
      "name": "Nat20_Force_Empty"
    },
    {
      "x": -11,
      "y": 17,
      "z": -3,
      "name": "Nat20_Force_Empty"
    },
    {
      "x": -11,
      "y": 18,
      "z": -3,
      "name": "Nat20_Force_Empty"
    },
    {
      "x": -11,
      "y": 19,
      "z": -3,
      "name": "Nat20_Force_Empty"
    },
    {
      "x": -11,
      "y": 0,
      "z": -2,
      "name": "Wood_Beech_Trunk",
      "support": 1,
      "rotation": 5
    },
    {
      "x": -11,
      "y": 1,
      "z": -2,
      "name": "Wood_Softwood_Decorative"
    },
    {
      "x": -11,
      "y": 2,
      "z": -2,
      "name": "Wood_Softwood_Fence",
      "rotation": 2
    },
    {
      "x": -11,
      "y": 3,
      "z": -2,
      "name": "Wood_Softwood_Decorative"
    },
    {
      "x": -11,
      "y": 4,
      "z": -2,
      "name": "Wood_Softwood_Decorative"
    },
    {
      "x": -11,
      "y": 5,
      "z": -2,
      "name": "Wood_Deadwood_Roof_Flat",
      "rotation": 1
    },
    {
      "x": -11,
      "y": 6,
      "z": -2,
      "name": "Nat20_Force_Empty"
    },
    {
      "x": -11,
      "y": 7,
      "z": -2,
      "name": "Nat20_Force_Empty"
    },
    {
      "x": -11,
      "y": 8,
      "z": -2,
      "name": "Nat20_Force_Empty"
    },
    {
      "x": -11,
      "y": 9,
      "z": -2,
      "name": "Nat20_Force_Empty"
    },
    {
      "x": -11,
      "y": 10,
      "z": -2,
      "name": "Nat20_Force_Empty"
    },
    {
      "x": -11,
      "y": 11,
      "z": -2,
      "name": "Nat20_Force_Empty"
    },
    {
      "x": -11,
      "y": 12,
      "z": -2,
      "name": "Nat20_Force_Empty"
    },
    {
      "x": -11,
      "y": 13,
      "z": -2,
      "name": "Nat20_Force_Empty"
    },
    {
      "x": -11,
      "y": 14,
      "z": -2,
      "name": "Nat20_Force_Empty"
    },
    {
      "x": -11,
      "y": 15,
      "z": -2,
      "name": "Nat20_Force_Empty"
    },
    {
      "x": -11,
      "y": 16,
      "z": -2,
      "name": "Nat20_Force_Empty"
    },
    {
      "x": -11,
      "y": 17,
      "z": -2,
      "name": "Nat20_Force_Empty"
    },
    {
      "x": -11,
      "y": 18,
      "z": -2,
      "name": "Nat20_Force_Empty"
    },
    {
      "x": -11,
      "y": 19,
      "z": -2,
      "name": "Nat20_Force_Empty"
    },
    {
      "x": -11,
      "y": 0,
      "z": -1,
      "name": "Wood_Softwood_Planks"
    },
    {
      "x": -11,
      "y": 1,
      "z": -1,
      "name": "Furniture_Village_Crate"
    },
    {
      "x": -11,
      "y": 2,
      "z": -1,
      "name": "Nat20_Force_Empty"
    },
    {
      "x": -11,
      "y": 3,
      "z": -1,
      "name": "Nat20_Force_Empty"
    },
    {
      "x": -11,
      "y": 4,
      "z": -1,
      "name": "Wood_Softwood_Planks"
    },
    {
      "x": -11,
      "y": 5,
      "z": -1,
      "name": "Wood_Deadwood_Roof_Flat",
      "rotation": 1
    },
    {
      "x": -11,
      "y": 6,
      "z": -1,
      "name": "Nat20_Force_Empty"
    },
    {
      "x": -11,
      "y": 7,
      "z": -1,
      "name": "Nat20_Force_Empty"
    },
    {
      "x": -11,
      "y": 8,
      "z": -1,
      "name": "Nat20_Force_Empty"
    },
    {
      "x": -11,
      "y": 9,
      "z": -1,
      "name": "Nat20_Force_Empty"
    },
    {
      "x": -11,
      "y": 10,
      "z": -1,
      "name": "Nat20_Force_Empty"
    },
    {
      "x": -11,
      "y": 11,
      "z": -1,
      "name": "Nat20_Force_Empty"
    },
    {
      "x": -11,
      "y": 12,
      "z": -1,
      "name": "Nat20_Force_Empty"
    },
    {
      "x": -11,
      "y": 13,
      "z": -1,
      "name": "Nat20_Force_Empty"
    },
    {
      "x": -11,
      "y": 14,
      "z": -1,
      "name": "Nat20_Force_Empty"
    },
    {
      "x": -11,
      "y": 15,
      "z": -1,
      "name": "Nat20_Force_Empty"
    },
    {
      "x": -11,
      "y": 16,
      "z": -1,
      "name": "Nat20_Force_Empty"
    },
    {
      "x": -11,
      "y": 17,
      "z": -1,
      "name": "Nat20_Force_Empty"
    },
    {
      "x": -11,
      "y": 18,
      "z": -1,
      "name": "Nat20_Force_Empty"
    },
    {
      "x": -11,
      "y": 19,
      "z": -1,
      "name": "Nat20_Force_Empty"
    },
    {
      "x": -11,
      "y": 0,
      "z": 0,
      "name": "Wood_Softwood_Planks"
    },
    {
      "x": -11,
      "y": 1,
      "z": 0,
      "name": "Furniture_Village_Crate"
    },
    {
      "x": -11,
      "y": 2,
      "z": 0,
      "name": "Nat20_Force_Empty"
    },
    {
      "x": -11,
      "y": 3,
      "z": 0,
      "name": "Nat20_Force_Empty"
    },
    {
      "x": -11,
      "y": 4,
      "z": 0,
      "name": "Wood_Softwood_Planks"
    },
    {
      "x": -11,
      "y": 5,
      "z": 0,
      "name": "Wood_Deadwood_Roof_Flat",
      "rotation": 1
    },
    {
      "x": -11,
      "y": 6,
      "z": 0,
      "name": "Nat20_Force_Empty"
    },
    {
      "x": -11,
      "y": 7,
      "z": 0,
      "name": "Nat20_Force_Empty"
    },
    {
      "x": -11,
      "y": 8,
      "z": 0,
      "name": "Nat20_Force_Empty"
    },
    {
      "x": -11,
      "y": 9,
      "z": 0,
      "name": "Nat20_Force_Empty"
    },
    {
      "x": -11,
      "y": 10,
      "z": 0,
      "name": "Nat20_Force_Empty"
    },
    {
      "x": -11,
      "y": 11,
      "z": 0,
      "name": "Nat20_Force_Empty"
    },
    {
      "x": -11,
      "y": 12,
      "z": 0,
      "name": "Nat20_Force_Empty"
    },
    {
      "x": -11,
      "y": 13,
      "z": 0,
      "name": "Nat20_Force_Empty"
    },
    {
      "x": -11,
      "y": 14,
      "z": 0,
      "name": "Nat20_Force_Empty"
    },
    {
      "x": -11,
      "y": 15,
      "z": 0,
      "name": "Nat20_Force_Empty"
    },
    {
      "x": -11,
      "y": 16,
      "z": 0,
      "name": "Nat20_Force_Empty"
    },
    {
      "x": -11,
      "y": 17,
      "z": 0,
      "name": "Nat20_Force_Empty"
    },
    {
      "x": -11,
      "y": 18,
      "z": 0,
      "name": "Nat20_Force_Empty"
    },
    {
      "x": -11,
      "y": 19,
      "z": 0,
      "name": "Nat20_Force_Empty"
    },
    {
      "x": -11,
      "y": 0,
      "z": 1,
      "name": "Wood_Softwood_Planks"
    },
    {
      "x": -11,
      "y": 1,
      "z": 1,
      "name": "Nat20_Force_Empty"
    },
    {
      "x": -11,
      "y": 2,
      "z": 1,
      "name": "Nat20_Force_Empty"
    },
    {
      "x": -11,
      "y": 3,
      "z": 1,
      "name": "Nat20_Force_Empty"
    },
    {
      "x": -11,
      "y": 4,
      "z": 1,
      "name": "Wood_Softwood_Planks"
    },
    {
      "x": -11,
      "y": 5,
      "z": 1,
      "name": "Wood_Deadwood_Roof_Flat",
      "rotation": 1
    },
    {
      "x": -11,
      "y": 6,
      "z": 1,
      "name": "Nat20_Force_Empty"
    },
    {
      "x": -11,
      "y": 7,
      "z": 1,
      "name": "Nat20_Force_Empty"
    },
    {
      "x": -11,
      "y": 8,
      "z": 1,
      "name": "Nat20_Force_Empty"
    },
    {
      "x": -11,
      "y": 9,
      "z": 1,
      "name": "Nat20_Force_Empty"
    },
    {
      "x": -11,
      "y": 10,
      "z": 1,
      "name": "Nat20_Force_Empty"
    },
    {
      "x": -11,
      "y": 11,
      "z": 1,
      "name": "Nat20_Force_Empty"
    },
    {
      "x": -11,
      "y": 12,
      "z": 1,
      "name": "Nat20_Force_Empty"
    },
    {
      "x": -11,
      "y": 13,
      "z": 1,
      "name": "Nat20_Force_Empty"
    },
    {
      "x": -11,
      "y": 14,
      "z": 1,
      "name": "Nat20_Force_Empty"
    },
    {
      "x": -11,
      "y": 15,
      "z": 1,
      "name": "Nat20_Force_Empty"
    },
    {
      "x": -11,
      "y": 16,
      "z": 1,
      "name": "Nat20_Force_Empty"
    },
    {
      "x": -11,
      "y": 17,
      "z": 1,
      "name": "Nat20_Force_Empty"
    },
    {
      "x": -11,
      "y": 18,
      "z": 1,
      "name": "Nat20_Force_Empty"
    },
    {
      "x": -11,
      "y": 19,
      "z": 1,
      "name": "Nat20_Force_Empty"
    },
    {
      "x": -11,
      "y": 0,
      "z": 2,
      "name": "Wood_Softwood_Planks"
    },
    {
      "x": -11,
      "y": 1,
      "z": 2,
      "name": "Nat20_Force_Empty"
    },
    {
      "x": -11,
      "y": 2,
      "z": 2,
      "name": "Nat20_Force_Empty"
    },
    {
      "x": -11,
      "y": 3,
      "z": 2,
      "name": "Nat20_Force_Empty"
    },
    {
      "x": -11,
      "y": 4,
      "z": 2,
      "name": "Wood_Softwood_Planks"
    },
    {
      "x": -11,
      "y": 5,
      "z": 2,
      "name": "Wood_Deadwood_Roof_Flat",
      "rotation": 1
    },
    {
      "x": -11,
      "y": 6,
      "z": 2,
      "name": "Nat20_Force_Empty"
    },
    {
      "x": -11,
      "y": 7,
      "z": 2,
      "name": "Nat20_Force_Empty"
    },
    {
      "x": -11,
      "y": 8,
      "z": 2,
      "name": "Nat20_Force_Empty"
    },
    {
      "x": -11,
      "y": 9,
      "z": 2,
      "name": "Nat20_Force_Empty"
    },
    {
      "x": -11,
      "y": 10,
      "z": 2,
      "name": "Nat20_Force_Empty"
    },
    {
      "x": -11,
      "y": 11,
      "z": 2,
      "name": "Nat20_Force_Empty"
    },
    {
      "x": -11,
      "y": 12,
      "z": 2,
      "name": "Nat20_Force_Empty"
    },
    {
      "x": -11,
      "y": 13,
      "z": 2,
      "name": "Nat20_Force_Empty"
    },
    {
      "x": -11,
      "y": 14,
      "z": 2,
      "name": "Nat20_Force_Empty"
    },
    {
      "x": -11,
      "y": 15,
      "z": 2,
      "name": "Nat20_Force_Empty"
    },
    {
      "x": -11,
      "y": 16,
      "z": 2,
      "name": "Nat20_Force_Empty"
    },
    {
      "x": -11,
      "y": 17,
      "z": 2,
      "name": "Nat20_Force_Empty"
    },
    {
      "x": -11,
      "y": 18,
      "z": 2,
      "name": "Nat20_Force_Empty"
    },
    {
      "x": -11,
      "y": 19,
      "z": 2,
      "name": "Nat20_Force_Empty"
    },
    {
      "x": -11,
      "y": 0,
      "z": 3,
      "name": "Wood_Softwood_Planks"
    },
    {
      "x": -11,
      "y": 1,
      "z": 3,
      "name": "Nat20_Force_Empty"
    },
    {
      "x": -11,
      "y": 2,
      "z": 3,
      "name": "Nat20_Force_Empty"
    },
    {
      "x": -11,
      "y": 3,
      "z": 3,
      "name": "Nat20_Force_Empty"
    },
    {
      "x": -11,
      "y": 4,
      "z": 3,
      "name": "Wood_Softwood_Planks"
    },
    {
      "x": -11,
      "y": 5,
      "z": 3,
      "name": "Wood_Deadwood_Roof_Flat",
      "rotation": 1
    },
    {
      "x": -11,
      "y": 6,
      "z": 3,
      "name": "Nat20_Force_Empty"
    },
    {
      "x": -11,
      "y": 7,
      "z": 3,
      "name": "Nat20_Force_Empty"
    },
    {
      "x": -11,
      "y": 8,
      "z": 3,
      "name": "Nat20_Force_Empty"
    },
    {
      "x": -11,
      "y": 9,
      "z": 3,
      "name": "Nat20_Force_Empty"
    },
    {
      "x": -11,
      "y": 10,
      "z": 3,
      "name": "Nat20_Force_Empty"
    },
    {
      "x": -11,
      "y": 11,
      "z": 3,
      "name": "Nat20_Force_Empty"
    },
    {
      "x": -11,
      "y": 12,
      "z": 3,
      "name": "Nat20_Force_Empty"
    },
    {
      "x": -11,
      "y": 13,
      "z": 3,
      "name": "Nat20_Force_Empty"
    },
    {
      "x": -11,
      "y": 14,
      "z": 3,
      "name": "Nat20_Force_Empty"
    },
    {
      "x": -11,
      "y": 15,
      "z": 3,
      "name": "Nat20_Force_Empty"
    },
    {
      "x": -11,
      "y": 16,
      "z": 3,
      "name": "Nat20_Force_Empty"
    },
    {
      "x": -11,
      "y": 17,
      "z": 3,
      "name": "Nat20_Force_Empty"
    },
    {
      "x": -11,
      "y": 18,
      "z": 3,
      "name": "Nat20_Force_Empty"
    },
    {
      "x": -11,
      "y": 19,
      "z": 3,
      "name": "Nat20_Force_Empty"
    },
    {
      "x": -11,
      "y": 0,
      "z": 4,
      "name": "Wood_Softwood_Planks"
    },
    {
      "x": -11,
      "y": 1,
      "z": 4,
      "name": "Nat20_Force_Empty"
    },
    {
      "x": -11,
      "y": 2,
      "z": 4,
      "name": "Nat20_Force_Empty"
    },
    {
      "x": -11,
      "y": 3,
      "z": 4,
      "name": "Nat20_Force_Empty"
    },
    {
      "x": -11,
      "y": 4,
      "z": 4,
      "name": "Wood_Softwood_Planks"
    },
    {
      "x": -11,
      "y": 5,
      "z": 4,
      "name": "Wood_Deadwood_Roof_Flat",
      "rotation": 1
    },
    {
      "x": -11,
      "y": 6,
      "z": 4,
      "name": "Nat20_Force_Empty"
    },
    {
      "x": -11,
      "y": 7,
      "z": 4,
      "name": "Nat20_Force_Empty"
    },
    {
      "x": -11,
      "y": 8,
      "z": 4,
      "name": "Nat20_Force_Empty"
    },
    {
      "x": -11,
      "y": 9,
      "z": 4,
      "name": "Nat20_Force_Empty"
    },
    {
      "x": -11,
      "y": 10,
      "z": 4,
      "name": "Nat20_Force_Empty"
    },
    {
      "x": -11,
      "y": 11,
      "z": 4,
      "name": "Nat20_Force_Empty"
    },
    {
      "x": -11,
      "y": 12,
      "z": 4,
      "name": "Nat20_Force_Empty"
    },
    {
      "x": -11,
      "y": 13,
      "z": 4,
      "name": "Nat20_Force_Empty"
    },
    {
      "x": -11,
      "y": 14,
      "z": 4,
      "name": "Nat20_Force_Empty"
    },
    {
      "x": -11,
      "y": 15,
      "z": 4,
      "name": "Nat20_Force_Empty"
    },
    {
      "x": -11,
      "y": 16,
      "z": 4,
      "name": "Nat20_Force_Empty"
    },
    {
      "x": -11,
      "y": 17,
      "z": 4,
      "name": "Nat20_Force_Empty"
    },
    {
      "x": -11,
      "y": 18,
      "z": 4,
      "name": "Nat20_Force_Empty"
    },
    {
      "x": -11,
      "y": 19,
      "z": 4,
      "name": "Nat20_Force_Empty"
    },
    {
      "x": -11,
      "y": 0,
      "z": 5,
      "name": "Wood_Softwood_Planks"
    },
    {
      "x": -11,
      "y": 1,
      "z": 5,
      "name": "Nat20_Anchor"
    },
    {
      "x": -11,
      "y": 2,
      "z": 5,
      "name": "Nat20_Force_Empty"
    },
    {
      "x": -11,
      "y": 3,
      "z": 5,
      "name": "Nat20_Force_Empty"
    },
    {
      "x": -11,
      "y": 4,
      "z": 5,
      "name": "Wood_Softwood_Planks"
    },
    {
      "x": -11,
      "y": 5,
      "z": 5,
      "name": "Wood_Deadwood_Roof_Flat",
      "rotation": 1
    },
    {
      "x": -11,
      "y": 6,
      "z": 5,
      "name": "Nat20_Force_Empty"
    },
    {
      "x": -11,
      "y": 7,
      "z": 5,
      "name": "Nat20_Force_Empty"
    },
    {
      "x": -11,
      "y": 8,
      "z": 5,
      "name": "Nat20_Force_Empty"
    },
    {
      "x": -11,
      "y": 9,
      "z": 5,
      "name": "Nat20_Force_Empty"
    },
    {
      "x": -11,
      "y": 10,
      "z": 5,
      "name": "Nat20_Force_Empty"
    },
    {
      "x": -11,
      "y": 11,
      "z": 5,
      "name": "Nat20_Force_Empty"
    },
    {
      "x": -11,
      "y": 12,
      "z": 5,
      "name": "Nat20_Force_Empty"
    },
    {
      "x": -11,
      "y": 13,
      "z": 5,
      "name": "Nat20_Force_Empty"
    },
    {
      "x": -11,
      "y": 14,
      "z": 5,
      "name": "Nat20_Force_Empty"
    },
    {
      "x": -11,
      "y": 15,
      "z": 5,
      "name": "Nat20_Force_Empty"
    },
    {
      "x": -11,
      "y": 16,
      "z": 5,
      "name": "Nat20_Force_Empty"
    },
    {
      "x": -11,
      "y": 17,
      "z": 5,
      "name": "Nat20_Force_Empty"
    },
    {
      "x": -11,
      "y": 18,
      "z": 5,
      "name": "Nat20_Force_Empty"
    },
    {
      "x": -11,
      "y": 19,
      "z": 5,
      "name": "Nat20_Force_Empty"
    },
    {
      "x": -11,
      "y": 0,
      "z": 6,
      "name": "Wood_Softwood_Planks"
    },
    {
      "x": -11,
      "y": 1,
      "z": 6,
      "name": "Nat20_Force_Empty"
    },
    {
      "x": -11,
      "y": 2,
      "z": 6,
      "name": "Nat20_Force_Empty"
    },
    {
      "x": -11,
      "y": 3,
      "z": 6,
      "name": "Nat20_Force_Empty"
    },
    {
      "x": -11,
      "y": 4,
      "z": 6,
      "name": "Wood_Softwood_Planks"
    },
    {
      "x": -11,
      "y": 5,
      "z": 6,
      "name": "Wood_Deadwood_Roof_Flat",
      "rotation": 1
    },
    {
      "x": -11,
      "y": 6,
      "z": 6,
      "name": "Nat20_Force_Empty"
    },
    {
      "x": -11,
      "y": 7,
      "z": 6,
      "name": "Nat20_Force_Empty"
    },
    {
      "x": -11,
      "y": 8,
      "z": 6,
      "name": "Nat20_Force_Empty"
    },
    {
      "x": -11,
      "y": 9,
      "z": 6,
      "name": "Nat20_Force_Empty"
    },
    {
      "x": -11,
      "y": 10,
      "z": 6,
      "name": "Nat20_Force_Empty"
    },
    {
      "x": -11,
      "y": 11,
      "z": 6,
      "name": "Nat20_Force_Empty"
    },
    {
      "x": -11,
      "y": 12,
      "z": 6,
      "name": "Nat20_Force_Empty"
    },
    {
      "x": -11,
      "y": 13,
      "z": 6,
      "name": "Nat20_Force_Empty"
    },
    {
      "x": -11,
      "y": 14,
      "z": 6,
      "name": "Nat20_Force_Empty"
    },
    {
      "x": -11,
      "y": 15,
      "z": 6,
      "name": "Nat20_Force_Empty"
    },
    {
      "x": -11,
      "y": 16,
      "z": 6,
      "name": "Nat20_Force_Empty"
    },
    {
      "x": -11,
      "y": 17,
      "z": 6,
      "name": "Nat20_Force_Empty"
    },
    {
      "x": -11,
      "y": 18,
      "z": 6,
      "name": "Nat20_Force_Empty"
    },
    {
      "x": -11,
      "y": 19,
      "z": 6,
      "name": "Nat20_Force_Empty"
    },
    {
      "x": -11,
      "y": 0,
      "z": 7,
      "name": "Wood_Softwood_Planks"
    },
    {
      "x": -11,
      "y": 1,
      "z": 7,
      "name": "Wood_Softwood_Decorative"
    },
    {
      "x": -11,
      "y": 2,
      "z": 7,
      "name": "Wood_Softwood_Decorative"
    },
    {
      "x": -11,
      "y": 3,
      "z": 7,
      "name": "Wood_Softwood_Decorative"
    },
    {
      "x": -11,
      "y": 4,
      "z": 7,
      "name": "Wood_Softwood_Decorative"
    },
    {
      "x": -11,
      "y": 5,
      "z": 7,
      "name": "Wood_Deadwood_Roof_Flat",
      "rotation": 1
    },
    {
      "x": -11,
      "y": 6,
      "z": 7,
      "name": "Nat20_Force_Empty"
    },
    {
      "x": -11,
      "y": 7,
      "z": 7,
      "name": "Nat20_Force_Empty"
    },
    {
      "x": -11,
      "y": 8,
      "z": 7,
      "name": "Nat20_Force_Empty"
    },
    {
      "x": -11,
      "y": 9,
      "z": 7,
      "name": "Nat20_Force_Empty"
    },
    {
      "x": -11,
      "y": 10,
      "z": 7,
      "name": "Nat20_Force_Empty"
    },
    {
      "x": -11,
      "y": 11,
      "z": 7,
      "name": "Nat20_Force_Empty"
    },
    {
      "x": -11,
      "y": 12,
      "z": 7,
      "name": "Nat20_Force_Empty"
    },
    {
      "x": -11,
      "y": 13,
      "z": 7,
      "name": "Nat20_Force_Empty"
    },
    {
      "x": -11,
      "y": 14,
      "z": 7,
      "name": "Nat20_Force_Empty"
    },
    {
      "x": -11,
      "y": 15,
      "z": 7,
      "name": "Nat20_Force_Empty"
    },
    {
      "x": -11,
      "y": 16,
      "z": 7,
      "name": "Nat20_Force_Empty"
    },
    {
      "x": -11,
      "y": 17,
      "z": 7,
      "name": "Nat20_Force_Empty"
    },
    {
      "x": -11,
      "y": 18,
      "z": 7,
      "name": "Nat20_Force_Empty"
    },
    {
      "x": -11,
      "y": 19,
      "z": 7,
      "name": "Nat20_Force_Empty"
    },
    {
      "x": -11,
      "y": 0,
      "z": 8,
      "name": "Wood_Beech_Trunk",
      "support": 1,
      "rotation": 5
    },
    {
      "x": -11,
      "y": 1,
      "z": 8,
      "name": "Nat20_Force_Empty"
    },
    {
      "x": -11,
      "y": 2,
      "z": 8,
      "name": "Nat20_Force_Empty"
    },
    {
      "x": -11,
      "y": 3,
      "z": 8,
      "name": "Nat20_Force_Empty"
    },
    {
      "x": -11,
      "y": 4,
      "z": 8,
      "name": "Nat20_Force_Empty"
    },
    {
      "x": -11,
      "y": 5,
      "z": 8,
      "name": "Wood_Deadwood_Roof_Flat",
      "rotation": 1
    },
    {
      "x": -11,
      "y": 6,
      "z": 8,
      "name": "Nat20_Force_Empty"
    },
    {
      "x": -11,
      "y": 7,
      "z": 8,
      "name": "Nat20_Force_Empty"
    },
    {
      "x": -11,
      "y": 8,
      "z": 8,
      "name": "Nat20_Force_Empty"
    },
    {
      "x": -11,
      "y": 9,
      "z": 8,
      "name": "Nat20_Force_Empty"
    },
    {
      "x": -11,
      "y": 10,
      "z": 8,
      "name": "Nat20_Force_Empty"
    },
    {
      "x": -11,
      "y": 11,
      "z": 8,
      "name": "Nat20_Force_Empty"
    },
    {
      "x": -11,
      "y": 12,
      "z": 8,
      "name": "Nat20_Force_Empty"
    },
    {
      "x": -11,
      "y": 13,
      "z": 8,
      "name": "Nat20_Force_Empty"
    },
    {
      "x": -11,
      "y": 14,
      "z": 8,
      "name": "Nat20_Force_Empty"
    },
    {
      "x": -11,
      "y": 15,
      "z": 8,
      "name": "Nat20_Force_Empty"
    },
    {
      "x": -11,
      "y": 16,
      "z": 8,
      "name": "Nat20_Force_Empty"
    },
    {
      "x": -11,
      "y": 17,
      "z": 8,
      "name": "Nat20_Force_Empty"
    },
    {
      "x": -11,
      "y": 18,
      "z": 8,
      "name": "Nat20_Force_Empty"
    },
    {
      "x": -11,
      "y": 19,
      "z": 8,
      "name": "Nat20_Force_Empty"
    },
    {
      "x": -10,
      "y": 1,
      "z": -7,
      "name": "Nat20_Force_Empty"
    },
    {
      "x": -10,
      "y": 2,
      "z": -7,
      "name": "Nat20_Force_Empty"
    },
    {
      "x": -10,
      "y": 3,
      "z": -7,
      "name": "Nat20_Force_Empty"
    },
    {
      "x": -10,
      "y": 4,
      "z": -7,
      "name": "Nat20_Force_Empty"
    },
    {
      "x": -10,
      "y": 5,
      "z": -7,
      "name": "Nat20_Force_Empty"
    },
    {
      "x": -10,
      "y": 6,
      "z": -7,
      "name": "Nat20_Force_Empty"
    },
    {
      "x": -10,
      "y": 7,
      "z": -7,
      "name": "Nat20_Force_Empty"
    },
    {
      "x": -10,
      "y": 8,
      "z": -7,
      "name": "Nat20_Force_Empty"
    },
    {
      "x": -10,
      "y": 9,
      "z": -7,
      "name": "Nat20_Force_Empty"
    },
    {
      "x": -10,
      "y": 10,
      "z": -7,
      "name": "Nat20_Force_Empty"
    },
    {
      "x": -10,
      "y": 11,
      "z": -7,
      "name": "Nat20_Force_Empty"
    },
    {
      "x": -10,
      "y": 12,
      "z": -7,
      "name": "Nat20_Force_Empty"
    },
    {
      "x": -10,
      "y": 13,
      "z": -7,
      "name": "Nat20_Force_Empty"
    },
    {
      "x": -10,
      "y": 14,
      "z": -7,
      "name": "Nat20_Force_Empty"
    },
    {
      "x": -10,
      "y": 15,
      "z": -7,
      "name": "Nat20_Force_Empty"
    },
    {
      "x": -10,
      "y": 16,
      "z": -7,
      "name": "Nat20_Force_Empty"
    },
    {
      "x": -10,
      "y": 17,
      "z": -7,
      "name": "Nat20_Force_Empty"
    },
    {
      "x": -10,
      "y": 18,
      "z": -7,
      "name": "Nat20_Force_Empty"
    },
    {
      "x": -10,
      "y": 19,
      "z": -7,
      "name": "Nat20_Force_Empty"
    },
    {
      "x": -10,
      "y": 1,
      "z": -6,
      "name": "Nat20_Force_Empty"
    },
    {
      "x": -10,
      "y": 2,
      "z": -6,
      "name": "Nat20_Force_Empty"
    },
    {
      "x": -10,
      "y": 3,
      "z": -6,
      "name": "Nat20_Force_Empty"
    },
    {
      "x": -10,
      "y": 4,
      "z": -6,
      "name": "Nat20_Force_Empty"
    },
    {
      "x": -10,
      "y": 5,
      "z": -6,
      "name": "Nat20_Force_Empty"
    },
    {
      "x": -10,
      "y": 6,
      "z": -6,
      "name": "Nat20_Force_Empty"
    },
    {
      "x": -10,
      "y": 7,
      "z": -6,
      "name": "Nat20_Force_Empty"
    },
    {
      "x": -10,
      "y": 8,
      "z": -6,
      "name": "Nat20_Force_Empty"
    },
    {
      "x": -10,
      "y": 9,
      "z": -6,
      "name": "Nat20_Force_Empty"
    },
    {
      "x": -10,
      "y": 10,
      "z": -6,
      "name": "Nat20_Force_Empty"
    },
    {
      "x": -10,
      "y": 11,
      "z": -6,
      "name": "Nat20_Force_Empty"
    },
    {
      "x": -10,
      "y": 12,
      "z": -6,
      "name": "Nat20_Force_Empty"
    },
    {
      "x": -10,
      "y": 13,
      "z": -6,
      "name": "Nat20_Force_Empty"
    },
    {
      "x": -10,
      "y": 14,
      "z": -6,
      "name": "Nat20_Force_Empty"
    },
    {
      "x": -10,
      "y": 15,
      "z": -6,
      "name": "Nat20_Force_Empty"
    },
    {
      "x": -10,
      "y": 16,
      "z": -6,
      "name": "Nat20_Force_Empty"
    },
    {
      "x": -10,
      "y": 17,
      "z": -6,
      "name": "Nat20_Force_Empty"
    },
    {
      "x": -10,
      "y": 18,
      "z": -6,
      "name": "Nat20_Force_Empty"
    },
    {
      "x": -10,
      "y": 19,
      "z": -6,
      "name": "Nat20_Force_Empty"
    },
    {
      "x": -10,
      "y": 1,
      "z": -5,
      "name": "Nat20_Force_Empty"
    },
    {
      "x": -10,
      "y": 2,
      "z": -5,
      "name": "Nat20_Force_Empty"
    },
    {
      "x": -10,
      "y": 3,
      "z": -5,
      "name": "Nat20_Force_Empty"
    },
    {
      "x": -10,
      "y": 4,
      "z": -5,
      "name": "Nat20_Force_Empty"
    },
    {
      "x": -10,
      "y": 5,
      "z": -5,
      "name": "Nat20_Force_Empty"
    },
    {
      "x": -10,
      "y": 6,
      "z": -5,
      "name": "Nat20_Force_Empty"
    },
    {
      "x": -10,
      "y": 7,
      "z": -5,
      "name": "Nat20_Force_Empty"
    },
    {
      "x": -10,
      "y": 8,
      "z": -5,
      "name": "Nat20_Force_Empty"
    },
    {
      "x": -10,
      "y": 9,
      "z": -5,
      "name": "Nat20_Force_Empty"
    },
    {
      "x": -10,
      "y": 10,
      "z": -5,
      "name": "Nat20_Force_Empty"
    },
    {
      "x": -10,
      "y": 11,
      "z": -5,
      "name": "Nat20_Force_Empty"
    },
    {
      "x": -10,
      "y": 12,
      "z": -5,
      "name": "Nat20_Force_Empty"
    },
    {
      "x": -10,
      "y": 13,
      "z": -5,
      "name": "Nat20_Force_Empty"
    },
    {
      "x": -10,
      "y": 14,
      "z": -5,
      "name": "Nat20_Force_Empty"
    },
    {
      "x": -10,
      "y": 15,
      "z": -5,
      "name": "Nat20_Force_Empty"
    },
    {
      "x": -10,
      "y": 16,
      "z": -5,
      "name": "Nat20_Force_Empty"
    },
    {
      "x": -10,
      "y": 17,
      "z": -5,
      "name": "Nat20_Force_Empty"
    },
    {
      "x": -10,
      "y": 18,
      "z": -5,
      "name": "Nat20_Force_Empty"
    },
    {
      "x": -10,
      "y": 19,
      "z": -5,
      "name": "Nat20_Force_Empty"
    },
    {
      "x": -10,
      "y": 1,
      "z": -4,
      "name": "Nat20_Force_Empty"
    },
    {
      "x": -10,
      "y": 2,
      "z": -4,
      "name": "Nat20_Force_Empty"
    },
    {
      "x": -10,
      "y": 3,
      "z": -4,
      "name": "Nat20_Force_Empty"
    },
    {
      "x": -10,
      "y": 4,
      "z": -4,
      "name": "Nat20_Force_Empty"
    },
    {
      "x": -10,
      "y": 5,
      "z": -4,
      "name": "Nat20_Force_Empty"
    },
    {
      "x": -10,
      "y": 6,
      "z": -4,
      "name": "Nat20_Force_Empty"
    },
    {
      "x": -10,
      "y": 7,
      "z": -4,
      "name": "Nat20_Force_Empty"
    },
    {
      "x": -10,
      "y": 8,
      "z": -4,
      "name": "Nat20_Force_Empty"
    },
    {
      "x": -10,
      "y": 9,
      "z": -4,
      "name": "Nat20_Force_Empty"
    },
    {
      "x": -10,
      "y": 10,
      "z": -4,
      "name": "Nat20_Force_Empty"
    },
    {
      "x": -10,
      "y": 11,
      "z": -4,
      "name": "Nat20_Force_Empty"
    },
    {
      "x": -10,
      "y": 12,
      "z": -4,
      "name": "Nat20_Force_Empty"
    },
    {
      "x": -10,
      "y": 13,
      "z": -4,
      "name": "Nat20_Force_Empty"
    },
    {
      "x": -10,
      "y": 14,
      "z": -4,
      "name": "Nat20_Force_Empty"
    },
    {
      "x": -10,
      "y": 15,
      "z": -4,
      "name": "Nat20_Force_Empty"
    },
    {
      "x": -10,
      "y": 16,
      "z": -4,
      "name": "Nat20_Force_Empty"
    },
    {
      "x": -10,
      "y": 17,
      "z": -4,
      "name": "Nat20_Force_Empty"
    },
    {
      "x": -10,
      "y": 18,
      "z": -4,
      "name": "Nat20_Force_Empty"
    },
    {
      "x": -10,
      "y": 19,
      "z": -4,
      "name": "Nat20_Force_Empty"
    },
    {
      "x": -10,
      "y": 0,
      "z": -3,
      "name": "Wood_Beech_Trunk",
      "support": 2,
      "rotation": 5
    },
    {
      "x": -10,
      "y": 1,
      "z": -3,
      "name": "Plant_Moss_Rug_Green"
    },
    {
      "x": -10,
      "y": 2,
      "z": -3,
      "name": "Nat20_Force_Empty"
    },
    {
      "x": -10,
      "y": 3,
      "z": -3,
      "name": "Nat20_Force_Empty"
    },
    {
      "x": -10,
      "y": 4,
      "z": -3,
      "name": "Nat20_Force_Empty"
    },
    {
      "x": -10,
      "y": 5,
      "z": -3,
      "name": "Wood_Deadwood_Roof",
      "rotation": 3
    },
    {
      "x": -10,
      "y": 6,
      "z": -3,
      "name": "Nat20_Force_Empty"
    },
    {
      "x": -10,
      "y": 7,
      "z": -3,
      "name": "Nat20_Force_Empty"
    },
    {
      "x": -10,
      "y": 8,
      "z": -3,
      "name": "Nat20_Force_Empty"
    },
    {
      "x": -10,
      "y": 9,
      "z": -3,
      "name": "Nat20_Force_Empty"
    },
    {
      "x": -10,
      "y": 10,
      "z": -3,
      "name": "Nat20_Force_Empty"
    },
    {
      "x": -10,
      "y": 11,
      "z": -3,
      "name": "Nat20_Force_Empty"
    },
    {
      "x": -10,
      "y": 12,
      "z": -3,
      "name": "Nat20_Force_Empty"
    },
    {
      "x": -10,
      "y": 13,
      "z": -3,
      "name": "Nat20_Force_Empty"
    },
    {
      "x": -10,
      "y": 14,
      "z": -3,
      "name": "Nat20_Force_Empty"
    },
    {
      "x": -10,
      "y": 15,
      "z": -3,
      "name": "Nat20_Force_Empty"
    },
    {
      "x": -10,
      "y": 16,
      "z": -3,
      "name": "Nat20_Force_Empty"
    },
    {
      "x": -10,
      "y": 17,
      "z": -3,
      "name": "Nat20_Force_Empty"
    },
    {
      "x": -10,
      "y": 18,
      "z": -3,
      "name": "Nat20_Force_Empty"
    },
    {
      "x": -10,
      "y": 19,
      "z": -3,
      "name": "Nat20_Force_Empty"
    },
    {
      "x": -10,
      "y": 0,
      "z": -2,
      "name": "Wood_Beech_Trunk",
      "support": 2,
      "rotation": 5
    },
    {
      "x": -10,
      "y": 1,
      "z": -2,
      "name": "Wood_Softwood_Planks"
    },
    {
      "x": -10,
      "y": 2,
      "z": -2,
      "name": "Wood_Softwood_Planks"
    },
    {
      "x": -10,
      "y": 3,
      "z": -2,
      "name": "Wood_Softwood_Planks"
    },
    {
      "x": -10,
      "y": 4,
      "z": -2,
      "name": "Wood_Softwood_Planks"
    },
    {
      "x": -10,
      "y": 5,
      "z": -2,
      "name": "Wood_Deadwood_Roof",
      "rotation": 3
    },
    {
      "x": -10,
      "y": 6,
      "z": -2,
      "name": "Nat20_Force_Empty"
    },
    {
      "x": -10,
      "y": 7,
      "z": -2,
      "name": "Nat20_Force_Empty"
    },
    {
      "x": -10,
      "y": 8,
      "z": -2,
      "name": "Nat20_Force_Empty"
    },
    {
      "x": -10,
      "y": 9,
      "z": -2,
      "name": "Nat20_Force_Empty"
    },
    {
      "x": -10,
      "y": 10,
      "z": -2,
      "name": "Nat20_Force_Empty"
    },
    {
      "x": -10,
      "y": 11,
      "z": -2,
      "name": "Nat20_Force_Empty"
    },
    {
      "x": -10,
      "y": 12,
      "z": -2,
      "name": "Nat20_Force_Empty"
    },
    {
      "x": -10,
      "y": 13,
      "z": -2,
      "name": "Nat20_Force_Empty"
    },
    {
      "x": -10,
      "y": 14,
      "z": -2,
      "name": "Nat20_Force_Empty"
    },
    {
      "x": -10,
      "y": 15,
      "z": -2,
      "name": "Nat20_Force_Empty"
    },
    {
      "x": -10,
      "y": 16,
      "z": -2,
      "name": "Nat20_Force_Empty"
    },
    {
      "x": -10,
      "y": 17,
      "z": -2,
      "name": "Nat20_Force_Empty"
    },
    {
      "x": -10,
      "y": 18,
      "z": -2,
      "name": "Nat20_Force_Empty"
    },
    {
      "x": -10,
      "y": 19,
      "z": -2,
      "name": "Nat20_Force_Empty"
    },
    {
      "x": -10,
      "y": 0,
      "z": -1,
      "name": "Wood_Softwood_Planks"
    },
    {
      "x": -10,
      "y": 1,
      "z": -1,
      "name": "Furniture_Village_Crate"
    },
    {
      "x": -10,
      "y": 2,
      "z": -1,
      "name": "Nat20_Force_Empty"
    },
    {
      "x": -10,
      "y": 3,
      "z": -1,
      "name": "Nat20_Force_Empty"
    },
    {
      "x": -10,
      "y": 4,
      "z": -1,
      "name": "Wood_Softwood_Planks_Half",
      "rotation": 8
    },
    {
      "x": -10,
      "y": 5,
      "z": -1,
      "name": "Wood_Deadwood_Roof",
      "rotation": 3
    },
    {
      "x": -10,
      "y": 6,
      "z": -1,
      "name": "Nat20_Force_Empty"
    },
    {
      "x": -10,
      "y": 7,
      "z": -1,
      "name": "Nat20_Force_Empty"
    },
    {
      "x": -10,
      "y": 8,
      "z": -1,
      "name": "Nat20_Force_Empty"
    },
    {
      "x": -10,
      "y": 9,
      "z": -1,
      "name": "Nat20_Force_Empty"
    },
    {
      "x": -10,
      "y": 10,
      "z": -1,
      "name": "Nat20_Force_Empty"
    },
    {
      "x": -10,
      "y": 11,
      "z": -1,
      "name": "Nat20_Force_Empty"
    },
    {
      "x": -10,
      "y": 12,
      "z": -1,
      "name": "Nat20_Force_Empty"
    },
    {
      "x": -10,
      "y": 13,
      "z": -1,
      "name": "Nat20_Force_Empty"
    },
    {
      "x": -10,
      "y": 14,
      "z": -1,
      "name": "Nat20_Force_Empty"
    },
    {
      "x": -10,
      "y": 15,
      "z": -1,
      "name": "Nat20_Force_Empty"
    },
    {
      "x": -10,
      "y": 16,
      "z": -1,
      "name": "Nat20_Force_Empty"
    },
    {
      "x": -10,
      "y": 17,
      "z": -1,
      "name": "Nat20_Force_Empty"
    },
    {
      "x": -10,
      "y": 18,
      "z": -1,
      "name": "Nat20_Force_Empty"
    },
    {
      "x": -10,
      "y": 19,
      "z": -1,
      "name": "Nat20_Force_Empty"
    },
    {
      "x": -10,
      "y": 0,
      "z": 0,
      "name": "Wood_Softwood_Planks"
    },
    {
      "x": -10,
      "y": 1,
      "z": 0,
      "name": "Nat20_Force_Empty"
    },
    {
      "x": -10,
      "y": 2,
      "z": 0,
      "name": "Nat20_Force_Empty"
    },
    {
      "x": -10,
      "y": 3,
      "z": 0,
      "name": "Nat20_Force_Empty"
    },
    {
      "x": -10,
      "y": 4,
      "z": 0,
      "name": "Wood_Softwood_Planks_Half",
      "rotation": 8
    },
    {
      "x": -10,
      "y": 5,
      "z": 0,
      "name": "Wood_Deadwood_Roof",
      "rotation": 3
    },
    {
      "x": -10,
      "y": 6,
      "z": 0,
      "name": "Nat20_Force_Empty"
    },
    {
      "x": -10,
      "y": 7,
      "z": 0,
      "name": "Nat20_Force_Empty"
    },
    {
      "x": -10,
      "y": 8,
      "z": 0,
      "name": "Nat20_Force_Empty"
    },
    {
      "x": -10,
      "y": 9,
      "z": 0,
      "name": "Nat20_Force_Empty"
    },
    {
      "x": -10,
      "y": 10,
      "z": 0,
      "name": "Nat20_Force_Empty"
    },
    {
      "x": -10,
      "y": 11,
      "z": 0,
      "name": "Nat20_Force_Empty"
    },
    {
      "x": -10,
      "y": 12,
      "z": 0,
      "name": "Nat20_Force_Empty"
    },
    {
      "x": -10,
      "y": 13,
      "z": 0,
      "name": "Nat20_Force_Empty"
    },
    {
      "x": -10,
      "y": 14,
      "z": 0,
      "name": "Nat20_Force_Empty"
    },
    {
      "x": -10,
      "y": 15,
      "z": 0,
      "name": "Nat20_Force_Empty"
    },
    {
      "x": -10,
      "y": 16,
      "z": 0,
      "name": "Nat20_Force_Empty"
    },
    {
      "x": -10,
      "y": 17,
      "z": 0,
      "name": "Nat20_Force_Empty"
    },
    {
      "x": -10,
      "y": 18,
      "z": 0,
      "name": "Nat20_Force_Empty"
    },
    {
      "x": -10,
      "y": 19,
      "z": 0,
      "name": "Nat20_Force_Empty"
    },
    {
      "x": -10,
      "y": 0,
      "z": 1,
      "name": "Wood_Softwood_Planks"
    },
    {
      "x": -10,
      "y": 1,
      "z": 1,
      "name": "Nat20_Force_Empty"
    },
    {
      "x": -10,
      "y": 2,
      "z": 1,
      "name": "Nat20_Force_Empty"
    },
    {
      "x": -10,
      "y": 3,
      "z": 1,
      "name": "Nat20_Force_Empty"
    },
    {
      "x": -10,
      "y": 4,
      "z": 1,
      "name": "Wood_Softwood_Planks_Half",
      "rotation": 8
    },
    {
      "x": -10,
      "y": 5,
      "z": 1,
      "name": "Wood_Deadwood_Roof",
      "rotation": 3
    },
    {
      "x": -10,
      "y": 6,
      "z": 1,
      "name": "Nat20_Force_Empty"
    },
    {
      "x": -10,
      "y": 7,
      "z": 1,
      "name": "Nat20_Force_Empty"
    },
    {
      "x": -10,
      "y": 8,
      "z": 1,
      "name": "Nat20_Force_Empty"
    },
    {
      "x": -10,
      "y": 9,
      "z": 1,
      "name": "Nat20_Force_Empty"
    },
    {
      "x": -10,
      "y": 10,
      "z": 1,
      "name": "Nat20_Force_Empty"
    },
    {
      "x": -10,
      "y": 11,
      "z": 1,
      "name": "Nat20_Force_Empty"
    },
    {
      "x": -10,
      "y": 12,
      "z": 1,
      "name": "Nat20_Force_Empty"
    },
    {
      "x": -10,
      "y": 13,
      "z": 1,
      "name": "Nat20_Force_Empty"
    },
    {
      "x": -10,
      "y": 14,
      "z": 1,
      "name": "Nat20_Force_Empty"
    },
    {
      "x": -10,
      "y": 15,
      "z": 1,
      "name": "Nat20_Force_Empty"
    },
    {
      "x": -10,
      "y": 16,
      "z": 1,
      "name": "Nat20_Force_Empty"
    },
    {
      "x": -10,
      "y": 17,
      "z": 1,
      "name": "Nat20_Force_Empty"
    },
    {
      "x": -10,
      "y": 18,
      "z": 1,
      "name": "Nat20_Force_Empty"
    },
    {
      "x": -10,
      "y": 19,
      "z": 1,
      "name": "Nat20_Force_Empty"
    },
    {
      "x": -10,
      "y": 0,
      "z": 2,
      "name": "Wood_Softwood_Planks"
    },
    {
      "x": -10,
      "y": 1,
      "z": 2,
      "name": "Nat20_Force_Empty"
    },
    {
      "x": -10,
      "y": 2,
      "z": 2,
      "name": "Nat20_Force_Empty"
    },
    {
      "x": -10,
      "y": 3,
      "z": 2,
      "name": "Nat20_Force_Empty"
    },
    {
      "x": -10,
      "y": 4,
      "z": 2,
      "name": "Wood_Softwood_Planks_Half",
      "rotation": 8
    },
    {
      "x": -10,
      "y": 5,
      "z": 2,
      "name": "Wood_Deadwood_Roof",
      "rotation": 3
    },
    {
      "x": -10,
      "y": 6,
      "z": 2,
      "name": "Nat20_Force_Empty"
    },
    {
      "x": -10,
      "y": 7,
      "z": 2,
      "name": "Nat20_Force_Empty"
    },
    {
      "x": -10,
      "y": 8,
      "z": 2,
      "name": "Nat20_Force_Empty"
    },
    {
      "x": -10,
      "y": 9,
      "z": 2,
      "name": "Nat20_Force_Empty"
    },
    {
      "x": -10,
      "y": 10,
      "z": 2,
      "name": "Nat20_Force_Empty"
    },
    {
      "x": -10,
      "y": 11,
      "z": 2,
      "name": "Nat20_Force_Empty"
    },
    {
      "x": -10,
      "y": 12,
      "z": 2,
      "name": "Nat20_Force_Empty"
    },
    {
      "x": -10,
      "y": 13,
      "z": 2,
      "name": "Nat20_Force_Empty"
    },
    {
      "x": -10,
      "y": 14,
      "z": 2,
      "name": "Nat20_Force_Empty"
    },
    {
      "x": -10,
      "y": 15,
      "z": 2,
      "name": "Nat20_Force_Empty"
    },
    {
      "x": -10,
      "y": 16,
      "z": 2,
      "name": "Nat20_Force_Empty"
    },
    {
      "x": -10,
      "y": 17,
      "z": 2,
      "name": "Nat20_Force_Empty"
    },
    {
      "x": -10,
      "y": 18,
      "z": 2,
      "name": "Nat20_Force_Empty"
    },
    {
      "x": -10,
      "y": 19,
      "z": 2,
      "name": "Nat20_Force_Empty"
    },
    {
      "x": -10,
      "y": 0,
      "z": 3,
      "name": "Wood_Softwood_Planks"
    },
    {
      "x": -10,
      "y": 1,
      "z": 3,
      "name": "Nat20_Force_Empty"
    },
    {
      "x": -10,
      "y": 2,
      "z": 3,
      "name": "Nat20_Force_Empty"
    },
    {
      "x": -10,
      "y": 3,
      "z": 3,
      "name": "Nat20_Force_Empty"
    },
    {
      "x": -10,
      "y": 4,
      "z": 3,
      "name": "Wood_Softwood_Planks_Half",
      "rotation": 8
    },
    {
      "x": -10,
      "y": 5,
      "z": 3,
      "name": "Wood_Softwood_Planks_Half"
    },
    {
      "x": -10,
      "y": 6,
      "z": 3,
      "name": "Nat20_Force_Empty"
    },
    {
      "x": -10,
      "y": 7,
      "z": 3,
      "name": "Nat20_Force_Empty"
    },
    {
      "x": -10,
      "y": 8,
      "z": 3,
      "name": "Nat20_Force_Empty"
    },
    {
      "x": -10,
      "y": 9,
      "z": 3,
      "name": "Nat20_Force_Empty"
    },
    {
      "x": -10,
      "y": 10,
      "z": 3,
      "name": "Nat20_Force_Empty"
    },
    {
      "x": -10,
      "y": 11,
      "z": 3,
      "name": "Nat20_Force_Empty"
    },
    {
      "x": -10,
      "y": 12,
      "z": 3,
      "name": "Nat20_Force_Empty"
    },
    {
      "x": -10,
      "y": 13,
      "z": 3,
      "name": "Nat20_Force_Empty"
    },
    {
      "x": -10,
      "y": 14,
      "z": 3,
      "name": "Nat20_Force_Empty"
    },
    {
      "x": -10,
      "y": 15,
      "z": 3,
      "name": "Nat20_Force_Empty"
    },
    {
      "x": -10,
      "y": 16,
      "z": 3,
      "name": "Nat20_Force_Empty"
    },
    {
      "x": -10,
      "y": 17,
      "z": 3,
      "name": "Nat20_Force_Empty"
    },
    {
      "x": -10,
      "y": 18,
      "z": 3,
      "name": "Nat20_Force_Empty"
    },
    {
      "x": -10,
      "y": 19,
      "z": 3,
      "name": "Nat20_Force_Empty"
    },
    {
      "x": -10,
      "y": 0,
      "z": 4,
      "name": "Wood_Softwood_Planks"
    },
    {
      "x": -10,
      "y": 1,
      "z": 4,
      "name": "Nat20_Force_Empty"
    },
    {
      "x": -10,
      "y": 2,
      "z": 4,
      "name": "Nat20_Force_Empty"
    },
    {
      "x": -10,
      "y": 3,
      "z": 4,
      "name": "Nat20_Force_Empty"
    },
    {
      "x": -10,
      "y": 4,
      "z": 4,
      "name": "Wood_Softwood_Planks_Half",
      "rotation": 8
    },
    {
      "x": -10,
      "y": 5,
      "z": 4,
      "name": "Wood_Softwood_Planks_Half"
    },
    {
      "x": -10,
      "y": 6,
      "z": 4,
      "name": "Nat20_Force_Empty"
    },
    {
      "x": -10,
      "y": 7,
      "z": 4,
      "name": "Nat20_Force_Empty"
    },
    {
      "x": -10,
      "y": 8,
      "z": 4,
      "name": "Nat20_Force_Empty"
    },
    {
      "x": -10,
      "y": 9,
      "z": 4,
      "name": "Nat20_Force_Empty"
    },
    {
      "x": -10,
      "y": 10,
      "z": 4,
      "name": "Nat20_Force_Empty"
    },
    {
      "x": -10,
      "y": 11,
      "z": 4,
      "name": "Nat20_Force_Empty"
    },
    {
      "x": -10,
      "y": 12,
      "z": 4,
      "name": "Nat20_Force_Empty"
    },
    {
      "x": -10,
      "y": 13,
      "z": 4,
      "name": "Nat20_Force_Empty"
    },
    {
      "x": -10,
      "y": 14,
      "z": 4,
      "name": "Nat20_Force_Empty"
    },
    {
      "x": -10,
      "y": 15,
      "z": 4,
      "name": "Nat20_Force_Empty"
    },
    {
      "x": -10,
      "y": 16,
      "z": 4,
      "name": "Nat20_Force_Empty"
    },
    {
      "x": -10,
      "y": 17,
      "z": 4,
      "name": "Nat20_Force_Empty"
    },
    {
      "x": -10,
      "y": 18,
      "z": 4,
      "name": "Nat20_Force_Empty"
    },
    {
      "x": -10,
      "y": 19,
      "z": 4,
      "name": "Nat20_Force_Empty"
    },
    {
      "x": -10,
      "y": 0,
      "z": 5,
      "name": "Wood_Softwood_Planks"
    },
    {
      "x": -10,
      "y": 1,
      "z": 5,
      "name": "Nat20_Force_Empty"
    },
    {
      "x": -10,
      "y": 2,
      "z": 5,
      "name": "Nat20_Force_Empty"
    },
    {
      "x": -10,
      "y": 3,
      "z": 5,
      "name": "Nat20_Force_Empty"
    },
    {
      "x": -10,
      "y": 4,
      "z": 5,
      "name": "Wood_Softwood_Planks_Half",
      "rotation": 8
    },
    {
      "x": -10,
      "y": 5,
      "z": 5,
      "name": "Wood_Softwood_Planks_Half"
    },
    {
      "x": -10,
      "y": 6,
      "z": 5,
      "name": "Nat20_Force_Empty"
    },
    {
      "x": -10,
      "y": 7,
      "z": 5,
      "name": "Nat20_Force_Empty"
    },
    {
      "x": -10,
      "y": 8,
      "z": 5,
      "name": "Nat20_Force_Empty"
    },
    {
      "x": -10,
      "y": 9,
      "z": 5,
      "name": "Nat20_Force_Empty"
    },
    {
      "x": -10,
      "y": 10,
      "z": 5,
      "name": "Nat20_Force_Empty"
    },
    {
      "x": -10,
      "y": 11,
      "z": 5,
      "name": "Nat20_Force_Empty"
    },
    {
      "x": -10,
      "y": 12,
      "z": 5,
      "name": "Nat20_Force_Empty"
    },
    {
      "x": -10,
      "y": 13,
      "z": 5,
      "name": "Nat20_Force_Empty"
    },
    {
      "x": -10,
      "y": 14,
      "z": 5,
      "name": "Nat20_Force_Empty"
    },
    {
      "x": -10,
      "y": 15,
      "z": 5,
      "name": "Nat20_Force_Empty"
    },
    {
      "x": -10,
      "y": 16,
      "z": 5,
      "name": "Nat20_Force_Empty"
    },
    {
      "x": -10,
      "y": 17,
      "z": 5,
      "name": "Nat20_Force_Empty"
    },
    {
      "x": -10,
      "y": 18,
      "z": 5,
      "name": "Nat20_Force_Empty"
    },
    {
      "x": -10,
      "y": 19,
      "z": 5,
      "name": "Nat20_Force_Empty"
    },
    {
      "x": -10,
      "y": 0,
      "z": 6,
      "name": "Wood_Softwood_Planks"
    },
    {
      "x": -10,
      "y": 1,
      "z": 6,
      "name": "Nat20_Force_Empty"
    },
    {
      "x": -10,
      "y": 2,
      "z": 6,
      "name": "Nat20_Force_Empty"
    },
    {
      "x": -10,
      "y": 3,
      "z": 6,
      "name": "Nat20_Force_Empty"
    },
    {
      "x": -10,
      "y": 4,
      "z": 6,
      "name": "Wood_Softwood_Planks_Half",
      "rotation": 8
    },
    {
      "x": -10,
      "y": 5,
      "z": 6,
      "name": "Wood_Softwood_Planks_Half"
    },
    {
      "x": -10,
      "y": 6,
      "z": 6,
      "name": "Nat20_Force_Empty"
    },
    {
      "x": -10,
      "y": 7,
      "z": 6,
      "name": "Nat20_Force_Empty"
    },
    {
      "x": -10,
      "y": 8,
      "z": 6,
      "name": "Nat20_Force_Empty"
    },
    {
      "x": -10,
      "y": 9,
      "z": 6,
      "name": "Nat20_Force_Empty"
    },
    {
      "x": -10,
      "y": 10,
      "z": 6,
      "name": "Nat20_Force_Empty"
    },
    {
      "x": -10,
      "y": 11,
      "z": 6,
      "name": "Nat20_Force_Empty"
    },
    {
      "x": -10,
      "y": 12,
      "z": 6,
      "name": "Nat20_Force_Empty"
    },
    {
      "x": -10,
      "y": 13,
      "z": 6,
      "name": "Nat20_Force_Empty"
    },
    {
      "x": -10,
      "y": 14,
      "z": 6,
      "name": "Nat20_Force_Empty"
    },
    {
      "x": -10,
      "y": 15,
      "z": 6,
      "name": "Nat20_Force_Empty"
    },
    {
      "x": -10,
      "y": 16,
      "z": 6,
      "name": "Nat20_Force_Empty"
    },
    {
      "x": -10,
      "y": 17,
      "z": 6,
      "name": "Nat20_Force_Empty"
    },
    {
      "x": -10,
      "y": 18,
      "z": 6,
      "name": "Nat20_Force_Empty"
    },
    {
      "x": -10,
      "y": 19,
      "z": 6,
      "name": "Nat20_Force_Empty"
    },
    {
      "x": -10,
      "y": 0,
      "z": 7,
      "name": "Wood_Softwood_Planks"
    },
    {
      "x": -10,
      "y": 1,
      "z": 7,
      "name": "Wood_Softwood_Planks"
    },
    {
      "x": -10,
      "y": 2,
      "z": 7,
      "name": "Wood_Softwood_Planks"
    },
    {
      "x": -10,
      "y": 3,
      "z": 7,
      "name": "Wood_Softwood_Planks"
    },
    {
      "x": -10,
      "y": 4,
      "z": 7,
      "name": "Wood_Softwood_Planks"
    },
    {
      "x": -10,
      "y": 5,
      "z": 7,
      "name": "Wood_Softwood_Planks_Half"
    },
    {
      "x": -10,
      "y": 6,
      "z": 7,
      "name": "Nat20_Force_Empty"
    },
    {
      "x": -10,
      "y": 7,
      "z": 7,
      "name": "Nat20_Force_Empty"
    },
    {
      "x": -10,
      "y": 8,
      "z": 7,
      "name": "Nat20_Force_Empty"
    },
    {
      "x": -10,
      "y": 9,
      "z": 7,
      "name": "Nat20_Force_Empty"
    },
    {
      "x": -10,
      "y": 10,
      "z": 7,
      "name": "Nat20_Force_Empty"
    },
    {
      "x": -10,
      "y": 11,
      "z": 7,
      "name": "Nat20_Force_Empty"
    },
    {
      "x": -10,
      "y": 12,
      "z": 7,
      "name": "Nat20_Force_Empty"
    },
    {
      "x": -10,
      "y": 13,
      "z": 7,
      "name": "Nat20_Force_Empty"
    },
    {
      "x": -10,
      "y": 14,
      "z": 7,
      "name": "Nat20_Force_Empty"
    },
    {
      "x": -10,
      "y": 15,
      "z": 7,
      "name": "Nat20_Force_Empty"
    },
    {
      "x": -10,
      "y": 16,
      "z": 7,
      "name": "Nat20_Force_Empty"
    },
    {
      "x": -10,
      "y": 17,
      "z": 7,
      "name": "Nat20_Force_Empty"
    },
    {
      "x": -10,
      "y": 18,
      "z": 7,
      "name": "Nat20_Force_Empty"
    },
    {
      "x": -10,
      "y": 19,
      "z": 7,
      "name": "Nat20_Force_Empty"
    },
    {
      "x": -10,
      "y": 0,
      "z": 8,
      "name": "Wood_Beech_Trunk",
      "support": 2,
      "rotation": 5
    },
    {
      "x": -10,
      "y": 1,
      "z": 8,
      "name": "Nat20_Force_Empty"
    },
    {
      "x": -10,
      "y": 2,
      "z": 8,
      "name": "Nat20_Force_Empty"
    },
    {
      "x": -10,
      "y": 3,
      "z": 8,
      "name": "Nat20_Force_Empty"
    },
    {
      "x": -10,
      "y": 4,
      "z": 8,
      "name": "Nat20_Force_Empty"
    },
    {
      "x": -10,
      "y": 5,
      "z": 8,
      "name": "Wood_Deadwood_Roof",
      "rotation": 3
    },
    {
      "x": -10,
      "y": 6,
      "z": 8,
      "name": "Nat20_Force_Empty"
    },
    {
      "x": -10,
      "y": 7,
      "z": 8,
      "name": "Nat20_Force_Empty"
    },
    {
      "x": -10,
      "y": 8,
      "z": 8,
      "name": "Nat20_Force_Empty"
    },
    {
      "x": -10,
      "y": 9,
      "z": 8,
      "name": "Nat20_Force_Empty"
    },
    {
      "x": -10,
      "y": 10,
      "z": 8,
      "name": "Nat20_Force_Empty"
    },
    {
      "x": -10,
      "y": 11,
      "z": 8,
      "name": "Nat20_Force_Empty"
    },
    {
      "x": -10,
      "y": 12,
      "z": 8,
      "name": "Nat20_Force_Empty"
    },
    {
      "x": -10,
      "y": 13,
      "z": 8,
      "name": "Nat20_Force_Empty"
    },
    {
      "x": -10,
      "y": 14,
      "z": 8,
      "name": "Nat20_Force_Empty"
    },
    {
      "x": -10,
      "y": 15,
      "z": 8,
      "name": "Nat20_Force_Empty"
    },
    {
      "x": -10,
      "y": 16,
      "z": 8,
      "name": "Nat20_Force_Empty"
    },
    {
      "x": -10,
      "y": 17,
      "z": 8,
      "name": "Nat20_Force_Empty"
    },
    {
      "x": -10,
      "y": 18,
      "z": 8,
      "name": "Nat20_Force_Empty"
    },
    {
      "x": -10,
      "y": 19,
      "z": 8,
      "name": "Nat20_Force_Empty"
    },
    {
      "x": -9,
      "y": 1,
      "z": -7,
      "name": "Nat20_Force_Empty"
    },
    {
      "x": -9,
      "y": 2,
      "z": -7,
      "name": "Nat20_Force_Empty"
    },
    {
      "x": -9,
      "y": 3,
      "z": -7,
      "name": "Nat20_Force_Empty"
    },
    {
      "x": -9,
      "y": 4,
      "z": -7,
      "name": "Nat20_Force_Empty"
    },
    {
      "x": -9,
      "y": 5,
      "z": -7,
      "name": "Nat20_Force_Empty"
    },
    {
      "x": -9,
      "y": 6,
      "z": -7,
      "name": "Nat20_Force_Empty"
    },
    {
      "x": -9,
      "y": 7,
      "z": -7,
      "name": "Nat20_Force_Empty"
    },
    {
      "x": -9,
      "y": 8,
      "z": -7,
      "name": "Nat20_Force_Empty"
    },
    {
      "x": -9,
      "y": 9,
      "z": -7,
      "name": "Nat20_Force_Empty"
    },
    {
      "x": -9,
      "y": 10,
      "z": -7,
      "name": "Nat20_Force_Empty"
    },
    {
      "x": -9,
      "y": 11,
      "z": -7,
      "name": "Nat20_Force_Empty"
    },
    {
      "x": -9,
      "y": 12,
      "z": -7,
      "name": "Nat20_Force_Empty"
    },
    {
      "x": -9,
      "y": 13,
      "z": -7,
      "name": "Nat20_Force_Empty"
    },
    {
      "x": -9,
      "y": 14,
      "z": -7,
      "name": "Nat20_Force_Empty"
    },
    {
      "x": -9,
      "y": 15,
      "z": -7,
      "name": "Nat20_Force_Empty"
    },
    {
      "x": -9,
      "y": 16,
      "z": -7,
      "name": "Nat20_Force_Empty"
    },
    {
      "x": -9,
      "y": 17,
      "z": -7,
      "name": "Nat20_Force_Empty"
    },
    {
      "x": -9,
      "y": 18,
      "z": -7,
      "name": "Nat20_Force_Empty"
    },
    {
      "x": -9,
      "y": 19,
      "z": -7,
      "name": "Nat20_Force_Empty"
    },
    {
      "x": -9,
      "y": 1,
      "z": -6,
      "name": "Nat20_Force_Empty"
    },
    {
      "x": -9,
      "y": 2,
      "z": -6,
      "name": "Nat20_Force_Empty"
    },
    {
      "x": -9,
      "y": 3,
      "z": -6,
      "name": "Nat20_Force_Empty"
    },
    {
      "x": -9,
      "y": 4,
      "z": -6,
      "name": "Nat20_Force_Empty"
    },
    {
      "x": -9,
      "y": 5,
      "z": -6,
      "name": "Nat20_Force_Empty"
    },
    {
      "x": -9,
      "y": 6,
      "z": -6,
      "name": "Nat20_Force_Empty"
    },
    {
      "x": -9,
      "y": 7,
      "z": -6,
      "name": "Nat20_Force_Empty"
    },
    {
      "x": -9,
      "y": 8,
      "z": -6,
      "name": "Nat20_Force_Empty"
    },
    {
      "x": -9,
      "y": 9,
      "z": -6,
      "name": "Nat20_Force_Empty"
    },
    {
      "x": -9,
      "y": 10,
      "z": -6,
      "name": "Nat20_Force_Empty"
    },
    {
      "x": -9,
      "y": 11,
      "z": -6,
      "name": "Nat20_Force_Empty"
    },
    {
      "x": -9,
      "y": 12,
      "z": -6,
      "name": "Nat20_Force_Empty"
    },
    {
      "x": -9,
      "y": 13,
      "z": -6,
      "name": "Nat20_Force_Empty"
    },
    {
      "x": -9,
      "y": 14,
      "z": -6,
      "name": "Nat20_Force_Empty"
    },
    {
      "x": -9,
      "y": 15,
      "z": -6,
      "name": "Nat20_Force_Empty"
    },
    {
      "x": -9,
      "y": 16,
      "z": -6,
      "name": "Nat20_Force_Empty"
    },
    {
      "x": -9,
      "y": 17,
      "z": -6,
      "name": "Nat20_Force_Empty"
    },
    {
      "x": -9,
      "y": 18,
      "z": -6,
      "name": "Nat20_Force_Empty"
    },
    {
      "x": -9,
      "y": 19,
      "z": -6,
      "name": "Nat20_Force_Empty"
    },
    {
      "x": -9,
      "y": 1,
      "z": -5,
      "name": "Nat20_Force_Empty"
    },
    {
      "x": -9,
      "y": 2,
      "z": -5,
      "name": "Nat20_Force_Empty"
    },
    {
      "x": -9,
      "y": 3,
      "z": -5,
      "name": "Nat20_Force_Empty"
    },
    {
      "x": -9,
      "y": 4,
      "z": -5,
      "name": "Nat20_Force_Empty"
    },
    {
      "x": -9,
      "y": 5,
      "z": -5,
      "name": "Nat20_Force_Empty"
    },
    {
      "x": -9,
      "y": 6,
      "z": -5,
      "name": "Nat20_Force_Empty"
    },
    {
      "x": -9,
      "y": 7,
      "z": -5,
      "name": "Nat20_Force_Empty"
    },
    {
      "x": -9,
      "y": 8,
      "z": -5,
      "name": "Nat20_Force_Empty"
    },
    {
      "x": -9,
      "y": 9,
      "z": -5,
      "name": "Nat20_Force_Empty"
    },
    {
      "x": -9,
      "y": 10,
      "z": -5,
      "name": "Nat20_Force_Empty"
    },
    {
      "x": -9,
      "y": 11,
      "z": -5,
      "name": "Nat20_Force_Empty"
    },
    {
      "x": -9,
      "y": 12,
      "z": -5,
      "name": "Nat20_Force_Empty"
    },
    {
      "x": -9,
      "y": 13,
      "z": -5,
      "name": "Nat20_Force_Empty"
    },
    {
      "x": -9,
      "y": 14,
      "z": -5,
      "name": "Nat20_Force_Empty"
    },
    {
      "x": -9,
      "y": 15,
      "z": -5,
      "name": "Nat20_Force_Empty"
    },
    {
      "x": -9,
      "y": 16,
      "z": -5,
      "name": "Nat20_Force_Empty"
    },
    {
      "x": -9,
      "y": 17,
      "z": -5,
      "name": "Nat20_Force_Empty"
    },
    {
      "x": -9,
      "y": 18,
      "z": -5,
      "name": "Nat20_Force_Empty"
    },
    {
      "x": -9,
      "y": 19,
      "z": -5,
      "name": "Nat20_Force_Empty"
    },
    {
      "x": -9,
      "y": 1,
      "z": -4,
      "name": "Nat20_Force_Empty"
    },
    {
      "x": -9,
      "y": 2,
      "z": -4,
      "name": "Nat20_Force_Empty"
    },
    {
      "x": -9,
      "y": 3,
      "z": -4,
      "name": "Nat20_Force_Empty"
    },
    {
      "x": -9,
      "y": 4,
      "z": -4,
      "name": "Nat20_Force_Empty"
    },
    {
      "x": -9,
      "y": 5,
      "z": -4,
      "name": "Nat20_Force_Empty"
    },
    {
      "x": -9,
      "y": 6,
      "z": -4,
      "name": "Nat20_Force_Empty"
    },
    {
      "x": -9,
      "y": 7,
      "z": -4,
      "name": "Nat20_Force_Empty"
    },
    {
      "x": -9,
      "y": 8,
      "z": -4,
      "name": "Nat20_Force_Empty"
    },
    {
      "x": -9,
      "y": 9,
      "z": -4,
      "name": "Nat20_Force_Empty"
    },
    {
      "x": -9,
      "y": 10,
      "z": -4,
      "name": "Nat20_Force_Empty"
    },
    {
      "x": -9,
      "y": 11,
      "z": -4,
      "name": "Nat20_Force_Empty"
    },
    {
      "x": -9,
      "y": 12,
      "z": -4,
      "name": "Nat20_Force_Empty"
    },
    {
      "x": -9,
      "y": 13,
      "z": -4,
      "name": "Nat20_Force_Empty"
    },
    {
      "x": -9,
      "y": 14,
      "z": -4,
      "name": "Nat20_Force_Empty"
    },
    {
      "x": -9,
      "y": 15,
      "z": -4,
      "name": "Nat20_Force_Empty"
    },
    {
      "x": -9,
      "y": 16,
      "z": -4,
      "name": "Nat20_Force_Empty"
    },
    {
      "x": -9,
      "y": 17,
      "z": -4,
      "name": "Nat20_Force_Empty"
    },
    {
      "x": -9,
      "y": 18,
      "z": -4,
      "name": "Nat20_Force_Empty"
    },
    {
      "x": -9,
      "y": 19,
      "z": -4,
      "name": "Nat20_Force_Empty"
    },
    {
      "x": -9,
      "y": 0,
      "z": -3,
      "name": "Wood_Beech_Trunk",
      "support": 1,
      "rotation": 5
    },
    {
      "x": -9,
      "y": 1,
      "z": -3,
      "name": "Wood_Beech_Trunk"
    },
    {
      "x": -9,
      "y": 2,
      "z": -3,
      "name": "Wood_Beech_Trunk",
      "support": 15
    },
    {
      "x": -9,
      "y": 3,
      "z": -3,
      "name": "Wood_Beech_Trunk",
      "support": 15
    },
    {
      "x": -9,
      "y": 4,
      "z": -3,
      "name": "Wood_Beech_Trunk",
      "support": 15
    },
    {
      "x": -9,
      "y": 5,
      "z": -3,
      "name": "Wood_Beech_Trunk",
      "support": 15
    },
    {
      "x": -9,
      "y": 6,
      "z": -3,
      "name": "Wood_Deadwood_Roof_Flat",
      "rotation": 1
    },
    {
      "x": -9,
      "y": 7,
      "z": -3,
      "name": "Nat20_Force_Empty"
    },
    {
      "x": -9,
      "y": 8,
      "z": -3,
      "name": "Nat20_Force_Empty"
    },
    {
      "x": -9,
      "y": 9,
      "z": -3,
      "name": "Nat20_Force_Empty"
    },
    {
      "x": -9,
      "y": 10,
      "z": -3,
      "name": "Nat20_Force_Empty"
    },
    {
      "x": -9,
      "y": 11,
      "z": -3,
      "name": "Nat20_Force_Empty"
    },
    {
      "x": -9,
      "y": 12,
      "z": -3,
      "name": "Nat20_Force_Empty"
    },
    {
      "x": -9,
      "y": 13,
      "z": -3,
      "name": "Nat20_Force_Empty"
    },
    {
      "x": -9,
      "y": 14,
      "z": -3,
      "name": "Nat20_Force_Empty"
    },
    {
      "x": -9,
      "y": 15,
      "z": -3,
      "name": "Nat20_Force_Empty"
    },
    {
      "x": -9,
      "y": 16,
      "z": -3,
      "name": "Nat20_Force_Empty"
    },
    {
      "x": -9,
      "y": 17,
      "z": -3,
      "name": "Nat20_Force_Empty"
    },
    {
      "x": -9,
      "y": 18,
      "z": -3,
      "name": "Nat20_Force_Empty"
    },
    {
      "x": -9,
      "y": 19,
      "z": -3,
      "name": "Nat20_Force_Empty"
    },
    {
      "x": -9,
      "y": 0,
      "z": -2,
      "name": "Wood_Beech_Trunk",
      "support": 1,
      "rotation": 5
    },
    {
      "x": -9,
      "y": 1,
      "z": -2,
      "name": "Wood_Softwood_Decorative"
    },
    {
      "x": -9,
      "y": 2,
      "z": -2,
      "name": "Wood_Softwood_Decorative"
    },
    {
      "x": -9,
      "y": 3,
      "z": -2,
      "name": "Wood_Softwood_Decorative"
    },
    {
      "x": -9,
      "y": 4,
      "z": -2,
      "name": "Wood_Softwood_Decorative"
    },
    {
      "x": -9,
      "y": 5,
      "z": -2,
      "name": "Wood_Softwood_Decorative"
    },
    {
      "x": -9,
      "y": 6,
      "z": -2,
      "name": "Wood_Deadwood_Roof_Flat",
      "rotation": 1
    },
    {
      "x": -9,
      "y": 7,
      "z": -2,
      "name": "Nat20_Force_Empty"
    },
    {
      "x": -9,
      "y": 8,
      "z": -2,
      "name": "Nat20_Force_Empty"
    },
    {
      "x": -9,
      "y": 9,
      "z": -2,
      "name": "Nat20_Force_Empty"
    },
    {
      "x": -9,
      "y": 10,
      "z": -2,
      "name": "Nat20_Force_Empty"
    },
    {
      "x": -9,
      "y": 11,
      "z": -2,
      "name": "Nat20_Force_Empty"
    },
    {
      "x": -9,
      "y": 12,
      "z": -2,
      "name": "Nat20_Force_Empty"
    },
    {
      "x": -9,
      "y": 13,
      "z": -2,
      "name": "Nat20_Force_Empty"
    },
    {
      "x": -9,
      "y": 14,
      "z": -2,
      "name": "Nat20_Force_Empty"
    },
    {
      "x": -9,
      "y": 15,
      "z": -2,
      "name": "Nat20_Force_Empty"
    },
    {
      "x": -9,
      "y": 16,
      "z": -2,
      "name": "Nat20_Force_Empty"
    },
    {
      "x": -9,
      "y": 17,
      "z": -2,
      "name": "Nat20_Force_Empty"
    },
    {
      "x": -9,
      "y": 18,
      "z": -2,
      "name": "Nat20_Force_Empty"
