{
  "version": 8,
  "blockIdVersion": 11,
  "anchorX": 0,
  "anchorY": 0,
  "anchorZ": 0,
  "blocks": [
    {
      "x": -7,
      "y": 1,
      "z": -10,
      "name": "Nat20_Force_Empty"
    },
    {
      "x": -7,
      "y": 2,
      "z": -10,
      "name": "Nat20_Force_Empty"
    },
    {
      "x": -7,
      "y": 3,
      "z": -10,
      "name": "Nat20_Force_Empty"
    },
    {
      "x": -7,
      "y": 4,
      "z": -10,
      "name": "Nat20_Force_Empty"
    },
    {
      "x": -7,
      "y": 5,
      "z": -10,
      "name": "Nat20_Force_Empty"
    },
    {
      "x": -7,
      "y": 6,
      "z": -10,
      "name": "Nat20_Force_Empty"
    },
    {
      "x": -7,
      "y": 7,
      "z": -10,
      "name": "Nat20_Force_Empty"
    },
    {
      "x": -7,
      "y": 8,
      "z": -10,
      "name": "Nat20_Force_Empty"
    },
    {
      "x": -7,
      "y": 9,
      "z": -10,
      "name": "Nat20_Force_Empty"
    },
    {
      "x": -7,
      "y": 10,
      "z": -10,
      "name": "Nat20_Force_Empty"
    },
    {
      "x": -7,
      "y": 11,
      "z": -10,
      "name": "Nat20_Force_Empty"
    },
    {
      "x": -7,
      "y": 12,
      "z": -10,
      "name": "Nat20_Force_Empty"
    },
    {
      "x": -7,
      "y": 13,
      "z": -10,
      "name": "Nat20_Force_Empty"
    },
    {
      "x": -7,
      "y": 14,
      "z": -10,
      "name": "Nat20_Force_Empty"
    },
    {
      "x": -7,
      "y": 15,
      "z": -10,
      "name": "Nat20_Force_Empty"
    },
    {
      "x": -7,
      "y": 16,
      "z": -10,
      "name": "Nat20_Force_Empty"
    },
    {
      "x": -7,
      "y": 17,
      "z": -10,
      "name": "Nat20_Force_Empty"
    },
    {
      "x": -7,
      "y": 18,
      "z": -10,
      "name": "Nat20_Force_Empty"
    },
    {
      "x": -7,
      "y": 19,
      "z": -10,
      "name": "Nat20_Force_Empty"
    },
    {
      "x": -7,
      "y": 1,
      "z": -9,
      "name": "Nat20_Force_Empty"
    },
    {
      "x": -7,
      "y": 2,
      "z": -9,
      "name": "Nat20_Force_Empty"
    },
    {
      "x": -7,
      "y": 3,
      "z": -9,
      "name": "Nat20_Force_Empty"
    },
    {
      "x": -7,
      "y": 4,
      "z": -9,
      "name": "Nat20_Force_Empty"
    },
    {
      "x": -7,
      "y": 5,
      "z": -9,
      "name": "Nat20_Force_Empty"
    },
    {
      "x": -7,
      "y": 6,
      "z": -9,
      "name": "Nat20_Force_Empty"
    },
    {
      "x": -7,
      "y": 7,
      "z": -9,
      "name": "Nat20_Force_Empty"
    },
    {
      "x": -7,
      "y": 8,
      "z": -9,
      "name": "Nat20_Force_Empty"
    },
    {
      "x": -7,
      "y": 9,
      "z": -9,
      "name": "Nat20_Force_Empty"
    },
    {
      "x": -7,
      "y": 10,
      "z": -9,
      "name": "Nat20_Force_Empty"
    },
    {
      "x": -7,
      "y": 11,
      "z": -9,
      "name": "Nat20_Force_Empty"
    },
    {
      "x": -7,
      "y": 12,
      "z": -9,
      "name": "Nat20_Force_Empty"
    },
    {
      "x": -7,
      "y": 13,
      "z": -9,
      "name": "Nat20_Force_Empty"
    },
    {
      "x": -7,
      "y": 14,
      "z": -9,
      "name": "Nat20_Force_Empty"
    },
    {
      "x": -7,
      "y": 15,
      "z": -9,
      "name": "Nat20_Force_Empty"
    },
    {
      "x": -7,
      "y": 16,
      "z": -9,
      "name": "Nat20_Force_Empty"
    },
    {
      "x": -7,
      "y": 17,
      "z": -9,
      "name": "Nat20_Force_Empty"
    },
    {
      "x": -7,
      "y": 18,
      "z": -9,
      "name": "Nat20_Force_Empty"
    },
    {
      "x": -7,
      "y": 19,
      "z": -9,
      "name": "Nat20_Force_Empty"
    },
    {
      "x": -7,
      "y": 1,
      "z": -8,
      "name": "Nat20_Force_Empty"
    },
    {
      "x": -7,
      "y": 2,
      "z": -8,
      "name": "Nat20_Force_Empty"
    },
    {
      "x": -7,
      "y": 3,
      "z": -8,
      "name": "Nat20_Force_Empty"
    },
    {
      "x": -7,
      "y": 4,
      "z": -8,
      "name": "Nat20_Force_Empty"
    },
    {
      "x": -7,
      "y": 5,
      "z": -8,
      "name": "Nat20_Force_Empty"
    },
    {
      "x": -7,
      "y": 6,
      "z": -8,
      "name": "Nat20_Force_Empty"
    },
    {
      "x": -7,
      "y": 7,
      "z": -8,
      "name": "Nat20_Force_Empty"
    },
    {
      "x": -7,
      "y": 8,
      "z": -8,
      "name": "Nat20_Force_Empty"
    },
    {
      "x": -7,
      "y": 9,
      "z": -8,
      "name": "Nat20_Force_Empty"
    },
    {
      "x": -7,
      "y": 10,
      "z": -8,
      "name": "Nat20_Force_Empty"
    },
    {
      "x": -7,
      "y": 11,
      "z": -8,
      "name": "Nat20_Force_Empty"
    },
    {
      "x": -7,
      "y": 12,
      "z": -8,
      "name": "Nat20_Force_Empty"
    },
    {
      "x": -7,
      "y": 13,
      "z": -8,
      "name": "Nat20_Force_Empty"
    },
    {
      "x": -7,
      "y": 14,
      "z": -8,
      "name": "Nat20_Force_Empty"
    },
    {
      "x": -7,
      "y": 15,
      "z": -8,
      "name": "Nat20_Force_Empty"
    },
    {
      "x": -7,
      "y": 16,
      "z": -8,
      "name": "Nat20_Force_Empty"
    },
    {
      "x": -7,
      "y": 17,
      "z": -8,
      "name": "Nat20_Force_Empty"
    },
    {
      "x": -7,
      "y": 18,
      "z": -8,
      "name": "Nat20_Force_Empty"
    },
    {
      "x": -7,
      "y": 19,
      "z": -8,
      "name": "Nat20_Force_Empty"
    },
    {
      "x": -7,
      "y": 1,
      "z": -7,
      "name": "Nat20_Force_Empty"
    },
    {
      "x": -7,
      "y": 2,
      "z": -7,
      "name": "Nat20_Force_Empty"
    },
    {
      "x": -7,
      "y": 3,
      "z": -7,
      "name": "Nat20_Force_Empty"
    },
    {
      "x": -7,
      "y": 4,
      "z": -7,
      "name": "Nat20_Force_Empty"
    },
    {
      "x": -7,
      "y": 5,
      "z": -7,
      "name": "Nat20_Force_Empty"
    },
    {
      "x": -7,
      "y": 6,
      "z": -7,
      "name": "Nat20_Force_Empty"
    },
    {
      "x": -7,
      "y": 7,
      "z": -7,
      "name": "Nat20_Force_Empty"
    },
    {
      "x": -7,
      "y": 8,
      "z": -7,
      "name": "Nat20_Force_Empty"
    },
    {
      "x": -7,
      "y": 9,
      "z": -7,
      "name": "Nat20_Force_Empty"
    },
    {
      "x": -7,
      "y": 10,
      "z": -7,
      "name": "Nat20_Force_Empty"
    },
    {
      "x": -7,
      "y": 11,
      "z": -7,
      "name": "Nat20_Force_Empty"
    },
    {
      "x": -7,
      "y": 12,
      "z": -7,
      "name": "Nat20_Force_Empty"
    },
    {
      "x": -7,
      "y": 13,
      "z": -7,
      "name": "Nat20_Force_Empty"
    },
    {
      "x": -7,
      "y": 14,
      "z": -7,
      "name": "Nat20_Force_Empty"
    },
    {
      "x": -7,
      "y": 15,
      "z": -7,
      "name": "Nat20_Force_Empty"
    },
    {
      "x": -7,
      "y": 16,
      "z": -7,
      "name": "Nat20_Force_Empty"
    },
    {
      "x": -7,
      "y": 17,
      "z": -7,
      "name": "Nat20_Force_Empty"
    },
    {
      "x": -7,
      "y": 18,
      "z": -7,
      "name": "Nat20_Force_Empty"
    },
    {
      "x": -7,
      "y": 19,
      "z": -7,
      "name": "Nat20_Force_Empty"
    },
    {
      "x": -7,
      "y": 1,
      "z": -6,
      "name": "Nat20_Force_Empty"
    },
    {
      "x": -7,
      "y": 2,
      "z": -6,
      "name": "Nat20_Force_Empty"
    },
    {
      "x": -7,
      "y": 3,
      "z": -6,
      "name": "Nat20_Force_Empty"
    },
    {
      "x": -7,
      "y": 4,
      "z": -6,
      "name": "Nat20_Force_Empty"
    },
    {
      "x": -7,
      "y": 5,
      "z": -6,
      "name": "Nat20_Force_Empty"
    },
    {
      "x": -7,
      "y": 6,
      "z": -6,
      "name": "Nat20_Force_Empty"
    },
    {
      "x": -7,
      "y": 7,
      "z": -6,
      "name": "Nat20_Force_Empty"
    },
    {
      "x": -7,
      "y": 8,
      "z": -6,
      "name": "Nat20_Force_Empty"
    },
    {
      "x": -7,
      "y": 9,
      "z": -6,
      "name": "Nat20_Force_Empty"
    },
    {
      "x": -7,
      "y": 10,
      "z": -6,
      "name": "Nat20_Force_Empty"
    },
    {
      "x": -7,
      "y": 11,
      "z": -6,
      "name": "Nat20_Force_Empty"
    },
    {
      "x": -7,
      "y": 12,
      "z": -6,
      "name": "Nat20_Force_Empty"
    },
    {
      "x": -7,
      "y": 13,
      "z": -6,
      "name": "Nat20_Force_Empty"
    },
    {
      "x": -7,
      "y": 14,
      "z": -6,
      "name": "Nat20_Force_Empty"
    },
    {
      "x": -7,
      "y": 15,
      "z": -6,
      "name": "Nat20_Force_Empty"
    },
    {
      "x": -7,
      "y": 16,
      "z": -6,
      "name": "Nat20_Force_Empty"
    },
    {
      "x": -7,
      "y": 17,
      "z": -6,
      "name": "Nat20_Force_Empty"
    },
    {
      "x": -7,
      "y": 18,
      "z": -6,
      "name": "Nat20_Force_Empty"
    },
    {
      "x": -7,
      "y": 19,
      "z": -6,
      "name": "Nat20_Force_Empty"
    },
    {
      "x": -7,
      "y": 0,
      "z": -5,
      "name": "Soil_Dirt_Dry"
    },
    {
      "x": -7,
      "y": 1,
      "z": -5,
      "name": "Nat20_Force_Empty"
    },
    {
      "x": -7,
      "y": 2,
      "z": -5,
      "name": "Nat20_Force_Empty"
    },
    {
      "x": -7,
      "y": 3,
      "z": -5,
      "name": "Nat20_Force_Empty"
    },
    {
      "x": -7,
      "y": 4,
      "z": -5,
      "name": "Nat20_Force_Empty"
    },
    {
      "x": -7,
      "y": 5,
      "z": -5,
      "name": "Nat20_Force_Empty"
    },
    {
      "x": -7,
      "y": 6,
      "z": -5,
      "name": "Nat20_Force_Empty"
    },
    {
      "x": -7,
      "y": 7,
      "z": -5,
      "name": "Nat20_Force_Empty"
    },
    {
      "x": -7,
      "y": 8,
      "z": -5,
      "name": "Nat20_Force_Empty"
    },
    {
      "x": -7,
      "y": 9,
      "z": -5,
      "name": "Nat20_Force_Empty"
    },
    {
      "x": -7,
      "y": 10,
      "z": -5,
      "name": "Nat20_Force_Empty"
    },
    {
      "x": -7,
      "y": 11,
      "z": -5,
      "name": "Nat20_Force_Empty"
    },
    {
      "x": -7,
      "y": 12,
      "z": -5,
      "name": "Nat20_Force_Empty"
    },
    {
      "x": -7,
      "y": 13,
      "z": -5,
      "name": "Nat20_Force_Empty"
    },
    {
      "x": -7,
      "y": 14,
      "z": -5,
      "name": "Nat20_Force_Empty"
    },
    {
      "x": -7,
      "y": 15,
      "z": -5,
      "name": "Nat20_Force_Empty"
    },
    {
      "x": -7,
      "y": 16,
      "z": -5,
      "name": "Nat20_Force_Empty"
    },
    {
      "x": -7,
      "y": 17,
      "z": -5,
      "name": "Nat20_Force_Empty"
    },
    {
      "x": -7,
      "y": 18,
      "z": -5,
      "name": "Nat20_Force_Empty"
    },
    {
      "x": -7,
      "y": 19,
      "z": -5,
      "name": "Nat20_Force_Empty"
    },
    {
      "x": -7,
      "y": 0,
      "z": -4,
      "name": "Soil_Dirt_Dry"
    },
    {
      "x": -7,
      "y": 1,
      "z": -4,
      "name": "Nat20_Force_Empty"
    },
    {
      "x": -7,
      "y": 2,
      "z": -4,
      "name": "Nat20_Force_Empty"
    },
    {
      "x": -7,
      "y": 3,
      "z": -4,
      "name": "Nat20_Force_Empty"
    },
    {
      "x": -7,
      "y": 4,
      "z": -4,
      "name": "Nat20_Force_Empty"
    },
    {
      "x": -7,
      "y": 5,
      "z": -4,
      "name": "Nat20_Force_Empty"
    },
    {
      "x": -7,
      "y": 6,
      "z": -4,
      "name": "Nat20_Force_Empty"
    },
    {
      "x": -7,
      "y": 7,
      "z": -4,
      "name": "Nat20_Force_Empty"
    },
    {
      "x": -7,
      "y": 8,
      "z": -4,
      "name": "Nat20_Force_Empty"
    },
    {
      "x": -7,
      "y": 9,
      "z": -4,
      "name": "Nat20_Force_Empty"
    },
    {
      "x": -7,
      "y": 10,
      "z": -4,
      "name": "Nat20_Force_Empty"
    },
    {
      "x": -7,
      "y": 11,
      "z": -4,
      "name": "Nat20_Force_Empty"
    },
    {
      "x": -7,
      "y": 12,
      "z": -4,
      "name": "Nat20_Force_Empty"
    },
    {
      "x": -7,
      "y": 13,
      "z": -4,
      "name": "Nat20_Force_Empty"
    },
    {
      "x": -7,
      "y": 14,
      "z": -4,
      "name": "Nat20_Force_Empty"
    },
    {
      "x": -7,
      "y": 15,
      "z": -4,
      "name": "Nat20_Force_Empty"
    },
    {
      "x": -7,
      "y": 16,
      "z": -4,
      "name": "Nat20_Force_Empty"
    },
    {
      "x": -7,
      "y": 17,
      "z": -4,
      "name": "Nat20_Force_Empty"
    },
    {
      "x": -7,
      "y": 18,
      "z": -4,
      "name": "Nat20_Force_Empty"
    },
    {
      "x": -7,
      "y": 19,
      "z": -4,
      "name": "Nat20_Force_Empty"
    },
    {
      "x": -7,
      "y": 0,
      "z": -3,
      "name": "Soil_Dirt_Dry"
    },
    {
      "x": -7,
      "y": 1,
      "z": -3,
      "name": "Nat20_Force_Empty"
    },
    {
      "x": -7,
      "y": 2,
      "z": -3,
      "name": "Nat20_Force_Empty"
    },
    {
      "x": -7,
      "y": 3,
      "z": -3,
      "name": "Nat20_Force_Empty"
    },
    {
      "x": -7,
      "y": 4,
      "z": -3,
      "name": "Nat20_Force_Empty"
    },
    {
      "x": -7,
      "y": 5,
      "z": -3,
      "name": "Nat20_Force_Empty"
    },
    {
      "x": -7,
      "y": 6,
      "z": -3,
      "name": "Nat20_Force_Empty"
    },
    {
      "x": -7,
      "y": 7,
      "z": -3,
      "name": "Nat20_Force_Empty"
    },
    {
      "x": -7,
      "y": 8,
      "z": -3,
      "name": "Nat20_Force_Empty"
    },
    {
      "x": -7,
      "y": 9,
      "z": -3,
      "name": "Nat20_Force_Empty"
    },
    {
      "x": -7,
      "y": 10,
      "z": -3,
      "name": "Nat20_Force_Empty"
    },
    {
      "x": -7,
      "y": 11,
      "z": -3,
      "name": "Nat20_Force_Empty"
    },
    {
      "x": -7,
      "y": 12,
      "z": -3,
      "name": "Nat20_Force_Empty"
    },
    {
      "x": -7,
      "y": 13,
      "z": -3,
      "name": "Nat20_Force_Empty"
    },
    {
      "x": -7,
      "y": 14,
      "z": -3,
      "name": "Nat20_Force_Empty"
    },
    {
      "x": -7,
      "y": 15,
      "z": -3,
      "name": "Nat20_Force_Empty"
    },
    {
      "x": -7,
      "y": 16,
      "z": -3,
      "name": "Nat20_Force_Empty"
    },
    {
      "x": -7,
      "y": 17,
      "z": -3,
      "name": "Nat20_Force_Empty"
    },
    {
      "x": -7,
      "y": 18,
      "z": -3,
      "name": "Nat20_Force_Empty"
    },
    {
      "x": -7,
      "y": 19,
      "z": -3,
      "name": "Nat20_Force_Empty"
    },
    {
      "x": -7,
      "y": 0,
      "z": -2,
      "name": "Soil_Dirt_Dry"
    },
    {
      "x": -7,
      "y": 1,
      "z": -2,
      "name": "Nat20_Force_Empty"
    },
    {
      "x": -7,
      "y": 2,
      "z": -2,
      "name": "Nat20_Force_Empty"
    },
    {
      "x": -7,
      "y": 3,
      "z": -2,
      "name": "Nat20_Force_Empty"
    },
    {
      "x": -7,
      "y": 4,
      "z": -2,
      "name": "Nat20_Force_Empty"
    },
    {
      "x": -7,
      "y": 5,
      "z": -2,
      "name": "Nat20_Force_Empty"
    },
    {
      "x": -7,
      "y": 6,
      "z": -2,
      "name": "Nat20_Force_Empty"
    },
    {
      "x": -7,
      "y": 7,
      "z": -2,
      "name": "Nat20_Force_Empty"
    },
    {
      "x": -7,
      "y": 8,
      "z": -2,
      "name": "Nat20_Force_Empty"
    },
    {
      "x": -7,
      "y": 9,
      "z": -2,
      "name": "Nat20_Force_Empty"
    },
    {
      "x": -7,
      "y": 10,
      "z": -2,
      "name": "Nat20_Force_Empty"
    },
    {
      "x": -7,
      "y": 11,
      "z": -2,
      "name": "Nat20_Force_Empty"
    },
    {
      "x": -7,
      "y": 12,
      "z": -2,
      "name": "Nat20_Force_Empty"
    },
    {
      "x": -7,
      "y": 13,
      "z": -2,
      "name": "Nat20_Force_Empty"
    },
    {
      "x": -7,
      "y": 14,
      "z": -2,
      "name": "Nat20_Force_Empty"
    },
    {
      "x": -7,
      "y": 15,
      "z": -2,
      "name": "Nat20_Force_Empty"
    },
    {
      "x": -7,
      "y": 16,
      "z": -2,
      "name": "Nat20_Force_Empty"
    },
    {
      "x": -7,
      "y": 17,
      "z": -2,
      "name": "Nat20_Force_Empty"
    },
    {
      "x": -7,
      "y": 18,
      "z": -2,
      "name": "Nat20_Force_Empty"
    },
    {
      "x": -7,
      "y": 19,
      "z": -2,
      "name": "Nat20_Force_Empty"
    },
    {
      "x": -7,
      "y": 0,
      "z": -1,
      "name": "Soil_Dirt_Dry"
    },
    {
      "x": -7,
      "y": 1,
      "z": -1,
      "name": "Nat20_Force_Empty"
    },
    {
      "x": -7,
      "y": 2,
      "z": -1,
      "name": "Nat20_Force_Empty"
    },
    {
      "x": -7,
      "y": 3,
      "z": -1,
      "name": "Nat20_Force_Empty"
    },
    {
      "x": -7,
      "y": 4,
      "z": -1,
      "name": "Nat20_Force_Empty"
    },
    {
      "x": -7,
      "y": 5,
      "z": -1,
      "name": "Nat20_Force_Empty"
    },
    {
      "x": -7,
      "y": 6,
      "z": -1,
      "name": "Nat20_Force_Empty"
    },
    {
      "x": -7,
      "y": 7,
      "z": -1,
      "name": "Nat20_Force_Empty"
    },
    {
      "x": -7,
      "y": 8,
      "z": -1,
      "name": "Nat20_Force_Empty"
    },
    {
      "x": -7,
      "y": 9,
      "z": -1,
      "name": "Nat20_Force_Empty"
    },
    {
      "x": -7,
      "y": 10,
      "z": -1,
      "name": "Nat20_Force_Empty"
    },
    {
      "x": -7,
      "y": 11,
      "z": -1,
      "name": "Nat20_Force_Empty"
    },
    {
      "x": -7,
      "y": 12,
      "z": -1,
      "name": "Nat20_Force_Empty"
    },
    {
      "x": -7,
      "y": 13,
      "z": -1,
      "name": "Nat20_Force_Empty"
    },
    {
      "x": -7,
      "y": 14,
      "z": -1,
      "name": "Nat20_Force_Empty"
    },
    {
      "x": -7,
      "y": 15,
      "z": -1,
      "name": "Nat20_Force_Empty"
    },
    {
      "x": -7,
      "y": 16,
      "z": -1,
      "name": "Nat20_Force_Empty"
    },
    {
      "x": -7,
      "y": 17,
      "z": -1,
      "name": "Nat20_Force_Empty"
    },
    {
      "x": -7,
      "y": 18,
      "z": -1,
      "name": "Nat20_Force_Empty"
    },
    {
      "x": -7,
      "y": 19,
      "z": -1,
      "name": "Nat20_Force_Empty"
    },
    {
      "x": -7,
      "y": 0,
      "z": 0,
      "name": "Soil_Dirt_Dry"
    },
    {
      "x": -7,
      "y": 1,
      "z": 0,
      "name": "Nat20_Force_Empty"
    },
    {
      "x": -7,
      "y": 2,
      "z": 0,
      "name": "Nat20_Force_Empty"
    },
    {
      "x": -7,
      "y": 3,
      "z": 0,
      "name": "Nat20_Force_Empty"
    },
    {
      "x": -7,
      "y": 4,
      "z": 0,
      "name": "Nat20_Force_Empty"
    },
    {
      "x": -7,
      "y": 5,
      "z": 0,
      "name": "Nat20_Force_Empty"
    },
    {
      "x": -7,
      "y": 6,
      "z": 0,
      "name": "Nat20_Force_Empty"
    },
    {
      "x": -7,
      "y": 7,
      "z": 0,
      "name": "Nat20_Force_Empty"
    },
    {
      "x": -7,
      "y": 8,
      "z": 0,
      "name": "Nat20_Force_Empty"
    },
    {
      "x": -7,
      "y": 9,
      "z": 0,
      "name": "Nat20_Force_Empty"
    },
    {
      "x": -7,
      "y": 10,
      "z": 0,
      "name": "Nat20_Force_Empty"
    },
    {
      "x": -7,
      "y": 11,
      "z": 0,
      "name": "Nat20_Force_Empty"
    },
    {
      "x": -7,
      "y": 12,
      "z": 0,
      "name": "Nat20_Force_Empty"
    },
    {
      "x": -7,
      "y": 13,
      "z": 0,
      "name": "Nat20_Force_Empty"
    },
    {
      "x": -7,
      "y": 14,
      "z": 0,
      "name": "Nat20_Force_Empty"
    },
    {
      "x": -7,
      "y": 15,
      "z": 0,
      "name": "Nat20_Force_Empty"
    },
    {
      "x": -7,
      "y": 16,
      "z": 0,
      "name": "Nat20_Force_Empty"
    },
    {
      "x": -7,
      "y": 17,
      "z": 0,
      "name": "Nat20_Force_Empty"
    },
    {
      "x": -7,
      "y": 18,
      "z": 0,
      "name": "Nat20_Force_Empty"
    },
    {
      "x": -7,
      "y": 19,
      "z": 0,
      "name": "Nat20_Force_Empty"
    },
    {
      "x": -7,
      "y": 1,
      "z": 1,
      "name": "Nat20_Force_Empty"
    },
    {
      "x": -7,
      "y": 2,
      "z": 1,
      "name": "Nat20_Force_Empty"
    },
    {
      "x": -7,
      "y": 3,
      "z": 1,
      "name": "Nat20_Force_Empty"
    },
    {
      "x": -7,
      "y": 4,
      "z": 1,
      "name": "Nat20_Force_Empty"
    },
    {
      "x": -7,
      "y": 5,
      "z": 1,
      "name": "Nat20_Force_Empty"
    },
    {
      "x": -7,
      "y": 6,
      "z": 1,
      "name": "Nat20_Force_Empty"
    },
    {
      "x": -7,
      "y": 7,
      "z": 1,
      "name": "Nat20_Force_Empty"
    },
    {
      "x": -7,
      "y": 8,
      "z": 1,
      "name": "Nat20_Force_Empty"
    },
    {
      "x": -7,
      "y": 9,
      "z": 1,
      "name": "Nat20_Force_Empty"
    },
    {
      "x": -7,
      "y": 10,
      "z": 1,
      "name": "Nat20_Force_Empty"
    },
    {
      "x": -7,
      "y": 11,
      "z": 1,
      "name": "Nat20_Force_Empty"
    },
    {
      "x": -7,
      "y": 12,
      "z": 1,
      "name": "Nat20_Force_Empty"
    },
    {
      "x": -7,
      "y": 13,
      "z": 1,
      "name": "Nat20_Force_Empty"
    },
    {
      "x": -7,
      "y": 14,
      "z": 1,
      "name": "Nat20_Force_Empty"
    },
    {
      "x": -7,
      "y": 15,
      "z": 1,
      "name": "Nat20_Force_Empty"
    },
    {
      "x": -7,
      "y": 16,
      "z": 1,
      "name": "Nat20_Force_Empty"
    },
    {
      "x": -7,
      "y": 17,
      "z": 1,
      "name": "Nat20_Force_Empty"
    },
    {
      "x": -7,
      "y": 18,
      "z": 1,
      "name": "Nat20_Force_Empty"
    },
    {
      "x": -7,
      "y": 19,
      "z": 1,
      "name": "Nat20_Force_Empty"
    },
    {
      "x": -7,
      "y": 1,
      "z": 2,
      "name": "Nat20_Force_Empty"
    },
    {
      "x": -7,
      "y": 2,
      "z": 2,
      "name": "Nat20_Force_Empty"
    },
    {
      "x": -7,
      "y": 3,
      "z": 2,
      "name": "Nat20_Force_Empty"
    },
    {
      "x": -7,
      "y": 4,
      "z": 2,
      "name": "Nat20_Force_Empty"
    },
    {
      "x": -7,
      "y": 5,
      "z": 2,
      "name": "Nat20_Force_Empty"
    },
    {
      "x": -7,
      "y": 6,
      "z": 2,
      "name": "Nat20_Force_Empty"
    },
    {
      "x": -7,
      "y": 7,
      "z": 2,
      "name": "Nat20_Force_Empty"
    },
    {
      "x": -7,
      "y": 8,
      "z": 2,
      "name": "Nat20_Force_Empty"
    },
    {
      "x": -7,
      "y": 9,
      "z": 2,
      "name": "Nat20_Force_Empty"
    },
    {
      "x": -7,
      "y": 10,
      "z": 2,
      "name": "Nat20_Force_Empty"
    },
    {
      "x": -7,
      "y": 11,
      "z": 2,
      "name": "Nat20_Force_Empty"
    },
    {
      "x": -7,
      "y": 12,
      "z": 2,
      "name": "Nat20_Force_Empty"
    },
    {
      "x": -7,
      "y": 13,
      "z": 2,
      "name": "Nat20_Force_Empty"
    },
    {
      "x": -7,
      "y": 14,
      "z": 2,
      "name": "Nat20_Force_Empty"
    },
    {
      "x": -7,
      "y": 15,
      "z": 2,
      "name": "Nat20_Force_Empty"
    },
    {
      "x": -7,
      "y": 16,
      "z": 2,
      "name": "Nat20_Force_Empty"
    },
    {
      "x": -7,
      "y": 17,
      "z": 2,
      "name": "Nat20_Force_Empty"
    },
    {
      "x": -7,
      "y": 18,
      "z": 2,
      "name": "Nat20_Force_Empty"
    },
    {
      "x": -7,
      "y": 19,
      "z": 2,
      "name": "Nat20_Force_Empty"
    },
    {
      "x": -7,
      "y": 1,
      "z": 3,
      "name": "Nat20_Force_Empty"
    },
    {
      "x": -7,
      "y": 2,
      "z": 3,
      "name": "Nat20_Force_Empty"
    },
    {
      "x": -7,
      "y": 3,
      "z": 3,
      "name": "Nat20_Force_Empty"
    },
    {
      "x": -7,
      "y": 4,
      "z": 3,
      "name": "Nat20_Force_Empty"
    },
    {
      "x": -7,
      "y": 5,
      "z": 3,
      "name": "Nat20_Force_Empty"
    },
    {
      "x": -7,
      "y": 6,
      "z": 3,
      "name": "Nat20_Force_Empty"
    },
    {
      "x": -7,
      "y": 7,
      "z": 3,
      "name": "Nat20_Force_Empty"
    },
    {
      "x": -7,
      "y": 8,
      "z": 3,
      "name": "Nat20_Force_Empty"
    },
    {
      "x": -7,
      "y": 9,
      "z": 3,
      "name": "Nat20_Force_Empty"
    },
    {
      "x": -7,
      "y": 10,
      "z": 3,
      "name": "Nat20_Force_Empty"
    },
    {
      "x": -7,
      "y": 11,
      "z": 3,
      "name": "Nat20_Force_Empty"
    },
    {
      "x": -7,
      "y": 12,
      "z": 3,
      "name": "Nat20_Force_Empty"
    },
    {
      "x": -7,
      "y": 13,
      "z": 3,
      "name": "Nat20_Force_Empty"
    },
    {
      "x": -7,
      "y": 14,
      "z": 3,
      "name": "Nat20_Force_Empty"
    },
    {
      "x": -7,
      "y": 15,
      "z": 3,
      "name": "Nat20_Force_Empty"
    },
    {
      "x": -7,
      "y": 16,
      "z": 3,
      "name": "Nat20_Force_Empty"
    },
    {
      "x": -7,
      "y": 17,
      "z": 3,
      "name": "Nat20_Force_Empty"
    },
    {
      "x": -7,
      "y": 18,
      "z": 3,
      "name": "Nat20_Force_Empty"
    },
    {
      "x": -7,
      "y": 19,
      "z": 3,
      "name": "Nat20_Force_Empty"
    },
    {
      "x": -7,
      "y": 1,
      "z": 4,
      "name": "Nat20_Force_Empty"
    },
    {
      "x": -7,
      "y": 2,
      "z": 4,
      "name": "Nat20_Force_Empty"
    },
    {
      "x": -7,
      "y": 3,
      "z": 4,
      "name": "Nat20_Force_Empty"
    },
    {
      "x": -7,
      "y": 4,
      "z": 4,
      "name": "Nat20_Force_Empty"
    },
    {
      "x": -7,
      "y": 5,
      "z": 4,
      "name": "Nat20_Force_Empty"
    },
    {
      "x": -7,
      "y": 6,
      "z": 4,
      "name": "Nat20_Force_Empty"
    },
    {
      "x": -7,
      "y": 7,
      "z": 4,
      "name": "Nat20_Force_Empty"
    },
    {
      "x": -7,
      "y": 8,
      "z": 4,
      "name": "Nat20_Force_Empty"
    },
    {
      "x": -7,
      "y": 9,
      "z": 4,
      "name": "Nat20_Force_Empty"
    },
    {
      "x": -7,
      "y": 10,
      "z": 4,
      "name": "Nat20_Force_Empty"
    },
    {
      "x": -7,
      "y": 11,
      "z": 4,
      "name": "Nat20_Force_Empty"
    },
    {
      "x": -7,
      "y": 12,
      "z": 4,
      "name": "Nat20_Force_Empty"
    },
    {
      "x": -7,
      "y": 13,
      "z": 4,
      "name": "Nat20_Force_Empty"
    },
    {
      "x": -7,
      "y": 14,
      "z": 4,
      "name": "Nat20_Force_Empty"
    },
    {
      "x": -7,
      "y": 15,
      "z": 4,
      "name": "Nat20_Force_Empty"
    },
    {
      "x": -7,
      "y": 16,
      "z": 4,
      "name": "Nat20_Force_Empty"
    },
    {
      "x": -7,
      "y": 17,
      "z": 4,
      "name": "Nat20_Force_Empty"
    },
    {
      "x": -7,
      "y": 18,
      "z": 4,
      "name": "Nat20_Force_Empty"
    },
    {
      "x": -7,
      "y": 19,
      "z": 4,
      "name": "Nat20_Force_Empty"
    },
    {
      "x": -7,
      "y": 0,
      "z": 5,
      "name": "Soil_Dirt_Dry"
    },
    {
      "x": -7,
      "y": 1,
      "z": 5,
      "name": "Furniture_Village_Crate",
      "components": {
        "Components": {
          "ItemContainerBlock": {
            "ItemContainer": {
              "Capacity": 20,
              "Items": {
                "0": {
                  "Id": "Ingredient_Hide_Medium",
                  "Quantity": 2,
                  "Durability": 0.0,
                  "MaxDurability": 0.0,
                  "OverrideDroppedItemAnimation": false
                },
                "1": {
                  "Id": "Ingredient_Charcoal",
                  "Quantity": 5,
                  "Durability": 0.0,
                  "MaxDurability": 0.0,
                  "OverrideDroppedItemAnimation": false
                }
              }
            },
            "Capacity": 20
          }
        }
      }
    },
    {
      "x": -7,
      "y": 2,
      "z": 5,
      "name": "Furniture_Village_Crate",
      "components": {
        "Components": {
          "ItemContainerBlock": {
            "ItemContainer": {
              "Capacity": 20,
              "Items": {
                "0": {
                  "Id": "Ingredient_Hide_Medium",
                  "Quantity": 2,
                  "Durability": 0.0,
                  "MaxDurability": 0.0,
                  "OverrideDroppedItemAnimation": false
                }
              }
            },
            "Capacity": 20
          }
        }
      }
    },
    {
      "x": -7,
      "y": 3,
      "z": 5,
      "name": "Nat20_Force_Empty"
    },
    {
      "x": -7,
      "y": 4,
      "z": 5,
      "name": "Nat20_Force_Empty"
    },
    {
      "x": -7,
      "y": 5,
      "z": 5,
      "name": "Nat20_Force_Empty"
    },
    {
      "x": -7,
      "y": 6,
      "z": 5,
      "name": "Nat20_Force_Empty"
    },
    {
      "x": -7,
      "y": 7,
      "z": 5,
      "name": "Nat20_Force_Empty"
    },
    {
      "x": -7,
      "y": 8,
      "z": 5,
      "name": "Nat20_Force_Empty"
    },
    {
      "x": -7,
      "y": 9,
      "z": 5,
      "name": "Nat20_Force_Empty"
    },
    {
      "x": -7,
      "y": 10,
      "z": 5,
      "name": "Nat20_Force_Empty"
    },
    {
      "x": -7,
      "y": 11,
      "z": 5,
      "name": "Nat20_Force_Empty"
    },
    {
      "x": -7,
      "y": 12,
      "z": 5,
      "name": "Nat20_Force_Empty"
    },
    {
      "x": -7,
      "y": 13,
      "z": 5,
      "name": "Nat20_Force_Empty"
    },
    {
      "x": -7,
      "y": 14,
      "z": 5,
      "name": "Nat20_Force_Empty"
    },
    {
      "x": -7,
      "y": 15,
      "z": 5,
      "name": "Nat20_Force_Empty"
    },
    {
      "x": -7,
      "y": 16,
      "z": 5,
      "name": "Nat20_Force_Empty"
    },
    {
      "x": -7,
      "y": 17,
      "z": 5,
      "name": "Nat20_Force_Empty"
    },
    {
      "x": -7,
      "y": 18,
      "z": 5,
      "name": "Nat20_Force_Empty"
    },
    {
      "x": -7,
      "y": 19,
      "z": 5,
      "name": "Nat20_Force_Empty"
    },
    {
      "x": -7,
      "y": 0,
      "z": 6,
      "name": "Soil_Dirt_Dry"
    },
    {
      "x": -7,
      "y": 1,
      "z": 6,
      "name": "Furniture_Village_Crate",
      "components": {
        "Components": {
          "ItemContainerBlock": {
            "ItemContainer": {
              "Capacity": 20,
              "Items": {
                "0": {
                  "Id": "Ingredient_Hide_Medium",
                  "Quantity": 2,
                  "Durability": 0.0,
                  "MaxDurability": 0.0,
                  "OverrideDroppedItemAnimation": false
                },
                "1": {
                  "Id": "Ingredient_Charcoal",
                  "Quantity": 5,
                  "Durability": 0.0,
                  "MaxDurability": 0.0,
                  "OverrideDroppedItemAnimation": false
                },
                "2": {
                  "Id": "Ore_Thorium",
                  "Quantity": 5,
                  "Durability": 0.0,
                  "MaxDurability": 0.0,
                  "OverrideDroppedItemAnimation": false
                }
              }
            },
            "Capacity": 20
          }
        }
      }
    },
    {
      "x": -7,
      "y": 2,
      "z": 6,
      "name": "Nat20_Force_Empty"
    },
    {
      "x": -7,
      "y": 3,
      "z": 6,
      "name": "Nat20_Force_Empty"
    },
    {
      "x": -7,
      "y": 4,
      "z": 6,
      "name": "Nat20_Force_Empty"
    },
    {
      "x": -7,
      "y": 5,
      "z": 6,
      "name": "Nat20_Force_Empty"
    },
    {
      "x": -7,
      "y": 6,
      "z": 6,
      "name": "Nat20_Force_Empty"
    },
    {
      "x": -7,
      "y": 7,
      "z": 6,
      "name": "Nat20_Force_Empty"
    },
    {
      "x": -7,
      "y": 8,
      "z": 6,
      "name": "Nat20_Force_Empty"
    },
    {
      "x": -7,
      "y": 9,
      "z": 6,
      "name": "Nat20_Force_Empty"
    },
    {
      "x": -7,
      "y": 10,
      "z": 6,
      "name": "Nat20_Force_Empty"
    },
    {
      "x": -7,
      "y": 11,
      "z": 6,
      "name": "Nat20_Force_Empty"
    },
    {
      "x": -7,
      "y": 12,
      "z": 6,
      "name": "Nat20_Force_Empty"
    },
    {
      "x": -7,
      "y": 13,
      "z": 6,
      "name": "Nat20_Force_Empty"
    },
    {
      "x": -7,
      "y": 14,
      "z": 6,
      "name": "Nat20_Force_Empty"
    },
    {
      "x": -7,
      "y": 15,
      "z": 6,
      "name": "Nat20_Force_Empty"
    },
    {
      "x": -7,
      "y": 16,
      "z": 6,
      "name": "Nat20_Force_Empty"
    },
    {
      "x": -7,
      "y": 17,
      "z": 6,
      "name": "Nat20_Force_Empty"
    },
    {
      "x": -7,
      "y": 18,
      "z": 6,
      "name": "Nat20_Force_Empty"
    },
    {
      "x": -7,
      "y": 19,
      "z": 6,
      "name": "Nat20_Force_Empty"
    },
    {
      "x": -7,
      "y": 0,
      "z": 7,
      "name": "Soil_Dirt_Dry"
    },
    {
      "x": -7,
      "y": 1,
      "z": 7,
      "name": "Nat20_Force_Empty"
    },
    {
      "x": -7,
      "y": 2,
      "z": 7,
      "name": "Nat20_Force_Empty"
    },
    {
      "x": -7,
      "y": 3,
      "z": 7,
      "name": "Nat20_Force_Empty"
    },
    {
      "x": -7,
      "y": 4,
      "z": 7,
      "name": "Nat20_Force_Empty"
    },
    {
      "x": -7,
      "y": 5,
      "z": 7,
      "name": "Nat20_Force_Empty"
    },
    {
      "x": -7,
      "y": 6,
      "z": 7,
      "name": "Nat20_Force_Empty"
    },
    {
      "x": -7,
      "y": 7,
      "z": 7,
      "name": "Nat20_Force_Empty"
    },
    {
      "x": -7,
      "y": 8,
      "z": 7,
      "name": "Nat20_Force_Empty"
    },
    {
      "x": -7,
      "y": 9,
      "z": 7,
      "name": "Nat20_Force_Empty"
    },
    {
      "x": -7,
      "y": 10,
      "z": 7,
      "name": "Nat20_Force_Empty"
    },
    {
      "x": -7,
      "y": 11,
      "z": 7,
      "name": "Nat20_Force_Empty"
    },
    {
      "x": -7,
      "y": 12,
      "z": 7,
      "name": "Nat20_Force_Empty"
    },
    {
      "x": -7,
      "y": 13,
      "z": 7,
      "name": "Nat20_Force_Empty"
    },
    {
      "x": -7,
      "y": 14,
      "z": 7,
      "name": "Nat20_Force_Empty"
    },
    {
      "x": -7,
      "y": 15,
      "z": 7,
      "name": "Nat20_Force_Empty"
    },
    {
      "x": -7,
      "y": 16,
      "z": 7,
      "name": "Nat20_Force_Empty"
    },
    {
      "x": -7,
      "y": 17,
      "z": 7,
      "name": "Nat20_Force_Empty"
    },
    {
      "x": -7,
      "y": 18,
      "z": 7,
      "name": "Nat20_Force_Empty"
    },
    {
      "x": -7,
      "y": 19,
      "z": 7,
      "name": "Nat20_Force_Empty"
    },
    {
      "x": -7,
      "y": 0,
      "z": 8,
      "name": "Soil_Dirt_Dry"
    },
    {
      "x": -7,
      "y": 1,
      "z": 8,
      "name": "Nat20_Direction"
    },
    {
      "x": -7,
      "y": 2,
      "z": 8,
      "name": "Nat20_Force_Empty"
    },
    {
      "x": -7,
      "y": 3,
      "z": 8,
      "name": "Nat20_Force_Empty"
    },
    {
      "x": -7,
      "y": 4,
      "z": 8,
      "name": "Nat20_Force_Empty"
    },
    {
      "x": -7,
      "y": 5,
      "z": 8,
      "name": "Nat20_Force_Empty"
    },
    {
      "x": -7,
      "y": 6,
      "z": 8,
      "name": "Nat20_Force_Empty"
    },
    {
      "x": -7,
      "y": 7,
      "z": 8,
      "name": "Nat20_Force_Empty"
    },
    {
      "x": -7,
      "y": 8,
      "z": 8,
      "name": "Nat20_Force_Empty"
    },
    {
      "x": -7,
      "y": 9,
      "z": 8,
      "name": "Nat20_Force_Empty"
    },
    {
      "x": -7,
      "y": 10,
      "z": 8,
      "name": "Nat20_Force_Empty"
    },
    {
      "x": -7,
      "y": 11,
      "z": 8,
      "name": "Nat20_Force_Empty"
    },
    {
      "x": -7,
      "y": 12,
      "z": 8,
      "name": "Nat20_Force_Empty"
    },
    {
      "x": -7,
      "y": 13,
      "z": 8,
      "name": "Nat20_Force_Empty"
    },
    {
      "x": -7,
      "y": 14,
      "z": 8,
      "name": "Nat20_Force_Empty"
    },
    {
      "x": -7,
      "y": 15,
      "z": 8,
      "name": "Nat20_Force_Empty"
    },
    {
      "x": -7,
      "y": 16,
      "z": 8,
      "name": "Nat20_Force_Empty"
    },
    {
      "x": -7,
      "y": 17,
      "z": 8,
      "name": "Nat20_Force_Empty"
    },
    {
      "x": -7,
      "y": 18,
      "z": 8,
      "name": "Nat20_Force_Empty"
    },
    {
      "x": -7,
      "y": 19,
      "z": 8,
      "name": "Nat20_Force_Empty"
    },
    {
      "x": -7,
      "y": 1,
      "z": 9,
      "name": "Nat20_Force_Empty"
    },
    {
      "x": -7,
      "y": 2,
      "z": 9,
      "name": "Nat20_Force_Empty"
    },
    {
      "x": -7,
      "y": 3,
      "z": 9,
      "name": "Nat20_Force_Empty"
    },
    {
      "x": -7,
      "y": 4,
      "z": 9,
      "name": "Nat20_Force_Empty"
    },
    {
      "x": -7,
      "y": 5,
      "z": 9,
      "name": "Nat20_Force_Empty"
    },
    {
      "x": -7,
      "y": 6,
      "z": 9,
      "name": "Nat20_Force_Empty"
    },
    {
      "x": -7,
      "y": 7,
      "z": 9,
      "name": "Nat20_Force_Empty"
    },
    {
      "x": -7,
      "y": 8,
      "z": 9,
      "name": "Nat20_Force_Empty"
    },
    {
      "x": -7,
      "y": 9,
      "z": 9,
      "name": "Nat20_Force_Empty"
    },
    {
      "x": -7,
      "y": 10,
      "z": 9,
      "name": "Nat20_Force_Empty"
    },
    {
      "x": -7,
      "y": 11,
      "z": 9,
      "name": "Nat20_Force_Empty"
    },
    {
      "x": -7,
      "y": 12,
      "z": 9,
      "name": "Nat20_Force_Empty"
    },
    {
      "x": -7,
      "y": 13,
      "z": 9,
      "name": "Nat20_Force_Empty"
    },
    {
      "x": -7,
      "y": 14,
      "z": 9,
      "name": "Nat20_Force_Empty"
    },
    {
      "x": -7,
      "y": 15,
      "z": 9,
      "name": "Nat20_Force_Empty"
    },
    {
      "x": -7,
      "y": 16,
      "z": 9,
      "name": "Nat20_Force_Empty"
    },
    {
      "x": -7,
      "y": 17,
      "z": 9,
      "name": "Nat20_Force_Empty"
    },
    {
      "x": -7,
      "y": 18,
      "z": 9,
      "name": "Nat20_Force_Empty"
    },
    {
      "x": -7,
      "y": 19,
      "z": 9,
      "name": "Nat20_Force_Empty"
    },
    {
      "x": -7,
      "y": 1,
      "z": 10,
      "name": "Nat20_Force_Empty"
    },
    {
      "x": -7,
      "y": 2,
      "z": 10,
      "name": "Nat20_Force_Empty"
    },
    {
      "x": -7,
      "y": 3,
      "z": 10,
      "name": "Nat20_Force_Empty"
    },
    {
      "x": -7,
      "y": 4,
      "z": 10,
      "name": "Nat20_Force_Empty"
    },
    {
      "x": -7,
      "y": 5,
      "z": 10,
      "name": "Nat20_Force_Empty"
    },
    {
      "x": -7,
      "y": 6,
      "z": 10,
      "name": "Nat20_Force_Empty"
    },
    {
      "x": -7,
      "y": 7,
      "z": 10,
      "name": "Nat20_Force_Empty"
    },
    {
      "x": -7,
      "y": 8,
      "z": 10,
      "name": "Nat20_Force_Empty"
    },
    {
      "x": -7,
      "y": 9,
      "z": 10,
      "name": "Nat20_Force_Empty"
    },
    {
      "x": -7,
      "y": 10,
      "z": 10,
      "name": "Nat20_Force_Empty"
    },
    {
      "x": -7,
      "y": 11,
      "z": 10,
      "name": "Nat20_Force_Empty"
    },
    {
      "x": -7,
      "y": 12,
      "z": 10,
      "name": "Nat20_Force_Empty"
    },
    {
      "x": -7,
      "y": 13,
      "z": 10,
      "name": "Nat20_Force_Empty"
    },
    {
      "x": -7,
      "y": 14,
      "z": 10,
      "name": "Nat20_Force_Empty"
    },
    {
      "x": -7,
      "y": 15,
      "z": 10,
      "name": "Nat20_Force_Empty"
    },
    {
      "x": -7,
      "y": 16,
      "z": 10,
      "name": "Nat20_Force_Empty"
    },
    {
      "x": -7,
      "y": 17,
      "z": 10,
      "name": "Nat20_Force_Empty"
    },
    {
      "x": -7,
      "y": 18,
      "z": 10,
      "name": "Nat20_Force_Empty"
    },
    {
      "x": -7,
      "y": 19,
      "z": 10,
      "name": "Nat20_Force_Empty"
    },
    {
      "x": -7,
      "y": 1,
      "z": 11,
      "name": "Nat20_Force_Empty"
    },
    {
      "x": -7,
      "y": 2,
      "z": 11,
      "name": "Nat20_Force_Empty"
    },
    {
      "x": -7,
      "y": 3,
      "z": 11,
      "name": "Nat20_Force_Empty"
    },
    {
      "x": -7,
      "y": 4,
      "z": 11,
      "name": "Nat20_Force_Empty"
    },
    {
      "x": -7,
      "y": 5,
      "z": 11,
      "name": "Nat20_Force_Empty"
    },
    {
      "x": -7,
      "y": 6,
      "z": 11,
      "name": "Nat20_Force_Empty"
    },
    {
      "x": -7,
      "y": 7,
      "z": 11,
      "name": "Nat20_Force_Empty"
    },
    {
      "x": -7,
      "y": 8,
      "z": 11,
      "name": "Nat20_Force_Empty"
    },
    {
      "x": -7,
      "y": 9,
      "z": 11,
      "name": "Nat20_Force_Empty"
    },
    {
      "x": -7,
      "y": 10,
      "z": 11,
      "name": "Nat20_Force_Empty"
    },
    {
      "x": -7,
      "y": 11,
      "z": 11,
      "name": "Nat20_Force_Empty"
    },
    {
      "x": -7,
      "y": 12,
      "z": 11,
      "name": "Nat20_Force_Empty"
    },
    {
      "x": -7,
      "y": 13,
      "z": 11,
      "name": "Nat20_Force_Empty"
    },
    {
      "x": -7,
      "y": 14,
      "z": 11,
      "name": "Nat20_Force_Empty"
    },
    {
      "x": -7,
      "y": 15,
      "z": 11,
      "name": "Nat20_Force_Empty"
    },
    {
      "x": -7,
      "y": 16,
      "z": 11,
      "name": "Nat20_Force_Empty"
    },
    {
      "x": -7,
      "y": 17,
      "z": 11,
      "name": "Nat20_Force_Empty"
    },
    {
      "x": -7,
      "y": 18,
      "z": 11,
      "name": "Nat20_Force_Empty"
    },
    {
      "x": -7,
      "y": 19,
      "z": 11,
      "name": "Nat20_Force_Empty"
    },
    {
      "x": -6,
      "y": 1,
      "z": -10,
      "name": "Nat20_Force_Empty"
    },
    {
      "x": -6,
      "y": 2,
      "z": -10,
      "name": "Nat20_Force_Empty"
    },
    {
      "x": -6,
      "y": 3,
      "z": -10,
      "name": "Nat20_Force_Empty"
    },
    {
      "x": -6,
      "y": 4,
      "z": -10,
      "name": "Nat20_Force_Empty"
    },
    {
      "x": -6,
      "y": 5,
      "z": -10,
      "name": "Nat20_Force_Empty"
    },
    {
      "x": -6,
      "y": 6,
      "z": -10,
      "name": "Nat20_Force_Empty"
    },
    {
      "x": -6,
      "y": 7,
      "z": -10,
      "name": "Nat20_Force_Empty"
    },
    {
      "x": -6,
      "y": 8,
      "z": -10,
      "name": "Nat20_Force_Empty"
    },
    {
      "x": -6,
      "y": 9,
      "z": -10,
      "name": "Nat20_Force_Empty"
    },
    {
      "x": -6,
      "y": 10,
      "z": -10,
      "name": "Nat20_Force_Empty"
    },
    {
      "x": -6,
      "y": 11,
      "z": -10,
      "name": "Nat20_Force_Empty"
    },
    {
      "x": -6,
      "y": 12,
      "z": -10,
      "name": "Nat20_Force_Empty"
    },
    {
      "x": -6,
      "y": 13,
      "z": -10,
      "name": "Nat20_Force_Empty"
    },
    {
      "x": -6,
      "y": 14,
      "z": -10,
      "name": "Nat20_Force_Empty"
    },
    {
      "x": -6,
      "y": 15,
      "z": -10,
      "name": "Nat20_Force_Empty"
    },
    {
      "x": -6,
      "y": 16,
      "z": -10,
      "name": "Nat20_Force_Empty"
    },
    {
      "x": -6,
      "y": 17,
      "z": -10,
      "name": "Nat20_Force_Empty"
    },
    {
      "x": -6,
      "y": 18,
      "z": -10,
      "name": "Nat20_Force_Empty"
    },
    {
      "x": -6,
      "y": 19,
      "z": -10,
      "name": "Nat20_Force_Empty"
    },
    {
      "x": -6,
      "y": 1,
      "z": -9,
      "name": "Nat20_Force_Empty"
    },
    {
      "x": -6,
      "y": 2,
      "z": -9,
      "name": "Nat20_Force_Empty"
    },
    {
      "x": -6,
      "y": 3,
      "z": -9,
      "name": "Nat20_Force_Empty"
    },
    {
      "x": -6,
      "y": 4,
      "z": -9,
      "name": "Nat20_Force_Empty"
    },
    {
      "x": -6,
      "y": 5,
      "z": -9,
      "name": "Nat20_Force_Empty"
    },
    {
      "x": -6,
      "y": 6,
      "z": -9,
      "name": "Nat20_Force_Empty"
    },
    {
      "x": -6,
      "y": 7,
      "z": -9,
      "name": "Nat20_Force_Empty"
    },
    {
      "x": -6,
      "y": 8,
      "z": -9,
      "name": "Nat20_Force_Empty"
    },
    {
      "x": -6,
      "y": 9,
      "z": -9,
      "name": "Nat20_Force_Empty"
    },
    {
      "x": -6,
      "y": 10,
      "z": -9,
      "name": "Nat20_Force_Empty"
    },
    {
      "x": -6,
      "y": 11,
      "z": -9,
      "name": "Nat20_Force_Empty"
    },
    {
      "x": -6,
      "y": 12,
      "z": -9,
      "name": "Nat20_Force_Empty"
    },
    {
      "x": -6,
      "y": 13,
      "z": -9,
      "name": "Nat20_Force_Empty"
    },
    {
      "x": -6,
      "y": 14,
      "z": -9,
      "name": "Nat20_Force_Empty"
    },
    {
      "x": -6,
      "y": 15,
      "z": -9,
      "name": "Nat20_Force_Empty"
    },
    {
      "x": -6,
      "y": 16,
      "z": -9,
      "name": "Nat20_Force_Empty"
    },
    {
      "x": -6,
      "y": 17,
      "z": -9,
      "name": "Nat20_Force_Empty"
    },
    {
      "x": -6,
      "y": 18,
      "z": -9,
      "name": "Nat20_Force_Empty"
    },
    {
      "x": -6,
      "y": 19,
      "z": -9,
      "name": "Nat20_Force_Empty"
    },
    {
      "x": -6,
      "y": 0,
      "z": -8,
      "name": "Soil_Dirt_Dry"
    },
    {
      "x": -6,
      "y": 1,
      "z": -8,
      "name": "Nat20_Force_Empty"
    },
    {
      "x": -6,
      "y": 2,
      "z": -8,
      "name": "Nat20_Force_Empty"
    },
    {
      "x": -6,
      "y": 3,
      "z": -8,
      "name": "Nat20_Force_Empty"
    },
    {
      "x": -6,
      "y": 4,
      "z": -8,
      "name": "Nat20_Force_Empty"
    },
    {
      "x": -6,
      "y": 5,
      "z": -8,
      "name": "Nat20_Force_Empty"
    },
    {
      "x": -6,
      "y": 6,
      "z": -8,
      "name": "Nat20_Force_Empty"
    },
    {
      "x": -6,
      "y": 7,
      "z": -8,
      "name": "Nat20_Force_Empty"
    },
    {
      "x": -6,
      "y": 8,
      "z": -8,
      "name": "Nat20_Force_Empty"
    },
    {
      "x": -6,
      "y": 9,
      "z": -8,
      "name": "Nat20_Force_Empty"
    },
    {
      "x": -6,
      "y": 10,
      "z": -8,
      "name": "Nat20_Force_Empty"
    },
    {
      "x": -6,
      "y": 11,
      "z": -8,
      "name": "Nat20_Force_Empty"
    },
    {
      "x": -6,
      "y": 12,
      "z": -8,
      "name": "Nat20_Force_Empty"
    },
    {
      "x": -6,
      "y": 13,
      "z": -8,
      "name": "Nat20_Force_Empty"
    },
    {
      "x": -6,
      "y": 14,
      "z": -8,
      "name": "Nat20_Force_Empty"
    },
    {
      "x": -6,
      "y": 15,
      "z": -8,
      "name": "Nat20_Force_Empty"
    },
    {
      "x": -6,
      "y": 16,
      "z": -8,
      "name": "Nat20_Force_Empty"
    },
    {
      "x": -6,
      "y": 17,
      "z": -8,
      "name": "Nat20_Force_Empty"
    },
    {
      "x": -6,
      "y": 18,
      "z": -8,
      "name": "Nat20_Force_Empty"
    },
    {
      "x": -6,
      "y": 19,
      "z": -8,
      "name": "Nat20_Force_Empty"
    },
    {
      "x": -6,
      "y": 0,
      "z": -7,
      "name": "Soil_Dirt_Dry"
    },
    {
      "x": -6,
      "y": 1,
      "z": -7,
      "name": "Nat20_Force_Empty"
    },
    {
      "x": -6,
      "y": 2,
      "z": -7,
      "name": "Nat20_Force_Empty"
    },
    {
      "x": -6,
      "y": 3,
      "z": -7,
      "name": "Nat20_Force_Empty"
    },
    {
      "x": -6,
      "y": 4,
      "z": -7,
      "name": "Nat20_Force_Empty"
    },
    {
      "x": -6,
      "y": 5,
      "z": -7,
      "name": "Nat20_Force_Empty"
    },
    {
      "x": -6,
      "y": 6,
      "z": -7,
      "name": "Nat20_Force_Empty"
    },
    {
      "x": -6,
      "y": 7,
      "z": -7,
      "name": "Nat20_Force_Empty"
    },
    {
      "x": -6,
      "y": 8,
      "z": -7,
      "name": "Nat20_Force_Empty"
    },
    {
      "x": -6,
      "y": 9,
      "z": -7,
      "name": "Nat20_Force_Empty"
    },
    {
      "x": -6,
      "y": 10,
      "z": -7,
      "name": "Nat20_Force_Empty"
    },
    {
      "x": -6,
      "y": 11,
      "z": -7,
      "name": "Nat20_Force_Empty"
    },
    {
      "x": -6,
      "y": 12,
      "z": -7,
      "name": "Nat20_Force_Empty"
    },
    {
      "x": -6,
      "y": 13,
      "z": -7,
      "name": "Nat20_Force_Empty"
    },
    {
      "x": -6,
      "y": 14,
      "z": -7,
      "name": "Nat20_Force_Empty"
    },
    {
      "x": -6,
      "y": 15,
      "z": -7,
      "name": "Nat20_Force_Empty"
    },
    {
      "x": -6,
      "y": 16,
      "z": -7,
      "name": "Nat20_Force_Empty"
    },
    {
      "x": -6,
      "y": 17,
      "z": -7,
      "name": "Nat20_Force_Empty"
    },
    {
      "x": -6,
      "y": 18,
      "z": -7,
      "name": "Nat20_Force_Empty"
    },
    {
      "x": -6,
      "y": 19,
      "z": -7,
      "name": "Nat20_Force_Empty"
    },
    {
      "x": -6,
      "y": 0,
      "z": -6,
      "name": "Soil_Dirt_Dry"
    },
    {
      "x": -6,
      "y": 1,
      "z": -6,
      "name": "Furniture_Village_Crate",
      "components": {
        "Components": {
          "ItemContainerBlock": {
            "ItemContainer": {
              "Capacity": 20,
              "Items": {
                "0": {
                  "Id": "Ingredient_Hide_Medium",
                  "Quantity": 2,
                  "Durability": 0.0,
                  "MaxDurability": 0.0,
                  "OverrideDroppedItemAnimation": false
                },
                "1": {
                  "Id": "Ingredient_Charcoal",
                  "Quantity": 5,
                  "Durability": 0.0,
                  "MaxDurability": 0.0,
                  "OverrideDroppedItemAnimation": false
                }
              }
            },
            "Capacity": 20
          }
        }
      }
    },
    {
      "x": -6,
      "y": 2,
      "z": -6,
      "name": "Nat20_Force_Empty"
    },
    {
      "x": -6,
      "y": 3,
      "z": -6,
      "name": "Nat20_Force_Empty"
    },
    {
      "x": -6,
      "y": 4,
      "z": -6,
      "name": "Nat20_Force_Empty"
    },
    {
      "x": -6,
      "y": 5,
      "z": -6,
      "name": "Nat20_Force_Empty"
    },
    {
      "x": -6,
      "y": 6,
      "z": -6,
      "name": "Nat20_Force_Empty"
    },
    {
      "x": -6,
      "y": 7,
      "z": -6,
      "name": "Nat20_Force_Empty"
    },
    {
      "x": -6,
      "y": 8,
      "z": -6,
      "name": "Nat20_Force_Empty"
    },
    {
      "x": -6,
      "y": 9,
      "z": -6,
      "name": "Nat20_Force_Empty"
    },
    {
      "x": -6,
      "y": 10,
      "z": -6,
      "name": "Nat20_Force_Empty"
    },
    {
      "x": -6,
      "y": 11,
      "z": -6,
      "name": "Nat20_Force_Empty"
    },
    {
      "x": -6,
      "y": 12,
      "z": -6,
      "name": "Nat20_Force_Empty"
    },
    {
      "x": -6,
      "y": 13,
      "z": -6,
      "name": "Nat20_Force_Empty"
    },
    {
      "x": -6,
      "y": 14,
      "z": -6,
      "name": "Nat20_Force_Empty"
    },
    {
      "x": -6,
      "y": 15,
      "z": -6,
      "name": "Nat20_Force_Empty"
    },
    {
      "x": -6,
      "y": 16,
      "z": -6,
      "name": "Nat20_Force_Empty"
    },
    {
      "x": -6,
      "y": 17,
      "z": -6,
      "name": "Nat20_Force_Empty"
    },
    {
      "x": -6,
      "y": 18,
      "z": -6,
      "name": "Nat20_Force_Empty"
    },
    {
      "x": -6,
      "y": 19,
      "z": -6,
      "name": "Nat20_Force_Empty"
    },
    {
      "x": -6,
      "y": 0,
      "z": -5,
      "name": "Soil_Dirt_Dry"
    },
    {
      "x": -6,
      "y": 1,
      "z": -5,
      "name": "Nat20_Force_Empty"
    },
    {
      "x": -6,
      "y": 2,
      "z": -5,
      "name": "Nat20_Force_Empty"
    },
    {
      "x": -6,
      "y": 3,
      "z": -5,
      "name": "Cloth_Roof_Blue_Flap",
      "rotation": 3
    },
    {
      "x": -6,
      "y": 4,
      "z": -5,
      "name": "Nat20_Force_Empty"
    },
    {
      "x": -6,
      "y": 5,
      "z": -5,
      "name": "Nat20_Force_Empty"
    },
    {
      "x": -6,
      "y": 6,
      "z": -5,
      "name": "Nat20_Force_Empty"
    },
    {
      "x": -6,
      "y": 7,
      "z": -5,
      "name": "Nat20_Force_Empty"
    },
    {
      "x": -6,
      "y": 8,
      "z": -5,
      "name": "Nat20_Force_Empty"
    },
    {
      "x": -6,
      "y": 9,
      "z": -5,
      "name": "Nat20_Force_Empty"
    },
    {
      "x": -6,
      "y": 10,
      "z": -5,
      "name": "Nat20_Force_Empty"
    },
    {
      "x": -6,
      "y": 11,
      "z": -5,
      "name": "Nat20_Force_Empty"
    },
    {
      "x": -6,
      "y": 12,
      "z": -5,
      "name": "Nat20_Force_Empty"
    },
    {
      "x": -6,
      "y": 13,
      "z": -5,
      "name": "Nat20_Force_Empty"
    },
    {
      "x": -6,
      "y": 14,
      "z": -5,
      "name": "Nat20_Force_Empty"
    },
    {
      "x": -6,
      "y": 15,
      "z": -5,
      "name": "Nat20_Force_Empty"
    },
    {
      "x": -6,
      "y": 16,
      "z": -5,
      "name": "Nat20_Force_Empty"
    },
    {
      "x": -6,
      "y": 17,
      "z": -5,
      "name": "Nat20_Force_Empty"
    },
    {
      "x": -6,
      "y": 18,
      "z": -5,
      "name": "Nat20_Force_Empty"
    },
    {
      "x": -6,
      "y": 19,
      "z": -5,
      "name": "Nat20_Force_Empty"
    },
    {
      "x": -6,
      "y": 0,
      "z": -4,
      "name": "Soil_Dirt_Dry"
    },
    {
      "x": -6,
      "y": 1,
      "z": -4,
      "name": "Bench_WorkBench",
      "components": {
        "Components": {
          "BenchBlock": {
            "TierLevel": 1,
            "UpgradeItems": []
          }
        }
      },
      "rotation": 1
    },
    {
      "x": -6,
      "y": 2,
      "z": -4,
      "name": "Nat20_Force_Empty"
    },
    {
      "x": -6,
      "y": 3,
      "z": -4,
      "name": "Cloth_Roof_Blue_Vertical",
      "rotation": 3
    },
    {
      "x": -6,
      "y": 4,
      "z": -4,
      "name": "Nat20_Force_Empty"
    },
    {
      "x": -6,
      "y": 5,
      "z": -4,
      "name": "Nat20_Force_Empty"
    },
    {
      "x": -6,
      "y": 6,
      "z": -4,
      "name": "Nat20_Force_Empty"
    },
    {
      "x": -6,
      "y": 7,
      "z": -4,
      "name": "Nat20_Force_Empty"
    },
    {
      "x": -6,
      "y": 8,
      "z": -4,
      "name": "Nat20_Force_Empty"
    },
    {
      "x": -6,
      "y": 9,
      "z": -4,
      "name": "Nat20_Force_Empty"
    },
    {
      "x": -6,
      "y": 10,
      "z": -4,
      "name": "Nat20_Force_Empty"
    },
    {
      "x": -6,
      "y": 11,
      "z": -4,
      "name": "Nat20_Force_Empty"
    },
    {
      "x": -6,
      "y": 12,
      "z": -4,
      "name": "Nat20_Force_Empty"
    },
    {
      "x": -6,
      "y": 13,
      "z": -4,
      "name": "Nat20_Force_Empty"
    },
    {
      "x": -6,
      "y": 14,
      "z": -4,
      "name": "Nat20_Force_Empty"
    },
    {
      "x": -6,
      "y": 15,
      "z": -4,
      "name": "Nat20_Force_Empty"
    },
    {
      "x": -6,
      "y": 16,
      "z": -4,
      "name": "Nat20_Force_Empty"
    },
    {
      "x": -6,
      "y": 17,
      "z": -4,
      "name": "Nat20_Force_Empty"
    },
    {
      "x": -6,
      "y": 18,
      "z": -4,
      "name": "Nat20_Force_Empty"
    },
    {
      "x": -6,
      "y": 19,
      "z": -4,
      "name": "Nat20_Force_Empty"
    },
    {
      "x": -6,
      "y": 0,
      "z": -3,
      "name": "Soil_Dirt_Dry"
    },
    {
      "x": -6,
      "y": 1,
      "z": -3,
      "name": "Bench_WorkBench",
      "filler": 32,
      "rotation": 1
    },
    {
      "x": -6,
      "y": 2,
      "z": -3,
      "name": "Nat20_Force_Empty"
    },
    {
      "x": -6,
      "y": 3,
      "z": -3,
      "name": "Cloth_Roof_Blue_Flap",
      "rotation": 3
    },
    {
      "x": -6,
      "y": 4,
      "z": -3,
      "name": "Nat20_Force_Empty"
    },
    {
      "x": -6,
      "y": 5,
      "z": -3,
      "name": "Nat20_Force_Empty"
    },
    {
      "x": -6,
      "y": 6,
      "z": -3,
      "name": "Nat20_Force_Empty"
    },
    {
      "x": -6,
      "y": 7,
      "z": -3,
      "name": "Nat20_Force_Empty"
    },
    {
      "x": -6,
      "y": 8,
      "z": -3,
      "name": "Nat20_Force_Empty"
    },
    {
      "x": -6,
      "y": 9,
      "z": -3,
      "name": "Nat20_Force_Empty"
    },
    {
      "x": -6,
      "y": 10,
      "z": -3,
      "name": "Nat20_Force_Empty"
    },
    {
      "x": -6,
      "y": 11,
      "z": -3,
      "name": "Nat20_Force_Empty"
    },
    {
      "x": -6,
      "y": 12,
      "z": -3,
      "name": "Nat20_Force_Empty"
    },
    {
      "x": -6,
      "y": 13,
      "z": -3,
      "name": "Nat20_Force_Empty"
    },
    {
      "x": -6,
      "y": 14,
      "z": -3,
      "name": "Nat20_Force_Empty"
    },
    {
      "x": -6,
      "y": 15,
      "z": -3,
      "name": "Nat20_Force_Empty"
    },
    {
      "x": -6,
      "y": 16,
      "z": -3,
      "name": "Nat20_Force_Empty"
    },
    {
      "x": -6,
      "y": 17,
      "z": -3,
      "name": "Nat20_Force_Empty"
    },
    {
      "x": -6,
      "y": 18,
      "z": -3,
      "name": "Nat20_Force_Empty"
    },
    {
      "x": -6,
      "y": 19,
      "z": -3,
      "name": "Nat20_Force_Empty"
    },
    {
      "x": -6,
      "y": 0,
      "z": -2,
      "name": "Soil_Dirt_Dry"
    },
    {
      "x": -6,
      "y": 1,
      "z": -2,
      "name": "Furniture_Village_Counter",
      "rotation": 1
    },
    {
      "x": -6,
      "y": 2,
      "z": -2,
      "name": "Nat20_Force_Empty"
    },
    {
      "x": -6,
      "y": 3,
      "z": -2,
      "name": "Nat20_Force_Empty"
    },
    {
      "x": -6,
      "y": 4,
      "z": -2,
      "name": "Nat20_Force_Empty"
    },
    {
      "x": -6,
      "y": 5,
      "z": -2,
      "name": "Nat20_Force_Empty"
    },
    {
      "x": -6,
      "y": 6,
      "z": -2,
      "name": "Nat20_Force_Empty"
    },
    {
      "x": -6,
      "y": 7,
      "z": -2,
      "name": "Nat20_Force_Empty"
    },
    {
      "x": -6,
      "y": 8,
      "z": -2,
      "name": "Nat20_Force_Empty"
    },
    {
      "x": -6,
      "y": 9,
      "z": -2,
      "name": "Nat20_Force_Empty"
    },
    {
      "x": -6,
      "y": 10,
      "z": -2,
      "name": "Nat20_Force_Empty"
    },
    {
      "x": -6,
      "y": 11,
      "z": -2,
      "name": "Nat20_Force_Empty"
    },
    {
      "x": -6,
      "y": 12,
      "z": -2,
      "name": "Nat20_Force_Empty"
    },
    {
      "x": -6,
      "y": 13,
      "z": -2,
      "name": "Nat20_Force_Empty"
    },
    {
      "x": -6,
      "y": 14,
      "z": -2,
      "name": "Nat20_Force_Empty"
    },
    {
      "x": -6,
      "y": 15,
      "z": -2,
      "name": "Nat20_Force_Empty"
    },
    {
      "x": -6,
      "y": 16,
      "z": -2,
      "name": "Nat20_Force_Empty"
    },
    {
      "x": -6,
      "y": 17,
      "z": -2,
      "name": "Nat20_Force_Empty"
    },
    {
      "x": -6,
      "y": 18,
      "z": -2,
      "name": "Nat20_Force_Empty"
    },
    {
      "x": -6,
      "y": 19,
      "z": -2,
      "name": "Nat20_Force_Empty"
    },
    {
      "x": -6,
      "y": 0,
      "z": -1,
      "name": "Soil_Dirt_Dry"
    },
    {
      "x": -6,
      "y": 1,
      "z": -1,
      "name": "Furniture_Village_Counter",
      "filler": 32,
      "rotation": 1
    },
    {
      "x": -6,
      "y": 2,
      "z": -1,
      "name": "Nat20_Force_Empty"
    },
    {
      "x": -6,
      "y": 3,
      "z": -1,
      "name": "Cloth_Roof_Blue_Flap",
      "rotation": 3
    },
    {
      "x": -6,
      "y": 4,
      "z": -1,
      "name": "Nat20_Force_Empty"
    },
    {
      "x": -6,
      "y": 5,
      "z": -1,
      "name": "Nat20_Force_Empty"
    },
    {
      "x": -6,
      "y": 6,
      "z": -1,
      "name": "Nat20_Force_Empty"
    },
    {
      "x": -6,
      "y": 7,
      "z": -1,
      "name": "Nat20_Force_Empty"
    },
    {
      "x": -6,
      "y": 8,
      "z": -1,
      "name": "Nat20_Force_Empty"
    },
    {
      "x": -6,
      "y": 9,
      "z": -1,
      "name": "Nat20_Force_Empty"
    },
    {
      "x": -6,
      "y": 10,
      "z": -1,
      "name": "Nat20_Force_Empty"
    },
    {
      "x": -6,
      "y": 11,
      "z": -1,
      "name": "Nat20_Force_Empty"
    },
    {
      "x": -6,
      "y": 12,
      "z": -1,
      "name": "Nat20_Force_Empty"
    },
    {
      "x": -6,
      "y": 13,
      "z": -1,
      "name": "Nat20_Force_Empty"
    },
    {
      "x": -6,
      "y": 14,
      "z": -1,
      "name": "Nat20_Force_Empty"
    },
    {
      "x": -6,
      "y": 15,
      "z": -1,
      "name": "Nat20_Force_Empty"
    },
    {
      "x": -6,
      "y": 16,
      "z": -1,
      "name": "Nat20_Force_Empty"
    },
    {
      "x": -6,
      "y": 17,
      "z": -1,
      "name": "Nat20_Force_Empty"
    },
    {
      "x": -6,
      "y": 18,
      "z": -1,
      "name": "Nat20_Force_Empty"
    },
    {
      "x": -6,
      "y": 19,
      "z": -1,
      "name": "Nat20_Force_Empty"
    },
    {
      "x": -6,
      "y": 0,
      "z": 0,
      "name": "Soil_Dirt_Dry"
    },
    {
      "x": -6,
      "y": 1,
      "z": 0,
      "name": "Nat20_Force_Empty"
    },
    {
      "x": -6,
      "y": 2,
      "z": 0,
      "name": "Nat20_Force_Empty"
    },
    {
      "x": -6,
      "y": 3,
      "z": 0,
      "name": "Cloth_Roof_Blue_Flap",
      "rotation": 3
    },
    {
      "x": -6,
      "y": 4,
      "z": 0,
      "name": "Nat20_Force_Empty"
    },
    {
      "x": -6,
      "y": 5,
      "z": 0,
      "name": "Nat20_Force_Empty"
    },
    {
      "x": -6,
      "y": 6,
      "z": 0,
      "name": "Nat20_Force_Empty"
    },
    {
      "x": -6,
      "y": 7,
      "z": 0,
      "name": "Nat20_Force_Empty"
    },
    {
      "x": -6,
      "y": 8,
      "z": 0,
      "name": "Nat20_Force_Empty"
    },
    {
      "x": -6,
      "y": 9,
      "z": 0,
      "name": "Nat20_Force_Empty"
    },
    {
      "x": -6,
      "y": 10,
      "z": 0,
      "name": "Nat20_Force_Empty"
    },
    {
      "x": -6,
      "y": 11,
      "z": 0,
      "name": "Nat20_Force_Empty"
    },
    {
      "x": -6,
      "y": 12,
      "z": 0,
      "name": "Nat20_Force_Empty"
    },
    {
      "x": -6,
      "y": 13,
      "z": 0,
      "name": "Nat20_Force_Empty"
    },
    {
      "x": -6,
      "y": 14,
      "z": 0,
      "name": "Nat20_Force_Empty"
    },
    {
      "x": -6,
      "y": 15,
      "z": 0,
      "name": "Nat20_Force_Empty"
    },
    {
      "x": -6,
      "y": 16,
      "z": 0,
      "name": "Nat20_Force_Empty"
    },
    {
      "x": -6,
      "y": 17,
      "z": 0,
      "name": "Nat20_Force_Empty"
    },
    {
      "x": -6,
      "y": 18,
      "z": 0,
      "name": "Nat20_Force_Empty"
    },
    {
      "x": -6,
      "y": 19,
      "z": 0,
      "name": "Nat20_Force_Empty"
    },
    {
      "x": -6,
      "y": 1,
      "z": 1,
      "name": "Nat20_Force_Empty"
    },
    {
      "x": -6,
      "y": 2,
      "z": 1,
      "name": "Nat20_Force_Empty"
    },
    {
      "x": -6,
      "y": 3,
      "z": 1,
      "name": "Nat20_Force_Empty"
    },
    {
      "x": -6,
      "y": 4,
      "z": 1,
      "name": "Nat20_Force_Empty"
    },
    {
      "x": -6,
      "y": 5,
      "z": 1,
      "name": "Nat20_Force_Empty"
    },
    {
      "x": -6,
      "y": 6,
      "z": 1,
      "name": "Nat20_Force_Empty"
    },
    {
      "x": -6,
      "y": 7,
      "z": 1,
      "name": "Nat20_Force_Empty"
    },
    {
      "x": -6,
      "y": 8,
      "z": 1,
      "name": "Rock_Sandstone_Brick_Half",
      "rotation": 7
    },
    {
      "x": -6,
      "y": 9,
      "z": 1,
      "name": "Nat20_Force_Empty"
    },
    {
      "x": -6,
      "y": 10,
      "z": 1,
      "name": "Nat20_Force_Empty"
    },
    {
      "x": -6,
      "y": 11,
      "z": 1,
      "name": "Nat20_Force_Empty"
    },
    {
      "x": -6,
      "y": 12,
      "z": 1,
      "name": "Nat20_Force_Empty"
    },
    {
      "x": -6,
      "y": 13,
      "z": 1,
      "name": "Nat20_Force_Empty"
    },
    {
      "x": -6,
      "y": 14,
      "z": 1,
      "name": "Nat20_Force_Empty"
    },
    {
      "x": -6,
      "y": 15,
      "z": 1,
      "name": "Nat20_Force_Empty"
    },
    {
      "x": -6,
      "y": 16,
      "z": 1,
      "name": "Nat20_Force_Empty"
    },
    {
      "x": -6,
      "y": 17,
      "z": 1,
      "name": "Nat20_Force_Empty"
    },
    {
      "x": -6,
      "y": 18,
      "z": 1,
      "name": "Nat20_Force_Empty"
    },
    {
      "x": -6,
      "y": 19,
      "z": 1,
      "name": "Nat20_Force_Empty"
    },
    {
      "x": -6,
      "y": 1,
      "z": 2,
      "name": "Nat20_Force_Empty"
    },
    {
      "x": -6,
      "y": 2,
      "z": 2,
      "name": "Nat20_Force_Empty"
    },
    {
      "x": -6,
      "y": 3,
      "z": 2,
      "name": "Nat20_Force_Empty"
    },
    {
      "x": -6,
      "y": 4,
      "z": 2,
      "name": "Nat20_Force_Empty"
    },
    {
      "x": -6,
      "y": 5,
      "z": 2,
      "name": "Nat20_Force_Empty"
    },
    {
      "x": -6,
      "y": 6,
      "z": 2,
      "name": "Nat20_Force_Empty"
    },
    {
      "x": -6,
      "y": 7,
      "z": 2,
      "name": "Rock_Sandstone_Cobble_Beam",
      "rotation": 5
    },
    {
      "x": -6,
      "y": 8,
      "z": 2,
      "name": "Rock_Sandstone_Brick_Half",
      "rotation": 7
    },
    {
      "x": -6,
      "y": 9,
      "z": 2,
      "name": "Nat20_Force_Empty"
    },
    {
      "x": -6,
      "y": 10,
      "z": 2,
      "name": "Nat20_Force_Empty"
    },
    {
      "x": -6,
      "y": 11,
      "z": 2,
      "name": "Nat20_Force_Empty"
    },
    {
      "x": -6,
      "y": 12,
      "z": 2,
      "name": "Nat20_Force_Empty"
    },
    {
      "x": -6,
      "y": 13,
      "z": 2,
      "name": "Nat20_Force_Empty"
    },
    {
      "x": -6,
      "y": 14,
      "z": 2,
      "name": "Nat20_Force_Empty"
    },
    {
      "x": -6,
      "y": 15,
      "z": 2,
      "name": "Nat20_Force_Empty"
    },
    {
      "x": -6,
      "y": 16,
      "z": 2,
      "name": "Nat20_Force_Empty"
    },
    {
      "x": -6,
      "y": 17,
      "z": 2,
      "name": "Nat20_Force_Empty"
    },
    {
      "x": -6,
      "y": 18,
      "z": 2,
      "name": "Nat20_Force_Empty"
    },
    {
      "x": -6,
      "y": 19,
      "z": 2,
      "name": "Nat20_Force_Empty"
    },
    {
      "x": -6,
      "y": 1,
      "z": 3,
      "name": "Nat20_Force_Empty"
    },
    {
      "x": -6,
      "y": 2,
      "z": 3,
      "name": "Nat20_Force_Empty"
    },
    {
      "x": -6,
      "y": 3,
      "z": 3,
      "name": "Nat20_Force_Empty"
    },
    {
      "x": -6,
      "y": 4,
      "z": 3,
      "name": "Nat20_Force_Empty"
    },
    {
      "x": -6,
      "y": 5,
      "z": 3,
      "name": "Nat20_Force_Empty"
    },
    {
      "x": -6,
      "y": 6,
      "z": 3,
      "name": "Nat20_Force_Empty"
    },
    {
      "x": -6,
      "y": 7,
      "z": 3,
      "name": "Nat20_Force_Empty"
    },
    {
      "x": -6,
      "y": 8,
      "z": 3,
      "name": "Nat20_Force_Empty"
    },
    {
      "x": -6,
      "y": 9,
      "z": 3,
      "name": "Nat20_Force_Empty"
    },
    {
      "x": -6,
      "y": 10,
      "z": 3,
      "name": "Nat20_Force_Empty"
    },
    {
      "x": -6,
      "y": 11,
      "z": 3,
      "name": "Nat20_Force_Empty"
    },
    {
      "x": -6,
      "y": 12,
      "z": 3,
      "name": "Nat20_Force_Empty"
    },
    {
      "x": -6,
      "y": 13,
      "z": 3,
      "name": "Nat20_Force_Empty"
    },
    {
      "x": -6,
      "y": 14,
      "z": 3,
      "name": "Nat20_Force_Empty"
    },
    {
      "x": -6,
      "y": 15,
      "z": 3,
      "name": "Nat20_Force_Empty"
    },
    {
      "x": -6,
      "y": 16,
      "z": 3,
      "name": "Nat20_Force_Empty"
    },
    {
      "x": -6,
      "y": 17,
      "z": 3,
      "name": "Nat20_Force_Empty"
    },
    {
      "x": -6,
      "y": 18,
      "z": 3,
      "name": "Nat20_Force_Empty"
    },
    {
      "x": -6,
      "y": 19,
      "z": 3,
      "name": "Nat20_Force_Empty"
    },
    {
      "x": -6,
      "y": 1,
      "z": 4,
      "name": "Nat20_Force_Empty"
    },
    {
      "x": -6,
      "y": 2,
      "z": 4,
      "name": "Nat20_Force_Empty"
    },
    {
      "x": -6,
      "y": 3,
      "z": 4,
      "name": "Nat20_Force_Empty"
    },
    {
      "x": -6,
      "y": 4,
      "z": 4,
      "name": "Nat20_Force_Empty"
    },
    {
      "x": -6,
      "y": 5,
      "z": 4,
      "name": "Nat20_Force_Empty"
    },
    {
      "x": -6,
      "y": 6,
      "z": 4,
      "name": "Nat20_Force_Empty"
    },
    {
      "x": -6,
      "y": 7,
      "z": 4,
      "name": "Nat20_Force_Empty"
    },
    {
      "x": -6,
      "y": 8,
      "z": 4,
      "name": "Nat20_Force_Empty"
    },
    {
      "x": -6,
      "y": 9,
      "z": 4,
      "name": "Nat20_Force_Empty"
    },
    {
      "x": -6,
      "y": 10,
      "z": 4,
      "name": "Nat20_Force_Empty"
    },
    {
      "x": -6,
      "y": 11,
      "z": 4,
      "name": "Nat20_Force_Empty"
    },
    {
      "x": -6,
      "y": 12,
      "z": 4,
      "name": "Nat20_Force_Empty"
    },
    {
      "x": -6,
      "y": 13,
      "z": 4,
      "name": "Nat20_Force_Empty"
    },
    {
      "x": -6,
      "y": 14,
      "z": 4,
      "name": "Nat20_Force_Empty"
    },
    {
      "x": -6,
      "y": 15,
      "z": 4,
      "name": "Nat20_Force_Empty"
    },
    {
      "x": -6,
      "y": 16,
      "z": 4,
      "name": "Nat20_Force_Empty"
    },
    {
      "x": -6,
      "y": 17,
      "z": 4,
      "name": "Nat20_Force_Empty"
    },
    {
      "x": -6,
      "y": 18,
      "z": 4,
      "name": "Nat20_Force_Empty"
    },
    {
      "x": -6,
      "y": 19,
      "z": 4,
      "name": "Nat20_Force_Empty"
    },
    {
      "x": -6,
      "y": 0,
      "z": 5,
      "name": "Soil_Dirt_Dry"
    },
    {
      "x": -6,
      "y": 1,
      "z": 5,
      "name": "Furniture_Village_Crate",
      "components": {
        "Components": {
          "ItemContainerBlock": {
            "ItemContainer": {
              "Capacity": 20,
              "Items": {
                "0": {
                  "Id": "Ingredient_Hide_Medium",
                  "Quantity": 2,
                  "Durability": 0.0,
                  "MaxDurability": 0.0,
                  "OverrideDroppedItemAnimation": false
                },
                "1": {
                  "Id": "Ingredient_Charcoal",
                  "Quantity": 5,
                  "Durability": 0.0,
                  "MaxDurability": 0.0,
                  "OverrideDroppedItemAnimation": false
                }
              }
            },
            "Capacity": 20
          }
        }
      }
    },
    {
      "x": -6,
      "y": 2,
      "z": 5,
      "name": "Furniture_Tavern_Barrel"
    },
    {
      "x": -6,
      "y": 3,
      "z": 5,
      "name": "Nat20_Force_Empty"
    },
    {
      "x": -6,
      "y": 4,
      "z": 5,
      "name": "Nat20_Force_Empty"
    },
    {
      "x": -6,
      "y": 5,
      "z": 5,
      "name": "Nat20_Force_Empty"
    },
    {
      "x": -6,
      "y": 6,
      "z": 5,
      "name": "Nat20_Force_Empty"
    },
    {
      "x": -6,
      "y": 7,
      "z": 5,
      "name": "Nat20_Force_Empty"
    },
    {
      "x": -6,
      "y": 8,
      "z": 5,
      "name": "Rock_Sandstone_Brick_Half",
      "rotation": 7
    },
    {
      "x": -6,
      "y": 9,
      "z": 5,
      "name": "Nat20_Force_Empty"
    },
    {
      "x": -6,
      "y": 10,
      "z": 5,
      "name": "Nat20_Force_Empty"
    },
    {
      "x": -6,
      "y": 11,
      "z": 5,
      "name": "Nat20_Force_Empty"
    },
    {
      "x": -6,
      "y": 12,
      "z": 5,
      "name": "Nat20_Force_Empty"
    },
    {
      "x": -6,
      "y": 13,
      "z": 5,
      "name": "Nat20_Force_Empty"
    },
    {
      "x": -6,
      "y": 14,
      "z": 5,
      "name": "Nat20_Force_Empty"
    },
    {
      "x": -6,
      "y": 15,
      "z": 5,
      "name": "Nat20_Force_Empty"
    },
    {
      "x": -6,
      "y": 16,
      "z": 5,
      "name": "Nat20_Force_Empty"
    },
    {
      "x": -6,
      "y": 17,
      "z": 5,
      "name": "Nat20_Force_Empty"
    },
    {
      "x": -6,
      "y": 18,
      "z": 5,
      "name": "Nat20_Force_Empty"
    },
    {
      "x": -6,
      "y": 19,
      "z": 5,
      "name": "Nat20_Force_Empty"
    },
    {
      "x": -6,
      "y": 0,
      "z": 6,
      "name": "Soil_Dirt_Dry"
    },
    {
      "x": -6,
      "y": 1,
      "z": 6,
      "name": "Furniture_Village_Crate",
      "components": {
        "Components": {
          "ItemContainerBlock": {
            "ItemContainer": {
              "Capacity": 20,
              "Items": {
                "0": {
                  "Id": "Ingredient_Hide_Medium",
                  "Quantity": 2,
                  "Durability": 0.0,
                  "MaxDurability": 0.0,
                  "OverrideDroppedItemAnimation": false
                },
                "1": {
                  "Id": "Ore_Cobalt",
                  "Quantity": 5,
                  "Durability": 0.0,
                  "MaxDurability": 0.0,
                  "OverrideDroppedItemAnimation": false
                }
              }
            },
            "Capacity": 20
          }
        }
      }
    },
    {
      "x": -6,
      "y": 2,
      "z": 6,
      "name": "Furniture_Village_Crate",
      "components": {
        "Components": {
          "ItemContainerBlock": {
            "ItemContainer": {
              "Capacity": 20,
              "Items": {
                "0": {
                  "Id": "Ingredient_Hide_Medium",
                  "Quantity": 2,
                  "Durability": 0.0,
                  "MaxDurability": 0.0,
                  "OverrideDroppedItemAnimation": false
                },
                "1": {
                  "Id": "Ingredient_Charcoal",
                  "Quantity": 5,
                  "Durability": 0.0,
                  "MaxDurability": 0.0,
                  "OverrideDroppedItemAnimation": false
                }
              }
            },
            "Capacity": 20
          }
        }
      }
    },
    {
      "x": -6,
      "y": 3,
      "z": 6,
      "name": "Nat20_Force_Empty"
    },
    {
      "x": -6,
      "y": 4,
      "z": 6,
      "name": "Nat20_Force_Empty"
    },
    {
      "x": -6,
      "y": 5,
      "z": 6,
      "name": "Nat20_Force_Empty"
    },
    {
      "x": -6,
      "y": 6,
      "z": 6,
      "name": "Nat20_Force_Empty"
    },
    {
      "x": -6,
      "y": 7,
      "z": 6,
      "name": "Rock_Sandstone_Cobble_Beam",
      "rotation": 5
    },
    {
      "x": -6,
      "y": 8,
      "z": 6,
      "name": "Rock_Sandstone_Brick_Half",
      "rotation": 7
    },
    {
      "x": -6,
      "y": 9,
      "z": 6,
      "name": "Nat20_Force_Empty"
    },
    {
      "x": -6,
      "y": 10,
      "z": 6,
      "name": "Nat20_Force_Empty"
    },
    {
      "x": -6,
      "y": 11,
      "z": 6,
      "name": "Nat20_Force_Empty"
    },
    {
      "x": -6,
      "y": 12,
      "z": 6,
      "name": "Nat20_Force_Empty"
    },
    {
      "x": -6,
      "y": 13,
      "z": 6,
      "name": "Nat20_Force_Empty"
    },
    {
      "x": -6,
      "y": 14,
      "z": 6,
      "name": "Nat20_Force_Empty"
    },
    {
      "x": -6,
      "y": 15,
      "z": 6,
      "name": "Nat20_Force_Empty"
    },
    {
      "x": -6,
      "y": 16,
      "z": 6,
      "name": "Nat20_Force_Empty"
    },
    {
      "x": -6,
      "y": 17,
      "z": 6,
      "name": "Nat20_Force_Empty"
    },
    {
      "x": -6,
      "y": 18,
      "z": 6,
      "name": "Nat20_Force_Empty"
    },
    {
      "x": -6,
      "y": 19,
      "z": 6,
      "name": "Nat20_Force_Empty"
    },
    {
      "x": -6,
      "y": 0,
      "z": 7,
      "name": "Soil_Dirt_Dry"
    },
    {
      "x": -6,
      "y": 1,
      "z": 7,
      "name": "Nat20_Force_Empty"
    },
    {
      "x": -6,
      "y": 2,
      "z": 7,
      "name": "Nat20_Force_Empty"
    },
    {
      "x": -6,
      "y": 3,
      "z": 7,
      "name": "Nat20_Force_Empty"
    },
    {
      "x": -6,
      "y": 4,
      "z": 7,
      "name": "Nat20_Force_Empty"
    },
    {
      "x": -6,
      "y": 5,
      "z": 7,
      "name": "Nat20_Force_Empty"
    },
    {
      "x": -6,
      "y": 6,
      "z": 7,
      "name": "Nat20_Force_Empty"
    },
    {
      "x": -6,
      "y": 7,
      "z": 7,
      "name": "Nat20_Force_Empty"
    },
    {
      "x": -6,
      "y": 8,
      "z": 7,
      "name": "Rock_Sandstone_Brick_Half",
      "rotation": 7
    },
    {
      "x": -6,
      "y": 9,
      "z": 7,
      "name": "Nat20_Force_Empty"
    },
    {
      "x": -6,
      "y": 10,
      "z": 7,
      "name": "Nat20_Force_Empty"
    },
    {
      "x": -6,
      "y": 11,
      "z": 7,
      "name": "Nat20_Force_Empty"
    },
    {
      "x": -6,
      "y": 12,
      "z": 7,
      "name": "Nat20_Force_Empty"
    },
    {
      "x": -6,
      "y": 13,
      "z": 7,
      "name": "Nat20_Force_Empty"
    },
    {
      "x": -6,
      "y": 14,
      "z": 7,
      "name": "Nat20_Force_Empty"
    },
    {
      "x": -6,
      "y": 15,
      "z": 7,
      "name": "Nat20_Force_Empty"
    },
    {
      "x": -6,
      "y": 16,
      "z": 7,
      "name": "Nat20_Force_Empty"
    },
    {
      "x": -6,
      "y": 17,
      "z": 7,
      "name": "Nat20_Force_Empty"
    },
    {
      "x": -6,
      "y": 18,
      "z": 7,
      "name": "Nat20_Force_Empty"
    },
    {
      "x": -6,
      "y": 19,
      "z": 7,
      "name": "Nat20_Force_Empty"
    },
    {
      "x": -6,
      "y": 0,
      "z": 8,
      "name": "Soil_Dirt_Dry"
    },
    {
      "x": -6,
      "y": 1,
      "z": 8,
      "name": "Nat20_Anchor"
    },
    {
      "x": -6,
      "y": 2,
      "z": 8,
      "name": "Nat20_Force_Empty"
    },
    {
      "x": -6,
      "y": 3,
      "z": 8,
      "name": "Nat20_Force_Empty"
    },
    {
      "x": -6,
      "y": 4,
      "z": 8,
      "name": "Nat20_Force_Empty"
    },
    {
      "x": -6,
      "y": 5,
      "z": 8,
      "name": "Nat20_Force_Empty"
    },
    {
      "x": -6,
      "y": 6,
      "z": 8,
      "name": "Nat20_Force_Empty"
    },
    {
      "x": -6,
      "y": 7,
      "z": 8,
      "name": "Nat20_Force_Empty"
    },
    {
      "x": -6,
      "y": 8,
      "z": 8,
      "name": "Rock_Sandstone_Brick_Half",
      "rotation": 7
    },
    {
      "x": -6,
      "y": 9,
      "z": 8,
      "name": "Nat20_Force_Empty"
    },
    {
      "x": -6,
      "y": 10,
      "z": 8,
      "name": "Nat20_Force_Empty"
    },
    {
      "x": -6,
      "y": 11,
      "z": 8,
      "name": "Nat20_Force_Empty"
    },
    {
      "x": -6,
      "y": 12,
      "z": 8,
      "name": "Nat20_Force_Empty"
    },
    {
      "x": -6,
      "y": 13,
      "z": 8,
      "name": "Nat20_Force_Empty"
    },
    {
      "x": -6,
      "y": 14,
      "z": 8,
      "name": "Nat20_Force_Empty"
    },
    {
      "x": -6,
      "y": 15,
      "z": 8,
      "name": "Nat20_Force_Empty"
    },
    {
      "x": -6,
      "y": 16,
      "z": 8,
      "name": "Nat20_Force_Empty"
    },
    {
      "x": -6,
      "y": 17,
      "z": 8,
      "name": "Nat20_Force_Empty"
    },
    {
      "x": -6,
      "y": 18,
      "z": 8,
      "name": "Nat20_Force_Empty"
    },
    {
      "x": -6,
      "y": 19,
      "z": 8,
      "name": "Nat20_Force_Empty"
    },
    {
      "x": -6,
      "y": 0,
      "z": 9,
      "name": "Soil_Dirt_Dry"
    },
    {
      "x": -6,
      "y": 1,
      "z": 9,
      "name": "Nat20_Force_Empty"
    },
    {
      "x": -6,
      "y": 2,
      "z": 9,
      "name": "Nat20_Force_Empty"
    },
    {
      "x": -6,
      "y": 3,
      "z": 9,
      "name": "Nat20_Force_Empty"
    },
    {
      "x": -6,
      "y": 4,
      "z": 9,
      "name": "Nat20_Force_Empty"
    },
    {
      "x": -6,
      "y": 5,
      "z": 9,
      "name": "Nat20_Force_Empty"
    },
    {
      "x": -6,
      "y": 6,
      "z": 9,
      "name": "Nat20_Force_Empty"
    },
    {
      "x": -6,
      "y": 7,
      "z": 9,
      "name": "Nat20_Force_Empty"
    },
    {
      "x": -6,
      "y": 8,
      "z": 9,
      "name": "Rock_Sandstone_Brick_Half",
      "rotation": 7
    },
    {
      "x": -6,
      "y": 9,
      "z": 9,
      "name": "Nat20_Force_Empty"
    },
    {
      "x": -6,
      "y": 10,
      "z": 9,
      "name": "Nat20_Force_Empty"
    },
    {
      "x": -6,
      "y": 11,
      "z": 9,
      "name": "Nat20_Force_Empty"
    },
    {
      "x": -6,
      "y": 12,
      "z": 9,
      "name": "Nat20_Force_Empty"
    },
    {
      "x": -6,
      "y": 13,
      "z": 9,
      "name": "Nat20_Force_Empty"
    },
    {
      "x": -6,
      "y": 14,
      "z": 9,
      "name": "Nat20_Force_Empty"
    },
    {
      "x": -6,
      "y": 15,
      "z": 9,
      "name": "Nat20_Force_Empty"
    },
    {
      "x": -6,
      "y": 16,
      "z": 9,
      "name": "Nat20_Force_Empty"
    },
    {
      "x": -6,
      "y": 17,
      "z": 9,
      "name": "Nat20_Force_Empty"
    },
    {
      "x": -6,
      "y": 18,
      "z": 9,
      "name": "Nat20_Force_Empty"
    },
    {
      "x": -6,
      "y": 19,
      "z": 9,
      "name": "Nat20_Force_Empty"
    },
    {
      "x": -6,
      "y": 0,
      "z": 10,
      "name": "Soil_Dirt_Dry"
    },
    {
      "x": -6,
      "y": 1,
      "z": 10,
      "name": "Nat20_Force_Empty"
    },
    {
      "x": -6,
      "y": 2,
      "z": 10,
      "name": "Nat20_Force_Empty"
    },
    {
      "x": -6,
      "y": 3,
      "z": 10,
      "name": "Nat20_Force_Empty"
    },
    {
      "x": -6,
      "y": 4,
      "z": 10,
      "name": "Nat20_Force_Empty"
    },
    {
      "x": -6,
      "y": 5,
      "z": 10,
      "name": "Nat20_Force_Empty"
    },
    {
      "x": -6,
      "y": 6,
      "z": 10,
      "name": "Nat20_Force_Empty"
    },
    {
      "x": -6,
      "y": 7,
      "z": 10,
      "name": "Rock_Sandstone_Cobble_Beam",
      "rotation": 5
    },
    {
      "x": -6,
      "y": 8,
      "z": 10,
      "name": "Rock_Sandstone_Brick_Half",
      "rotation": 7
    },
    {
      "x": -6,
      "y": 9,
      "z": 10,
      "name": "Nat20_Force_Empty"
    },
    {
      "x": -6,
      "y": 10,
      "z": 10,
      "name": "Nat20_Force_Empty"
    },
    {
      "x": -6,
      "y": 11,
      "z": 10,
      "name": "Nat20_Force_Empty"
    },
    {
      "x": -6,
      "y": 12,
      "z": 10,
      "name": "Nat20_Force_Empty"
    },
    {
      "x": -6,
      "y": 13,
      "z": 10,
      "name": "Nat20_Force_Empty"
    },
    {
      "x": -6,
      "y": 14,
      "z": 10,
      "name": "Nat20_Force_Empty"
    },
    {
      "x": -6,
      "y": 15,
      "z": 10,
      "name": "Nat20_Force_Empty"
    },
    {
      "x": -6,
      "y": 16,
      "z": 10,
      "name": "Nat20_Force_Empty"
    },
    {
      "x": -6,
      "y": 17,
      "z": 10,
      "name": "Nat20_Force_Empty"
    },
    {
      "x": -6,
      "y": 18,
      "z": 10,
      "name": "Nat20_Force_Empty"
    },
    {
      "x": -6,
      "y": 19,
      "z": 10,
      "name": "Nat20_Force_Empty"
    },
    {
      "x": -6,
      "y": 1,
      "z": 11,
      "name": "Nat20_Force_Empty"
    },
    {
      "x": -6,
      "y": 2,
      "z": 11,
      "name": "Nat20_Force_Empty"
    },
    {
      "x": -6,
      "y": 3,
      "z": 11,
      "name": "Nat20_Force_Empty"
    },
    {
      "x": -6,
      "y": 4,
      "z": 11,
      "name": "Nat20_Force_Empty"
    },
    {
      "x": -6,
      "y": 5,
      "z": 11,
      "name": "Nat20_Force_Empty"
    },
    {
      "x": -6,
      "y": 6,
      "z": 11,
      "name": "Nat20_Force_Empty"
    },
    {
      "x": -6,
      "y": 7,
      "z": 11,
      "name": "Nat20_Force_Empty"
    },
    {
      "x": -6,
      "y": 8,
      "z": 11,
      "name": "Rock_Sandstone_Brick_Half",
      "rotation": 7
    },
    {
      "x": -6,
      "y": 9,
      "z": 11,
      "name": "Nat20_Force_Empty"
    },
    {
      "x": -6,
      "y": 10,
      "z": 11,
      "name": "Nat20_Force_Empty"
    },
    {
      "x": -6,
      "y": 11,
      "z": 11,
      "name": "Nat20_Force_Empty"
    },
    {
      "x": -6,
      "y": 12,
      "z": 11,
      "name": "Nat20_Force_Empty"
    },
    {
      "x": -6,
      "y": 13,
      "z": 11,
      "name": "Nat20_Force_Empty"
    },
    {
      "x": -6,
      "y": 14,
      "z": 11,
      "name": "Nat20_Force_Empty"
    },
    {
      "x": -6,
      "y": 15,
      "z": 11,
      "name": "Nat20_Force_Empty"
    },
    {
      "x": -6,
      "y": 16,
      "z": 11,
      "name": "Nat20_Force_Empty"
    },
    {
      "x": -6,
      "y": 17,
      "z": 11,
      "name": "Nat20_Force_Empty"
    },
    {
      "x": -6,
      "y": 18,
      "z": 11,
      "name": "Nat20_Force_Empty"
    },
    {
      "x": -6,
      "y": 19,
      "z": 11,
      "name": "Nat20_Force_Empty"
    },
    {
      "x": -5,
      "y": 1,
      "z": -10,
      "name": "Nat20_Force_Empty"
    },
    {
      "x": -5,
      "y": 2,
      "z": -10,
      "name": "Nat20_Force_Empty"
    },
    {
      "x": -5,
      "y": 3,
      "z": -10,
      "name": "Nat20_Force_Empty"
    },
    {
      "x": -5,
      "y": 4,
      "z": -10,
      "name": "Nat20_Force_Empty"
    },
    {
      "x": -5,
      "y": 5,
      "z": -10,
      "name": "Nat20_Force_Empty"
    },
    {
      "x": -5,
      "y": 6,
      "z": -10,
      "name": "Nat20_Force_Empty"
    },
    {
      "x": -5,
      "y": 7,
      "z": -10,
      "name": "Nat20_Force_Empty"
    },
    {
      "x": -5,
      "y": 8,
      "z": -10,
      "name": "Nat20_Force_Empty"
    },
    {
      "x": -5,
      "y": 9,
      "z": -10,
      "name": "Nat20_Force_Empty"
    },
    {
      "x": -5,
      "y": 10,
      "z": -10,
      "name": "Nat20_Force_Empty"
    },
    {
      "x": -5,
      "y": 11,
      "z": -10,
      "name": "Nat20_Force_Empty"
    },
    {
      "x": -5,
      "y": 12,
      "z": -10,
      "name": "Nat20_Force_Empty"
    },
    {
      "x": -5,
      "y": 13,
      "z": -10,
      "name": "Nat20_Force_Empty"
    },
    {
      "x": -5,
      "y": 14,
      "z": -10,
      "name": "Nat20_Force_Empty"
    },
    {
      "x": -5,
      "y": 15,
      "z": -10,
      "name": "Nat20_Force_Empty"
    },
    {
      "x": -5,
      "y": 16,
      "z": -10,
      "name": "Nat20_Force_Empty"
    },
    {
      "x": -5,
      "y": 17,
      "z": -10,
      "name": "Nat20_Force_Empty"
    },
    {
      "x": -5,
      "y": 18,
      "z": -10,
      "name": "Nat20_Force_Empty"
    },
    {
      "x": -5,
      "y": 19,
      "z": -10,
      "name": "Nat20_Force_Empty"
    },
    {
      "x": -5,
      "y": 1,
      "z": -9,
      "name": "Nat20_Force_Empty"
    },
    {
      "x": -5,
      "y": 2,
      "z": -9,
      "name": "Nat20_Force_Empty"
    },
    {
      "x": -5,
      "y": 3,
      "z": -9,
      "name": "Nat20_Force_Empty"
    },
    {
      "x": -5,
      "y": 4,
      "z": -9,
      "name": "Nat20_Force_Empty"
    },
    {
      "x": -5,
      "y": 5,
      "z": -9,
      "name": "Nat20_Force_Empty"
    },
    {
      "x": -5,
      "y": 6,
      "z": -9,
      "name": "Nat20_Force_Empty"
    },
    {
      "x": -5,
      "y": 7,
      "z": -9,
      "name": "Nat20_Force_Empty"
    },
    {
      "x": -5,
      "y": 8,
      "z": -9,
      "name": "Nat20_Force_Empty"
    },
    {
      "x": -5,
      "y": 9,
      "z": -9,
      "name": "Nat20_Force_Empty"
    },
    {
      "x": -5,
      "y": 10,
      "z": -9,
      "name": "Nat20_Force_Empty"
    },
    {
      "x": -5,
      "y": 11,
      "z": -9,
      "name": "Nat20_Force_Empty"
    },
    {
      "x": -5,
      "y": 12,
      "z": -9,
      "name": "Nat20_Force_Empty"
    },
    {
      "x": -5,
      "y": 13,
      "z": -9,
      "name": "Nat20_Force_Empty"
    },
    {
      "x": -5,
      "y": 14,
      "z": -9,
      "name": "Nat20_Force_Empty"
    },
    {
      "x": -5,
      "y": 15,
      "z": -9,
      "name": "Nat20_Force_Empty"
    },
    {
      "x": -5,
      "y": 16,
      "z": -9,
      "name": "Nat20_Force_Empty"
    },
    {
      "x": -5,
      "y": 17,
      "z": -9,
      "name": "Nat20_Force_Empty"
    },
    {
      "x": -5,
      "y": 18,
      "z": -9,
      "name": "Nat20_Force_Empty"
    },
    {
      "x": -5,
      "y": 19,
      "z": -9,
      "name": "Nat20_Force_Empty"
    },
    {
      "x": -5,
      "y": 0,
      "z": -8,
      "name": "Soil_Dirt_Dry"
    },
    {
      "x": -5,
      "y": 1,
      "z": -8,
      "name": "Nat20_Force_Empty"
    },
    {
      "x": -5,
      "y": 2,
      "z": -8,
      "name": "Nat20_Force_Empty"
    },
    {
      "x": -5,
      "y": 3,
      "z": -8,
      "name": "Nat20_Force_Empty"
    },
    {
      "x": -5,
      "y": 4,
      "z": -8,
      "name": "Nat20_Force_Empty"
    },
    {
      "x": -5,
      "y": 5,
      "z": -8,
      "name": "Nat20_Force_Empty"
    },
    {
      "x": -5,
      "y": 6,
      "z": -8,
      "name": "Nat20_Force_Empty"
    },
    {
      "x": -5,
      "y": 7,
      "z": -8,
      "name": "Nat20_Force_Empty"
    },
    {
      "x": -5,
      "y": 8,
      "z": -8,
      "name": "Nat20_Force_Empty"
    },
    {
      "x": -5,
      "y": 9,
      "z": -8,
      "name": "Nat20_Force_Empty"
    },
    {
      "x": -5,
      "y": 10,
      "z": -8,
      "name": "Nat20_Force_Empty"
    },
    {
      "x": -5,
      "y": 11,
      "z": -8,
      "name": "Nat20_Force_Empty"
    },
    {
      "x": -5,
      "y": 12,
      "z": -8,
      "name": "Nat20_Force_Empty"
    },
    {
      "x": -5,
      "y": 13,
      "z": -8,
      "name": "Nat20_Force_Empty"
    },
    {
      "x": -5,
      "y": 14,
      "z": -8,
      "name": "Nat20_Force_Empty"
    },
    {
      "x": -5,
      "y": 15,
      "z": -8,
      "name": "Nat20_Force_Empty"
    },
    {
      "x": -5,
      "y": 16,
      "z": -8,
      "name": "Nat20_Force_Empty"
    },
    {
      "x": -5,
      "y": 17,
      "z": -8,
      "name": "Nat20_Force_Empty"
    },
    {
      "x": -5,
      "y": 18,
      "z": -8,
      "name": "Nat20_Force_Empty"
    },
    {
      "x": -5,
      "y": 19,
      "z": -8,
      "name": "Nat20_Force_Empty"
    },
    {
      "x": -5,
      "y": 0,
      "z": -7,
      "name": "Soil_Dirt_Dry"
    },
    {
      "x": -5,
      "y": 1,
      "z": -7,
      "name": "Furniture_Tavern_Barrel"
    },
    {
      "x": -5,
      "y": 2,
      "z": -7,
      "name": "Nat20_Force_Empty"
    },
    {
      "x": -5,
      "y": 3,
      "z": -7,
      "name": "Nat20_Force_Empty"
    },
    {
      "x": -5,
      "y": 4,
      "z": -7,
      "name": "Nat20_Force_Empty"
    },
    {
      "x": -5,
      "y": 5,
      "z": -7,
      "name": "Nat20_Force_Empty"
    },
    {
      "x": -5,
      "y": 6,
      "z": -7,
      "name": "Nat20_Force_Empty"
    },
    {
      "x": -5,
      "y": 7,
      "z": -7,
      "name": "Nat20_Force_Empty"
    },
    {
      "x": -5,
      "y": 8,
      "z": -7,
      "name": "Nat20_Force_Empty"
    },
    {
      "x": -5,
      "y": 9,
      "z": -7,
      "name": "Nat20_Force_Empty"
    },
    {
      "x": -5,
      "y": 10,
      "z": -7,
      "name": "Nat20_Force_Empty"
    },
    {
      "x": -5,
      "y": 11,
      "z": -7,
      "name": "Nat20_Force_Empty"
    },
    {
      "x": -5,
      "y": 12,
      "z": -7,
      "name": "Nat20_Force_Empty"
    },
    {
      "x": -5,
      "y": 13,
      "z": -7,
      "name": "Nat20_Force_Empty"
    },
    {
      "x": -5,
      "y": 14,
      "z": -7,
      "name": "Nat20_Force_Empty"
    },
    {
      "x": -5,
      "y": 15,
      "z": -7,
      "name": "Nat20_Force_Empty"
    },
    {
      "x": -5,
      "y": 16,
      "z": -7,
      "name": "Nat20_Force_Empty"
    },
    {
      "x": -5,
      "y": 17,
      "z": -7,
      "name": "Nat20_Force_Empty"
    },
    {
      "x": -5,
      "y": 18,
      "z": -7,
      "name": "Nat20_Force_Empty"
    },
    {
      "x": -5,
      "y": 19,
      "z": -7,
      "name": "Nat20_Force_Empty"
    },
    {
      "x": -5,
      "y": 0,
      "z": -6,
      "name": "Soil_Dirt_Dry"
    },
    {
      "x": -5,
      "y": 1,
      "z": -6,
      "name": "Furniture_Village_Crate",
      "components": {
        "Components": {
          "ItemContainerBlock": {
            "ItemContainer": {
              "Capacity": 20,
              "Items": {
                "0": {
                  "Id": "Ingredient_Hide_Medium",
                  "Quantity": 2,
                  "Durability": 0.0,
                  "MaxDurability": 0.0,
                  "OverrideDroppedItemAnimation": false
                }
              }
            },
            "Capacity": 20
          }
        }
      }
    },
    {
      "x": -5,
      "y": 2,
      "z": -6,
      "name": "Nat20_Force_Empty"
    },
    {
      "x": -5,
      "y": 3,
      "z": -6,
      "name": "Nat20_Force_Empty"
    },
    {
      "x": -5,
      "y": 4,
      "z": -6,
      "name": "Nat20_Force_Empty"
    },
    {
      "x": -5,
      "y": 5,
      "z": -6,
      "name": "Nat20_Force_Empty"
    },
    {
      "x": -5,
      "y": 6,
      "z": -6,
      "name": "Nat20_Force_Empty"
    },
    {
      "x": -5,
      "y": 7,
      "z": -6,
      "name": "Nat20_Force_Empty"
    },
    {
      "x": -5,
      "y": 8,
      "z": -6,
      "name": "Nat20_Force_Empty"
    },
    {
      "x": -5,
      "y": 9,
      "z": -6,
      "name": "Nat20_Force_Empty"
    },
    {
      "x": -5,
      "y": 10,
      "z": -6,
      "name": "Nat20_Force_Empty"
    },
    {
      "x": -5,
      "y": 11,
      "z": -6,
      "name": "Nat20_Force_Empty"
    },
    {
      "x": -5,
      "y": 12,
      "z": -6,
      "name": "Nat20_Force_Empty"
    },
    {
      "x": -5,
      "y": 13,
      "z": -6,
      "name": "Nat20_Force_Empty"
    },
    {
      "x": -5,
      "y": 14,
      "z": -6,
      "name": "Nat20_Force_Empty"
    },
    {
      "x": -5,
      "y": 15,
      "z": -6,
      "name": "Nat20_Force_Empty"
    },
    {
      "x": -5,
      "y": 16,
      "z": -6,
      "name": "Nat20_Force_Empty"
    },
    {
      "x": -5,
      "y": 17,
      "z": -6,
      "name": "Nat20_Force_Empty"
    },
    {
      "x": -5,
      "y": 18,
      "z": -6,
      "name": "Nat20_Force_Empty"
    },
    {
      "x": -5,
      "y": 19,
      "z": -6,
      "name": "Nat20_Force_Empty"
    },
    {
      "x": -5,
      "y": 0,
      "z": -5,
      "name": "Soil_Dirt_Dry"
    },
    {
      "x": -5,
      "y": 1,
      "z": -5,
      "name": "Wood_Dry_Branch_Long"
    },
    {
      "x": -5,
      "y": 2,
      "z": -5,
      "name": "Wood_Dry_Branch_Long"
    },
    {
      "x": -5,
      "y": 3,
      "z": -5,
      "name": "Wood_Dry_Branch_Long"
    },
    {
      "x": -5,
      "y": 4,
      "z": -5,
      "name": "Wood_Dry_Trunk",
      "rotation": 5
    },
    {
      "x": -5,
      "y": 5,
      "z": -5,
      "name": "Nat20_Force_Empty"
    },
    {
      "x": -5,
      "y": 6,
      "z": -5,
      "name": "Nat20_Force_Empty"
    },
    {
      "x": -5,
      "y": 7,
      "z": -5,
      "name": "Nat20_Force_Empty"
    },
    {
      "x": -5,
      "y": 8,
      "z": -5,
      "name": "Nat20_Force_Empty"
    },
    {
      "x": -5,
      "y": 9,
      "z": -5,
      "name": "Nat20_Force_Empty"
    },
    {
      "x": -5,
      "y": 10,
      "z": -5,
      "name": "Nat20_Force_Empty"
    },
    {
      "x": -5,
      "y": 11,
      "z": -5,
      "name": "Nat20_Force_Empty"
    },
    {
      "x": -5,
      "y": 12,
      "z": -5,
      "name": "Nat20_Force_Empty"
    },
    {
      "x": -5,
      "y": 13,
      "z": -5,
      "name": "Nat20_Force_Empty"
    },
    {
      "x": -5,
      "y": 14,
      "z": -5,
      "name": "Nat20_Force_Empty"
    },
    {
      "x": -5,
      "y": 15,
      "z": -5,
      "name": "Nat20_Force_Empty"
    },
    {
      "x": -5,
      "y": 16,
      "z": -5,
      "name": "Nat20_Force_Empty"
    },
    {
      "x": -5,
      "y": 17,
      "z": -5,
      "name": "Nat20_Force_Empty"
    },
    {
      "x": -5,
      "y": 18,
      "z": -5,
      "name": "Nat20_Force_Empty"
    },
    {
      "x": -5,
      "y": 19,
      "z": -5,
      "name": "Nat20_Force_Empty"
    },
    {
      "x": -5,
      "y": 0,
      "z": -4,
      "name": "Soil_Dirt_Dry"
    },
    {
      "x": -5,
      "y": 1,
      "z": -4,
      "name": "Furniture_Village_Pot"
    },
    {
      "x": -5,
      "y": 2,
      "z": -4,
      "name": "Nat20_Force_Empty"
    },
    {
      "x": -5,
      "y": 3,
      "z": -4,
      "name": "Nat20_Force_Empty"
    },
    {
      "x": -5,
      "y": 4,
      "z": -4,
      "name": "Cloth_Roof_Blue",
      "rotation": 3
    },
    {
      "x": -5,
      "y": 5,
      "z": -4,
      "name": "Nat20_Force_Empty"
    },
    {
      "x": -5,
      "y": 6,
      "z": -4,
      "name": "Nat20_Force_Empty"
    },
    {
      "x": -5,
      "y": 7,
      "z": -4,
      "name": "Nat20_Force_Empty"
    },
    {
      "x": -5,
      "y": 8,
      "z": -4,
      "name": "Nat20_Force_Empty"
    },
    {
      "x": -5,
      "y": 9,
      "z": -4,
      "name": "Nat20_Force_Empty"
    },
    {
      "x": -5,
      "y": 10,
      "z": -4,
      "name": "Nat20_Force_Empty"
    },
    {
      "x": -5,
      "y": 11,
      "z": -4,
      "name": "Nat20_Force_Empty"
    },
    {
      "x": -5,
      "y": 12,
      "z": -4,
      "name": "Nat20_Force_Empty"
    },
    {
      "x": -5,
      "y": 13,
      "z": -4,
      "name": "Nat20_Force_Empty"
    },
    {
      "x": -5,
      "y": 14,
      "z": -4,
      "name": "Nat20_Force_Empty"
    },
    {
      "x": -5,
      "y": 15,
      "z": -4,
      "name": "Nat20_Force_Empty"
    },
    {
      "x": -5,
      "y": 16,
      "z": -4,
      "name": "Nat20_Force_Empty"
    },
    {
      "x": -5,
      "y": 17,
      "z": -4,
      "name": "Nat20_Force_Empty"
    },
    {
      "x": -5,
      "y": 18,
      "z": -4,
      "name": "Nat20_Force_Empty"
    },
    {
      "x": -5,
      "y": 19,
      "z": -4,
      "name": "Nat20_Force_Empty"
    },
    {
      "x": -5,
      "y": 0,
      "z": -3,
      "name": "Soil_Dirt_Dry"
    },
    {
      "x": -5,
      "y": 1,
      "z": -3,
      "name": "Nat20_Force_Empty"
    },
    {
      "x": -5,
      "y": 2,
      "z": -3,
      "name": "Nat20_Force_Empty"
    },
    {
      "x": -5,
      "y": 3,
      "z": -3,
      "name": "Nat20_Force_Empty"
    },
    {
      "x": -5,
      "y": 4,
      "z": -3,
      "name": "Cloth_Roof_Blue",
      "rotation": 3
    },
    {
      "x": -5,
      "y": 5,
      "z": -3,
      "name": "Nat20_Force_Empty"
    },
    {
      "x": -5,
      "y": 6,
      "z": -3,
      "name": "Nat20_Force_Empty"
    },
    {
      "x": -5,
      "y": 7,
      "z": -3,
      "name": "Nat20_Force_Empty"
    },
    {
      "x": -5,
      "y": 8,
      "z": -3,
      "name": "Nat20_Force_Empty"
    },
    {
      "x": -5,
      "y": 9,
      "z": -3,
      "name": "Nat20_Force_Empty"
    },
    {
      "x": -5,
      "y": 10,
      "z": -3,
      "name": "Nat20_Force_Empty"
    },
    {
      "x": -5,
      "y": 11,
      "z": -3,
      "name": "Nat20_Force_Empty"
    },
    {
      "x": -5,
      "y": 12,
      "z": -3,
      "name": "Nat20_Force_Empty"
    },
    {
      "x": -5,
      "y": 13,
      "z": -3,
      "name": "Nat20_Force_Empty"
    },
    {
      "x": -5,
      "y": 14,
      "z": -3,
      "name": "Nat20_Force_Empty"
    },
    {
      "x": -5,
      "y": 15,
      "z": -3,
      "name": "Nat20_Force_Empty"
    },
    {
      "x": -5,
      "y": 16,
      "z": -3,
      "name": "Nat20_Force_Empty"
    },
    {
      "x": -5,
      "y": 17,
      "z": -3,
      "name": "Nat20_Force_Empty"
    },
    {
      "x": -5,
      "y": 18,
      "z": -3,
      "name": "Nat20_Force_Empty"
    },
    {
      "x": -5,
      "y": 19,
      "z": -3,
      "name": "Nat20_Force_Empty"
    },
    {
      "x": -5,
      "y": 0,
      "z": -2,
      "name": "Soil_Dirt_Dry"
    },
    {
      "x": -5,
      "y": 1,
      "z": -2,
      "name": "Furniture_Crude_Stool"
    },
    {
      "x": -5,
      "y": 2,
      "z": -2,
      "name": "Nat20_Force_Empty"
    },
    {
      "x": -5,
      "y": 3,
      "z": -2,
