{
  "version": 8,
  "blockIdVersion": 11,
  "anchorX": 0,
  "anchorY": 0,
  "anchorZ": 0,
  "blocks": [
    {
      "x": -4,
      "y": 1,
      "z": -5,
      "name": "Nat20_Force_Empty"
    },
    {
      "x": -4,
      "y": 2,
      "z": -5,
      "name": "Nat20_Force_Empty"
    },
    {
      "x": -4,
      "y": 3,
      "z": -5,
      "name": "Nat20_Force_Empty"
    },
    {
      "x": -4,
      "y": 4,
      "z": -5,
      "name": "Nat20_Force_Empty"
    },
    {
      "x": -4,
      "y": 5,
      "z": -5,
      "name": "Nat20_Force_Empty"
    },
    {
      "x": -4,
      "y": 6,
      "z": -5,
      "name": "Nat20_Force_Empty"
    },
    {
      "x": -4,
      "y": 7,
      "z": -5,
      "name": "Nat20_Force_Empty"
    },
    {
      "x": -4,
      "y": 0,
      "z": -4,
      "name": "Rock_Stone"
    },
    {
      "x": -4,
      "y": 1,
      "z": -4,
      "name": "Rock_Stone"
    },
    {
      "x": -4,
      "y": 2,
      "z": -4,
      "name": "Rock_Stone"
    },
    {
      "x": -4,
      "y": 3,
      "z": -4,
      "name": "Nat20_Force_Empty"
    },
    {
      "x": -4,
      "y": 4,
      "z": -4,
      "name": "Nat20_Force_Empty"
    },
    {
      "x": -4,
      "y": 5,
      "z": -4,
      "name": "Nat20_Force_Empty"
    },
    {
      "x": -4,
      "y": 6,
      "z": -4,
      "name": "Nat20_Force_Empty"
    },
    {
      "x": -4,
      "y": 7,
      "z": -4,
      "name": "Nat20_Force_Empty"
    },
    {
      "x": -4,
      "y": 0,
      "z": -3,
      "name": "Rock_Stone"
    },
    {
      "x": -4,
      "y": 1,
      "z": -3,
      "name": "Rock_Stone"
    },
    {
      "x": -4,
      "y": 2,
      "z": -3,
      "name": "Rock_Stone"
    },
    {
      "x": -4,
      "y": 3,
      "z": -3,
      "name": "Rock_Stone"
    },
    {
      "x": -4,
      "y": 4,
      "z": -3,
      "name": "Nat20_Force_Empty"
    },
    {
      "x": -4,
      "y": 5,
      "z": -3,
      "name": "Nat20_Force_Empty"
    },
    {
      "x": -4,
      "y": 6,
      "z": -3,
      "name": "Nat20_Force_Empty"
    },
    {
      "x": -4,
      "y": 7,
      "z": -3,
      "name": "Nat20_Force_Empty"
    },
    {
      "x": -4,
      "y": 0,
      "z": -2,
      "name": "Rock_Stone"
    },
    {
      "x": -4,
      "y": 1,
      "z": -2,
      "name": "Rock_Stone"
    },
    {
      "x": -4,
      "y": 2,
      "z": -2,
      "name": "Rock_Stone"
    },
    {
      "x": -4,
      "y": 3,
      "z": -2,
      "name": "Nat20_Force_Empty"
    },
    {
      "x": -4,
      "y": 4,
      "z": -2,
      "name": "Nat20_Force_Empty"
    },
    {
      "x": -4,
      "y": 5,
      "z": -2,
      "name": "Nat20_Force_Empty"
    },
    {
      "x": -4,
      "y": 6,
      "z": -2,
      "name": "Nat20_Force_Empty"
    },
    {
      "x": -4,
      "y": 7,
      "z": -2,
      "name": "Nat20_Force_Empty"
    },
    {
      "x": -4,
      "y": 0,
      "z": -1,
      "name": "Soil_Pathway"
    },
    {
      "x": -4,
      "y": 1,
      "z": -1,
      "name": "Soil_Clay_Brick"
    },
    {
      "x": -4,
      "y": 2,
      "z": -1,
      "name": "Nat20_Force_Empty"
    },
    {
      "x": -4,
      "y": 3,
      "z": -1,
      "name": "Nat20_Force_Empty"
    },
    {
      "x": -4,
      "y": 4,
      "z": -1,
      "name": "Nat20_Force_Empty"
    },
    {
      "x": -4,
      "y": 5,
      "z": -1,
      "name": "Nat20_Force_Empty"
    },
    {
      "x": -4,
      "y": 6,
      "z": -1,
      "name": "Nat20_Force_Empty"
    },
    {
      "x": -4,
      "y": 7,
      "z": -1,
      "name": "Nat20_Force_Empty"
    },
    {
      "x": -4,
      "y": 0,
      "z": 0,
      "name": "Soil_Pathway"
    },
    {
      "x": -4,
      "y": 1,
      "z": 0,
      "name": "Soil_Clay_Brick"
    },
    {
      "x": -4,
      "y": 2,
      "z": 0,
      "name": "Nat20_Force_Empty"
    },
    {
      "x": -4,
      "y": 3,
      "z": 0,
      "name": "Nat20_Force_Empty"
    },
    {
      "x": -4,
      "y": 4,
      "z": 0,
      "name": "Nat20_Force_Empty"
    },
    {
      "x": -4,
      "y": 5,
      "z": 0,
      "name": "Nat20_Force_Empty"
    },
    {
      "x": -4,
      "y": 6,
      "z": 0,
      "name": "Nat20_Force_Empty"
    },
    {
      "x": -4,
      "y": 7,
      "z": 0,
      "name": "Nat20_Force_Empty"
    },
    {
      "x": -4,
      "y": 0,
      "z": 1,
      "name": "Soil_Pathway"
    },
    {
      "x": -4,
      "y": 1,
      "z": 1,
      "name": "Soil_Clay_Brick"
    },
    {
      "x": -4,
      "y": 2,
      "z": 1,
      "name": "Nat20_Force_Empty"
    },
    {
      "x": -4,
      "y": 3,
      "z": 1,
      "name": "Nat20_Force_Empty"
    },
    {
      "x": -4,
      "y": 4,
      "z": 1,
      "name": "Nat20_Force_Empty"
    },
    {
      "x": -4,
      "y": 5,
      "z": 1,
      "name": "Nat20_Force_Empty"
    },
    {
      "x": -4,
      "y": 6,
      "z": 1,
      "name": "Nat20_Force_Empty"
    },
    {
      "x": -4,
      "y": 7,
      "z": 1,
      "name": "Nat20_Force_Empty"
    },
    {
      "x": -4,
      "y": 0,
      "z": 2,
      "name": "Soil_Pathway"
    },
    {
      "x": -4,
      "y": 1,
      "z": 2,
      "name": "Rock_Stone_Cobble"
    },
    {
      "x": -4,
      "y": 2,
      "z": 2,
      "name": "Rock_Stone_Cobble"
    },
    {
      "x": -4,
      "y": 3,
      "z": 2,
      "name": "Rock_Stone_Cobble"
    },
    {
      "x": -4,
      "y": 4,
      "z": 2,
      "name": "Wood_Hardwood_Planks_Half"
    },
    {
      "x": -4,
      "y": 5,
      "z": 2,
      "name": "Nat20_Force_Empty"
    },
    {
      "x": -4,
      "y": 6,
      "z": 2,
      "name": "Nat20_Force_Empty"
    },
    {
      "x": -4,
      "y": 7,
      "z": 2,
      "name": "Nat20_Force_Empty"
    },
    {
      "x": -4,
      "y": 0,
      "z": 3,
      "name": "Rock_Stone"
    },
    {
      "x": -4,
      "y": 1,
      "z": 3,
      "name": "Rock_Stone"
    },
    {
      "x": -4,
      "y": 2,
      "z": 3,
      "name": "Rock_Stone"
    },
    {
      "x": -4,
      "y": 3,
      "z": 3,
      "name": "Wood_Beech_Trunk",
      "support": 15,
      "rotation": 5
    },
    {
      "x": -4,
      "y": 4,
      "z": 3,
      "name": "Wood_Hardwood_Planks_Half"
    },
    {
      "x": -4,
      "y": 5,
      "z": 3,
      "name": "Nat20_Force_Empty"
    },
    {
      "x": -4,
      "y": 6,
      "z": 3,
      "name": "Nat20_Force_Empty"
    },
    {
      "x": -4,
      "y": 7,
      "z": 3,
      "name": "Nat20_Force_Empty"
    },
    {
      "x": -4,
      "y": 0,
      "z": 4,
      "name": "Rock_Stone"
    },
    {
      "x": -4,
      "y": 1,
      "z": 4,
      "name": "Rock_Stone"
    },
    {
      "x": -4,
      "y": 2,
      "z": 4,
      "name": "Nat20_Force_Empty"
    },
    {
      "x": -4,
      "y": 3,
      "z": 4,
      "name": "Nat20_Force_Empty"
    },
    {
      "x": -4,
      "y": 4,
      "z": 4,
      "name": "Nat20_Force_Empty"
    },
    {
      "x": -4,
      "y": 5,
      "z": 4,
      "name": "Nat20_Force_Empty"
    },
    {
      "x": -4,
      "y": 6,
      "z": 4,
      "name": "Nat20_Force_Empty"
    },
    {
      "x": -4,
      "y": 7,
      "z": 4,
      "name": "Nat20_Force_Empty"
    },
    {
      "x": -3,
      "y": 0,
      "z": -5,
      "name": "Rock_Stone"
    },
    {
      "x": -3,
      "y": 1,
      "z": -5,
      "name": "Rock_Stone"
    },
    {
      "x": -3,
      "y": 2,
      "z": -5,
      "name": "Rock_Stone"
    },
    {
      "x": -3,
      "y": 3,
      "z": -5,
      "name": "Nat20_Force_Empty"
    },
    {
      "x": -3,
      "y": 4,
      "z": -5,
      "name": "Nat20_Force_Empty"
    },
    {
      "x": -3,
      "y": 5,
      "z": -5,
      "name": "Wood_Softwood_Stairs",
      "rotation": 3
    },
    {
      "x": -3,
      "y": 6,
      "z": -5,
      "name": "Nat20_Force_Empty"
    },
    {
      "x": -3,
      "y": 7,
      "z": -5,
      "name": "Nat20_Force_Empty"
    },
    {
      "x": -3,
      "y": 0,
      "z": -4,
      "name": "Rock_Volcanic_Brick"
    },
    {
      "x": -3,
      "y": 1,
      "z": -4,
      "name": "Rock_Volcanic_Brick"
    },
    {
      "x": -3,
      "y": 2,
      "z": -4,
      "name": "Rock_Volcanic_Brick"
    },
    {
      "x": -3,
      "y": 3,
      "z": -4,
      "name": "Rock_Volcanic_Brick"
    },
    {
      "x": -3,
      "y": 4,
      "z": -4,
      "name": "Rock_Volcanic_Brick"
    },
    {
      "x": -3,
      "y": 5,
      "z": -4,
      "name": "Wood_Beech_Trunk",
      "support": 15,
      "rotation": 5
    },
    {
      "x": -3,
      "y": 6,
      "z": -4,
      "name": "Nat20_Force_Empty"
    },
    {
      "x": -3,
      "y": 7,
      "z": -4,
      "name": "Nat20_Force_Empty"
    },
    {
      "x": -3,
      "y": 0,
      "z": -3,
      "name": "Rock_Volcanic_Brick"
    },
    {
      "x": -3,
      "y": 1,
      "z": -3,
      "name": "Rock_Volcanic_Brick"
    },
    {
      "x": -3,
      "y": 2,
      "z": -3,
      "name": "Rock_Volcanic_Brick"
    },
    {
      "x": -3,
      "y": 3,
      "z": -3,
      "name": "Rock_Volcanic_Brick"
    },
    {
      "x": -3,
      "y": 4,
      "z": -3,
      "name": "Rock_Volcanic_Brick"
    },
    {
      "x": -3,
      "y": 5,
      "z": -3,
      "name": "Wood_Beech_Trunk",
      "support": 15,
      "rotation": 4
    },
    {
      "x": -3,
      "y": 6,
      "z": -3,
      "name": "Nat20_Force_Empty"
    },
    {
      "x": -3,
      "y": 7,
      "z": -3,
      "name": "Nat20_Force_Empty"
    },
    {
      "x": -3,
      "y": 0,
      "z": -2,
      "name": "Rock_Volcanic_Brick"
    },
    {
      "x": -3,
      "y": 1,
      "z": -2,
      "name": "Rock_Volcanic_Brick"
    },
    {
      "x": -3,
      "y": 2,
      "z": -2,
      "name": "Rock_Volcanic_Brick"
    },
    {
      "x": -3,
      "y": 3,
      "z": -2,
      "name": "Rock_Volcanic_Brick"
    },
    {
      "x": -3,
      "y": 4,
      "z": -2,
      "name": "Rock_Volcanic_Brick"
    },
    {
      "x": -3,
      "y": 5,
      "z": -2,
      "name": "Wood_Beech_Trunk",
      "support": 15,
      "rotation": 4
    },
    {
      "x": -3,
      "y": 6,
      "z": -2,
      "name": "Nat20_Force_Empty"
    },
    {
      "x": -3,
      "y": 7,
      "z": -2,
      "name": "Nat20_Force_Empty"
    },
    {
      "x": -3,
      "y": 0,
      "z": -1,
      "name": "Rock_Volcanic_Brick"
    },
    {
      "x": -3,
      "y": 1,
      "z": -1,
      "name": "Rock_Volcanic_Brick"
    },
    {
      "x": -3,
      "y": 2,
      "z": -1,
      "name": "Rock_Volcanic_Brick_Wall",
      "rotation": 3
    },
    {
      "x": -3,
      "y": 3,
      "z": -1,
      "name": "Rock_Volcanic_Brick_Wall",
      "rotation": 3
    },
    {
      "x": -3,
      "y": 4,
      "z": -1,
      "name": "Rock_Volcanic_Brick"
    },
    {
      "x": -3,
      "y": 5,
      "z": -1,
      "name": "Wood_Beech_Trunk",
      "support": 15,
      "rotation": 4
    },
    {
      "x": -3,
      "y": 6,
      "z": -1,
      "name": "Nat20_Force_Empty"
    },
    {
      "x": -3,
      "y": 7,
      "z": -1,
      "name": "Nat20_Force_Empty"
    },
    {
      "x": -3,
      "y": 0,
      "z": 0,
      "name": "Rock_Volcanic_Brick"
    },
    {
      "x": -3,
      "y": 1,
      "z": 0,
      "name": "Rock_Volcanic_Brick"
    },
    {
      "x": -3,
      "y": 2,
      "z": 0,
      "name": "Rock_Volcanic_Brick_Wall",
      "rotation": 3
    },
    {
      "x": -3,
      "y": 3,
      "z": 0,
      "name": "Rock_Volcanic_Brick_Wall",
      "rotation": 3
    },
    {
      "x": -3,
      "y": 4,
      "z": 0,
      "name": "Rock_Volcanic_Brick"
    },
    {
      "x": -3,
      "y": 5,
      "z": 0,
      "name": "Wood_Beech_Trunk",
      "support": 15,
      "rotation": 4
    },
    {
      "x": -3,
      "y": 6,
      "z": 0,
      "name": "Nat20_Force_Empty"
    },
    {
      "x": -3,
      "y": 7,
      "z": 0,
      "name": "Nat20_Force_Empty"
    },
    {
      "x": -3,
      "y": 0,
      "z": 1,
      "name": "Rock_Volcanic_Brick"
    },
    {
      "x": -3,
      "y": 1,
      "z": 1,
      "name": "Rock_Volcanic_Brick"
    },
    {
      "x": -3,
      "y": 2,
      "z": 1,
      "name": "Rock_Volcanic_Brick"
    },
    {
      "x": -3,
      "y": 3,
      "z": 1,
      "name": "Rock_Volcanic_Brick"
    },
    {
      "x": -3,
      "y": 4,
      "z": 1,
      "name": "Rock_Volcanic_Brick"
    },
    {
      "x": -3,
      "y": 5,
      "z": 1,
      "name": "Wood_Beech_Trunk",
      "support": 15,
      "rotation": 4
    },
    {
      "x": -3,
      "y": 6,
      "z": 1,
      "name": "Nat20_Force_Empty"
    },
    {
      "x": -3,
      "y": 7,
      "z": 1,
      "name": "Nat20_Force_Empty"
    },
    {
      "x": -3,
      "y": 0,
      "z": 2,
      "name": "Rock_Volcanic_Brick"
    },
    {
      "x": -3,
      "y": 1,
      "z": 2,
      "name": "Rock_Volcanic_Brick"
    },
    {
      "x": -3,
      "y": 2,
      "z": 2,
      "name": "Rock_Volcanic_Brick"
    },
    {
      "x": -3,
      "y": 3,
      "z": 2,
      "name": "Rock_Volcanic_Brick"
    },
    {
      "x": -3,
      "y": 4,
      "z": 2,
      "name": "Rock_Volcanic_Brick"
    },
    {
      "x": -3,
      "y": 5,
      "z": 2,
      "name": "Wood_Beech_Trunk",
      "support": 15,
      "rotation": 4
    },
    {
      "x": -3,
      "y": 6,
      "z": 2,
      "name": "Plant_Leaves_Bramble"
    },
    {
      "x": -3,
      "y": 7,
      "z": 2,
      "name": "Nat20_Force_Empty"
    },
    {
      "x": -3,
      "y": 0,
      "z": 3,
      "name": "Rock_Volcanic_Brick"
    },
    {
      "x": -3,
      "y": 1,
      "z": 3,
      "name": "Rock_Volcanic_Brick"
    },
    {
      "x": -3,
      "y": 2,
      "z": 3,
      "name": "Rock_Volcanic_Brick"
    },
    {
      "x": -3,
      "y": 3,
      "z": 3,
      "name": "Rock_Volcanic_Brick"
    },
    {
      "x": -3,
      "y": 4,
      "z": 3,
      "name": "Rock_Volcanic_Brick"
    },
    {
      "x": -3,
      "y": 5,
      "z": 3,
      "name": "Wood_Beech_Trunk",
      "support": 15,
      "rotation": 5
    },
    {
      "x": -3,
      "y": 6,
      "z": 3,
      "name": "Wood_Softwood_Stairs",
      "rotation": 1
    },
    {
      "x": -3,
      "y": 7,
      "z": 3,
      "name": "Nat20_Force_Empty"
    },
    {
      "x": -3,
      "y": 0,
      "z": 4,
      "name": "Rock_Stone"
    },
    {
      "x": -3,
      "y": 1,
      "z": 4,
      "name": "Wood_Beech_Trunk",
      "support": 15
    },
    {
      "x": -3,
      "y": 2,
      "z": 4,
      "name": "Wood_Beech_Trunk",
      "support": 15
    },
    {
      "x": -3,
      "y": 3,
      "z": 4,
      "name": "Wood_Beech_Trunk",
      "support": 15
    },
    {
      "x": -3,
      "y": 4,
      "z": 4,
      "name": "Wood_Beech_Branch_Long",
      "support": 15
    },
    {
      "x": -3,
      "y": 5,
      "z": 4,
      "name": "Wood_Softwood_Beam"
    },
    {
      "x": -3,
      "y": 6,
      "z": 4,
      "name": "Nat20_Force_Empty"
    },
    {
      "x": -3,
      "y": 7,
      "z": 4,
      "name": "Nat20_Force_Empty"
    },
    {
      "x": -2,
      "y": 0,
      "z": -5,
      "name": "Rock_Stone"
    },
    {
      "x": -2,
      "y": 1,
      "z": -5,
      "name": "Rock_Stone"
    },
    {
      "x": -2,
      "y": 2,
      "z": -5,
      "name": "Rock_Stone"
    },
    {
      "x": -2,
      "y": 3,
      "z": -5,
      "name": "Rock_Stone"
    },
    {
      "x": -2,
      "y": 4,
      "z": -5,
      "name": "Wood_Beech_Trunk",
      "support": 15,
      "rotation": 5
    },
    {
      "x": -2,
      "y": 5,
      "z": -5,
      "name": "Wood_Softwood_Planks_Half"
    },
    {
      "x": -2,
      "y": 6,
      "z": -5,
      "name": "Deco_Bone_Ribs",
      "rotation": 2
    },
    {
      "x": -2,
      "y": 7,
      "z": -5,
      "name": "Nat20_Force_Empty"
    },
    {
      "x": -2,
      "y": 0,
      "z": -4,
      "name": "Rock_Volcanic_Brick"
    },
    {
      "x": -2,
      "y": 1,
      "z": -4,
      "name": "Rock_Volcanic_Brick"
    },
    {
      "x": -2,
      "y": 2,
      "z": -4,
      "name": "Rock_Volcanic_Brick"
    },
    {
      "x": -2,
      "y": 3,
      "z": -4,
      "name": "Rock_Volcanic_Brick"
    },
    {
      "x": -2,
      "y": 4,
      "z": -4,
      "name": "Rock_Volcanic_Brick"
    },
    {
      "x": -2,
      "y": 5,
      "z": -4,
      "name": "Rock_Volcanic_Brick"
    },
    {
      "x": -2,
      "y": 6,
      "z": -4,
      "name": "Deco_Bone_Full",
      "rotation": 4
    },
    {
      "x": -2,
      "y": 7,
      "z": -4,
      "name": "Nat20_Force_Empty"
    },
    {
      "x": -2,
      "y": 0,
      "z": -3,
      "name": "Rock_Stone"
    },
    {
      "x": -2,
      "y": 1,
      "z": -3,
      "name": "Rock_Stone"
    },
    {
      "x": -2,
      "y": 2,
      "z": -3,
      "name": "Rock_Stone"
    },
    {
      "x": -2,
      "y": 3,
      "z": -3,
      "name": "Wood_Beech_Trunk",
      "support": 15
    },
    {
      "x": -2,
      "y": 4,
      "z": -3,
      "name": "Wood_Beech_Trunk",
      "support": 15
    },
    {
      "x": -2,
      "y": 5,
      "z": -3,
      "name": "Rock_Volcanic_Brick"
    },
    {
      "x": -2,
      "y": 6,
      "z": -3,
      "name": "Deco_Bone_Full",
      "rotation": 4
    },
    {
      "x": -2,
      "y": 7,
      "z": -3,
      "name": "Nat20_Force_Empty"
    },
    {
      "x": -2,
      "y": 0,
      "z": -2,
      "name": "Soil_Pathway"
    },
    {
      "x": -2,
      "y": 1,
      "z": -2,
      "name": "Furniture_Lumberjack_Chest_Small",
      "components": {
        "Components": {
          "ItemContainerBlock": {
            "ItemContainer": {
              "Capacity": 18,
              "Items": {
                "7": {
                  "Id": "Tool_Hatchet_Crude",
                  "Quantity": 1,
                  "Durability": 150.0,
                  "MaxDurability": 150.0,
                  "OverrideDroppedItemAnimation": false
                },
                "6": {
                  "Id": "Ingredient_Charcoal",
                  "Quantity": 7,
                  "Durability": 0.0,
                  "MaxDurability": 0.0,
                  "OverrideDroppedItemAnimation": false
                },
                "4": {
                  "Id": "Food_Wildmeat_Cooked",
                  "Quantity": 1,
                  "Durability": 0.0,
                  "MaxDurability": 0.0,
                  "OverrideDroppedItemAnimation": false
                },
                "12": {
                  "Id": "Ingredient_Bar_Silver",
                  "Quantity": 2,
                  "Durability": 0.0,
                  "MaxDurability": 0.0,
                  "OverrideDroppedItemAnimation": false
                },
                "8": {
                  "Id": "Food_Beef_Raw",
                  "Quantity": 2,
                  "Durability": 0.0,
                  "MaxDurability": 0.0,
                  "OverrideDroppedItemAnimation": false
                },
                "9": {
                  "Id": "Ore_Copper",
                  "Quantity": 2,
                  "Durability": 0.0,
                  "MaxDurability": 0.0,
                  "OverrideDroppedItemAnimation": false
                },
                "11": {
                  "Id": "Food_Fish_Grilled",
                  "Quantity": 2,
                  "Durability": 0.0,
                  "MaxDurability": 0.0,
                  "OverrideDroppedItemAnimation": false
                },
                "10": {
                  "Id": "Plant_Seeds_Carrot",
                  "Quantity": 2,
                  "Durability": 0.0,
                  "MaxDurability": 0.0,
                  "OverrideDroppedItemAnimation": false
                }
              }
            },
            "Capacity": 20
          }
        }
      },
      "rotation": 1
    },
    {
      "x": -2,
      "y": 2,
      "z": -2,
      "name": "Furniture_Crude_Shelf"
    },
    {
      "x": -2,
      "y": 3,
      "z": -2,
      "name": "Furniture_Tavern_Shelf"
    },
    {
      "x": -2,
      "y": 4,
      "z": -2,
      "name": "Nat20_Force_Empty"
    },
    {
      "x": -2,
      "y": 5,
      "z": -2,
      "name": "Rock_Volcanic_Brick"
    },
    {
      "x": -2,
      "y": 6,
      "z": -2,
      "name": "Plant_Leaves_Bramble"
    },
    {
      "x": -2,
      "y": 7,
      "z": -2,
      "name": "Nat20_Force_Empty"
    },
    {
      "x": -2,
      "y": 0,
      "z": -1,
      "name": "Soil_Pathway"
    },
    {
      "x": -2,
      "y": 1,
      "z": -1,
      "name": "Nat20_Force_Empty"
    },
    {
      "x": -2,
      "y": 2,
      "z": -1,
      "name": "Nat20_Force_Empty"
    },
    {
      "x": -2,
      "y": 3,
      "z": -1,
      "name": "Nat20_Force_Empty"
    },
    {
      "x": -2,
      "y": 4,
      "z": -1,
      "name": "Nat20_Force_Empty"
    },
    {
      "x": -2,
      "y": 5,
      "z": -1,
      "name": "Rock_Volcanic_Brick"
    },
    {
      "x": -2,
      "y": 6,
      "z": -1,
      "name": "Cloth_Roof_Leather",
      "rotation": 3
    },
    {
      "x": -2,
      "y": 7,
      "z": -1,
      "name": "Nat20_Force_Empty"
    },
    {
      "x": -2,
      "y": 0,
      "z": 0,
      "name": "Soil_Pathway"
    },
    {
      "x": -2,
      "y": 1,
      "z": 0,
      "name": "Nat20_Force_Empty"
    },
    {
      "x": -2,
      "y": 2,
      "z": 0,
      "name": "Nat20_Force_Empty"
    },
    {
      "x": -2,
      "y": 3,
      "z": 0,
      "name": "Nat20_Force_Empty"
    },
    {
      "x": -2,
      "y": 4,
      "z": 0,
      "name": "Nat20_Force_Empty"
    },
    {
      "x": -2,
      "y": 5,
      "z": 0,
      "name": "Rock_Volcanic_Brick"
    },
    {
      "x": -2,
      "y": 6,
      "z": 0,
      "name": "Cloth_Roof_Leather",
      "rotation": 3
    },
    {
      "x": -2,
      "y": 7,
      "z": 0,
      "name": "Nat20_Force_Empty"
    },
    {
      "x": -2,
      "y": 0,
      "z": 1,
      "name": "Soil_Pathway"
    },
    {
      "x": -2,
      "y": 1,
      "z": 1,
      "name": "Nat20_Force_Empty"
    },
    {
      "x": -2,
      "y": 2,
      "z": 1,
      "name": "Nat20_Force_Empty"
    },
    {
      "x": -2,
      "y": 3,
      "z": 1,
      "name": "Nat20_Force_Empty"
    },
    {
      "x": -2,
      "y": 4,
      "z": 1,
      "name": "Nat20_Force_Empty"
    },
    {
      "x": -2,
      "y": 5,
      "z": 1,
      "name": "Rock_Volcanic_Brick"
    },
    {
      "x": -2,
      "y": 6,
      "z": 1,
      "name": "Cloth_Roof_Leather",
      "rotation": 3
    },
    {
      "x": -2,
      "y": 7,
      "z": 1,
      "name": "Plant_Leaves_Bramble"
    },
    {
      "x": -2,
      "y": 0,
      "z": 2,
      "name": "Soil_Pathway"
    },
    {
      "x": -2,
      "y": 1,
      "z": 2,
      "name": "Nat20_Force_Empty"
    },
    {
      "x": -2,
      "y": 2,
      "z": 2,
      "name": "Nat20_Force_Empty"
    },
    {
      "x": -2,
      "y": 3,
      "z": 2,
      "name": "Nat20_Force_Empty"
    },
    {
      "x": -2,
      "y": 4,
      "z": 2,
      "name": "Nat20_Force_Empty"
    },
    {
      "x": -2,
      "y": 5,
      "z": 2,
      "name": "Rock_Volcanic_Brick"
    },
    {
      "x": -2,
      "y": 6,
      "z": 2,
      "name": "Plant_Leaves_Bramble"
    },
    {
      "x": -2,
      "y": 7,
      "z": 2,
      "name": "Nat20_Force_Empty"
    },
    {
      "x": -2,
      "y": 0,
      "z": 3,
      "name": "Rock_Volcanic_Brick"
    },
    {
      "x": -2,
      "y": 1,
      "z": 3,
      "name": "Rock_Volcanic_Brick"
    },
    {
      "x": -2,
      "y": 2,
      "z": 3,
      "name": "Rock_Volcanic_Brick"
    },
    {
      "x": -2,
      "y": 3,
      "z": 3,
      "name": "Rock_Volcanic_Brick"
    },
    {
      "x": -2,
      "y": 4,
      "z": 3,
      "name": "Rock_Volcanic_Brick"
    },
    {
      "x": -2,
      "y": 5,
      "z": 3,
      "name": "Rock_Volcanic_Brick"
    },
    {
      "x": -2,
      "y": 6,
      "z": 3,
      "name": "Wood_Softwood_Stairs",
      "rotation": 1
    },
    {
      "x": -2,
      "y": 7,
      "z": 3,
      "name": "Nat20_Force_Empty"
    },
    {
      "x": -2,
      "y": 0,
      "z": 4,
      "name": "Rock_Stone"
    },
    {
      "x": -2,
      "y": 1,
      "z": 4,
      "name": "Rock_Stone"
    },
    {
      "x": -2,
      "y": 2,
      "z": 4,
      "name": "Rock_Stone"
    },
    {
      "x": -2,
      "y": 3,
      "z": 4,
      "name": "Furniture_Crude_Sign"
    },
    {
      "x": -2,
      "y": 4,
      "z": 4,
      "name": "Deco_Bone_Ribs",
      "rotation": 3
    },
    {
      "x": -2,
      "y": 5,
      "z": 4,
      "name": "Deco_Bone_Full",
      "rotation": 4
    },
    {
      "x": -2,
      "y": 6,
      "z": 4,
      "name": "Nat20_Force_Empty"
    },
    {
      "x": -2,
      "y": 7,
      "z": 4,
      "name": "Nat20_Force_Empty"
    },
    {
      "x": -2,
      "y": 5,
      "z": 5,
      "name": "Deco_Bone_Ribs_Long",
      "rotation": 4
    },
    {
      "x": -2,
      "y": 5,
      "z": 6,
      "name": "Deco_Bone_Ribs"
    },
    {
      "x": -1,
      "y": 0,
      "z": -5,
      "name": "Rock_Stone"
    },
    {
      "x": -1,
      "y": 1,
      "z": -5,
      "name": "Rock_Stone"
    },
    {
      "x": -1,
      "y": 2,
      "z": -5,
      "name": "Rock_Stone"
    },
    {
      "x": -1,
      "y": 3,
      "z": -5,
      "name": "Rock_Stone"
    },
    {
      "x": -1,
      "y": 4,
      "z": -5,
      "name": "Wood_Beech_Trunk",
      "support": 15,
      "rotation": 5
    },
    {
      "x": -1,
      "y": 5,
      "z": -5,
      "name": "Plant_Leaves_Bramble"
    },
    {
      "x": -1,
      "y": 6,
      "z": -5,
      "name": "Nat20_Force_Empty"
    },
    {
      "x": -1,
      "y": 7,
      "z": -5,
      "name": "Nat20_Force_Empty"
    },
    {
      "x": -1,
      "y": 0,
      "z": -4,
      "name": "Rock_Volcanic_Brick"
    },
    {
      "x": -1,
      "y": 1,
      "z": -4,
      "name": "Rock_Volcanic_Brick"
    },
    {
      "x": -1,
      "y": 2,
      "z": -4,
      "name": "Rock_Volcanic_Brick"
    },
    {
      "x": -1,
      "y": 3,
      "z": -4,
      "name": "Rock_Volcanic_Brick"
    },
    {
      "x": -1,
      "y": 4,
      "z": -4,
      "name": "Rock_Volcanic_Brick"
    },
    {
      "x": -1,
      "y": 5,
      "z": -4,
      "name": "Rock_Volcanic_Brick"
    },
    {
      "x": -1,
      "y": 6,
      "z": -4,
      "name": "Nat20_Force_Empty"
    },
    {
      "x": -1,
      "y": 7,
      "z": -4,
      "name": "Nat20_Force_Empty"
    },
    {
      "x": -1,
      "y": 0,
      "z": -3,
      "name": "Rock_Stone"
    },
    {
      "x": -1,
      "y": 1,
      "z": -3,
      "name": "Rock_Stone"
    },
    {
      "x": -1,
      "y": 2,
      "z": -3,
      "name": "Nat20_Chest_Spawn"
    },
    {
      "x": -1,
      "y": 3,
      "z": -3,
      "name": "Furniture_Village_Shelf_Full"
    },
    {
      "x": -1,
      "y": 4,
      "z": -3,
      "name": "Nat20_Force_Empty"
    },
    {
      "x": -1,
      "y": 5,
      "z": -3,
      "name": "Rock_Volcanic_Brick"
    },
    {
      "x": -1,
      "y": 6,
      "z": -3,
      "name": "Plant_Leaves_Bramble"
    },
    {
      "x": -1,
      "y": 7,
      "z": -3,
      "name": "Nat20_Force_Empty"
    },
    {
      "x": -1,
      "y": 0,
      "z": -2,
      "name": "Soil_Pathway"
    },
    {
      "x": -1,
      "y": 1,
      "z": -2,
      "name": "Nat20_Force_Empty"
    },
    {
      "x": -1,
      "y": 2,
      "z": -2,
      "name": "Nat20_Force_Empty"
    },
    {
      "x": -1,
      "y": 3,
      "z": -2,
      "name": "Nat20_Force_Empty"
    },
    {
      "x": -1,
      "y": 4,
      "z": -2,
      "name": "Nat20_Force_Empty"
    },
    {
      "x": -1,
      "y": 5,
      "z": -2,
      "name": "Rock_Volcanic_Brick"
    },
    {
      "x": -1,
      "y": 6,
      "z": -2,
      "name": "Cloth_Roof_Leather",
      "rotation": 2
    },
    {
      "x": -1,
      "y": 7,
      "z": -2,
      "name": "Nat20_Force_Empty"
    },
    {
      "x": -1,
      "y": 0,
      "z": -1,
      "name": "Soil_Pathway"
    },
    {
      "x": -1,
      "y": 1,
      "z": -1,
      "name": "Nat20_Force_Empty"
    },
    {
      "x": -1,
      "y": 2,
      "z": -1,
      "name": "Nat20_Force_Empty"
    },
    {
      "x": -1,
      "y": 3,
      "z": -1,
      "name": "Nat20_Force_Empty"
    },
    {
      "x": -1,
      "y": 4,
      "z": -1,
      "name": "Nat20_Force_Empty"
    },
    {
      "x": -1,
      "y": 5,
      "z": -1,
      "name": "Rock_Volcanic_Brick"
    },
    {
      "x": -1,
      "y": 6,
      "z": -1,
      "name": "Nat20_Force_Empty"
    },
    {
      "x": -1,
      "y": 7,
      "z": -1,
      "name": "*Cloth_Roof_Leather_State_Definitions_Corner_Right",
      "rotation": 3
    },
    {
      "x": -1,
      "y": 0,
      "z": 0,
      "name": "Soil_Pathway"
    },
    {
      "x": -1,
      "y": 1,
      "z": 0,
      "name": "Nat20_Force_Empty"
    },
    {
      "x": -1,
      "y": 2,
      "z": 0,
      "name": "Nat20_Force_Empty"
    },
    {
      "x": -1,
      "y": 3,
      "z": 0,
      "name": "Nat20_Force_Empty"
    },
    {
      "x": -1,
      "y": 4,
      "z": 0,
      "name": "Nat20_Force_Empty"
    },
    {
      "x": -1,
      "y": 5,
      "z": 0,
      "name": "Rock_Volcanic_Brick"
    },
    {
      "x": -1,
      "y": 6,
      "z": 0,
      "name": "Nat20_Force_Empty"
    },
    {
      "x": -1,
      "y": 7,
      "z": 0,
      "name": "Cloth_Roof_Leather",
      "rotation": 3
    },
    {
      "x": -1,
      "y": 0,
      "z": 1,
      "name": "Soil_Pathway"
    },
    {
      "x": -1,
      "y": 1,
      "z": 1,
      "name": "Nat20_Force_Empty"
    },
    {
      "x": -1,
      "y": 2,
      "z": 1,
      "name": "Nat20_Force_Empty"
    },
    {
      "x": -1,
      "y": 3,
      "z": 1,
      "name": "Nat20_Force_Empty"
    },
    {
      "x": -1,
      "y": 4,
      "z": 1,
      "name": "Nat20_Force_Empty"
    },
    {
      "x": -1,
      "y": 5,
      "z": 1,
      "name": "Rock_Volcanic_Brick"
    },
    {
      "x": -1,
      "y": 6,
      "z": 1,
      "name": "Nat20_Force_Empty"
    },
    {
      "x": -1,
      "y": 7,
      "z": 1,
      "name": "*Cloth_Roof_Leather_State_Definitions_Corner_Right"
    },
    {
      "x": -1,
      "y": 0,
      "z": 2,
      "name": "Soil_Pathway"
    },
    {
      "x": -1,
      "y": 1,
      "z": 2,
      "name": "Nat20_Force_Empty"
    },
    {
      "x": -1,
      "y": 2,
      "z": 2,
      "name": "Nat20_Force_Empty"
    },
    {
      "x": -1,
      "y": 3,
      "z": 2,
      "name": "Nat20_Force_Empty"
    },
    {
      "x": -1,
      "y": 4,
      "z": 2,
      "name": "Nat20_Force_Empty"
    },
    {
      "x": -1,
      "y": 5,
      "z": 2,
      "name": "Rock_Volcanic_Brick"
    },
    {
      "x": -1,
      "y": 6,
      "z": 2,
      "name": "Plant_Leaves_Bramble"
    },
    {
      "x": -1,
      "y": 7,
      "z": 2,
      "name": "Plant_Leaves_Bramble"
    },
    {
      "x": -1,
      "y": 0,
      "z": 3,
      "name": "Rock_Volcanic_Brick"
    },
    {
      "x": -1,
      "y": 1,
      "z": 3,
      "name": "Rock_Volcanic_Brick_Wall"
    },
    {
      "x": -1,
      "y": 2,
      "z": 3,
      "name": "Rock_Volcanic_Brick_Wall"
    },
    {
      "x": -1,
      "y": 3,
      "z": 3,
      "name": "Rock_Volcanic_Brick"
    },
    {
      "x": -1,
      "y": 4,
      "z": 3,
      "name": "Rock_Volcanic_Brick"
    },
    {
      "x": -1,
      "y": 5,
      "z": 3,
      "name": "Wood_Softwood_Planks"
    },
    {
      "x": -1,
      "y": 6,
      "z": 3,
      "name": "Wood_Softwood_Planks_Half"
    },
    {
      "x": -1,
      "y": 7,
      "z": 3,
      "name": "Nat20_Force_Empty"
    },
    {
      "x": -1,
      "y": 0,
      "z": 4,
      "name": "Soil_Dirt"
    },
    {
      "x": -1,
      "y": 1,
      "z": 4,
      "name": "Nat20_Force_Empty"
    },
    {
      "x": -1,
      "y": 2,
      "z": 4,
      "name": "Nat20_Force_Empty"
    },
    {
      "x": -1,
      "y": 3,
      "z": 4,
      "name": "Nat20_Force_Empty"
    },
    {
      "x": -1,
      "y": 4,
      "z": 4,
      "name": "Deco_Bone_Ribs",
      "rotation": 11
    },
    {
      "x": -1,
      "y": 5,
      "z": 4,
      "name": "Nat20_Force_Empty"
    },
    {
      "x": -1,
      "y": 6,
      "z": 4,
      "name": "Nat20_Force_Empty"
    },
    {
      "x": -1,
      "y": 7,
      "z": 4,
      "name": "Nat20_Force_Empty"
    },
    {
      "x": 0,
      "y": 0,
      "z": -5,
      "name": "Soil_Pathway"
    },
    {
      "x": 0,
      "y": 1,
      "z": -5,
      "name": "Rock_Stone_Cobble"
    },
    {
      "x": 0,
      "y": 2,
      "z": -5,
      "name": "Rock_Stone_Cobble"
    },
    {
      "x": 0,
      "y": 3,
      "z": -5,
      "name": "Rock_Stone_Cobble"
    },
    {
      "x": 0,
      "y": 4,
      "z": -5,
      "name": "Wood_Beech_Trunk",
      "support": 15,
      "rotation": 5
    },
    {
      "x": 0,
      "y": 5,
      "z": -5,
      "name": "Wood_Softwood_Planks_Half"
    },
    {
      "x": 0,
      "y": 6,
      "z": -5,
      "name": "Nat20_Force_Empty"
    },
    {
      "x": 0,
      "y": 7,
      "z": -5,
      "name": "Nat20_Force_Empty"
    },
    {
      "x": 0,
      "y": 0,
      "z": -4,
      "name": "Rock_Volcanic_Brick"
    },
    {
      "x": 0,
      "y": 1,
      "z": -4,
      "name": "Rock_Volcanic_Brick"
    },
    {
      "x": 0,
      "y": 2,
      "z": -4,
      "name": "Rock_Volcanic_Brick"
    },
    {
      "x": 0,
      "y": 3,
      "z": -4,
      "name": "Rock_Volcanic_Brick"
    },
    {
      "x": 0,
      "y": 4,
      "z": -4,
      "name": "Rock_Volcanic_Brick"
    },
    {
      "x": 0,
      "y": 5,
      "z": -4,
      "name": "Rock_Volcanic_Brick"
    },
    {
      "x": 0,
      "y": 6,
      "z": -4,
      "name": "Nat20_Force_Empty"
    },
    {
      "x": 0,
      "y": 7,
      "z": -4,
      "name": "Nat20_Force_Empty"
    },
    {
      "x": 0,
      "y": 0,
      "z": -3,
      "name": "Soil_Pathway"
    },
    {
      "x": 0,
      "y": 1,
      "z": -3,
      "name": "Furniture_Tavern_Shelf"
    },
    {
      "x": 0,
      "y": 2,
      "z": -3,
      "name": "Furniture_Crude_Shelf"
    },
    {
      "x": 0,
      "y": 3,
      "z": -3,
      "name": "Furniture_Village_Shelf_Full"
    },
    {
      "x": 0,
      "y": 4,
      "z": -3,
      "name": "Nat20_Force_Empty"
    },
    {
      "x": 0,
      "y": 5,
      "z": -3,
      "name": "Rock_Volcanic_Brick"
    },
    {
      "x": 0,
      "y": 6,
      "z": -3,
      "name": "Nat20_Force_Empty"
    },
    {
      "x": 0,
      "y": 7,
      "z": -3,
      "name": "Nat20_Force_Empty"
    },
    {
      "x": 0,
      "y": 0,
      "z": -2,
      "name": "Soil_Pathway"
    },
    {
      "x": 0,
      "y": 1,
      "z": -2,
      "name": "Nat20_Force_Empty"
    },
    {
      "x": 0,
      "y": 2,
      "z": -2,
      "name": "Nat20_Force_Empty"
    },
    {
      "x": 0,
      "y": 3,
      "z": -2,
      "name": "Nat20_Force_Empty"
    },
    {
      "x": 0,
      "y": 4,
      "z": -2,
      "name": "Nat20_Force_Empty"
    },
    {
      "x": 0,
      "y": 5,
      "z": -2,
      "name": "Rock_Volcanic_Brick"
    },
    {
      "x": 0,
      "y": 6,
      "z": -2,
      "name": "Cloth_Roof_Leather",
      "rotation": 2
    },
    {
      "x": 0,
      "y": 7,
      "z": -2,
      "name": "Nat20_Force_Empty"
    },
    {
      "x": 0,
      "y": 0,
      "z": -1,
      "name": "Soil_Pathway"
    },
    {
      "x": 0,
      "y": 1,
      "z": -1,
      "name": "Nat20_Npc_Spawn"
    },
    {
      "x": 0,
      "y": 2,
      "z": -1,
      "name": "Nat20_Force_Empty"
    },
    {
      "x": 0,
      "y": 3,
      "z": -1,
      "name": "Nat20_Force_Empty"
    },
    {
      "x": 0,
      "y": 4,
      "z": -1,
      "name": "Nat20_Force_Empty"
    },
    {
      "x": 0,
      "y": 5,
      "z": -1,
      "name": "Rock_Volcanic_Brick"
    },
    {
      "x": 0,
      "y": 6,
      "z": -1,
      "name": "Nat20_Force_Empty"
    },
    {
      "x": 0,
      "y": 7,
      "z": -1,
      "name": "Cloth_Roof_Leather",
      "rotation": 2
    },
    {
      "x": 0,
      "y": 0,
      "z": 0,
      "name": "Soil_Dirt"
    },
    {
      "x": 0,
      "y": 1,
      "z": 0,
      "name": "Nat20_Force_Empty"
    },
    {
      "x": 0,
      "y": 2,
      "z": 0,
      "name": "Nat20_Force_Empty"
    },
    {
      "x": 0,
      "y": 3,
      "z": 0,
      "name": "Nat20_Force_Empty"
    },
    {
      "x": 0,
      "y": 4,
      "z": 0,
      "name": "Nat20_Force_Empty"
    },
    {
      "x": 0,
      "y": 5,
      "z": 0,
      "name": "Rock_Volcanic_Brick"
    },
    {
      "x": 0,
      "y": 6,
      "z": 0,
      "name": "Nat20_Force_Empty"
    },
    {
      "x": 0,
      "y": 7,
      "z": 0,
      "name": "Plant_Leaves_Bramble"
    },
    {
      "x": 0,
      "y": 0,
      "z": 1,
      "name": "Soil_Dirt"
    },
    {
      "x": 0,
      "y": 1,
      "z": 1,
      "name": "Nat20_Force_Empty"
    },
    {
      "x": 0,
      "y": 2,
      "z": 1,
      "name": "Nat20_Force_Empty"
    },
    {
      "x": 0,
      "y": 3,
      "z": 1,
      "name": "Nat20_Force_Empty"
    },
    {
      "x": 0,
      "y": 4,
      "z": 1,
      "name": "Nat20_Force_Empty"
    },
    {
      "x": 0,
      "y": 5,
      "z": 1,
      "name": "Rock_Volcanic_Brick"
    },
    {
      "x": 0,
      "y": 6,
      "z": 1,
      "name": "Nat20_Force_Empty"
    },
    {
      "x": 0,
      "y": 7,
      "z": 1,
      "name": "Cloth_Roof_Leather"
    },
    {
      "x": 0,
      "y": 0,
      "z": 2,
      "name": "Soil_Pathway"
    },
    {
      "x": 0,
      "y": 1,
      "z": 2,
      "name": "Nat20_Force_Empty"
    },
    {
      "x": 0,
      "y": 2,
      "z": 2,
      "name": "Nat20_Force_Empty"
    },
    {
      "x": 0,
      "y": 3,
      "z": 2,
      "name": "Nat20_Force_Empty"
    },
    {
      "x": 0,
      "y": 4,
      "z": 2,
      "name": "Nat20_Force_Empty"
    },
    {
      "x": 0,
      "y": 5,
      "z": 2,
      "name": "Rock_Volcanic_Brick"
    },
    {
      "x": 0,
      "y": 6,
      "z": 2,
      "name": "Cloth_Roof_Leather"
    },
    {
      "x": 0,
      "y": 7,
      "z": 2,
      "name": "Nat20_Force_Empty"
    },
    {
      "x": 0,
      "y": 0,
      "z": 3,
      "name": "Rock_Volcanic_Brick"
    },
    {
      "x": 0,
      "y": 1,
      "z": 3,
      "name": "Nat20_Anchor"
    },
    {
      "x": 0,
      "y": 2,
      "z": 3,
      "name": "Nat20_Force_Empty"
    },
    {
      "x": 0,
      "y": 3,
      "z": 3,
      "name": "Rock_Volcanic_Brick_Wall"
    },
    {
      "x": 0,
      "y": 4,
      "z": 3,
      "name": "Rock_Volcanic_Brick"
    },
    {
      "x": 0,
      "y": 5,
      "z": 3,
      "name": "Wood_Softwood_Planks"
    },
    {
      "x": 0,
      "y": 6,
      "z": 3,
      "name": "Cloth_Roof_Leather_Flat"
    },
    {
      "x": 0,
      "y": 7,
      "z": 3,
      "name": "Nat20_Force_Empty"
    },
    {
      "x": 0,
      "y": 0,
      "z": 4,
      "name": "Soil_Pathway"
    },
    {
      "x": 0,
      "y": 1,
      "z": 4,
      "name": "Nat20_Direction"
    },
    {
      "x": 0,
      "y": 2,
      "z": 4,
      "name": "Nat20_Force_Empty"
    },
    {
      "x": 0,
      "y": 3,
      "z": 4,
      "name": "Nat20_Force_Empty"
    },
    {
      "x": 0,
      "y": 4,
      "z": 4,
      "name": "Nat20_Force_Empty"
    },
    {
      "x": 0,
      "y": 5,
      "z": 4,
      "name": "Nat20_Force_Empty"
    },
    {
      "x": 0,
      "y": 6,
      "z": 4,
      "name": "Nat20_Force_Empty"
    },
    {
      "x": 0,
      "y": 7,
      "z": 4,
      "name": "Nat20_Force_Empty"
    },
    {
      "x": 1,
      "y": 0,
      "z": -5,
      "name": "Soil_Pathway"
    },
    {
      "x": 1,
      "y": 1,
      "z": -5,
      "name": "Rock_Stone_Cobble"
    },
    {
      "x": 1,
      "y": 2,
      "z": -5,
      "name": "Rock_Stone_Cobble"
    },
    {
      "x": 1,
      "y": 3,
      "z": -5,
      "name": "Rock_Stone_Cobble"
    },
    {
      "x": 1,
      "y": 4,
      "z": -5,
      "name": "Wood_Beech_Trunk",
      "support": 15,
      "rotation": 5
    },
    {
      "x": 1,
      "y": 5,
      "z": -5,
      "name": "Wood_Softwood_Planks_Half"
    },
    {
      "x": 1,
      "y": 6,
      "z": -5,
      "name": "Nat20_Force_Empty"
    },
    {
      "x": 1,
      "y": 7,
      "z": -5,
      "name": "Nat20_Force_Empty"
    },
    {
      "x": 1,
      "y": 0,
      "z": -4,
      "name": "Rock_Volcanic_Brick"
    },
    {
      "x": 1,
      "y": 1,
      "z": -4,
      "name": "Rock_Volcanic_Brick"
    },
    {
      "x": 1,
      "y": 2,
      "z": -4,
      "name": "Rock_Volcanic_Brick"
    },
    {
      "x": 1,
      "y": 3,
      "z": -4,
      "name": "Rock_Volcanic_Brick"
    },
    {
      "x": 1,
      "y": 4,
      "z": -4,
      "name": "Rock_Volcanic_Brick"
    },
    {
      "x": 1,
      "y": 5,
      "z": -4,
      "name": "Rock_Volcanic_Brick"
    },
    {
      "x": 1,
      "y": 6,
      "z": -4,
      "name": "Nat20_Force_Empty"
    },
    {
      "x": 1,
      "y": 7,
      "z": -4,
      "name": "Nat20_Force_Empty"
    },
    {
      "x": 1,
      "y": 0,
      "z": -3,
      "name": "Soil_Pathway"
    },
    {
      "x": 1,
      "y": 1,
      "z": -3,
      "name": "Furniture_Tavern_Shelf"
    },
    {
      "x": 1,
      "y": 2,
      "z": -3,
      "name": "Nat20_Force_Empty"
    },
    {
      "x": 1,
      "y": 3,
      "z": -3,
      "name": "Furniture_Village_Shelf_Full"
    },
    {
      "x": 1,
      "y": 4,
      "z": -3,
      "name": "Nat20_Force_Empty"
    },
    {
      "x": 1,
      "y": 5,
      "z": -3,
      "name": "Rock_Volcanic_Brick"
    },
    {
      "x": 1,
      "y": 6,
      "z": -3,
      "name": "Nat20_Force_Empty"
    },
    {
      "x": 1,
      "y": 7,
      "z": -3,
      "name": "Nat20_Force_Empty"
    },
    {
      "x": 1,
      "y": 0,
      "z": -2,
      "name": "Soil_Pathway"
    },
    {
      "x": 1,
      "y": 1,
      "z": -2,
      "name": "Nat20_Force_Empty"
    },
    {
      "x": 1,
      "y": 2,
      "z": -2,
      "name": "Nat20_Force_Empty"
    },
    {
      "x": 1,
      "y": 3,
      "z": -2,
      "name": "Nat20_Force_Empty"
    },
    {
      "x": 1,
      "y": 4,
      "z": -2,
      "name": "Nat20_Force_Empty"
    },
    {
      "x": 1,
      "y": 5,
      "z": -2,
      "name": "Rock_Volcanic_Brick"
    },
    {
      "x": 1,
      "y": 6,
      "z": -2,
      "name": "Cloth_Roof_Leather",
      "rotation": 2
    },
    {
      "x": 1,
      "y": 7,
      "z": -2,
      "name": "Nat20_Force_Empty"
    },
    {
      "x": 1,
      "y": 0,
      "z": -1,
      "name": "Soil_Pathway"
    },
    {
      "x": 1,
      "y": 1,
      "z": -1,
      "name": "Nat20_Force_Empty"
    },
    {
      "x": 1,
      "y": 2,
      "z": -1,
      "name": "Nat20_Force_Empty"
    },
    {
      "x": 1,
      "y": 3,
      "z": -1,
      "name": "Nat20_Force_Empty"
    },
    {
      "x": 1,
      "y": 4,
      "z": -1,
      "name": "Nat20_Force_Empty"
    },
    {
      "x": 1,
      "y": 5,
      "z": -1,
      "name": "Rock_Volcanic_Brick"
    },
    {
      "x": 1,
      "y": 6,
      "z": -1,
      "name": "Nat20_Force_Empty"
    },
    {
      "x": 1,
      "y": 7,
      "z": -1,
      "name": "*Cloth_Roof_Leather_State_Definitions_Corner_Right",
      "rotation": 2
    },
    {
      "x": 1,
      "y": 0,
      "z": 0,
      "name": "Soil_Pathway"
    },
    {
      "x": 1,
      "y": 1,
      "z": 0,
      "name": "Furniture_Village_Counter",
      "rotation": 2
    },
    {
      "x": 1,
      "y": 2,
      "z": 0,
      "name": "Nat20_Force_Empty"
    },
    {
      "x": 1,
      "y": 3,
      "z": 0,
      "name": "Nat20_Force_Empty"
    },
    {
      "x": 1,
      "y": 4,
      "z": 0,
      "name": "Nat20_Force_Empty"
    },
    {
      "x": 1,
      "y": 5,
      "z": 0,
      "name": "Rock_Volcanic_Brick"
    },
    {
      "x": 1,
      "y": 6,
      "z": 0,
      "name": "Nat20_Force_Empty"
    },
    {
      "x": 1,
      "y": 7,
      "z": 0,
      "name": "Cloth_Roof_Leather",
      "rotation": 1
    },
    {
      "x": 1,
      "y": 0,
      "z": 1,
      "name": "Soil_Dirt"
    },
    {
      "x": 1,
      "y": 1,
      "z": 1,
      "name": "Nat20_Force_Empty"
    },
    {
      "x": 1,
      "y": 2,
      "z": 1,
      "name": "Nat20_Force_Empty"
    },
    {
      "x": 1,
      "y": 3,
      "z": 1,
      "name": "Nat20_Force_Empty"
    },
    {
      "x": 1,
      "y": 4,
      "z": 1,
      "name": "Nat20_Force_Empty"
    },
    {
      "x": 1,
      "y": 5,
      "z": 1,
      "name": "Rock_Volcanic_Brick"
    },
    {
      "x": 1,
      "y": 6,
      "z": 1,
      "name": "Nat20_Force_Empty"
    },
    {
      "x": 1,
      "y": 7,
      "z": 1,
      "name": "*Cloth_Roof_Leather_State_Definitions_Corner_Right",
      "rotation": 1
    },
    {
      "x": 1,
      "y": 0,
      "z": 2,
      "name": "Soil_Pathway"
    },
    {
      "x": 1,
      "y": 1,
      "z": 2,
      "name": "Nat20_Force_Empty"
    },
    {
      "x": 1,
      "y": 2,
      "z": 2,
      "name": "Nat20_Force_Empty"
    },
    {
      "x": 1,
      "y": 3,
      "z": 2,
      "name": "Nat20_Force_Empty"
    },
    {
      "x": 1,
      "y": 4,
      "z": 2,
      "name": "Nat20_Force_Empty"
    },
    {
      "x": 1,
      "y": 5,
      "z": 2,
      "name": "Rock_Volcanic_Brick"
    },
    {
      "x": 1,
      "y": 6,
      "z": 2,
      "name": "Cloth_Roof_Leather"
    },
    {
      "x": 1,
      "y": 7,
      "z": 2,
      "name": "Nat20_Force_Empty"
    },
    {
      "x": 1,
      "y": 0,
      "z": 3,
      "name": "Rock_Volcanic_Brick"
    },
    {
      "x": 1,
      "y": 1,
      "z": 3,
      "name": "Nat20_Force_Empty"
    },
    {
      "x": 1,
      "y": 2,
      "z": 3,
      "name": "Nat20_Force_Empty"
    },
    {
      "x": 1,
      "y": 3,
      "z": 3,
      "name": "Rock_Volcanic_Brick_Wall"
    },
    {
      "x": 1,
      "y": 4,
      "z": 3,
      "name": "Rock_Volcanic_Brick"
    },
    {
      "x": 1,
      "y": 5,
      "z": 3,
      "name": "Wood_Softwood_Planks"
    },
    {
      "x": 1,
      "y": 6,
      "z": 3,
      "name": "Cloth_Roof_Leather_Flat"
    },
    {
      "x": 1,
      "y": 7,
      "z": 3,
      "name": "Nat20_Force_Empty"
    },
    {
      "x": 1,
      "y": 0,
      "z": 4,
      "name": "Soil_Pathway"
    },
    {
      "x": 1,
      "y": 1,
      "z": 4,
      "name": "Nat20_Force_Empty"
    },
    {
      "x": 1,
      "y": 2,
      "z": 4,
      "name": "Nat20_Force_Empty"
    },
    {
      "x": 1,
      "y": 3,
      "z": 4,
      "name": "Nat20_Force_Empty"
    },
    {
      "x": 1,
      "y": 4,
      "z": 4,
      "name": "Deco_Bone_Ribs",
      "rotation": 9
    },
    {
      "x": 1,
      "y": 5,
      "z": 4,
      "name": "Nat20_Force_Empty"
    },
    {
      "x": 1,
      "y": 6,
      "z": 4,
      "name": "Nat20_Force_Empty"
    },
    {
      "x": 1,
      "y": 7,
      "z": 4,
      "name": "Nat20_Force_Empty"
    },
    {
      "x": 2,
      "y": 0,
      "z": -5,
      "name": "Soil_Pathway"
    },
    {
      "x": 2,
      "y": 1,
      "z": -5,
      "name": "Wood_Beech_Trunk",
      "support": 15
    },
    {
      "x": 2,
      "y": 2,
      "z": -5,
      "name": "Wood_Beech_Trunk",
      "support": 15
    },
    {
      "x": 2,
      "y": 3,
      "z": -5,
      "name": "Wood_Beech_Trunk",
      "support": 15
    },
    {
      "x": 2,
      "y": 4,
      "z": -5,
      "name": "Wood_Beech_Trunk",
      "support": 15,
      "rotation": 5
    },
    {
      "x": 2,
      "y": 5,
      "z": -5,
      "name": "Wood_Softwood_Planks_Half"
    },
    {
      "x": 2,
      "y": 6,
      "z": -5,
      "name": "Deco_Bone_Ribs",
      "rotation": 2
    },
    {
      "x": 2,
      "y": 7,
      "z": -5,
      "name": "Nat20_Force_Empty"
    },
    {
      "x": 2,
      "y": 0,
      "z": -4,
      "name": "Rock_Volcanic_Brick"
    },
    {
      "x": 2,
      "y": 1,
      "z": -4,
      "name": "Rock_Volcanic_Brick"
    },
    {
      "x": 2,
      "y": 2,
      "z": -4,
      "name": "Rock_Volcanic_Brick"
    },
    {
      "x": 2,
      "y": 3,
      "z": -4,
      "name": "Rock_Volcanic_Brick"
    },
    {
      "x": 2,
      "y": 4,
      "z": -4,
      "name": "Rock_Volcanic_Brick"
    },
    {
      "x": 2,
      "y": 5,
      "z": -4,
      "name": "Rock_Volcanic_Brick"
    },
    {
      "x": 2,
      "y": 6,
      "z": -4,
      "name": "Deco_Bone_Full",
      "rotation": 4
    },
    {
      "x": 2,
      "y": 7,
      "z": -4,
      "name": "Nat20_Force_Empty"
    },
    {
      "x": 2,
      "y": 0,
      "z": -3,
      "name": "Soil_Pathway"
    },
    {
      "x": 2,
      "y": 1,
      "z": -3,
      "name": "Wood_Beech_Trunk",
      "support": 15
    },
    {
      "x": 2,
      "y": 2,
      "z": -3,
      "name": "Wood_Beech_Trunk",
      "support": 15
    },
    {
      "x": 2,
      "y": 3,
      "z": -3,
      "name": "Wood_Beech_Trunk",
      "support": 15
    },
    {
      "x": 2,
      "y": 4,
      "z": -3,
      "name": "Wood_Beech_Trunk",
      "support": 15
    },
    {
      "x": 2,
      "y": 5,
      "z": -3,
      "name": "Rock_Volcanic_Brick"
    },
    {
      "x": 2,
      "y": 6,
      "z": -3,
      "name": "Deco_Bone_Full",
      "rotation": 4
    },
    {
      "x": 2,
      "y": 7,
      "z": -3,
      "name": "Nat20_Force_Empty"
    },
    {
      "x": 2,
      "y": 0,
      "z": -2,
      "name": "Soil_Pathway"
    },
    {
      "x": 2,
      "y": 1,
      "z": -2,
      "name": "Nat20_Force_Empty"
    },
    {
      "x": 2,
      "y": 2,
      "z": -2,
      "name": "Furniture_Crude_Shelf"
    },
    {
      "x": 2,
      "y": 3,
      "z": -2,
      "name": "Furniture_Crude_Shelf"
    },
    {
      "x": 2,
      "y": 4,
      "z": -2,
      "name": "Furniture_Village_Shelf_Full"
    },
    {
      "x": 2,
      "y": 5,
      "z": -2,
      "name": "Rock_Volcanic_Brick"
    },
    {
      "x": 2,
      "y": 6,
      "z": -2,
      "name": "Plant_Leaves_Bramble"
    },
    {
      "x": 2,
      "y": 7,
      "z": -2,
      "name": "Nat20_Force_Empty"
    },
    {
      "x": 2,
      "y": 0,
      "z": -1,
      "name": "Soil_Pathway"
    },
    {
      "x": 2,
      "y": 1,
      "z": -1,
      "name": "Nat20_Force_Empty"
    },
    {
      "x": 2,
      "y": 2,
      "z": -1,
      "name": "Nat20_Force_Empty"
    },
    {
      "x": 2,
      "y": 3,
      "z": -1,
      "name": "Nat20_Force_Empty"
    },
    {
      "x": 2,
      "y": 4,
      "z": -1,
      "name": "Nat20_Force_Empty"
    },
    {
      "x": 2,
      "y": 5,
      "z": -1,
      "name": "Rock_Volcanic_Brick"
    },
    {
      "x": 2,
      "y": 6,
      "z": -1,
      "name": "Plant_Leaves_Bramble"
    },
    {
      "x": 2,
      "y": 7,
      "z": -1,
      "name": "Plant_Leaves_Bramble"
    },
    {
      "x": 2,
      "y": 0,
      "z": 0,
      "name": "Soil_Pathway"
    },
    {
      "x": 2,
      "y": 1,
      "z": 0,
      "name": "Furniture_Village_Counter",
      "filler": 1,
      "rotation": 2
    },
    {
      "x": 2,
      "y": 2,
      "z": 0,
      "name": "Furniture_Crude_Candle"
    },
    {
      "x": 2,
      "y": 3,
      "z": 0,
      "name": "Nat20_Force_Empty"
    },
    {
      "x": 2,
      "y": 4,
      "z": 0,
      "name": "Nat20_Force_Empty"
    },
    {
      "x": 2,
      "y": 5,
      "z": 0,
      "name": "Rock_Volcanic_Brick"
    },
    {
      "x": 2,
      "y": 6,
      "z": 0,
      "name": "Cloth_Roof_Leather",
      "rotation": 1
    },
    {
      "x": 2,
      "y": 7,
      "z": 0,
      "name": "Nat20_Force_Empty"
    },
    {
      "x": 2,
      "y": 0,
      "z": 1,
      "name": "Soil_Dirt"
    },
    {
      "x": 2,
      "y": 1,
      "z": 1,
      "name": "Nat20_Force_Empty"
    },
    {
      "x": 2,
      "y": 2,
      "z": 1,
      "name": "Nat20_Force_Empty"
    },
    {
      "x": 2,
      "y": 3,
      "z": 1,
      "name": "Nat20_Force_Empty"
    },
    {
      "x": 2,
      "y": 4,
      "z": 1,
      "name": "Nat20_Force_Empty"
    },
    {
      "x": 2,
      "y": 5,
      "z": 1,
      "name": "Rock_Volcanic_Brick"
    },
    {
      "x": 2,
      "y": 6,
      "z": 1,
      "name": "Cloth_Roof_Leather",
      "rotation": 1
    },
    {
      "x": 2,
      "y": 7,
      "z": 1,
      "name": "Nat20_Force_Empty"
    },
    {
      "x": 2,
      "y": 0,
      "z": 2,
      "name": "Soil_Dirt"
    },
    {
      "x": 2,
      "y": 1,
      "z": 2,
      "name": "Deco_Pot_Clay_Broken"
    },
    {
      "x": 2,
      "y": 2,
      "z": 2,
      "name": "Nat20_Force_Empty"
    },
    {
      "x": 2,
      "y": 3,
      "z": 2,
      "name": "Nat20_Force_Empty"
    },
    {
      "x": 2,
      "y": 4,
      "z": 2,
      "name": "Nat20_Force_Empty"
    },
    {
      "x": 2,
      "y": 5,
      "z": 2,
      "name": "Rock_Volcanic_Brick"
    },
    {
      "x": 2,
      "y": 6,
      "z": 2,
      "name": "*Cloth_Roof_Leather_State_Definitions_Corner_Right",
      "rotation": 1
    },
    {
      "x": 2,
      "y": 7,
      "z": 2,
      "name": "Nat20_Force_Empty"
    },
    {
      "x": 2,
      "y": 0,
      "z": 3,
      "name": "Rock_Volcanic_Brick"
    },
    {
      "x": 2,
      "y": 1,
      "z": 3,
      "name": "Rock_Volcanic_Brick_Wall"
    },
    {
      "x": 2,
      "y": 2,
      "z": 3,
      "name": "Rock_Volcanic_Brick_Wall"
    },
    {
      "x": 2,
      "y": 3,
      "z": 3,
      "name": "Rock_Volcanic_Brick"
    },
    {
      "x": 2,
      "y": 4,
      "z": 3,
      "name": "Rock_Volcanic_Brick"
    },
    {
      "x": 2,
      "y": 5,
      "z": 3,
      "name": "Rock_Volcanic_Brick"
    },
    {
      "x": 2,
      "y": 6,
      "z": 3,
      "name": "Wood_Softwood_Stairs",
      "rotation": 3
    },
    {
      "x": 2,
      "y": 7,
      "z": 3,
      "name": "Nat20_Force_Empty"
    },
    {
      "x": 2,
      "y": 0,
      "z": 4,
      "name": "Soil_Pathway"
    },
    {
      "x": 2,
      "y": 1,
      "z": 4,
      "name": "Nat20_Force_Empty"
    },
    {
      "x": 2,
      "y": 2,
      "z": 4,
      "name": "Nat20_Force_Empty"
    },
    {
      "x": 2,
      "y": 3,
      "z": 4,
      "name": "Nat20_Force_Empty"
    },
    {
      "x": 2,
      "y": 4,
      "z": 4,
      "name": "Deco_Bone_Ribs",
      "rotation": 1
    },
    {
      "x": 2,
      "y": 5,
      "z": 4,
      "name": "Deco_Bone_Full",
      "rotation": 4
    },
    {
      "x": 2,
      "y": 6,
      "z": 4,
      "name": "Nat20_Force_Empty"
    },
    {
      "x": 2,
      "y": 7,
      "z": 4,
      "name": "Nat20_Force_Empty"
    },
    {
      "x": 2,
      "y": 5,
      "z": 5,
      "name": "Deco_Bone_Ribs_Long",
      "rotation": 4
    },
    {
      "x": 2,
      "y": 5,
      "z": 6,
      "name": "Deco_Bone_Ribs"
    },
    {
      "x": 3,
      "y": 1,
      "z": -5,
      "name": "Rock_Stone_Cobble_Half",
      "rotation": 6
    },
    {
      "x": 3,
      "y": 2,
      "z": -5,
      "name": "Rock_Stone_Cobble_Half",
      "rotation": 6
    },
    {
      "x": 3,
      "y": 3,
      "z": -5,
      "name": "Rock_Stone_Cobble_Half",
      "rotation": 6
    },
    {
      "x": 3,
      "y": 4,
      "z": -5,
      "name": "Wood_Softwood_Planks_Half",
      "rotation": 5
    },
    {
      "x": 3,
      "y": 5,
      "z": -5,
      "name": "Wood_Softwood_Stairs",
      "rotation": 1
    },
    {
      "x": 3,
      "y": 6,
      "z": -5,
      "name": "Nat20_Force_Empty"
    },
    {
      "x": 3,
      "y": 7,
      "z": -5,
      "name": "Nat20_Force_Empty"
    },
    {
      "x": 3,
      "y": 0,
      "z": -4,
      "name": "Rock_Volcanic_Brick"
    },
    {
      "x": 3,
      "y": 1,
      "z": -4,
      "name": "Rock_Volcanic_Brick"
    },
    {
      "x": 3,
      "y": 2,
      "z": -4,
      "name": "Rock_Volcanic_Brick"
    },
    {
      "x": 3,
      "y": 3,
      "z": -4,
      "name": "Rock_Volcanic_Brick"
    },
    {
      "x": 3,
      "y": 4,
      "z": -4,
      "name": "Rock_Volcanic_Brick"
    },
    {
      "x": 3,
      "y": 5,
      "z": -4,
      "name": "Rock_Volcanic_Brick"
    },
    {
      "x": 3,
      "y": 6,
      "z": -4,
      "name": "Nat20_Force_Empty"
    },
    {
      "x": 3,
      "y": 7,
      "z": -4,
      "name": "Nat20_Force_Empty"
    },
    {
      "x": 3,
      "y": 0,
      "z": -3,
      "name": "Rock_Volcanic_Brick"
    },
    {
      "x": 3,
      "y": 1,
      "z": -3,
      "name": "Rock_Volcanic_Brick"
    },
    {
      "x": 3,
      "y": 2,
      "z": -3,
      "name": "Rock_Volcanic_Brick"
    },
    {
      "x": 3,
      "y": 3,
      "z": -3,
      "name": "Rock_Volcanic_Brick"
    },
    {
      "x": 3,
      "y": 4,
      "z": -3,
      "name": "Rock_Volcanic_Brick"
    },
    {
      "x": 3,
      "y": 5,
      "z": -3,
      "name": "Rock_Volcanic_Brick"
    },
    {
      "x": 3,
      "y": 6,
      "z": -3,
      "name": "Nat20_Force_Empty"
    },
    {
      "x": 3,
      "y": 7,
      "z": -3,
      "name": "Nat20_Force_Empty"
    },
    {
      "x": 3,
      "y": 0,
      "z": -2,
      "name": "Rock_Volcanic_Brick"
    },
    {
      "x": 3,
      "y": 1,
      "z": -2,
      "name": "Rock_Volcanic_Brick"
    },
    {
      "x": 3,
      "y": 2,
      "z": -2,
      "name": "Rock_Volcanic_Brick"
    },
    {
      "x": 3,
      "y": 3,
      "z": -2,
      "name": "Rock_Volcanic_Brick"
    },
    {
      "x": 3,
      "y": 4,
      "z": -2,
      "name": "Rock_Volcanic_Brick"
    },
    {
      "x": 3,
      "y": 5,
      "z": -2,
      "name": "Rock_Volcanic_Brick"
    },
    {
      "x": 3,
      "y": 6,
      "z": -2,
      "name": "Plant_Leaves_Bramble"
    },
    {
      "x": 3,
      "y": 7,
      "z": -2,
      "name": "Nat20_Force_Empty"
    },
    {
      "x": 3,
      "y": 0,
      "z": -1,
      "name": "Rock_Volcanic_Brick"
    },
    {
      "x": 3,
      "y": 1,
      "z": -1,
      "name": "Rock_Volcanic_Brick"
    },
    {
      "x": 3,
      "y": 2,
      "z": -1,
      "name": "Rock_Volcanic_Brick"
    },
    {
      "x": 3,
      "y": 3,
      "z": -1,
      "name": "Rock_Volcanic_Brick"
    },
    {
      "x": 3,
      "y": 4,
      "z": -1,
      "name": "Rock_Volcanic_Brick"
    },
    {
      "x": 3,
      "y": 5,
      "z": -1,
      "name": "Rock_Volcanic_Brick"
    },
    {
      "x": 3,
      "y": 6,
      "z": -1,
      "name": "Plant_Leaves_Bramble"
    },
    {
      "x": 3,
      "y": 7,
      "z": -1,
      "name": "Nat20_Force_Empty"
    },
    {
      "x": 3,
      "y": 0,
      "z": 0,
      "name": "Rock_Volcanic_Brick"
    },
    {
      "x": 3,
      "y": 1,
      "z": 0,
      "name": "Rock_Volcanic_Brick"
    },
    {
      "x": 3,
      "y": 2,
      "z": 0,
      "name": "Rock_Volcanic_Brick"
    },
    {
      "x": 3,
      "y": 3,
      "z": 0,
      "name": "Rock_Volcanic_Brick"
    },
    {
      "x": 3,
      "y": 4,
      "z": 0,
      "name": "Rock_Volcanic_Brick"
    },
    {
      "x": 3,
      "y": 5,
      "z": 0,
      "name": "Rock_Volcanic_Brick"
    },
    {
      "x": 3,
      "y": 6,
      "z": 0,
      "name": "Nat20_Force_Empty"
    },
    {
      "x": 3,
      "y": 7,
      "z": 0,
      "name": "Nat20_Force_Empty"
    },
    {
      "x": 3,
      "y": 0,
      "z": 1,
      "name": "Rock_Volcanic_Brick"
    },
    {
      "x": 3,
      "y": 1,
      "z": 1,
      "name": "Rock_Volcanic_Brick"
    },
    {
      "x": 3,
      "y": 2,
      "z": 1,
      "name": "Rock_Volcanic_Brick"
    },
    {
      "x": 3,
      "y": 3,
      "z": 1,
      "name": "Rock_Volcanic_Brick"
    },
    {
      "x": 3,
      "y": 4,
      "z": 1,
      "name": "Rock_Volcanic_Brick"
    },
    {
      "x": 3,
      "y": 5,
      "z": 1,
      "name": "Rock_Volcanic_Brick"
    },
    {
      "x": 3,
      "y": 6,
      "z": 1,
      "name": "Nat20_Force_Empty"
    },
    {
      "x": 3,
      "y": 7,
      "z": 1,
      "name": "Nat20_Force_Empty"
    },
    {
      "x": 3,
      "y": 0,
      "z": 2,
      "name": "Rock_Volcanic_Brick"
    },
    {
      "x": 3,
      "y": 1,
      "z": 2,
      "name": "Rock_Volcanic_Brick"
    },
    {
      "x": 3,
      "y": 2,
      "z": 2,
      "name": "Rock_Volcanic_Brick"
    },
    {
      "x": 3,
      "y": 3,
      "z": 2,
      "name": "Rock_Volcanic_Brick"
    },
    {
      "x": 3,
      "y": 4,
      "z": 2,
      "name": "Rock_Volcanic_Brick"
    },
    {
      "x": 3,
      "y": 5,
      "z": 2,
      "name": "Rock_Volcanic_Brick"
    },
    {
      "x": 3,
      "y": 6,
      "z": 2,
      "name": "Nat20_Force_Empty"
    },
    {
      "x": 3,
      "y": 7,
      "z": 2,
      "name": "Nat20_Force_Empty"
    },
    {
      "x": 3,
      "y": 0,
      "z": 3,
      "name": "Rock_Volcanic_Brick"
    },
    {
      "x": 3,
      "y": 1,
      "z": 3,
      "name": "Rock_Volcanic_Brick"
    },
    {
      "x": 3,
      "y": 2,
      "z": 3,
      "name": "Rock_Volcanic_Brick"
    },
    {
      "x": 3,
      "y": 3,
      "z": 3,
      "name": "Rock_Volcanic_Brick"
    },
    {
      "x": 3,
      "y": 4,
      "z": 3,
      "name": "Rock_Volcanic_Brick"
    },
    {
      "x": 3,
      "y": 5,
      "z": 3,
      "name": "Rock_Volcanic_Brick"
    },
    {
      "x": 3,
      "y": 6,
      "z": 3,
      "name": "Wood_Softwood_Planks_Half"
    },
    {
      "x": 3,
      "y": 7,
      "z": 3,
      "name": "Nat20_Force_Empty"
    },
    {
      "x": 3,
      "y": 0,
      "z": 4,
      "name": "Wood_Beech_Trunk",
      "support": 15
    },
    {
      "x": 3,
      "y": 1,
      "z": 4,
      "name": "Wood_Beech_Trunk",
      "support": 15
    },
    {
      "x": 3,
      "y": 2,
      "z": 4,
      "name": "Wood_Beech_Trunk",
      "support": 15
    },
    {
      "x": 3,
      "y": 3,
      "z": 4,
      "name": "Wood_Beech_Branch_Long",
      "support": 15
    },
    {
      "x": 3,
      "y": 4,
      "z": 4,
      "name": "Wood_Beech_Branch_Long",
      "support": 15
    },
    {
      "x": 3,
      "y": 5,
      "z": 4,
      "name": "Wood_Softwood_Beam"
    },
    {
      "x": 3,
      "y": 6,
      "z": 4,
      "name": "Nat20_Force_Empty"
    },
    {
      "x": 3,
      "y": 7,
      "z": 4,
      "name": "Nat20_Force_Empty"
    },
    {
      "x": 3,
      "y": 2,
      "z": 5,
      "name": "Furniture_Crude_Sign",
      "rotation": 3
    },
    {
      "x": 4,
      "y": 1,
      "z": -5,
      "name": "Nat20_Force_Empty"
    },
    {
      "x": 4,
      "y": 2,
      "z": -5,
      "name": "Nat20_Force_Empty"
    },
    {
      "x": 4,
      "y": 3,
      "z": -5,
      "name": "Nat20_Force_Empty"
    },
    {
      "x": 4,
      "y": 4,
      "z": -5,
      "name": "Nat20_Force_Empty"
    },
    {
      "x": 4,
      "y": 5,
      "z": -5,
      "name": "Nat20_Force_Empty"
    },
    {
      "x": 4,
      "y": 6,
      "z": -5,
      "name": "Nat20_Force_Empty"
    },
    {
      "x": 4,
      "y": 7,
      "z": -5,
      "name": "Nat20_Force_Empty"
    },
    {
      "x": 4,
      "y": 1,
      "z": -4,
      "name": "Nat20_Force_Empty"
    },
    {
      "x": 4,
      "y": 2,
      "z": -4,
      "name": "Nat20_Force_Empty"
    },
    {
      "x": 4,
      "y": 3,
      "z": -4,
      "name": "Nat20_Force_Empty"
    },
    {
      "x": 4,
      "y": 4,
      "z": -4,
      "name": "Nat20_Force_Empty"
    },
    {
      "x": 4,
      "y": 5,
      "z": -4,
      "name": "Nat20_Force_Empty"
    },
    {
      "x": 4,
      "y": 6,
      "z": -4,
      "name": "Nat20_Force_Empty"
    },
    {
      "x": 4,
      "y": 7,
      "z": -4,
      "name": "Nat20_Force_Empty"
    },
    {
      "x": 4,
      "y": 0,
      "z": -3,
      "name": "Soil_Pathway"
    },
    {
      "x": 4,
      "y": 1,
      "z": -3,
      "name": "Rock_Stone_Cobble_Half",
      "rotation": 5
    },
    {
      "x": 4,
      "y": 2,
      "z": -3,
      "name": "Rock_Stone_Cobble_Half",
      "rotation": 5
    },
    {
      "x": 4,
      "y": 3,
      "z": -3,
      "name": "Rock_Stone_Cobble_Half",
      "rotation": 5
    },
    {
      "x": 4,
      "y": 4,
      "z": -3,
      "name": "Wood_Hardwood_Planks_Half"
    },
    {
      "x": 4,
      "y": 5,
      "z": -3,
      "name": "Nat20_Force_Empty"
    },
    {
      "x": 4,
      "y": 6,
      "z": -3,
      "name": "Nat20_Force_Empty"
    },
    {
      "x": 4,
      "y": 7,
      "z": -3,
      "name": "Nat20_Force_Empty"
    },
    {
      "x": 4,
      "y": 0,
      "z": -2,
      "name": "Soil_Pathway"
    },
    {
      "x": 4,
      "y": 1,
      "z": -2,
      "name": "Rock_Stone_Cobble"
    },
    {
      "x": 4,
      "y": 2,
      "z": -2,
      "name": "Rock_Stone_Cobble"
    },
    {
      "x": 4,
      "y": 3,
      "z": -2,
      "name": "Rock_Stone_Cobble"
    },
    {
      "x": 4,
      "y": 4,
      "z": -2,
      "name": "Wood_Hardwood_Planks_Half"
    },
    {
      "x": 4,
      "y": 5,
      "z": -2,
      "name": "Nat20_Force_Empty"
    },
    {
      "x": 4,
      "y": 6,
      "z": -2,
      "name": "Nat20_Force_Empty"
    },
    {
      "x": 4,
      "y": 7,
      "z": -2,
      "name": "Nat20_Force_Empty"
    },
    {
      "x": 4,
      "y": 0,
      "z": -1,
      "name": "Soil_Pathway"
    },
    {
      "x": 4,
      "y": 1,
      "z": -1,
      "name": "Rock_Stone_Cobble_Half",
      "rotation": 5
    },
    {
      "x": 4,
      "y": 2,
      "z": -1,
      "name": "Rock_Stone_Cobble"
    },
    {
      "x": 4,
      "y": 3,
      "z": -1,
      "name": "Rock_Stone_Cobble"
    },
    {
      "x": 4,
      "y": 4,
      "z": -1,
      "name": "Wood_Hardwood_Planks_Half"
    },
    {
      "x": 4,
      "y": 5,
      "z": -1,
      "name": "Nat20_Force_Empty"
    },
    {
      "x": 4,
      "y": 6,
      "z": -1,
      "name": "Nat20_Force_Empty"
    },
    {
      "x": 4,
      "y": 7,
      "z": -1,
      "name": "Nat20_Force_Empty"
    },
    {
      "x": 4,
      "y": 0,
      "z": 0,
      "name": "Soil_Pathway"
    },
    {
      "x": 4,
      "y": 1,
      "z": 0,
      "name": "Rock_Stone_Cobble_Half",
      "rotation": 5
    },
    {
      "x": 4,
      "y": 2,
      "z": 0,
      "name": "Rock_Stone_Cobble"
    },
    {
      "x": 4,
      "y": 3,
      "z": 0,
      "name": "Rock_Stone_Cobble"
    },
    {
      "x": 4,
      "y": 4,
      "z": 0,
      "name": "Wood_Hardwood_Planks_Half"
    },
    {
      "x": 4,
      "y": 5,
      "z": 0,
      "name": "Nat20_Force_Empty"
    },
    {
      "x": 4,
      "y": 6,
      "z": 0,
      "name": "Nat20_Force_Empty"
    },
    {
      "x": 4,
      "y": 7,
      "z": 0,
      "name": "Nat20_Force_Empty"
    },
    {
      "x": 4,
      "y": 0,
      "z": 1,
      "name": "Rock_Stone"
    },
    {
      "x": 4,
      "y": 1,
      "z": 1,
      "name": "Rock_Stone"
    },
    {
      "x": 4,
      "y": 2,
      "z": 1,
      "name": "Rock_Stone"
    },
    {
      "x": 4,
      "y": 3,
      "z": 1,
      "name": "Rock_Stone_Cobble"
    },
    {
      "x": 4,
      "y": 4,
      "z": 1,
      "name": "Wood_Hardwood_Planks_Half"
    },
    {
      "x": 4,
      "y": 5,
      "z": 1,
      "name": "Nat20_Force_Empty"
    },
    {
      "x": 4,
      "y": 6,
      "z": 1,
      "name": "Nat20_Force_Empty"
    },
    {
      "x": 4,
      "y": 7,
      "z": 1,
      "name": "Nat20_Force_Empty"
    },
    {
      "x": 4,
      "y": 0,
      "z": 2,
      "name": "Rock_Stone"
    },
    {
      "x": 4,
      "y": 1,
      "z": 2,
      "name": "Rock_Stone"
    },
    {
      "x": 4,
      "y": 2,
      "z": 2,
      "name": "Rock_Stone"
    },
    {
      "x": 4,
      "y": 3,
      "z": 2,
      "name": "Rock_Stone"
    },
    {
      "x": 4,
      "y": 4,
      "z": 2,
      "name": "Rock_Stone"
    },
    {
      "x": 4,
      "y": 5,
      "z": 2,
      "name": "Rock_Stone"
    },
    {
      "x": 4,
      "y": 6,
      "z": 2,
      "name": "Nat20_Force_Empty"
    },
    {
      "x": 4,
      "y": 7,
      "z": 2,
      "name": "Nat20_Force_Empty"
    },
    {
      "x": 4,
      "y": 0,
      "z": 3,
      "name": "Rock_Stone"
    },
    {
      "x": 4,
      "y": 1,
      "z": 3,
      "name": "Rock_Stone"
    },
    {
      "x": 4,
      "y": 2,
      "z": 3,
      "name": "Rock_Stone"
    },
    {
      "x": 4,
      "y": 3,
      "z": 3,
      "name": "Rock_Stone"
    },
    {
      "x": 4,
      "y": 4,
      "z": 3,
      "name": "Rock_Stone"
    },
    {
      "x": 4,
      "y": 5,
      "z": 3,
      "name": "Nat20_Force_Empty"
    },
    {
      "x": 4,
      "y": 6,
      "z": 3,
      "name": "Nat20_Force_Empty"
    },
    {
      "x": 4,
      "y": 7,
      "z": 3,
      "name": "Nat20_Force_Empty"
    },
    {
      "x": 4,
      "y": 1,
      "z": 4,
      "name": "Nat20_Force_Empty"
    },
    {
      "x": 4,
      "y": 2,
      "z": 4,
      "name": "Nat20_Force_Empty"
    },
    {
      "x": 4,
      "y": 3,
      "z": 4,
      "name": "Nat20_Force_Empty"
    },
    {
      "x": 4,
      "y": 4,
      "z": 4,
      "name": "Nat20_Force_Empty"
    },
    {
      "x": 4,
      "y": 5,
      "z": 4,
      "name": "Nat20_Force_Empty"
    },
    {
      "x": 4,
      "y": 6,
      "z": 4,
      "name": "Nat20_Force_Empty"
    },
    {
      "x": 4,
      "y": 7,
      "z": 4,
      "name": "Nat20_Force_Empty"
    }
  ],
  "fluids": [
    {
      "x": -4,
      "y": 1,
      "z": -5,
      "name": "Empty",
      "level": 0
    },
    {
      "x": -4,
      "y": 2,
      "z": -5,
      "name": "Empty",
      "level": 0
    },
    {
      "x": -4,
      "y": 3,
      "z": -5,
      "name": "Empty",
      "level": 0
    },
    {
      "x": -4,
      "y": 4,
      "z": -5,
      "name": "Empty",
      "level": 0
    },
    {
      "x": -4,
      "y": 5,
      "z": -5,
      "name": "Empty",
      "level": 0
    },
    {
      "x": -4,
      "y": 6,
      "z": -5,
      "name": "Empty",
      "level": 0
    },
    {
      "x": -4,
      "y": 7,
      "z": -5,
      "name": "Empty",
      "level": 0
    },
    {
      "x": -4,
      "y": 0,
      "z": -4,
      "name": "Empty",
      "level": 0
    },
    {
      "x": -4,
      "y": 1,
      "z": -4,
      "name": "Empty",
      "level": 0
    },
    {
      "x": -4,
      "y": 2,
      "z": -4,
      "name": "Empty",
      "level": 0
    },
    {
      "x": -4,
      "y": 3,
      "z": -4,
      "name": "Empty",
      "level": 0
    },
    {
      "x": -4,
      "y": 4,
      "z": -4,
      "name": "Empty",
      "level": 0
    },
    {
      "x": -4,
      "y": 5,
      "z": -4,
      "name": "Empty",
      "level": 0
    },
    {
      "x": -4,
      "y": 6,
      "z": -4,
      "name": "Empty",
      "level": 0
    },
    {
      "x": -4,
      "y": 7,
      "z": -4,
      "name": "Empty",
      "level": 0
    },
    {
      "x": -4,
      "y": 0,
      "z": -3,
      "name": "Empty",
      "level": 0
    },
    {
      "x": -4,
      "y": 1,
      "z": -3,
      "name": "Empty",
      "level": 0
    },
    {
      "x": -4,
      "y": 2,
      "z": -3,
      "name": "Empty",
      "level": 0
    },
    {
      "x": -4,
      "y": 3,
      "z": -3,
      "name": "Empty",
      "level": 0
    },
    {
      "x": -4,
      "y": 4,
      "z": -3,
      "name": "Empty",
      "level": 0
    },
    {
      "x": -4,
      "y": 5,
      "z": -3,
      "name": "Empty",
      "level": 0
    },
    {
      "x": -4,
      "y": 6,
      "z": -3,
      "name": "Empty",
      "level": 0
    },
    {
      "x": -4,
      "y": 7,
      "z": -3,
      "name": "Empty",
      "level": 0
    },
    {
      "x": -4,
      "y": 0,
      "z": -2,
      "name": "Empty",
      "level": 0
    },
    {
      "x": -4,
      "y": 1,
      "z": -2,
      "name": "Empty",
      "level": 0
    },
    {
      "x": -4,
      "y": 2,
      "z": -2,
      "name": "Empty",
      "level": 0
    },
    {
      "x": -4,
      "y": 3,
      "z": -2,
      "name": "Empty",
      "level": 0
    },
    {
      "x": -4,
      "y": 4,
      "z": -2,
      "name": "Empty",
      "level": 0
    },
    {
      "x": -4,
      "y": 5,
      "z": -2,
      "name": "Empty",
      "level": 0
    },
    {
      "x": -4,
      "y": 6,
      "z": -2,
      "name": "Empty",
      "level": 0
    },
    {
      "x": -4,
      "y": 7,
      "z": -2,
      "name": "Empty",
      "level": 0
    },
    {
      "x": -4,
      "y": 0,
      "z": -1,
      "name": "Empty",
      "level": 0
    },
    {
      "x": -4,
      "y": 1,
      "z": -1,
      "name": "Empty",
      "level": 0
    },
    {
      "x": -4,
      "y": 2,
      "z": -1,
      "name": "Empty",
      "level": 0
    },
    {
      "x": -4,
      "y": 3,
      "z": -1,
      "name": "Empty",
      "level": 0
    },
    {
      "x": -4,
      "y": 4,
      "z": -1,
      "name": "Empty",
      "level": 0
    },
    {
      "x": -4,
      "y": 5,
      "z": -1,
      "name": "Empty",
      "level": 0
    },
    {
      "x": -4,
      "y": 6,
      "z": -1,
      "name": "Empty",
      "level": 0
    },
    {
      "x": -4,
      "y": 7,
      "z": -1,
      "name": "Empty",
      "level": 0
    },
    {
      "x": -4,
      "y": 0,
      "z": 0,
      "name": "Empty",
      "level": 0
    },
    {
      "x": -4,
      "y": 1,
      "z": 0,
      "name": "Empty",
      "level": 0
    },
    {
      "x": -4,
      "y": 2,
      "z": 0,
      "name": "Empty",
      "level": 0
    },
    {
      "x": -4,
      "y": 3,
      "z": 0,
      "name": "Empty",
      "level": 0
    },
    {
      "x": -4,
      "y": 4,
      "z": 0,
      "name": "Empty",
      "level": 0
    },
    {
      "x": -4,
      "y": 5,
      "z": 0,
      "name": "Empty",
      "level": 0
    },
    {
      "x": -4,
      "y": 6,
      "z": 0,
      "name": "Empty",
      "level": 0
    },
    {
      "x": -4,
      "y": 7,
      "z": 0,
      "name": "Empty",
      "level": 0
    },
    {
      "x": -4,
      "y": 0,
      "z": 1,
      "name": "Empty",
      "level": 0
    },
    {
      "x": -4,
      "y": 1,
      "z": 1,
      "name": "Empty",
      "level": 0
    },
    {
      "x": -4,
      "y": 2,
      "z": 1,
      "name": "Empty",
      "level": 0
    },
    {
      "x": -4,
      "y": 3,
      "z": 1,
      "name": "Empty",
      "level": 0
    },
    {
      "x": -4,
      "y": 4,
      "z": 1,
      "name": "Empty",
      "level": 0
    },
    {
      "x": -4,
      "y": 5,
      "z": 1,
      "name": "Empty",
      "level": 0
    },
    {
      "x": -4,
      "y": 6,
      "z": 1,
      "name": "Empty",
      "level": 0
    },
    {
      "x": -4,
      "y": 7,
      "z": 1,
      "name": "Empty",
      "level": 0
    },
    {
      "x": -4,
      "y": 0,
      "z": 2,
      "name": "Empty",
      "level": 0
    },
    {
      "x": -4,
      "y": 1,
      "z": 2,
      "name": "Empty",
      "level": 0
    },
    {
      "x": -4,
      "y": 2,
      "z": 2,
      "name": "Empty",
      "level": 0
    },
    {
      "x": -4,
      "y": 3,
      "z": 2,
      "name": "Empty",
      "level": 0
    },
    {
      "x": -4,
      "y": 4,
      "z": 2,
      "name": "Empty",
      "level": 0
    },
    {
      "x": -4,
      "y": 5,
      "z": 2,
      "name": "Empty",
      "level": 0
    },
    {
      "x": -4,
      "y": 6,
      "z": 2,
      "name": "Empty",
      "level": 0
    },
    {
      "x": -4,
      "y": 7,
      "z": 2,
      "name": "Empty",
      "level": 0
    },
    {
      "x": -4,
      "y": 0,
      "z": 3,
      "name": "Empty",
      "level": 0
    },
    {
      "x": -4,
      "y": 1,
      "z": 3,
      "name": "Empty",
      "level": 0
    },
    {
      "x": -4,
      "y": 2,
      "z": 3,
      "name": "Empty",
      "level": 0
    },
    {
      "x": -4,
      "y": 3,
      "z": 3,
      "name": "Empty",
      "level": 0
    },
    {
      "x": -4,
      "y": 4,
      "z": 3,
      "name": "Empty",
      "level": 0
    },
    {
      "x": -4,
      "y": 5,
      "z": 3,
      "name": "Empty",
      "level": 0
    },
    {
      "x": -4,
      "y": 6,
      "z": 3,
      "name": "Empty",
      "level": 0
    },
    {
      "x": -4,
      "y": 7,
      "z": 3,
      "name": "Empty",
      "level": 0
    },
    {
      "x": -4,
      "y": 0,
      "z": 4,
      "name": "Empty",
      "level": 0
    },
    {
      "x": -4,
      "y": 1,
      "z": 4,
      "name": "Empty",
      "level": 0
    },
    {
      "x": -4,
      "y": 2,
      "z": 4,
      "name": "Empty",
      "level": 0
    },
    {
      "x": -4,
      "y": 3,
      "z": 4,
      "name": "Empty",
      "level": 0
    },
    {
      "x": -4,
      "y": 4,
      "z": 4,
      "name": "Empty",
      "level": 0
    },
    {
      "x": -4,
      "y": 5,
      "z": 4,
      "name": "Empty",
      "level": 0
    },
    {
      "x": -4,
      "y": 6,
      "z": 4,
      "name": "Empty",
      "level": 0
    },
    {
      "x": -4,
      "y": 7,
      "z": 4,
      "name": "Empty",
      "level": 0
    },
    {
      "x": -3,
      "y": 0,
      "z": -5,
      "name": "Empty",
      "level": 0
    },
    {
      "x": -3,
      "y": 1,
      "z": -5,
      "name": "Empty",
      "level": 0
    },
    {
      "x": -3,
      "y": 2,
      "z": -5,
      "name": "Empty",
      "level": 0
    },
    {
      "x": -3,
      "y": 3,
      "z": -5,
      "name": "Empty",
      "level": 0
    },
    {
      "x": -3,
      "y": 4,
      "z": -5,
      "name": "Empty",
      "level": 0
    },
    {
      "x": -3,
      "y": 5,
      "z": -5,
      "name": "Empty",
      "level": 0
    },
    {
      "x": -3,
      "y": 6,
      "z": -5,
      "name": "Empty",
      "level": 0
    },
    {
      "x": -3,
      "y": 7,
      "z": -5,
      "name": "Empty",
      "level": 0
    },
    {
      "x": -3,
      "y": 0,
      "z": -4,
      "name": "Empty",
      "level": 0
    },
    {
      "x": -3,
      "y": 1,
      "z": -4,
      "name": "Empty",
      "level": 0
    },
    {
      "x": -3,
      "y": 2,
      "z": -4,
      "name": "Empty",
      "level": 0
    },
    {
      "x": -3,
      "y": 3,
      "z": -4,
      "name": "Empty",
      "level": 0
    },
    {
      "x": -3,
      "y": 4,
      "z": -4,
      "name": "Empty",
      "level": 0
    },
    {
      "x": -3,
      "y": 5,
      "z": -4,
      "name": "Empty",
      "level": 0
    },
    {
      "x": -3,
      "y": 6,
      "z": -4,
      "name": "Empty",
      "level": 0
    },
    {
      "x": -3,
      "y": 7,
      "z": -4,
      "name": "Empty",
      "level": 0
    },
    {
      "x": -3,
      "y": 0,
      "z": -3,
      "name": "Empty",
      "level": 0
    },
    {
      "x": -3,
      "y": 1,
      "z": -3,
      "name": "Empty",
      "level": 0
    },
    {
      "x": -3,
      "y": 2,
      "z": -3,
      "name": "Empty",
      "level": 0
    },
    {
      "x": -3,
      "y": 3,
      "z": -3,
      "name": "Empty",
      "level": 0
    },
    {
      "x": -3,
      "y": 4,
      "z": -3,
      "name": "Empty",
      "level": 0
    },
    {
      "x": -3,
      "y": 5,
      "z": -3,
      "name": "Empty",
      "level": 0
    },
    {
      "x": -3,
      "y": 6,
      "z": -3,
      "name": "Empty",
      "level": 0
    },
    {
      "x": -3,
      "y": 7,
      "z": -3,
      "name": "Empty",
      "level": 0
    },
    {
      "x": -3,
      "y": 0,
      "z": -2,
      "name": "Empty",
      "level": 0
    },
    {
      "x": -3,
      "y": 1,
      "z": -2,
      "name": "Empty",
      "level": 0
    },
    {
      "x": -3,
      "y": 2,
      "z": -2,
      "name": "Empty",
      "level": 0
    },
    {
      "x": -3,
      "y": 3,
      "z": -2,
      "name": "Empty",
      "level": 0
    },
    {
      "x": -3,
      "y": 4,
      "z": -2,
      "name": "Empty",
      "level": 0
    },
    {
      "x": -3,
      "y": 5,
      "z": -2,
      "name": "Empty",
      "level": 0
    },
    {
      "x": -3,
      "y": 6,
      "z": -2,
      "name": "Empty",
      "level": 0
    },
    {
      "x": -3,
      "y": 7,
      "z": -2,
      "name": "Empty",
      "level": 0
    },
    {
      "x": -3,
      "y": 0,
      "z": -1,
      "name": "Empty",
      "level": 0
    },
    {
      "x": -3,
      "y": 1,
      "z": -1,
      "name": "Empty",
      "level": 0
    },
    {
      "x": -3,
      "y": 2,
      "z": -1,
      "name": "Empty",
      "level": 0
    },
    {
      "x": -3,
      "y": 3,
      "z": -1,
      "name": "Empty",
      "level": 0
    },
    {
      "x": -3,
      "y": 4,
      "z": -1,
      "name": "Empty",
      "level": 0
    },
    {
      "x": -3,
      "y": 5,
      "z": -1,
      "name": "Empty",
      "level": 0
    },
    {
      "x": -3,
      "y": 6,
      "z": -1,
      "name": "Empty",
      "level": 0
    },
    {
      "x": -3,
      "y": 7,
      "z": -1,
      "name": "Empty",
      "level": 0
    },
    {
      "x": -3,
      "y": 0,
      "z": 0,
      "name": "Empty",
      "level": 0
    },
    {
      "x": -3,
      "y": 1,
      "z": 0,
      "name": "Empty",
      "level": 0
    },
    {
      "x": -3,
      "y": 2,
      "z": 0,
      "name": "Empty",
      "level": 0
    },
    {
      "x": -3,
      "y": 3,
      "z": 0,
      "name": "Empty",
      "level": 0
    },
    {
      "x": -3,
      "y": 4,
      "z": 0,
      "name": "Empty",
      "level": 0
    },
    {
      "x": -3,
      "y": 5,
      "z": 0,
      "name": "Empty",
      "level": 0
    },
    {
      "x": -3,
      "y": 6,
      "z": 0,
      "name": "Empty",
      "level": 0
    },
    {
      "x": -3,
      "y": 7,
      "z": 0,
      "name": "Empty",
      "level": 0
    },
    {
      "x": -3,
      "y": 0,
      "z": 1,
      "name": "Empty",
      "level": 0
    },
    {
      "x": -3,
      "y": 1,
      "z": 1,
      "name": "Empty",
      "level": 0
    },
    {
      "x": -3,
      "y": 2,
      "z": 1,
      "name": "Empty",
      "level": 0
    },
    {
      "x": -3,
      "y": 3,
      "z": 1,
      "name": "Empty",
      "level": 0
    },
    {
      "x": -3,
      "y": 4,
      "z": 1,
      "name": "Empty",
      "level": 0
    },
    {
      "x": -3,
      "y": 5,
      "z": 1,
      "name": "Empty",
      "level": 0
    },
    {
      "x": -3,
      "y": 6,
      "z": 1,
      "name": "Empty",
      "level": 0
    },
    {
      "x": -3,
      "y": 7,
      "z": 1,
      "name": "Empty",
      "level": 0
    },
    {
      "x": -3,
      "y": 0,
      "z": 2,
      "name": "Empty",
      "level": 0
    },
    {
      "x": -3,
      "y": 1,
      "z": 2,
      "name": "Empty",
      "level": 0
    },
    {
      "x": -3,
      "y": 2,
      "z": 2,
      "name": "Empty",
      "level": 0
    },
    {
      "x": -3,
      "y": 3,
      "z": 2,
      "name": "Empty",
      "level": 0
    },
    {
      "x": -3,
      "y": 4,
      "z": 2,
      "name": "Empty",
      "level": 0
    },
    {
      "x": -3,
      "y": 5,
      "z": 2,
      "name": "Empty",
      "level": 0
    },
    {
      "x": -3,
      "y": 6,
      "z": 2,
      "name": "Empty",
      "level": 0
    },
    {
      "x": -3,
      "y": 7,
      "z": 2,
      "name": "Empty",
      "level": 0
    },
    {
      "x": -3,
      "y": 0,
      "z": 3,
      "name": "Empty",
      "level": 0
    },
    {
      "x": -3,
      "y": 1,
      "z": 3,
      "name": "Empty",
      "level": 0
    },
    {
      "x": -3,
      "y": 2,
      "z": 3,
      "name": "Empty",
      "level": 0
    },
    {
      "x": -3,
      "y": 3,
      "z": 3,
      "name": "Empty",
      "level": 0
    },
    {
      "x": -3,
      "y": 4,
      "z": 3,
      "name": "Empty",
      "level": 0
    },
    {
      "x": -3,
      "y": 5,
      "z": 3,
      "name": "Empty",
      "level": 0
    },
    {
      "x": -3,
      "y": 6,
      "z": 3,
      "name": "Empty",
      "level": 0
    },
    {
      "x": -3,
      "y": 7,
      "z": 3,
      "name": "Empty",
      "level": 0
    },
    {
      "x": -3,
      "y": 0,
      "z": 4,
      "name": "Empty",
      "level": 0
    },
    {
      "x": -3,
      "y": 1,
      "z": 4,
      "name": "Empty",
      "level": 0
    },
    {
      "x": -3,
      "y": 2,
      "z": 4,
      "name": "Empty",
      "level": 0
    },
    {
      "x": -3,
      "y": 3,
      "z": 4,
      "name": "Empty",
      "level": 0
    },
    {
      "x": -3,
      "y": 4,
      "z": 4,
      "name": "Empty",
      "level": 0
    },
    {
      "x": -3,
      "y": 5,
      "z": 4,
      "name": "Empty",
      "level": 0
    },
    {
      "x": -3,
      "y": 6,
      "z": 4,
      "name": "Empty",
      "level": 0
    },
    {
      "x": -3,
      "y": 7,
      "z": 4,
      "name": "Empty",
      "level": 0
    },
    {
      "x": -2,
      "y": 0,
      "z": -5,
      "name": "Empty",
      "level": 0
    },
    {
      "x": -2,
      "y": 1,
      "z": -5,
      "name": "Empty",
      "level": 0
    },
    {
      "x": -2,
      "y": 2,
      "z": -5,
      "name": "Empty",
      "level": 0
    },
    {
      "x": -2,
      "y": 3,
      "z": -5,
      "name": "Empty",
      "level": 0
    },
    {
      "x": -2,
      "y": 4,
      "z": -5,
      "name": "Empty",
      "level": 0
    },
    {
      "x": -2,
      "y": 5,
      "z": -5,
      "name": "Empty",
      "level": 0
    },
    {
      "x": -2,
      "y": 6,
      "z": -5,
      "name": "Empty",
      "level": 0
    },
    {
      "x": -2,
      "y": 7,
      "z": -5,
      "name": "Empty",
      "level": 0
    },
    {
      "x": -2,
      "y": 0,
      "z": -4,
      "name": "Empty",
      "level": 0
    },
    {
      "x": -2,
      "y": 1,
      "z": -4,
      "name": "Empty",
      "level": 0
    },
    {
      "x": -2,
      "y": 2,
      "z": -4,
      "name": "Empty",
      "level": 0
    },
    {
      "x": -2,
      "y": 3,
      "z": -4,
      "name": "Empty",
      "level": 0
    },
    {
      "x": -2,
      "y": 4,
      "z": -4,
      "name": "Empty",
      "level": 0
    },
    {
      "x": -2,
      "y": 5,
      "z": -4,
      "name": "Empty",
      "level": 0
    },
    {
      "x": -2,
      "y": 6,
      "z": -4,
      "name": "Empty",
      "level": 0
    },
    {
      "x": -2,
      "y": 7,
      "z": -4,
      "name": "Empty",
      "level": 0
    },
    {
      "x": -2,
      "y": 0,
      "z": -3,
      "name": "Empty",
      "level": 0
    },
    {
      "x": -2,
      "y": 1,
      "z": -3,
      "name": "Empty",
      "level": 0
    },
    {
      "x": -2,
      "y": 2,
      "z": -3,
      "name": "Empty",
      "level": 0
    },
    {
      "x": -2,
      "y": 3,
      "z": -3,
      "name": "Empty",
      "level": 0
    },
    {
      "x": -2,
      "y": 4,
      "z": -3,
      "name": "Empty",
      "level": 0
    },
    {
      "x": -2,
      "y": 5,
      "z": -3,
      "name": "Empty",
      "level": 0
    },
    {
      "x": -2,
      "y": 6,
      "z": -3,
      "name": "Empty",
      "level": 0
    },
    {
      "x": -2,
      "y": 7,
      "z": -3,
      "name": "Empty",
      "level": 0
    },
    {
      "x": -2,
      "y": 0,
      "z": -2,
      "name": "Empty",
      "level": 0
    },
    {
      "x": -2,
      "y": 1,
      "z": -2,
      "name": "Empty",
      "level": 0
    },
    {
      "x": -2,
      "y": 2,
      "z": -2,
      "name": "Empty",
      "level": 0
    },
    {
      "x": -2,
      "y": 3,
      "z": -2,
      "name": "Empty",
      "level": 0
    },
    {
      "x": -2,
      "y": 4,
      "z": -2,
      "name": "Empty",
      "level": 0
    },
    {
      "x": -2,
      "y": 5,
      "z": -2,
      "name": "Empty",
      "level": 0
    },
    {
      "x": -2,
      "y": 6,
      "z": -2,
      "name": "Empty",
      "level": 0
    },
    {
      "x": -2,
      "y": 7,
      "z": -2,
      "name": "Empty",
      "level": 0
    },
    {
      "x": -2,
      "y": 0,
      "z": -1,
      "name": "Empty",
      "level": 0
    },
    {
      "x": -2,
      "y": 1,
      "z": -1,
      "name": "Empty",
      "level": 0
    },
    {
      "x": -2,
      "y": 2,
      "z": -1,
      "name": "Empty",
      "level": 0
    },
    {
      "x": -2,
      "y": 3,
      "z": -1,
      "name": "Empty",
      "level": 0
    },
    {
      "x": -2,
      "y": 4,
      "z": -1,
      "name": "Empty",
      "level": 0
    },
    {
      "x": -2,
      "y": 5,
      "z": -1,
      "name": "Empty",
      "level": 0
    },
    {
      "x": -2,
      "y": 6,
      "z": -1,
      "name": "Empty",
      "level": 0
    },
    {
      "x": -2,
      "y": 7,
      "z": -1,
      "name": "Empty",
      "level": 0
    },
    {
      "x": -2,
      "y": 0,
      "z": 0,
      "name": "Empty",
      "level": 0
    },
    {
      "x": -2,
      "y": 1,
      "z": 0,
      "name": "Empty",
      "level": 0
    },
    {
      "x": -2,
      "y": 2,
      "z": 0,
      "name": "Empty",
      "level": 0
    },
    {
      "x": -2,
      "y": 3,
      "z": 0,
      "name": "Empty",
      "level": 0
    },
    {
      "x": -2,
      "y": 4,
      "z": 0,
      "name": "Empty",
      "level": 0
    },
    {
      "x": -2,
      "y": 5,
      "z": 0,
      "name": "Empty",
      "level": 0
    },
    {
      "x": -2,
      "y": 6,
      "z": 0,
      "name": "Empty",
      "level": 0
    },
    {
      "x": -2,
      "y": 7,
      "z": 0,
      "name": "Empty",
      "level": 0
    },
    {
      "x": -2,
      "y": 0,
      "z": 1,
      "name": "Empty",
      "level": 0
    },
    {
      "x": -2,
      "y": 1,
      "z": 1,
      "name": "Empty",
      "level": 0
    },
    {
      "x": -2,
      "y": 2,
      "z": 1,
      "name": "Empty",
      "level": 0
    },
    {
      "x": -2,
      "y": 3,
      "z": 1,
      "name": "Empty",
      "level": 0
    },
    {
      "x": -2,
      "y": 4,
      "z": 1,
      "name": "Empty",
      "level": 0
    },
    {
      "x": -2,
      "y": 5,
      "z": 1,
      "name": "Empty",
      "level": 0
    },
    {
      "x": -2,
      "y": 6,
      "z": 1,
      "name": "Empty",
      "level": 0
    },
    {
      "x": -2,
      "y": 7,
      "z": 1,
      "name": "Empty",
      "level": 0
    },
    {
      "x": -2,
      "y": 0,
      "z": 2,
      "name": "Empty",
      "level": 0
    },
    {
      "x": -2,
      "y": 1,
      "z": 2,
      "name": "Empty",
      "level": 0
    },
    {
      "x": -2,
      "y": 2,
      "z": 2,
      "name": "Empty",
      "level": 0
    },
    {
      "x": -2,
      "y": 3,
      "z": 2,
      "name": "Empty",
      "level": 0
    },
    {
      "x": -2,
      "y": 4,
      "z": 2,
      "name": "Empty",
      "level": 0
    },
    {
      "x": -2,
      "y": 5,
      "z": 2,
      "name": "Empty",
      "level": 0
    },
    {
      "x": -2,
      "y": 6,
      "z": 2,
      "name": "Empty",
      "level": 0
    },
    {
      "x": -2,
      "y": 7,
      "z": 2,
      "name": "Empty",
      "level": 0
    },
    {
      "x": -2,
      "y": 0,
      "z": 3,
      "name": "Empty",
      "level": 0
    },
    {
      "x": -2,
      "y": 1,
      "z": 3,
      "name": "Empty",
      "level": 0
    },
    {
      "x": -2,
      "y": 2,
      "z": 3,
      "name": "Empty",
      "level": 0
    },
    {
      "x": -2,
      "y": 3,
      "z": 3,
      "name": "Empty",
      "level": 0
    },
    {
      "x": -2,
      "y": 4,
      "z": 3,
      "name": "Empty",
      "level": 0
    },
    {
      "x": -2,
      "y": 5,
      "z": 3,
      "name": "Empty",
      "level": 0
    },
    {
      "x": -2,
      "y": 6,
      "z": 3,
      "name": "Empty",
      "level": 0
    },
    {
      "x": -2,
      "y": 7,
      "z": 3,
      "name": "Empty",
      "level": 0
    },
    {
      "x": -2,
      "y": 0,
      "z": 4,
      "name": "Empty",
      "level": 0
    },
    {
      "x": -2,
      "y": 1,
      "z": 4,
      "name": "Empty",
      "level": 0
    },
    {
      "x": -2,
      "y": 2,
      "z": 4,
      "name": "Empty",
      "level": 0
    },
    {
      "x": -2,
      "y": 3,
      "z": 4,
      "name": "Empty",
      "level": 0
    },
    {
      "x": -2,
      "y": 4,
      "z": 4,
      "name": "Empty",
      "level": 0
    },
    {
      "x": -2,
      "y": 5,
      "z": 4,
      "name": "Empty",
      "level": 0
    },
    {
      "x": -2,
      "y": 6,
      "z": 4,
      "name": "Empty",
      "level": 0
    },
    {
      "x": -2,
      "y": 7,
      "z": 4,
      "name": "Empty",
      "level": 0
    },
    {
      "x": -2,
      "y": 5,
      "z": 5,
      "name": "Empty",
      "level": 0
    },
    {
      "x": -2,
      "y": 5,
      "z": 6,
      "name": "Empty",
      "level": 0
    },
    {
      "x": -1,
      "y": 0,
      "z": -5,
      "name": "Empty",
      "level": 0
    },
    {
      "x": -1,
      "y": 1,
      "z": -5,
      "name": "Empty",
      "level": 0
    },
    {
      "x": -1,
      "y": 2,
      "z": -5,
      "name": "Empty",
      "level": 0
    },
    {
      "x": -1,
      "y": 3,
      "z": -5,
      "name": "Empty",
      "level": 0
    },
    {
      "x": -1,
      "y": 4,
      "z": -5,
      "name": "Empty",
      "level": 0
    },
    {
      "x": -1,
      "y": 5,
      "z": -5,
      "name": "Empty",
      "level": 0
    },
    {
      "x": -1,
      "y": 6,
      "z": -5,
      "name": "Empty",
      "level": 0
    },
    {
      "x": -1,
      "y": 7,
      "z": -5,
      "name": "Empty",
      "level": 0
    },
    {
      "x": -1,
      "y": 0,
      "z": -4,
      "name": "Empty",
      "level": 0
    },
    {
      "x": -1,
      "y": 1,
      "z": -4,
      "name": "Empty",
      "level": 0
    },
    {
      "x": -1,
      "y": 2,
      "z": -4,
      "name": "Empty",
      "level": 0
    },
    {
      "x": -1,
      "y": 3,
      "z": -4,
      "name": "Empty",
      "level": 0
    },
    {
      "x": -1,
      "y": 4,
      "z": -4,
      "name": "Empty",
      "level": 0
    },
    {
      "x": -1,
      "y": 5,
      "z": -4,
      "name": "Empty",
      "level": 0
    },
    {
      "x": -1,
      "y": 6,
      "z": -4,
      "name": "Empty",
      "level": 0
    },
    {
      "x": -1,
      "y": 7,
      "z": -4,
      "name": "Empty",
      "level": 0
    },
    {
      "x": -1,
      "y": 0,
      "z": -3,
      "name": "Empty",
      "level": 0
    },
    {
      "x": -1,
      "y": 1,
      "z": -3,
      "name": "Empty",
      "level": 0
    },
    {
      "x": -1,
      "y": 2,
      "z": -3,
      "name": "Empty",
      "level": 0
    },
    {
      "x": -1,
      "y": 3,
      "z": -3,
      "name": "Empty",
      "level": 0
    },
    {
      "x": -1,
      "y": 4,
      "z": -3,
      "name": "Empty",
      "level": 0
    },
    {
      "x": -1,
      "y": 5,
      "z": -3,
      "name": "Empty",
      "level": 0
    },
    {
      "x": -1,
      "y": 6,
      "z": -3,
      "name": "Empty",
      "level": 0
    },
    {
      "x": -1,
      "y": 7,
      "z": -3,
      "name": "Empty",
      "level": 0
    },
    {
      "x": -1,
      "y": 0,
      "z": -2,
      "name": "Empty",
      "level": 0
    },
    {
      "x": -1,
      "y": 1,
      "z": -2,
      "name": "Empty",
      "level": 0
    },
    {
      "x": -1,
      "y": 2,
      "z": -2,
      "name": "Empty",
      "level": 0
    },
    {
      "x": -1,
      "y": 3,
      "z": -2,
      "name": "Empty",
      "level": 0
    },
    {
      "x": -1,
      "y": 4,
      "z": -2,
      "name": "Empty",
      "level": 0
    },
    {
      "x": -1,
      "y": 5,
      "z": -2,
      "name": "Empty",
      "level": 0
    },
    {
      "x": -1,
      "y": 6,
      "z": -2,
      "name": "Empty",
      "level": 0
    },
    {
      "x": -1,
      "y": 7,
      "z": -2,
      "name": "Empty",
      "level": 0
    },
    {
      "x": -1,
      "y": 0,
      "z": -1,
      "name": "Empty",
      "level": 0
    },
    {
      "x": -1,
      "y": 1,
      "z": -1,
      "name": "Empty",
      "level": 0
    },
    {
      "x": -1,
      "y": 2,
      "z": -1,
      "name": "Empty",
      "level": 0
    },
    {
      "x": -1,
      "y": 3,
      "z": -1,
      "name": "Empty",
      "level": 0
    },
    {
      "x": -1,
      "y": 4,
      "z": -1,
      "name": "Empty",
      "level": 0
    },
    {
      "x": -1,
      "y": 5,
      "z": -1,
      "name": "Empty",
      "level": 0
    },
    {
      "x": -1,
      "y": 6,
      "z": -1,
      "name": "Empty",
      "level": 0
    },
    {
      "x": -1,
      "y": 7,
      "z": -1,
      "name": "Empty",
      "level": 0
    },
    {
      "x": -1,
      "y": 0,
      "z": 0,
      "name": "Empty",
      "level": 0
    },
    {
      "x": -1,
      "y": 1,
      "z": 0,
      "name": "Empty",
      "level": 0
    },
    {
      "x": -1,
      "y": 2,
      "z": 0,
      "name": "Empty",
      "level": 0
    },
    {
      "x": -1,
      "y": 3,
      "z": 0,
      "name": "Empty",
      "level": 0
    },
    {
      "x": -1,
      "y": 4,
      "z": 0,
      "name": "Empty",
      "level": 0
    },
    {
      "x": -1,
      "y": 5,
      "z": 0,
      "name": "Empty",
      "level": 0
    },
    {
      "x": -1,
      "y": 6,
      "z": 0,
      "name": "Empty",
      "level": 0
    },
    {
      "x": -1,
      "y": 7,
      "z": 0,
      "name": "Empty",
      "level": 0
    },
    {
      "x": -1,
      "y": 0,
      "z": 1,
      "name": "Empty",
      "level": 0
    },
    {
      "x": -1,
      "y": 1,
      "z": 1,
      "name": "Empty",
      "level": 0
    },
    {
      "x": -1,
      "y": 2,
      "z": 1,
      "name": "Empty",
      "level": 0
    },
    {
      "x": -1,
      "y": 3,
      "z": 1,
      "name": "Empty",
      "level": 0
    },
    {
      "x": -1,
      "y": 4,
      "z": 1,
      "name": "Empty",
      "level": 0
    },
    {
      "x": -1,
      "y": 5,
      "z": 1,
      "name": "Empty",
      "level": 0
    },
    {
      "x": -1,
      "y": 6,
      "z": 1,
      "name": "Empty",
      "level": 0
    },
    {
      "x": -1,
      "y": 7,
      "z": 1,
      "name": "Empty",
      "level": 0
    },
    {
      "x": -1,
      "y": 0,
      "z": 2,
      "name": "Empty",
      "level": 0
    },
    {
      "x": -1,
      "y": 1,
      "z": 2,
      "name": "Empty",
      "level": 0
    },
    {
      "x": -1,
      "y": 2,
      "z": 2,
      "name": "Empty",
      "level": 0
    },
    {
      "x": -1,
      "y": 3,
      "z": 2,
      "name": "Empty",
      "level": 0
    },
    {
      "x": -1,
      "y": 4,
      "z": 2,
      "name": "Empty",
      "level": 0
    },
    {
      "x": -1,
      "y": 5,
      "z": 2,
      "name": "Empty",
      "level": 0
    },
    {
      "x": -1,
      "y": 6,
      "z": 2,
      "name": "Empty",
      "level": 0
    },
    {
      "x": -1,
      "y": 7,
      "z": 2,
      "name": "Empty",
      "level": 0
    },
    {
      "x": -1,
      "y": 0,
      "z": 3,
      "name": "Empty",
      "level": 0
    },
    {
      "x": -1,
      "y": 1,
      "z": 3,
      "name": "Empty",
      "level": 0
    },
    {
      "x": -1,
      "y": 2,
      "z": 3,
      "name": "Empty",
      "level": 0
    },
    {
      "x": -1,
      "y": 3,
      "z": 3,
      "name": "Empty",
      "level": 0
    },
    {
      "x": -1,
      "y": 4,
      "z": 3,
      "name": "Empty",
      "level": 0
    },
    {
      "x": -1,
      "y": 5,
      "z": 3,
      "name": "Empty",
      "level": 0
    },
    {
      "x": -1,
      "y": 6,
      "z": 3,
      "name": "Empty",
      "level": 0
    },
    {
      "x": -1,
      "y": 7,
      "z": 3,
      "name": "Empty",
      "level": 0
    },
    {
      "x": -1,
      "y": 0,
      "z": 4,
      "name": "Empty",
      "level": 0
    },
    {
      "x": -1,
      "y": 1,
      "z": 4,
      "name": "Empty",
      "level": 0
    },
    {
      "x": -1,
      "y": 2,
      "z": 4,
      "name": "Empty",
      "level": 0
    },
