{
  "version": 8,
  "blockIdVersion": 11,
  "anchorX": 0,
  "anchorY": 0,
  "anchorZ": 0,
  "blocks": [
    {
      "x": -4,
      "y": 0,
      "z": -4,
      "name": "Rock_Stone"
    },
    {
      "x": -4,
      "y": 1,
      "z": -4,
      "name": "Rock_Stone"
    },
    {
      "x": -4,
      "y": 2,
      "z": -4,
      "name": "Rock_Stone"
    },
    {
      "x": -4,
      "y": 3,
      "z": -4,
      "name": "Rock_Stone"
    },
    {
      "x": -4,
      "y": 4,
      "z": -4,
      "name": "Rock_Stone"
    },
    {
      "x": -4,
      "y": 5,
      "z": -4,
      "name": "Nat20_Force_Empty"
    },
    {
      "x": -4,
      "y": 6,
      "z": -4,
      "name": "Nat20_Force_Empty"
    },
    {
      "x": -4,
      "y": 7,
      "z": -4,
      "name": "Nat20_Force_Empty"
    },
    {
      "x": -4,
      "y": 8,
      "z": -4,
      "name": "Nat20_Force_Empty"
    },
    {
      "x": -4,
      "y": 9,
      "z": -4,
      "name": "Nat20_Force_Empty"
    },
    {
      "x": -4,
      "y": 10,
      "z": -4,
      "name": "Nat20_Force_Empty"
    },
    {
      "x": -4,
      "y": 11,
      "z": -4,
      "name": "Nat20_Force_Empty"
    },
    {
      "x": -4,
      "y": 0,
      "z": -3,
      "name": "Rock_Stone"
    },
    {
      "x": -4,
      "y": 1,
      "z": -3,
      "name": "Rock_Stone"
    },
    {
      "x": -4,
      "y": 2,
      "z": -3,
      "name": "Rock_Stone"
    },
    {
      "x": -4,
      "y": 3,
      "z": -3,
      "name": "Rock_Stone"
    },
    {
      "x": -4,
      "y": 4,
      "z": -3,
      "name": "Rock_Stone"
    },
    {
      "x": -4,
      "y": 5,
      "z": -3,
      "name": "Deco_Bone_Ribs",
      "rotation": 3
    },
    {
      "x": -4,
      "y": 6,
      "z": -3,
      "name": "Nat20_Force_Empty"
    },
    {
      "x": -4,
      "y": 7,
      "z": -3,
      "name": "Nat20_Force_Empty"
    },
    {
      "x": -4,
      "y": 8,
      "z": -3,
      "name": "Nat20_Force_Empty"
    },
    {
      "x": -4,
      "y": 9,
      "z": -3,
      "name": "Nat20_Force_Empty"
    },
    {
      "x": -4,
      "y": 10,
      "z": -3,
      "name": "Nat20_Force_Empty"
    },
    {
      "x": -4,
      "y": 11,
      "z": -3,
      "name": "Nat20_Force_Empty"
    },
    {
      "x": -4,
      "y": 0,
      "z": -2,
      "name": "Rock_Stone_Cobble"
    },
    {
      "x": -4,
      "y": 1,
      "z": -2,
      "name": "Rock_Stone_Cobble_Half",
      "rotation": 7
    },
    {
      "x": -4,
      "y": 2,
      "z": -2,
      "name": "Rock_Stone_Cobble_Half",
      "rotation": 7
    },
    {
      "x": -4,
      "y": 3,
      "z": -2,
      "name": "Rock_Stone_Cobble"
    },
    {
      "x": -4,
      "y": 4,
      "z": -2,
      "name": "Nat20_Force_Empty"
    },
    {
      "x": -4,
      "y": 5,
      "z": -2,
      "name": "Nat20_Force_Empty"
    },
    {
      "x": -4,
      "y": 6,
      "z": -2,
      "name": "Nat20_Force_Empty"
    },
    {
      "x": -4,
      "y": 7,
      "z": -2,
      "name": "Nat20_Force_Empty"
    },
    {
      "x": -4,
      "y": 8,
      "z": -2,
      "name": "Nat20_Force_Empty"
    },
    {
      "x": -4,
      "y": 9,
      "z": -2,
      "name": "Nat20_Force_Empty"
    },
    {
      "x": -4,
      "y": 10,
      "z": -2,
      "name": "Nat20_Force_Empty"
    },
    {
      "x": -4,
      "y": 11,
      "z": -2,
      "name": "Nat20_Force_Empty"
    },
    {
      "x": -4,
      "y": 0,
      "z": -1,
      "name": "Rock_Stone_Cobble"
    },
    {
      "x": -4,
      "y": 1,
      "z": -1,
      "name": "Rock_Stone_Cobble_Half",
      "rotation": 7
    },
    {
      "x": -4,
      "y": 2,
      "z": -1,
      "name": "Rock_Stone_Cobble"
    },
    {
      "x": -4,
      "y": 3,
      "z": -1,
      "name": "Rock_Stone_Cobble"
    },
    {
      "x": -4,
      "y": 4,
      "z": -1,
      "name": "Rock_Stone_Cobble_Half"
    },
    {
      "x": -4,
      "y": 5,
      "z": -1,
      "name": "Nat20_Force_Empty"
    },
    {
      "x": -4,
      "y": 6,
      "z": -1,
      "name": "Nat20_Force_Empty"
    },
    {
      "x": -4,
      "y": 7,
      "z": -1,
      "name": "Nat20_Force_Empty"
    },
    {
      "x": -4,
      "y": 8,
      "z": -1,
      "name": "Nat20_Force_Empty"
    },
    {
      "x": -4,
      "y": 9,
      "z": -1,
      "name": "Nat20_Force_Empty"
    },
    {
      "x": -4,
      "y": 10,
      "z": -1,
      "name": "Nat20_Force_Empty"
    },
    {
      "x": -4,
      "y": 11,
      "z": -1,
      "name": "Nat20_Force_Empty"
    },
    {
      "x": -4,
      "y": 0,
      "z": 0,
      "name": "Rock_Stone_Cobble"
    },
    {
      "x": -4,
      "y": 1,
      "z": 0,
      "name": "Rock_Stone_Cobble"
    },
    {
      "x": -4,
      "y": 2,
      "z": 0,
      "name": "Rock_Stone_Cobble"
    },
    {
      "x": -4,
      "y": 3,
      "z": 0,
      "name": "Rock_Stone_Cobble"
    },
    {
      "x": -4,
      "y": 4,
      "z": 0,
      "name": "Rock_Stone_Cobble_Half"
    },
    {
      "x": -4,
      "y": 5,
      "z": 0,
      "name": "Nat20_Force_Empty"
    },
    {
      "x": -4,
      "y": 6,
      "z": 0,
      "name": "Nat20_Force_Empty"
    },
    {
      "x": -4,
      "y": 7,
      "z": 0,
      "name": "Nat20_Force_Empty"
    },
    {
      "x": -4,
      "y": 8,
      "z": 0,
      "name": "Nat20_Force_Empty"
    },
    {
      "x": -4,
      "y": 9,
      "z": 0,
      "name": "Nat20_Force_Empty"
    },
    {
      "x": -4,
      "y": 10,
      "z": 0,
      "name": "Nat20_Force_Empty"
    },
    {
      "x": -4,
      "y": 11,
      "z": 0,
      "name": "Nat20_Force_Empty"
    },
    {
      "x": -4,
      "y": 0,
      "z": 1,
      "name": "Rock_Stone_Cobble"
    },
    {
      "x": -4,
      "y": 1,
      "z": 1,
      "name": "Rock_Stone_Cobble"
    },
    {
      "x": -4,
      "y": 2,
      "z": 1,
      "name": "Nat20_Force_Empty"
    },
    {
      "x": -4,
      "y": 3,
      "z": 1,
      "name": "Rock_Stone_Cobble"
    },
    {
      "x": -4,
      "y": 4,
      "z": 1,
      "name": "Rock_Stone_Cobble_Half"
    },
    {
      "x": -4,
      "y": 5,
      "z": 1,
      "name": "Nat20_Force_Empty"
    },
    {
      "x": -4,
      "y": 6,
      "z": 1,
      "name": "Nat20_Force_Empty"
    },
    {
      "x": -4,
      "y": 7,
      "z": 1,
      "name": "Nat20_Force_Empty"
    },
    {
      "x": -4,
      "y": 8,
      "z": 1,
      "name": "Nat20_Force_Empty"
    },
    {
      "x": -4,
      "y": 9,
      "z": 1,
      "name": "Nat20_Force_Empty"
    },
    {
      "x": -4,
      "y": 10,
      "z": 1,
      "name": "Nat20_Force_Empty"
    },
    {
      "x": -4,
      "y": 11,
      "z": 1,
      "name": "Nat20_Force_Empty"
    },
    {
      "x": -4,
      "y": 0,
      "z": 2,
      "name": "Rock_Stone_Cobble"
    },
    {
      "x": -4,
      "y": 1,
      "z": 2,
      "name": "Rock_Stone_Cobble"
    },
    {
      "x": -4,
      "y": 2,
      "z": 2,
      "name": "Rock_Stone_Cobble"
    },
    {
      "x": -4,
      "y": 3,
      "z": 2,
      "name": "Rock_Stone_Cobble"
    },
    {
      "x": -4,
      "y": 4,
      "z": 2,
      "name": "Nat20_Force_Empty"
    },
    {
      "x": -4,
      "y": 5,
      "z": 2,
      "name": "Nat20_Force_Empty"
    },
    {
      "x": -4,
      "y": 6,
      "z": 2,
      "name": "Nat20_Force_Empty"
    },
    {
      "x": -4,
      "y": 7,
      "z": 2,
      "name": "Nat20_Force_Empty"
    },
    {
      "x": -4,
      "y": 8,
      "z": 2,
      "name": "Nat20_Force_Empty"
    },
    {
      "x": -4,
      "y": 9,
      "z": 2,
      "name": "Nat20_Force_Empty"
    },
    {
      "x": -4,
      "y": 10,
      "z": 2,
      "name": "Nat20_Force_Empty"
    },
    {
      "x": -4,
      "y": 11,
      "z": 2,
      "name": "Nat20_Force_Empty"
    },
    {
      "x": -4,
      "y": 0,
      "z": 3,
      "name": "Rock_Stone_Cobble"
    },
    {
      "x": -4,
      "y": 1,
      "z": 3,
      "name": "Rock_Stone_Cobble"
    },
    {
      "x": -4,
      "y": 2,
      "z": 3,
      "name": "Rock_Stone"
    },
    {
      "x": -4,
      "y": 3,
      "z": 3,
      "name": "Rock_Stone"
    },
    {
      "x": -4,
      "y": 4,
      "z": 3,
      "name": "Rock_Stone"
    },
    {
      "x": -4,
      "y": 5,
      "z": 3,
      "name": "Rock_Stone"
    },
    {
      "x": -4,
      "y": 6,
      "z": 3,
      "name": "Nat20_Force_Empty"
    },
    {
      "x": -4,
      "y": 7,
      "z": 3,
      "name": "Nat20_Force_Empty"
    },
    {
      "x": -4,
      "y": 8,
      "z": 3,
      "name": "Nat20_Force_Empty"
    },
    {
      "x": -4,
      "y": 9,
      "z": 3,
      "name": "Nat20_Force_Empty"
    },
    {
      "x": -4,
      "y": 10,
      "z": 3,
      "name": "Nat20_Force_Empty"
    },
    {
      "x": -4,
      "y": 11,
      "z": 3,
      "name": "Nat20_Force_Empty"
    },
    {
      "x": -4,
      "y": 0,
      "z": 4,
      "name": "Rock_Stone_Cobble"
    },
    {
      "x": -4,
      "y": 1,
      "z": 4,
      "name": "Rock_Stone"
    },
    {
      "x": -4,
      "y": 2,
      "z": 4,
      "name": "Rock_Stone"
    },
    {
      "x": -4,
      "y": 3,
      "z": 4,
      "name": "Rock_Stone"
    },
    {
      "x": -4,
      "y": 4,
      "z": 4,
      "name": "Wood_Oak_Trunk",
      "support": 15,
      "rotation": 5
    },
    {
      "x": -4,
      "y": 5,
      "z": 4,
      "name": "Rubble_Stone"
    },
    {
      "x": -4,
      "y": 6,
      "z": 4,
      "name": "Nat20_Force_Empty"
    },
    {
      "x": -4,
      "y": 7,
      "z": 4,
      "name": "Nat20_Force_Empty"
    },
    {
      "x": -4,
      "y": 8,
      "z": 4,
      "name": "Nat20_Force_Empty"
    },
    {
      "x": -4,
      "y": 9,
      "z": 4,
      "name": "Nat20_Force_Empty"
    },
    {
      "x": -4,
      "y": 10,
      "z": 4,
      "name": "Nat20_Force_Empty"
    },
    {
      "x": -4,
      "y": 11,
      "z": 4,
      "name": "Nat20_Force_Empty"
    },
    {
      "x": -3,
      "y": 0,
      "z": -4,
      "name": "Rock_Stone"
    },
    {
      "x": -3,
      "y": 1,
      "z": -4,
      "name": "Rock_Stone"
    },
    {
      "x": -3,
      "y": 2,
      "z": -4,
      "name": "Rock_Stone"
    },
    {
      "x": -3,
      "y": 3,
      "z": -4,
      "name": "Rock_Stone"
    },
    {
      "x": -3,
      "y": 4,
      "z": -4,
      "name": "Rock_Stone"
    },
    {
      "x": -3,
      "y": 5,
      "z": -4,
      "name": "Plant_Leaves_Bramble"
    },
    {
      "x": -3,
      "y": 6,
      "z": -4,
      "name": "Nat20_Force_Empty"
    },
    {
      "x": -3,
      "y": 7,
      "z": -4,
      "name": "Nat20_Force_Empty"
    },
    {
      "x": -3,
      "y": 8,
      "z": -4,
      "name": "Nat20_Force_Empty"
    },
    {
      "x": -3,
      "y": 9,
      "z": -4,
      "name": "Nat20_Force_Empty"
    },
    {
      "x": -3,
      "y": 10,
      "z": -4,
      "name": "Nat20_Force_Empty"
    },
    {
      "x": -3,
      "y": 11,
      "z": -4,
      "name": "Nat20_Force_Empty"
    },
    {
      "x": -3,
      "y": 0,
      "z": -3,
      "name": "Rock_Stone"
    },
    {
      "x": -3,
      "y": 1,
      "z": -3,
      "name": "Rock_Stone"
    },
    {
      "x": -3,
      "y": 2,
      "z": -3,
      "name": "Rock_Stone"
    },
    {
      "x": -3,
      "y": 3,
      "z": -3,
      "name": "Rock_Stone"
    },
    {
      "x": -3,
      "y": 4,
      "z": -3,
      "name": "Rock_Stone"
    },
    {
      "x": -3,
      "y": 5,
      "z": -3,
      "name": "Deco_Bone_Full"
    },
    {
      "x": -3,
      "y": 6,
      "z": -3,
      "name": "Deco_Bone_Full"
    },
    {
      "x": -3,
      "y": 7,
      "z": -3,
      "name": "Deco_Bone_Ribs_Long"
    },
    {
      "x": -3,
      "y": 8,
      "z": -3,
      "name": "Nat20_Force_Empty"
    },
    {
      "x": -3,
      "y": 9,
      "z": -3,
      "name": "Nat20_Force_Empty"
    },
    {
      "x": -3,
      "y": 10,
      "z": -3,
      "name": "Nat20_Force_Empty"
    },
    {
      "x": -3,
      "y": 11,
      "z": -3,
      "name": "Nat20_Force_Empty"
    },
    {
      "x": -3,
      "y": 0,
      "z": -2,
      "name": "Soil_Pathway"
    },
    {
      "x": -3,
      "y": 1,
      "z": -2,
      "name": "Furniture_Tavern_Shelf",
      "rotation": 1
    },
    {
      "x": -3,
      "y": 2,
      "z": -2,
      "name": "Furniture_Ancient_Shelf",
      "rotation": 1
    },
    {
      "x": -3,
      "y": 3,
      "z": -2,
      "name": "Nat20_Force_Empty"
    },
    {
      "x": -3,
      "y": 4,
      "z": -2,
      "name": "Wood_Beech_Trunk",
      "support": 15,
      "rotation": 4
    },
    {
      "x": -3,
      "y": 5,
      "z": -2,
      "name": "Cloth_Roof_Leather",
      "rotation": 3
    },
    {
      "x": -3,
      "y": 6,
      "z": -2,
      "name": "Plant_Leaves_Bramble"
    },
    {
      "x": -3,
      "y": 7,
      "z": -2,
      "name": "Nat20_Force_Empty"
    },
    {
      "x": -3,
      "y": 8,
      "z": -2,
      "name": "Nat20_Force_Empty"
    },
    {
      "x": -3,
      "y": 9,
      "z": -2,
      "name": "Nat20_Force_Empty"
    },
    {
      "x": -3,
      "y": 10,
      "z": -2,
      "name": "Nat20_Force_Empty"
    },
    {
      "x": -3,
      "y": 11,
      "z": -2,
      "name": "Nat20_Force_Empty"
    },
    {
      "x": -3,
      "y": 0,
      "z": -1,
      "name": "Soil_Pathway"
    },
    {
      "x": -3,
      "y": 1,
      "z": -1,
      "name": "Nat20_Force_Empty"
    },
    {
      "x": -3,
      "y": 2,
      "z": -1,
      "name": "Nat20_Force_Empty"
    },
    {
      "x": -3,
      "y": 3,
      "z": -1,
      "name": "Nat20_Force_Empty"
    },
    {
      "x": -3,
      "y": 4,
      "z": -1,
      "name": "Wood_Beech_Trunk",
      "support": 15,
      "rotation": 4
    },
    {
      "x": -3,
      "y": 5,
      "z": -1,
      "name": "Cloth_Roof_Leather",
      "rotation": 3
    },
    {
      "x": -3,
      "y": 6,
      "z": -1,
      "name": "Plant_Leaves_Bramble"
    },
    {
      "x": -3,
      "y": 7,
      "z": -1,
      "name": "Nat20_Force_Empty"
    },
    {
      "x": -3,
      "y": 8,
      "z": -1,
      "name": "Nat20_Force_Empty"
    },
    {
      "x": -3,
      "y": 9,
      "z": -1,
      "name": "Nat20_Force_Empty"
    },
    {
      "x": -3,
      "y": 10,
      "z": -1,
      "name": "Nat20_Force_Empty"
    },
    {
      "x": -3,
      "y": 11,
      "z": -1,
      "name": "Nat20_Force_Empty"
    },
    {
      "x": -3,
      "y": 0,
      "z": 0,
      "name": "Soil_Pathway"
    },
    {
      "x": -3,
      "y": 1,
      "z": 0,
      "name": "Nat20_Chest_Spawn"
    },
    {
      "x": -3,
      "y": 2,
      "z": 0,
      "name": "Nat20_Force_Empty"
    },
    {
      "x": -3,
      "y": 3,
      "z": 0,
      "name": "Nat20_Force_Empty"
    },
    {
      "x": -3,
      "y": 4,
      "z": 0,
      "name": "Wood_Beech_Trunk",
      "support": 15,
      "rotation": 4
    },
    {
      "x": -3,
      "y": 5,
      "z": 0,
      "name": "Cloth_Roof_Leather",
      "rotation": 3
    },
    {
      "x": -3,
      "y": 6,
      "z": 0,
      "name": "Nat20_Force_Empty"
    },
    {
      "x": -3,
      "y": 7,
      "z": 0,
      "name": "Nat20_Force_Empty"
    },
    {
      "x": -3,
      "y": 8,
      "z": 0,
      "name": "Nat20_Force_Empty"
    },
    {
      "x": -3,
      "y": 9,
      "z": 0,
      "name": "Nat20_Force_Empty"
    },
    {
      "x": -3,
      "y": 10,
      "z": 0,
      "name": "Nat20_Force_Empty"
    },
    {
      "x": -3,
      "y": 11,
      "z": 0,
      "name": "Nat20_Force_Empty"
    },
    {
      "x": -3,
      "y": 0,
      "z": 1,
      "name": "Soil_Pathway"
    },
    {
      "x": -3,
      "y": 1,
      "z": 1,
      "name": "Nat20_Force_Empty"
    },
    {
      "x": -3,
      "y": 2,
      "z": 1,
      "name": "Nat20_Force_Empty"
    },
    {
      "x": -3,
      "y": 3,
      "z": 1,
      "name": "Deco_Rope_Diagonal"
    },
    {
      "x": -3,
      "y": 4,
      "z": 1,
      "name": "Wood_Beech_Trunk",
      "support": 15,
      "rotation": 4
    },
    {
      "x": -3,
      "y": 5,
      "z": 1,
      "name": "Cloth_Roof_Leather",
      "rotation": 3
    },
    {
      "x": -3,
      "y": 6,
      "z": 1,
      "name": "Nat20_Force_Empty"
    },
    {
      "x": -3,
      "y": 7,
      "z": 1,
      "name": "Nat20_Force_Empty"
    },
    {
      "x": -3,
      "y": 8,
      "z": 1,
      "name": "Nat20_Force_Empty"
    },
    {
      "x": -3,
      "y": 9,
      "z": 1,
      "name": "Nat20_Force_Empty"
    },
    {
      "x": -3,
      "y": 10,
      "z": 1,
      "name": "Nat20_Force_Empty"
    },
    {
      "x": -3,
      "y": 11,
      "z": 1,
      "name": "Nat20_Force_Empty"
    },
    {
      "x": -3,
      "y": 0,
      "z": 2,
      "name": "Soil_Pathway"
    },
    {
      "x": -3,
      "y": 1,
      "z": 2,
      "name": "Nat20_Force_Empty"
    },
    {
      "x": -3,
      "y": 2,
      "z": 2,
      "name": "Deco_Rope_Diagonal"
    },
    {
      "x": -3,
      "y": 3,
      "z": 2,
      "name": "Nat20_Force_Empty"
    },
    {
      "x": -3,
      "y": 4,
      "z": 2,
      "name": "Wood_Beech_Trunk",
      "support": 15,
      "rotation": 4
    },
    {
      "x": -3,
      "y": 5,
      "z": 2,
      "name": "Cloth_Roof_Leather",
      "rotation": 3
    },
    {
      "x": -3,
      "y": 6,
      "z": 2,
      "name": "Nat20_Force_Empty"
    },
    {
      "x": -3,
      "y": 7,
      "z": 2,
      "name": "Nat20_Force_Empty"
    },
    {
      "x": -3,
      "y": 8,
      "z": 2,
      "name": "Nat20_Force_Empty"
    },
    {
      "x": -3,
      "y": 9,
      "z": 2,
      "name": "Nat20_Force_Empty"
    },
    {
      "x": -3,
      "y": 10,
      "z": 2,
      "name": "Nat20_Force_Empty"
    },
    {
      "x": -3,
      "y": 11,
      "z": 2,
      "name": "Nat20_Force_Empty"
    },
    {
      "x": -3,
      "y": 0,
      "z": 3,
      "name": "Rock_Stone_Cobble"
    },
    {
      "x": -3,
      "y": 1,
      "z": 3,
      "name": "Rock_Stone"
    },
    {
      "x": -3,
      "y": 2,
      "z": 3,
      "name": "Rock_Stone"
    },
    {
      "x": -3,
      "y": 3,
      "z": 3,
      "name": "Rock_Stone"
    },
    {
      "x": -3,
      "y": 4,
      "z": 3,
      "name": "Rock_Stone"
    },
    {
      "x": -3,
      "y": 5,
      "z": 3,
      "name": "Deco_Bone_Full"
    },
    {
      "x": -3,
      "y": 6,
      "z": 3,
      "name": "Deco_Bone_Full"
    },
    {
      "x": -3,
      "y": 7,
      "z": 3,
      "name": "Deco_Bone_Ribs_Long"
    },
    {
      "x": -3,
      "y": 8,
      "z": 3,
      "name": "Deco_Bone_Ribs_Long"
    },
    {
      "x": -3,
      "y": 9,
      "z": 3,
      "name": "Nat20_Force_Empty"
    },
    {
      "x": -3,
      "y": 10,
      "z": 3,
      "name": "Nat20_Force_Empty"
    },
    {
      "x": -3,
      "y": 11,
      "z": 3,
      "name": "Nat20_Force_Empty"
    },
    {
      "x": -3,
      "y": 0,
      "z": 4,
      "name": "Rock_Stone_Cobble"
    },
    {
      "x": -3,
      "y": 1,
      "z": 4,
      "name": "Rock_Stone"
    },
    {
      "x": -3,
      "y": 2,
      "z": 4,
      "name": "Rock_Stone"
    },
    {
      "x": -3,
      "y": 3,
      "z": 4,
      "name": "Wood_Softwood_Stairs",
      "rotation": 10
    },
    {
      "x": -3,
      "y": 4,
      "z": 4,
      "name": "Wood_Oak_Trunk",
      "support": 15,
      "rotation": 5
    },
    {
      "x": -3,
      "y": 5,
      "z": 4,
      "name": "Rock_Stone"
    },
    {
      "x": -3,
      "y": 6,
      "z": 4,
      "name": "Nat20_Force_Empty"
    },
    {
      "x": -3,
      "y": 7,
      "z": 4,
      "name": "Nat20_Force_Empty"
    },
    {
      "x": -3,
      "y": 8,
      "z": 4,
      "name": "Nat20_Force_Empty"
    },
    {
      "x": -3,
      "y": 9,
      "z": 4,
      "name": "Nat20_Force_Empty"
    },
    {
      "x": -3,
      "y": 10,
      "z": 4,
      "name": "Nat20_Force_Empty"
    },
    {
      "x": -3,
      "y": 11,
      "z": 4,
      "name": "Nat20_Force_Empty"
    },
    {
      "x": -2,
      "y": 0,
      "z": -4,
      "name": "Rock_Stone"
    },
    {
      "x": -2,
      "y": 1,
      "z": -4,
      "name": "Rock_Stone"
    },
    {
      "x": -2,
      "y": 2,
      "z": -4,
      "name": "Rock_Stone"
    },
    {
      "x": -2,
      "y": 3,
      "z": -4,
      "name": "Rock_Stone"
    },
    {
      "x": -2,
      "y": 4,
      "z": -4,
      "name": "Plant_Leaves_Bramble"
    },
    {
      "x": -2,
      "y": 5,
      "z": -4,
      "name": "Plant_Leaves_Bramble"
    },
    {
      "x": -2,
      "y": 6,
      "z": -4,
      "name": "Nat20_Force_Empty"
    },
    {
      "x": -2,
      "y": 7,
      "z": -4,
      "name": "Nat20_Force_Empty"
    },
    {
      "x": -2,
      "y": 8,
      "z": -4,
      "name": "Nat20_Force_Empty"
    },
    {
      "x": -2,
      "y": 9,
      "z": -4,
      "name": "Nat20_Force_Empty"
    },
    {
      "x": -2,
      "y": 10,
      "z": -4,
      "name": "Nat20_Force_Empty"
    },
    {
      "x": -2,
      "y": 11,
      "z": -4,
      "name": "Nat20_Force_Empty"
    },
    {
      "x": -2,
      "y": 0,
      "z": -3,
      "name": "Rock_Stone"
    },
    {
      "x": -2,
      "y": 1,
      "z": -3,
      "name": "Rock_Stone"
    },
    {
      "x": -2,
      "y": 2,
      "z": -3,
      "name": "Rock_Stone"
    },
    {
      "x": -2,
      "y": 3,
      "z": -3,
      "name": "Nat20_Force_Empty"
    },
    {
      "x": -2,
      "y": 4,
      "z": -3,
      "name": "Wood_Beech_Trunk",
      "support": 15,
      "rotation": 5
    },
    {
      "x": -2,
      "y": 5,
      "z": -3,
      "name": "Cloth_Roof_Leather",
      "rotation": 2
    },
    {
      "x": -2,
      "y": 6,
      "z": -3,
      "name": "Plant_Leaves_Bramble"
    },
    {
      "x": -2,
      "y": 7,
      "z": -3,
      "name": "Nat20_Force_Empty"
    },
    {
      "x": -2,
      "y": 8,
      "z": -3,
      "name": "Nat20_Force_Empty"
    },
    {
      "x": -2,
      "y": 9,
      "z": -3,
      "name": "Nat20_Force_Empty"
    },
    {
      "x": -2,
      "y": 10,
      "z": -3,
      "name": "Nat20_Force_Empty"
    },
    {
      "x": -2,
      "y": 11,
      "z": -3,
      "name": "Nat20_Force_Empty"
    },
    {
      "x": -2,
      "y": 0,
      "z": -2,
      "name": "Soil_Pathway"
    },
    {
      "x": -2,
      "y": 1,
      "z": -2,
      "name": "Nat20_Force_Empty"
    },
    {
      "x": -2,
      "y": 2,
      "z": -2,
      "name": "Nat20_Force_Empty"
    },
    {
      "x": -2,
      "y": 3,
      "z": -2,
      "name": "Nat20_Force_Empty"
    },
    {
      "x": -2,
      "y": 4,
      "z": -2,
      "name": "Wood_Beech_Trunk_Full",
      "support": 15
    },
    {
      "x": -2,
      "y": 5,
      "z": -2,
      "name": "Wood_Beech_Trunk",
      "support": 15
    },
    {
      "x": -2,
      "y": 6,
      "z": -2,
      "name": "Wood_Beech_Trunk",
      "support": 15
    },
    {
      "x": -2,
      "y": 7,
      "z": -2,
      "name": "Wood_Beech_Trunk",
      "support": 15
    },
    {
      "x": -2,
      "y": 8,
      "z": -2,
      "name": "Wood_Beech_Trunk_Full",
      "support": 15
    },
    {
      "x": -2,
      "y": 9,
      "z": -2,
      "name": "Wood_Beech_Branch_Long",
      "support": 15
    },
    {
      "x": -2,
      "y": 10,
      "z": -2,
      "name": "Wood_Softwood_Beam"
    },
    {
      "x": -2,
      "y": 11,
      "z": -2,
      "name": "Nat20_Force_Empty"
    },
    {
      "x": -2,
      "y": 0,
      "z": -1,
      "name": "Soil_Pathway"
    },
    {
      "x": -2,
      "y": 1,
      "z": -1,
      "name": "Nat20_Force_Empty"
    },
    {
      "x": -2,
      "y": 2,
      "z": -1,
      "name": "Nat20_Force_Empty"
    },
    {
      "x": -2,
      "y": 3,
      "z": -1,
      "name": "Nat20_Force_Empty"
    },
    {
      "x": -2,
      "y": 4,
      "z": -1,
      "name": "Nat20_Force_Empty"
    },
    {
      "x": -2,
      "y": 5,
      "z": -1,
      "name": "Nat20_Force_Empty"
    },
    {
      "x": -2,
      "y": 6,
      "z": -1,
      "name": "Wood_Softwood_Planks"
    },
    {
      "x": -2,
      "y": 7,
      "z": -1,
      "name": "Plant_Leaves_Bramble"
    },
    {
      "x": -2,
      "y": 8,
      "z": -1,
      "name": "Nat20_Force_Empty"
    },
    {
      "x": -2,
      "y": 9,
      "z": -1,
      "name": "Nat20_Force_Empty"
    },
    {
      "x": -2,
      "y": 10,
      "z": -1,
      "name": "Nat20_Force_Empty"
    },
    {
      "x": -2,
      "y": 11,
      "z": -1,
      "name": "Nat20_Force_Empty"
    },
    {
      "x": -2,
      "y": 0,
      "z": 0,
      "name": "Soil_Pathway"
    },
    {
      "x": -2,
      "y": 1,
      "z": 0,
      "name": "Nat20_Force_Empty"
    },
    {
      "x": -2,
      "y": 2,
      "z": 0,
      "name": "Nat20_Force_Empty"
    },
    {
      "x": -2,
      "y": 3,
      "z": 0,
      "name": "Nat20_Force_Empty"
    },
    {
      "x": -2,
      "y": 4,
      "z": 0,
      "name": "Nat20_Force_Empty"
    },
    {
      "x": -2,
      "y": 5,
      "z": 0,
      "name": "Nat20_Force_Empty"
    },
    {
      "x": -2,
      "y": 6,
      "z": 0,
      "name": "Wood_Softwood_Planks"
    },
    {
      "x": -2,
      "y": 7,
      "z": 0,
      "name": "Cloth_Roof_Leather",
      "rotation": 3
    },
    {
      "x": -2,
      "y": 8,
      "z": 0,
      "name": "Nat20_Force_Empty"
    },
    {
      "x": -2,
      "y": 9,
      "z": 0,
      "name": "Nat20_Force_Empty"
    },
    {
      "x": -2,
      "y": 10,
      "z": 0,
      "name": "Nat20_Force_Empty"
    },
    {
      "x": -2,
      "y": 11,
      "z": 0,
      "name": "Nat20_Force_Empty"
    },
    {
      "x": -2,
      "y": 0,
      "z": 1,
      "name": "Soil_Pathway"
    },
    {
      "x": -2,
      "y": 1,
      "z": 1,
      "name": "Nat20_Force_Empty"
    },
    {
      "x": -2,
      "y": 2,
      "z": 1,
      "name": "Nat20_Force_Empty"
    },
    {
      "x": -2,
      "y": 3,
      "z": 1,
      "name": "Nat20_Force_Empty"
    },
    {
      "x": -2,
      "y": 4,
      "z": 1,
      "name": "Nat20_Force_Empty"
    },
    {
      "x": -2,
      "y": 5,
      "z": 1,
      "name": "Nat20_Force_Empty"
    },
    {
      "x": -2,
      "y": 6,
      "z": 1,
      "name": "Wood_Softwood_Planks"
    },
    {
      "x": -2,
      "y": 7,
      "z": 1,
      "name": "Cloth_Roof_Leather",
      "rotation": 3
    },
    {
      "x": -2,
      "y": 8,
      "z": 1,
      "name": "Nat20_Force_Empty"
    },
    {
      "x": -2,
      "y": 9,
      "z": 1,
      "name": "Nat20_Force_Empty"
    },
    {
      "x": -2,
      "y": 10,
      "z": 1,
      "name": "Nat20_Force_Empty"
    },
    {
      "x": -2,
      "y": 11,
      "z": 1,
      "name": "Nat20_Force_Empty"
    },
    {
      "x": -2,
      "y": 0,
      "z": 2,
      "name": "Soil_Pathway"
    },
    {
      "x": -2,
      "y": 1,
      "z": 2,
      "name": "Nat20_Force_Empty"
    },
    {
      "x": -2,
      "y": 2,
      "z": 2,
      "name": "Nat20_Force_Empty"
    },
    {
      "x": -2,
      "y": 3,
      "z": 2,
      "name": "Nat20_Force_Empty"
    },
    {
      "x": -2,
      "y": 4,
      "z": 2,
      "name": "Wood_Beech_Trunk_Full",
      "support": 15
    },
    {
      "x": -2,
      "y": 5,
      "z": 2,
      "name": "Wood_Beech_Trunk",
      "support": 15
    },
    {
      "x": -2,
      "y": 6,
      "z": 2,
      "name": "Wood_Beech_Trunk",
      "support": 15
    },
    {
      "x": -2,
      "y": 7,
      "z": 2,
      "name": "Wood_Beech_Trunk",
      "support": 15
    },
    {
      "x": -2,
      "y": 8,
      "z": 2,
      "name": "Wood_Beech_Trunk_Full",
      "support": 15
    },
    {
      "x": -2,
      "y": 9,
      "z": 2,
      "name": "Wood_Beech_Branch_Long",
      "support": 15
    },
    {
      "x": -2,
      "y": 10,
      "z": 2,
      "name": "Wood_Softwood_Beam"
    },
    {
      "x": -2,
      "y": 11,
      "z": 2,
      "name": "Nat20_Force_Empty"
    },
    {
      "x": -2,
      "y": 0,
      "z": 3,
      "name": "Rock_Stone_Cobble"
    },
    {
      "x": -2,
      "y": 1,
      "z": 3,
      "name": "Rock_Stone_Cobble"
    },
    {
      "x": -2,
      "y": 2,
      "z": 3,
      "name": "Rock_Stone_Cobble"
    },
    {
      "x": -2,
      "y": 3,
      "z": 3,
      "name": "Rock_Stone_Cobble"
    },
    {
      "x": -2,
      "y": 4,
      "z": 3,
      "name": "Rock_Stone"
    },
    {
      "x": -2,
      "y": 5,
      "z": 3,
      "name": "Rock_Stone"
    },
    {
      "x": -2,
      "y": 6,
      "z": 3,
      "name": "Plant_Leaves_Bramble"
    },
    {
      "x": -2,
      "y": 7,
      "z": 3,
      "name": "Nat20_Force_Empty"
    },
    {
      "x": -2,
      "y": 8,
      "z": 3,
      "name": "Nat20_Force_Empty"
    },
    {
      "x": -2,
      "y": 9,
      "z": 3,
      "name": "Nat20_Force_Empty"
    },
    {
      "x": -2,
      "y": 10,
      "z": 3,
      "name": "Nat20_Force_Empty"
    },
    {
      "x": -2,
      "y": 11,
      "z": 3,
      "name": "Nat20_Force_Empty"
    },
    {
      "x": -2,
      "y": 0,
      "z": 4,
      "name": "Soil_Dirt"
    },
    {
      "x": -2,
      "y": 1,
      "z": 4,
      "name": "Furniture_Ancient_Barrel"
    },
    {
      "x": -2,
      "y": 2,
      "z": 4,
      "name": "Nat20_Force_Empty"
    },
    {
      "x": -2,
      "y": 3,
      "z": 4,
      "name": "Nat20_Force_Empty"
    },
    {
      "x": -2,
      "y": 4,
      "z": 4,
      "name": "Wood_Oak_Trunk",
      "support": 15,
      "rotation": 5
    },
    {
      "x": -2,
      "y": 5,
      "z": 4,
      "name": "Rock_Stone"
    },
    {
      "x": -2,
      "y": 6,
      "z": 4,
      "name": "Plant_Leaves_Bramble"
    },
    {
      "x": -2,
      "y": 7,
      "z": 4,
      "name": "Nat20_Force_Empty"
    },
    {
      "x": -2,
      "y": 8,
      "z": 4,
      "name": "Nat20_Force_Empty"
    },
    {
      "x": -2,
      "y": 9,
      "z": 4,
      "name": "Nat20_Force_Empty"
    },
    {
      "x": -2,
      "y": 10,
      "z": 4,
      "name": "Nat20_Force_Empty"
    },
    {
      "x": -2,
      "y": 11,
      "z": 4,
      "name": "Nat20_Force_Empty"
    },
    {
      "x": -1,
      "y": 0,
      "z": -4,
      "name": "Rock_Stone_Cobble"
    },
    {
      "x": -1,
      "y": 1,
      "z": -4,
      "name": "Rock_Stone_Cobble_Stairs",
      "rotation": 2
    },
    {
      "x": -1,
      "y": 2,
      "z": -4,
      "name": "Rock_Stone_Cobble_Half",
      "rotation": 6
    },
    {
      "x": -1,
      "y": 3,
      "z": -4,
      "name": "Rock_Stone_Cobble"
    },
    {
      "x": -1,
      "y": 4,
      "z": -4,
      "name": "Rock_Stone_Cobble_Half"
    },
    {
      "x": -1,
      "y": 5,
      "z": -4,
      "name": "Nat20_Force_Empty"
    },
    {
      "x": -1,
      "y": 6,
      "z": -4,
      "name": "Nat20_Force_Empty"
    },
    {
      "x": -1,
      "y": 7,
      "z": -4,
      "name": "Nat20_Force_Empty"
    },
    {
      "x": -1,
      "y": 8,
      "z": -4,
      "name": "Nat20_Force_Empty"
    },
    {
      "x": -1,
      "y": 9,
      "z": -4,
      "name": "Nat20_Force_Empty"
    },
    {
      "x": -1,
      "y": 10,
      "z": -4,
      "name": "Nat20_Force_Empty"
    },
    {
      "x": -1,
      "y": 11,
      "z": -4,
      "name": "Nat20_Force_Empty"
    },
    {
      "x": -1,
      "y": 0,
      "z": -3,
      "name": "Soil_Dirt"
    },
    {
      "x": -1,
      "y": 1,
      "z": -3,
      "name": "Furniture_Village_Crate",
      "components": {
        "Components": {
          "ItemContainerBlock": {
            "ItemContainer": {
              "Capacity": 20,
              "Items": {}
            },
            "Capacity": 20
          }
        }
      }
    },
    {
      "x": -1,
      "y": 2,
      "z": -3,
      "name": "Furniture_Ancient_Barrel"
    },
    {
      "x": -1,
      "y": 3,
      "z": -3,
      "name": "Nat20_Force_Empty"
    },
    {
      "x": -1,
      "y": 4,
      "z": -3,
      "name": "Wood_Beech_Trunk",
      "support": 15,
      "rotation": 5
    },
    {
      "x": -1,
      "y": 5,
      "z": -3,
      "name": "Cloth_Roof_Leather",
      "rotation": 2
    },
    {
      "x": -1,
      "y": 6,
      "z": -3,
      "name": "Plant_Leaves_Bramble"
    },
    {
      "x": -1,
      "y": 7,
      "z": -3,
      "name": "Nat20_Force_Empty"
    },
    {
      "x": -1,
      "y": 8,
      "z": -3,
      "name": "Nat20_Force_Empty"
    },
    {
      "x": -1,
      "y": 9,
      "z": -3,
      "name": "Nat20_Force_Empty"
    },
    {
      "x": -1,
      "y": 10,
      "z": -3,
      "name": "Nat20_Force_Empty"
    },
    {
      "x": -1,
      "y": 11,
      "z": -3,
      "name": "Nat20_Force_Empty"
    },
    {
      "x": -1,
      "y": 0,
      "z": -2,
      "name": "Soil_Pathway"
    },
    {
      "x": -1,
      "y": 1,
      "z": -2,
      "name": "Furniture_Ancient_Crate",
      "components": {
        "Components": {
          "ItemContainerBlock": {
            "ItemContainer": {
              "Capacity": 20,
              "Items": {}
            },
            "Capacity": 20
          }
        }
      }
    },
    {
      "x": -1,
      "y": 2,
      "z": -2,
      "name": "Deco_Bone_Pile"
    },
    {
      "x": -1,
      "y": 3,
      "z": -2,
      "name": "Nat20_Force_Empty"
    },
    {
      "x": -1,
      "y": 4,
      "z": -2,
      "name": "Nat20_Force_Empty"
    },
    {
      "x": -1,
      "y": 5,
      "z": -2,
      "name": "Nat20_Force_Empty"
    },
    {
      "x": -1,
      "y": 6,
      "z": -2,
      "name": "Wood_Softwood_Planks"
    },
    {
      "x": -1,
      "y": 7,
      "z": -2,
      "name": "Plant_Leaves_Bramble"
    },
    {
      "x": -1,
      "y": 8,
      "z": -2,
      "name": "Nat20_Force_Empty"
    },
    {
      "x": -1,
      "y": 9,
      "z": -2,
      "name": "Nat20_Force_Empty"
    },
    {
      "x": -1,
      "y": 10,
      "z": -2,
      "name": "Nat20_Force_Empty"
    },
    {
      "x": -1,
      "y": 11,
      "z": -2,
      "name": "Nat20_Force_Empty"
    },
    {
      "x": -1,
      "y": 0,
      "z": -1,
      "name": "Soil_Gravel"
    },
    {
      "x": -1,
      "y": 1,
      "z": -1,
      "name": "Nat20_Force_Empty"
    },
    {
      "x": -1,
      "y": 2,
      "z": -1,
      "name": "Nat20_Force_Empty"
    },
    {
      "x": -1,
      "y": 3,
      "z": -1,
      "name": "Nat20_Force_Empty"
    },
    {
      "x": -1,
      "y": 4,
      "z": -1,
      "name": "Nat20_Force_Empty"
    },
    {
      "x": -1,
      "y": 5,
      "z": -1,
      "name": "Nat20_Force_Empty"
    },
    {
      "x": -1,
      "y": 6,
      "z": -1,
      "name": "Nat20_Force_Empty"
    },
    {
      "x": -1,
      "y": 7,
      "z": -1,
      "name": "Nat20_Force_Empty"
    },
    {
      "x": -1,
      "y": 8,
      "z": -1,
      "name": "Cloth_Roof_Leather_Flat"
    },
    {
      "x": -1,
      "y": 9,
      "z": -1,
      "name": "Nat20_Force_Empty"
    },
    {
      "x": -1,
      "y": 10,
      "z": -1,
      "name": "Nat20_Force_Empty"
    },
    {
      "x": -1,
      "y": 11,
      "z": -1,
      "name": "Nat20_Force_Empty"
    },
    {
      "x": -1,
      "y": 0,
      "z": 0,
      "name": "Soil_Gravel"
    },
    {
      "x": -1,
      "y": 1,
      "z": 0,
      "name": "Nat20_Force_Empty"
    },
    {
      "x": -1,
      "y": 2,
      "z": 0,
      "name": "Nat20_Force_Empty"
    },
    {
      "x": -1,
      "y": 3,
      "z": 0,
      "name": "Nat20_Force_Empty"
    },
    {
      "x": -1,
      "y": 4,
      "z": 0,
      "name": "Nat20_Force_Empty"
    },
    {
      "x": -1,
      "y": 5,
      "z": 0,
      "name": "Nat20_Force_Empty"
    },
    {
      "x": -1,
      "y": 6,
      "z": 0,
      "name": "Nat20_Force_Empty"
    },
    {
      "x": -1,
      "y": 7,
      "z": 0,
      "name": "Nat20_Force_Empty"
    },
    {
      "x": -1,
      "y": 8,
      "z": 0,
      "name": "Cloth_Roof_Leather_Flat"
    },
    {
      "x": -1,
      "y": 9,
      "z": 0,
      "name": "Nat20_Force_Empty"
    },
    {
      "x": -1,
      "y": 10,
      "z": 0,
      "name": "Nat20_Force_Empty"
    },
    {
      "x": -1,
      "y": 11,
      "z": 0,
      "name": "Nat20_Force_Empty"
    },
    {
      "x": -1,
      "y": 0,
      "z": 1,
      "name": "Soil_Pathway"
    },
    {
      "x": -1,
      "y": 1,
      "z": 1,
      "name": "Nat20_Force_Empty"
    },
    {
      "x": -1,
      "y": 2,
      "z": 1,
      "name": "Nat20_Force_Empty"
    },
    {
      "x": -1,
      "y": 3,
      "z": 1,
      "name": "Nat20_Force_Empty"
    },
    {
      "x": -1,
      "y": 4,
      "z": 1,
      "name": "Nat20_Force_Empty"
    },
    {
      "x": -1,
      "y": 5,
      "z": 1,
      "name": "Nat20_Force_Empty"
    },
    {
      "x": -1,
      "y": 6,
      "z": 1,
      "name": "Nat20_Force_Empty"
    },
    {
      "x": -1,
      "y": 7,
      "z": 1,
      "name": "Nat20_Force_Empty"
    },
    {
      "x": -1,
      "y": 8,
      "z": 1,
      "name": "Cloth_Roof_Leather_Flat"
    },
    {
      "x": -1,
      "y": 9,
      "z": 1,
      "name": "Nat20_Force_Empty"
    },
    {
      "x": -1,
      "y": 10,
      "z": 1,
      "name": "Nat20_Force_Empty"
    },
    {
      "x": -1,
      "y": 11,
      "z": 1,
      "name": "Nat20_Force_Empty"
    },
    {
      "x": -1,
      "y": 0,
      "z": 2,
      "name": "Soil_Pathway"
    },
    {
      "x": -1,
      "y": 1,
      "z": 2,
      "name": "Nat20_Force_Empty"
    },
    {
      "x": -1,
      "y": 2,
      "z": 2,
      "name": "Nat20_Force_Empty"
    },
    {
      "x": -1,
      "y": 3,
      "z": 2,
      "name": "Nat20_Force_Empty"
    },
    {
      "x": -1,
      "y": 4,
      "z": 2,
      "name": "Nat20_Force_Empty"
    },
    {
      "x": -1,
      "y": 5,
      "z": 2,
      "name": "Nat20_Force_Empty"
    },
    {
      "x": -1,
      "y": 6,
      "z": 2,
      "name": "Wood_Softwood_Planks"
    },
    {
      "x": -1,
      "y": 7,
      "z": 2,
      "name": "Plant_Leaves_Bramble"
    },
    {
      "x": -1,
      "y": 8,
      "z": 2,
      "name": "Nat20_Force_Empty"
    },
    {
      "x": -1,
      "y": 9,
      "z": 2,
      "name": "Nat20_Force_Empty"
    },
    {
      "x": -1,
      "y": 10,
      "z": 2,
      "name": "Nat20_Force_Empty"
    },
    {
      "x": -1,
      "y": 11,
      "z": 2,
      "name": "Nat20_Force_Empty"
    },
    {
      "x": -1,
      "y": 0,
      "z": 3,
      "name": "Soil_Dirt"
    },
    {
      "x": -1,
      "y": 1,
      "z": 3,
      "name": "Nat20_Force_Empty"
    },
    {
      "x": -1,
      "y": 2,
      "z": 3,
      "name": "Nat20_Force_Empty"
    },
    {
      "x": -1,
      "y": 3,
      "z": 3,
      "name": "Rock_Stone_Cobble_Half",
      "rotation": 5
    },
    {
      "x": -1,
      "y": 4,
      "z": 3,
      "name": "Rock_Stone"
    },
    {
      "x": -1,
      "y": 5,
      "z": 3,
      "name": "Rock_Stone"
    },
    {
      "x": -1,
      "y": 6,
      "z": 3,
      "name": "Plant_Leaves_Bramble"
    },
    {
      "x": -1,
      "y": 7,
      "z": 3,
      "name": "Plant_Leaves_Bramble"
    },
    {
      "x": -1,
      "y": 8,
      "z": 3,
      "name": "Nat20_Force_Empty"
    },
    {
      "x": -1,
      "y": 9,
      "z": 3,
      "name": "Nat20_Force_Empty"
    },
    {
      "x": -1,
      "y": 10,
      "z": 3,
      "name": "Nat20_Force_Empty"
    },
    {
      "x": -1,
      "y": 11,
      "z": 3,
      "name": "Nat20_Force_Empty"
    },
    {
      "x": -1,
      "y": 0,
      "z": 4,
      "name": "Soil_Dirt"
    },
    {
      "x": -1,
      "y": 1,
      "z": 4,
      "name": "Nat20_Force_Empty"
    },
    {
      "x": -1,
      "y": 2,
      "z": 4,
      "name": "Nat20_Force_Empty"
    },
    {
      "x": -1,
      "y": 3,
      "z": 4,
      "name": "Nat20_Force_Empty"
    },
    {
      "x": -1,
      "y": 4,
      "z": 4,
      "name": "Wood_Oak_Trunk",
      "support": 15,
      "rotation": 5
    },
    {
      "x": -1,
      "y": 5,
      "z": 4,
      "name": "Rock_Stone"
    },
    {
      "x": -1,
      "y": 6,
      "z": 4,
      "name": "Plant_Leaves_Bramble"
    },
    {
      "x": -1,
      "y": 7,
      "z": 4,
      "name": "Nat20_Force_Empty"
    },
    {
      "x": -1,
      "y": 8,
      "z": 4,
      "name": "Nat20_Force_Empty"
    },
    {
      "x": -1,
      "y": 9,
      "z": 4,
      "name": "Nat20_Force_Empty"
    },
    {
      "x": -1,
      "y": 10,
      "z": 4,
      "name": "Nat20_Force_Empty"
    },
    {
      "x": -1,
      "y": 11,
      "z": 4,
      "name": "Nat20_Force_Empty"
    },
    {
      "x": 0,
      "y": 0,
      "z": -4,
      "name": "Soil_Clay_Brick"
    },
    {
      "x": 0,
      "y": 1,
      "z": -4,
      "name": "Soil_Clay_Brick"
    },
    {
      "x": 0,
      "y": 2,
      "z": -4,
      "name": "Rock_Stone_Cobble_Half",
      "rotation": 6
    },
    {
      "x": 0,
      "y": 3,
      "z": -4,
      "name": "Rock_Stone_Cobble"
    },
    {
      "x": 0,
      "y": 4,
      "z": -4,
      "name": "Rock_Stone_Cobble_Half"
    },
    {
      "x": 0,
      "y": 5,
      "z": -4,
      "name": "Nat20_Force_Empty"
    },
    {
      "x": 0,
      "y": 6,
      "z": -4,
      "name": "Nat20_Force_Empty"
    },
    {
      "x": 0,
      "y": 7,
      "z": -4,
      "name": "Nat20_Force_Empty"
    },
    {
      "x": 0,
      "y": 8,
      "z": -4,
      "name": "Nat20_Force_Empty"
    },
    {
      "x": 0,
      "y": 9,
      "z": -4,
      "name": "Nat20_Force_Empty"
    },
    {
      "x": 0,
      "y": 10,
      "z": -4,
      "name": "Nat20_Force_Empty"
    },
    {
      "x": 0,
      "y": 11,
      "z": -4,
      "name": "Nat20_Force_Empty"
    },
    {
      "x": 0,
      "y": 0,
      "z": -3,
      "name": "Soil_Dirt"
    },
    {
      "x": 0,
      "y": 1,
      "z": -3,
      "name": "Furniture_Village_Crate",
      "components": {
        "Components": {
          "ItemContainerBlock": {
            "ItemContainer": {
              "Capacity": 20,
              "Items": {}
            },
            "Capacity": 20
          }
        }
      }
    },
    {
      "x": 0,
      "y": 2,
      "z": -3,
      "name": "Furniture_Ancient_Barrel"
    },
    {
      "x": 0,
      "y": 3,
      "z": -3,
      "name": "Nat20_Force_Empty"
    },
    {
      "x": 0,
      "y": 4,
      "z": -3,
      "name": "Wood_Beech_Trunk",
      "support": 15,
      "rotation": 5
    },
    {
      "x": 0,
      "y": 5,
      "z": -3,
      "name": "Cloth_Roof_Leather",
      "rotation": 2
    },
    {
      "x": 0,
      "y": 6,
      "z": -3,
      "name": "Nat20_Force_Empty"
    },
    {
      "x": 0,
      "y": 7,
      "z": -3,
      "name": "Nat20_Force_Empty"
    },
    {
      "x": 0,
      "y": 8,
      "z": -3,
      "name": "Nat20_Force_Empty"
    },
    {
      "x": 0,
      "y": 9,
      "z": -3,
      "name": "Nat20_Force_Empty"
    },
    {
      "x": 0,
      "y": 10,
      "z": -3,
      "name": "Nat20_Force_Empty"
    },
    {
      "x": 0,
      "y": 11,
      "z": -3,
      "name": "Nat20_Force_Empty"
    },
    {
      "x": 0,
      "y": 0,
      "z": -2,
      "name": "Soil_Pathway"
    },
    {
      "x": 0,
      "y": 1,
      "z": -2,
      "name": "Nat20_Force_Empty"
    },
    {
      "x": 0,
      "y": 2,
      "z": -2,
      "name": "Nat20_Force_Empty"
    },
    {
      "x": 0,
      "y": 3,
      "z": -2,
      "name": "Nat20_Force_Empty"
    },
    {
      "x": 0,
      "y": 4,
      "z": -2,
      "name": "Nat20_Force_Empty"
    },
    {
      "x": 0,
      "y": 5,
      "z": -2,
      "name": "Nat20_Force_Empty"
    },
    {
      "x": 0,
      "y": 6,
      "z": -2,
      "name": "Wood_Softwood_Planks"
    },
    {
      "x": 0,
      "y": 7,
      "z": -2,
      "name": "Cloth_Roof_Leather",
      "rotation": 2
    },
    {
      "x": 0,
      "y": 8,
      "z": -2,
      "name": "Nat20_Force_Empty"
    },
    {
      "x": 0,
      "y": 9,
      "z": -2,
      "name": "Nat20_Force_Empty"
    },
    {
      "x": 0,
      "y": 10,
      "z": -2,
      "name": "Nat20_Force_Empty"
    },
    {
      "x": 0,
      "y": 11,
      "z": -2,
      "name": "Nat20_Force_Empty"
    },
    {
      "x": 0,
      "y": 0,
      "z": -1,
      "name": "Soil_Gravel"
    },
    {
      "x": 0,
      "y": 1,
      "z": -1,
      "name": "Nat20_Force_Empty"
    },
    {
      "x": 0,
      "y": 2,
      "z": -1,
      "name": "Nat20_Force_Empty"
    },
    {
      "x": 0,
      "y": 3,
      "z": -1,
      "name": "Nat20_Force_Empty"
    },
    {
      "x": 0,
      "y": 4,
      "z": -1,
      "name": "Nat20_Force_Empty"
    },
    {
      "x": 0,
      "y": 5,
      "z": -1,
      "name": "Nat20_Force_Empty"
    },
    {
      "x": 0,
      "y": 6,
      "z": -1,
      "name": "Nat20_Force_Empty"
    },
    {
      "x": 0,
      "y": 7,
      "z": -1,
      "name": "Nat20_Force_Empty"
    },
    {
      "x": 0,
      "y": 8,
      "z": -1,
      "name": "Cloth_Roof_Leather_Flat"
    },
    {
      "x": 0,
      "y": 9,
      "z": -1,
      "name": "Nat20_Force_Empty"
    },
    {
      "x": 0,
      "y": 10,
      "z": -1,
      "name": "Nat20_Force_Empty"
    },
    {
      "x": 0,
      "y": 11,
      "z": -1,
      "name": "Nat20_Force_Empty"
    },
    {
      "x": 0,
      "y": 0,
      "z": 0,
      "name": "Soil_Gravel"
    },
    {
      "x": 0,
      "y": 1,
      "z": 0,
      "name": "Nat20_Force_Empty"
    },
    {
      "x": 0,
      "y": 2,
      "z": 0,
      "name": "Nat20_Force_Empty"
    },
    {
      "x": 0,
      "y": 3,
      "z": 0,
      "name": "Nat20_Force_Empty"
    },
    {
      "x": 0,
      "y": 4,
      "z": 0,
      "name": "Nat20_Force_Empty"
    },
    {
      "x": 0,
      "y": 5,
      "z": 0,
      "name": "Nat20_Force_Empty"
    },
    {
      "x": 0,
      "y": 6,
      "z": 0,
      "name": "Nat20_Force_Empty"
    },
    {
      "x": 0,
      "y": 7,
      "z": 0,
      "name": "Nat20_Force_Empty"
    },
    {
      "x": 0,
      "y": 8,
      "z": 0,
      "name": "Nat20_Force_Empty"
    },
    {
      "x": 0,
      "y": 9,
      "z": 0,
      "name": "Nat20_Force_Empty"
    },
    {
      "x": 0,
      "y": 10,
      "z": 0,
      "name": "Nat20_Force_Empty"
    },
    {
      "x": 0,
      "y": 11,
      "z": 0,
      "name": "Nat20_Force_Empty"
    },
    {
      "x": 0,
      "y": 0,
      "z": 1,
      "name": "Soil_Gravel"
    },
    {
      "x": 0,
      "y": 1,
      "z": 1,
      "name": "Nat20_Force_Empty"
    },
    {
      "x": 0,
      "y": 2,
      "z": 1,
      "name": "Nat20_Force_Empty"
    },
    {
      "x": 0,
      "y": 3,
      "z": 1,
      "name": "Nat20_Force_Empty"
    },
    {
      "x": 0,
      "y": 4,
      "z": 1,
      "name": "Nat20_Force_Empty"
    },
    {
      "x": 0,
      "y": 5,
      "z": 1,
      "name": "Nat20_Force_Empty"
    },
    {
      "x": 0,
      "y": 6,
      "z": 1,
      "name": "Nat20_Force_Empty"
    },
    {
      "x": 0,
      "y": 7,
      "z": 1,
      "name": "Nat20_Force_Empty"
    },
    {
      "x": 0,
      "y": 8,
      "z": 1,
      "name": "Cloth_Roof_Leather_Flat"
    },
    {
      "x": 0,
      "y": 9,
      "z": 1,
      "name": "Nat20_Force_Empty"
    },
    {
      "x": 0,
      "y": 10,
      "z": 1,
      "name": "Nat20_Force_Empty"
    },
    {
      "x": 0,
      "y": 11,
      "z": 1,
      "name": "Nat20_Force_Empty"
    },
    {
      "x": 0,
      "y": 0,
      "z": 2,
      "name": "Soil_Pathway"
    },
    {
      "x": 0,
      "y": 1,
      "z": 2,
      "name": "Nat20_Force_Empty"
    },
    {
      "x": 0,
      "y": 2,
      "z": 2,
      "name": "Nat20_Force_Empty"
    },
    {
      "x": 0,
      "y": 3,
      "z": 2,
      "name": "Nat20_Force_Empty"
    },
    {
      "x": 0,
      "y": 4,
      "z": 2,
      "name": "Nat20_Force_Empty"
    },
    {
      "x": 0,
      "y": 5,
      "z": 2,
      "name": "Nat20_Force_Empty"
    },
    {
      "x": 0,
      "y": 6,
      "z": 2,
      "name": "Wood_Softwood_Planks"
    },
    {
      "x": 0,
      "y": 7,
      "z": 2,
      "name": "Cloth_Roof_Leather"
    },
    {
      "x": 0,
      "y": 8,
      "z": 2,
      "name": "Nat20_Force_Empty"
    },
    {
      "x": 0,
      "y": 9,
      "z": 2,
      "name": "Nat20_Force_Empty"
    },
    {
      "x": 0,
      "y": 10,
      "z": 2,
      "name": "Nat20_Force_Empty"
    },
    {
      "x": 0,
      "y": 11,
      "z": 2,
      "name": "Nat20_Force_Empty"
    },
    {
      "x": 0,
      "y": 0,
      "z": 3,
      "name": "Soil_Pathway"
    },
    {
      "x": 0,
      "y": 1,
      "z": 3,
      "name": "Nat20_Anchor"
    },
    {
      "x": 0,
      "y": 2,
      "z": 3,
      "name": "Nat20_Force_Empty"
    },
    {
      "x": 0,
      "y": 3,
      "z": 3,
      "name": "Nat20_Force_Empty"
    },
    {
      "x": 0,
      "y": 4,
      "z": 3,
      "name": "Rock_Stone"
    },
    {
      "x": 0,
      "y": 5,
      "z": 3,
      "name": "Rock_Stone"
    },
    {
      "x": 0,
      "y": 6,
      "z": 3,
      "name": "Plant_Leaves_Bramble"
    },
    {
      "x": 0,
      "y": 7,
      "z": 3,
      "name": "Nat20_Force_Empty"
    },
    {
      "x": 0,
      "y": 8,
      "z": 3,
      "name": "Nat20_Force_Empty"
    },
    {
      "x": 0,
      "y": 9,
      "z": 3,
      "name": "Nat20_Force_Empty"
    },
    {
      "x": 0,
      "y": 10,
      "z": 3,
      "name": "Nat20_Force_Empty"
    },
    {
      "x": 0,
      "y": 11,
      "z": 3,
      "name": "Nat20_Force_Empty"
    },
    {
      "x": 0,
      "y": 0,
      "z": 4,
      "name": "Soil_Pathway"
    },
    {
      "x": 0,
      "y": 1,
      "z": 4,
      "name": "Nat20_Direction"
    },
    {
      "x": 0,
      "y": 2,
      "z": 4,
      "name": "Nat20_Force_Empty"
    },
    {
      "x": 0,
      "y": 3,
      "z": 4,
      "name": "Nat20_Force_Empty"
    },
    {
      "x": 0,
      "y": 4,
      "z": 4,
      "name": "Wood_Oak_Trunk",
      "support": 15,
      "rotation": 5
    },
    {
      "x": 0,
      "y": 5,
      "z": 4,
      "name": "Rock_Stone"
    },
    {
      "x": 0,
      "y": 6,
      "z": 4,
      "name": "Nat20_Force_Empty"
    },
    {
      "x": 0,
      "y": 7,
      "z": 4,
      "name": "Nat20_Force_Empty"
    },
    {
      "x": 0,
      "y": 8,
      "z": 4,
      "name": "Nat20_Force_Empty"
    },
    {
      "x": 0,
      "y": 9,
      "z": 4,
      "name": "Nat20_Force_Empty"
    },
    {
      "x": 0,
      "y": 10,
      "z": 4,
      "name": "Nat20_Force_Empty"
    },
    {
      "x": 0,
      "y": 11,
      "z": 4,
      "name": "Nat20_Force_Empty"
    },
    {
      "x": 1,
      "y": 0,
      "z": -4,
      "name": "Soil_Clay_Brick"
    },
    {
      "x": 1,
      "y": 1,
      "z": -4,
      "name": "Soil_Clay_Brick"
    },
    {
      "x": 1,
      "y": 2,
      "z": -4,
      "name": "Soil_Clay_Brick"
    },
    {
      "x": 1,
      "y": 3,
      "z": -4,
      "name": "Rock_Stone_Cobble"
    },
    {
      "x": 1,
      "y": 4,
      "z": -4,
      "name": "Rock_Stone_Cobble_Half"
    },
    {
      "x": 1,
      "y": 5,
      "z": -4,
      "name": "Nat20_Force_Empty"
    },
    {
      "x": 1,
      "y": 6,
      "z": -4,
      "name": "Nat20_Force_Empty"
    },
    {
      "x": 1,
      "y": 7,
      "z": -4,
      "name": "Nat20_Force_Empty"
    },
    {
      "x": 1,
      "y": 8,
      "z": -4,
      "name": "Nat20_Force_Empty"
    },
    {
      "x": 1,
      "y": 9,
      "z": -4,
      "name": "Nat20_Force_Empty"
    },
    {
      "x": 1,
      "y": 10,
      "z": -4,
      "name": "Nat20_Force_Empty"
    },
    {
      "x": 1,
      "y": 11,
      "z": -4,
      "name": "Nat20_Force_Empty"
    },
    {
      "x": 1,
      "y": 0,
      "z": -3,
      "name": "Soil_Dirt"
    },
    {
      "x": 1,
      "y": 1,
      "z": -3,
      "name": "Rubble_Stone"
    },
    {
      "x": 1,
      "y": 2,
      "z": -3,
      "name": "Nat20_Force_Empty"
    },
    {
      "x": 1,
      "y": 3,
      "z": -3,
      "name": "Nat20_Force_Empty"
    },
    {
      "x": 1,
      "y": 4,
      "z": -3,
      "name": "Wood_Beech_Trunk",
      "support": 15,
      "rotation": 5
    },
    {
      "x": 1,
      "y": 5,
      "z": -3,
      "name": "Cloth_Roof_Leather",
      "rotation": 2
    },
    {
      "x": 1,
      "y": 6,
      "z": -3,
      "name": "Nat20_Force_Empty"
    },
    {
      "x": 1,
      "y": 7,
      "z": -3,
      "name": "Nat20_Force_Empty"
    },
    {
      "x": 1,
      "y": 8,
      "z": -3,
      "name": "Nat20_Force_Empty"
    },
    {
      "x": 1,
      "y": 9,
      "z": -3,
      "name": "Nat20_Force_Empty"
    },
    {
      "x": 1,
      "y": 10,
      "z": -3,
      "name": "Nat20_Force_Empty"
    },
    {
      "x": 1,
      "y": 11,
      "z": -3,
      "name": "Nat20_Force_Empty"
    },
    {
      "x": 1,
      "y": 0,
      "z": -2,
      "name": "Soil_Dirt"
    },
    {
      "x": 1,
      "y": 1,
      "z": -2,
      "name": "Nat20_Force_Empty"
    },
    {
      "x": 1,
      "y": 2,
      "z": -2,
      "name": "Nat20_Force_Empty"
    },
    {
      "x": 1,
      "y": 3,
      "z": -2,
      "name": "Nat20_Force_Empty"
    },
    {
      "x": 1,
      "y": 4,
      "z": -2,
      "name": "Nat20_Force_Empty"
    },
    {
      "x": 1,
      "y": 5,
      "z": -2,
      "name": "Nat20_Force_Empty"
    },
    {
      "x": 1,
      "y": 6,
      "z": -2,
      "name": "Wood_Softwood_Planks"
    },
    {
      "x": 1,
      "y": 7,
      "z": -2,
      "name": "Cloth_Roof_Leather",
      "rotation": 2
    },
    {
      "x": 1,
      "y": 8,
      "z": -2,
      "name": "Nat20_Force_Empty"
    },
    {
      "x": 1,
      "y": 9,
      "z": -2,
      "name": "Nat20_Force_Empty"
    },
    {
      "x": 1,
      "y": 10,
      "z": -2,
      "name": "Nat20_Force_Empty"
    },
    {
      "x": 1,
      "y": 11,
      "z": -2,
      "name": "Nat20_Force_Empty"
    },
    {
      "x": 1,
      "y": 0,
      "z": -1,
      "name": "Soil_Pathway"
    },
    {
      "x": 1,
      "y": 1,
      "z": -1,
      "name": "Nat20_Npc_Spawn"
    },
    {
      "x": 1,
      "y": 2,
      "z": -1,
      "name": "Nat20_Force_Empty"
    },
    {
      "x": 1,
      "y": 3,
      "z": -1,
      "name": "Nat20_Force_Empty"
    },
    {
      "x": 1,
      "y": 4,
      "z": -1,
      "name": "Nat20_Force_Empty"
    },
    {
      "x": 1,
      "y": 5,
      "z": -1,
      "name": "Nat20_Force_Empty"
    },
    {
      "x": 1,
      "y": 6,
      "z": -1,
      "name": "Nat20_Force_Empty"
    },
    {
      "x": 1,
      "y": 7,
      "z": -1,
      "name": "Nat20_Force_Empty"
    },
    {
      "x": 1,
      "y": 8,
      "z": -1,
      "name": "Cloth_Roof_Leather_Flat"
    },
    {
      "x": 1,
      "y": 9,
      "z": -1,
      "name": "Nat20_Force_Empty"
    },
    {
      "x": 1,
      "y": 10,
      "z": -1,
      "name": "Nat20_Force_Empty"
    },
    {
      "x": 1,
      "y": 11,
      "z": -1,
      "name": "Nat20_Force_Empty"
    },
    {
      "x": 1,
      "y": 0,
      "z": 0,
      "name": "Soil_Pathway"
    },
    {
      "x": 1,
      "y": 1,
      "z": 0,
      "name": "Nat20_Force_Empty"
    },
    {
      "x": 1,
      "y": 2,
      "z": 0,
      "name": "Nat20_Force_Empty"
    },
    {
      "x": 1,
      "y": 3,
      "z": 0,
      "name": "Nat20_Force_Empty"
    },
    {
      "x": 1,
      "y": 4,
      "z": 0,
      "name": "Nat20_Force_Empty"
    },
    {
      "x": 1,
      "y": 5,
      "z": 0,
      "name": "Nat20_Force_Empty"
    },
    {
      "x": 1,
      "y": 6,
      "z": 0,
      "name": "Nat20_Force_Empty"
    },
    {
      "x": 1,
      "y": 7,
      "z": 0,
      "name": "Nat20_Force_Empty"
    },
    {
      "x": 1,
      "y": 8,
      "z": 0,
      "name": "Cloth_Roof_Leather_Flat"
    },
    {
      "x": 1,
      "y": 9,
      "z": 0,
      "name": "Nat20_Force_Empty"
    },
    {
      "x": 1,
      "y": 10,
      "z": 0,
      "name": "Nat20_Force_Empty"
    },
    {
      "x": 1,
      "y": 11,
      "z": 0,
      "name": "Nat20_Force_Empty"
    },
    {
      "x": 1,
      "y": 0,
      "z": 1,
      "name": "Soil_Pathway"
    },
    {
      "x": 1,
      "y": 1,
      "z": 1,
      "name": "Nat20_Force_Empty"
    },
    {
      "x": 1,
      "y": 2,
      "z": 1,
      "name": "Nat20_Force_Empty"
    },
    {
      "x": 1,
      "y": 3,
      "z": 1,
      "name": "Nat20_Force_Empty"
    },
    {
      "x": 1,
      "y": 4,
      "z": 1,
      "name": "Nat20_Force_Empty"
    },
    {
      "x": 1,
      "y": 5,
      "z": 1,
      "name": "Nat20_Force_Empty"
    },
    {
      "x": 1,
      "y": 6,
      "z": 1,
      "name": "Nat20_Force_Empty"
    },
    {
      "x": 1,
      "y": 7,
      "z": 1,
      "name": "Nat20_Force_Empty"
    },
    {
      "x": 1,
      "y": 8,
      "z": 1,
      "name": "Cloth_Roof_Leather_Flat"
    },
    {
      "x": 1,
      "y": 9,
      "z": 1,
      "name": "Nat20_Force_Empty"
    },
    {
      "x": 1,
      "y": 10,
      "z": 1,
      "name": "Nat20_Force_Empty"
    },
    {
      "x": 1,
      "y": 11,
      "z": 1,
      "name": "Nat20_Force_Empty"
    },
    {
      "x": 1,
      "y": 0,
      "z": 2,
      "name": "Soil_Pathway"
    },
    {
      "x": 1,
      "y": 1,
      "z": 2,
      "name": "Nat20_Force_Empty"
    },
    {
      "x": 1,
      "y": 2,
      "z": 2,
      "name": "Nat20_Force_Empty"
    },
    {
      "x": 1,
      "y": 3,
      "z": 2,
      "name": "Nat20_Force_Empty"
    },
    {
      "x": 1,
      "y": 4,
      "z": 2,
      "name": "Nat20_Force_Empty"
    },
    {
      "x": 1,
      "y": 5,
      "z": 2,
      "name": "Nat20_Force_Empty"
    },
    {
      "x": 1,
      "y": 6,
      "z": 2,
      "name": "Wood_Softwood_Planks"
    },
    {
      "x": 1,
      "y": 7,
      "z": 2,
      "name": "Cloth_Roof_Leather"
    },
    {
      "x": 1,
      "y": 8,
      "z": 2,
      "name": "Nat20_Force_Empty"
    },
    {
      "x": 1,
      "y": 9,
      "z": 2,
      "name": "Nat20_Force_Empty"
    },
    {
      "x": 1,
      "y": 10,
      "z": 2,
      "name": "Nat20_Force_Empty"
    },
    {
      "x": 1,
      "y": 11,
      "z": 2,
      "name": "Nat20_Force_Empty"
    },
    {
      "x": 1,
      "y": 0,
      "z": 3,
      "name": "Soil_Pathway"
    },
    {
      "x": 1,
      "y": 1,
      "z": 3,
      "name": "Nat20_Force_Empty"
    },
    {
      "x": 1,
      "y": 2,
      "z": 3,
      "name": "Nat20_Force_Empty"
    },
    {
      "x": 1,
      "y": 3,
      "z": 3,
      "name": "Rock_Stone_Cobble_Half",
      "rotation": 7
    },
    {
      "x": 1,
      "y": 4,
      "z": 3,
      "name": "Rock_Stone"
    },
    {
      "x": 1,
      "y": 5,
      "z": 3,
      "name": "Rock_Stone"
    },
    {
      "x": 1,
      "y": 6,
      "z": 3,
      "name": "Plant_Leaves_Bramble"
    },
    {
      "x": 1,
      "y": 7,
      "z": 3,
      "name": "Nat20_Force_Empty"
    },
    {
      "x": 1,
      "y": 8,
      "z": 3,
      "name": "Nat20_Force_Empty"
    },
    {
      "x": 1,
      "y": 9,
      "z": 3,
      "name": "Nat20_Force_Empty"
    },
    {
      "x": 1,
      "y": 10,
      "z": 3,
      "name": "Nat20_Force_Empty"
    },
    {
      "x": 1,
      "y": 11,
      "z": 3,
      "name": "Nat20_Force_Empty"
    },
    {
      "x": 1,
      "y": 0,
      "z": 4,
      "name": "Soil_Pathway"
    },
    {
      "x": 1,
      "y": 1,
      "z": 4,
      "name": "Nat20_Force_Empty"
    },
    {
      "x": 1,
      "y": 2,
      "z": 4,
      "name": "Nat20_Force_Empty"
    },
    {
      "x": 1,
      "y": 3,
      "z": 4,
      "name": "Nat20_Force_Empty"
    },
    {
      "x": 1,
      "y": 4,
      "z": 4,
      "name": "Wood_Oak_Trunk",
      "support": 15,
      "rotation": 5
    },
    {
      "x": 1,
      "y": 5,
      "z": 4,
      "name": "Rock_Stone"
    },
    {
      "x": 1,
      "y": 6,
      "z": 4,
      "name": "Nat20_Force_Empty"
    },
    {
      "x": 1,
      "y": 7,
      "z": 4,
      "name": "Nat20_Force_Empty"
    },
    {
      "x": 1,
      "y": 8,
      "z": 4,
      "name": "Nat20_Force_Empty"
    },
    {
      "x": 1,
      "y": 9,
      "z": 4,
      "name": "Nat20_Force_Empty"
    },
    {
      "x": 1,
      "y": 10,
      "z": 4,
      "name": "Nat20_Force_Empty"
    },
    {
      "x": 1,
      "y": 11,
      "z": 4,
      "name": "Nat20_Force_Empty"
    },
    {
      "x": 2,
      "y": 0,
      "z": -4,
      "name": "Soil_Clay_Brick"
    },
    {
      "x": 2,
      "y": 1,
      "z": -4,
      "name": "Soil_Clay_Brick"
    },
    {
      "x": 2,
      "y": 2,
      "z": -4,
      "name": "Soil_Clay_Brick"
    },
    {
      "x": 2,
      "y": 3,
      "z": -4,
      "name": "Rock_Stone_Cobble"
    },
    {
      "x": 2,
      "y": 4,
      "z": -4,
      "name": "Plant_Leaves_Bramble"
    },
    {
      "x": 2,
      "y": 5,
      "z": -4,
      "name": "Plant_Leaves_Bramble"
    },
    {
      "x": 2,
      "y": 6,
      "z": -4,
      "name": "Nat20_Force_Empty"
    },
    {
      "x": 2,
      "y": 7,
      "z": -4,
      "name": "Nat20_Force_Empty"
    },
    {
      "x": 2,
      "y": 8,
      "z": -4,
      "name": "Nat20_Force_Empty"
    },
    {
      "x": 2,
      "y": 9,
      "z": -4,
      "name": "Nat20_Force_Empty"
    },
    {
      "x": 2,
      "y": 10,
      "z": -4,
      "name": "Nat20_Force_Empty"
    },
    {
      "x": 2,
      "y": 11,
      "z": -4,
      "name": "Nat20_Force_Empty"
    },
    {
      "x": 2,
      "y": 0,
      "z": -3,
      "name": "Soil_Dirt"
    },
    {
      "x": 2,
      "y": 1,
      "z": -3,
      "name": "Nat20_Force_Empty"
    },
    {
      "x": 2,
      "y": 2,
      "z": -3,
      "name": "Nat20_Force_Empty"
    },
    {
      "x": 2,
      "y": 3,
      "z": -3,
      "name": "Nat20_Force_Empty"
    },
    {
      "x": 2,
      "y": 4,
      "z": -3,
      "name": "Wood_Beech_Trunk",
      "support": 15,
      "rotation": 5
    },
    {
      "x": 2,
      "y": 5,
      "z": -3,
      "name": "Cloth_Roof_Leather",
      "rotation": 2
    },
    {
      "x": 2,
      "y": 6,
      "z": -3,
      "name": "Nat20_Force_Empty"
    },
    {
      "x": 2,
      "y": 7,
      "z": -3,
      "name": "Nat20_Force_Empty"
    },
    {
      "x": 2,
      "y": 8,
      "z": -3,
      "name": "Nat20_Force_Empty"
    },
    {
      "x": 2,
      "y": 9,
      "z": -3,
      "name": "Nat20_Force_Empty"
    },
    {
      "x": 2,
      "y": 10,
      "z": -3,
      "name": "Nat20_Force_Empty"
    },
    {
      "x": 2,
      "y": 11,
      "z": -3,
      "name": "Nat20_Force_Empty"
    },
    {
      "x": 2,
      "y": 0,
      "z": -2,
      "name": "Soil_Dirt"
    },
    {
      "x": 2,
      "y": 1,
      "z": -2,
      "name": "Nat20_Force_Empty"
    },
    {
      "x": 2,
      "y": 2,
      "z": -2,
      "name": "Nat20_Force_Empty"
    },
    {
      "x": 2,
      "y": 3,
      "z": -2,
      "name": "Deco_Iron_Chain_Small"
    },
    {
      "x": 2,
      "y": 4,
      "z": -2,
      "name": "Wood_Beech_Trunk_Full",
      "support": 15
    },
    {
      "x": 2,
      "y": 5,
      "z": -2,
      "name": "Wood_Beech_Trunk",
      "support": 15
    },
    {
      "x": 2,
      "y": 6,
      "z": -2,
      "name": "Wood_Beech_Trunk",
      "support": 15
    },
    {
      "x": 2,
      "y": 7,
      "z": -2,
      "name": "Wood_Beech_Trunk_Full",
      "support": 15
    },
    {
      "x": 2,
      "y": 8,
      "z": -2,
      "name": "Wood_Beech_Branch_Long",
      "support": 15
    },
    {
      "x": 2,
      "y": 9,
      "z": -2,
      "name": "Wood_Beech_Branch_Long",
      "support": 15
    },
    {
      "x": 2,
      "y": 10,
      "z": -2,
      "name": "Wood_Softwood_Beam"
    },
    {
      "x": 2,
      "y": 11,
      "z": -2,
      "name": "Nat20_Force_Empty"
    },
    {
      "x": 2,
      "y": 0,
      "z": -1,
      "name": "Soil_Pathway"
    },
    {
      "x": 2,
      "y": 1,
      "z": -1,
      "name": "Nat20_Force_Empty"
    },
    {
      "x": 2,
      "y": 2,
      "z": -1,
      "name": "Nat20_Force_Empty"
    },
    {
      "x": 2,
      "y": 3,
      "z": -1,
      "name": "Nat20_Force_Empty"
    },
    {
      "x": 2,
      "y": 4,
      "z": -1,
      "name": "Deco_Rope",
      "rotation": 4
    },
    {
      "x": 2,
      "y": 5,
      "z": -1,
      "name": "Nat20_Force_Empty"
    },
    {
      "x": 2,
      "y": 6,
      "z": -1,
      "name": "Wood_Softwood_Planks"
    },
    {
      "x": 2,
      "y": 7,
      "z": -1,
      "name": "Cloth_Roof_Leather",
      "rotation": 1
    },
    {
      "x": 2,
      "y": 8,
      "z": -1,
      "name": "Nat20_Force_Empty"
    },
    {
      "x": 2,
      "y": 9,
      "z": -1,
      "name": "Nat20_Force_Empty"
    },
    {
      "x": 2,
      "y": 10,
      "z": -1,
      "name": "Nat20_Force_Empty"
    },
    {
      "x": 2,
      "y": 11,
      "z": -1,
      "name": "Nat20_Force_Empty"
    },
    {
      "x": 2,
      "y": 0,
      "z": 0,
      "name": "Soil_Pathway"
    },
    {
      "x": 2,
      "y": 1,
      "z": 0,
      "name": "Nat20_Force_Empty"
    },
    {
      "x": 2,
      "y": 2,
      "z": 0,
      "name": "Nat20_Force_Empty"
    },
    {
      "x": 2,
      "y": 3,
      "z": 0,
      "name": "Nat20_Force_Empty"
    },
    {
      "x": 2,
      "y": 4,
      "z": 0,
      "name": "Deco_Rope",
      "rotation": 4
    },
    {
      "x": 2,
      "y": 5,
      "z": 0,
      "name": "Nat20_Force_Empty"
    },
    {
      "x": 2,
      "y": 6,
      "z": 0,
      "name": "Wood_Softwood_Planks"
    },
    {
      "x": 2,
      "y": 7,
      "z": 0,
      "name": "Cloth_Roof_Leather",
      "rotation": 1
    },
    {
      "x": 2,
      "y": 8,
      "z": 0,
      "name": "Nat20_Force_Empty"
    },
    {
      "x": 2,
      "y": 9,
      "z": 0,
      "name": "Nat20_Force_Empty"
    },
    {
      "x": 2,
      "y": 10,
      "z": 0,
      "name": "Nat20_Force_Empty"
    },
    {
      "x": 2,
      "y": 11,
      "z": 0,
      "name": "Nat20_Force_Empty"
    },
    {
      "x": 2,
      "y": 0,
      "z": 1,
      "name": "Soil_Pathway"
    },
    {
      "x": 2,
      "y": 1,
      "z": 1,
      "name": "Nat20_Force_Empty"
    },
    {
      "x": 2,
      "y": 2,
      "z": 1,
      "name": "Nat20_Force_Empty"
    },
    {
      "x": 2,
      "y": 3,
      "z": 1,
      "name": "Nat20_Force_Empty"
    },
    {
      "x": 2,
      "y": 4,
      "z": 1,
      "name": "Deco_Rope",
      "rotation": 4
    },
    {
      "x": 2,
      "y": 5,
      "z": 1,
      "name": "Nat20_Force_Empty"
    },
    {
      "x": 2,
      "y": 6,
      "z": 1,
      "name": "Wood_Softwood_Planks"
    },
    {
      "x": 2,
      "y": 7,
      "z": 1,
      "name": "Cloth_Roof_Leather",
      "rotation": 1
    },
    {
      "x": 2,
      "y": 8,
      "z": 1,
      "name": "Nat20_Force_Empty"
    },
    {
      "x": 2,
      "y": 9,
      "z": 1,
      "name": "Nat20_Force_Empty"
    },
    {
      "x": 2,
      "y": 10,
      "z": 1,
      "name": "Nat20_Force_Empty"
    },
    {
      "x": 2,
      "y": 11,
      "z": 1,
      "name": "Nat20_Force_Empty"
    },
    {
      "x": 2,
      "y": 0,
      "z": 2,
      "name": "Soil_Dirt"
    },
    {
      "x": 2,
      "y": 1,
      "z": 2,
      "name": "Nat20_Force_Empty"
    },
    {
      "x": 2,
      "y": 2,
      "z": 2,
      "name": "Nat20_Force_Empty"
    },
    {
      "x": 2,
      "y": 3,
      "z": 2,
      "name": "Nat20_Force_Empty"
    },
    {
      "x": 2,
      "y": 4,
      "z": 2,
      "name": "Wood_Beech_Trunk_Full",
      "support": 15
    },
    {
      "x": 2,
      "y": 5,
      "z": 2,
      "name": "Wood_Beech_Trunk",
      "support": 15
    },
    {
      "x": 2,
      "y": 6,
      "z": 2,
      "name": "Wood_Beech_Trunk",
      "support": 15
    },
    {
      "x": 2,
      "y": 7,
      "z": 2,
      "name": "Wood_Beech_Trunk_Full",
      "support": 15
    },
    {
      "x": 2,
      "y": 8,
      "z": 2,
      "name": "Wood_Beech_Branch_Long",
      "support": 15
    },
    {
      "x": 2,
      "y": 9,
      "z": 2,
      "name": "Wood_Softwood_Beam"
    },
    {
      "x": 2,
      "y": 10,
      "z": 2,
      "name": "Nat20_Force_Empty"
    },
    {
      "x": 2,
      "y": 11,
      "z": 2,
      "name": "Nat20_Force_Empty"
    },
    {
      "x": 2,
      "y": 0,
      "z": 3,
      "name": "Rock_Stone_Cobble"
    },
    {
      "x": 2,
      "y": 1,
      "z": 3,
      "name": "Rock_Stone_Cobble"
    },
    {
      "x": 2,
      "y": 2,
      "z": 3,
      "name": "Rock_Stone_Cobble"
    },
    {
      "x": 2,
      "y": 3,
      "z": 3,
      "name": "Rock_Stone_Cobble"
    },
    {
      "x": 2,
      "y": 4,
      "z": 3,
      "name": "Rock_Stone"
    },
    {
      "x": 2,
      "y": 5,
      "z": 3,
      "name": "Rock_Stone"
    },
    {
      "x": 2,
      "y": 6,
      "z": 3,
      "name": "Nat20_Force_Empty"
    },
    {
      "x": 2,
      "y": 7,
      "z": 3,
      "name": "Nat20_Force_Empty"
    },
    {
      "x": 2,
      "y": 8,
      "z": 3,
      "name": "Nat20_Force_Empty"
    },
    {
      "x": 2,
      "y": 9,
      "z": 3,
      "name": "Nat20_Force_Empty"
    },
    {
      "x": 2,
      "y": 10,
      "z": 3,
      "name": "Nat20_Force_Empty"
    },
    {
      "x": 2,
      "y": 11,
      "z": 3,
      "name": "Nat20_Force_Empty"
    },
    {
      "x": 2,
      "y": 0,
      "z": 4,
      "name": "Soil_Pathway"
    },
    {
      "x": 2,
      "y": 1,
      "z": 4,
      "name": "Deco_Bone_Skulls"
    },
    {
      "x": 2,
      "y": 2,
      "z": 4,
      "name": "Nat20_Force_Empty"
    },
    {
      "x": 2,
      "y": 3,
      "z": 4,
      "name": "Nat20_Force_Empty"
    },
    {
      "x": 2,
      "y": 4,
      "z": 4,
      "name": "Wood_Oak_Trunk",
      "support": 15,
      "rotation": 5
    },
    {
      "x": 2,
      "y": 5,
      "z": 4,
      "name": "Rock_Stone"
    },
    {
      "x": 2,
      "y": 6,
      "z": 4,
      "name": "Nat20_Force_Empty"
    },
    {
      "x": 2,
      "y": 7,
      "z": 4,
      "name": "Nat20_Force_Empty"
    },
    {
      "x": 2,
      "y": 8,
      "z": 4,
      "name": "Nat20_Force_Empty"
    },
    {
      "x": 2,
      "y": 9,
      "z": 4,
      "name": "Nat20_Force_Empty"
    },
    {
      "x": 2,
      "y": 10,
      "z": 4,
      "name": "Nat20_Force_Empty"
    },
    {
      "x": 2,
      "y": 11,
      "z": 4,
      "name": "Nat20_Force_Empty"
    },
    {
      "x": 3,
      "y": 0,
      "z": -4,
      "name": "Soil_Clay_Brick"
    },
    {
      "x": 3,
      "y": 1,
      "z": -4,
      "name": "Soil_Clay_Brick"
    },
    {
      "x": 3,
      "y": 2,
      "z": -4,
      "name": "Soil_Clay_Brick"
    },
    {
      "x": 3,
      "y": 3,
      "z": -4,
      "name": "Rock_Stone_Cobble"
    },
    {
      "x": 3,
      "y": 4,
      "z": -4,
      "name": "Plant_Leaves_Bramble"
    },
    {
      "x": 3,
      "y": 5,
      "z": -4,
      "name": "Deco_Bone_Ribs",
      "rotation": 2
    },
    {
      "x": 3,
      "y": 6,
      "z": -4,
      "name": "Deco_Bone_Ribs_Long"
    },
    {
      "x": 3,
      "y": 7,
      "z": -4,
      "name": "Nat20_Force_Empty"
    },
    {
      "x": 3,
      "y": 8,
      "z": -4,
      "name": "Nat20_Force_Empty"
    },
    {
      "x": 3,
      "y": 9,
      "z": -4,
      "name": "Nat20_Force_Empty"
    },
    {
      "x": 3,
      "y": 10,
      "z": -4,
      "name": "Nat20_Force_Empty"
    },
    {
      "x": 3,
      "y": 11,
      "z": -4,
      "name": "Nat20_Force_Empty"
    },
    {
      "x": 3,
      "y": 0,
      "z": -3,
      "name": "Rock_Stone"
    },
    {
      "x": 3,
      "y": 1,
      "z": -3,
      "name": "Rock_Stone"
    },
    {
      "x": 3,
      "y": 2,
      "z": -3,
      "name": "Rock_Stone"
    },
    {
      "x": 3,
      "y": 3,
      "z": -3,
      "name": "Rock_Stone"
    },
    {
      "x": 3,
      "y": 4,
      "z": -3,
      "name": "Deco_Bone_Full"
    },
    {
      "x": 3,
      "y": 5,
      "z": -3,
      "name": "Deco_Bone_Full"
    },
    {
      "x": 3,
      "y": 6,
      "z": -3,
      "name": "Deco_Bone_Full"
    },
    {
      "x": 3,
      "y": 7,
      "z": -3,
      "name": "Deco_Bone_Ribs_Long"
    },
    {
      "x": 3,
      "y": 8,
      "z": -3,
      "name": "Deco_Bone_Ribs_Long"
    },
    {
      "x": 3,
      "y": 9,
      "z": -3,
      "name": "Nat20_Force_Empty"
    },
    {
      "x": 3,
      "y": 10,
      "z": -3,
      "name": "Nat20_Force_Empty"
    },
    {
      "x": 3,
      "y": 11,
      "z": -3,
      "name": "Nat20_Force_Empty"
    },
    {
      "x": 3,
      "y": 0,
      "z": -2,
      "name": "Rock_Stone"
    },
    {
      "x": 3,
      "y": 1,
      "z": -2,
      "name": "Rock_Stone"
    },
    {
      "x": 3,
      "y": 2,
      "z": -2,
      "name": "Rock_Stone"
    },
    {
      "x": 3,
      "y": 3,
      "z": -2,
      "name": "Nat20_Force_Empty"
    },
    {
      "x": 3,
      "y": 4,
      "z": -2,
      "name": "Wood_Beech_Trunk",
      "support": 15,
      "rotation": 4
    },
    {
      "x": 3,
      "y": 5,
      "z": -2,
      "name": "Plant_Leaves_Bramble"
    },
    {
      "x": 3,
      "y": 6,
      "z": -2,
      "name": "Plant_Leaves_Bramble"
    },
    {
      "x": 3,
      "y": 7,
      "z": -2,
      "name": "Nat20_Force_Empty"
    },
    {
      "x": 3,
      "y": 8,
      "z": -2,
      "name": "Nat20_Force_Empty"
    },
    {
      "x": 3,
      "y": 9,
      "z": -2,
      "name": "Nat20_Force_Empty"
    },
    {
      "x": 3,
      "y": 10,
      "z": -2,
      "name": "Nat20_Force_Empty"
    },
    {
      "x": 3,
      "y": 11,
      "z": -2,
      "name": "Nat20_Force_Empty"
    },
    {
      "x": 3,
      "y": 0,
      "z": -1,
      "name": "Soil_Pathway"
    },
    {
      "x": 3,
      "y": 1,
      "z": -1,
      "name": "Nat20_Force_Empty"
    },
    {
      "x": 3,
      "y": 2,
      "z": -1,
      "name": "Nat20_Force_Empty"
    },
    {
      "x": 3,
      "y": 3,
      "z": -1,
      "name": "Nat20_Force_Empty"
    },
    {
      "x": 3,
      "y": 4,
      "z": -1,
      "name": "Wood_Beech_Trunk",
      "support": 15,
      "rotation": 4
    },
    {
      "x": 3,
      "y": 5,
      "z": -1,
      "name": "Plant_Leaves_Bramble"
    },
    {
      "x": 3,
      "y": 6,
      "z": -1,
      "name": "Plant_Leaves_Bramble"
    },
    {
      "x": 3,
      "y": 7,
      "z": -1,
      "name": "Nat20_Force_Empty"
    },
    {
      "x": 3,
      "y": 8,
      "z": -1,
      "name": "Nat20_Force_Empty"
    },
    {
      "x": 3,
      "y": 9,
      "z": -1,
      "name": "Nat20_Force_Empty"
    },
    {
      "x": 3,
      "y": 10,
      "z": -1,
      "name": "Nat20_Force_Empty"
    },
    {
      "x": 3,
      "y": 11,
      "z": -1,
      "name": "Nat20_Force_Empty"
    },
    {
      "x": 3,
      "y": 0,
      "z": 0,
      "name": "Soil_Pathway"
    },
    {
      "x": 3,
      "y": 1,
      "z": 0,
      "name": "Nat20_Force_Empty"
    },
    {
      "x": 3,
      "y": 2,
      "z": 0,
      "name": "Nat20_Force_Empty"
    },
    {
      "x": 3,
      "y": 3,
      "z": 0,
      "name": "Nat20_Force_Empty"
    },
    {
      "x": 3,
      "y": 4,
      "z": 0,
      "name": "Wood_Beech_Trunk",
      "support": 15,
      "rotation": 4
    },
    {
      "x": 3,
      "y": 5,
      "z": 0,
      "name": "Cloth_Roof_Leather",
      "rotation": 1
    },
    {
      "x": 3,
      "y": 6,
      "z": 0,
      "name": "Nat20_Force_Empty"
    },
    {
      "x": 3,
      "y": 7,
      "z": 0,
      "name": "Nat20_Force_Empty"
    },
    {
      "x": 3,
      "y": 8,
      "z": 0,
      "name": "Nat20_Force_Empty"
    },
    {
      "x": 3,
      "y": 9,
      "z": 0,
      "name": "Nat20_Force_Empty"
    },
    {
      "x": 3,
      "y": 10,
      "z": 0,
      "name": "Nat20_Force_Empty"
    },
    {
      "x": 3,
      "y": 11,
      "z": 0,
      "name": "Nat20_Force_Empty"
    },
    {
      "x": 3,
      "y": 0,
      "z": 1,
      "name": "Soil_Dirt"
    },
    {
      "x": 3,
      "y": 1,
      "z": 1,
      "name": "Nat20_Force_Empty"
    },
    {
      "x": 3,
      "y": 2,
      "z": 1,
      "name": "Nat20_Force_Empty"
    },
    {
      "x": 3,
      "y": 3,
      "z": 1,
      "name": "Nat20_Force_Empty"
    },
    {
      "x": 3,
      "y": 4,
      "z": 1,
      "name": "Wood_Beech_Trunk",
      "support": 15,
      "rotation": 4
    },
    {
      "x": 3,
      "y": 5,
      "z": 1,
      "name": "Cloth_Roof_Leather",
      "rotation": 1
    },
    {
      "x": 3,
      "y": 6,
      "z": 1,
      "name": "Nat20_Force_Empty"
    },
    {
      "x": 3,
      "y": 7,
      "z": 1,
      "name": "Nat20_Force_Empty"
    },
    {
      "x": 3,
      "y": 8,
      "z": 1,
      "name": "Nat20_Force_Empty"
    },
    {
      "x": 3,
      "y": 9,
      "z": 1,
      "name": "Nat20_Force_Empty"
    },
    {
      "x": 3,
      "y": 10,
      "z": 1,
      "name": "Nat20_Force_Empty"
    },
    {
      "x": 3,
      "y": 11,
      "z": 1,
      "name": "Nat20_Force_Empty"
    },
    {
      "x": 3,
      "y": 0,
      "z": 2,
      "name": "Soil_Dirt"
    },
    {
      "x": 3,
      "y": 1,
      "z": 2,
      "name": "Nat20_Force_Empty"
    },
    {
      "x": 3,
      "y": 2,
      "z": 2,
      "name": "Nat20_Force_Empty"
    },
    {
      "x": 3,
      "y": 3,
      "z": 2,
      "name": "Nat20_Force_Empty"
    },
    {
      "x": 3,
      "y": 4,
      "z": 2,
      "name": "Wood_Beech_Trunk",
      "support": 15,
      "rotation": 4
    },
    {
      "x": 3,
      "y": 5,
      "z": 2,
      "name": "Cloth_Roof_Leather",
      "rotation": 1
    },
    {
      "x": 3,
      "y": 6,
      "z": 2,
      "name": "Nat20_Force_Empty"
    },
    {
      "x": 3,
      "y": 7,
      "z": 2,
      "name": "Nat20_Force_Empty"
    },
    {
      "x": 3,
      "y": 8,
      "z": 2,
      "name": "Nat20_Force_Empty"
    },
    {
      "x": 3,
      "y": 9,
      "z": 2,
      "name": "Nat20_Force_Empty"
    },
    {
      "x": 3,
      "y": 10,
      "z": 2,
      "name": "Nat20_Force_Empty"
    },
    {
      "x": 3,
      "y": 11,
      "z": 2,
      "name": "Nat20_Force_Empty"
    },
    {
      "x": 3,
      "y": 0,
      "z": 3,
      "name": "Rock_Stone_Cobble"
    },
    {
      "x": 3,
      "y": 1,
      "z": 3,
      "name": "Rock_Stone_Cobble"
    },
    {
      "x": 3,
      "y": 2,
      "z": 3,
      "name": "Rock_Stone"
    },
    {
      "x": 3,
      "y": 3,
      "z": 3,
      "name": "Rock_Stone"
    },
    {
      "x": 3,
      "y": 4,
      "z": 3,
      "name": "Rock_Stone"
    },
    {
      "x": 3,
      "y": 5,
      "z": 3,
      "name": "Deco_Bone_Full"
    },
    {
      "x": 3,
      "y": 6,
      "z": 3,
      "name": "Deco_Bone_Full"
    },
    {
      "x": 3,
      "y": 7,
      "z": 3,
      "name": "Deco_Bone_Ribs_Long"
    },
    {
      "x": 3,
      "y": 8,
      "z": 3,
      "name": "Nat20_Force_Empty"
    },
    {
      "x": 3,
      "y": 9,
      "z": 3,
      "name": "Nat20_Force_Empty"
    },
    {
      "x": 3,
      "y": 10,
      "z": 3,
      "name": "Nat20_Force_Empty"
    },
    {
      "x": 3,
      "y": 11,
      "z": 3,
      "name": "Nat20_Force_Empty"
    },
    {
      "x": 3,
      "y": 0,
      "z": 4,
      "name": "Rock_Stone_Cobble"
    },
    {
      "x": 3,
      "y": 1,
      "z": 4,
      "name": "Rock_Stone_Cobble"
    },
    {
      "x": 3,
      "y": 2,
      "z": 4,
      "name": "Wood_Softwood_Planks_Half",
      "rotation": 4
    },
    {
      "x": 3,
      "y": 3,
      "z": 4,
      "name": "Wood_Softwood_Stairs",
      "rotation": 10
    },
    {
      "x": 3,
      "y": 4,
      "z": 4,
      "name": "Wood_Oak_Trunk",
      "support": 15,
      "rotation": 5
    },
    {
      "x": 3,
      "y": 5,
      "z": 4,
      "name": "Rubble_Stone_Medium"
    },
    {
      "x": 3,
      "y": 6,
      "z": 4,
      "name": "Nat20_Force_Empty"
    },
    {
      "x": 3,
      "y": 7,
      "z": 4,
      "name": "Nat20_Force_Empty"
    },
    {
      "x": 3,
      "y": 8,
      "z": 4,
      "name": "Nat20_Force_Empty"
    },
    {
      "x": 3,
      "y": 9,
      "z": 4,
      "name": "Nat20_Force_Empty"
    },
    {
      "x": 3,
      "y": 10,
      "z": 4,
      "name": "Nat20_Force_Empty"
    },
    {
      "x": 3,
      "y": 11,
      "z": 4,
      "name": "Nat20_Force_Empty"
    },
    {
      "x": 4,
      "y": 0,
      "z": -4,
      "name": "Rock_Stone_Cobble"
    },
    {
      "x": 4,
      "y": 1,
      "z": -4,
      "name": "Rock_Stone_Cobble"
    },
    {
      "x": 4,
      "y": 2,
      "z": -4,
      "name": "Rock_Stone_Cobble"
    },
    {
      "x": 4,
      "y": 3,
      "z": -4,
      "name": "Deco_Bone_Full"
    },
    {
      "x": 4,
      "y": 4,
      "z": -4,
      "name": "Deco_Bone_Full"
    },
    {
      "x": 4,
      "y": 5,
      "z": -4,
      "name": "Nat20_Force_Empty"
    },
    {
      "x": 4,
      "y": 6,
      "z": -4,
      "name": "Nat20_Force_Empty"
    },
    {
      "x": 4,
      "y": 7,
      "z": -4,
      "name": "Nat20_Force_Empty"
    },
    {
      "x": 4,
      "y": 8,
      "z": -4,
      "name": "Nat20_Force_Empty"
    },
    {
      "x": 4,
      "y": 9,
      "z": -4,
      "name": "Nat20_Force_Empty"
    },
    {
      "x": 4,
      "y": 10,
      "z": -4,
      "name": "Nat20_Force_Empty"
    },
    {
      "x": 4,
      "y": 11,
      "z": -4,
      "name": "Nat20_Force_Empty"
    },
    {
      "x": 4,
      "y": 0,
      "z": -3,
      "name": "Rock_Stone"
    },
    {
      "x": 4,
      "y": 1,
      "z": -3,
      "name": "Rock_Stone"
    },
    {
      "x": 4,
      "y": 2,
      "z": -3,
      "name": "Rock_Stone"
    },
    {
      "x": 4,
      "y": 3,
      "z": -3,
      "name": "Rock_Stone"
    },
    {
      "x": 4,
      "y": 4,
      "z": -3,
      "name": "Plant_Leaves_Bramble"
    },
    {
      "x": 4,
      "y": 5,
      "z": -3,
      "name": "Nat20_Force_Empty"
    },
    {
      "x": 4,
      "y": 6,
      "z": -3,
      "name": "Nat20_Force_Empty"
    },
    {
      "x": 4,
      "y": 7,
      "z": -3,
      "name": "Nat20_Force_Empty"
    },
    {
      "x": 4,
      "y": 8,
      "z": -3,
      "name": "Nat20_Force_Empty"
    },
    {
      "x": 4,
      "y": 9,
      "z": -3,
      "name": "Nat20_Force_Empty"
    },
    {
      "x": 4,
      "y": 10,
      "z": -3,
      "name": "Nat20_Force_Empty"
    },
    {
      "x": 4,
      "y": 11,
      "z": -3,
      "name": "Nat20_Force_Empty"
    },
    {
      "x": 4,
      "y": 0,
      "z": -2,
      "name": "Rock_Stone"
    },
    {
      "x": 4,
      "y": 1,
      "z": -2,
      "name": "Rock_Stone"
    },
    {
      "x": 4,
      "y": 2,
      "z": -2,
      "name": "Rock_Stone"
    },
    {
      "x": 4,
      "y": 3,
      "z": -2,
      "name": "Rock_Stone"
    },
    {
      "x": 4,
      "y": 4,
      "z": -2,
      "name": "Plant_Leaves_Bramble"
    },
    {
      "x": 4,
      "y": 5,
      "z": -2,
      "name": "Plant_Leaves_Bramble"
    },
    {
      "x": 4,
      "y": 6,
      "z": -2,
      "name": "Nat20_Force_Empty"
    },
    {
      "x": 4,
      "y": 7,
      "z": -2,
      "name": "Nat20_Force_Empty"
    },
    {
      "x": 4,
      "y": 8,
      "z": -2,
      "name": "Nat20_Force_Empty"
    },
    {
      "x": 4,
      "y": 9,
      "z": -2,
      "name": "Nat20_Force_Empty"
    },
    {
      "x": 4,
      "y": 10,
      "z": -2,
      "name": "Nat20_Force_Empty"
    },
    {
      "x": 4,
      "y": 11,
      "z": -2,
      "name": "Nat20_Force_Empty"
    },
    {
      "x": 4,
      "y": 0,
      "z": -1,
      "name": "Rock_Stone_Cobble"
    },
    {
      "x": 4,
      "y": 1,
      "z": -1,
      "name": "Rock_Stone_Cobble"
    },
    {
      "x": 4,
      "y": 2,
      "z": -1,
      "name": "Nat20_Force_Empty"
    },
    {
      "x": 4,
      "y": 3,
      "z": -1,
      "name": "Rock_Stone_Cobble"
    },
    {
      "x": 4,
      "y": 4,
      "z": -1,
      "name": "Rock_Stone_Cobble_Half"
    },
    {
      "x": 4,
      "y": 5,
      "z": -1,
      "name": "Nat20_Force_Empty"
    },
    {
      "x": 4,
      "y": 6,
      "z": -1,
      "name": "Nat20_Force_Empty"
    },
    {
      "x": 4,
      "y": 7,
      "z": -1,
      "name": "Nat20_Force_Empty"
    },
    {
      "x": 4,
      "y": 8,
      "z": -1,
      "name": "Nat20_Force_Empty"
    },
    {
      "x": 4,
      "y": 9,
      "z": -1,
      "name": "Nat20_Force_Empty"
    },
    {
      "x": 4,
      "y": 10,
      "z": -1,
      "name": "Nat20_Force_Empty"
    },
    {
      "x": 4,
      "y": 11,
      "z": -1,
      "name": "Nat20_Force_Empty"
    },
    {
      "x": 4,
      "y": 0,
      "z": 0,
      "name": "Rock_Stone_Cobble"
    },
    {
      "x": 4,
      "y": 1,
      "z": 0,
      "name": "Rock_Stone_Cobble"
    },
    {
      "x": 4,
      "y": 2,
      "z": 0,
      "name": "Nat20_Force_Empty"
    },
    {
      "x": 4,
      "y": 3,
      "z": 0,
      "name": "Rock_Stone_Cobble"
    },
    {
      "x": 4,
      "y": 4,
      "z": 0,
      "name": "Rock_Stone_Cobble_Half"
    },
    {
      "x": 4,
      "y": 5,
      "z": 0,
      "name": "Nat20_Force_Empty"
    },
    {
      "x": 4,
      "y": 6,
      "z": 0,
      "name": "Nat20_Force_Empty"
    },
    {
      "x": 4,
      "y": 7,
      "z": 0,
      "name": "Nat20_Force_Empty"
    },
    {
      "x": 4,
      "y": 8,
      "z": 0,
      "name": "Nat20_Force_Empty"
    },
    {
      "x": 4,
      "y": 9,
      "z": 0,
      "name": "Nat20_Force_Empty"
    },
    {
      "x": 4,
      "y": 10,
      "z": 0,
      "name": "Nat20_Force_Empty"
    },
    {
      "x": 4,
      "y": 11,
      "z": 0,
      "name": "Nat20_Force_Empty"
    },
    {
      "x": 4,
      "y": 0,
      "z": 1,
      "name": "Rock_Stone_Cobble"
    },
    {
      "x": 4,
      "y": 1,
      "z": 1,
      "name": "Rock_Stone_Cobble_Half",
      "rotation": 5
    },
    {
      "x": 4,
      "y": 2,
      "z": 1,
      "name": "Rock_Stone_Cobble_Half",
      "rotation": 5
    },
    {
      "x": 4,
      "y": 3,
      "z": 1,
      "name": "Rock_Stone_Cobble"
    },
    {
      "x": 4,
      "y": 4,
      "z": 1,
      "name": "Rock_Stone_Cobble_Half"
    },
    {
      "x": 4,
      "y": 5,
      "z": 1,
      "name": "Nat20_Force_Empty"
    },
    {
      "x": 4,
      "y": 6,
      "z": 1,
      "name": "Nat20_Force_Empty"
    },
    {
      "x": 4,
      "y": 7,
      "z": 1,
      "name": "Nat20_Force_Empty"
    },
    {
      "x": 4,
      "y": 8,
      "z": 1,
      "name": "Nat20_Force_Empty"
    },
    {
      "x": 4,
      "y": 9,
      "z": 1,
      "name": "Nat20_Force_Empty"
    },
    {
      "x": 4,
      "y": 10,
      "z": 1,
      "name": "Nat20_Force_Empty"
    },
    {
      "x": 4,
      "y": 11,
      "z": 1,
      "name": "Nat20_Force_Empty"
    },
    {
      "x": 4,
      "y": 0,
      "z": 2,
      "name": "Rock_Stone_Cobble"
    },
    {
      "x": 4,
      "y": 1,
      "z": 2,
      "name": "Rock_Stone_Cobble"
    },
    {
      "x": 4,
      "y": 2,
      "z": 2,
      "name": "Rock_Stone_Cobble"
    },
    {
      "x": 4,
      "y": 3,
      "z": 2,
      "name": "Rock_Stone_Cobble"
    },
    {
      "x": 4,
      "y": 4,
      "z": 2,
      "name": "Nat20_Force_Empty"
    },
    {
      "x": 4,
      "y": 5,
      "z": 2,
      "name": "Nat20_Force_Empty"
    },
    {
      "x": 4,
      "y": 6,
      "z": 2,
      "name": "Nat20_Force_Empty"
    },
    {
      "x": 4,
      "y": 7,
      "z": 2,
      "name": "Nat20_Force_Empty"
    },
    {
      "x": 4,
      "y": 8,
      "z": 2,
      "name": "Nat20_Force_Empty"
    },
    {
      "x": 4,
      "y": 9,
      "z": 2,
      "name": "Nat20_Force_Empty"
    },
    {
      "x": 4,
      "y": 10,
      "z": 2,
      "name": "Nat20_Force_Empty"
    },
    {
      "x": 4,
      "y": 11,
      "z": 2,
      "name": "Nat20_Force_Empty"
    },
    {
      "x": 4,
      "y": 0,
      "z": 3,
      "name": "Rock_Stone_Cobble"
    },
    {
      "x": 4,
      "y": 1,
      "z": 3,
      "name": "Rock_Stone_Cobble"
    },
    {
      "x": 4,
      "y": 2,
      "z": 3,
      "name": "Rock_Stone_Cobble"
    },
    {
      "x": 4,
      "y": 3,
      "z": 3,
      "name": "Rock_Stone"
    },
    {
      "x": 4,
      "y": 4,
      "z": 3,
      "name": "Rock_Stone"
    },
    {
      "x": 4,
      "y": 5,
      "z": 3,
      "name": "Nat20_Force_Empty"
    },
    {
      "x": 4,
      "y": 6,
      "z": 3,
      "name": "Nat20_Force_Empty"
    },
    {
      "x": 4,
      "y": 7,
      "z": 3,
      "name": "Nat20_Force_Empty"
    },
    {
      "x": 4,
      "y": 8,
      "z": 3,
      "name": "Nat20_Force_Empty"
    },
    {
      "x": 4,
      "y": 9,
      "z": 3,
      "name": "Nat20_Force_Empty"
    },
    {
      "x": 4,
      "y": 10,
      "z": 3,
      "name": "Nat20_Force_Empty"
    },
    {
      "x": 4,
      "y": 11,
      "z": 3,
      "name": "Nat20_Force_Empty"
    },
    {
      "x": 4,
      "y": 0,
      "z": 4,
      "name": "Rock_Stone_Cobble"
    },
    {
      "x": 4,
      "y": 1,
      "z": 4,
      "name": "Rock_Stone_Cobble"
    },
    {
      "x": 4,
      "y": 2,
      "z": 4,
      "name": "Rock_Stone_Cobble"
    },
    {
      "x": 4,
      "y": 3,
      "z": 4,
      "name": "Nat20_Force_Empty"
    },
    {
      "x": 4,
      "y": 4,
      "z": 4,
      "name": "Wood_Oak_Trunk",
      "support": 15,
      "rotation": 5
    },
    {
      "x": 4,
      "y": 5,
      "z": 4,
      "name": "Nat20_Force_Empty"
    },
    {
      "x": 4,
      "y": 6,
      "z": 4,
      "name": "Nat20_Force_Empty"
    },
    {
      "x": 4,
      "y": 7,
      "z": 4,
      "name": "Nat20_Force_Empty"
    },
    {
      "x": 4,
      "y": 8,
      "z": 4,
      "name": "Nat20_Force_Empty"
    },
    {
      "x": 4,
      "y": 9,
      "z": 4,
      "name": "Nat20_Force_Empty"
    },
    {
      "x": 4,
      "y": 10,
      "z": 4,
      "name": "Nat20_Force_Empty"
    },
    {
      "x": 4,
      "y": 11,
      "z": 4,
      "name": "Nat20_Force_Empty"
    }
  ],
  "fluids": [
    {
      "x": -4,
      "y": 0,
      "z": -4,
      "name": "Empty",
      "level": 0
    },
    {
      "x": -4,
      "y": 1,
      "z": -4,
      "name": "Empty",
      "level": 0
    },
    {
      "x": -4,
      "y": 2,
      "z": -4,
      "name": "Empty",
      "level": 0
    },
    {
      "x": -4,
      "y": 3,
      "z": -4,
      "name": "Empty",
      "level": 0
    },
    {
      "x": -4,
      "y": 4,
      "z": -4,
      "name": "Empty",
      "level": 0
    },
    {
      "x": -4,
      "y": 5,
      "z": -4,
      "name": "Empty",
      "level": 0
    },
    {
      "x": -4,
      "y": 6,
      "z": -4,
      "name": "Empty",
      "level": 0
    },
    {
      "x": -4,
      "y": 7,
      "z": -4,
      "name": "Empty",
      "level": 0
    },
    {
      "x": -4,
      "y": 8,
      "z": -4,
      "name": "Empty",
      "level": 0
    },
    {
      "x": -4,
      "y": 9,
      "z": -4,
      "name": "Empty",
      "level": 0
    },
    {
      "x": -4,
      "y": 10,
      "z": -4,
      "name": "Empty",
      "level": 0
    },
    {
      "x": -4,
      "y": 11,
      "z": -4,
      "name": "Empty",
      "level": 0
    },
    {
      "x": -4,
      "y": 0,
      "z": -3,
      "name": "Empty",
      "level": 0
    },
    {
      "x": -4,
      "y": 1,
      "z": -3,
      "name": "Empty",
      "level": 0
    },
    {
      "x": -4,
      "y": 2,
      "z": -3,
      "name": "Empty",
      "level": 0
    },
    {
      "x": -4,
      "y": 3,
      "z": -3,
      "name": "Empty",
      "level": 0
    },
    {
      "x": -4,
      "y": 4,
      "z": -3,
      "name": "Empty",
      "level": 0
    },
    {
      "x": -4,
      "y": 5,
      "z": -3,
      "name": "Empty",
      "level": 0
    },
    {
      "x": -4,
      "y": 6,
      "z": -3,
      "name": "Empty",
      "level": 0
    },
    {
      "x": -4,
      "y": 7,
      "z": -3,
      "name": "Empty",
      "level": 0
    },
    {
      "x": -4,
      "y": 8,
      "z": -3,
      "name": "Empty",
      "level": 0
    },
    {
      "x": -4,
      "y": 9,
      "z": -3,
      "name": "Empty",
      "level": 0
    },
    {
      "x": -4,
      "y": 10,
      "z": -3,
      "name": "Empty",
      "level": 0
    },
    {
      "x": -4,
      "y": 11,
      "z": -3,
      "name": "Empty",
      "level": 0
    },
    {
      "x": -4,
      "y": 0,
      "z": -2,
      "name": "Empty",
      "level": 0
    },
    {
      "x": -4,
      "y": 1,
      "z": -2,
      "name": "Empty",
      "level": 0
    },
    {
      "x": -4,
      "y": 2,
      "z": -2,
      "name": "Empty",
      "level": 0
    },
    {
      "x": -4,
      "y": 3,
      "z": -2,
      "name": "Empty",
      "level": 0
    },
    {
      "x": -4,
      "y": 4,
      "z": -2,
      "name": "Empty",
      "level": 0
    },
    {
      "x": -4,
      "y": 5,
      "z": -2,
      "name": "Empty",
      "level": 0
    },
    {
      "x": -4,
      "y": 6,
      "z": -2,
      "name": "Empty",
      "level": 0
    },
    {
      "x": -4,
      "y": 7,
      "z": -2,
      "name": "Empty",
      "level": 0
    },
    {
      "x": -4,
      "y": 8,
      "z": -2,
      "name": "Empty",
      "level": 0
    },
    {
      "x": -4,
      "y": 9,
      "z": -2,
      "name": "Empty",
      "level": 0
    },
    {
      "x": -4,
      "y": 10,
      "z": -2,
      "name": "Empty",
      "level": 0
    },
    {
      "x": -4,
      "y": 11,
      "z": -2,
      "name": "Empty",
      "level": 0
    },
    {
      "x": -4,
      "y": 0,
      "z": -1,
      "name": "Empty",
      "level": 0
    },
    {
      "x": -4,
      "y": 1,
      "z": -1,
      "name": "Empty",
      "level": 0
    },
    {
      "x": -4,
      "y": 2,
      "z": -1,
      "name": "Empty",
      "level": 0
    },
    {
      "x": -4,
      "y": 3,
      "z": -1,
      "name": "Empty",
      "level": 0
    },
    {
      "x": -4,
      "y": 4,
      "z": -1,
      "name": "Empty",
      "level": 0
    },
    {
      "x": -4,
      "y": 5,
      "z": -1,
      "name": "Empty",
      "level": 0
    },
    {
      "x": -4,
      "y": 6,
      "z": -1,
      "name": "Empty",
      "level": 0
    },
    {
      "x": -4,
      "y": 7,
      "z": -1,
      "name": "Empty",
      "level": 0
    },
    {
      "x": -4,
      "y": 8,
      "z": -1,
      "name": "Empty",
      "level": 0
    },
    {
      "x": -4,
      "y": 9,
      "z": -1,
      "name": "Empty",
      "level": 0
    },
    {
      "x": -4,
      "y": 10,
      "z": -1,
      "name": "Empty",
      "level": 0
    },
    {
      "x": -4,
      "y": 11,
      "z": -1,
      "name": "Empty",
      "level": 0
    },
    {
      "x": -4,
      "y": 0,
      "z": 0,
      "name": "Empty",
      "level": 0
    },
    {
      "x": -4,
      "y": 1,
      "z": 0,
      "name": "Empty",
      "level": 0
    },
    {
      "x": -4,
      "y": 2,
      "z": 0,
      "name": "Empty",
      "level": 0
    },
    {
      "x": -4,
      "y": 3,
      "z": 0,
      "name": "Empty",
      "level": 0
    },
    {
      "x": -4,
      "y": 4,
      "z": 0,
      "name": "Empty",
      "level": 0
    },
    {
      "x": -4,
      "y": 5,
      "z": 0,
      "name": "Empty",
      "level": 0
    },
    {
      "x": -4,
      "y": 6,
      "z": 0,
      "name": "Empty",
      "level": 0
    },
    {
      "x": -4,
      "y": 7,
      "z": 0,
      "name": "Empty",
      "level": 0
    },
    {
      "x": -4,
      "y": 8,
      "z": 0,
      "name": "Empty",
      "level": 0
    },
    {
      "x": -4,
      "y": 9,
      "z": 0,
      "name": "Empty",
      "level": 0
    },
    {
      "x": -4,
      "y": 10,
      "z": 0,
      "name": "Empty",
      "level": 0
    },
    {
      "x": -4,
      "y": 11,
      "z": 0,
      "name": "Empty",
      "level": 0
    },
    {
      "x": -4,
      "y": 0,
      "z": 1,
      "name": "Empty",
      "level": 0
    },
    {
      "x": -4,
      "y": 1,
      "z": 1,
      "name": "Empty",
      "level": 0
    },
    {
      "x": -4,
      "y": 2,
      "z": 1,
      "name": "Empty",
      "level": 0
    },
    {
      "x": -4,
      "y": 3,
      "z": 1,
      "name": "Empty",
      "level": 0
    },
    {
      "x": -4,
      "y": 4,
      "z": 1,
      "name": "Empty",
      "level": 0
    },
    {
      "x": -4,
      "y": 5,
      "z": 1,
      "name": "Empty",
      "level": 0
    },
    {
      "x": -4,
      "y": 6,
      "z": 1,
      "name": "Empty",
      "level": 0
    },
    {
      "x": -4,
      "y": 7,
      "z": 1,
      "name": "Empty",
      "level": 0
    },
    {
      "x": -4,
      "y": 8,
      "z": 1,
      "name": "Empty",
      "level": 0
    },
    {
      "x": -4,
      "y": 9,
      "z": 1,
      "name": "Empty",
      "level": 0
    },
    {
      "x": -4,
      "y": 10,
      "z": 1,
      "name": "Empty",
      "level": 0
    },
    {
      "x": -4,
      "y": 11,
      "z": 1,
      "name": "Empty",
      "level": 0
    },
    {
      "x": -4,
      "y": 0,
      "z": 2,
      "name": "Empty",
      "level": 0
    },
    {
      "x": -4,
      "y": 1,
      "z": 2,
      "name": "Empty",
      "level": 0
    },
    {
      "x": -4,
      "y": 2,
      "z": 2,
      "name": "Empty",
      "level": 0
    },
    {
      "x": -4,
      "y": 3,
      "z": 2,
      "name": "Empty",
      "level": 0
    },
    {
      "x": -4,
      "y": 4,
      "z": 2,
      "name": "Empty",
      "level": 0
    },
    {
      "x": -4,
      "y": 5,
      "z": 2,
      "name": "Empty",
      "level": 0
    },
    {
      "x": -4,
      "y": 6,
      "z": 2,
      "name": "Empty",
      "level": 0
    },
    {
      "x": -4,
      "y": 7,
      "z": 2,
      "name": "Empty",
      "level": 0
    },
    {
      "x": -4,
      "y": 8,
      "z": 2,
      "name": "Empty",
      "level": 0
    },
    {
      "x": -4,
      "y": 9,
      "z": 2,
      "name": "Empty",
      "level": 0
    },
    {
      "x": -4,
      "y": 10,
      "z": 2,
      "name": "Empty",
      "level": 0
    },
    {
      "x": -4,
      "y": 11,
      "z": 2,
      "name": "Empty",
      "level": 0
    },
    {
      "x": -4,
      "y": 0,
      "z": 3,
      "name": "Empty",
      "level": 0
    },
    {
      "x": -4,
      "y": 1,
      "z": 3,
      "name": "Empty",
      "level": 0
    },
    {
      "x": -4,
      "y": 2,
      "z": 3,
      "name": "Empty",
      "level": 0
    },
    {
      "x": -4,
      "y": 3,
      "z": 3,
      "name": "Empty",
      "level": 0
    },
    {
      "x": -4,
      "y": 4,
      "z": 3,
      "name": "Empty",
      "level": 0
    },
    {
      "x": -4,
      "y": 5,
      "z": 3,
      "name": "Empty",
      "level": 0
    },
    {
      "x": -4,
      "y": 6,
      "z": 3,
      "name": "Empty",
      "level": 0
    },
    {
      "x": -4,
      "y": 7,
      "z": 3,
      "name": "Empty",
      "level": 0
    },
    {
      "x": -4,
      "y": 8,
      "z": 3,
      "name": "Empty",
      "level": 0
    },
    {
      "x": -4,
      "y": 9,
      "z": 3,
      "name": "Empty",
      "level": 0
    },
    {
      "x": -4,
      "y": 10,
      "z": 3,
      "name": "Empty",
      "level": 0
    },
    {
      "x": -4,
      "y": 11,
      "z": 3,
      "name": "Empty",
      "level": 0
    },
    {
      "x": -4,
      "y": 0,
      "z": 4,
      "name": "Empty",
      "level": 0
    },
    {
      "x": -4,
      "y": 1,
      "z": 4,
      "name": "Empty",
      "level": 0
    },
    {
      "x": -4,
      "y": 2,
      "z": 4,
      "name": "Empty",
      "level": 0
    },
    {
      "x": -4,
      "y": 3,
      "z": 4,
      "name": "Empty",
      "level": 0
    },
    {
      "x": -4,
      "y": 4,
      "z": 4,
      "name": "Empty",
      "level": 0
    },
    {
      "x": -4,
      "y": 5,
      "z": 4,
