{
  "version": 8,
  "blockIdVersion": 11,
  "anchorX": 0,
  "anchorY": 0,
  "anchorZ": 0,
  "blocks": [
    {
      "x": -9,
      "y": 1,
      "z": -10,
      "name": "Nat20_Force_Empty"
    },
    {
      "x": -9,
      "y": 2,
      "z": -10,
      "name": "Nat20_Force_Empty"
    },
    {
      "x": -9,
      "y": 3,
      "z": -10,
      "name": "Nat20_Force_Empty"
    },
    {
      "x": -9,
      "y": 4,
      "z": -10,
      "name": "Nat20_Force_Empty"
    },
    {
      "x": -9,
      "y": 5,
      "z": -10,
      "name": "Nat20_Force_Empty"
    },
    {
      "x": -9,
      "y": 6,
      "z": -10,
      "name": "Nat20_Force_Empty"
    },
    {
      "x": -9,
      "y": 7,
      "z": -10,
      "name": "Nat20_Force_Empty"
    },
    {
      "x": -9,
      "y": 8,
      "z": -10,
      "name": "Nat20_Force_Empty"
    },
    {
      "x": -9,
      "y": 9,
      "z": -10,
      "name": "Nat20_Force_Empty"
    },
    {
      "x": -9,
      "y": 10,
      "z": -10,
      "name": "Nat20_Force_Empty"
    },
    {
      "x": -9,
      "y": 11,
      "z": -10,
      "name": "Nat20_Force_Empty"
    },
    {
      "x": -9,
      "y": 12,
      "z": -10,
      "name": "Nat20_Force_Empty"
    },
    {
      "x": -9,
      "y": 13,
      "z": -10,
      "name": "Nat20_Force_Empty"
    },
    {
      "x": -9,
      "y": 14,
      "z": -10,
      "name": "Nat20_Force_Empty"
    },
    {
      "x": -9,
      "y": 15,
      "z": -10,
      "name": "Nat20_Force_Empty"
    },
    {
      "x": -9,
      "y": 16,
      "z": -10,
      "name": "Nat20_Force_Empty"
    },
    {
      "x": -9,
      "y": 17,
      "z": -10,
      "name": "Nat20_Force_Empty"
    },
    {
      "x": -9,
      "y": 18,
      "z": -10,
      "name": "Nat20_Force_Empty"
    },
    {
      "x": -9,
      "y": 19,
      "z": -10,
      "name": "Nat20_Force_Empty"
    },
    {
      "x": -9,
      "y": 1,
      "z": -9,
      "name": "Nat20_Force_Empty"
    },
    {
      "x": -9,
      "y": 2,
      "z": -9,
      "name": "Nat20_Force_Empty"
    },
    {
      "x": -9,
      "y": 3,
      "z": -9,
      "name": "Nat20_Force_Empty"
    },
    {
      "x": -9,
      "y": 4,
      "z": -9,
      "name": "Nat20_Force_Empty"
    },
    {
      "x": -9,
      "y": 5,
      "z": -9,
      "name": "Nat20_Force_Empty"
    },
    {
      "x": -9,
      "y": 6,
      "z": -9,
      "name": "Nat20_Force_Empty"
    },
    {
      "x": -9,
      "y": 7,
      "z": -9,
      "name": "Nat20_Force_Empty"
    },
    {
      "x": -9,
      "y": 8,
      "z": -9,
      "name": "Nat20_Force_Empty"
    },
    {
      "x": -9,
      "y": 9,
      "z": -9,
      "name": "Nat20_Force_Empty"
    },
    {
      "x": -9,
      "y": 10,
      "z": -9,
      "name": "Nat20_Force_Empty"
    },
    {
      "x": -9,
      "y": 11,
      "z": -9,
      "name": "Nat20_Force_Empty"
    },
    {
      "x": -9,
      "y": 12,
      "z": -9,
      "name": "Nat20_Force_Empty"
    },
    {
      "x": -9,
      "y": 13,
      "z": -9,
      "name": "Nat20_Force_Empty"
    },
    {
      "x": -9,
      "y": 14,
      "z": -9,
      "name": "Nat20_Force_Empty"
    },
    {
      "x": -9,
      "y": 15,
      "z": -9,
      "name": "Nat20_Force_Empty"
    },
    {
      "x": -9,
      "y": 16,
      "z": -9,
      "name": "Nat20_Force_Empty"
    },
    {
      "x": -9,
      "y": 17,
      "z": -9,
      "name": "Nat20_Force_Empty"
    },
    {
      "x": -9,
      "y": 18,
      "z": -9,
      "name": "Nat20_Force_Empty"
    },
    {
      "x": -9,
      "y": 19,
      "z": -9,
      "name": "Nat20_Force_Empty"
    },
    {
      "x": -9,
      "y": 1,
      "z": -8,
      "name": "Nat20_Force_Empty"
    },
    {
      "x": -9,
      "y": 2,
      "z": -8,
      "name": "Nat20_Force_Empty"
    },
    {
      "x": -9,
      "y": 3,
      "z": -8,
      "name": "Nat20_Force_Empty"
    },
    {
      "x": -9,
      "y": 4,
      "z": -8,
      "name": "Nat20_Force_Empty"
    },
    {
      "x": -9,
      "y": 5,
      "z": -8,
      "name": "Nat20_Force_Empty"
    },
    {
      "x": -9,
      "y": 6,
      "z": -8,
      "name": "Nat20_Force_Empty"
    },
    {
      "x": -9,
      "y": 7,
      "z": -8,
      "name": "Nat20_Force_Empty"
    },
    {
      "x": -9,
      "y": 8,
      "z": -8,
      "name": "Nat20_Force_Empty"
    },
    {
      "x": -9,
      "y": 9,
      "z": -8,
      "name": "Nat20_Force_Empty"
    },
    {
      "x": -9,
      "y": 10,
      "z": -8,
      "name": "Nat20_Force_Empty"
    },
    {
      "x": -9,
      "y": 11,
      "z": -8,
      "name": "Nat20_Force_Empty"
    },
    {
      "x": -9,
      "y": 12,
      "z": -8,
      "name": "Nat20_Force_Empty"
    },
    {
      "x": -9,
      "y": 13,
      "z": -8,
      "name": "Nat20_Force_Empty"
    },
    {
      "x": -9,
      "y": 14,
      "z": -8,
      "name": "Nat20_Force_Empty"
    },
    {
      "x": -9,
      "y": 15,
      "z": -8,
      "name": "Nat20_Force_Empty"
    },
    {
      "x": -9,
      "y": 16,
      "z": -8,
      "name": "Nat20_Force_Empty"
    },
    {
      "x": -9,
      "y": 17,
      "z": -8,
      "name": "Nat20_Force_Empty"
    },
    {
      "x": -9,
      "y": 18,
      "z": -8,
      "name": "Nat20_Force_Empty"
    },
    {
      "x": -9,
      "y": 19,
      "z": -8,
      "name": "Nat20_Force_Empty"
    },
    {
      "x": -9,
      "y": 1,
      "z": -7,
      "name": "Nat20_Force_Empty"
    },
    {
      "x": -9,
      "y": 2,
      "z": -7,
      "name": "Nat20_Force_Empty"
    },
    {
      "x": -9,
      "y": 3,
      "z": -7,
      "name": "Nat20_Force_Empty"
    },
    {
      "x": -9,
      "y": 4,
      "z": -7,
      "name": "Nat20_Force_Empty"
    },
    {
      "x": -9,
      "y": 5,
      "z": -7,
      "name": "Nat20_Force_Empty"
    },
    {
      "x": -9,
      "y": 6,
      "z": -7,
      "name": "Nat20_Force_Empty"
    },
    {
      "x": -9,
      "y": 7,
      "z": -7,
      "name": "Nat20_Force_Empty"
    },
    {
      "x": -9,
      "y": 8,
      "z": -7,
      "name": "Nat20_Force_Empty"
    },
    {
      "x": -9,
      "y": 9,
      "z": -7,
      "name": "Nat20_Force_Empty"
    },
    {
      "x": -9,
      "y": 10,
      "z": -7,
      "name": "Nat20_Force_Empty"
    },
    {
      "x": -9,
      "y": 11,
      "z": -7,
      "name": "Nat20_Force_Empty"
    },
    {
      "x": -9,
      "y": 12,
      "z": -7,
      "name": "Nat20_Force_Empty"
    },
    {
      "x": -9,
      "y": 13,
      "z": -7,
      "name": "Nat20_Force_Empty"
    },
    {
      "x": -9,
      "y": 14,
      "z": -7,
      "name": "Nat20_Force_Empty"
    },
    {
      "x": -9,
      "y": 15,
      "z": -7,
      "name": "Nat20_Force_Empty"
    },
    {
      "x": -9,
      "y": 16,
      "z": -7,
      "name": "Nat20_Force_Empty"
    },
    {
      "x": -9,
      "y": 17,
      "z": -7,
      "name": "Nat20_Force_Empty"
    },
    {
      "x": -9,
      "y": 18,
      "z": -7,
      "name": "Nat20_Force_Empty"
    },
    {
      "x": -9,
      "y": 19,
      "z": -7,
      "name": "Nat20_Force_Empty"
    },
    {
      "x": -9,
      "y": 1,
      "z": -6,
      "name": "Nat20_Force_Empty"
    },
    {
      "x": -9,
      "y": 2,
      "z": -6,
      "name": "Nat20_Force_Empty"
    },
    {
      "x": -9,
      "y": 3,
      "z": -6,
      "name": "Nat20_Force_Empty"
    },
    {
      "x": -9,
      "y": 4,
      "z": -6,
      "name": "Nat20_Force_Empty"
    },
    {
      "x": -9,
      "y": 5,
      "z": -6,
      "name": "Nat20_Force_Empty"
    },
    {
      "x": -9,
      "y": 6,
      "z": -6,
      "name": "Nat20_Force_Empty"
    },
    {
      "x": -9,
      "y": 7,
      "z": -6,
      "name": "Nat20_Force_Empty"
    },
    {
      "x": -9,
      "y": 8,
      "z": -6,
      "name": "Nat20_Force_Empty"
    },
    {
      "x": -9,
      "y": 9,
      "z": -6,
      "name": "Nat20_Force_Empty"
    },
    {
      "x": -9,
      "y": 10,
      "z": -6,
      "name": "Nat20_Force_Empty"
    },
    {
      "x": -9,
      "y": 11,
      "z": -6,
      "name": "Nat20_Force_Empty"
    },
    {
      "x": -9,
      "y": 12,
      "z": -6,
      "name": "Nat20_Force_Empty"
    },
    {
      "x": -9,
      "y": 13,
      "z": -6,
      "name": "Nat20_Force_Empty"
    },
    {
      "x": -9,
      "y": 14,
      "z": -6,
      "name": "Nat20_Force_Empty"
    },
    {
      "x": -9,
      "y": 15,
      "z": -6,
      "name": "Nat20_Force_Empty"
    },
    {
      "x": -9,
      "y": 16,
      "z": -6,
      "name": "Nat20_Force_Empty"
    },
    {
      "x": -9,
      "y": 17,
      "z": -6,
      "name": "Nat20_Force_Empty"
    },
    {
      "x": -9,
      "y": 18,
      "z": -6,
      "name": "Nat20_Force_Empty"
    },
    {
      "x": -9,
      "y": 19,
      "z": -6,
      "name": "Nat20_Force_Empty"
    },
    {
      "x": -9,
      "y": 1,
      "z": -5,
      "name": "Nat20_Force_Empty"
    },
    {
      "x": -9,
      "y": 2,
      "z": -5,
      "name": "Nat20_Force_Empty"
    },
    {
      "x": -9,
      "y": 3,
      "z": -5,
      "name": "Nat20_Force_Empty"
    },
    {
      "x": -9,
      "y": 4,
      "z": -5,
      "name": "Nat20_Force_Empty"
    },
    {
      "x": -9,
      "y": 5,
      "z": -5,
      "name": "Nat20_Force_Empty"
    },
    {
      "x": -9,
      "y": 6,
      "z": -5,
      "name": "Nat20_Force_Empty"
    },
    {
      "x": -9,
      "y": 7,
      "z": -5,
      "name": "Nat20_Force_Empty"
    },
    {
      "x": -9,
      "y": 8,
      "z": -5,
      "name": "Wood_Drywood_Planks_Half",
      "rotation": 7
    },
    {
      "x": -9,
      "y": 9,
      "z": -5,
      "name": "Nat20_Force_Empty"
    },
    {
      "x": -9,
      "y": 10,
      "z": -5,
      "name": "Nat20_Force_Empty"
    },
    {
      "x": -9,
      "y": 11,
      "z": -5,
      "name": "Nat20_Force_Empty"
    },
    {
      "x": -9,
      "y": 12,
      "z": -5,
      "name": "Nat20_Force_Empty"
    },
    {
      "x": -9,
      "y": 13,
      "z": -5,
      "name": "Nat20_Force_Empty"
    },
    {
      "x": -9,
      "y": 14,
      "z": -5,
      "name": "Nat20_Force_Empty"
    },
    {
      "x": -9,
      "y": 15,
      "z": -5,
      "name": "Nat20_Force_Empty"
    },
    {
      "x": -9,
      "y": 16,
      "z": -5,
      "name": "Nat20_Force_Empty"
    },
    {
      "x": -9,
      "y": 17,
      "z": -5,
      "name": "Nat20_Force_Empty"
    },
    {
      "x": -9,
      "y": 18,
      "z": -5,
      "name": "Nat20_Force_Empty"
    },
    {
      "x": -9,
      "y": 19,
      "z": -5,
      "name": "Nat20_Force_Empty"
    },
    {
      "x": -9,
      "y": 1,
      "z": -4,
      "name": "Nat20_Force_Empty"
    },
    {
      "x": -9,
      "y": 2,
      "z": -4,
      "name": "Nat20_Force_Empty"
    },
    {
      "x": -9,
      "y": 3,
      "z": -4,
      "name": "Nat20_Force_Empty"
    },
    {
      "x": -9,
      "y": 4,
      "z": -4,
      "name": "Nat20_Force_Empty"
    },
    {
      "x": -9,
      "y": 5,
      "z": -4,
      "name": "Nat20_Force_Empty"
    },
    {
      "x": -9,
      "y": 6,
      "z": -4,
      "name": "Nat20_Force_Empty"
    },
    {
      "x": -9,
      "y": 7,
      "z": -4,
      "name": "Nat20_Force_Empty"
    },
    {
      "x": -9,
      "y": 8,
      "z": -4,
      "name": "Wood_Drywood_Planks"
    },
    {
      "x": -9,
      "y": 9,
      "z": -4,
      "name": "Nat20_Force_Empty"
    },
    {
      "x": -9,
      "y": 10,
      "z": -4,
      "name": "Nat20_Force_Empty"
    },
    {
      "x": -9,
      "y": 11,
      "z": -4,
      "name": "Nat20_Force_Empty"
    },
    {
      "x": -9,
      "y": 12,
      "z": -4,
      "name": "Nat20_Force_Empty"
    },
    {
      "x": -9,
      "y": 13,
      "z": -4,
      "name": "Nat20_Force_Empty"
    },
    {
      "x": -9,
      "y": 14,
      "z": -4,
      "name": "Nat20_Force_Empty"
    },
    {
      "x": -9,
      "y": 15,
      "z": -4,
      "name": "Nat20_Force_Empty"
    },
    {
      "x": -9,
      "y": 16,
      "z": -4,
      "name": "Nat20_Force_Empty"
    },
    {
      "x": -9,
      "y": 17,
      "z": -4,
      "name": "Nat20_Force_Empty"
    },
    {
      "x": -9,
      "y": 18,
      "z": -4,
      "name": "Nat20_Force_Empty"
    },
    {
      "x": -9,
      "y": 19,
      "z": -4,
      "name": "Nat20_Force_Empty"
    },
    {
      "x": -9,
      "y": 0,
      "z": -3,
      "name": "Soil_Clay"
    },
    {
      "x": -9,
      "y": 1,
      "z": -3,
      "name": "Soil_Clay"
    },
    {
      "x": -9,
      "y": 2,
      "z": -3,
      "name": "Soil_Clay"
    },
    {
      "x": -9,
      "y": 3,
      "z": -3,
      "name": "Soil_Clay"
    },
    {
      "x": -9,
      "y": 4,
      "z": -3,
      "name": "Soil_Clay"
    },
    {
      "x": -9,
      "y": 5,
      "z": -3,
      "name": "Soil_Clay"
    },
    {
      "x": -9,
      "y": 6,
      "z": -3,
      "name": "Nat20_Force_Empty"
    },
    {
      "x": -9,
      "y": 7,
      "z": -3,
      "name": "Nat20_Force_Empty"
    },
    {
      "x": -9,
      "y": 8,
      "z": -3,
      "name": "Wood_Drywood_Planks"
    },
    {
      "x": -9,
      "y": 9,
      "z": -3,
      "name": "Nat20_Force_Empty"
    },
    {
      "x": -9,
      "y": 10,
      "z": -3,
      "name": "Nat20_Force_Empty"
    },
    {
      "x": -9,
      "y": 11,
      "z": -3,
      "name": "Nat20_Force_Empty"
    },
    {
      "x": -9,
      "y": 12,
      "z": -3,
      "name": "Nat20_Force_Empty"
    },
    {
      "x": -9,
      "y": 13,
      "z": -3,
      "name": "Nat20_Force_Empty"
    },
    {
      "x": -9,
      "y": 14,
      "z": -3,
      "name": "Nat20_Force_Empty"
    },
    {
      "x": -9,
      "y": 15,
      "z": -3,
      "name": "Nat20_Force_Empty"
    },
    {
      "x": -9,
      "y": 16,
      "z": -3,
      "name": "Nat20_Force_Empty"
    },
    {
      "x": -9,
      "y": 17,
      "z": -3,
      "name": "Nat20_Force_Empty"
    },
    {
      "x": -9,
      "y": 18,
      "z": -3,
      "name": "Nat20_Force_Empty"
    },
    {
      "x": -9,
      "y": 19,
      "z": -3,
      "name": "Nat20_Force_Empty"
    },
    {
      "x": -9,
      "y": 0,
      "z": -2,
      "name": "Soil_Clay"
    },
    {
      "x": -9,
      "y": 1,
      "z": -2,
      "name": "Soil_Clay"
    },
    {
      "x": -9,
      "y": 2,
      "z": -2,
      "name": "Soil_Clay"
    },
    {
      "x": -9,
      "y": 3,
      "z": -2,
      "name": "Soil_Clay"
    },
    {
      "x": -9,
      "y": 4,
      "z": -2,
      "name": "Soil_Clay"
    },
    {
      "x": -9,
      "y": 5,
      "z": -2,
      "name": "Soil_Clay"
    },
    {
      "x": -9,
      "y": 6,
      "z": -2,
      "name": "Rock_Sandstone_Cobble"
    },
    {
      "x": -9,
      "y": 7,
      "z": -2,
      "name": "Rock_Sandstone_Cobble"
    },
    {
      "x": -9,
      "y": 8,
      "z": -2,
      "name": "Wood_Drywood_Planks"
    },
    {
      "x": -9,
      "y": 9,
      "z": -2,
      "name": "*Cloth_Roof_Hide_State_Definitions_Corner_Right",
      "rotation": 3
    },
    {
      "x": -9,
      "y": 10,
      "z": -2,
      "name": "Nat20_Force_Empty"
    },
    {
      "x": -9,
      "y": 11,
      "z": -2,
      "name": "Nat20_Force_Empty"
    },
    {
      "x": -9,
      "y": 12,
      "z": -2,
      "name": "Nat20_Force_Empty"
    },
    {
      "x": -9,
      "y": 13,
      "z": -2,
      "name": "Nat20_Force_Empty"
    },
    {
      "x": -9,
      "y": 14,
      "z": -2,
      "name": "Nat20_Force_Empty"
    },
    {
      "x": -9,
      "y": 15,
      "z": -2,
      "name": "Nat20_Force_Empty"
    },
    {
      "x": -9,
      "y": 16,
      "z": -2,
      "name": "Nat20_Force_Empty"
    },
    {
      "x": -9,
      "y": 17,
      "z": -2,
      "name": "Nat20_Force_Empty"
    },
    {
      "x": -9,
      "y": 18,
      "z": -2,
      "name": "Nat20_Force_Empty"
    },
    {
      "x": -9,
      "y": 19,
      "z": -2,
      "name": "Nat20_Force_Empty"
    },
    {
      "x": -9,
      "y": 0,
      "z": -1,
      "name": "Soil_Clay"
    },
    {
      "x": -9,
      "y": 1,
      "z": -1,
      "name": "Soil_Clay"
    },
    {
      "x": -9,
      "y": 2,
      "z": -1,
      "name": "Soil_Clay"
    },
    {
      "x": -9,
      "y": 3,
      "z": -1,
      "name": "Soil_Clay"
    },
    {
      "x": -9,
      "y": 4,
      "z": -1,
      "name": "Soil_Clay"
    },
    {
      "x": -9,
      "y": 5,
      "z": -1,
      "name": "Soil_Clay"
    },
    {
      "x": -9,
      "y": 6,
      "z": -1,
      "name": "Rock_Sandstone_Cobble"
    },
    {
      "x": -9,
      "y": 7,
      "z": -1,
      "name": "Wood_Dry_Branch_Long"
    },
    {
      "x": -9,
      "y": 8,
      "z": -1,
      "name": "Wood_Drywood_Planks"
    },
    {
      "x": -9,
      "y": 9,
      "z": -1,
      "name": "Cloth_Roof_Hide",
      "rotation": 3
    },
    {
      "x": -9,
      "y": 10,
      "z": -1,
      "name": "Nat20_Force_Empty"
    },
    {
      "x": -9,
      "y": 11,
      "z": -1,
      "name": "Nat20_Force_Empty"
    },
    {
      "x": -9,
      "y": 12,
      "z": -1,
      "name": "Nat20_Force_Empty"
    },
    {
      "x": -9,
      "y": 13,
      "z": -1,
      "name": "Nat20_Force_Empty"
    },
    {
      "x": -9,
      "y": 14,
      "z": -1,
      "name": "Nat20_Force_Empty"
    },
    {
      "x": -9,
      "y": 15,
      "z": -1,
      "name": "Nat20_Force_Empty"
    },
    {
      "x": -9,
      "y": 16,
      "z": -1,
      "name": "Nat20_Force_Empty"
    },
    {
      "x": -9,
      "y": 17,
      "z": -1,
      "name": "Nat20_Force_Empty"
    },
    {
      "x": -9,
      "y": 18,
      "z": -1,
      "name": "Nat20_Force_Empty"
    },
    {
      "x": -9,
      "y": 19,
      "z": -1,
      "name": "Nat20_Force_Empty"
    },
    {
      "x": -9,
      "y": 0,
      "z": 0,
      "name": "Soil_Clay"
    },
    {
      "x": -9,
      "y": 1,
      "z": 0,
      "name": "Soil_Clay"
    },
    {
      "x": -9,
      "y": 2,
      "z": 0,
      "name": "Soil_Clay"
    },
    {
      "x": -9,
      "y": 3,
      "z": 0,
      "name": "Soil_Clay"
    },
    {
      "x": -9,
      "y": 4,
      "z": 0,
      "name": "Soil_Clay"
    },
    {
      "x": -9,
      "y": 5,
      "z": 0,
      "name": "Soil_Clay"
    },
    {
      "x": -9,
      "y": 6,
      "z": 0,
      "name": "Rock_Sandstone_Cobble"
    },
    {
      "x": -9,
      "y": 7,
      "z": 0,
      "name": "Rock_Sandstone_Cobble"
    },
    {
      "x": -9,
      "y": 8,
      "z": 0,
      "name": "Wood_Drywood_Planks"
    },
    {
      "x": -9,
      "y": 9,
      "z": 0,
      "name": "*Cloth_Roof_Hide_State_Definitions_Corner_Right"
    },
    {
      "x": -9,
      "y": 10,
      "z": 0,
      "name": "Nat20_Force_Empty"
    },
    {
      "x": -9,
      "y": 11,
      "z": 0,
      "name": "Nat20_Force_Empty"
    },
    {
      "x": -9,
      "y": 12,
      "z": 0,
      "name": "Nat20_Force_Empty"
    },
    {
      "x": -9,
      "y": 13,
      "z": 0,
      "name": "Nat20_Force_Empty"
    },
    {
      "x": -9,
      "y": 14,
      "z": 0,
      "name": "Nat20_Force_Empty"
    },
    {
      "x": -9,
      "y": 15,
      "z": 0,
      "name": "Nat20_Force_Empty"
    },
    {
      "x": -9,
      "y": 16,
      "z": 0,
      "name": "Nat20_Force_Empty"
    },
    {
      "x": -9,
      "y": 17,
      "z": 0,
      "name": "Nat20_Force_Empty"
    },
    {
      "x": -9,
      "y": 18,
      "z": 0,
      "name": "Nat20_Force_Empty"
    },
    {
      "x": -9,
      "y": 19,
      "z": 0,
      "name": "Nat20_Force_Empty"
    },
    {
      "x": -9,
      "y": 0,
      "z": 1,
      "name": "Soil_Clay"
    },
    {
      "x": -9,
      "y": 1,
      "z": 1,
      "name": "Soil_Clay"
    },
    {
      "x": -9,
      "y": 2,
      "z": 1,
      "name": "Soil_Clay"
    },
    {
      "x": -9,
      "y": 3,
      "z": 1,
      "name": "Soil_Clay"
    },
    {
      "x": -9,
      "y": 4,
      "z": 1,
      "name": "Soil_Clay"
    },
    {
      "x": -9,
      "y": 5,
      "z": 1,
      "name": "Nat20_Force_Empty"
    },
    {
      "x": -9,
      "y": 6,
      "z": 1,
      "name": "Nat20_Force_Empty"
    },
    {
      "x": -9,
      "y": 7,
      "z": 1,
      "name": "Nat20_Force_Empty"
    },
    {
      "x": -9,
      "y": 8,
      "z": 1,
      "name": "Wood_Drywood_Planks"
    },
    {
      "x": -9,
      "y": 9,
      "z": 1,
      "name": "Nat20_Force_Empty"
    },
    {
      "x": -9,
      "y": 10,
      "z": 1,
      "name": "Nat20_Force_Empty"
    },
    {
      "x": -9,
      "y": 11,
      "z": 1,
      "name": "Nat20_Force_Empty"
    },
    {
      "x": -9,
      "y": 12,
      "z": 1,
      "name": "Nat20_Force_Empty"
    },
    {
      "x": -9,
      "y": 13,
      "z": 1,
      "name": "Nat20_Force_Empty"
    },
    {
      "x": -9,
      "y": 14,
      "z": 1,
      "name": "Nat20_Force_Empty"
    },
    {
      "x": -9,
      "y": 15,
      "z": 1,
      "name": "Wood_Dry_Branch_Long",
      "rotation": 5
    },
    {
      "x": -9,
      "y": 16,
      "z": 1,
      "name": "Wood_Dry_Branch_Long",
      "rotation": 5
    },
    {
      "x": -9,
      "y": 17,
      "z": 1,
      "name": "Nat20_Force_Empty"
    },
    {
      "x": -9,
      "y": 18,
      "z": 1,
      "name": "Nat20_Force_Empty"
    },
    {
      "x": -9,
      "y": 19,
      "z": 1,
      "name": "Nat20_Force_Empty"
    },
    {
      "x": -9,
      "y": 1,
      "z": 2,
      "name": "Nat20_Force_Empty"
    },
    {
      "x": -9,
      "y": 2,
      "z": 2,
      "name": "Nat20_Force_Empty"
    },
    {
      "x": -9,
      "y": 3,
      "z": 2,
      "name": "Nat20_Force_Empty"
    },
    {
      "x": -9,
      "y": 4,
      "z": 2,
      "name": "Nat20_Force_Empty"
    },
    {
      "x": -9,
      "y": 5,
      "z": 2,
      "name": "Nat20_Force_Empty"
    },
    {
      "x": -9,
      "y": 6,
      "z": 2,
      "name": "Nat20_Force_Empty"
    },
    {
      "x": -9,
      "y": 7,
      "z": 2,
      "name": "Nat20_Force_Empty"
    },
    {
      "x": -9,
      "y": 8,
      "z": 2,
      "name": "Wood_Drywood_Planks"
    },
    {
      "x": -9,
      "y": 9,
      "z": 2,
      "name": "Nat20_Force_Empty"
    },
    {
      "x": -9,
      "y": 10,
      "z": 2,
      "name": "Nat20_Force_Empty"
    },
    {
      "x": -9,
      "y": 11,
      "z": 2,
      "name": "Nat20_Force_Empty"
    },
    {
      "x": -9,
      "y": 12,
      "z": 2,
      "name": "Nat20_Force_Empty"
    },
    {
      "x": -9,
      "y": 13,
      "z": 2,
      "name": "Nat20_Force_Empty"
    },
    {
      "x": -9,
      "y": 14,
      "z": 2,
      "name": "Nat20_Force_Empty"
    },
    {
      "x": -9,
      "y": 15,
      "z": 2,
      "name": "Nat20_Force_Empty"
    },
    {
      "x": -9,
      "y": 16,
      "z": 2,
      "name": "Nat20_Force_Empty"
    },
    {
      "x": -9,
      "y": 17,
      "z": 2,
      "name": "Nat20_Force_Empty"
    },
    {
      "x": -9,
      "y": 18,
      "z": 2,
      "name": "Nat20_Force_Empty"
    },
    {
      "x": -9,
      "y": 19,
      "z": 2,
      "name": "Nat20_Force_Empty"
    },
    {
      "x": -9,
      "y": 1,
      "z": 3,
      "name": "Nat20_Force_Empty"
    },
    {
      "x": -9,
      "y": 2,
      "z": 3,
      "name": "Nat20_Force_Empty"
    },
    {
      "x": -9,
      "y": 3,
      "z": 3,
      "name": "Nat20_Force_Empty"
    },
    {
      "x": -9,
      "y": 4,
      "z": 3,
      "name": "Nat20_Force_Empty"
    },
    {
      "x": -9,
      "y": 5,
      "z": 3,
      "name": "Nat20_Force_Empty"
    },
    {
      "x": -9,
      "y": 6,
      "z": 3,
      "name": "Nat20_Force_Empty"
    },
    {
      "x": -9,
      "y": 7,
      "z": 3,
      "name": "Nat20_Force_Empty"
    },
    {
      "x": -9,
      "y": 8,
      "z": 3,
      "name": "Wood_Drywood_Planks_Half",
      "rotation": 7
    },
    {
      "x": -9,
      "y": 9,
      "z": 3,
      "name": "Nat20_Force_Empty"
    },
    {
      "x": -9,
      "y": 10,
      "z": 3,
      "name": "Nat20_Force_Empty"
    },
    {
      "x": -9,
      "y": 11,
      "z": 3,
      "name": "Nat20_Force_Empty"
    },
    {
      "x": -9,
      "y": 12,
      "z": 3,
      "name": "Nat20_Force_Empty"
    },
    {
      "x": -9,
      "y": 13,
      "z": 3,
      "name": "Nat20_Force_Empty"
    },
    {
      "x": -9,
      "y": 14,
      "z": 3,
      "name": "Nat20_Force_Empty"
    },
    {
      "x": -9,
      "y": 15,
      "z": 3,
      "name": "Nat20_Force_Empty"
    },
    {
      "x": -9,
      "y": 16,
      "z": 3,
      "name": "Nat20_Force_Empty"
    },
    {
      "x": -9,
      "y": 17,
      "z": 3,
      "name": "Nat20_Force_Empty"
    },
    {
      "x": -9,
      "y": 18,
      "z": 3,
      "name": "Nat20_Force_Empty"
    },
    {
      "x": -9,
      "y": 19,
      "z": 3,
      "name": "Nat20_Force_Empty"
    },
    {
      "x": -9,
      "y": 1,
      "z": 4,
      "name": "Nat20_Force_Empty"
    },
    {
      "x": -9,
      "y": 2,
      "z": 4,
      "name": "Nat20_Force_Empty"
    },
    {
      "x": -9,
      "y": 3,
      "z": 4,
      "name": "Nat20_Force_Empty"
    },
    {
      "x": -9,
      "y": 4,
      "z": 4,
      "name": "Nat20_Force_Empty"
    },
    {
      "x": -9,
      "y": 5,
      "z": 4,
      "name": "Nat20_Force_Empty"
    },
    {
      "x": -9,
      "y": 6,
      "z": 4,
      "name": "Nat20_Force_Empty"
    },
    {
      "x": -9,
      "y": 7,
      "z": 4,
      "name": "Nat20_Force_Empty"
    },
    {
      "x": -9,
      "y": 8,
      "z": 4,
      "name": "Nat20_Force_Empty"
    },
    {
      "x": -9,
      "y": 9,
      "z": 4,
      "name": "Nat20_Force_Empty"
    },
    {
      "x": -9,
      "y": 10,
      "z": 4,
      "name": "Nat20_Force_Empty"
    },
    {
      "x": -9,
      "y": 11,
      "z": 4,
      "name": "Nat20_Force_Empty"
    },
    {
      "x": -9,
      "y": 12,
      "z": 4,
      "name": "Nat20_Force_Empty"
    },
    {
      "x": -9,
      "y": 13,
      "z": 4,
      "name": "Nat20_Force_Empty"
    },
    {
      "x": -9,
      "y": 14,
      "z": 4,
      "name": "Nat20_Force_Empty"
    },
    {
      "x": -9,
      "y": 15,
      "z": 4,
      "name": "Nat20_Force_Empty"
    },
    {
      "x": -9,
      "y": 16,
      "z": 4,
      "name": "Nat20_Force_Empty"
    },
    {
      "x": -9,
      "y": 17,
      "z": 4,
      "name": "Nat20_Force_Empty"
    },
    {
      "x": -9,
      "y": 18,
      "z": 4,
      "name": "Nat20_Force_Empty"
    },
    {
      "x": -9,
      "y": 19,
      "z": 4,
      "name": "Nat20_Force_Empty"
    },
    {
      "x": -9,
      "y": 1,
      "z": 5,
      "name": "Nat20_Force_Empty"
    },
    {
      "x": -9,
      "y": 2,
      "z": 5,
      "name": "Nat20_Force_Empty"
    },
    {
      "x": -9,
      "y": 3,
      "z": 5,
      "name": "Nat20_Force_Empty"
    },
    {
      "x": -9,
      "y": 4,
      "z": 5,
      "name": "Nat20_Force_Empty"
    },
    {
      "x": -9,
      "y": 5,
      "z": 5,
      "name": "Nat20_Force_Empty"
    },
    {
      "x": -9,
      "y": 6,
      "z": 5,
      "name": "Nat20_Force_Empty"
    },
    {
      "x": -9,
      "y": 7,
      "z": 5,
      "name": "Nat20_Force_Empty"
    },
    {
      "x": -9,
      "y": 8,
      "z": 5,
      "name": "Nat20_Force_Empty"
    },
    {
      "x": -9,
      "y": 9,
      "z": 5,
      "name": "Nat20_Force_Empty"
    },
    {
      "x": -9,
      "y": 10,
      "z": 5,
      "name": "Nat20_Force_Empty"
    },
    {
      "x": -9,
      "y": 11,
      "z": 5,
      "name": "Nat20_Force_Empty"
    },
    {
      "x": -9,
      "y": 12,
      "z": 5,
      "name": "Nat20_Force_Empty"
    },
    {
      "x": -9,
      "y": 13,
      "z": 5,
      "name": "Nat20_Force_Empty"
    },
    {
      "x": -9,
      "y": 14,
      "z": 5,
      "name": "Nat20_Force_Empty"
    },
    {
      "x": -9,
      "y": 15,
      "z": 5,
      "name": "Nat20_Force_Empty"
    },
    {
      "x": -9,
      "y": 16,
      "z": 5,
      "name": "Nat20_Force_Empty"
    },
    {
      "x": -9,
      "y": 17,
      "z": 5,
      "name": "Nat20_Force_Empty"
    },
    {
      "x": -9,
      "y": 18,
      "z": 5,
      "name": "Nat20_Force_Empty"
    },
    {
      "x": -9,
      "y": 19,
      "z": 5,
      "name": "Nat20_Force_Empty"
    },
    {
      "x": -9,
      "y": 1,
      "z": 6,
      "name": "Nat20_Force_Empty"
    },
    {
      "x": -9,
      "y": 2,
      "z": 6,
      "name": "Nat20_Force_Empty"
    },
    {
      "x": -9,
      "y": 3,
      "z": 6,
      "name": "Nat20_Force_Empty"
    },
    {
      "x": -9,
      "y": 4,
      "z": 6,
      "name": "Nat20_Force_Empty"
    },
    {
      "x": -9,
      "y": 5,
      "z": 6,
      "name": "Nat20_Force_Empty"
    },
    {
      "x": -9,
      "y": 6,
      "z": 6,
      "name": "Nat20_Force_Empty"
    },
    {
      "x": -9,
      "y": 7,
      "z": 6,
      "name": "Nat20_Force_Empty"
    },
    {
      "x": -9,
      "y": 8,
      "z": 6,
      "name": "Nat20_Force_Empty"
    },
    {
      "x": -9,
      "y": 9,
      "z": 6,
      "name": "Nat20_Force_Empty"
    },
    {
      "x": -9,
      "y": 10,
      "z": 6,
      "name": "Nat20_Force_Empty"
    },
    {
      "x": -9,
      "y": 11,
      "z": 6,
      "name": "Nat20_Force_Empty"
    },
    {
      "x": -9,
      "y": 12,
      "z": 6,
      "name": "Nat20_Force_Empty"
    },
    {
      "x": -9,
      "y": 13,
      "z": 6,
      "name": "Nat20_Force_Empty"
    },
    {
      "x": -9,
      "y": 14,
      "z": 6,
      "name": "Nat20_Force_Empty"
    },
    {
      "x": -9,
      "y": 15,
      "z": 6,
      "name": "Nat20_Force_Empty"
    },
    {
      "x": -9,
      "y": 16,
      "z": 6,
      "name": "Nat20_Force_Empty"
    },
    {
      "x": -9,
      "y": 17,
      "z": 6,
      "name": "Nat20_Force_Empty"
    },
    {
      "x": -9,
      "y": 18,
      "z": 6,
      "name": "Nat20_Force_Empty"
    },
    {
      "x": -9,
      "y": 19,
      "z": 6,
      "name": "Nat20_Force_Empty"
    },
    {
      "x": -9,
      "y": 1,
      "z": 7,
      "name": "Nat20_Force_Empty"
    },
    {
      "x": -9,
      "y": 2,
      "z": 7,
      "name": "Nat20_Force_Empty"
    },
    {
      "x": -9,
      "y": 3,
      "z": 7,
      "name": "Nat20_Force_Empty"
    },
    {
      "x": -9,
      "y": 4,
      "z": 7,
      "name": "Nat20_Force_Empty"
    },
    {
      "x": -9,
      "y": 5,
      "z": 7,
      "name": "Nat20_Force_Empty"
    },
    {
      "x": -9,
      "y": 6,
      "z": 7,
      "name": "Nat20_Force_Empty"
    },
    {
      "x": -9,
      "y": 7,
      "z": 7,
      "name": "Nat20_Force_Empty"
    },
    {
      "x": -9,
      "y": 8,
      "z": 7,
      "name": "Nat20_Force_Empty"
    },
    {
      "x": -9,
      "y": 9,
      "z": 7,
      "name": "Nat20_Force_Empty"
    },
    {
      "x": -9,
      "y": 10,
      "z": 7,
      "name": "Nat20_Force_Empty"
    },
    {
      "x": -9,
      "y": 11,
      "z": 7,
      "name": "Nat20_Force_Empty"
    },
    {
      "x": -9,
      "y": 12,
      "z": 7,
      "name": "Nat20_Force_Empty"
    },
    {
      "x": -9,
      "y": 13,
      "z": 7,
      "name": "Nat20_Force_Empty"
    },
    {
      "x": -9,
      "y": 14,
      "z": 7,
      "name": "Nat20_Force_Empty"
    },
    {
      "x": -9,
      "y": 15,
      "z": 7,
      "name": "Nat20_Force_Empty"
    },
    {
      "x": -9,
      "y": 16,
      "z": 7,
      "name": "Nat20_Force_Empty"
    },
    {
      "x": -9,
      "y": 17,
      "z": 7,
      "name": "Nat20_Force_Empty"
    },
    {
      "x": -9,
      "y": 18,
      "z": 7,
      "name": "Nat20_Force_Empty"
    },
    {
      "x": -9,
      "y": 19,
      "z": 7,
      "name": "Nat20_Force_Empty"
    },
    {
      "x": -9,
      "y": 1,
      "z": 8,
      "name": "Nat20_Force_Empty"
    },
    {
      "x": -9,
      "y": 2,
      "z": 8,
      "name": "Nat20_Force_Empty"
    },
    {
      "x": -9,
      "y": 3,
      "z": 8,
      "name": "Nat20_Force_Empty"
    },
    {
      "x": -9,
      "y": 4,
      "z": 8,
      "name": "Nat20_Force_Empty"
    },
    {
      "x": -9,
      "y": 5,
      "z": 8,
      "name": "Nat20_Force_Empty"
    },
    {
      "x": -9,
      "y": 6,
      "z": 8,
      "name": "Nat20_Force_Empty"
    },
    {
      "x": -9,
      "y": 7,
      "z": 8,
      "name": "Nat20_Force_Empty"
    },
    {
      "x": -9,
      "y": 8,
      "z": 8,
      "name": "Nat20_Force_Empty"
    },
    {
      "x": -9,
      "y": 9,
      "z": 8,
      "name": "Nat20_Force_Empty"
    },
    {
      "x": -9,
      "y": 10,
      "z": 8,
      "name": "Nat20_Force_Empty"
    },
    {
      "x": -9,
      "y": 11,
      "z": 8,
      "name": "Nat20_Force_Empty"
    },
    {
      "x": -9,
      "y": 12,
      "z": 8,
      "name": "Nat20_Force_Empty"
    },
    {
      "x": -9,
      "y": 13,
      "z": 8,
      "name": "Nat20_Force_Empty"
    },
    {
      "x": -9,
      "y": 14,
      "z": 8,
      "name": "Nat20_Force_Empty"
    },
    {
      "x": -9,
      "y": 15,
      "z": 8,
      "name": "Nat20_Force_Empty"
    },
    {
      "x": -9,
      "y": 16,
      "z": 8,
      "name": "Nat20_Force_Empty"
    },
    {
      "x": -9,
      "y": 17,
      "z": 8,
      "name": "Nat20_Force_Empty"
    },
    {
      "x": -9,
      "y": 18,
      "z": 8,
      "name": "Nat20_Force_Empty"
    },
    {
      "x": -9,
      "y": 19,
      "z": 8,
      "name": "Nat20_Force_Empty"
    },
    {
      "x": -9,
      "y": 1,
      "z": 9,
      "name": "Nat20_Force_Empty"
    },
    {
      "x": -9,
      "y": 2,
      "z": 9,
      "name": "Nat20_Force_Empty"
    },
    {
      "x": -9,
      "y": 3,
      "z": 9,
      "name": "Nat20_Force_Empty"
    },
    {
      "x": -9,
      "y": 4,
      "z": 9,
      "name": "Nat20_Force_Empty"
    },
    {
      "x": -9,
      "y": 5,
      "z": 9,
      "name": "Nat20_Force_Empty"
    },
    {
      "x": -9,
      "y": 6,
      "z": 9,
      "name": "Nat20_Force_Empty"
    },
    {
      "x": -9,
      "y": 7,
      "z": 9,
      "name": "Nat20_Force_Empty"
    },
    {
      "x": -9,
      "y": 8,
      "z": 9,
      "name": "Nat20_Force_Empty"
    },
    {
      "x": -9,
      "y": 9,
      "z": 9,
      "name": "Nat20_Force_Empty"
    },
    {
      "x": -9,
      "y": 10,
      "z": 9,
      "name": "Nat20_Force_Empty"
    },
    {
      "x": -9,
      "y": 11,
      "z": 9,
      "name": "Nat20_Force_Empty"
    },
    {
      "x": -9,
      "y": 12,
      "z": 9,
      "name": "Nat20_Force_Empty"
    },
    {
      "x": -9,
      "y": 13,
      "z": 9,
      "name": "Nat20_Force_Empty"
    },
    {
      "x": -9,
      "y": 14,
      "z": 9,
      "name": "Nat20_Force_Empty"
    },
    {
      "x": -9,
      "y": 15,
      "z": 9,
      "name": "Nat20_Force_Empty"
    },
    {
      "x": -9,
      "y": 16,
      "z": 9,
      "name": "Nat20_Force_Empty"
    },
    {
      "x": -9,
      "y": 17,
      "z": 9,
      "name": "Nat20_Force_Empty"
    },
    {
      "x": -9,
      "y": 18,
      "z": 9,
      "name": "Nat20_Force_Empty"
    },
    {
      "x": -9,
      "y": 19,
      "z": 9,
      "name": "Nat20_Force_Empty"
    },
    {
      "x": -9,
      "y": 1,
      "z": 10,
      "name": "Nat20_Force_Empty"
    },
    {
      "x": -9,
      "y": 2,
      "z": 10,
      "name": "Nat20_Force_Empty"
    },
    {
      "x": -9,
      "y": 3,
      "z": 10,
      "name": "Nat20_Force_Empty"
    },
    {
      "x": -9,
      "y": 4,
      "z": 10,
      "name": "Nat20_Force_Empty"
    },
    {
      "x": -9,
      "y": 5,
      "z": 10,
      "name": "Nat20_Force_Empty"
    },
    {
      "x": -9,
      "y": 6,
      "z": 10,
      "name": "Nat20_Force_Empty"
    },
    {
      "x": -9,
      "y": 7,
      "z": 10,
      "name": "Nat20_Force_Empty"
    },
    {
      "x": -9,
      "y": 8,
      "z": 10,
      "name": "Nat20_Force_Empty"
    },
    {
      "x": -9,
      "y": 9,
      "z": 10,
      "name": "Nat20_Force_Empty"
    },
    {
      "x": -9,
      "y": 10,
      "z": 10,
      "name": "Nat20_Force_Empty"
    },
    {
      "x": -9,
      "y": 11,
      "z": 10,
      "name": "Nat20_Force_Empty"
    },
    {
      "x": -9,
      "y": 12,
      "z": 10,
      "name": "Nat20_Force_Empty"
    },
    {
      "x": -9,
      "y": 13,
      "z": 10,
      "name": "Nat20_Force_Empty"
    },
    {
      "x": -9,
      "y": 14,
      "z": 10,
      "name": "Nat20_Force_Empty"
    },
    {
      "x": -9,
      "y": 15,
      "z": 10,
      "name": "Nat20_Force_Empty"
    },
    {
      "x": -9,
      "y": 16,
      "z": 10,
      "name": "Nat20_Force_Empty"
    },
    {
      "x": -9,
      "y": 17,
      "z": 10,
      "name": "Nat20_Force_Empty"
    },
    {
      "x": -9,
      "y": 18,
      "z": 10,
      "name": "Nat20_Force_Empty"
    },
    {
      "x": -9,
      "y": 19,
      "z": 10,
      "name": "Nat20_Force_Empty"
    },
    {
      "x": -8,
      "y": 1,
      "z": -10,
      "name": "Nat20_Force_Empty"
    },
    {
      "x": -8,
      "y": 2,
      "z": -10,
      "name": "Nat20_Force_Empty"
    },
    {
      "x": -8,
      "y": 3,
      "z": -10,
      "name": "Nat20_Force_Empty"
    },
    {
      "x": -8,
      "y": 4,
      "z": -10,
      "name": "Nat20_Force_Empty"
    },
    {
      "x": -8,
      "y": 5,
      "z": -10,
      "name": "Nat20_Force_Empty"
    },
    {
      "x": -8,
      "y": 6,
      "z": -10,
      "name": "Nat20_Force_Empty"
    },
    {
      "x": -8,
      "y": 7,
      "z": -10,
      "name": "Nat20_Force_Empty"
    },
    {
      "x": -8,
      "y": 8,
      "z": -10,
      "name": "Nat20_Force_Empty"
    },
    {
      "x": -8,
      "y": 9,
      "z": -10,
      "name": "Nat20_Force_Empty"
    },
    {
      "x": -8,
      "y": 10,
      "z": -10,
      "name": "Nat20_Force_Empty"
    },
    {
      "x": -8,
      "y": 11,
      "z": -10,
      "name": "Nat20_Force_Empty"
    },
    {
      "x": -8,
      "y": 12,
      "z": -10,
      "name": "Nat20_Force_Empty"
    },
    {
      "x": -8,
      "y": 13,
      "z": -10,
      "name": "Nat20_Force_Empty"
    },
    {
      "x": -8,
      "y": 14,
      "z": -10,
      "name": "Nat20_Force_Empty"
    },
    {
      "x": -8,
      "y": 15,
      "z": -10,
      "name": "Nat20_Force_Empty"
    },
    {
      "x": -8,
      "y": 16,
      "z": -10,
      "name": "Nat20_Force_Empty"
    },
    {
      "x": -8,
      "y": 17,
      "z": -10,
      "name": "Nat20_Force_Empty"
    },
    {
      "x": -8,
      "y": 18,
      "z": -10,
      "name": "Nat20_Force_Empty"
    },
    {
      "x": -8,
      "y": 19,
      "z": -10,
      "name": "Nat20_Force_Empty"
    },
    {
      "x": -8,
      "y": 1,
      "z": -9,
      "name": "Nat20_Force_Empty"
    },
    {
      "x": -8,
      "y": 2,
      "z": -9,
      "name": "Nat20_Force_Empty"
    },
    {
      "x": -8,
      "y": 3,
      "z": -9,
      "name": "Nat20_Force_Empty"
    },
    {
      "x": -8,
      "y": 4,
      "z": -9,
      "name": "Nat20_Force_Empty"
    },
    {
      "x": -8,
      "y": 5,
      "z": -9,
      "name": "Nat20_Force_Empty"
    },
    {
      "x": -8,
      "y": 6,
      "z": -9,
      "name": "Nat20_Force_Empty"
    },
    {
      "x": -8,
      "y": 7,
      "z": -9,
      "name": "Nat20_Force_Empty"
    },
    {
      "x": -8,
      "y": 8,
      "z": -9,
      "name": "Nat20_Force_Empty"
    },
    {
      "x": -8,
      "y": 9,
      "z": -9,
      "name": "Nat20_Force_Empty"
    },
    {
      "x": -8,
      "y": 10,
      "z": -9,
      "name": "Nat20_Force_Empty"
    },
    {
      "x": -8,
      "y": 11,
      "z": -9,
      "name": "Nat20_Force_Empty"
    },
    {
      "x": -8,
      "y": 12,
      "z": -9,
      "name": "Nat20_Force_Empty"
    },
    {
      "x": -8,
      "y": 13,
      "z": -9,
      "name": "Nat20_Force_Empty"
    },
    {
      "x": -8,
      "y": 14,
      "z": -9,
      "name": "Nat20_Force_Empty"
    },
    {
      "x": -8,
      "y": 15,
      "z": -9,
      "name": "Nat20_Force_Empty"
    },
    {
      "x": -8,
      "y": 16,
      "z": -9,
      "name": "Nat20_Force_Empty"
    },
    {
      "x": -8,
      "y": 17,
      "z": -9,
      "name": "Nat20_Force_Empty"
    },
    {
      "x": -8,
      "y": 18,
      "z": -9,
      "name": "Nat20_Force_Empty"
    },
    {
      "x": -8,
      "y": 19,
      "z": -9,
      "name": "Nat20_Force_Empty"
    },
    {
      "x": -8,
      "y": 1,
      "z": -8,
      "name": "Nat20_Force_Empty"
    },
    {
      "x": -8,
      "y": 2,
      "z": -8,
      "name": "Nat20_Force_Empty"
    },
    {
      "x": -8,
      "y": 3,
      "z": -8,
      "name": "Nat20_Force_Empty"
    },
    {
      "x": -8,
      "y": 4,
      "z": -8,
      "name": "Nat20_Force_Empty"
    },
    {
      "x": -8,
      "y": 5,
      "z": -8,
      "name": "Nat20_Force_Empty"
    },
    {
      "x": -8,
      "y": 6,
      "z": -8,
      "name": "Nat20_Force_Empty"
    },
    {
      "x": -8,
      "y": 7,
      "z": -8,
      "name": "Nat20_Force_Empty"
    },
    {
      "x": -8,
      "y": 8,
      "z": -8,
      "name": "Nat20_Force_Empty"
    },
    {
      "x": -8,
      "y": 9,
      "z": -8,
      "name": "Nat20_Force_Empty"
    },
    {
      "x": -8,
      "y": 10,
      "z": -8,
      "name": "Nat20_Force_Empty"
    },
    {
      "x": -8,
      "y": 11,
      "z": -8,
      "name": "Nat20_Force_Empty"
    },
    {
      "x": -8,
      "y": 12,
      "z": -8,
      "name": "Nat20_Force_Empty"
    },
    {
      "x": -8,
      "y": 13,
      "z": -8,
      "name": "Nat20_Force_Empty"
    },
    {
      "x": -8,
      "y": 14,
      "z": -8,
      "name": "Nat20_Force_Empty"
    },
    {
      "x": -8,
      "y": 15,
      "z": -8,
      "name": "Nat20_Force_Empty"
    },
    {
      "x": -8,
      "y": 16,
      "z": -8,
      "name": "Nat20_Force_Empty"
    },
    {
      "x": -8,
      "y": 17,
      "z": -8,
      "name": "Nat20_Force_Empty"
    },
    {
      "x": -8,
      "y": 18,
      "z": -8,
      "name": "Nat20_Force_Empty"
    },
    {
      "x": -8,
      "y": 19,
      "z": -8,
      "name": "Nat20_Force_Empty"
    },
    {
      "x": -8,
      "y": 1,
      "z": -7,
      "name": "Nat20_Force_Empty"
    },
    {
      "x": -8,
      "y": 2,
      "z": -7,
      "name": "Nat20_Force_Empty"
    },
    {
      "x": -8,
      "y": 3,
      "z": -7,
      "name": "Nat20_Force_Empty"
    },
    {
      "x": -8,
      "y": 4,
      "z": -7,
      "name": "Nat20_Force_Empty"
    },
    {
      "x": -8,
      "y": 5,
      "z": -7,
      "name": "Nat20_Force_Empty"
    },
    {
      "x": -8,
      "y": 6,
      "z": -7,
      "name": "Nat20_Force_Empty"
    },
    {
      "x": -8,
      "y": 7,
      "z": -7,
      "name": "Nat20_Force_Empty"
    },
    {
      "x": -8,
      "y": 8,
      "z": -7,
      "name": "Wood_Drywood_Planks_Half",
      "rotation": 7
    },
    {
      "x": -8,
      "y": 9,
      "z": -7,
      "name": "Nat20_Force_Empty"
    },
    {
      "x": -8,
      "y": 10,
      "z": -7,
      "name": "Nat20_Force_Empty"
    },
    {
      "x": -8,
      "y": 11,
      "z": -7,
      "name": "Nat20_Force_Empty"
    },
    {
      "x": -8,
      "y": 12,
      "z": -7,
      "name": "Nat20_Force_Empty"
    },
    {
      "x": -8,
      "y": 13,
      "z": -7,
      "name": "Nat20_Force_Empty"
    },
    {
      "x": -8,
      "y": 14,
      "z": -7,
      "name": "Nat20_Force_Empty"
    },
    {
      "x": -8,
      "y": 15,
      "z": -7,
      "name": "Nat20_Force_Empty"
    },
    {
      "x": -8,
      "y": 16,
      "z": -7,
      "name": "Nat20_Force_Empty"
    },
    {
      "x": -8,
      "y": 17,
      "z": -7,
      "name": "Nat20_Force_Empty"
    },
    {
      "x": -8,
      "y": 18,
      "z": -7,
      "name": "Nat20_Force_Empty"
    },
    {
      "x": -8,
      "y": 19,
      "z": -7,
      "name": "Nat20_Force_Empty"
    },
    {
      "x": -8,
      "y": 1,
      "z": -6,
      "name": "Nat20_Force_Empty"
    },
    {
      "x": -8,
      "y": 2,
      "z": -6,
      "name": "Nat20_Force_Empty"
    },
    {
      "x": -8,
      "y": 3,
      "z": -6,
      "name": "Nat20_Force_Empty"
    },
    {
      "x": -8,
      "y": 4,
      "z": -6,
      "name": "Nat20_Force_Empty"
    },
    {
      "x": -8,
      "y": 5,
      "z": -6,
      "name": "Nat20_Force_Empty"
    },
    {
      "x": -8,
      "y": 6,
      "z": -6,
      "name": "Nat20_Force_Empty"
    },
    {
      "x": -8,
      "y": 7,
      "z": -6,
      "name": "Nat20_Force_Empty"
    },
    {
      "x": -8,
      "y": 8,
      "z": -6,
      "name": "Wood_Drywood_Planks"
    },
    {
      "x": -8,
      "y": 9,
      "z": -6,
      "name": "Nat20_Force_Empty"
    },
    {
      "x": -8,
      "y": 10,
      "z": -6,
      "name": "Nat20_Force_Empty"
    },
    {
      "x": -8,
      "y": 11,
      "z": -6,
      "name": "Nat20_Force_Empty"
    },
    {
      "x": -8,
      "y": 12,
      "z": -6,
      "name": "Nat20_Force_Empty"
    },
    {
      "x": -8,
      "y": 13,
      "z": -6,
      "name": "Nat20_Force_Empty"
    },
    {
      "x": -8,
      "y": 14,
      "z": -6,
      "name": "Nat20_Force_Empty"
    },
    {
      "x": -8,
      "y": 15,
      "z": -6,
      "name": "Nat20_Force_Empty"
    },
    {
      "x": -8,
      "y": 16,
      "z": -6,
      "name": "Nat20_Force_Empty"
    },
    {
      "x": -8,
      "y": 17,
      "z": -6,
      "name": "Nat20_Force_Empty"
    },
    {
      "x": -8,
      "y": 18,
      "z": -6,
      "name": "Nat20_Force_Empty"
    },
    {
      "x": -8,
      "y": 19,
      "z": -6,
      "name": "Nat20_Force_Empty"
    },
    {
      "x": -8,
      "y": 0,
      "z": -5,
      "name": "Soil_Clay"
    },
    {
      "x": -8,
      "y": 1,
      "z": -5,
      "name": "Soil_Clay"
    },
    {
      "x": -8,
      "y": 2,
      "z": -5,
      "name": "Soil_Clay"
    },
    {
      "x": -8,
      "y": 3,
      "z": -5,
      "name": "Soil_Clay"
    },
    {
      "x": -8,
      "y": 4,
      "z": -5,
      "name": "Rock_Sandstone_Cobble"
    },
    {
      "x": -8,
      "y": 5,
      "z": -5,
      "name": "Rock_Sandstone_Cobble"
    },
    {
      "x": -8,
      "y": 6,
      "z": -5,
      "name": "Rock_Sandstone_Cobble"
    },
    {
      "x": -8,
      "y": 7,
      "z": -5,
      "name": "Rock_Sandstone_Cobble"
    },
    {
      "x": -8,
      "y": 8,
      "z": -5,
      "name": "Wood_Drywood_Planks"
    },
    {
      "x": -8,
      "y": 9,
      "z": -5,
      "name": "Deco_Rope_Diagonal",
      "rotation": 2
    },
    {
      "x": -8,
      "y": 10,
      "z": -5,
      "name": "Nat20_Force_Empty"
    },
    {
      "x": -8,
      "y": 11,
      "z": -5,
      "name": "Nat20_Force_Empty"
    },
    {
      "x": -8,
      "y": 12,
      "z": -5,
      "name": "Nat20_Force_Empty"
    },
    {
      "x": -8,
      "y": 13,
      "z": -5,
      "name": "Nat20_Force_Empty"
    },
    {
      "x": -8,
      "y": 14,
      "z": -5,
      "name": "Nat20_Force_Empty"
    },
    {
      "x": -8,
      "y": 15,
      "z": -5,
      "name": "Nat20_Force_Empty"
    },
    {
      "x": -8,
      "y": 16,
      "z": -5,
      "name": "Nat20_Force_Empty"
    },
    {
      "x": -8,
      "y": 17,
      "z": -5,
      "name": "Nat20_Force_Empty"
    },
    {
      "x": -8,
      "y": 18,
      "z": -5,
      "name": "Nat20_Force_Empty"
    },
    {
      "x": -8,
      "y": 19,
      "z": -5,
      "name": "Nat20_Force_Empty"
    },
    {
      "x": -8,
      "y": 0,
      "z": -4,
      "name": "Soil_Clay"
    },
    {
      "x": -8,
      "y": 1,
      "z": -4,
      "name": "Soil_Clay"
    },
    {
      "x": -8,
      "y": 2,
      "z": -4,
      "name": "Soil_Clay"
    },
    {
      "x": -8,
      "y": 3,
      "z": -4,
      "name": "Soil_Clay"
    },
    {
      "x": -8,
      "y": 4,
      "z": -4,
      "name": "Soil_Clay"
    },
    {
      "x": -8,
      "y": 5,
      "z": -4,
      "name": "Rock_Sandstone_Cobble"
    },
    {
      "x": -8,
      "y": 6,
      "z": -4,
      "name": "Rock_Sandstone_Cobble"
    },
    {
      "x": -8,
      "y": 7,
      "z": -4,
      "name": "Wood_Dry_Branch_Long"
    },
    {
      "x": -8,
      "y": 8,
      "z": -4,
      "name": "Wood_Drywood_Planks"
    },
    {
      "x": -8,
      "y": 9,
      "z": -4,
      "name": "*Cloth_Roof_Hide_State_Definitions_Corner_Right",
      "rotation": 3
    },
    {
      "x": -8,
      "y": 10,
      "z": -4,
      "name": "Deco_Rope_Diagonal",
      "rotation": 2
    },
    {
      "x": -8,
      "y": 11,
      "z": -4,
      "name": "Nat20_Force_Empty"
    },
    {
      "x": -8,
      "y": 12,
      "z": -4,
      "name": "Nat20_Force_Empty"
    },
    {
      "x": -8,
      "y": 13,
      "z": -4,
      "name": "Nat20_Force_Empty"
    },
    {
      "x": -8,
      "y": 14,
      "z": -4,
      "name": "Nat20_Force_Empty"
    },
    {
      "x": -8,
      "y": 15,
      "z": -4,
      "name": "Nat20_Force_Empty"
    },
    {
      "x": -8,
      "y": 16,
      "z": -4,
      "name": "Nat20_Force_Empty"
    },
    {
      "x": -8,
      "y": 17,
      "z": -4,
      "name": "Nat20_Force_Empty"
    },
    {
      "x": -8,
      "y": 18,
      "z": -4,
      "name": "Nat20_Force_Empty"
    },
    {
      "x": -8,
      "y": 19,
      "z": -4,
      "name": "Nat20_Force_Empty"
    },
    {
      "x": -8,
      "y": 0,
      "z": -3,
      "name": "Soil_Clay"
    },
    {
      "x": -8,
      "y": 1,
      "z": -3,
      "name": "Soil_Clay"
    },
    {
      "x": -8,
      "y": 2,
      "z": -3,
      "name": "Soil_Clay"
    },
    {
      "x": -8,
      "y": 3,
      "z": -3,
      "name": "Soil_Clay"
    },
    {
      "x": -8,
      "y": 4,
      "z": -3,
      "name": "Soil_Clay"
    },
    {
      "x": -8,
      "y": 5,
      "z": -3,
      "name": "Soil_Clay"
    },
    {
      "x": -8,
      "y": 6,
      "z": -3,
      "name": "Rock_Sandstone_Cobble"
    },
    {
      "x": -8,
      "y": 7,
      "z": -3,
      "name": "Rock_Sandstone_Cobble"
    },
    {
      "x": -8,
      "y": 8,
      "z": -3,
      "name": "Wood_Drywood_Planks"
    },
    {
      "x": -8,
      "y": 9,
      "z": -3,
      "name": "Cloth_Roof_Hide",
      "rotation": 3
    },
    {
      "x": -8,
      "y": 10,
      "z": -3,
      "name": "Nat20_Force_Empty"
    },
    {
      "x": -8,
      "y": 11,
      "z": -3,
      "name": "Deco_Rope_Diagonal",
      "rotation": 2
    },
    {
      "x": -8,
      "y": 12,
      "z": -3,
      "name": "Nat20_Force_Empty"
    },
    {
      "x": -8,
      "y": 13,
      "z": -3,
      "name": "Nat20_Force_Empty"
    },
    {
      "x": -8,
      "y": 14,
      "z": -3,
      "name": "Nat20_Force_Empty"
    },
    {
      "x": -8,
      "y": 15,
      "z": -3,
      "name": "Nat20_Force_Empty"
    },
    {
      "x": -8,
      "y": 16,
      "z": -3,
      "name": "Nat20_Force_Empty"
    },
    {
      "x": -8,
      "y": 17,
      "z": -3,
      "name": "Nat20_Force_Empty"
    },
    {
      "x": -8,
      "y": 18,
      "z": -3,
      "name": "Nat20_Force_Empty"
    },
    {
      "x": -8,
      "y": 19,
      "z": -3,
      "name": "Nat20_Force_Empty"
    },
    {
      "x": -8,
      "y": 0,
      "z": -2,
      "name": "Soil_Dirt_Dry"
    },
    {
      "x": -8,
      "y": 1,
      "z": -2,
      "name": "Soil_Dirt_Dry"
    },
    {
      "x": -8,
      "y": 2,
      "z": -2,
      "name": "Soil_Dirt_Dry"
    },
    {
      "x": -8,
      "y": 3,
      "z": -2,
      "name": "Wood_Drywood_Planks"
    },
    {
      "x": -8,
      "y": 4,
      "z": -2,
      "name": "Nat20_Force_Empty"
    },
    {
      "x": -8,
      "y": 5,
      "z": -2,
      "name": "Nat20_Force_Empty"
    },
    {
      "x": -8,
      "y": 6,
      "z": -2,
      "name": "Nat20_Force_Empty"
    },
    {
      "x": -8,
      "y": 7,
      "z": -2,
      "name": "Nat20_Force_Empty"
    },
    {
      "x": -8,
      "y": 8,
      "z": -2,
      "name": "Wood_Drywood_Planks_Half",
      "rotation": 5
    },
    {
      "x": -8,
      "y": 9,
      "z": -2,
      "name": "*Cloth_Roof_Hide_State_Definitions_Corner_Right",
      "rotation": 10
    },
    {
      "x": -8,
      "y": 10,
      "z": -2,
      "name": "Nat20_Force_Empty"
    },
    {
      "x": -8,
      "y": 11,
      "z": -2,
      "name": "Nat20_Force_Empty"
    },
    {
      "x": -8,
      "y": 12,
      "z": -2,
      "name": "Deco_Rope_Diagonal",
      "rotation": 2
    },
    {
      "x": -8,
      "y": 13,
      "z": -2,
      "name": "Nat20_Force_Empty"
    },
    {
      "x": -8,
      "y": 14,
      "z": -2,
      "name": "Nat20_Force_Empty"
    },
    {
      "x": -8,
      "y": 15,
      "z": -2,
      "name": "Nat20_Force_Empty"
    },
    {
      "x": -8,
      "y": 16,
      "z": -2,
      "name": "Nat20_Force_Empty"
    },
    {
      "x": -8,
      "y": 17,
      "z": -2,
      "name": "Nat20_Force_Empty"
    },
    {
      "x": -8,
      "y": 18,
      "z": -2,
      "name": "Nat20_Force_Empty"
    },
    {
      "x": -8,
      "y": 19,
      "z": -2,
      "name": "Nat20_Force_Empty"
    },
    {
      "x": -8,
      "y": 0,
      "z": -1,
      "name": "Soil_Dirt_Dry"
    },
    {
      "x": -8,
      "y": 1,
      "z": -1,
      "name": "Soil_Dirt_Dry"
    },
    {
      "x": -8,
      "y": 2,
      "z": -1,
      "name": "Soil_Dirt_Dry"
    },
    {
      "x": -8,
      "y": 3,
      "z": -1,
      "name": "Wood_Drywood_Planks"
    },
    {
      "x": -8,
      "y": 4,
      "z": -1,
      "name": "Nat20_Force_Empty"
    },
    {
      "x": -8,
      "y": 5,
      "z": -1,
      "name": "Nat20_Force_Empty"
    },
    {
      "x": -8,
      "y": 6,
      "z": -1,
      "name": "Nat20_Force_Empty"
    },
    {
      "x": -8,
      "y": 7,
      "z": -1,
      "name": "Nat20_Force_Empty"
    },
    {
      "x": -8,
      "y": 8,
      "z": -1,
      "name": "Wood_Drywood_Planks_Half",
      "rotation": 5
    },
    {
      "x": -8,
      "y": 9,
      "z": -1,
      "name": "Cloth_Roof_Hide_Flat",
      "rotation": 8
    },
    {
      "x": -8,
      "y": 10,
      "z": -1,
      "name": "Nat20_Force_Empty"
    },
    {
      "x": -8,
      "y": 11,
      "z": -1,
      "name": "Nat20_Force_Empty"
    },
    {
      "x": -8,
      "y": 12,
      "z": -1,
      "name": "Deco_Rope_Diagonal"
    },
    {
      "x": -8,
      "y": 13,
      "z": -1,
      "name": "Deco_Rope_Diagonal",
      "rotation": 2
    },
    {
      "x": -8,
      "y": 14,
      "z": -1,
      "name": "Nat20_Force_Empty"
    },
    {
      "x": -8,
      "y": 15,
      "z": -1,
      "name": "Nat20_Force_Empty"
    },
    {
      "x": -8,
      "y": 16,
      "z": -1,
      "name": "Nat20_Force_Empty"
    },
    {
      "x": -8,
      "y": 17,
      "z": -1,
      "name": "Nat20_Force_Empty"
    },
    {
      "x": -8,
      "y": 18,
      "z": -1,
      "name": "Nat20_Force_Empty"
    },
    {
      "x": -8,
      "y": 19,
      "z": -1,
      "name": "Nat20_Force_Empty"
    },
    {
      "x": -8,
      "y": 0,
      "z": 0,
      "name": "Soil_Dirt_Dry"
    },
    {
      "x": -8,
      "y": 1,
      "z": 0,
      "name": "Soil_Dirt_Dry"
    },
    {
      "x": -8,
      "y": 2,
      "z": 0,
      "name": "Soil_Dirt_Dry"
    },
    {
      "x": -8,
      "y": 3,
      "z": 0,
      "name": "Wood_Drywood_Planks"
    },
    {
      "x": -8,
      "y": 4,
      "z": 0,
      "name": "Nat20_Force_Empty"
    },
    {
      "x": -8,
      "y": 5,
      "z": 0,
      "name": "Nat20_Force_Empty"
    },
    {
      "x": -8,
      "y": 6,
      "z": 0,
      "name": "Nat20_Force_Empty"
    },
    {
      "x": -8,
      "y": 7,
      "z": 0,
      "name": "Nat20_Force_Empty"
    },
    {
      "x": -8,
      "y": 8,
      "z": 0,
      "name": "Wood_Drywood_Planks_Half",
      "rotation": 5
    },
    {
      "x": -8,
      "y": 9,
      "z": 0,
      "name": "*Cloth_Roof_Hide_State_Definitions_Corner_Right",
      "rotation": 11
    },
    {
      "x": -8,
      "y": 10,
      "z": 0,
      "name": "Nat20_Force_Empty"
    },
    {
      "x": -8,
      "y": 11,
      "z": 0,
      "name": "Deco_Rope_Diagonal"
    },
    {
      "x": -8,
      "y": 12,
      "z": 0,
      "name": "Nat20_Force_Empty"
    },
    {
      "x": -8,
      "y": 13,
      "z": 0,
      "name": "Nat20_Force_Empty"
    },
    {
      "x": -8,
      "y": 14,
      "z": 0,
      "name": "Deco_Rope_Diagonal",
      "rotation": 2
    },
    {
      "x": -8,
      "y": 15,
      "z": 0,
      "name": "Nat20_Force_Empty"
    },
    {
      "x": -8,
      "y": 16,
      "z": 0,
      "name": "Nat20_Force_Empty"
    },
    {
      "x": -8,
      "y": 17,
      "z": 0,
      "name": "Nat20_Force_Empty"
    },
    {
      "x": -8,
      "y": 18,
      "z": 0,
      "name": "Nat20_Force_Empty"
    },
    {
      "x": -8,
      "y": 19,
      "z": 0,
      "name": "Nat20_Force_Empty"
    },
    {
      "x": -8,
      "y": 0,
      "z": 1,
      "name": "Soil_Clay"
    },
    {
      "x": -8,
      "y": 1,
      "z": 1,
      "name": "Soil_Clay"
    },
    {
      "x": -8,
      "y": 2,
      "z": 1,
      "name": "Wood_Dry_Trunk"
    },
    {
      "x": -8,
      "y": 3,
      "z": 1,
      "name": "Wood_Dry_Trunk"
    },
    {
      "x": -8,
      "y": 4,
      "z": 1,
      "name": "Wood_Dry_Trunk"
    },
    {
      "x": -8,
      "y": 5,
      "z": 1,
      "name": "Wood_Dry_Trunk"
    },
    {
      "x": -8,
      "y": 6,
      "z": 1,
      "name": "Wood_Dry_Trunk"
    },
    {
      "x": -8,
      "y": 7,
      "z": 1,
      "name": "Wood_Dry_Trunk"
    },
    {
      "x": -8,
      "y": 8,
      "z": 1,
      "name": "Wood_Dry_Trunk"
    },
    {
      "x": -8,
      "y": 9,
      "z": 1,
      "name": "Wood_Dry_Trunk"
    },
    {
      "x": -8,
      "y": 10,
      "z": 1,
      "name": "Wood_Dry_Trunk"
    },
    {
      "x": -8,
      "y": 11,
      "z": 1,
      "name": "Wood_Dry_Trunk"
    },
    {
      "x": -8,
      "y": 12,
      "z": 1,
      "name": "Wood_Dry_Trunk"
    },
    {
      "x": -8,
      "y": 13,
      "z": 1,
      "name": "Wood_Dry_Trunk"
    },
    {
      "x": -8,
      "y": 14,
      "z": 1,
      "name": "Wood_Dry_Trunk"
    },
    {
      "x": -8,
      "y": 15,
      "z": 1,
      "name": "Wood_Dry_Trunk"
    },
    {
      "x": -8,
      "y": 16,
      "z": 1,
      "name": "Wood_Dry_Trunk"
    },
    {
      "x": -8,
      "y": 17,
      "z": 1,
      "name": "Wood_Dry_Trunk"
    },
    {
      "x": -8,
      "y": 18,
      "z": 1,
      "name": "Wood_Dry_Branch_Long"
    },
    {
      "x": -8,
      "y": 19,
      "z": 1,
      "name": "Wood_Dry_Branch_Long"
    },
    {
      "x": -8,
      "y": 0,
      "z": 2,
      "name": "Soil_Clay"
    },
    {
      "x": -8,
      "y": 1,
      "z": 2,
      "name": "Soil_Clay"
    },
    {
      "x": -8,
      "y": 2,
      "z": 2,
      "name": "Soil_Clay"
    },
    {
      "x": -8,
      "y": 3,
      "z": 2,
      "name": "Soil_Clay"
    },
    {
      "x": -8,
      "y": 4,
      "z": 2,
      "name": "Soil_Clay"
    },
    {
      "x": -8,
      "y": 5,
      "z": 2,
      "name": "Rock_Sandstone_Cobble"
    },
    {
      "x": -8,
      "y": 6,
      "z": 2,
      "name": "Rock_Sandstone_Cobble"
    },
    {
      "x": -8,
      "y": 7,
      "z": 2,
      "name": "Wood_Dry_Branch_Long"
    },
    {
      "x": -8,
      "y": 8,
      "z": 2,
      "name": "Wood_Drywood_Planks"
    },
    {
      "x": -8,
      "y": 9,
      "z": 2,
      "name": "*Cloth_Roof_Hide_State_Definitions_Corner_Right"
    },
    {
      "x": -8,
      "y": 10,
      "z": 2,
      "name": "Deco_Rope_Diagonal"
    },
    {
      "x": -8,
      "y": 11,
      "z": 2,
      "name": "Nat20_Force_Empty"
    },
    {
      "x": -8,
      "y": 12,
      "z": 2,
      "name": "Nat20_Force_Empty"
    },
    {
      "x": -8,
      "y": 13,
      "z": 2,
      "name": "Wood_Dry_Branch_Long",
      "rotation": 4
    },
    {
      "x": -8,
      "y": 14,
      "z": 2,
      "name": "Nat20_Force_Empty"
    },
    {
      "x": -8,
      "y": 15,
      "z": 2,
      "name": "Nat20_Force_Empty"
    },
    {
      "x": -8,
      "y": 16,
      "z": 2,
      "name": "Nat20_Force_Empty"
    },
    {
      "x": -8,
      "y": 17,
      "z": 2,
      "name": "Nat20_Force_Empty"
    },
    {
      "x": -8,
      "y": 18,
      "z": 2,
      "name": "Nat20_Force_Empty"
    },
    {
      "x": -8,
      "y": 19,
      "z": 2,
      "name": "Nat20_Force_Empty"
    },
    {
      "x": -8,
      "y": 0,
      "z": 3,
      "name": "Soil_Clay"
    },
    {
      "x": -8,
      "y": 1,
      "z": 3,
      "name": "Soil_Clay"
    },
    {
      "x": -8,
      "y": 2,
      "z": 3,
      "name": "Soil_Clay"
    },
    {
      "x": -8,
      "y": 3,
      "z": 3,
      "name": "Soil_Clay"
    },
    {
      "x": -8,
      "y": 4,
      "z": 3,
      "name": "Soil_Clay"
    },
    {
      "x": -8,
      "y": 5,
      "z": 3,
      "name": "Rock_Sandstone_Cobble"
    },
    {
      "x": -8,
      "y": 6,
      "z": 3,
      "name": "Rock_Sandstone_Cobble"
    },
    {
      "x": -8,
      "y": 7,
      "z": 3,
      "name": "Rock_Sandstone_Cobble"
    },
    {
      "x": -8,
      "y": 8,
      "z": 3,
      "name": "Wood_Drywood_Planks"
    },
    {
      "x": -8,
      "y": 9,
      "z": 3,
      "name": "Deco_Rope_Diagonal"
    },
    {
      "x": -8,
      "y": 10,
      "z": 3,
      "name": "Nat20_Force_Empty"
    },
    {
      "x": -8,
      "y": 11,
      "z": 3,
      "name": "Nat20_Force_Empty"
    },
    {
      "x": -8,
      "y": 12,
      "z": 3,
      "name": "Nat20_Force_Empty"
    },
    {
      "x": -8,
      "y": 13,
      "z": 3,
      "name": "Nat20_Force_Empty"
    },
    {
      "x": -8,
      "y": 14,
      "z": 3,
      "name": "Nat20_Force_Empty"
    },
    {
      "x": -8,
      "y": 15,
      "z": 3,
      "name": "Nat20_Force_Empty"
    },
    {
      "x": -8,
      "y": 16,
      "z": 3,
      "name": "Nat20_Force_Empty"
    },
    {
      "x": -8,
      "y": 17,
      "z": 3,
      "name": "Nat20_Force_Empty"
    },
    {
      "x": -8,
      "y": 18,
      "z": 3,
      "name": "Nat20_Force_Empty"
    },
    {
      "x": -8,
      "y": 19,
      "z": 3,
      "name": "Nat20_Force_Empty"
    },
    {
      "x": -8,
      "y": 1,
      "z": 4,
      "name": "Nat20_Force_Empty"
    },
    {
      "x": -8,
      "y": 2,
      "z": 4,
      "name": "Nat20_Force_Empty"
    },
    {
      "x": -8,
      "y": 3,
      "z": 4,
      "name": "Nat20_Force_Empty"
    },
    {
      "x": -8,
      "y": 4,
      "z": 4,
      "name": "Nat20_Force_Empty"
    },
    {
      "x": -8,
      "y": 5,
      "z": 4,
      "name": "Nat20_Force_Empty"
    },
    {
      "x": -8,
      "y": 6,
      "z": 4,
      "name": "Nat20_Force_Empty"
    },
    {
      "x": -8,
      "y": 7,
      "z": 4,
      "name": "Nat20_Force_Empty"
    },
    {
      "x": -8,
      "y": 8,
      "z": 4,
      "name": "Wood_Drywood_Planks"
    },
    {
      "x": -8,
      "y": 9,
      "z": 4,
      "name": "Nat20_Force_Empty"
    },
    {
      "x": -8,
      "y": 10,
      "z": 4,
      "name": "Nat20_Force_Empty"
    },
    {
      "x": -8,
      "y": 11,
      "z": 4,
      "name": "Nat20_Force_Empty"
    },
    {
      "x": -8,
      "y": 12,
      "z": 4,
      "name": "Nat20_Force_Empty"
    },
    {
      "x": -8,
      "y": 13,
      "z": 4,
      "name": "Nat20_Force_Empty"
    },
    {
      "x": -8,
      "y": 14,
      "z": 4,
      "name": "Nat20_Force_Empty"
    },
    {
      "x": -8,
      "y": 15,
      "z": 4,
      "name": "Nat20_Force_Empty"
    },
    {
      "x": -8,
      "y": 16,
      "z": 4,
      "name": "Nat20_Force_Empty"
    },
    {
      "x": -8,
      "y": 17,
      "z": 4,
      "name": "Nat20_Force_Empty"
    },
    {
      "x": -8,
      "y": 18,
      "z": 4,
      "name": "Nat20_Force_Empty"
    },
    {
      "x": -8,
      "y": 19,
      "z": 4,
      "name": "Nat20_Force_Empty"
    },
    {
      "x": -8,
      "y": 1,
      "z": 5,
      "name": "Nat20_Force_Empty"
    },
    {
      "x": -8,
      "y": 2,
      "z": 5,
      "name": "Nat20_Force_Empty"
    },
    {
      "x": -8,
      "y": 3,
      "z": 5,
      "name": "Nat20_Force_Empty"
    },
    {
      "x": -8,
      "y": 4,
      "z": 5,
      "name": "Nat20_Force_Empty"
    },
    {
      "x": -8,
      "y": 5,
      "z": 5,
      "name": "Nat20_Force_Empty"
    },
    {
      "x": -8,
      "y": 6,
      "z": 5,
      "name": "Nat20_Force_Empty"
    },
    {
      "x": -8,
      "y": 7,
      "z": 5,
      "name": "Nat20_Force_Empty"
    },
    {
      "x": -8,
      "y": 8,
      "z": 5,
      "name": "Wood_Drywood_Planks_Half",
      "rotation": 7
    },
    {
      "x": -8,
      "y": 9,
      "z": 5,
      "name": "Nat20_Force_Empty"
    },
    {
      "x": -8,
      "y": 10,
      "z": 5,
      "name": "Nat20_Force_Empty"
    },
    {
      "x": -8,
      "y": 11,
      "z": 5,
      "name": "Nat20_Force_Empty"
    },
    {
      "x": -8,
      "y": 12,
      "z": 5,
      "name": "Nat20_Force_Empty"
    },
    {
      "x": -8,
      "y": 13,
      "z": 5,
      "name": "Nat20_Force_Empty"
    },
    {
      "x": -8,
      "y": 14,
      "z": 5,
      "name": "Nat20_Force_Empty"
    },
    {
      "x": -8,
      "y": 15,
      "z": 5,
      "name": "Nat20_Force_Empty"
    },
    {
      "x": -8,
      "y": 16,
      "z": 5,
      "name": "Nat20_Force_Empty"
    },
    {
      "x": -8,
      "y": 17,
      "z": 5,
      "name": "Nat20_Force_Empty"
    },
    {
      "x": -8,
      "y": 18,
      "z": 5,
      "name": "Nat20_Force_Empty"
    },
    {
      "x": -8,
      "y": 19,
      "z": 5,
      "name": "Nat20_Force_Empty"
    },
    {
      "x": -8,
      "y": 1,
      "z": 6,
      "name": "Nat20_Force_Empty"
    },
    {
      "x": -8,
      "y": 2,
      "z": 6,
      "name": "Nat20_Force_Empty"
    },
    {
      "x": -8,
      "y": 3,
      "z": 6,
      "name": "Nat20_Force_Empty"
    },
    {
      "x": -8,
      "y": 4,
      "z": 6,
      "name": "Nat20_Force_Empty"
    },
    {
      "x": -8,
      "y": 5,
      "z": 6,
      "name": "Nat20_Force_Empty"
    },
    {
      "x": -8,
      "y": 6,
      "z": 6,
      "name": "Nat20_Force_Empty"
    },
    {
      "x": -8,
      "y": 7,
      "z": 6,
      "name": "Nat20_Force_Empty"
    },
    {
      "x": -8,
      "y": 8,
      "z": 6,
      "name": "Nat20_Force_Empty"
    },
    {
      "x": -8,
      "y": 9,
      "z": 6,
      "name": "Nat20_Force_Empty"
    },
    {
      "x": -8,
      "y": 10,
      "z": 6,
      "name": "Nat20_Force_Empty"
    },
    {
      "x": -8,
      "y": 11,
      "z": 6,
      "name": "Nat20_Force_Empty"
    },
    {
      "x": -8,
      "y": 12,
      "z": 6,
      "name": "Nat20_Force_Empty"
    },
    {
      "x": -8,
      "y": 13,
      "z": 6,
      "name": "Nat20_Force_Empty"
    },
    {
      "x": -8,
      "y": 14,
      "z": 6,
      "name": "Nat20_Force_Empty"
    },
    {
      "x": -8,
      "y": 15,
      "z": 6,
      "name": "Nat20_Force_Empty"
    },
    {
      "x": -8,
      "y": 16,
      "z": 6,
      "name": "Nat20_Force_Empty"
    },
    {
      "x": -8,
      "y": 17,
      "z": 6,
      "name": "Nat20_Force_Empty"
    },
    {
      "x": -8,
      "y": 18,
      "z": 6,
      "name": "Nat20_Force_Empty"
    },
    {
      "x": -8,
      "y": 19,
      "z": 6,
      "name": "Nat20_Force_Empty"
    },
    {
      "x": -8,
      "y": 1,
      "z": 7,
      "name": "Nat20_Force_Empty"
    },
    {
      "x": -8,
      "y": 2,
      "z": 7,
      "name": "Nat20_Force_Empty"
    },
    {
      "x": -8,
      "y": 3,
      "z": 7,
      "name": "Nat20_Force_Empty"
    },
    {
      "x": -8,
      "y": 4,
      "z": 7,
      "name": "Nat20_Force_Empty"
    },
    {
      "x": -8,
      "y": 5,
      "z": 7,
      "name": "Nat20_Force_Empty"
    },
    {
      "x": -8,
      "y": 6,
      "z": 7,
      "name": "Nat20_Force_Empty"
    },
    {
      "x": -8,
      "y": 7,
      "z": 7,
      "name": "Nat20_Force_Empty"
    },
    {
      "x": -8,
      "y": 8,
      "z": 7,
      "name": "Nat20_Force_Empty"
    },
    {
      "x": -8,
      "y": 9,
      "z": 7,
      "name": "Nat20_Force_Empty"
    },
    {
      "x": -8,
      "y": 10,
      "z": 7,
      "name": "Nat20_Force_Empty"
    },
    {
      "x": -8,
      "y": 11,
      "z": 7,
      "name": "Nat20_Force_Empty"
    },
    {
      "x": -8,
      "y": 12,
      "z": 7,
      "name": "Nat20_Force_Empty"
    },
    {
      "x": -8,
      "y": 13,
      "z": 7,
      "name": "Nat20_Force_Empty"
    },
    {
      "x": -8,
      "y": 14,
      "z": 7,
      "name": "Nat20_Force_Empty"
    },
    {
      "x": -8,
      "y": 15,
      "z": 7,
      "name": "Nat20_Force_Empty"
    },
    {
      "x": -8,
      "y": 16,
      "z": 7,
      "name": "Nat20_Force_Empty"
    },
    {
      "x": -8,
      "y": 17,
      "z": 7,
      "name": "Nat20_Force_Empty"
    },
    {
      "x": -8,
      "y": 18,
      "z": 7,
      "name": "Nat20_Force_Empty"
    },
    {
      "x": -8,
      "y": 19,
      "z": 7,
      "name": "Nat20_Force_Empty"
    },
    {
      "x": -8,
      "y": 1,
      "z": 8,
      "name": "Nat20_Force_Empty"
    },
    {
      "x": -8,
      "y": 2,
      "z": 8,
      "name": "Nat20_Force_Empty"
    },
    {
      "x": -8,
      "y": 3,
      "z": 8,
      "name": "Nat20_Force_Empty"
    },
    {
      "x": -8,
      "y": 4,
      "z": 8,
      "name": "Nat20_Force_Empty"
    },
    {
      "x": -8,
      "y": 5,
      "z": 8,
      "name": "Nat20_Force_Empty"
    },
    {
      "x": -8,
      "y": 6,
      "z": 8,
      "name": "Nat20_Force_Empty"
    },
    {
      "x": -8,
      "y": 7,
      "z": 8,
      "name": "Nat20_Force_Empty"
    },
    {
      "x": -8,
      "y": 8,
      "z": 8,
      "name": "Nat20_Force_Empty"
    },
    {
      "x": -8,
      "y": 9,
      "z": 8,
      "name": "Nat20_Force_Empty"
    },
    {
      "x": -8,
      "y": 10,
      "z": 8,
      "name": "Nat20_Force_Empty"
    },
    {
      "x": -8,
      "y": 11,
      "z": 8,
      "name": "Nat20_Force_Empty"
    },
    {
      "x": -8,
      "y": 12,
      "z": 8,
      "name": "Nat20_Force_Empty"
    },
    {
      "x": -8,
      "y": 13,
      "z": 8,
      "name": "Nat20_Force_Empty"
    },
    {
      "x": -8,
      "y": 14,
      "z": 8,
      "name": "Nat20_Force_Empty"
    },
    {
      "x": -8,
      "y": 15,
      "z": 8,
      "name": "Nat20_Force_Empty"
    },
    {
      "x": -8,
      "y": 16,
      "z": 8,
      "name": "Nat20_Force_Empty"
    },
    {
      "x": -8,
      "y": 17,
      "z": 8,
      "name": "Nat20_Force_Empty"
    },
    {
      "x": -8,
      "y": 18,
      "z": 8,
      "name": "Nat20_Force_Empty"
    },
    {
      "x": -8,
      "y": 19,
      "z": 8,
      "name": "Nat20_Force_Empty"
    },
    {
      "x": -8,
      "y": 1,
      "z": 9,
      "name": "Nat20_Force_Empty"
    },
    {
      "x": -8,
      "y": 2,
      "z": 9,
      "name": "Nat20_Force_Empty"
    },
    {
      "x": -8,
      "y": 3,
      "z": 9,
      "name": "Nat20_Force_Empty"
    },
    {
      "x": -8,
      "y": 4,
      "z": 9,
      "name": "Nat20_Force_Empty"
    },
    {
      "x": -8,
      "y": 5,
      "z": 9,
      "name": "Nat20_Force_Empty"
    },
    {
      "x": -8,
      "y": 6,
      "z": 9,
      "name": "Nat20_Force_Empty"
    },
    {
      "x": -8,
      "y": 7,
      "z": 9,
      "name": "Nat20_Force_Empty"
    },
    {
      "x": -8,
      "y": 8,
      "z": 9,
      "name": "Nat20_Force_Empty"
    },
    {
      "x": -8,
      "y": 9,
      "z": 9,
      "name": "Nat20_Force_Empty"
    },
    {
      "x": -8,
      "y": 10,
      "z": 9,
      "name": "Nat20_Force_Empty"
    },
    {
      "x": -8,
      "y": 11,
      "z": 9,
      "name": "Nat20_Force_Empty"
    },
    {
      "x": -8,
      "y": 12,
      "z": 9,
      "name": "Nat20_Force_Empty"
    },
    {
      "x": -8,
      "y": 13,
      "z": 9,
      "name": "Nat20_Force_Empty"
    },
    {
      "x": -8,
      "y": 14,
      "z": 9,
      "name": "Nat20_Force_Empty"
    },
    {
      "x": -8,
      "y": 15,
      "z": 9,
      "name": "Nat20_Force_Empty"
    },
    {
      "x": -8,
      "y": 16,
      "z": 9,
      "name": "Nat20_Force_Empty"
    },
    {
      "x": -8,
      "y": 17,
      "z": 9,
      "name": "Nat20_Force_Empty"
    },
    {
      "x": -8,
      "y": 18,
      "z": 9,
      "name": "Nat20_Force_Empty"
    },
    {
      "x": -8,
      "y": 19,
      "z": 9,
      "name": "Nat20_Force_Empty"
    },
    {
      "x": -8,
      "y": 1,
      "z": 10,
      "name": "Nat20_Force_Empty"
    },
    {
      "x": -8,
      "y": 2,
      "z": 10,
      "name": "Nat20_Force_Empty"
    },
    {
      "x": -8,
      "y": 3,
      "z": 10,
      "name": "Nat20_Force_Empty"
    },
    {
      "x": -8,
      "y": 4,
      "z": 10,
      "name": "Nat20_Force_Empty"
    },
    {
      "x": -8,
      "y": 5,
      "z": 10,
      "name": "Nat20_Force_Empty"
    },
    {
      "x": -8,
      "y": 6,
      "z": 10,
      "name": "Nat20_Force_Empty"
    },
    {
      "x": -8,
      "y": 7,
      "z": 10,
      "name": "Nat20_Force_Empty"
    },
    {
      "x": -8,
      "y": 8,
      "z": 10,
      "name": "Nat20_Force_Empty"
    },
    {
      "x": -8,
      "y": 9,
      "z": 10,
      "name": "Nat20_Force_Empty"
    },
    {
      "x": -8,
      "y": 10,
      "z": 10,
      "name": "Nat20_Force_Empty"
    },
    {
      "x": -8,
      "y": 11,
      "z": 10,
      "name": "Nat20_Force_Empty"
    },
    {
      "x": -8,
      "y": 12,
      "z": 10,
      "name": "Nat20_Force_Empty"
    },
    {
      "x": -8,
      "y": 13,
      "z": 10,
      "name": "Nat20_Force_Empty"
    },
    {
      "x": -8,
      "y": 14,
      "z": 10,
      "name": "Nat20_Force_Empty"
    },
    {
      "x": -8,
      "y": 15,
      "z": 10,
      "name": "Nat20_Force_Empty"
    },
    {
      "x": -8,
      "y": 16,
      "z": 10,
      "name": "Nat20_Force_Empty"
    },
    {
      "x": -8,
      "y": 17,
      "z": 10,
      "name": "Nat20_Force_Empty"
    },
    {
      "x": -8,
      "y": 18,
      "z": 10,
      "name": "Nat20_Force_Empty"
    },
    {
      "x": -8,
      "y": 19,
      "z": 10,
      "name": "Nat20_Force_Empty"
    },
    {
      "x": -7,
      "y": 1,
      "z": -10,
      "name": "Nat20_Force_Empty"
    },
    {
      "x": -7,
      "y": 2,
      "z": -10,
      "name": "Nat20_Force_Empty"
    },
    {
      "x": -7,
      "y": 3,
      "z": -10,
      "name": "Nat20_Force_Empty"
    },
    {
      "x": -7,
      "y": 4,
      "z": -10,
      "name": "Nat20_Force_Empty"
    },
    {
      "x": -7,
      "y": 5,
      "z": -10,
      "name": "Nat20_Force_Empty"
    },
    {
      "x": -7,
      "y": 6,
      "z": -10,
      "name": "Nat20_Force_Empty"
    },
    {
      "x": -7,
      "y": 7,
      "z": -10,
      "name": "Nat20_Force_Empty"
    },
    {
      "x": -7,
      "y": 8,
      "z": -10,
      "name": "Nat20_Force_Empty"
    },
    {
      "x": -7,
      "y": 9,
      "z": -10,
      "name": "Nat20_Force_Empty"
    },
    {
      "x": -7,
      "y": 10,
      "z": -10,
      "name": "Nat20_Force_Empty"
    },
    {
      "x": -7,
      "y": 11,
      "z": -10,
      "name": "Nat20_Force_Empty"
    },
    {
      "x": -7,
      "y": 12,
      "z": -10,
      "name": "Nat20_Force_Empty"
    },
    {
      "x": -7,
      "y": 13,
      "z": -10,
      "name": "Nat20_Force_Empty"
    },
    {
      "x": -7,
      "y": 14,
      "z": -10,
      "name": "Nat20_Force_Empty"
    },
    {
      "x": -7,
      "y": 15,
      "z": -10,
      "name": "Nat20_Force_Empty"
    },
    {
      "x": -7,
      "y": 16,
      "z": -10,
      "name": "Nat20_Force_Empty"
    },
    {
      "x": -7,
      "y": 17,
      "z": -10,
      "name": "Nat20_Force_Empty"
    },
    {
      "x": -7,
      "y": 18,
      "z": -10,
      "name": "Nat20_Force_Empty"
    },
    {
      "x": -7,
      "y": 19,
      "z": -10,
      "name": "Nat20_Force_Empty"
    },
    {
      "x": -7,
      "y": 1,
      "z": -9,
      "name": "Nat20_Force_Empty"
    },
    {
      "x": -7,
      "y": 2,
      "z": -9,
      "name": "Nat20_Force_Empty"
    },
    {
      "x": -7,
      "y": 3,
      "z": -9,
      "name": "Nat20_Force_Empty"
    },
    {
      "x": -7,
      "y": 4,
      "z": -9,
      "name": "Nat20_Force_Empty"
    },
    {
      "x": -7,
      "y": 5,
      "z": -9,
      "name": "Nat20_Force_Empty"
    },
    {
      "x": -7,
      "y": 6,
      "z": -9,
      "name": "Nat20_Force_Empty"
    },
    {
      "x": -7,
      "y": 7,
      "z": -9,
      "name": "Nat20_Force_Empty"
    },
    {
      "x": -7,
      "y": 8,
      "z": -9,
      "name": "Nat20_Force_Empty"
    },
    {
      "x": -7,
      "y": 9,
      "z": -9,
      "name": "Nat20_Force_Empty"
    },
    {
      "x": -7,
      "y": 10,
      "z": -9,
      "name": "Nat20_Force_Empty"
    },
    {
      "x": -7,
      "y": 11,
      "z": -9,
      "name": "Nat20_Force_Empty"
    },
    {
      "x": -7,
      "y": 12,
      "z": -9,
      "name": "Nat20_Force_Empty"
    },
    {
      "x": -7,
      "y": 13,
      "z": -9,
      "name": "Nat20_Force_Empty"
    },
    {
      "x": -7,
      "y": 14,
      "z": -9,
      "name": "Nat20_Force_Empty"
    },
    {
      "x": -7,
      "y": 15,
      "z": -9,
      "name": "Nat20_Force_Empty"
    },
    {
      "x": -7,
      "y": 16,
      "z": -9,
      "name": "Nat20_Force_Empty"
    },
    {
      "x": -7,
      "y": 17,
      "z": -9,
      "name": "Nat20_Force_Empty"
    },
    {
      "x": -7,
      "y": 18,
      "z": -9,
      "name": "Nat20_Force_Empty"
    },
    {
      "x": -7,
      "y": 19,
      "z": -9,
      "name": "Nat20_Force_Empty"
    },
    {
      "x": -7,
      "y": 1,
      "z": -8,
      "name": "Nat20_Force_Empty"
    },
    {
      "x": -7,
      "y": 2,
      "z": -8,
      "name": "Nat20_Force_Empty"
    },
    {
      "x": -7,
      "y": 3,
      "z": -8,
      "name": "Nat20_Force_Empty"
    },
    {
      "x": -7,
      "y": 4,
      "z": -8,
      "name": "Nat20_Force_Empty"
    },
    {
      "x": -7,
      "y": 5,
      "z": -8,
      "name": "Nat20_Force_Empty"
    },
    {
      "x": -7,
      "y": 6,
      "z": -8,
      "name": "Nat20_Force_Empty"
    },
    {
      "x": -7,
      "y": 7,
      "z": -8,
      "name": "Nat20_Force_Empty"
    },
    {
      "x": -7,
      "y": 8,
      "z": -8,
      "name": "Wood_Drywood_Planks"
    },
    {
      "x": -7,
      "y": 9,
      "z": -8,
      "name": "Nat20_Force_Empty"
    },
    {
      "x": -7,
      "y": 10,
      "z": -8,
      "name": "Nat20_Force_Empty"
    },
    {
      "x": -7,
      "y": 11,
      "z": -8,
      "name": "Nat20_Force_Empty"
    },
    {
      "x": -7,
      "y": 12,
      "z": -8,
      "name": "Nat20_Force_Empty"
    },
    {
      "x": -7,
      "y": 13,
      "z": -8,
      "name": "Nat20_Force_Empty"
    },
    {
      "x": -7,
      "y": 14,
      "z": -8,
      "name": "Nat20_Force_Empty"
    },
    {
      "x": -7,
      "y": 15,
      "z": -8,
      "name": "Nat20_Force_Empty"
    },
    {
      "x": -7,
      "y": 16,
      "z": -8,
      "name": "Nat20_Force_Empty"
    },
    {
      "x": -7,
      "y": 17,
      "z": -8,
      "name": "Nat20_Force_Empty"
    },
    {
      "x": -7,
      "y": 18,
      "z": -8,
      "name": "Nat20_Force_Empty"
    },
    {
      "x": -7,
      "y": 19,
      "z": -8,
      "name": "Nat20_Force_Empty"
    },
    {
      "x": -7,
      "y": 0,
      "z": -7,
      "name": "Soil_Clay"
    },
    {
      "x": -7,
      "y": 1,
      "z": -7,
      "name": "Soil_Clay"
    },
    {
      "x": -7,
      "y": 2,
      "z": -7,
      "name": "Soil_Clay"
    },
    {
      "x": -7,
      "y": 3,
      "z": -7,
      "name": "Soil_Clay"
    },
    {
      "x": -7,
      "y": 4,
      "z": -7,
      "name": "Rock_Sandstone_Cobble"
    },
    {
      "x": -7,
      "y": 5,
      "z": -7,
      "name": "Rock_Sandstone_Cobble"
    },
    {
      "x": -7,
      "y": 6,
      "z": -7,
      "name": "Nat20_Force_Empty"
    },
    {
      "x": -7,
      "y": 7,
      "z": -7,
      "name": "Nat20_Force_Empty"
    },
    {
      "x": -7,
      "y": 8,
      "z": -7,
      "name": "Wood_Drywood_Planks"
    },
    {
      "x": -7,
      "y": 9,
      "z": -7,
      "name": "Nat20_Force_Empty"
    },
    {
      "x": -7,
      "y": 10,
      "z": -7,
      "name": "Nat20_Force_Empty"
    },
    {
      "x": -7,
      "y": 11,
      "z": -7,
      "name": "Nat20_Force_Empty"
    },
    {
      "x": -7,
      "y": 12,
      "z": -7,
      "name": "Nat20_Force_Empty"
    },
    {
      "x": -7,
      "y": 13,
      "z": -7,
      "name": "Nat20_Force_Empty"
    },
    {
      "x": -7,
      "y": 14,
      "z": -7,
      "name": "Nat20_Force_Empty"
    },
    {
      "x": -7,
      "y": 15,
      "z": -7,
      "name": "Nat20_Force_Empty"
    },
    {
      "x": -7,
      "y": 16,
      "z": -7,
      "name": "Nat20_Force_Empty"
    },
    {
      "x": -7,
      "y": 17,
      "z": -7,
      "name": "Nat20_Force_Empty"
    },
    {
      "x": -7,
      "y": 18,
      "z": -7,
      "name": "Nat20_Force_Empty"
    },
    {
      "x": -7,
      "y": 19,
      "z": -7,
      "name": "Nat20_Force_Empty"
    },
    {
      "x": -7,
      "y": 0,
      "z": -6,
      "name": "Soil_Clay"
    },
    {
      "x": -7,
      "y": 1,
      "z": -6,
      "name": "Soil_Clay"
    },
    {
      "x": -7,
      "y": 2,
      "z": -6,
      "name": "Soil_Clay"
    },
    {
      "x": -7,
      "y": 3,
      "z": -6,
      "name": "Soil_Clay"
    },
    {
      "x": -7,
      "y": 4,
      "z": -6,
      "name": "Rock_Sandstone_Cobble"
    },
    {
      "x": -7,
      "y": 5,
      "z": -6,
      "name": "Rock_Sandstone_Cobble"
    },
    {
      "x": -7,
      "y": 6,
      "z": -6,
      "name": "Rock_Sandstone_Cobble"
    },
    {
      "x": -7,
      "y": 7,
      "z": -6,
      "name": "Wood_Dry_Branch_Long"
    },
    {
      "x": -7,
      "y": 8,
      "z": -6,
      "name": "Wood_Drywood_Planks"
    },
    {
      "x": -7,
      "y": 9,
      "z": -6,
      "name": "*Cloth_Roof_Hide_State_Definitions_Corner_Right",
      "rotation": 3
    },
    {
      "x": -7,
      "y": 10,
      "z": -6,
      "name": "Nat20_Force_Empty"
    },
    {
      "x": -7,
      "y": 11,
      "z": -6,
      "name": "Nat20_Force_Empty"
    },
    {
      "x": -7,
      "y": 12,
      "z": -6,
      "name": "Nat20_Force_Empty"
    },
    {
      "x": -7,
      "y": 13,
      "z": -6,
      "name": "Nat20_Force_Empty"
    },
    {
      "x": -7,
      "y": 14,
      "z": -6,
      "name": "Nat20_Force_Empty"
    },
    {
      "x": -7,
      "y": 15,
      "z": -6,
      "name": "Nat20_Force_Empty"
    },
    {
      "x": -7,
      "y": 16,
      "z": -6,
      "name": "Nat20_Force_Empty"
    },
    {
      "x": -7,
      "y": 17,
      "z": -6,
      "name": "Nat20_Force_Empty"
    },
    {
      "x": -7,
      "y": 18,
      "z": -6,
      "name": "Nat20_Force_Empty"
    },
    {
      "x": -7,
      "y": 19,
      "z": -6,
      "name": "Nat20_Force_Empty"
    },
    {
      "x": -7,
      "y": 0,
      "z": -5,
      "name": "Soil_Clay"
    },
    {
      "x": -7,
      "y": 1,
      "z": -5,
      "name": "Soil_Clay"
    },
    {
      "x": -7,
      "y": 2,
      "z": -5,
      "name": "Soil_Clay"
    },
    {
      "x": -7,
      "y": 3,
      "z": -5,
      "name": "Soil_Clay"
    },
    {
      "x": -7,
      "y": 4,
      "z": -5,
      "name": "Rock_Sandstone_Cobble"
    },
    {
      "x": -7,
      "y": 5,
      "z": -5,
      "name": "Rock_Sandstone_Cobble"
    },
    {
      "x": -7,
      "y": 6,
      "z": -5,
      "name": "Rock_Sandstone_Cobble"
    },
    {
      "x": -7,
      "y": 7,
      "z": -5,
      "name": "Rock_Sandstone_Cobble"
    },
    {
      "x": -7,
      "y": 8,
      "z": -5,
      "name": "Wood_Drywood_Planks"
    },
    {
      "x": -7,
      "y": 9,
      "z": -5,
      "name": "Cloth_Roof_Hide",
      "rotation": 3
    },
    {
      "x": -7,
      "y": 10,
      "z": -5,
      "name": "Nat20_Force_Empty"
    },
    {
      "x": -7,
      "y": 11,
      "z": -5,
      "name": "Nat20_Force_Empty"
    },
    {
      "x": -7,
      "y": 12,
      "z": -5,
      "name": "Nat20_Force_Empty"
    },
    {
      "x": -7,
      "y": 13,
      "z": -5,
      "name": "Nat20_Force_Empty"
    },
    {
      "x": -7,
      "y": 14,
      "z": -5,
      "name": "Nat20_Force_Empty"
    },
    {
      "x": -7,
      "y": 15,
      "z": -5,
      "name": "Nat20_Force_Empty"
    },
    {
      "x": -7,
      "y": 16,
      "z": -5,
      "name": "Nat20_Force_Empty"
    },
    {
      "x": -7,
      "y": 17,
      "z": -5,
      "name": "Nat20_Force_Empty"
    },
    {
      "x": -7,
      "y": 18,
      "z": -5,
      "name": "Nat20_Force_Empty"
    },
    {
      "x": -7,
      "y": 19,
      "z": -5,
      "name": "Nat20_Force_Empty"
    },
    {
      "x": -7,
      "y": 0,
      "z": -4,
      "name": "Soil_Clay"
    },
    {
      "x": -7,
      "y": 1,
      "z": -4,
      "name": "Soil_Clay"
    },
    {
      "x": -7,
      "y": 2,
      "z": -4,
      "name": "Soil_Dirt_Dry"
    },
    {
      "x": -7,
      "y": 3,
      "z": -4,
      "name": "Wood_Drywood_Planks"
    },
    {
      "x": -7,
      "y": 4,
      "z": -4,
      "name": "Nat20_Force_Empty"
    },
    {
      "x": -7,
      "y": 5,
      "z": -4,
      "name": "Nat20_Force_Empty"
    },
    {
      "x": -7,
      "y": 6,
      "z": -4,
      "name": "Nat20_Force_Empty"
    },
    {
      "x": -7,
      "y": 7,
      "z": -4,
      "name": "Nat20_Force_Empty"
    },
    {
      "x": -7,
      "y": 8,
      "z": -4,
      "name": "Wood_Drywood_Planks_Half",
      "rotation": 5
    },
    {
      "x": -7,
      "y": 9,
      "z": -4,
      "name": "*Cloth_Roof_Hide_State_Definitions_Corner_Right",
      "rotation": 10
    },
    {
      "x": -7,
      "y": 10,
      "z": -4,
      "name": "Nat20_Force_Empty"
    },
    {
      "x": -7,
      "y": 11,
      "z": -4,
      "name": "Nat20_Force_Empty"
    },
    {
      "x": -7,
      "y": 12,
      "z": -4,
      "name": "Nat20_Force_Empty"
    },
    {
      "x": -7,
      "y": 13,
      "z": -4,
      "name": "Nat20_Force_Empty"
    },
    {
      "x": -7,
      "y": 14,
      "z": -4,
      "name": "Nat20_Force_Empty"
    },
    {
      "x": -7,
      "y": 15,
      "z": -4,
      "name": "Nat20_Force_Empty"
    },
    {
      "x": -7,
      "y": 16,
      "z": -4,
      "name": "Nat20_Force_Empty"
    },
    {
      "x": -7,
      "y": 17,
      "z": -4,
      "name": "Nat20_Force_Empty"
    },
    {
      "x": -7,
      "y": 18,
      "z": -4,
      "name": "Nat20_Force_Empty"
    },
    {
      "x": -7,
      "y": 19,
      "z": -4,
      "name": "Nat20_Force_Empty"
    },
    {
      "x": -7,
      "y": 0,
      "z": -3,
      "name": "Soil_Clay"
    },
    {
      "x": -7,
      "y": 1,
      "z": -3,
      "name": "Soil_Clay"
    },
    {
      "x": -7,
      "y": 2,
      "z": -3,
      "name": "Soil_Dirt_Dry"
    },
    {
      "x": -7,
      "y": 3,
      "z": -3,
      "name": "Wood_Drywood_Planks"
    },
    {
      "x": -7,
      "y": 4,
      "z": -3,
      "name": "Nat20_Force_Empty"
    },
    {
      "x": -7,
      "y": 5,
      "z": -3,
      "name": "Nat20_Force_Empty"
    },
    {
      "x": -7,
      "y": 6,
      "z": -3,
      "name": "Nat20_Force_Empty"
    },
    {
      "x": -7,
      "y": 7,
      "z": -3,
      "name": "Nat20_Force_Empty"
    },
    {
      "x": -7,
      "y": 8,
      "z": -3,
      "name": "Nat20_Force_Empty"
    },
    {
      "x": -7,
      "y": 9,
      "z": -3,
      "name": "Nat20_Force_Empty"
    },
    {
      "x": -7,
      "y": 10,
      "z": -3,
      "name": "*Cloth_Roof_Hide_State_Definitions_Corner_Right",
      "rotation": 3
    },
    {
      "x": -7,
      "y": 11,
      "z": -3,
      "name": "Nat20_Force_Empty"
    },
    {
      "x": -7,
      "y": 12,
      "z": -3,
      "name": "Nat20_Force_Empty"
    },
    {
      "x": -7,
      "y": 13,
      "z": -3,
      "name": "Nat20_Force_Empty"
    },
    {
      "x": -7,
      "y": 14,
      "z": -3,
      "name": "Nat20_Force_Empty"
    },
    {
      "x": -7,
      "y": 15,
      "z": -3,
      "name": "Nat20_Force_Empty"
    },
    {
      "x": -7,
      "y": 16,
      "z": -3,
      "name": "Nat20_Force_Empty"
    },
    {
      "x": -7,
      "y": 17,
      "z": -3,
      "name": "Nat20_Force_Empty"
    },
    {
      "x": -7,
      "y": 18,
      "z": -3,
      "name": "Nat20_Force_Empty"
    },
    {
      "x": -7,
      "y": 19,
      "z": -3,
      "name": "Nat20_Force_Empty"
    },
    {
      "x": -7,
      "y": 0,
      "z": -2,
      "name": "Soil_Dirt_Dry"
    },
    {
      "x": -7,
      "y": 1,
      "z": -2,
      "name": "Soil_Dirt_Dry"
    },
    {
      "x": -7,
      "y": 2,
      "z": -2,
      "name": "Soil_Dirt_Dry"
    },
    {
      "x": -7,
      "y": 3,
      "z": -2,
      "name": "Wood_Drywood_Planks"
    },
    {
      "x": -7,
      "y": 4,
      "z": -2,
      "name": "Nat20_Force_Empty"
    },
    {
      "x": -7,
      "y": 5,
      "z": -2,
      "name": "Nat20_Force_Empty"
    },
    {
      "x": -7,
      "y": 6,
      "z": -2,
      "name": "Nat20_Force_Empty"
    },
    {
      "x": -7,
      "y": 7,
      "z": -2,
      "name": "Nat20_Force_Empty"
    },
    {
      "x": -7,
      "y": 8,
      "z": -2,
      "name": "Nat20_Force_Empty"
    },
    {
      "x": -7,
      "y": 9,
      "z": -2,
      "name": "Nat20_Force_Empty"
    },
    {
      "x": -7,
      "y": 10,
      "z": -2,
      "name": "Cloth_Roof_Hide",
      "rotation": 3
    },
    {
      "x": -7,
      "y": 11,
      "z": -2,
      "name": "Nat20_Force_Empty"
    },
    {
      "x": -7,
      "y": 12,
      "z": -2,
      "name": "Nat20_Force_Empty"
    },
    {
      "x": -7,
      "y": 13,
      "z": -2,
      "name": "Nat20_Force_Empty"
    },
    {
      "x": -7,
      "y": 14,
      "z": -2,
      "name": "Nat20_Force_Empty"
    },
    {
      "x": -7,
      "y": 15,
      "z": -2,
      "name": "Nat20_Force_Empty"
    },
    {
      "x": -7,
      "y": 16,
      "z": -2,
      "name": "Nat20_Force_Empty"
    },
    {
      "x": -7,
      "y": 17,
      "z": -2,
      "name": "Nat20_Force_Empty"
    },
    {
      "x": -7,
      "y": 18,
      "z": -2,
      "name": "Nat20_Force_Empty"
    },
    {
      "x": -7,
      "y": 19,
      "z": -2,
      "name": "Nat20_Force_Empty"
    },
    {
      "x": -7,
      "y": 0,
      "z": -1,
      "name": "Soil_Dirt_Dry"
    },
    {
      "x": -7,
      "y": 1,
      "z": -1,
      "name": "Soil_Dirt_Dry"
    },
    {
      "x": -7,
      "y": 2,
      "z": -1,
      "name": "Soil_Dirt_Dry"
    },
    {
      "x": -7,
      "y": 3,
      "z": -1,
      "name": "Wood_Drywood_Planks"
    },
    {
      "x": -7,
      "y": 4,
      "z": -1,
      "name": "Nat20_Force_Empty"
    },
    {
      "x": -7,
      "y": 5,
      "z": -1,
      "name": "Nat20_Force_Empty"
    },
    {
      "x": -7,
      "y": 6,
      "z": -1,
      "name": "Nat20_Force_Empty"
    },
    {
      "x": -7,
      "y": 7,
      "z": -1,
      "name": "Nat20_Force_Empty"
    },
    {
      "x": -7,
      "y": 8,
      "z": -1,
      "name": "Nat20_Force_Empty"
    },
    {
      "x": -7,
      "y": 9,
      "z": -1,
      "name": "Nat20_Force_Empty"
    },
    {
      "x": -7,
      "y": 10,
      "z": -1,
      "name": "Cloth_Roof_Hide",
      "rotation": 3
    },
    {
      "x": -7,
      "y": 11,
      "z": -1,
      "name": "Nat20_Force_Empty"
    },
    {
      "x": -7,
      "y": 12,
      "z": -1,
      "name": "Nat20_Force_Empty"
    },
    {
      "x": -7,
      "y": 13,
      "z": -1,
      "name": "Nat20_Force_Empty"
    },
    {
      "x": -7,
      "y": 14,
      "z": -1,
      "name": "Nat20_Force_Empty"
    },
    {
      "x": -7,
      "y": 15,
      "z": -1,
      "name": "Nat20_Force_Empty"
    },
    {
      "x": -7,
      "y": 16,
      "z": -1,
      "name": "Nat20_Force_Empty"
    },
    {
      "x": -7,
      "y": 17,
      "z": -1,
      "name": "Nat20_Force_Empty"
    },
    {
      "x": -7,
      "y": 18,
      "z": -1,
      "name": "Nat20_Force_Empty"
    },
    {
      "x": -7,
      "y": 19,
      "z": -1,
      "name": "Nat20_Force_Empty"
    },
    {
      "x": -7,
      "y": 0,
      "z": 0,
      "name": "Soil_Dirt_Dry"
    },
    {
      "x": -7,
      "y": 1,
      "z": 0,
      "name": "Soil_Dirt_Dry"
    },
    {
      "x": -7,
      "y": 2,
      "z": 0,
      "name": "Soil_Dirt_Dry"
    },
    {
      "x": -7,
      "y": 3,
      "z": 0,
      "name": "Wood_Drywood_Planks"
    },
    {
      "x": -7,
      "y": 4,
      "z": 0,
      "name": "Nat20_Force_Empty"
    },
    {
      "x": -7,
      "y": 5,
      "z": 0,
      "name": "Nat20_Force_Empty"
    },
    {
      "x": -7,
      "y": 6,
      "z": 0,
      "name": "Nat20_Force_Empty"
    },
    {
      "x": -7,
      "y": 7,
      "z": 0,
      "name": "Nat20_Force_Empty"
    },
    {
      "x": -7,
      "y": 8,
      "z": 0,
      "name": "Nat20_Force_Empty"
    },
    {
      "x": -7,
      "y": 9,
      "z": 0,
      "name": "Nat20_Force_Empty"
    },
    {
      "x": -7,
      "y": 10,
      "z": 0,
      "name": "Cloth_Roof_Hide",
      "rotation": 3
    },
    {
      "x": -7,
      "y": 11,
      "z": 0,
      "name": "Nat20_Force_Empty"
    },
    {
      "x": -7,
      "y": 12,
      "z": 0,
      "name": "Nat20_Force_Empty"
    },
    {
      "x": -7,
      "y": 13,
      "z": 0,
      "name": "Nat20_Force_Empty"
    },
    {
      "x": -7,
      "y": 14,
      "z": 0,
      "name": "Nat20_Force_Empty"
    },
    {
      "x": -7,
      "y": 15,
      "z": 0,
      "name": "Nat20_Force_Empty"
    },
    {
      "x": -7,
      "y": 16,
      "z": 0,
      "name": "Nat20_Force_Empty"
    },
    {
      "x": -7,
      "y": 17,
      "z": 0,
      "name": "Nat20_Force_Empty"
    },
    {
      "x": -7,
      "y": 18,
      "z": 0,
      "name": "Nat20_Force_Empty"
    },
    {
      "x": -7,
      "y": 19,
      "z": 0,
      "name": "Nat20_Force_Empty"
    },
    {
      "x": -7,
      "y": 0,
      "z": 1,
      "name": "Soil_Clay"
    },
    {
      "x": -7,
      "y": 1,
      "z": 1,
      "name": "Soil_Clay"
    },
    {
      "x": -7,
      "y": 2,
      "z": 1,
      "name": "Soil_Dirt_Dry"
    },
    {
      "x": -7,
      "y": 3,
      "z": 1,
      "name": "Wood_Drywood_Planks"
    },
    {
      "x": -7,
      "y": 4,
      "z": 1,
      "name": "Nat20_Force_Empty"
    },
    {
      "x": -7,
      "y": 5,
      "z": 1,
      "name": "Nat20_Force_Empty"
    },
    {
      "x": -7,
      "y": 6,
      "z": 1,
      "name": "Nat20_Force_Empty"
    },
    {
      "x": -7,
      "y": 7,
      "z": 1,
      "name": "Nat20_Force_Empty"
    },
    {
      "x": -7,
      "y": 8,
      "z": 1,
      "name": "Nat20_Force_Empty"
    },
    {
      "x": -7,
      "y": 9,
      "z": 1,
      "name": "Nat20_Force_Empty"
    },
    {
      "x": -7,
      "y": 10,
      "z": 1,
      "name": "*Cloth_Roof_Hide_State_Definitions_Corner_Right"
    },
    {
      "x": -7,
      "y": 11,
      "z": 1,
      "name": "Nat20_Force_Empty"
    },
    {
      "x": -7,
      "y": 12,
      "z": 1,
      "name": "Nat20_Force_Empty"
    },
    {
      "x": -7,
      "y": 13,
      "z": 1,
      "name": "Deco_Rope_Diagonal",
      "rotation": 3
    },
    {
      "x": -7,
      "y": 14,
      "z": 1,
      "name": "Nat20_Force_Empty"
    },
    {
      "x": -7,
      "y": 15,
      "z": 1,
      "name": "Nat20_Force_Empty"
    },
    {
      "x": -7,
      "y": 16,
      "z": 1,
      "name": "Deco_Rope_Diagonal",
      "rotation": 1
    },
    {
      "x": -7,
      "y": 17,
      "z": 1,
      "name": "Nat20_Force_Empty"
    },
    {
      "x": -7,
      "y": 18,
      "z": 1,
      "name": "Nat20_Force_Empty"
    },
    {
      "x": -7,
      "y": 19,
      "z": 1,
      "name": "Nat20_Force_Empty"
    },
    {
      "x": -7,
      "y": 0,
      "z": 2,
      "name": "Soil_Clay"
    },
    {
      "x": -7,
      "y": 1,
      "z": 2,
      "name": "Soil_Clay"
    },
    {
      "x": -7,
      "y": 2,
      "z": 2,
      "name": "Soil_Dirt_Dry"
    },
    {
      "x": -7,
      "y": 3,
      "z": 2,
      "name": "Wood_Drywood_Planks"
    },
    {
      "x": -7,
      "y": 4,
      "z": 2,
      "name": "Nat20_Force_Empty"
    },
    {
      "x": -7,
      "y": 5,
      "z": 2,
      "name": "Nat20_Force_Empty"
    },
    {
      "x": -7,
      "y": 6,
      "z": 2,
      "name": "Nat20_Force_Empty"
    },
    {
      "x": -7,
      "y": 7,
      "z": 2,
      "name": "Nat20_Force_Empty"
    },
    {
      "x": -7,
      "y": 8,
      "z": 2,
      "name": "Wood_Drywood_Planks_Half",
      "rotation": 5
    },
    {
      "x": -7,
      "y": 9,
      "z": 2,
      "name": "*Cloth_Roof_Hide_State_Definitions_Corner_Right",
      "rotation": 11
    },
    {
      "x": -7,
      "y": 10,
      "z": 2,
      "name": "Nat20_Force_Empty"
    },
    {
      "x": -7,
      "y": 11,
      "z": 2,
      "name": "Nat20_Force_Empty"
    },
    {
      "x": -7,
      "y": 12,
      "z": 2,
      "name": "Nat20_Force_Empty"
    },
    {
      "x": -7,
      "y": 13,
      "z": 2,
      "name": "Nat20_Force_Empty"
    },
    {
      "x": -7,
      "y": 14,
      "z": 2,
      "name": "Nat20_Force_Empty"
    },
    {
      "x": -7,
      "y": 15,
      "z": 2,
      "name": "Nat20_Force_Empty"
    },
    {
      "x": -7,
      "y": 16,
      "z": 2,
      "name": "Nat20_Force_Empty"
    },
    {
      "x": -7,
      "y": 17,
      "z": 2,
      "name": "Nat20_Force_Empty"
    },
    {
      "x": -7,
      "y": 18,
      "z": 2,
      "name": "Nat20_Force_Empty"
    },
    {
      "x": -7,
      "y": 19,
      "z": 2,
      "name": "Nat20_Force_Empty"
    },
    {
      "x": -7,
      "y": 0,
      "z": 3,
      "name": "Soil_Clay"
    },
    {
      "x": -7,
      "y": 1,
      "z": 3,
      "name": "Soil_Clay"
    },
    {
      "x": -7,
      "y": 2,
      "z": 3,
      "name": "Soil_Clay"
    },
    {
      "x": -7,
      "y": 3,
      "z": 3,
      "name": "Soil_Clay"
    },
    {
      "x": -7,
      "y": 4,
      "z": 3,
      "name": "Soil_Clay"
    },
    {
      "x": -7,
      "y": 5,
      "z": 3,
      "name": "Rock_Sandstone_Cobble"
    },
    {
      "x": -7,
      "y": 6,
      "z": 3,
      "name": "Rock_Sandstone_Cobble"
    },
    {
      "x": -7,
      "y": 7,
      "z": 3,
      "name": "Rock_Sandstone_Cobble"
    },
    {
      "x": -7,
      "y": 8,
      "z": 3,
      "name": "Wood_Drywood_Planks"
    },
    {
      "x": -7,
      "y": 9,
      "z": 3,
      "name": "Cloth_Roof_Hide",
      "rotation": 3
    },
    {
      "x": -7,
      "y": 10,
      "z": 3,
      "name": "Nat20_Force_Empty"
    },
    {
      "x": -7,
      "y": 11,
      "z": 3,
      "name": "Nat20_Force_Empty"
    },
    {
      "x": -7,
      "y": 12,
      "z": 3,
      "name": "Nat20_Force_Empty"
    },
    {
      "x": -7,
      "y": 13,
      "z": 3,
      "name": "Nat20_Force_Empty"
    },
    {
      "x": -7,
      "y": 14,
      "z": 3,
      "name": "Nat20_Force_Empty"
    },
    {
      "x": -7,
      "y": 15,
      "z": 3,
      "name": "Nat20_Force_Empty"
    },
    {
      "x": -7,
      "y": 16,
      "z": 3,
      "name": "Nat20_Force_Empty"
    },
    {
      "x": -7,
      "y": 17,
      "z": 3,
      "name": "Nat20_Force_Empty"
    },
    {
      "x": -7,
      "y": 18,
      "z": 3,
      "name": "Nat20_Force_Empty"
    },
    {
      "x": -7,
      "y": 19,
      "z": 3,
      "name": "Nat20_Force_Empty"
    },
    {
      "x": -7,
      "y": 0,
      "z": 4,
