{
  "version": 8,
  "blockIdVersion": 11,
  "anchorX": 0,
  "anchorY": 0,
  "anchorZ": 0,
  "blocks": [
    {
      "x": -3,
      "y": 0,
      "z": 0,
      "name": "Rock_Basalt"
    },
    {
      "x": -3,
      "y": 1,
      "z": 0,
      "name": "Rock_Basalt_Stalactite_Small"
    },
    {
      "x": -3,
      "y": 0,
      "z": 1,
      "name": "Rock_Basalt"
    },
    {
      "x": -3,
      "y": 1,
      "z": 1,
      "name": "Rock_Basalt"
    },
    {
      "x": -3,
      "y": 2,
      "z": 1,
      "name": "Nat20_Chest_Spawn"
    },
    {
      "x": -3,
      "y": 0,
      "z": 2,
      "name": "Rock_Basalt"
    },
    {
      "x": -2,
      "y": 0,
      "z": -3,
      "name": "Soil_Dirt_Burnt"
    },
    {
      "x": -2,
      "y": 1,
      "z": -3,
      "name": "Nat20_Force_Empty"
    },
    {
      "x": -2,
      "y": 2,
      "z": -3,
      "name": "Nat20_Force_Empty"
    },
    {
      "x": -2,
      "y": 3,
      "z": -3,
      "name": "Nat20_Force_Empty"
    },
    {
      "x": -2,
      "y": 4,
      "z": -3,
      "name": "Nat20_Force_Empty"
    },
    {
      "x": -2,
      "y": 5,
      "z": -3,
      "name": "Nat20_Force_Empty"
    },
    {
      "x": -2,
      "y": 6,
      "z": -3,
      "name": "Nat20_Force_Empty"
    },
    {
      "x": -2,
      "y": 7,
      "z": -3,
      "name": "Nat20_Force_Empty"
    },
    {
      "x": -2,
      "y": 0,
      "z": -2,
      "name": "Soil_Dirt_Burnt"
    },
    {
      "x": -2,
      "y": 1,
      "z": -2,
      "name": "Nat20_Force_Empty"
    },
    {
      "x": -2,
      "y": 2,
      "z": -2,
      "name": "Nat20_Force_Empty"
    },
    {
      "x": -2,
      "y": 3,
      "z": -2,
      "name": "Nat20_Force_Empty"
    },
    {
      "x": -2,
      "y": 4,
      "z": -2,
      "name": "Wood_Deadwood_Planks_Half",
      "rotation": 7
    },
    {
      "x": -2,
      "y": 5,
      "z": -2,
      "name": "Nat20_Force_Empty"
    },
    {
      "x": -2,
      "y": 6,
      "z": -2,
      "name": "Nat20_Force_Empty"
    },
    {
      "x": -2,
      "y": 7,
      "z": -2,
      "name": "Nat20_Force_Empty"
    },
    {
      "x": -2,
      "y": 0,
      "z": -1,
      "name": "Rock_Stone_Brick"
    },
    {
      "x": -2,
      "y": 1,
      "z": -1,
      "name": "Nat20_Direction"
    },
    {
      "x": -2,
      "y": 2,
      "z": -1,
      "name": "Nat20_Force_Empty"
    },
    {
      "x": -2,
      "y": 3,
      "z": -1,
      "name": "Nat20_Force_Empty"
    },
    {
      "x": -2,
      "y": 4,
      "z": -1,
      "name": "Nat20_Force_Empty"
    },
    {
      "x": -2,
      "y": 5,
      "z": -1,
      "name": "Nat20_Force_Empty"
    },
    {
      "x": -2,
      "y": 6,
      "z": -1,
      "name": "Nat20_Force_Empty"
    },
    {
      "x": -2,
      "y": 7,
      "z": -1,
      "name": "Nat20_Force_Empty"
    },
    {
      "x": -2,
      "y": 0,
      "z": 0,
      "name": "Rock_Basalt"
    },
    {
      "x": -2,
      "y": 1,
      "z": 0,
      "name": "Rock_Basalt"
    },
    {
      "x": -2,
      "y": 2,
      "z": 0,
      "name": "Plant_Moss_Rug_Green"
    },
    {
      "x": -2,
      "y": 3,
      "z": 0,
      "name": "Nat20_Force_Empty"
    },
    {
      "x": -2,
      "y": 4,
      "z": 0,
      "name": "Nat20_Force_Empty"
    },
    {
      "x": -2,
      "y": 5,
      "z": 0,
      "name": "Nat20_Force_Empty"
    },
    {
      "x": -2,
      "y": 6,
      "z": 0,
      "name": "Nat20_Force_Empty"
    },
    {
      "x": -2,
      "y": 7,
      "z": 0,
      "name": "Nat20_Force_Empty"
    },
    {
      "x": -2,
      "y": 0,
      "z": 1,
      "name": "Rock_Basalt"
    },
    {
      "x": -2,
      "y": 1,
      "z": 1,
      "name": "Rock_Basalt"
    },
    {
      "x": -2,
      "y": 2,
      "z": 1,
      "name": "Rock_Basalt"
    },
    {
      "x": -2,
      "y": 3,
      "z": 1,
      "name": "Rock_Basalt_Stalactite_Small"
    },
    {
      "x": -2,
      "y": 4,
      "z": 1,
      "name": "Cloth_Roof_Hide_Flap",
      "rotation": 3
    },
    {
      "x": -2,
      "y": 5,
      "z": 1,
      "name": "Nat20_Force_Empty"
    },
    {
      "x": -2,
      "y": 6,
      "z": 1,
      "name": "Nat20_Force_Empty"
    },
    {
      "x": -2,
      "y": 7,
      "z": 1,
      "name": "Nat20_Force_Empty"
    },
    {
      "x": -2,
      "y": 0,
      "z": 2,
      "name": "Rock_Basalt"
    },
    {
      "x": -2,
      "y": 1,
      "z": 2,
      "name": "Rock_Basalt"
    },
    {
      "x": -2,
      "y": 2,
      "z": 2,
      "name": "Rock_Basalt_Stalactite_Large"
    },
    {
      "x": -2,
      "y": 3,
      "z": 2,
      "name": "Rock_Basalt_Stalactite_Large",
      "filler": 1024
    },
    {
      "x": -2,
      "y": 4,
      "z": 2,
      "name": "Cloth_Roof_Hide_Flap",
      "rotation": 3
    },
    {
      "x": -2,
      "y": 5,
      "z": 2,
      "name": "Nat20_Force_Empty"
    },
    {
      "x": -2,
      "y": 6,
      "z": 2,
      "name": "Nat20_Force_Empty"
    },
    {
      "x": -2,
      "y": 7,
      "z": 2,
      "name": "Nat20_Force_Empty"
    },
    {
      "x": -2,
      "y": 0,
      "z": 3,
      "name": "Rock_Basalt"
    },
    {
      "x": -2,
      "y": 1,
      "z": 3,
      "name": "Rubble_Basalt"
    },
    {
      "x": -2,
      "y": 2,
      "z": 3,
      "name": "Nat20_Force_Empty"
    },
    {
      "x": -2,
      "y": 3,
      "z": 3,
      "name": "Nat20_Force_Empty"
    },
    {
      "x": -2,
      "y": 4,
      "z": 3,
      "name": "Nat20_Force_Empty"
    },
    {
      "x": -2,
      "y": 5,
      "z": 3,
      "name": "Nat20_Force_Empty"
    },
    {
      "x": -2,
      "y": 6,
      "z": 3,
      "name": "Nat20_Force_Empty"
    },
    {
      "x": -2,
      "y": 7,
      "z": 3,
      "name": "Nat20_Force_Empty"
    },
    {
      "x": -1,
      "y": 0,
      "z": -3,
      "name": "Soil_Dirt_Burnt"
    },
    {
      "x": -1,
      "y": 1,
      "z": -3,
      "name": "Nat20_Force_Empty"
    },
    {
      "x": -1,
      "y": 2,
      "z": -3,
      "name": "Nat20_Force_Empty"
    },
    {
      "x": -1,
      "y": 3,
      "z": -3,
      "name": "Nat20_Force_Empty"
    },
    {
      "x": -1,
      "y": 4,
      "z": -3,
      "name": "Cloth_Roof_Hide_Flap",
      "rotation": 2
    },
    {
      "x": -1,
      "y": 5,
      "z": -3,
      "name": "Nat20_Force_Empty"
    },
    {
      "x": -1,
      "y": 6,
      "z": -3,
      "name": "Nat20_Force_Empty"
    },
    {
      "x": -1,
      "y": 7,
      "z": -3,
      "name": "Nat20_Force_Empty"
    },
    {
      "x": -1,
      "y": 0,
      "z": -2,
      "name": "Rock_Basalt"
    },
    {
      "x": -1,
      "y": 1,
      "z": -2,
      "name": "Wood_Softwood_Planks"
    },
    {
      "x": -1,
      "y": 2,
      "z": -2,
      "name": "Plant_Moss_Rug_Green"
    },
    {
      "x": -1,
      "y": 3,
      "z": -2,
      "name": "Nat20_Force_Empty"
    },
    {
      "x": -1,
      "y": 4,
      "z": -2,
      "name": "Wood_Deadwood_Planks"
    },
    {
      "x": -1,
      "y": 5,
      "z": -2,
      "name": "*Cloth_Roof_Hide_State_Definitions_Corner_Right",
      "rotation": 3
    },
    {
      "x": -1,
      "y": 6,
      "z": -2,
      "name": "Nat20_Force_Empty"
    },
    {
      "x": -1,
      "y": 7,
      "z": -2,
      "name": "Nat20_Force_Empty"
    },
    {
      "x": -1,
      "y": 0,
      "z": -1,
      "name": "Rock_Stone_Brick"
    },
    {
      "x": -1,
      "y": 1,
      "z": -1,
      "name": "Nat20_Anchor"
    },
    {
      "x": -1,
      "y": 2,
      "z": -1,
      "name": "Nat20_Force_Empty"
    },
    {
      "x": -1,
      "y": 3,
      "z": -1,
      "name": "Nat20_Force_Empty"
    },
    {
      "x": -1,
      "y": 4,
      "z": -1,
      "name": "*Wood_Softwood_Planks_Half_State_Definitions_Block",
      "rotation": 8
    },
    {
      "x": -1,
      "y": 5,
      "z": -1,
      "name": "Nat20_Force_Empty"
    },
    {
      "x": -1,
      "y": 6,
      "z": -1,
      "name": "Nat20_Force_Empty"
    },
    {
      "x": -1,
      "y": 7,
      "z": -1,
      "name": "Nat20_Force_Empty"
    },
    {
      "x": -1,
      "y": 0,
      "z": 0,
      "name": "Rock_Stone_Brick"
    },
    {
      "x": -1,
      "y": 1,
      "z": 0,
      "name": "Nat20_Force_Empty"
    },
    {
      "x": -1,
      "y": 2,
      "z": 0,
      "name": "Nat20_Force_Empty"
    },
    {
      "x": -1,
      "y": 3,
      "z": 0,
      "name": "Nat20_Force_Empty"
    },
    {
      "x": -1,
      "y": 4,
      "z": 0,
      "name": "Wood_Softwood_Planks_Half",
      "rotation": 8
    },
    {
      "x": -1,
      "y": 5,
      "z": 0,
      "name": "Nat20_Force_Empty"
    },
    {
      "x": -1,
      "y": 6,
      "z": 0,
      "name": "Nat20_Force_Empty"
    },
    {
      "x": -1,
      "y": 7,
      "z": 0,
      "name": "Nat20_Force_Empty"
    },
    {
      "x": -1,
      "y": 0,
      "z": 1,
      "name": "Rock_Basalt"
    },
    {
      "x": -1,
      "y": 1,
      "z": 1,
      "name": "Wood_Deadwood_Planks"
    },
    {
      "x": -1,
      "y": 2,
      "z": 1,
      "name": "Wood_Deadwood_Beam"
    },
    {
      "x": -1,
      "y": 3,
      "z": 1,
      "name": "Wood_Deadwood_Beam"
    },
    {
      "x": -1,
      "y": 4,
      "z": 1,
      "name": "Wood_Deadwood_Planks"
    },
    {
      "x": -1,
      "y": 5,
      "z": 1,
      "name": "Cloth_Roof_Hide",
      "rotation": 3
    },
    {
      "x": -1,
      "y": 6,
      "z": 1,
      "name": "Nat20_Force_Empty"
    },
    {
      "x": -1,
      "y": 7,
      "z": 1,
      "name": "Nat20_Force_Empty"
    },
    {
      "x": -1,
      "y": 0,
      "z": 2,
      "name": "Rock_Basalt"
    },
    {
      "x": -1,
      "y": 1,
      "z": 2,
      "name": "Wood_Softwood_Fence",
      "rotation": 2
    },
    {
      "x": -1,
      "y": 2,
      "z": 2,
      "name": "Wood_Softwood_Fence",
      "rotation": 2
    },
    {
      "x": -1,
      "y": 3,
      "z": 2,
      "name": "Wood_Deadwood_Planks"
    },
    {
      "x": -1,
      "y": 4,
      "z": 2,
      "name": "Wood_Deadwood_Planks"
    },
    {
      "x": -1,
      "y": 5,
      "z": 2,
      "name": "*Cloth_Roof_Hide_State_Definitions_Corner_Right"
    },
    {
      "x": -1,
      "y": 6,
      "z": 2,
      "name": "Nat20_Force_Empty"
    },
    {
      "x": -1,
      "y": 7,
      "z": 2,
      "name": "Nat20_Force_Empty"
    },
    {
      "x": -1,
      "y": 0,
      "z": 3,
      "name": "Rock_Basalt"
    },
    {
      "x": -1,
      "y": 1,
      "z": 3,
      "name": "Rock_Basalt_Stalactite_Large"
    },
    {
      "x": -1,
      "y": 2,
      "z": 3,
      "name": "Rock_Basalt_Stalactite_Large",
      "filler": 1024
    },
    {
      "x": -1,
      "y": 3,
      "z": 3,
      "name": "Nat20_Force_Empty"
    },
    {
      "x": -1,
      "y": 4,
      "z": 3,
      "name": "Cloth_Roof_Hide_Flap"
    },
    {
      "x": -1,
      "y": 5,
      "z": 3,
      "name": "Nat20_Force_Empty"
    },
    {
      "x": -1,
      "y": 6,
      "z": 3,
      "name": "Nat20_Force_Empty"
    },
    {
      "x": -1,
      "y": 7,
      "z": 3,
      "name": "Nat20_Force_Empty"
    },
    {
      "x": 0,
      "y": 0,
      "z": -3,
      "name": "Rock_Basalt"
    },
    {
      "x": 0,
      "y": 1,
      "z": -3,
      "name": "Nat20_Force_Empty"
    },
    {
      "x": 0,
      "y": 2,
      "z": -3,
      "name": "Plant_Moss_Wall_Green",
      "rotation": 2
    },
    {
      "x": 0,
      "y": 3,
      "z": -3,
      "name": "Plant_Moss_Wall_Green",
      "rotation": 2
    },
    {
      "x": 0,
      "y": 4,
      "z": -3,
      "name": "Cloth_Roof_Hide_Flap",
      "rotation": 2
    },
    {
      "x": 0,
      "y": 5,
      "z": -3,
      "name": "Nat20_Force_Empty"
    },
    {
      "x": 0,
      "y": 6,
      "z": -3,
      "name": "Nat20_Force_Empty"
    },
    {
      "x": 0,
      "y": 7,
      "z": -3,
      "name": "Nat20_Force_Empty"
    },
    {
      "x": 0,
      "y": 0,
      "z": -2,
      "name": "Rock_Basalt"
    },
    {
      "x": 0,
      "y": 1,
      "z": -2,
      "name": "Wood_Softwood_Planks"
    },
    {
      "x": 0,
      "y": 2,
      "z": -2,
      "name": "Wood_Softwood_Planks"
    },
    {
      "x": 0,
      "y": 3,
      "z": -2,
      "name": "Wood_Deadwood_Beam"
    },
    {
      "x": 0,
      "y": 4,
      "z": -2,
      "name": "Wood_Deadwood_Planks"
    },
    {
      "x": 0,
      "y": 5,
      "z": -2,
      "name": "Cloth_Roof_Hide",
      "rotation": 2
    },
    {
      "x": 0,
      "y": 6,
      "z": -2,
      "name": "Nat20_Force_Empty"
    },
    {
      "x": 0,
      "y": 7,
      "z": -2,
      "name": "Nat20_Force_Empty"
    },
    {
      "x": 0,
      "y": 0,
      "z": -1,
      "name": "Rock_Stone_Brick"
    },
    {
      "x": 0,
      "y": 1,
      "z": -1,
      "name": "Nat20_Force_Empty"
    },
    {
      "x": 0,
      "y": 2,
      "z": -1,
      "name": "Nat20_Force_Empty"
    },
    {
      "x": 0,
      "y": 3,
      "z": -1,
      "name": "Nat20_Force_Empty"
    },
    {
      "x": 0,
      "y": 4,
      "z": -1,
      "name": "Wood_Deadwood_Beam",
      "rotation": 5
    },
    {
      "x": 0,
      "y": 5,
      "z": -1,
      "name": "Nat20_Force_Empty"
    },
    {
      "x": 0,
      "y": 6,
      "z": -1,
      "name": "Nat20_Force_Empty"
    },
    {
      "x": 0,
      "y": 7,
      "z": -1,
      "name": "Nat20_Force_Empty"
    },
    {
      "x": 0,
      "y": 0,
      "z": 0,
      "name": "Rock_Stone_Brick"
    },
    {
      "x": 0,
      "y": 1,
      "z": 0,
      "name": "Nat20_Force_Empty"
    },
    {
      "x": 0,
      "y": 2,
      "z": 0,
      "name": "Nat20_Force_Empty"
    },
    {
      "x": 0,
      "y": 3,
      "z": 0,
      "name": "Nat20_Force_Empty"
    },
    {
      "x": 0,
      "y": 4,
      "z": 0,
      "name": "Nat20_Force_Empty"
    },
    {
      "x": 0,
      "y": 5,
      "z": 0,
      "name": "Nat20_Force_Empty"
    },
    {
      "x": 0,
      "y": 6,
      "z": 0,
      "name": "Cloth_Roof_Hide_Flat"
    },
    {
      "x": 0,
      "y": 7,
      "z": 0,
      "name": "Nat20_Force_Empty"
    },
    {
      "x": 0,
      "y": 0,
      "z": 1,
      "name": "Rock_Stone_Brick"
    },
    {
      "x": 0,
      "y": 1,
      "z": 1,
      "name": "Nat20_Force_Empty"
    },
    {
      "x": 0,
      "y": 2,
      "z": 1,
      "name": "Nat20_Force_Empty"
    },
    {
      "x": 0,
      "y": 3,
      "z": 1,
      "name": "Nat20_Force_Empty"
    },
    {
      "x": 0,
      "y": 4,
      "z": 1,
      "name": "Nat20_Force_Empty"
    },
    {
      "x": 0,
      "y": 5,
      "z": 1,
      "name": "Nat20_Force_Empty"
    },
    {
      "x": 0,
      "y": 6,
      "z": 1,
      "name": "Nat20_Force_Empty"
    },
    {
      "x": 0,
      "y": 7,
      "z": 1,
      "name": "Nat20_Force_Empty"
    },
    {
      "x": 0,
      "y": 0,
      "z": 2,
      "name": "Rock_Basalt"
    },
    {
      "x": 0,
      "y": 1,
      "z": 2,
      "name": "Wood_Deadwood_Planks"
    },
    {
      "x": 0,
      "y": 2,
      "z": 2,
      "name": "Wood_Softwood_Fence"
    },
    {
      "x": 0,
      "y": 3,
      "z": 2,
      "name": "Wood_Softwood_Fence"
    },
    {
      "x": 0,
      "y": 4,
      "z": 2,
      "name": "Wood_Deadwood_Beam",
      "rotation": 5
    },
    {
      "x": 0,
      "y": 5,
      "z": 2,
      "name": "Cloth_Roof_Hide"
    },
    {
      "x": 0,
      "y": 6,
      "z": 2,
      "name": "Nat20_Force_Empty"
    },
    {
      "x": 0,
      "y": 7,
      "z": 2,
      "name": "Nat20_Force_Empty"
    },
    {
      "x": 0,
      "y": 0,
      "z": 3,
      "name": "Soil_Dirt_Burnt"
    },
    {
      "x": 0,
      "y": 1,
      "z": 3,
      "name": "Nat20_Force_Empty"
    },
    {
      "x": 0,
      "y": 2,
      "z": 3,
      "name": "Nat20_Force_Empty"
    },
    {
      "x": 0,
      "y": 3,
      "z": 3,
      "name": "Nat20_Force_Empty"
    },
    {
      "x": 0,
      "y": 4,
      "z": 3,
      "name": "Cloth_Roof_Hide_Flap"
    },
    {
      "x": 0,
      "y": 5,
      "z": 3,
      "name": "Nat20_Force_Empty"
    },
    {
      "x": 0,
      "y": 6,
      "z": 3,
      "name": "Nat20_Force_Empty"
    },
    {
      "x": 0,
      "y": 7,
      "z": 3,
      "name": "Nat20_Force_Empty"
    },
    {
      "x": 1,
      "y": 0,
      "z": -3,
      "name": "Rock_Basalt"
    },
    {
      "x": 1,
      "y": 1,
      "z": -3,
      "name": "Nat20_Force_Empty"
    },
    {
      "x": 1,
      "y": 2,
      "z": -3,
      "name": "Nat20_Force_Empty"
    },
    {
      "x": 1,
      "y": 3,
      "z": -3,
      "name": "Plant_Moss_Wall_Green",
      "rotation": 2
    },
    {
      "x": 1,
      "y": 4,
      "z": -3,
      "name": "Plant_Moss_Wall_Green",
      "rotation": 2
    },
    {
      "x": 1,
      "y": 5,
      "z": -3,
      "name": "Nat20_Force_Empty"
    },
    {
      "x": 1,
      "y": 6,
      "z": -3,
      "name": "Nat20_Force_Empty"
    },
    {
      "x": 1,
      "y": 7,
      "z": -3,
      "name": "Nat20_Force_Empty"
    },
    {
      "x": 1,
      "y": 0,
      "z": -2,
      "name": "Rock_Basalt"
    },
    {
      "x": 1,
      "y": 1,
      "z": -2,
      "name": "Wood_Softwood_Planks"
    },
    {
      "x": 1,
      "y": 2,
      "z": -2,
      "name": "Wood_Softwood_Planks_Half",
      "rotation": 4
    },
    {
      "x": 1,
      "y": 3,
      "z": -2,
      "name": "*Wood_Deadwood_Planks_Half_State_Definitions_Block",
      "rotation": 7
    },
    {
      "x": 1,
      "y": 4,
      "z": -2,
      "name": "Wood_Deadwood_Planks"
    },
    {
      "x": 1,
      "y": 5,
      "z": -2,
      "name": "Cloth_Roof_Hide",
      "rotation": 2
    },
    {
      "x": 1,
      "y": 6,
      "z": -2,
      "name": "Nat20_Force_Empty"
    },
    {
      "x": 1,
      "y": 7,
      "z": -2,
      "name": "Nat20_Force_Empty"
    },
    {
      "x": 1,
      "y": 0,
      "z": -1,
      "name": "Rock_Stone_Brick"
    },
    {
      "x": 1,
      "y": 1,
      "z": -1,
      "name": "Nat20_Force_Empty"
    },
    {
      "x": 1,
      "y": 2,
      "z": -1,
      "name": "Nat20_Force_Empty"
    },
    {
      "x": 1,
      "y": 3,
      "z": -1,
      "name": "Nat20_Force_Empty"
    },
    {
      "x": 1,
      "y": 4,
      "z": -1,
      "name": "Wood_Deadwood_Beam",
      "rotation": 5
    },
    {
      "x": 1,
      "y": 5,
      "z": -1,
      "name": "Nat20_Force_Empty"
    },
    {
      "x": 1,
      "y": 6,
      "z": -1,
      "name": "Cloth_Roof_Hide_Flat"
    },
    {
      "x": 1,
      "y": 7,
      "z": -1,
      "name": "Nat20_Force_Empty"
    },
    {
      "x": 1,
      "y": 0,
      "z": 0,
      "name": "Rock_Stone_Brick"
    },
    {
      "x": 1,
      "y": 1,
      "z": 0,
      "name": "Nat20_Npc_Spawn"
    },
    {
      "x": 1,
      "y": 2,
      "z": 0,
      "name": "Nat20_Force_Empty"
    },
    {
      "x": 1,
      "y": 3,
      "z": 0,
      "name": "Nat20_Force_Empty"
    },
    {
      "x": 1,
      "y": 4,
      "z": 0,
      "name": "Nat20_Force_Empty"
    },
    {
      "x": 1,
      "y": 5,
      "z": 0,
      "name": "Nat20_Force_Empty"
    },
    {
      "x": 1,
      "y": 6,
      "z": 0,
      "name": "Nat20_Force_Empty"
    },
    {
      "x": 1,
      "y": 7,
      "z": 0,
      "name": "Nat20_Force_Empty"
    },
    {
      "x": 1,
      "y": 0,
      "z": 1,
      "name": "Rock_Stone_Brick"
    },
    {
      "x": 1,
      "y": 1,
      "z": 1,
      "name": "Nat20_Force_Empty"
    },
    {
      "x": 1,
      "y": 2,
      "z": 1,
      "name": "Nat20_Force_Empty"
    },
    {
      "x": 1,
      "y": 3,
      "z": 1,
      "name": "Nat20_Force_Empty"
    },
    {
      "x": 1,
      "y": 4,
      "z": 1,
      "name": "Nat20_Force_Empty"
    },
    {
      "x": 1,
      "y": 5,
      "z": 1,
      "name": "Nat20_Force_Empty"
    },
    {
      "x": 1,
      "y": 6,
      "z": 1,
      "name": "Nat20_Force_Empty"
    },
    {
      "x": 1,
      "y": 7,
      "z": 1,
      "name": "Nat20_Force_Empty"
    },
    {
      "x": 1,
      "y": 0,
      "z": 2,
      "name": "Rock_Basalt"
    },
    {
      "x": 1,
      "y": 1,
      "z": 2,
      "name": "Wood_Deadwood_Planks"
    },
    {
      "x": 1,
      "y": 2,
      "z": 2,
      "name": "Plant_Moss_Rug_Green"
    },
    {
      "x": 1,
      "y": 3,
      "z": 2,
      "name": "Nat20_Force_Empty"
    },
    {
      "x": 1,
      "y": 4,
      "z": 2,
      "name": "Wood_Deadwood_Beam",
      "rotation": 5
    },
    {
      "x": 1,
      "y": 5,
      "z": 2,
      "name": "Nat20_Force_Empty"
    },
    {
      "x": 1,
      "y": 6,
      "z": 2,
      "name": "Nat20_Force_Empty"
    },
    {
      "x": 1,
      "y": 7,
      "z": 2,
      "name": "Nat20_Force_Empty"
    },
    {
      "x": 1,
      "y": 0,
      "z": 3,
      "name": "Soil_Dirt_Burnt"
    },
    {
      "x": 1,
      "y": 1,
      "z": 3,
      "name": "Nat20_Force_Empty"
    },
    {
      "x": 1,
      "y": 2,
      "z": 3,
      "name": "Nat20_Force_Empty"
    },
    {
      "x": 1,
      "y": 3,
      "z": 3,
      "name": "Nat20_Force_Empty"
    },
    {
      "x": 1,
      "y": 4,
      "z": 3,
      "name": "Nat20_Force_Empty"
    },
    {
      "x": 1,
      "y": 5,
      "z": 3,
      "name": "Nat20_Force_Empty"
    },
    {
      "x": 1,
      "y": 6,
      "z": 3,
      "name": "Nat20_Force_Empty"
    },
    {
      "x": 1,
      "y": 7,
      "z": 3,
      "name": "Nat20_Force_Empty"
    },
    {
      "x": 2,
      "y": 0,
      "z": -3,
      "name": "Rock_Basalt"
    },
    {
      "x": 2,
      "y": 1,
      "z": -3,
      "name": "Nat20_Force_Empty"
    },
    {
      "x": 2,
      "y": 2,
      "z": -3,
      "name": "Nat20_Force_Empty"
    },
    {
      "x": 2,
      "y": 3,
      "z": -3,
      "name": "Wood_Deadwood_Planks_Half",
      "rotation": 6
    },
    {
      "x": 2,
      "y": 4,
      "z": -3,
      "name": "Wood_Deadwood_Planks_Half",
      "rotation": 6
    },
    {
      "x": 2,
      "y": 5,
      "z": -3,
      "name": "Nat20_Force_Empty"
    },
    {
      "x": 2,
      "y": 6,
      "z": -3,
      "name": "Nat20_Force_Empty"
    },
    {
      "x": 2,
      "y": 7,
      "z": -3,
      "name": "Nat20_Force_Empty"
    },
    {
      "x": 2,
      "y": 0,
      "z": -2,
      "name": "Rock_Basalt"
    },
    {
      "x": 2,
      "y": 1,
      "z": -2,
      "name": "Wood_Deadwood_Planks"
    },
    {
      "x": 2,
      "y": 2,
      "z": -2,
      "name": "Wood_Deadwood_Planks"
    },
    {
      "x": 2,
      "y": 3,
      "z": -2,
      "name": "Wood_Deadwood_Planks"
    },
    {
      "x": 2,
      "y": 4,
      "z": -2,
      "name": "Wood_Deadwood_Planks"
    },
    {
      "x": 2,
      "y": 5,
      "z": -2,
      "name": "*Cloth_Roof_Hide_State_Definitions_Corner_Right",
      "rotation": 2
    },
    {
      "x": 2,
      "y": 6,
      "z": -2,
      "name": "Nat20_Force_Empty"
    },
    {
      "x": 2,
      "y": 7,
      "z": -2,
      "name": "Nat20_Force_Empty"
    },
    {
      "x": 2,
      "y": 0,
      "z": -1,
      "name": "Soil_Dirt_Burnt"
    },
    {
      "x": 2,
      "y": 1,
      "z": -1,
      "name": "Furniture_Crude_Door",
      "rotation": 1
    },
    {
      "x": 2,
      "y": 2,
      "z": -1,
      "name": "Furniture_Crude_Door",
      "filler": 1024,
      "rotation": 1
    },
    {
      "x": 2,
      "y": 3,
      "z": -1,
      "name": "Wood_Softwood_Fence",
      "rotation": 1
    },
    {
      "x": 2,
      "y": 4,
      "z": -1,
      "name": "Wood_Deadwood_Planks"
    },
    {
      "x": 2,
      "y": 5,
      "z": -1,
      "name": "Cloth_Roof_Hide",
      "rotation": 1
    },
    {
      "x": 2,
      "y": 6,
      "z": -1,
      "name": "Nat20_Force_Empty"
    },
    {
      "x": 2,
      "y": 7,
      "z": -1,
      "name": "Nat20_Force_Empty"
    },
    {
      "x": 2,
      "y": 0,
      "z": 0,
      "name": "Rock_Basalt"
    },
    {
      "x": 2,
      "y": 1,
      "z": 0,
      "name": "Wood_Softwood_Planks"
    },
    {
      "x": 2,
      "y": 2,
      "z": 0,
      "name": "Furniture_Crude_Window",
      "rotation": 1
    },
    {
      "x": 2,
      "y": 3,
      "z": 0,
      "name": "Wood_Softwood_Fence",
      "rotation": 1
    },
    {
      "x": 2,
      "y": 4,
      "z": 0,
      "name": "Wood_Deadwood_Planks"
    },
    {
      "x": 2,
      "y": 5,
      "z": 0,
      "name": "Cloth_Roof_Hide",
      "rotation": 1
    },
    {
      "x": 2,
      "y": 6,
      "z": 0,
      "name": "Nat20_Force_Empty"
    },
    {
      "x": 2,
      "y": 7,
      "z": 0,
      "name": "Nat20_Force_Empty"
    },
    {
      "x": 2,
      "y": 0,
      "z": 1,
      "name": "Rock_Basalt"
    },
    {
      "x": 2,
      "y": 1,
      "z": 1,
      "name": "Wood_Softwood_Planks"
    },
    {
      "x": 2,
      "y": 2,
      "z": 1,
      "name": "Wood_Softwood_Fence",
      "rotation": 1
    },
    {
      "x": 2,
      "y": 3,
      "z": 1,
      "name": "Furniture_Crude_Window",
      "rotation": 1
    },
    {
      "x": 2,
      "y": 4,
      "z": 1,
      "name": "Wood_Deadwood_Planks"
    },
    {
      "x": 2,
      "y": 5,
      "z": 1,
      "name": "Plant_Moss_Rug_Green"
    },
    {
      "x": 2,
      "y": 6,
      "z": 1,
      "name": "Nat20_Force_Empty"
    },
    {
      "x": 2,
      "y": 7,
      "z": 1,
      "name": "Nat20_Force_Empty"
    },
    {
      "x": 2,
      "y": 0,
      "z": 2,
      "name": "Rock_Basalt"
    },
    {
      "x": 2,
      "y": 1,
      "z": 2,
      "name": "Wood_Softwood_Planks_Half",
      "rotation": 4
    },
    {
      "x": 2,
      "y": 2,
      "z": 2,
      "name": "Wood_Softwood_Planks_Half",
      "rotation": 4
    },
    {
      "x": 2,
      "y": 3,
      "z": 2,
      "name": "Wood_Deadwood_Planks"
    },
    {
      "x": 2,
      "y": 4,
      "z": 2,
      "name": "Wood_Deadwood_Planks"
    },
    {
      "x": 2,
      "y": 5,
      "z": 2,
      "name": "Plant_Moss_Rug_Green"
    },
    {
      "x": 2,
      "y": 6,
      "z": 2,
      "name": "Nat20_Force_Empty"
    },
    {
      "x": 2,
      "y": 7,
      "z": 2,
      "name": "Nat20_Force_Empty"
    },
    {
      "x": 2,
      "y": 0,
      "z": 3,
      "name": "Rock_Basalt"
    },
    {
      "x": 2,
      "y": 1,
      "z": 3,
      "name": "Nat20_Force_Empty"
    },
    {
      "x": 2,
      "y": 2,
      "z": 3,
      "name": "Nat20_Force_Empty"
    },
    {
      "x": 2,
      "y": 3,
      "z": 3,
      "name": "Plant_Moss_Wall_Green"
    },
    {
      "x": 2,
      "y": 4,
      "z": 3,
      "name": "Plant_Moss_Wall_Green"
    },
    {
      "x": 2,
      "y": 5,
      "z": 3,
      "name": "Nat20_Force_Empty"
    },
    {
      "x": 2,
      "y": 6,
      "z": 3,
      "name": "Nat20_Force_Empty"
    },
    {
      "x": 2,
      "y": 7,
      "z": 3,
      "name": "Nat20_Force_Empty"
    },
    {
      "x": 3,
      "y": 0,
      "z": -3,
      "name": "Rock_Basalt"
    },
    {
      "x": 3,
      "y": 1,
      "z": -3,
      "name": "Nat20_Force_Empty"
    },
    {
      "x": 3,
      "y": 2,
      "z": -3,
      "name": "Nat20_Force_Empty"
    },
    {
      "x": 3,
      "y": 3,
      "z": -3,
      "name": "Nat20_Force_Empty"
    },
    {
      "x": 3,
      "y": 4,
      "z": -3,
      "name": "Nat20_Force_Empty"
    },
    {
      "x": 3,
      "y": 5,
      "z": -3,
      "name": "Nat20_Force_Empty"
    },
    {
      "x": 3,
      "y": 6,
      "z": -3,
      "name": "Nat20_Force_Empty"
    },
    {
      "x": 3,
      "y": 7,
      "z": -3,
      "name": "Nat20_Force_Empty"
    },
    {
      "x": 3,
      "y": 0,
      "z": -2,
      "name": "Soil_Dirt_Burnt"
    },
    {
      "x": 3,
      "y": 1,
      "z": -2,
      "name": "Nat20_Force_Empty"
    },
    {
      "x": 3,
      "y": 2,
      "z": -2,
      "name": "Nat20_Force_Empty"
    },
    {
      "x": 3,
      "y": 3,
      "z": -2,
      "name": "Nat20_Force_Empty"
    },
    {
      "x": 3,
      "y": 4,
      "z": -2,
      "name": "Wood_Deadwood_Planks_Half",
      "rotation": 5
    },
    {
      "x": 3,
      "y": 5,
      "z": -2,
      "name": "Nat20_Force_Empty"
    },
    {
      "x": 3,
      "y": 6,
      "z": -2,
      "name": "Nat20_Force_Empty"
    },
    {
      "x": 3,
      "y": 7,
      "z": -2,
      "name": "Nat20_Force_Empty"
    },
    {
      "x": 3,
      "y": 0,
      "z": -1,
      "name": "Soil_Dirt_Burnt"
    },
    {
      "x": 3,
      "y": 1,
      "z": -1,
      "name": "Nat20_Force_Empty"
    },
    {
      "x": 3,
      "y": 2,
      "z": -1,
      "name": "Nat20_Force_Empty"
    },
    {
      "x": 3,
      "y": 3,
      "z": -1,
      "name": "Nat20_Force_Empty"
    },
    {
      "x": 3,
      "y": 4,
      "z": -1,
      "name": "Cloth_Roof_Hide_Flap",
      "rotation": 1
    },
    {
      "x": 3,
      "y": 5,
      "z": -1,
      "name": "Nat20_Force_Empty"
    },
    {
      "x": 3,
      "y": 6,
      "z": -1,
      "name": "Nat20_Force_Empty"
    },
    {
      "x": 3,
      "y": 7,
      "z": -1,
      "name": "Nat20_Force_Empty"
    },
    {
      "x": 3,
      "y": 0,
      "z": 0,
      "name": "Rock_Basalt"
    },
    {
      "x": 3,
      "y": 1,
      "z": 0,
      "name": "Nat20_Force_Empty"
    },
    {
      "x": 3,
      "y": 2,
      "z": 0,
      "name": "Nat20_Force_Empty"
    },
    {
      "x": 3,
      "y": 3,
      "z": 0,
      "name": "Nat20_Force_Empty"
    },
    {
      "x": 3,
      "y": 4,
      "z": 0,
      "name": "Wood_Deadwood_Planks_Half",
      "rotation": 5
    },
    {
      "x": 3,
      "y": 5,
      "z": 0,
      "name": "Nat20_Force_Empty"
    },
    {
      "x": 3,
      "y": 6,
      "z": 0,
      "name": "Nat20_Force_Empty"
    },
    {
      "x": 3,
      "y": 7,
      "z": 0,
      "name": "Nat20_Force_Empty"
    },
    {
      "x": 3,
      "y": 0,
      "z": 1,
      "name": "Rock_Basalt"
    },
    {
      "x": 3,
      "y": 1,
      "z": 1,
      "name": "Nat20_Force_Empty"
    },
    {
      "x": 3,
      "y": 2,
      "z": 1,
      "name": "Nat20_Force_Empty"
    },
    {
      "x": 3,
      "y": 3,
      "z": 1,
      "name": "Nat20_Force_Empty"
    },
    {
      "x": 3,
      "y": 4,
      "z": 1,
      "name": "Plant_Moss_Wall_Green",
      "rotation": 1
    },
    {
      "x": 3,
      "y": 5,
      "z": 1,
      "name": "Nat20_Force_Empty"
    },
    {
      "x": 3,
      "y": 6,
      "z": 1,
      "name": "Nat20_Force_Empty"
    },
    {
      "x": 3,
      "y": 7,
      "z": 1,
      "name": "Nat20_Force_Empty"
    },
    {
      "x": 3,
      "y": 0,
      "z": 2,
      "name": "Rock_Basalt"
    },
    {
      "x": 3,
      "y": 1,
      "z": 2,
      "name": "Rubble_Basalt"
    },
    {
      "x": 3,
      "y": 2,
      "z": 2,
      "name": "Nat20_Force_Empty"
    },
    {
      "x": 3,
      "y": 3,
      "z": 2,
      "name": "Plant_Moss_Wall_Green",
      "rotation": 1
    },
    {
      "x": 3,
      "y": 4,
      "z": 2,
      "name": "Plant_Moss_Wall_Green",
      "rotation": 1
    },
    {
      "x": 3,
      "y": 5,
      "z": 2,
      "name": "Nat20_Force_Empty"
    },
    {
      "x": 3,
      "y": 6,
      "z": 2,
      "name": "Nat20_Force_Empty"
    },
    {
      "x": 3,
      "y": 7,
      "z": 2,
      "name": "Nat20_Force_Empty"
    },
    {
      "x": 3,
      "y": 0,
      "z": 3,
      "name": "Rock_Basalt"
    },
    {
      "x": 3,
      "y": 1,
      "z": 3,
      "name": "Nat20_Force_Empty"
    },
    {
      "x": 3,
      "y": 2,
      "z": 3,
      "name": "Nat20_Force_Empty"
    },
    {
      "x": 3,
      "y": 3,
      "z": 3,
      "name": "Nat20_Force_Empty"
    },
    {
      "x": 3,
      "y": 4,
      "z": 3,
      "name": "Nat20_Force_Empty"
    },
    {
      "x": 3,
      "y": 5,
      "z": 3,
      "name": "Nat20_Force_Empty"
    },
    {
      "x": 3,
      "y": 6,
      "z": 3,
      "name": "Nat20_Force_Empty"
    },
    {
      "x": 3,
      "y": 7,
      "z": 3,
      "name": "Nat20_Force_Empty"
    }
  ],
  "fluids": [
    {
      "x": -3,
      "y": 0,
      "z": 0,
      "name": "Empty",
      "level": 0
    },
    {
      "x": -3,
      "y": 1,
      "z": 0,
      "name": "Empty",
      "level": 0
    },
    {
      "x": -3,
      "y": 0,
      "z": 1,
      "name": "Empty",
      "level": 0
    },
    {
      "x": -3,
      "y": 1,
      "z": 1,
      "name": "Empty",
      "level": 0
    },
    {
      "x": -3,
      "y": 2,
      "z": 1,
      "name": "Empty",
      "level": 0
    },
    {
      "x": -3,
      "y": 0,
      "z": 2,
      "name": "Empty",
      "level": 0
    },
    {
      "x": -2,
      "y": 0,
      "z": -3,
      "name": "Empty",
      "level": 0
    },
    {
      "x": -2,
      "y": 1,
      "z": -3,
      "name": "Empty",
      "level": 0
    },
    {
      "x": -2,
      "y": 2,
      "z": -3,
      "name": "Empty",
      "level": 0
    },
    {
      "x": -2,
      "y": 3,
      "z": -3,
      "name": "Empty",
      "level": 0
    },
    {
      "x": -2,
      "y": 4,
      "z": -3,
      "name": "Empty",
      "level": 0
    },
    {
      "x": -2,
      "y": 5,
      "z": -3,
      "name": "Empty",
      "level": 0
    },
    {
      "x": -2,
      "y": 6,
      "z": -3,
      "name": "Empty",
      "level": 0
    },
    {
      "x": -2,
      "y": 7,
      "z": -3,
      "name": "Empty",
      "level": 0
    },
    {
      "x": -2,
      "y": 0,
      "z": -2,
      "name": "Empty",
      "level": 0
    },
    {
      "x": -2,
      "y": 1,
      "z": -2,
      "name": "Empty",
      "level": 0
    },
    {
      "x": -2,
      "y": 2,
      "z": -2,
      "name": "Empty",
      "level": 0
    },
    {
      "x": -2,
      "y": 3,
      "z": -2,
      "name": "Empty",
      "level": 0
    },
    {
      "x": -2,
      "y": 4,
      "z": -2,
      "name": "Empty",
      "level": 0
    },
    {
      "x": -2,
      "y": 5,
      "z": -2,
      "name": "Empty",
      "level": 0
    },
    {
      "x": -2,
      "y": 6,
      "z": -2,
      "name": "Empty",
      "level": 0
    },
    {
      "x": -2,
      "y": 7,
      "z": -2,
      "name": "Empty",
      "level": 0
    },
    {
      "x": -2,
      "y": 0,
      "z": -1,
      "name": "Empty",
      "level": 0
    },
    {
      "x": -2,
      "y": 1,
      "z": -1,
      "name": "Empty",
      "level": 0
    },
    {
      "x": -2,
      "y": 2,
      "z": -1,
      "name": "Empty",
      "level": 0
    },
    {
      "x": -2,
      "y": 3,
      "z": -1,
      "name": "Empty",
      "level": 0
    },
    {
      "x": -2,
      "y": 4,
      "z": -1,
      "name": "Empty",
      "level": 0
    },
    {
      "x": -2,
      "y": 5,
      "z": -1,
      "name": "Empty",
      "level": 0
    },
    {
      "x": -2,
      "y": 6,
      "z": -1,
      "name": "Empty",
      "level": 0
    },
    {
      "x": -2,
      "y": 7,
      "z": -1,
      "name": "Empty",
      "level": 0
    },
    {
      "x": -2,
      "y": 0,
      "z": 0,
      "name": "Empty",
      "level": 0
    },
    {
      "x": -2,
      "y": 1,
      "z": 0,
      "name": "Empty",
      "level": 0
    },
    {
      "x": -2,
      "y": 2,
      "z": 0,
      "name": "Empty",
      "level": 0
    },
    {
      "x": -2,
      "y": 3,
      "z": 0,
      "name": "Empty",
      "level": 0
    },
    {
      "x": -2,
      "y": 4,
      "z": 0,
      "name": "Empty",
      "level": 0
    },
    {
      "x": -2,
      "y": 5,
      "z": 0,
      "name": "Empty",
      "level": 0
    },
    {
      "x": -2,
      "y": 6,
      "z": 0,
      "name": "Empty",
      "level": 0
    },
    {
      "x": -2,
      "y": 7,
      "z": 0,
      "name": "Empty",
      "level": 0
    },
    {
      "x": -2,
      "y": 0,
      "z": 1,
      "name": "Empty",
      "level": 0
    },
    {
      "x": -2,
      "y": 1,
      "z": 1,
      "name": "Empty",
      "level": 0
    },
    {
      "x": -2,
      "y": 2,
      "z": 1,
      "name": "Empty",
      "level": 0
    },
    {
      "x": -2,
      "y": 3,
      "z": 1,
      "name": "Empty",
      "level": 0
    },
    {
      "x": -2,
      "y": 4,
      "z": 1,
      "name": "Empty",
      "level": 0
    },
    {
      "x": -2,
      "y": 5,
      "z": 1,
      "name": "Empty",
      "level": 0
    },
    {
      "x": -2,
      "y": 6,
      "z": 1,
      "name": "Empty",
      "level": 0
    },
    {
      "x": -2,
      "y": 7,
      "z": 1,
      "name": "Empty",
      "level": 0
    },
    {
      "x": -2,
      "y": 0,
      "z": 2,
      "name": "Empty",
      "level": 0
    },
    {
      "x": -2,
      "y": 1,
      "z": 2,
      "name": "Empty",
      "level": 0
    },
    {
      "x": -2,
      "y": 2,
      "z": 2,
      "name": "Empty",
      "level": 0
    },
    {
      "x": -2,
      "y": 3,
      "z": 2,
      "name": "Empty",
      "level": 0
    },
    {
      "x": -2,
      "y": 4,
      "z": 2,
      "name": "Empty",
      "level": 0
    },
    {
      "x": -2,
      "y": 5,
      "z": 2,
      "name": "Empty",
      "level": 0
    },
    {
      "x": -2,
      "y": 6,
      "z": 2,
      "name": "Empty",
      "level": 0
    },
    {
      "x": -2,
      "y": 7,
      "z": 2,
      "name": "Empty",
      "level": 0
    },
    {
      "x": -2,
      "y": 0,
      "z": 3,
      "name": "Empty",
      "level": 0
    },
    {
      "x": -2,
      "y": 1,
      "z": 3,
      "name": "Empty",
      "level": 0
    },
    {
      "x": -2,
      "y": 2,
      "z": 3,
      "name": "Empty",
      "level": 0
    },
    {
      "x": -2,
      "y": 3,
      "z": 3,
      "name": "Empty",
      "level": 0
    },
    {
      "x": -2,
      "y": 4,
      "z": 3,
      "name": "Empty",
      "level": 0
    },
    {
      "x": -2,
      "y": 5,
      "z": 3,
      "name": "Empty",
      "level": 0
    },
    {
      "x": -2,
      "y": 6,
      "z": 3,
      "name": "Empty",
      "level": 0
    },
    {
      "x": -2,
      "y": 7,
      "z": 3,
      "name": "Empty",
      "level": 0
    },
    {
      "x": -1,
      "y": 0,
      "z": -3,
      "name": "Empty",
      "level": 0
    },
    {
      "x": -1,
      "y": 1,
      "z": -3,
      "name": "Empty",
      "level": 0
    },
    {
      "x": -1,
      "y": 2,
      "z": -3,
      "name": "Empty",
      "level": 0
    },
    {
      "x": -1,
      "y": 3,
      "z": -3,
      "name": "Empty",
      "level": 0
    },
    {
      "x": -1,
      "y": 4,
      "z": -3,
      "name": "Empty",
      "level": 0
    },
    {
      "x": -1,
      "y": 5,
      "z": -3,
      "name": "Empty",
      "level": 0
    },
    {
      "x": -1,
      "y": 6,
      "z": -3,
      "name": "Empty",
      "level": 0
    },
    {
      "x": -1,
      "y": 7,
      "z": -3,
      "name": "Empty",
      "level": 0
    },
    {
      "x": -1,
      "y": 0,
      "z": -2,
      "name": "Empty",
      "level": 0
    },
    {
      "x": -1,
      "y": 1,
      "z": -2,
      "name": "Empty",
      "level": 0
    },
    {
      "x": -1,
      "y": 2,
      "z": -2,
      "name": "Empty",
      "level": 0
    },
    {
      "x": -1,
      "y": 3,
      "z": -2,
      "name": "Empty",
      "level": 0
    },
    {
      "x": -1,
      "y": 4,
      "z": -2,
      "name": "Empty",
      "level": 0
    },
    {
      "x": -1,
      "y": 5,
      "z": -2,
      "name": "Empty",
      "level": 0
    },
    {
      "x": -1,
      "y": 6,
      "z": -2,
      "name": "Empty",
      "level": 0
    },
    {
      "x": -1,
      "y": 7,
      "z": -2,
      "name": "Empty",
      "level": 0
    },
    {
      "x": -1,
      "y": 0,
      "z": -1,
      "name": "Empty",
      "level": 0
    },
    {
      "x": -1,
      "y": 1,
      "z": -1,
      "name": "Empty",
      "level": 0
    },
    {
      "x": -1,
      "y": 2,
      "z": -1,
      "name": "Empty",
      "level": 0
    },
    {
      "x": -1,
      "y": 3,
      "z": -1,
      "name": "Empty",
      "level": 0
    },
    {
      "x": -1,
      "y": 4,
      "z": -1,
      "name": "Empty",
      "level": 0
    },
    {
      "x": -1,
      "y": 5,
      "z": -1,
      "name": "Empty",
      "level": 0
    },
    {
      "x": -1,
      "y": 6,
      "z": -1,
      "name": "Empty",
      "level": 0
    },
    {
      "x": -1,
      "y": 7,
      "z": -1,
      "name": "Empty",
      "level": 0
    },
    {
      "x": -1,
      "y": 0,
      "z": 0,
      "name": "Empty",
      "level": 0
    },
    {
      "x": -1,
      "y": 1,
      "z": 0,
      "name": "Empty",
      "level": 0
    },
    {
      "x": -1,
      "y": 2,
      "z": 0,
      "name": "Empty",
      "level": 0
    },
    {
      "x": -1,
      "y": 3,
      "z": 0,
      "name": "Empty",
      "level": 0
    },
    {
      "x": -1,
      "y": 4,
      "z": 0,
      "name": "Empty",
      "level": 0
    },
    {
      "x": -1,
      "y": 5,
      "z": 0,
      "name": "Empty",
      "level": 0
    },
    {
      "x": -1,
      "y": 6,
      "z": 0,
      "name": "Empty",
      "level": 0
    },
    {
      "x": -1,
      "y": 7,
      "z": 0,
      "name": "Empty",
      "level": 0
    },
    {
      "x": -1,
      "y": 0,
      "z": 1,
      "name": "Empty",
      "level": 0
    },
    {
      "x": -1,
      "y": 1,
      "z": 1,
      "name": "Empty",
      "level": 0
    },
    {
      "x": -1,
      "y": 2,
      "z": 1,
      "name": "Empty",
      "level": 0
    },
    {
      "x": -1,
      "y": 3,
      "z": 1,
      "name": "Empty",
      "level": 0
    },
    {
      "x": -1,
      "y": 4,
      "z": 1,
      "name": "Empty",
      "level": 0
    },
    {
      "x": -1,
      "y": 5,
      "z": 1,
      "name": "Empty",
      "level": 0
    },
    {
      "x": -1,
      "y": 6,
      "z": 1,
      "name": "Empty",
      "level": 0
    },
    {
      "x": -1,
      "y": 7,
      "z": 1,
      "name": "Empty",
      "level": 0
    },
    {
      "x": -1,
      "y": 0,
      "z": 2,
      "name": "Empty",
      "level": 0
    },
    {
      "x": -1,
      "y": 1,
      "z": 2,
      "name": "Empty",
      "level": 0
    },
    {
      "x": -1,
      "y": 2,
      "z": 2,
      "name": "Empty",
      "level": 0
    },
    {
      "x": -1,
      "y": 3,
      "z": 2,
      "name": "Empty",
      "level": 0
    },
    {
      "x": -1,
      "y": 4,
      "z": 2,
      "name": "Empty",
      "level": 0
    },
    {
      "x": -1,
      "y": 5,
      "z": 2,
      "name": "Empty",
      "level": 0
    },
    {
      "x": -1,
      "y": 6,
      "z": 2,
      "name": "Empty",
      "level": 0
    },
    {
      "x": -1,
      "y": 7,
      "z": 2,
      "name": "Empty",
      "level": 0
    },
    {
      "x": -1,
      "y": 0,
      "z": 3,
      "name": "Empty",
      "level": 0
    },
    {
      "x": -1,
      "y": 1,
      "z": 3,
      "name": "Empty",
      "level": 0
    },
    {
      "x": -1,
      "y": 2,
      "z": 3,
      "name": "Empty",
      "level": 0
    },
    {
      "x": -1,
      "y": 3,
      "z": 3,
      "name": "Empty",
      "level": 0
    },
    {
      "x": -1,
      "y": 4,
      "z": 3,
      "name": "Empty",
      "level": 0
    },
    {
      "x": -1,
      "y": 5,
      "z": 3,
      "name": "Empty",
      "level": 0
    },
    {
      "x": -1,
      "y": 6,
      "z": 3,
      "name": "Empty",
      "level": 0
    },
    {
      "x": -1,
      "y": 7,
      "z": 3,
      "name": "Empty",
      "level": 0
    },
    {
      "x": 0,
      "y": 0,
      "z": -3,
      "name": "Empty",
      "level": 0
    },
    {
      "x": 0,
      "y": 1,
      "z": -3,
      "name": "Empty",
      "level": 0
    },
    {
      "x": 0,
      "y": 2,
      "z": -3,
      "name": "Empty",
      "level": 0
    },
    {
      "x": 0,
      "y": 3,
      "z": -3,
      "name": "Empty",
      "level": 0
    },
    {
      "x": 0,
      "y": 4,
      "z": -3,
      "name": "Empty",
      "level": 0
    },
    {
      "x": 0,
      "y": 5,
      "z": -3,
      "name": "Empty",
      "level": 0
    },
    {
      "x": 0,
      "y": 6,
      "z": -3,
      "name": "Empty",
      "level": 0
    },
    {
      "x": 0,
      "y": 7,
      "z": -3,
      "name": "Empty",
      "level": 0
    },
    {
      "x": 0,
      "y": 0,
      "z": -2,
      "name": "Empty",
      "level": 0
    },
    {
      "x": 0,
      "y": 1,
      "z": -2,
      "name": "Empty",
      "level": 0
    },
    {
      "x": 0,
      "y": 2,
      "z": -2,
      "name": "Empty",
      "level": 0
    },
    {
      "x": 0,
      "y": 3,
      "z": -2,
      "name": "Empty",
      "level": 0
    },
    {
      "x": 0,
      "y": 4,
      "z": -2,
      "name": "Empty",
      "level": 0
    },
    {
      "x": 0,
      "y": 5,
      "z": -2,
      "name": "Empty",
      "level": 0
    },
    {
      "x": 0,
      "y": 6,
      "z": -2,
      "name": "Empty",
      "level": 0
    },
    {
      "x": 0,
      "y": 7,
      "z": -2,
      "name": "Empty",
      "level": 0
    },
    {
      "x": 0,
      "y": 0,
      "z": -1,
      "name": "Empty",
      "level": 0
    },
    {
      "x": 0,
      "y": 1,
      "z": -1,
      "name": "Empty",
      "level": 0
    },
    {
      "x": 0,
      "y": 2,
      "z": -1,
      "name": "Empty",
      "level": 0
    },
    {
      "x": 0,
      "y": 3,
      "z": -1,
      "name": "Empty",
      "level": 0
    },
    {
      "x": 0,
      "y": 4,
      "z": -1,
      "name": "Empty",
      "level": 0
    },
    {
      "x": 0,
      "y": 5,
      "z": -1,
      "name": "Empty",
      "level": 0
    },
    {
      "x": 0,
      "y": 6,
      "z": -1,
      "name": "Empty",
      "level": 0
    },
    {
      "x": 0,
      "y": 7,
      "z": -1,
      "name": "Empty",
      "level": 0
    },
    {
      "x": 0,
      "y": 0,
      "z": 0,
      "name": "Empty",
      "level": 0
    },
    {
      "x": 0,
      "y": 1,
      "z": 0,
      "name": "Empty",
      "level": 0
    },
    {
      "x": 0,
      "y": 2,
      "z": 0,
      "name": "Empty",
      "level": 0
    },
    {
      "x": 0,
      "y": 3,
      "z": 0,
      "name": "Empty",
      "level": 0
    },
    {
      "x": 0,
      "y": 4,
      "z": 0,
      "name": "Empty",
      "level": 0
    },
    {
      "x": 0,
      "y": 5,
      "z": 0,
      "name": "Empty",
      "level": 0
    },
    {
      "x": 0,
      "y": 6,
      "z": 0,
      "name": "Empty",
      "level": 0
    },
    {
      "x": 0,
      "y": 7,
      "z": 0,
      "name": "Empty",
      "level": 0
    },
    {
      "x": 0,
      "y": 0,
      "z": 1,
      "name": "Empty",
      "level": 0
    },
    {
      "x": 0,
      "y": 1,
      "z": 1,
      "name": "Empty",
      "level": 0
    },
    {
      "x": 0,
      "y": 2,
      "z": 1,
      "name": "Empty",
      "level": 0
    },
    {
      "x": 0,
      "y": 3,
      "z": 1,
      "name": "Empty",
      "level": 0
    },
    {
      "x": 0,
      "y": 4,
      "z": 1,
      "name": "Empty",
      "level": 0
    },
    {
      "x": 0,
      "y": 5,
      "z": 1,
      "name": "Empty",
      "level": 0
    },
    {
      "x": 0,
      "y": 6,
      "z": 1,
      "name": "Empty",
      "level": 0
    },
    {
      "x": 0,
      "y": 7,
      "z": 1,
      "name": "Empty",
      "level": 0
    },
    {
      "x": 0,
      "y": 0,
      "z": 2,
      "name": "Empty",
      "level": 0
    },
    {
      "x": 0,
      "y": 1,
      "z": 2,
      "name": "Empty",
      "level": 0
    },
    {
      "x": 0,
      "y": 2,
      "z": 2,
      "name": "Empty",
      "level": 0
    },
    {
      "x": 0,
      "y": 3,
      "z": 2,
      "name": "Empty",
      "level": 0
    },
    {
      "x": 0,
      "y": 4,
      "z": 2,
      "name": "Empty",
      "level": 0
    },
    {
      "x": 0,
      "y": 5,
      "z": 2,
      "name": "Empty",
      "level": 0
    },
    {
      "x": 0,
      "y": 6,
      "z": 2,
      "name": "Empty",
      "level": 0
    },
    {
      "x": 0,
      "y": 7,
      "z": 2,
      "name": "Empty",
      "level": 0
    },
    {
      "x": 0,
      "y": 0,
      "z": 3,
      "name": "Empty",
      "level": 0
    },
    {
      "x": 0,
      "y": 1,
      "z": 3,
      "name": "Empty",
      "level": 0
    },
    {
      "x": 0,
      "y": 2,
      "z": 3,
      "name": "Empty",
      "level": 0
    },
    {
      "x": 0,
      "y": 3,
      "z": 3,
      "name": "Empty",
      "level": 0
    },
    {
      "x": 0,
      "y": 4,
      "z": 3,
      "name": "Empty",
      "level": 0
    },
    {
      "x": 0,
      "y": 5,
      "z": 3,
      "name": "Empty",
      "level": 0
    },
    {
      "x": 0,
      "y": 6,
      "z": 3,
      "name": "Empty",
      "level": 0
    },
    {
      "x": 0,
      "y": 7,
      "z": 3,
      "name": "Empty",
      "level": 0
    },
    {
      "x": 1,
      "y": 0,
      "z": -3,
      "name": "Empty",
      "level": 0
    },
    {
      "x": 1,
      "y": 1,
      "z": -3,
      "name": "Empty",
      "level": 0
    },
    {
      "x": 1,
      "y": 2,
      "z": -3,
      "name": "Empty",
      "level": 0
    },
    {
      "x": 1,
      "y": 3,
      "z": -3,
      "name": "Empty",
      "level": 0
    },
    {
      "x": 1,
      "y": 4,
      "z": -3,
      "name": "Empty",
      "level": 0
    },
    {
      "x": 1,
      "y": 5,
      "z": -3,
      "name": "Empty",
      "level": 0
    },
    {
      "x": 1,
      "y": 6,
      "z": -3,
      "name": "Empty",
      "level": 0
    },
    {
      "x": 1,
      "y": 7,
      "z": -3,
      "name": "Empty",
      "level": 0
    },
    {
      "x": 1,
      "y": 0,
      "z": -2,
      "name": "Empty",
      "level": 0
    },
    {
      "x": 1,
      "y": 1,
      "z": -2,
      "name": "Empty",
      "level": 0
    },
    {
      "x": 1,
      "y": 2,
      "z": -2,
      "name": "Empty",
      "level": 0
    },
    {
      "x": 1,
      "y": 3,
      "z": -2,
      "name": "Empty",
      "level": 0
    },
    {
      "x": 1,
      "y": 4,
      "z": -2,
      "name": "Empty",
      "level": 0
    },
    {
      "x": 1,
      "y": 5,
      "z": -2,
      "name": "Empty",
      "level": 0
    },
    {
      "x": 1,
      "y": 6,
      "z": -2,
      "name": "Empty",
      "level": 0
    },
    {
      "x": 1,
      "y": 7,
      "z": -2,
      "name": "Empty",
      "level": 0
    },
    {
      "x": 1,
      "y": 0,
      "z": -1,
      "name": "Empty",
      "level": 0
    },
    {
      "x": 1,
      "y": 1,
      "z": -1,
      "name": "Empty",
      "level": 0
    },
    {
      "x": 1,
      "y": 2,
      "z": -1,
      "name": "Empty",
      "level": 0
    },
    {
      "x": 1,
      "y": 3,
      "z": -1,
      "name": "Empty",
      "level": 0
    },
    {
      "x": 1,
      "y": 4,
      "z": -1,
      "name": "Empty",
      "level": 0
    },
    {
      "x": 1,
      "y": 5,
      "z": -1,
      "name": "Empty",
      "level": 0
    },
    {
      "x": 1,
      "y": 6,
      "z": -1,
      "name": "Empty",
      "level": 0
    },
    {
      "x": 1,
      "y": 7,
      "z": -1,
      "name": "Empty",
      "level": 0
    },
    {
      "x": 1,
      "y": 0,
      "z": 0,
      "name": "Empty",
      "level": 0
    },
    {
      "x": 1,
      "y": 1,
      "z": 0,
      "name": "Empty",
      "level": 0
    },
    {
      "x": 1,
      "y": 2,
      "z": 0,
      "name": "Empty",
      "level": 0
    },
    {
      "x": 1,
      "y": 3,
      "z": 0,
      "name": "Empty",
      "level": 0
    },
    {
      "x": 1,
      "y": 4,
      "z": 0,
      "name": "Empty",
      "level": 0
    },
    {
      "x": 1,
      "y": 5,
      "z": 0,
      "name": "Empty",
      "level": 0
    },
    {
      "x": 1,
      "y": 6,
      "z": 0,
      "name": "Empty",
      "level": 0
    },
    {
      "x": 1,
      "y": 7,
      "z": 0,
      "name": "Empty",
      "level": 0
    },
    {
      "x": 1,
      "y": 0,
      "z": 1,
      "name": "Empty",
      "level": 0
    },
    {
      "x": 1,
      "y": 1,
      "z": 1,
      "name": "Empty",
      "level": 0
    },
    {
      "x": 1,
      "y": 2,
      "z": 1,
      "name": "Empty",
      "level": 0
    },
    {
      "x": 1,
      "y": 3,
      "z": 1,
      "name": "Empty",
      "level": 0
    },
    {
      "x": 1,
      "y": 4,
      "z": 1,
      "name": "Empty",
      "level": 0
    },
    {
      "x": 1,
      "y": 5,
      "z": 1,
      "name": "Empty",
      "level": 0
    },
    {
      "x": 1,
      "y": 6,
      "z": 1,
      "name": "Empty",
      "level": 0
    },
    {
      "x": 1,
      "y": 7,
      "z": 1,
      "name": "Empty",
      "level": 0
    },
    {
      "x": 1,
      "y": 0,
      "z": 2,
      "name": "Empty",
      "level": 0
    },
    {
      "x": 1,
      "y": 1,
      "z": 2,
      "name": "Empty",
      "level": 0
    },
    {
      "x": 1,
      "y": 2,
      "z": 2,
      "name": "Empty",
      "level": 0
    },
    {
      "x": 1,
      "y": 3,
      "z": 2,
      "name": "Empty",
      "level": 0
    },
    {
      "x": 1,
      "y": 4,
      "z": 2,
      "name": "Empty",
      "level": 0
    },
    {
      "x": 1,
      "y": 5,
      "z": 2,
      "name": "Empty",
      "level": 0
    },
    {
      "x": 1,
      "y": 6,
      "z": 2,
      "name": "Empty",
      "level": 0
    },
    {
      "x": 1,
      "y": 7,
      "z": 2,
      "name": "Empty",
      "level": 0
    },
    {
      "x": 1,
      "y": 0,
      "z": 3,
      "name": "Empty",
      "level": 0
    },
    {
      "x": 1,
      "y": 1,
      "z": 3,
      "name": "Empty",
      "level": 0
    },
    {
      "x": 1,
      "y": 2,
      "z": 3,
      "name": "Empty",
      "level": 0
    },
    {
      "x": 1,
      "y": 3,
      "z": 3,
      "name": "Empty",
      "level": 0
    },
    {
      "x": 1,
      "y": 4,
      "z": 3,
      "name": "Empty",
      "level": 0
    },
    {
      "x": 1,
      "y": 5,
      "z": 3,
      "name": "Empty",
      "level": 0
    },
    {
      "x": 1,
      "y": 6,
      "z": 3,
      "name": "Empty",
      "level": 0
    },
    {
      "x": 1,
      "y": 7,
      "z": 3,
      "name": "Empty",
      "level": 0
    },
    {
      "x": 2,
      "y": 0,
      "z": -3,
      "name": "Empty",
      "level": 0
    },
    {
      "x": 2,
      "y": 1,
      "z": -3,
      "name": "Empty",
      "level": 0
    },
    {
      "x": 2,
      "y": 2,
      "z": -3,
      "name": "Empty",
      "level": 0
    },
    {
      "x": 2,
      "y": 3,
      "z": -3,
      "name": "Empty",
      "level": 0
    },
    {
      "x": 2,
      "y": 4,
      "z": -3,
      "name": "Empty",
      "level": 0
    },
    {
      "x": 2,
      "y": 5,
      "z": -3,
      "name": "Empty",
      "level": 0
    },
    {
      "x": 2,
      "y": 6,
      "z": -3,
      "name": "Empty",
      "level": 0
    },
    {
      "x": 2,
      "y": 7,
      "z": -3,
      "name": "Empty",
      "level": 0
    },
    {
      "x": 2,
      "y": 0,
      "z": -2,
      "name": "Empty",
      "level": 0
    },
    {
      "x": 2,
      "y": 1,
      "z": -2,
      "name": "Empty",
      "level": 0
    },
    {
      "x": 2,
      "y": 2,
      "z": -2,
      "name": "Empty",
      "level": 0
    },
    {
      "x": 2,
      "y": 3,
      "z": -2,
      "name": "Empty",
      "level": 0
    },
    {
      "x": 2,
      "y": 4,
      "z": -2,
      "name": "Empty",
      "level": 0
    },
    {
      "x": 2,
      "y": 5,
      "z": -2,
      "name": "Empty",
      "level": 0
    },
    {
      "x": 2,
      "y": 6,
      "z": -2,
      "name": "Empty",
      "level": 0
    },
    {
      "x": 2,
      "y": 7,
      "z": -2,
      "name": "Empty",
      "level": 0
    },
    {
      "x": 2,
      "y": 0,
      "z": -1,
      "name": "Empty",
      "level": 0
    },
    {
      "x": 2,
      "y": 1,
      "z": -1,
      "name": "Empty",
      "level": 0
    },
    {
      "x": 2,
      "y": 2,
      "z": -1,
      "name": "Empty",
      "level": 0
    },
    {
      "x": 2,
      "y": 3,
      "z": -1,
      "name": "Empty",
      "level": 0
    },
    {
      "x": 2,
      "y": 4,
      "z": -1,
      "name": "Empty",
      "level": 0
    },
    {
      "x": 2,
      "y": 5,
      "z": -1,
      "name": "Empty",
      "level": 0
    },
    {
      "x": 2,
      "y": 6,
      "z": -1,
      "name": "Empty",
      "level": 0
    },
    {
      "x": 2,
      "y": 7,
      "z": -1,
      "name": "Empty",
      "level": 0
    },
    {
      "x": 2,
      "y": 0,
      "z": 0,
      "name": "Empty",
      "level": 0
    },
    {
      "x": 2,
      "y": 1,
      "z": 0,
      "name": "Empty",
      "level": 0
    },
    {
      "x": 2,
      "y": 2,
      "z": 0,
      "name": "Empty",
      "level": 0
    },
    {
      "x": 2,
      "y": 3,
      "z": 0,
      "name": "Empty",
      "level": 0
    },
    {
      "x": 2,
      "y": 4,
      "z": 0,
      "name": "Empty",
      "level": 0
    },
    {
      "x": 2,
      "y": 5,
      "z": 0,
      "name": "Empty",
      "level": 0
    },
    {
      "x": 2,
      "y": 6,
      "z": 0,
      "name": "Empty",
      "level": 0
    },
    {
      "x": 2,
      "y": 7,
      "z": 0,
      "name": "Empty",
      "level": 0
    },
    {
      "x": 2,
      "y": 0,
      "z": 1,
      "name": "Empty",
      "level": 0
    },
    {
      "x": 2,
      "y": 1,
      "z": 1,
      "name": "Empty",
      "level": 0
    },
    {
      "x": 2,
      "y": 2,
      "z": 1,
      "name": "Empty",
      "level": 0
    },
    {
      "x": 2,
      "y": 3,
      "z": 1,
      "name": "Empty",
      "level": 0
    },
    {
      "x": 2,
      "y": 4,
      "z": 1,
      "name": "Empty",
      "level": 0
    },
    {
      "x": 2,
      "y": 5,
      "z": 1,
      "name": "Empty",
      "level": 0
    },
    {
      "x": 2,
      "y": 6,
      "z": 1,
      "name": "Empty",
      "level": 0
    },
    {
      "x": 2,
      "y": 7,
      "z": 1,
      "name": "Empty",
      "level": 0
    },
    {
      "x": 2,
      "y": 0,
      "z": 2,
      "name": "Empty",
      "level": 0
    },
    {
      "x": 2,
      "y": 1,
      "z": 2,
      "name": "Empty",
      "level": 0
    },
    {
      "x": 2,
      "y": 2,
      "z": 2,
      "name": "Empty",
      "level": 0
    },
    {
      "x": 2,
      "y": 3,
      "z": 2,
      "name": "Empty",
      "level": 0
    },
    {
      "x": 2,
      "y": 4,
      "z": 2,
      "name": "Empty",
      "level": 0
    },
    {
      "x": 2,
      "y": 5,
      "z": 2,
      "name": "Empty",
      "level": 0
    },
    {
      "x": 2,
      "y": 6,
      "z": 2,
      "name": "Empty",
      "level": 0
    },
    {
      "x": 2,
      "y": 7,
      "z": 2,
      "name": "Empty",
      "level": 0
    },
    {
      "x": 2,
      "y": 0,
      "z": 3,
      "name": "Empty",
      "level": 0
    },
    {
      "x": 2,
      "y": 1,
      "z": 3,
      "name": "Empty",
      "level": 0
    },
    {
      "x": 2,
      "y": 2,
      "z": 3,
      "name": "Empty",
      "level": 0
    },
    {
      "x": 2,
      "y": 3,
      "z": 3,
      "name": "Empty",
      "level": 0
    },
    {
      "x": 2,
      "y": 4,
      "z": 3,
      "name": "Empty",
      "level": 0
    },
    {
      "x": 2,
      "y": 5,
      "z": 3,
      "name": "Empty",
      "level": 0
    },
    {
      "x": 2,
      "y": 6,
      "z": 3,
      "name": "Empty",
      "level": 0
    },
    {
      "x": 2,
      "y": 7,
      "z": 3,
      "name": "Empty",
      "level": 0
    },
    {
      "x": 3,
      "y": 0,
      "z": -3,
      "name": "Empty",
      "level": 0
    },
    {
      "x": 3,
      "y": 1,
      "z": -3,
      "name": "Empty",
      "level": 0
    },
    {
      "x": 3,
      "y": 2,
      "z": -3,
      "name": "Empty",
      "level": 0
    },
    {
      "x": 3,
      "y": 3,
      "z": -3,
      "name": "Empty",
      "level": 0
    },
    {
      "x": 3,
      "y": 4,
      "z": -3,
      "name": "Empty",
      "level": 0
    },
    {
      "x": 3,
      "y": 5,
      "z": -3,
      "name": "Empty",
      "level": 0
    },
    {
      "x": 3,
      "y": 6,
      "z": -3,
      "name": "Empty",
      "level": 0
    },
    {
      "x": 3,
      "y": 7,
      "z": -3,
      "name": "Empty",
      "level": 0
    },
    {
      "x": 3,
      "y": 0,
      "z": -2,
      "name": "Empty",
      "level": 0
    },
    {
      "x": 3,
      "y": 1,
      "z": -2,
      "name": "Empty",
      "level": 0
    },
    {
      "x": 3,
      "y": 2,
      "z": -2,
      "name": "Empty",
      "level": 0
    },
    {
      "x": 3,
      "y": 3,
      "z": -2,
      "name": "Empty",
      "level": 0
    },
    {
      "x": 3,
      "y": 4,
      "z": -2,
      "name": "Empty",
      "level": 0
    },
    {
      "x": 3,
      "y": 5,
      "z": -2,
      "name": "Empty",
      "level": 0
    },
    {
      "x": 3,
      "y": 6,
      "z": -2,
      "name": "Empty",
      "level": 0
    },
    {
      "x": 3,
      "y": 7,
      "z": -2,
      "name": "Empty",
      "level": 0
    },
    {
      "x": 3,
      "y": 0,
      "z": -1,
      "name": "Empty",
      "level": 0
    },
    {
      "x": 3,
      "y": 1,
      "z": -1,
      "name": "Empty",
      "level": 0
    },
    {
      "x": 3,
      "y": 2,
      "z": -1,
      "name": "Empty",
      "level": 0
    },
    {
      "x": 3,
      "y": 3,
      "z": -1,
      "name": "Empty",
      "level": 0
    },
    {
      "x": 3,
      "y": 4,
      "z": -1,
      "name": "Empty",
      "level": 0
    },
    {
      "x": 3,
      "y": 5,
      "z": -1,
      "name": "Empty",
      "level": 0
    },
    {
      "x": 3,
      "y": 6,
      "z": -1,
      "name": "Empty",
      "level": 0
    },
    {
      "x": 3,
      "y": 7,
      "z": -1,
      "name": "Empty",
      "level": 0
    },
    {
      "x": 3,
      "y": 0,
      "z": 0,
      "name": "Empty",
      "level": 0
    },
    {
      "x": 3,
      "y": 1,
      "z": 0,
      "name": "Empty",
      "level": 0
    },
    {
      "x": 3,
      "y": 2,
      "z": 0,
      "name": "Empty",
      "level": 0
    },
    {
      "x": 3,
      "y": 3,
      "z": 0,
      "name": "Empty",
      "level": 0
    },
    {
      "x": 3,
      "y": 4,
      "z": 0,
      "name": "Empty",
      "level": 0
    },
    {
      "x": 3,
      "y": 5,
      "z": 0,
      "name": "Empty",
      "level": 0
    },
    {
      "x": 3,
      "y": 6,
      "z": 0,
      "name": "Empty",
      "level": 0
    },
    {
      "x": 3,
      "y": 7,
      "z": 0,
      "name": "Empty",
      "level": 0
    },
    {
      "x": 3,
      "y": 0,
      "z": 1,
      "name": "Empty",
      "level": 0
    },
    {
      "x": 3,
      "y": 1,
      "z": 1,
      "name": "Empty",
      "level": 0
    },
    {
      "x": 3,
      "y": 2,
      "z": 1,
      "name": "Empty",
      "level": 0
    },
    {
      "x": 3,
      "y": 3,
      "z": 1,
      "name": "Empty",
      "level": 0
    },
    {
      "x": 3,
      "y": 4,
      "z": 1,
      "name": "Empty",
      "level": 0
    },
    {
      "x": 3,
      "y": 5,
      "z": 1,
      "name": "Empty",
      "level": 0
    },
    {
      "x": 3,
      "y": 6,
      "z": 1,
      "name": "Empty",
      "level": 0
    },
    {
      "x": 3,
      "y": 7,
      "z": 1,
      "name": "Empty",
      "level": 0
    },
    {
      "x": 3,
      "y": 0,
      "z": 2,
      "name": "Empty",
      "level": 0
    },
    {
      "x": 3,
      "y": 1,
      "z": 2,
      "name": "Empty",
      "level": 0
    },
    {
      "x": 3,
      "y": 2,
      "z": 2,
      "name": "Empty",
      "level": 0
    },
    {
      "x": 3,
      "y": 3,
      "z": 2,
      "name": "Empty",
      "level": 0
    },
    {
      "x": 3,
      "y": 4,
      "z": 2,
      "name": "Empty",
      "level": 0
    },
    {
      "x": 3,
      "y": 5,
      "z": 2,
      "name": "Empty",
      "level": 0
    },
    {
      "x": 3,
      "y": 6,
      "z": 2,
      "name": "Empty",
      "level": 0
    },
    {
      "x": 3,
      "y": 7,
      "z": 2,
      "name": "Empty",
      "level": 0
    },
    {
      "x": 3,
      "y": 0,
      "z": 3,
      "name": "Empty",
      "level": 0
    },
    {
      "x": 3,
      "y": 1,
      "z": 3,
      "name": "Empty",
      "level": 0
    },
    {
      "x": 3,
      "y": 2,
      "z": 3,
      "name": "Empty",
      "level": 0
    },
    {
      "x": 3,
      "y": 3,
      "z": 3,
      "name": "Empty",
      "level": 0
    },
    {
      "x": 3,
      "y": 4,
      "z": 3,
      "name": "Empty",
      "level": 0
    },
    {
      "x": 3,
      "y": 5,
      "z": 3,
      "name": "Empty",
      "level": 0
    },
    {
      "x": 3,
      "y": 6,
      "z": 3,
      "name": "Empty",
      "level": 0
    },
    {
      "x": 3,
      "y": 7,
      "z": 3,
      "name": "Empty",
      "level": 0
    }
  ]
}