{
  "version": 8,
  "blockIdVersion": 11,
  "anchorX": 0,
  "anchorY": 0,
  "anchorZ": 0,
  "blocks": [
    {
      "x": -13,
      "y": 13,
      "z": -12,
      "name": "Nat20_Force_Empty"
    },
    {
      "x": -13,
      "y": 14,
      "z": -12,
      "name": "Nat20_Force_Empty"
    },
    {
      "x": -13,
      "y": 15,
      "z": -12,
      "name": "Nat20_Force_Empty"
    },
    {
      "x": -13,
      "y": 16,
      "z": -12,
      "name": "Nat20_Force_Empty"
    },
    {
      "x": -13,
      "y": 17,
      "z": -12,
      "name": "Nat20_Force_Empty"
    },
    {
      "x": -13,
      "y": 18,
      "z": -12,
      "name": "Nat20_Force_Empty"
    },
    {
      "x": -13,
      "y": 19,
      "z": -12,
      "name": "Nat20_Force_Empty"
    },
    {
      "x": -13,
      "y": 20,
      "z": -12,
      "name": "Nat20_Force_Empty"
    },
    {
      "x": -13,
      "y": 21,
      "z": -12,
      "name": "Nat20_Force_Empty"
    },
    {
      "x": -13,
      "y": 22,
      "z": -12,
      "name": "Nat20_Force_Empty"
    },
    {
      "x": -13,
      "y": 23,
      "z": -12,
      "name": "Nat20_Force_Empty"
    },
    {
      "x": -13,
      "y": 24,
      "z": -12,
      "name": "Nat20_Force_Empty"
    },
    {
      "x": -13,
      "y": 25,
      "z": -12,
      "name": "Nat20_Force_Empty"
    },
    {
      "x": -13,
      "y": 26,
      "z": -12,
      "name": "Nat20_Force_Empty"
    },
    {
      "x": -13,
      "y": 27,
      "z": -12,
      "name": "Nat20_Force_Empty"
    },
    {
      "x": -13,
      "y": 13,
      "z": -11,
      "name": "Nat20_Force_Empty"
    },
    {
      "x": -13,
      "y": 14,
      "z": -11,
      "name": "Nat20_Force_Empty"
    },
    {
      "x": -13,
      "y": 15,
      "z": -11,
      "name": "Nat20_Force_Empty"
    },
    {
      "x": -13,
      "y": 16,
      "z": -11,
      "name": "Nat20_Force_Empty"
    },
    {
      "x": -13,
      "y": 17,
      "z": -11,
      "name": "Nat20_Force_Empty"
    },
    {
      "x": -13,
      "y": 18,
      "z": -11,
      "name": "Nat20_Force_Empty"
    },
    {
      "x": -13,
      "y": 19,
      "z": -11,
      "name": "Nat20_Force_Empty"
    },
    {
      "x": -13,
      "y": 20,
      "z": -11,
      "name": "Nat20_Force_Empty"
    },
    {
      "x": -13,
      "y": 21,
      "z": -11,
      "name": "Nat20_Force_Empty"
    },
    {
      "x": -13,
      "y": 22,
      "z": -11,
      "name": "Nat20_Force_Empty"
    },
    {
      "x": -13,
      "y": 23,
      "z": -11,
      "name": "Nat20_Force_Empty"
    },
    {
      "x": -13,
      "y": 24,
      "z": -11,
      "name": "Nat20_Force_Empty"
    },
    {
      "x": -13,
      "y": 25,
      "z": -11,
      "name": "Nat20_Force_Empty"
    },
    {
      "x": -13,
      "y": 26,
      "z": -11,
      "name": "Nat20_Force_Empty"
    },
    {
      "x": -13,
      "y": 27,
      "z": -11,
      "name": "Nat20_Force_Empty"
    },
    {
      "x": -13,
      "y": 13,
      "z": -10,
      "name": "Nat20_Force_Empty"
    },
    {
      "x": -13,
      "y": 14,
      "z": -10,
      "name": "Nat20_Force_Empty"
    },
    {
      "x": -13,
      "y": 15,
      "z": -10,
      "name": "Nat20_Force_Empty"
    },
    {
      "x": -13,
      "y": 16,
      "z": -10,
      "name": "Nat20_Force_Empty"
    },
    {
      "x": -13,
      "y": 17,
      "z": -10,
      "name": "Nat20_Force_Empty"
    },
    {
      "x": -13,
      "y": 18,
      "z": -10,
      "name": "Nat20_Force_Empty"
    },
    {
      "x": -13,
      "y": 19,
      "z": -10,
      "name": "Nat20_Force_Empty"
    },
    {
      "x": -13,
      "y": 20,
      "z": -10,
      "name": "Nat20_Force_Empty"
    },
    {
      "x": -13,
      "y": 21,
      "z": -10,
      "name": "Nat20_Force_Empty"
    },
    {
      "x": -13,
      "y": 22,
      "z": -10,
      "name": "Nat20_Force_Empty"
    },
    {
      "x": -13,
      "y": 23,
      "z": -10,
      "name": "Nat20_Force_Empty"
    },
    {
      "x": -13,
      "y": 24,
      "z": -10,
      "name": "Nat20_Force_Empty"
    },
    {
      "x": -13,
      "y": 25,
      "z": -10,
      "name": "Nat20_Force_Empty"
    },
    {
      "x": -13,
      "y": 26,
      "z": -10,
      "name": "Nat20_Force_Empty"
    },
    {
      "x": -13,
      "y": 27,
      "z": -10,
      "name": "Nat20_Force_Empty"
    },
    {
      "x": -13,
      "y": 13,
      "z": -9,
      "name": "Nat20_Force_Empty"
    },
    {
      "x": -13,
      "y": 14,
      "z": -9,
      "name": "Nat20_Force_Empty"
    },
    {
      "x": -13,
      "y": 15,
      "z": -9,
      "name": "Nat20_Force_Empty"
    },
    {
      "x": -13,
      "y": 16,
      "z": -9,
      "name": "Nat20_Force_Empty"
    },
    {
      "x": -13,
      "y": 17,
      "z": -9,
      "name": "Nat20_Force_Empty"
    },
    {
      "x": -13,
      "y": 18,
      "z": -9,
      "name": "Nat20_Force_Empty"
    },
    {
      "x": -13,
      "y": 19,
      "z": -9,
      "name": "Nat20_Force_Empty"
    },
    {
      "x": -13,
      "y": 20,
      "z": -9,
      "name": "Nat20_Force_Empty"
    },
    {
      "x": -13,
      "y": 21,
      "z": -9,
      "name": "Nat20_Force_Empty"
    },
    {
      "x": -13,
      "y": 22,
      "z": -9,
      "name": "Nat20_Force_Empty"
    },
    {
      "x": -13,
      "y": 23,
      "z": -9,
      "name": "Nat20_Force_Empty"
    },
    {
      "x": -13,
      "y": 24,
      "z": -9,
      "name": "Nat20_Force_Empty"
    },
    {
      "x": -13,
      "y": 25,
      "z": -9,
      "name": "Nat20_Force_Empty"
    },
    {
      "x": -13,
      "y": 26,
      "z": -9,
      "name": "Nat20_Force_Empty"
    },
    {
      "x": -13,
      "y": 27,
      "z": -9,
      "name": "Nat20_Force_Empty"
    },
    {
      "x": -13,
      "y": 13,
      "z": -8,
      "name": "Nat20_Force_Empty"
    },
    {
      "x": -13,
      "y": 14,
      "z": -8,
      "name": "Nat20_Force_Empty"
    },
    {
      "x": -13,
      "y": 15,
      "z": -8,
      "name": "Nat20_Force_Empty"
    },
    {
      "x": -13,
      "y": 16,
      "z": -8,
      "name": "Nat20_Force_Empty"
    },
    {
      "x": -13,
      "y": 17,
      "z": -8,
      "name": "Nat20_Force_Empty"
    },
    {
      "x": -13,
      "y": 18,
      "z": -8,
      "name": "Nat20_Force_Empty"
    },
    {
      "x": -13,
      "y": 19,
      "z": -8,
      "name": "Nat20_Force_Empty"
    },
    {
      "x": -13,
      "y": 20,
      "z": -8,
      "name": "Nat20_Force_Empty"
    },
    {
      "x": -13,
      "y": 21,
      "z": -8,
      "name": "Nat20_Force_Empty"
    },
    {
      "x": -13,
      "y": 22,
      "z": -8,
      "name": "Nat20_Force_Empty"
    },
    {
      "x": -13,
      "y": 23,
      "z": -8,
      "name": "Nat20_Force_Empty"
    },
    {
      "x": -13,
      "y": 24,
      "z": -8,
      "name": "Nat20_Force_Empty"
    },
    {
      "x": -13,
      "y": 25,
      "z": -8,
      "name": "Nat20_Force_Empty"
    },
    {
      "x": -13,
      "y": 26,
      "z": -8,
      "name": "Nat20_Force_Empty"
    },
    {
      "x": -13,
      "y": 27,
      "z": -8,
      "name": "Nat20_Force_Empty"
    },
    {
      "x": -13,
      "y": 13,
      "z": -7,
      "name": "Nat20_Force_Empty"
    },
    {
      "x": -13,
      "y": 14,
      "z": -7,
      "name": "Nat20_Force_Empty"
    },
    {
      "x": -13,
      "y": 15,
      "z": -7,
      "name": "Nat20_Force_Empty"
    },
    {
      "x": -13,
      "y": 16,
      "z": -7,
      "name": "Nat20_Force_Empty"
    },
    {
      "x": -13,
      "y": 17,
      "z": -7,
      "name": "Nat20_Force_Empty"
    },
    {
      "x": -13,
      "y": 18,
      "z": -7,
      "name": "Nat20_Force_Empty"
    },
    {
      "x": -13,
      "y": 19,
      "z": -7,
      "name": "Plant_Leaves_Oak"
    },
    {
      "x": -13,
      "y": 20,
      "z": -7,
      "name": "Plant_Leaves_Oak"
    },
    {
      "x": -13,
      "y": 21,
      "z": -7,
      "name": "Nat20_Force_Empty"
    },
    {
      "x": -13,
      "y": 22,
      "z": -7,
      "name": "Nat20_Force_Empty"
    },
    {
      "x": -13,
      "y": 23,
      "z": -7,
      "name": "Nat20_Force_Empty"
    },
    {
      "x": -13,
      "y": 24,
      "z": -7,
      "name": "Nat20_Force_Empty"
    },
    {
      "x": -13,
      "y": 25,
      "z": -7,
      "name": "Nat20_Force_Empty"
    },
    {
      "x": -13,
      "y": 26,
      "z": -7,
      "name": "Nat20_Force_Empty"
    },
    {
      "x": -13,
      "y": 27,
      "z": -7,
      "name": "Nat20_Force_Empty"
    },
    {
      "x": -13,
      "y": 13,
      "z": -6,
      "name": "Nat20_Force_Empty"
    },
    {
      "x": -13,
      "y": 14,
      "z": -6,
      "name": "Nat20_Force_Empty"
    },
    {
      "x": -13,
      "y": 15,
      "z": -6,
      "name": "Nat20_Force_Empty"
    },
    {
      "x": -13,
      "y": 16,
      "z": -6,
      "name": "Nat20_Force_Empty"
    },
    {
      "x": -13,
      "y": 17,
      "z": -6,
      "name": "Nat20_Force_Empty"
    },
    {
      "x": -13,
      "y": 18,
      "z": -6,
      "name": "Nat20_Force_Empty"
    },
    {
      "x": -13,
      "y": 19,
      "z": -6,
      "name": "Plant_Leaves_Oak"
    },
    {
      "x": -13,
      "y": 20,
      "z": -6,
      "name": "Plant_Leaves_Oak"
    },
    {
      "x": -13,
      "y": 21,
      "z": -6,
      "name": "Nat20_Force_Empty"
    },
    {
      "x": -13,
      "y": 22,
      "z": -6,
      "name": "Nat20_Force_Empty"
    },
    {
      "x": -13,
      "y": 23,
      "z": -6,
      "name": "Nat20_Force_Empty"
    },
    {
      "x": -13,
      "y": 24,
      "z": -6,
      "name": "Nat20_Force_Empty"
    },
    {
      "x": -13,
      "y": 25,
      "z": -6,
      "name": "Nat20_Force_Empty"
    },
    {
      "x": -13,
      "y": 26,
      "z": -6,
      "name": "Nat20_Force_Empty"
    },
    {
      "x": -13,
      "y": 27,
      "z": -6,
      "name": "Nat20_Force_Empty"
    },
    {
      "x": -13,
      "y": 13,
      "z": -5,
      "name": "Nat20_Force_Empty"
    },
    {
      "x": -13,
      "y": 14,
      "z": -5,
      "name": "Nat20_Force_Empty"
    },
    {
      "x": -13,
      "y": 15,
      "z": -5,
      "name": "Nat20_Force_Empty"
    },
    {
      "x": -13,
      "y": 16,
      "z": -5,
      "name": "Nat20_Force_Empty"
    },
    {
      "x": -13,
      "y": 17,
      "z": -5,
      "name": "Nat20_Force_Empty"
    },
    {
      "x": -13,
      "y": 18,
      "z": -5,
      "name": "Nat20_Force_Empty"
    },
    {
      "x": -13,
      "y": 19,
      "z": -5,
      "name": "Plant_Leaves_Oak"
    },
    {
      "x": -13,
      "y": 20,
      "z": -5,
      "name": "Plant_Leaves_Oak"
    },
    {
      "x": -13,
      "y": 21,
      "z": -5,
      "name": "Nat20_Force_Empty"
    },
    {
      "x": -13,
      "y": 22,
      "z": -5,
      "name": "Nat20_Force_Empty"
    },
    {
      "x": -13,
      "y": 23,
      "z": -5,
      "name": "Nat20_Force_Empty"
    },
    {
      "x": -13,
      "y": 24,
      "z": -5,
      "name": "Nat20_Force_Empty"
    },
    {
      "x": -13,
      "y": 25,
      "z": -5,
      "name": "Nat20_Force_Empty"
    },
    {
      "x": -13,
      "y": 26,
      "z": -5,
      "name": "Nat20_Force_Empty"
    },
    {
      "x": -13,
      "y": 27,
      "z": -5,
      "name": "Nat20_Force_Empty"
    },
    {
      "x": -13,
      "y": 13,
      "z": -4,
      "name": "Nat20_Force_Empty"
    },
    {
      "x": -13,
      "y": 14,
      "z": -4,
      "name": "Nat20_Force_Empty"
    },
    {
      "x": -13,
      "y": 15,
      "z": -4,
      "name": "Nat20_Force_Empty"
    },
    {
      "x": -13,
      "y": 16,
      "z": -4,
      "name": "Nat20_Force_Empty"
    },
    {
      "x": -13,
      "y": 17,
      "z": -4,
      "name": "Nat20_Force_Empty"
    },
    {
      "x": -13,
      "y": 18,
      "z": -4,
      "name": "Nat20_Force_Empty"
    },
    {
      "x": -13,
      "y": 19,
      "z": -4,
      "name": "Plant_Leaves_Oak"
    },
    {
      "x": -13,
      "y": 20,
      "z": -4,
      "name": "Nat20_Force_Empty"
    },
    {
      "x": -13,
      "y": 21,
      "z": -4,
      "name": "Nat20_Force_Empty"
    },
    {
      "x": -13,
      "y": 22,
      "z": -4,
      "name": "Nat20_Force_Empty"
    },
    {
      "x": -13,
      "y": 23,
      "z": -4,
      "name": "Nat20_Force_Empty"
    },
    {
      "x": -13,
      "y": 24,
      "z": -4,
      "name": "Nat20_Force_Empty"
    },
    {
      "x": -13,
      "y": 25,
      "z": -4,
      "name": "Nat20_Force_Empty"
    },
    {
      "x": -13,
      "y": 26,
      "z": -4,
      "name": "Nat20_Force_Empty"
    },
    {
      "x": -13,
      "y": 27,
      "z": -4,
      "name": "Nat20_Force_Empty"
    },
    {
      "x": -13,
      "y": 13,
      "z": -3,
      "name": "Nat20_Force_Empty"
    },
    {
      "x": -13,
      "y": 14,
      "z": -3,
      "name": "Nat20_Force_Empty"
    },
    {
      "x": -13,
      "y": 15,
      "z": -3,
      "name": "Nat20_Force_Empty"
    },
    {
      "x": -13,
      "y": 16,
      "z": -3,
      "name": "Nat20_Force_Empty"
    },
    {
      "x": -13,
      "y": 17,
      "z": -3,
      "name": "Nat20_Force_Empty"
    },
    {
      "x": -13,
      "y": 18,
      "z": -3,
      "name": "Nat20_Force_Empty"
    },
    {
      "x": -13,
      "y": 19,
      "z": -3,
      "name": "Plant_Leaves_Oak"
    },
    {
      "x": -13,
      "y": 20,
      "z": -3,
      "name": "Nat20_Force_Empty"
    },
    {
      "x": -13,
      "y": 21,
      "z": -3,
      "name": "Nat20_Force_Empty"
    },
    {
      "x": -13,
      "y": 22,
      "z": -3,
      "name": "Nat20_Force_Empty"
    },
    {
      "x": -13,
      "y": 23,
      "z": -3,
      "name": "Nat20_Force_Empty"
    },
    {
      "x": -13,
      "y": 24,
      "z": -3,
      "name": "Nat20_Force_Empty"
    },
    {
      "x": -13,
      "y": 25,
      "z": -3,
      "name": "Nat20_Force_Empty"
    },
    {
      "x": -13,
      "y": 26,
      "z": -3,
      "name": "Nat20_Force_Empty"
    },
    {
      "x": -13,
      "y": 27,
      "z": -3,
      "name": "Nat20_Force_Empty"
    },
    {
      "x": -13,
      "y": 13,
      "z": -2,
      "name": "Nat20_Force_Empty"
    },
    {
      "x": -13,
      "y": 14,
      "z": -2,
      "name": "Nat20_Force_Empty"
    },
    {
      "x": -13,
      "y": 15,
      "z": -2,
      "name": "Nat20_Force_Empty"
    },
    {
      "x": -13,
      "y": 16,
      "z": -2,
      "name": "Nat20_Force_Empty"
    },
    {
      "x": -13,
      "y": 17,
      "z": -2,
      "name": "Nat20_Force_Empty"
    },
    {
      "x": -13,
      "y": 18,
      "z": -2,
      "name": "Nat20_Force_Empty"
    },
    {
      "x": -13,
      "y": 19,
      "z": -2,
      "name": "Nat20_Force_Empty"
    },
    {
      "x": -13,
      "y": 20,
      "z": -2,
      "name": "Nat20_Force_Empty"
    },
    {
      "x": -13,
      "y": 21,
      "z": -2,
      "name": "Nat20_Force_Empty"
    },
    {
      "x": -13,
      "y": 22,
      "z": -2,
      "name": "Nat20_Force_Empty"
    },
    {
      "x": -13,
      "y": 23,
      "z": -2,
      "name": "Nat20_Force_Empty"
    },
    {
      "x": -13,
      "y": 24,
      "z": -2,
      "name": "Nat20_Force_Empty"
    },
    {
      "x": -13,
      "y": 25,
      "z": -2,
      "name": "Nat20_Force_Empty"
    },
    {
      "x": -13,
      "y": 26,
      "z": -2,
      "name": "Nat20_Force_Empty"
    },
    {
      "x": -13,
      "y": 27,
      "z": -2,
      "name": "Nat20_Force_Empty"
    },
    {
      "x": -13,
      "y": 13,
      "z": -1,
      "name": "Nat20_Force_Empty"
    },
    {
      "x": -13,
      "y": 14,
      "z": -1,
      "name": "Nat20_Force_Empty"
    },
    {
      "x": -13,
      "y": 15,
      "z": -1,
      "name": "Nat20_Force_Empty"
    },
    {
      "x": -13,
      "y": 16,
      "z": -1,
      "name": "Nat20_Force_Empty"
    },
    {
      "x": -13,
      "y": 17,
      "z": -1,
      "name": "Nat20_Force_Empty"
    },
    {
      "x": -13,
      "y": 18,
      "z": -1,
      "name": "Nat20_Force_Empty"
    },
    {
      "x": -13,
      "y": 19,
      "z": -1,
      "name": "Nat20_Force_Empty"
    },
    {
      "x": -13,
      "y": 20,
      "z": -1,
      "name": "Nat20_Force_Empty"
    },
    {
      "x": -13,
      "y": 21,
      "z": -1,
      "name": "Nat20_Force_Empty"
    },
    {
      "x": -13,
      "y": 22,
      "z": -1,
      "name": "Nat20_Force_Empty"
    },
    {
      "x": -13,
      "y": 23,
      "z": -1,
      "name": "Nat20_Force_Empty"
    },
    {
      "x": -13,
      "y": 24,
      "z": -1,
      "name": "Nat20_Force_Empty"
    },
    {
      "x": -13,
      "y": 25,
      "z": -1,
      "name": "Nat20_Force_Empty"
    },
    {
      "x": -13,
      "y": 26,
      "z": -1,
      "name": "Nat20_Force_Empty"
    },
    {
      "x": -13,
      "y": 27,
      "z": -1,
      "name": "Nat20_Force_Empty"
    },
    {
      "x": -13,
      "y": 13,
      "z": 0,
      "name": "Nat20_Force_Empty"
    },
    {
      "x": -13,
      "y": 14,
      "z": 0,
      "name": "Nat20_Force_Empty"
    },
    {
      "x": -13,
      "y": 15,
      "z": 0,
      "name": "Nat20_Force_Empty"
    },
    {
      "x": -13,
      "y": 16,
      "z": 0,
      "name": "Nat20_Force_Empty"
    },
    {
      "x": -13,
      "y": 17,
      "z": 0,
      "name": "Nat20_Force_Empty"
    },
    {
      "x": -13,
      "y": 18,
      "z": 0,
      "name": "Nat20_Force_Empty"
    },
    {
      "x": -13,
      "y": 19,
      "z": 0,
      "name": "Nat20_Force_Empty"
    },
    {
      "x": -13,
      "y": 20,
      "z": 0,
      "name": "Nat20_Force_Empty"
    },
    {
      "x": -13,
      "y": 21,
      "z": 0,
      "name": "Nat20_Force_Empty"
    },
    {
      "x": -13,
      "y": 22,
      "z": 0,
      "name": "Nat20_Force_Empty"
    },
    {
      "x": -13,
      "y": 23,
      "z": 0,
      "name": "Nat20_Force_Empty"
    },
    {
      "x": -13,
      "y": 24,
      "z": 0,
      "name": "Nat20_Force_Empty"
    },
    {
      "x": -13,
      "y": 25,
      "z": 0,
      "name": "Nat20_Force_Empty"
    },
    {
      "x": -13,
      "y": 26,
      "z": 0,
      "name": "Nat20_Force_Empty"
    },
    {
      "x": -13,
      "y": 27,
      "z": 0,
      "name": "Nat20_Force_Empty"
    },
    {
      "x": -13,
      "y": 13,
      "z": 1,
      "name": "Nat20_Force_Empty"
    },
    {
      "x": -13,
      "y": 14,
      "z": 1,
      "name": "Nat20_Force_Empty"
    },
    {
      "x": -13,
      "y": 15,
      "z": 1,
      "name": "Nat20_Force_Empty"
    },
    {
      "x": -13,
      "y": 16,
      "z": 1,
      "name": "Nat20_Force_Empty"
    },
    {
      "x": -13,
      "y": 17,
      "z": 1,
      "name": "Nat20_Force_Empty"
    },
    {
      "x": -13,
      "y": 18,
      "z": 1,
      "name": "Nat20_Force_Empty"
    },
    {
      "x": -13,
      "y": 19,
      "z": 1,
      "name": "Nat20_Force_Empty"
    },
    {
      "x": -13,
      "y": 20,
      "z": 1,
      "name": "Nat20_Force_Empty"
    },
    {
      "x": -13,
      "y": 21,
      "z": 1,
      "name": "Nat20_Force_Empty"
    },
    {
      "x": -13,
      "y": 22,
      "z": 1,
      "name": "Nat20_Force_Empty"
    },
    {
      "x": -13,
      "y": 23,
      "z": 1,
      "name": "Nat20_Force_Empty"
    },
    {
      "x": -13,
      "y": 24,
      "z": 1,
      "name": "Nat20_Force_Empty"
    },
    {
      "x": -13,
      "y": 25,
      "z": 1,
      "name": "Nat20_Force_Empty"
    },
    {
      "x": -13,
      "y": 26,
      "z": 1,
      "name": "Nat20_Force_Empty"
    },
    {
      "x": -13,
      "y": 27,
      "z": 1,
      "name": "Nat20_Force_Empty"
    },
    {
      "x": -13,
      "y": 13,
      "z": 2,
      "name": "Nat20_Force_Empty"
    },
    {
      "x": -13,
      "y": 14,
      "z": 2,
      "name": "Nat20_Force_Empty"
    },
    {
      "x": -13,
      "y": 15,
      "z": 2,
      "name": "Nat20_Force_Empty"
    },
    {
      "x": -13,
      "y": 16,
      "z": 2,
      "name": "Nat20_Force_Empty"
    },
    {
      "x": -13,
      "y": 17,
      "z": 2,
      "name": "Nat20_Force_Empty"
    },
    {
      "x": -13,
      "y": 18,
      "z": 2,
      "name": "Nat20_Force_Empty"
    },
    {
      "x": -13,
      "y": 19,
      "z": 2,
      "name": "Nat20_Force_Empty"
    },
    {
      "x": -13,
      "y": 20,
      "z": 2,
      "name": "Nat20_Force_Empty"
    },
    {
      "x": -13,
      "y": 21,
      "z": 2,
      "name": "Nat20_Force_Empty"
    },
    {
      "x": -13,
      "y": 22,
      "z": 2,
      "name": "Nat20_Force_Empty"
    },
    {
      "x": -13,
      "y": 23,
      "z": 2,
      "name": "Nat20_Force_Empty"
    },
    {
      "x": -13,
      "y": 24,
      "z": 2,
      "name": "Nat20_Force_Empty"
    },
    {
      "x": -13,
      "y": 25,
      "z": 2,
      "name": "Nat20_Force_Empty"
    },
    {
      "x": -13,
      "y": 26,
      "z": 2,
      "name": "Nat20_Force_Empty"
    },
    {
      "x": -13,
      "y": 27,
      "z": 2,
      "name": "Nat20_Force_Empty"
    },
    {
      "x": -13,
      "y": 13,
      "z": 3,
      "name": "Nat20_Force_Empty"
    },
    {
      "x": -13,
      "y": 14,
      "z": 3,
      "name": "Nat20_Force_Empty"
    },
    {
      "x": -13,
      "y": 15,
      "z": 3,
      "name": "Nat20_Force_Empty"
    },
    {
      "x": -13,
      "y": 16,
      "z": 3,
      "name": "Nat20_Force_Empty"
    },
    {
      "x": -13,
      "y": 17,
      "z": 3,
      "name": "Nat20_Force_Empty"
    },
    {
      "x": -13,
      "y": 18,
      "z": 3,
      "name": "Nat20_Force_Empty"
    },
    {
      "x": -13,
      "y": 19,
      "z": 3,
      "name": "Nat20_Force_Empty"
    },
    {
      "x": -13,
      "y": 20,
      "z": 3,
      "name": "Nat20_Force_Empty"
    },
    {
      "x": -13,
      "y": 21,
      "z": 3,
      "name": "Nat20_Force_Empty"
    },
    {
      "x": -13,
      "y": 22,
      "z": 3,
      "name": "Nat20_Force_Empty"
    },
    {
      "x": -13,
      "y": 23,
      "z": 3,
      "name": "Nat20_Force_Empty"
    },
    {
      "x": -13,
      "y": 24,
      "z": 3,
      "name": "Nat20_Force_Empty"
    },
    {
      "x": -13,
      "y": 25,
      "z": 3,
      "name": "Nat20_Force_Empty"
    },
    {
      "x": -13,
      "y": 26,
      "z": 3,
      "name": "Nat20_Force_Empty"
    },
    {
      "x": -13,
      "y": 27,
      "z": 3,
      "name": "Nat20_Force_Empty"
    },
    {
      "x": -13,
      "y": 13,
      "z": 4,
      "name": "Nat20_Force_Empty"
    },
    {
      "x": -13,
      "y": 14,
      "z": 4,
      "name": "Nat20_Force_Empty"
    },
    {
      "x": -13,
      "y": 15,
      "z": 4,
      "name": "Nat20_Force_Empty"
    },
    {
      "x": -13,
      "y": 16,
      "z": 4,
      "name": "Nat20_Force_Empty"
    },
    {
      "x": -13,
      "y": 17,
      "z": 4,
      "name": "Nat20_Force_Empty"
    },
    {
      "x": -13,
      "y": 18,
      "z": 4,
      "name": "Nat20_Force_Empty"
    },
    {
      "x": -13,
      "y": 19,
      "z": 4,
      "name": "Nat20_Force_Empty"
    },
    {
      "x": -13,
      "y": 20,
      "z": 4,
      "name": "Nat20_Force_Empty"
    },
    {
      "x": -13,
      "y": 21,
      "z": 4,
      "name": "Nat20_Force_Empty"
    },
    {
      "x": -13,
      "y": 22,
      "z": 4,
      "name": "Nat20_Force_Empty"
    },
    {
      "x": -13,
      "y": 23,
      "z": 4,
      "name": "Nat20_Force_Empty"
    },
    {
      "x": -13,
      "y": 24,
      "z": 4,
      "name": "Nat20_Force_Empty"
    },
    {
      "x": -13,
      "y": 25,
      "z": 4,
      "name": "Nat20_Force_Empty"
    },
    {
      "x": -13,
      "y": 26,
      "z": 4,
      "name": "Nat20_Force_Empty"
    },
    {
      "x": -13,
      "y": 27,
      "z": 4,
      "name": "Nat20_Force_Empty"
    },
    {
      "x": -13,
      "y": 13,
      "z": 5,
      "name": "Nat20_Force_Empty"
    },
    {
      "x": -13,
      "y": 14,
      "z": 5,
      "name": "Nat20_Force_Empty"
    },
    {
      "x": -13,
      "y": 15,
      "z": 5,
      "name": "Nat20_Force_Empty"
    },
    {
      "x": -13,
      "y": 16,
      "z": 5,
      "name": "Nat20_Force_Empty"
    },
    {
      "x": -13,
      "y": 17,
      "z": 5,
      "name": "Nat20_Force_Empty"
    },
    {
      "x": -13,
      "y": 18,
      "z": 5,
      "name": "Nat20_Force_Empty"
    },
    {
      "x": -13,
      "y": 19,
      "z": 5,
      "name": "Nat20_Force_Empty"
    },
    {
      "x": -13,
      "y": 20,
      "z": 5,
      "name": "Nat20_Force_Empty"
    },
    {
      "x": -13,
      "y": 21,
      "z": 5,
      "name": "Nat20_Force_Empty"
    },
    {
      "x": -13,
      "y": 22,
      "z": 5,
      "name": "Nat20_Force_Empty"
    },
    {
      "x": -13,
      "y": 23,
      "z": 5,
      "name": "Nat20_Force_Empty"
    },
    {
      "x": -13,
      "y": 24,
      "z": 5,
      "name": "Nat20_Force_Empty"
    },
    {
      "x": -13,
      "y": 25,
      "z": 5,
      "name": "Nat20_Force_Empty"
    },
    {
      "x": -13,
      "y": 26,
      "z": 5,
      "name": "Nat20_Force_Empty"
    },
    {
      "x": -13,
      "y": 27,
      "z": 5,
      "name": "Nat20_Force_Empty"
    },
    {
      "x": -13,
      "y": 13,
      "z": 6,
      "name": "Nat20_Force_Empty"
    },
    {
      "x": -13,
      "y": 14,
      "z": 6,
      "name": "Nat20_Force_Empty"
    },
    {
      "x": -13,
      "y": 15,
      "z": 6,
      "name": "Nat20_Force_Empty"
    },
    {
      "x": -13,
      "y": 16,
      "z": 6,
      "name": "Nat20_Force_Empty"
    },
    {
      "x": -13,
      "y": 17,
      "z": 6,
      "name": "Nat20_Force_Empty"
    },
    {
      "x": -13,
      "y": 18,
      "z": 6,
      "name": "Nat20_Force_Empty"
    },
    {
      "x": -13,
      "y": 19,
      "z": 6,
      "name": "Nat20_Force_Empty"
    },
    {
      "x": -13,
      "y": 20,
      "z": 6,
      "name": "Nat20_Force_Empty"
    },
    {
      "x": -13,
      "y": 21,
      "z": 6,
      "name": "Nat20_Force_Empty"
    },
    {
      "x": -13,
      "y": 22,
      "z": 6,
      "name": "Nat20_Force_Empty"
    },
    {
      "x": -13,
      "y": 23,
      "z": 6,
      "name": "Nat20_Force_Empty"
    },
    {
      "x": -13,
      "y": 24,
      "z": 6,
      "name": "Nat20_Force_Empty"
    },
    {
      "x": -13,
      "y": 25,
      "z": 6,
      "name": "Nat20_Force_Empty"
    },
    {
      "x": -13,
      "y": 26,
      "z": 6,
      "name": "Nat20_Force_Empty"
    },
    {
      "x": -13,
      "y": 27,
      "z": 6,
      "name": "Nat20_Force_Empty"
    },
    {
      "x": -13,
      "y": 13,
      "z": 7,
      "name": "Nat20_Force_Empty"
    },
    {
      "x": -13,
      "y": 14,
      "z": 7,
      "name": "Nat20_Force_Empty"
    },
    {
      "x": -13,
      "y": 15,
      "z": 7,
      "name": "Nat20_Force_Empty"
    },
    {
      "x": -13,
      "y": 16,
      "z": 7,
      "name": "Nat20_Force_Empty"
    },
    {
      "x": -13,
      "y": 17,
      "z": 7,
      "name": "Nat20_Force_Empty"
    },
    {
      "x": -13,
      "y": 18,
      "z": 7,
      "name": "Nat20_Force_Empty"
    },
    {
      "x": -13,
      "y": 19,
      "z": 7,
      "name": "Nat20_Force_Empty"
    },
    {
      "x": -13,
      "y": 20,
      "z": 7,
      "name": "Nat20_Force_Empty"
    },
    {
      "x": -13,
      "y": 21,
      "z": 7,
      "name": "Nat20_Force_Empty"
    },
    {
      "x": -13,
      "y": 22,
      "z": 7,
      "name": "Nat20_Force_Empty"
    },
    {
      "x": -13,
      "y": 23,
      "z": 7,
      "name": "Nat20_Force_Empty"
    },
    {
      "x": -13,
      "y": 24,
      "z": 7,
      "name": "Nat20_Force_Empty"
    },
    {
      "x": -13,
      "y": 25,
      "z": 7,
      "name": "Nat20_Force_Empty"
    },
    {
      "x": -13,
      "y": 26,
      "z": 7,
      "name": "Nat20_Force_Empty"
    },
    {
      "x": -13,
      "y": 27,
      "z": 7,
      "name": "Nat20_Force_Empty"
    },
    {
      "x": -13,
      "y": 13,
      "z": 8,
      "name": "Nat20_Force_Empty"
    },
    {
      "x": -13,
      "y": 14,
      "z": 8,
      "name": "Nat20_Force_Empty"
    },
    {
      "x": -13,
      "y": 15,
      "z": 8,
      "name": "Nat20_Force_Empty"
    },
    {
      "x": -13,
      "y": 16,
      "z": 8,
      "name": "Nat20_Force_Empty"
    },
    {
      "x": -13,
      "y": 17,
      "z": 8,
      "name": "Nat20_Force_Empty"
    },
    {
      "x": -13,
      "y": 18,
      "z": 8,
      "name": "Nat20_Force_Empty"
    },
    {
      "x": -13,
      "y": 19,
      "z": 8,
      "name": "Nat20_Force_Empty"
    },
    {
      "x": -13,
      "y": 20,
      "z": 8,
      "name": "Nat20_Force_Empty"
    },
    {
      "x": -13,
      "y": 21,
      "z": 8,
      "name": "Nat20_Force_Empty"
    },
    {
      "x": -13,
      "y": 22,
      "z": 8,
      "name": "Nat20_Force_Empty"
    },
    {
      "x": -13,
      "y": 23,
      "z": 8,
      "name": "Nat20_Force_Empty"
    },
    {
      "x": -13,
      "y": 24,
      "z": 8,
      "name": "Nat20_Force_Empty"
    },
    {
      "x": -13,
      "y": 25,
      "z": 8,
      "name": "Nat20_Force_Empty"
    },
    {
      "x": -13,
      "y": 26,
      "z": 8,
      "name": "Nat20_Force_Empty"
    },
    {
      "x": -13,
      "y": 27,
      "z": 8,
      "name": "Nat20_Force_Empty"
    },
    {
      "x": -13,
      "y": 13,
      "z": 9,
      "name": "Nat20_Force_Empty"
    },
    {
      "x": -13,
      "y": 14,
      "z": 9,
      "name": "Nat20_Force_Empty"
    },
    {
      "x": -13,
      "y": 15,
      "z": 9,
      "name": "Nat20_Force_Empty"
    },
    {
      "x": -13,
      "y": 16,
      "z": 9,
      "name": "Nat20_Force_Empty"
    },
    {
      "x": -13,
      "y": 17,
      "z": 9,
      "name": "Nat20_Force_Empty"
    },
    {
      "x": -13,
      "y": 18,
      "z": 9,
      "name": "Nat20_Force_Empty"
    },
    {
      "x": -13,
      "y": 19,
      "z": 9,
      "name": "Nat20_Force_Empty"
    },
    {
      "x": -13,
      "y": 20,
      "z": 9,
      "name": "Nat20_Force_Empty"
    },
    {
      "x": -13,
      "y": 21,
      "z": 9,
      "name": "Nat20_Force_Empty"
    },
    {
      "x": -13,
      "y": 22,
      "z": 9,
      "name": "Nat20_Force_Empty"
    },
    {
      "x": -13,
      "y": 23,
      "z": 9,
      "name": "Nat20_Force_Empty"
    },
    {
      "x": -13,
      "y": 24,
      "z": 9,
      "name": "Nat20_Force_Empty"
    },
    {
      "x": -13,
      "y": 25,
      "z": 9,
      "name": "Nat20_Force_Empty"
    },
    {
      "x": -13,
      "y": 26,
      "z": 9,
      "name": "Nat20_Force_Empty"
    },
    {
      "x": -13,
      "y": 27,
      "z": 9,
      "name": "Nat20_Force_Empty"
    },
    {
      "x": -13,
      "y": 13,
      "z": 10,
      "name": "Nat20_Force_Empty"
    },
    {
      "x": -13,
      "y": 14,
      "z": 10,
      "name": "Nat20_Force_Empty"
    },
    {
      "x": -13,
      "y": 15,
      "z": 10,
      "name": "Nat20_Force_Empty"
    },
    {
      "x": -13,
      "y": 16,
      "z": 10,
      "name": "Nat20_Force_Empty"
    },
    {
      "x": -13,
      "y": 17,
      "z": 10,
      "name": "Nat20_Force_Empty"
    },
    {
      "x": -13,
      "y": 18,
      "z": 10,
      "name": "Nat20_Force_Empty"
    },
    {
      "x": -13,
      "y": 19,
      "z": 10,
      "name": "Nat20_Force_Empty"
    },
    {
      "x": -13,
      "y": 20,
      "z": 10,
      "name": "Nat20_Force_Empty"
    },
    {
      "x": -13,
      "y": 21,
      "z": 10,
      "name": "Nat20_Force_Empty"
    },
    {
      "x": -13,
      "y": 22,
      "z": 10,
      "name": "Nat20_Force_Empty"
    },
    {
      "x": -13,
      "y": 23,
      "z": 10,
      "name": "Nat20_Force_Empty"
    },
    {
      "x": -13,
      "y": 24,
      "z": 10,
      "name": "Nat20_Force_Empty"
    },
    {
      "x": -13,
      "y": 25,
      "z": 10,
      "name": "Nat20_Force_Empty"
    },
    {
      "x": -13,
      "y": 26,
      "z": 10,
      "name": "Nat20_Force_Empty"
    },
    {
      "x": -13,
      "y": 27,
      "z": 10,
      "name": "Nat20_Force_Empty"
    },
    {
      "x": -13,
      "y": 13,
      "z": 11,
      "name": "Nat20_Force_Empty"
    },
    {
      "x": -13,
      "y": 14,
      "z": 11,
      "name": "Nat20_Force_Empty"
    },
    {
      "x": -13,
      "y": 15,
      "z": 11,
      "name": "Nat20_Force_Empty"
    },
    {
      "x": -13,
      "y": 16,
      "z": 11,
      "name": "Nat20_Force_Empty"
    },
    {
      "x": -13,
      "y": 17,
      "z": 11,
      "name": "Nat20_Force_Empty"
    },
    {
      "x": -13,
      "y": 18,
      "z": 11,
      "name": "Nat20_Force_Empty"
    },
    {
      "x": -13,
      "y": 19,
      "z": 11,
      "name": "Nat20_Force_Empty"
    },
    {
      "x": -13,
      "y": 20,
      "z": 11,
      "name": "Nat20_Force_Empty"
    },
    {
      "x": -13,
      "y": 21,
      "z": 11,
      "name": "Nat20_Force_Empty"
    },
    {
      "x": -13,
      "y": 22,
      "z": 11,
      "name": "Nat20_Force_Empty"
    },
    {
      "x": -13,
      "y": 23,
      "z": 11,
      "name": "Nat20_Force_Empty"
    },
    {
      "x": -13,
      "y": 24,
      "z": 11,
      "name": "Nat20_Force_Empty"
    },
    {
      "x": -13,
      "y": 25,
      "z": 11,
      "name": "Nat20_Force_Empty"
    },
    {
      "x": -13,
      "y": 26,
      "z": 11,
      "name": "Nat20_Force_Empty"
    },
    {
      "x": -13,
      "y": 27,
      "z": 11,
      "name": "Nat20_Force_Empty"
    },
    {
      "x": -13,
      "y": 13,
      "z": 12,
      "name": "Nat20_Force_Empty"
    },
    {
      "x": -13,
      "y": 14,
      "z": 12,
      "name": "Nat20_Force_Empty"
    },
    {
      "x": -13,
      "y": 15,
      "z": 12,
      "name": "Nat20_Force_Empty"
    },
    {
      "x": -13,
      "y": 16,
      "z": 12,
      "name": "Nat20_Force_Empty"
    },
    {
      "x": -13,
      "y": 17,
      "z": 12,
      "name": "Nat20_Force_Empty"
    },
    {
      "x": -13,
      "y": 18,
      "z": 12,
      "name": "Nat20_Force_Empty"
    },
    {
      "x": -13,
      "y": 19,
      "z": 12,
      "name": "Nat20_Force_Empty"
    },
    {
      "x": -13,
      "y": 20,
      "z": 12,
      "name": "Nat20_Force_Empty"
    },
    {
      "x": -13,
      "y": 21,
      "z": 12,
      "name": "Nat20_Force_Empty"
    },
    {
      "x": -13,
      "y": 22,
      "z": 12,
      "name": "Nat20_Force_Empty"
    },
    {
      "x": -13,
      "y": 23,
      "z": 12,
      "name": "Nat20_Force_Empty"
    },
    {
      "x": -13,
      "y": 24,
      "z": 12,
      "name": "Nat20_Force_Empty"
    },
    {
      "x": -13,
      "y": 25,
      "z": 12,
      "name": "Nat20_Force_Empty"
    },
    {
      "x": -13,
      "y": 26,
      "z": 12,
      "name": "Nat20_Force_Empty"
    },
    {
      "x": -13,
      "y": 27,
      "z": 12,
      "name": "Nat20_Force_Empty"
    },
    {
      "x": -12,
      "y": 13,
      "z": -12,
      "name": "Nat20_Force_Empty"
    },
    {
      "x": -12,
      "y": 14,
      "z": -12,
      "name": "Nat20_Force_Empty"
    },
    {
      "x": -12,
      "y": 15,
      "z": -12,
      "name": "Nat20_Force_Empty"
    },
    {
      "x": -12,
      "y": 16,
      "z": -12,
      "name": "Nat20_Force_Empty"
    },
    {
      "x": -12,
      "y": 17,
      "z": -12,
      "name": "Nat20_Force_Empty"
    },
    {
      "x": -12,
      "y": 18,
      "z": -12,
      "name": "Nat20_Force_Empty"
    },
    {
      "x": -12,
      "y": 19,
      "z": -12,
      "name": "Nat20_Force_Empty"
    },
    {
      "x": -12,
      "y": 20,
      "z": -12,
      "name": "Nat20_Force_Empty"
    },
    {
      "x": -12,
      "y": 21,
      "z": -12,
      "name": "Nat20_Force_Empty"
    },
    {
      "x": -12,
      "y": 22,
      "z": -12,
      "name": "Nat20_Force_Empty"
    },
    {
      "x": -12,
      "y": 23,
      "z": -12,
      "name": "Nat20_Force_Empty"
    },
    {
      "x": -12,
      "y": 24,
      "z": -12,
      "name": "Nat20_Force_Empty"
    },
    {
      "x": -12,
      "y": 25,
      "z": -12,
      "name": "Nat20_Force_Empty"
    },
    {
      "x": -12,
      "y": 26,
      "z": -12,
      "name": "Nat20_Force_Empty"
    },
    {
      "x": -12,
      "y": 27,
      "z": -12,
      "name": "Nat20_Force_Empty"
    },
    {
      "x": -12,
      "y": 13,
      "z": -11,
      "name": "Nat20_Force_Empty"
    },
    {
      "x": -12,
      "y": 14,
      "z": -11,
      "name": "Nat20_Force_Empty"
    },
    {
      "x": -12,
      "y": 15,
      "z": -11,
      "name": "Nat20_Force_Empty"
    },
    {
      "x": -12,
      "y": 16,
      "z": -11,
      "name": "Nat20_Force_Empty"
    },
    {
      "x": -12,
      "y": 17,
      "z": -11,
      "name": "Nat20_Force_Empty"
    },
    {
      "x": -12,
      "y": 18,
      "z": -11,
      "name": "Nat20_Force_Empty"
    },
    {
      "x": -12,
      "y": 19,
      "z": -11,
      "name": "Nat20_Force_Empty"
    },
    {
      "x": -12,
      "y": 20,
      "z": -11,
      "name": "Nat20_Force_Empty"
    },
    {
      "x": -12,
      "y": 21,
      "z": -11,
      "name": "Nat20_Force_Empty"
    },
    {
      "x": -12,
      "y": 22,
      "z": -11,
      "name": "Nat20_Force_Empty"
    },
    {
      "x": -12,
      "y": 23,
      "z": -11,
      "name": "Nat20_Force_Empty"
    },
    {
      "x": -12,
      "y": 24,
      "z": -11,
      "name": "Nat20_Force_Empty"
    },
    {
      "x": -12,
      "y": 25,
      "z": -11,
      "name": "Nat20_Force_Empty"
    },
    {
      "x": -12,
      "y": 26,
      "z": -11,
      "name": "Nat20_Force_Empty"
    },
    {
      "x": -12,
      "y": 27,
      "z": -11,
      "name": "Nat20_Force_Empty"
    },
    {
      "x": -12,
      "y": 13,
      "z": -10,
      "name": "Nat20_Force_Empty"
    },
    {
      "x": -12,
      "y": 14,
      "z": -10,
      "name": "Nat20_Force_Empty"
    },
    {
      "x": -12,
      "y": 15,
      "z": -10,
      "name": "Nat20_Force_Empty"
    },
    {
      "x": -12,
      "y": 16,
      "z": -10,
      "name": "Nat20_Force_Empty"
    },
    {
      "x": -12,
      "y": 17,
      "z": -10,
      "name": "Nat20_Force_Empty"
    },
    {
      "x": -12,
      "y": 18,
      "z": -10,
      "name": "Nat20_Force_Empty"
    },
    {
      "x": -12,
      "y": 19,
      "z": -10,
      "name": "Nat20_Force_Empty"
    },
    {
      "x": -12,
      "y": 20,
      "z": -10,
      "name": "Nat20_Force_Empty"
    },
    {
      "x": -12,
      "y": 21,
      "z": -10,
      "name": "Nat20_Force_Empty"
    },
    {
      "x": -12,
      "y": 22,
      "z": -10,
      "name": "Nat20_Force_Empty"
    },
    {
      "x": -12,
      "y": 23,
      "z": -10,
      "name": "Nat20_Force_Empty"
    },
    {
      "x": -12,
      "y": 24,
      "z": -10,
      "name": "Nat20_Force_Empty"
    },
    {
      "x": -12,
      "y": 25,
      "z": -10,
      "name": "Nat20_Force_Empty"
    },
    {
      "x": -12,
      "y": 26,
      "z": -10,
      "name": "Nat20_Force_Empty"
    },
    {
      "x": -12,
      "y": 27,
      "z": -10,
      "name": "Nat20_Force_Empty"
    },
    {
      "x": -12,
      "y": 13,
      "z": -9,
      "name": "Nat20_Force_Empty"
    },
    {
      "x": -12,
      "y": 14,
      "z": -9,
      "name": "Nat20_Force_Empty"
    },
    {
      "x": -12,
      "y": 15,
      "z": -9,
      "name": "Nat20_Force_Empty"
    },
    {
      "x": -12,
      "y": 16,
      "z": -9,
      "name": "Nat20_Force_Empty"
    },
    {
      "x": -12,
      "y": 17,
      "z": -9,
      "name": "Nat20_Force_Empty"
    },
    {
      "x": -12,
      "y": 18,
      "z": -9,
      "name": "Nat20_Force_Empty"
    },
    {
      "x": -12,
      "y": 19,
      "z": -9,
      "name": "Nat20_Force_Empty"
    },
    {
      "x": -12,
      "y": 20,
      "z": -9,
      "name": "Nat20_Force_Empty"
    },
    {
      "x": -12,
      "y": 21,
      "z": -9,
      "name": "Nat20_Force_Empty"
    },
    {
      "x": -12,
      "y": 22,
      "z": -9,
      "name": "Nat20_Force_Empty"
    },
    {
      "x": -12,
      "y": 23,
      "z": -9,
      "name": "Nat20_Force_Empty"
    },
    {
      "x": -12,
      "y": 24,
      "z": -9,
      "name": "Nat20_Force_Empty"
    },
    {
      "x": -12,
      "y": 25,
      "z": -9,
      "name": "Nat20_Force_Empty"
    },
    {
      "x": -12,
      "y": 26,
      "z": -9,
      "name": "Nat20_Force_Empty"
    },
    {
      "x": -12,
      "y": 27,
      "z": -9,
      "name": "Nat20_Force_Empty"
    },
    {
      "x": -12,
      "y": 13,
      "z": -8,
      "name": "Nat20_Force_Empty"
    },
    {
      "x": -12,
      "y": 14,
      "z": -8,
      "name": "Nat20_Force_Empty"
    },
    {
      "x": -12,
      "y": 15,
      "z": -8,
      "name": "Nat20_Force_Empty"
    },
    {
      "x": -12,
      "y": 16,
      "z": -8,
      "name": "Nat20_Force_Empty"
    },
    {
      "x": -12,
      "y": 17,
      "z": -8,
      "name": "Nat20_Force_Empty"
    },
    {
      "x": -12,
      "y": 18,
      "z": -8,
      "name": "Nat20_Force_Empty"
    },
    {
      "x": -12,
      "y": 19,
      "z": -8,
      "name": "Plant_Leaves_Oak"
    },
    {
      "x": -12,
      "y": 20,
      "z": -8,
      "name": "Nat20_Force_Empty"
    },
    {
      "x": -12,
      "y": 21,
      "z": -8,
      "name": "Nat20_Force_Empty"
    },
    {
      "x": -12,
      "y": 22,
      "z": -8,
      "name": "Nat20_Force_Empty"
    },
    {
      "x": -12,
      "y": 23,
      "z": -8,
      "name": "Nat20_Force_Empty"
    },
    {
      "x": -12,
      "y": 24,
      "z": -8,
      "name": "Nat20_Force_Empty"
    },
    {
      "x": -12,
      "y": 25,
      "z": -8,
      "name": "Nat20_Force_Empty"
    },
    {
      "x": -12,
      "y": 26,
      "z": -8,
      "name": "Nat20_Force_Empty"
    },
    {
      "x": -12,
      "y": 27,
      "z": -8,
      "name": "Nat20_Force_Empty"
    },
    {
      "x": -12,
      "y": 13,
      "z": -7,
      "name": "Nat20_Force_Empty"
    },
    {
      "x": -12,
      "y": 14,
      "z": -7,
      "name": "Nat20_Force_Empty"
    },
    {
      "x": -12,
      "y": 15,
      "z": -7,
      "name": "Nat20_Force_Empty"
    },
    {
      "x": -12,
      "y": 16,
      "z": -7,
      "name": "Nat20_Force_Empty"
    },
    {
      "x": -12,
      "y": 17,
      "z": -7,
      "name": "Nat20_Force_Empty"
    },
    {
      "x": -12,
      "y": 18,
      "z": -7,
      "name": "Nat20_Force_Empty"
    },
    {
      "x": -12,
      "y": 19,
      "z": -7,
      "name": "Plant_Leaves_Oak"
    },
    {
      "x": -12,
      "y": 20,
      "z": -7,
      "name": "Nat20_Force_Empty"
    },
    {
      "x": -12,
      "y": 21,
      "z": -7,
      "name": "Nat20_Force_Empty"
    },
    {
      "x": -12,
      "y": 22,
      "z": -7,
      "name": "Nat20_Force_Empty"
    },
    {
      "x": -12,
      "y": 23,
      "z": -7,
      "name": "Nat20_Force_Empty"
    },
    {
      "x": -12,
      "y": 24,
      "z": -7,
      "name": "Nat20_Force_Empty"
    },
    {
      "x": -12,
      "y": 25,
      "z": -7,
      "name": "Nat20_Force_Empty"
    },
    {
      "x": -12,
      "y": 26,
      "z": -7,
      "name": "Nat20_Force_Empty"
    },
    {
      "x": -12,
      "y": 27,
      "z": -7,
      "name": "Nat20_Force_Empty"
    },
    {
      "x": -12,
      "y": 13,
      "z": -6,
      "name": "Nat20_Force_Empty"
    },
    {
      "x": -12,
      "y": 14,
      "z": -6,
      "name": "Nat20_Force_Empty"
    },
    {
      "x": -12,
      "y": 15,
      "z": -6,
      "name": "Nat20_Force_Empty"
    },
    {
      "x": -12,
      "y": 16,
      "z": -6,
      "name": "Nat20_Force_Empty"
    },
    {
      "x": -12,
      "y": 17,
      "z": -6,
      "name": "Nat20_Force_Empty"
    },
    {
      "x": -12,
      "y": 18,
      "z": -6,
      "name": "Plant_Leaves_Oak"
    },
    {
      "x": -12,
      "y": 19,
      "z": -6,
      "name": "Plant_Leaves_Oak"
    },
    {
      "x": -12,
      "y": 20,
      "z": -6,
      "name": "Plant_Leaves_Oak"
    },
    {
      "x": -12,
      "y": 21,
      "z": -6,
      "name": "Nat20_Force_Empty"
    },
    {
      "x": -12,
      "y": 22,
      "z": -6,
      "name": "Nat20_Force_Empty"
    },
    {
      "x": -12,
      "y": 23,
      "z": -6,
      "name": "Nat20_Force_Empty"
    },
    {
      "x": -12,
      "y": 24,
      "z": -6,
      "name": "Nat20_Force_Empty"
    },
    {
      "x": -12,
      "y": 25,
      "z": -6,
      "name": "Nat20_Force_Empty"
    },
    {
      "x": -12,
      "y": 26,
      "z": -6,
      "name": "Nat20_Force_Empty"
    },
    {
      "x": -12,
      "y": 27,
      "z": -6,
      "name": "Nat20_Force_Empty"
    },
    {
      "x": -12,
      "y": 13,
      "z": -5,
      "name": "Nat20_Force_Empty"
    },
    {
      "x": -12,
      "y": 14,
      "z": -5,
      "name": "Nat20_Force_Empty"
    },
    {
      "x": -12,
      "y": 15,
      "z": -5,
      "name": "Nat20_Force_Empty"
    },
    {
      "x": -12,
      "y": 16,
      "z": -5,
      "name": "Nat20_Force_Empty"
    },
    {
      "x": -12,
      "y": 17,
      "z": -5,
      "name": "Nat20_Force_Empty"
    },
    {
      "x": -12,
      "y": 18,
      "z": -5,
      "name": "Plant_Leaves_Oak"
    },
    {
      "x": -12,
      "y": 19,
      "z": -5,
      "name": "Plant_Leaves_Oak"
    },
    {
      "x": -12,
      "y": 20,
      "z": -5,
      "name": "Nat20_Force_Empty"
    },
    {
      "x": -12,
      "y": 21,
      "z": -5,
      "name": "Nat20_Force_Empty"
    },
    {
      "x": -12,
      "y": 22,
      "z": -5,
      "name": "Nat20_Force_Empty"
    },
    {
      "x": -12,
      "y": 23,
      "z": -5,
      "name": "Nat20_Force_Empty"
    },
    {
      "x": -12,
      "y": 24,
      "z": -5,
      "name": "Nat20_Force_Empty"
    },
    {
      "x": -12,
      "y": 25,
      "z": -5,
      "name": "Nat20_Force_Empty"
    },
    {
      "x": -12,
      "y": 26,
      "z": -5,
      "name": "Nat20_Force_Empty"
    },
    {
      "x": -12,
      "y": 27,
      "z": -5,
      "name": "Nat20_Force_Empty"
    },
    {
      "x": -12,
      "y": 13,
      "z": -4,
      "name": "Nat20_Force_Empty"
    },
    {
      "x": -12,
      "y": 14,
      "z": -4,
      "name": "Nat20_Force_Empty"
    },
    {
      "x": -12,
      "y": 15,
      "z": -4,
      "name": "Nat20_Force_Empty"
    },
    {
      "x": -12,
      "y": 16,
      "z": -4,
      "name": "Nat20_Force_Empty"
    },
    {
      "x": -12,
      "y": 17,
      "z": -4,
      "name": "Nat20_Force_Empty"
    },
    {
      "x": -12,
      "y": 18,
      "z": -4,
      "name": "Nat20_Force_Empty"
    },
    {
      "x": -12,
      "y": 19,
      "z": -4,
      "name": "Plant_Leaves_Oak"
    },
    {
      "x": -12,
      "y": 20,
      "z": -4,
      "name": "Plant_Leaves_Oak"
    },
    {
      "x": -12,
      "y": 21,
      "z": -4,
      "name": "Nat20_Force_Empty"
    },
    {
      "x": -12,
      "y": 22,
      "z": -4,
      "name": "Nat20_Force_Empty"
    },
    {
      "x": -12,
      "y": 23,
      "z": -4,
      "name": "Nat20_Force_Empty"
    },
    {
      "x": -12,
      "y": 24,
      "z": -4,
      "name": "Nat20_Force_Empty"
    },
    {
      "x": -12,
      "y": 25,
      "z": -4,
      "name": "Nat20_Force_Empty"
    },
    {
      "x": -12,
      "y": 26,
      "z": -4,
      "name": "Nat20_Force_Empty"
    },
    {
      "x": -12,
      "y": 27,
      "z": -4,
      "name": "Nat20_Force_Empty"
    },
    {
      "x": -12,
      "y": 13,
      "z": -3,
      "name": "Nat20_Force_Empty"
    },
    {
      "x": -12,
      "y": 14,
      "z": -3,
      "name": "Nat20_Force_Empty"
    },
    {
      "x": -12,
      "y": 15,
      "z": -3,
      "name": "Nat20_Force_Empty"
    },
    {
      "x": -12,
      "y": 16,
      "z": -3,
      "name": "Nat20_Force_Empty"
    },
    {
      "x": -12,
      "y": 17,
      "z": -3,
      "name": "Nat20_Force_Empty"
    },
    {
      "x": -12,
      "y": 18,
      "z": -3,
      "name": "Nat20_Force_Empty"
    },
    {
      "x": -12,
      "y": 19,
      "z": -3,
      "name": "Plant_Leaves_Oak"
    },
    {
      "x": -12,
      "y": 20,
      "z": -3,
      "name": "Nat20_Force_Empty"
    },
    {
      "x": -12,
      "y": 21,
      "z": -3,
      "name": "Nat20_Force_Empty"
    },
    {
      "x": -12,
      "y": 22,
      "z": -3,
      "name": "Nat20_Force_Empty"
    },
    {
      "x": -12,
      "y": 23,
      "z": -3,
      "name": "Nat20_Force_Empty"
    },
    {
      "x": -12,
      "y": 24,
      "z": -3,
      "name": "Nat20_Force_Empty"
    },
    {
      "x": -12,
      "y": 25,
      "z": -3,
      "name": "Nat20_Force_Empty"
    },
    {
      "x": -12,
      "y": 26,
      "z": -3,
      "name": "Nat20_Force_Empty"
    },
    {
      "x": -12,
      "y": 27,
      "z": -3,
      "name": "Nat20_Force_Empty"
    },
    {
      "x": -12,
      "y": 13,
      "z": -2,
      "name": "Nat20_Force_Empty"
    },
    {
      "x": -12,
      "y": 14,
      "z": -2,
      "name": "Nat20_Force_Empty"
    },
    {
      "x": -12,
      "y": 15,
      "z": -2,
      "name": "Nat20_Force_Empty"
    },
    {
      "x": -12,
      "y": 16,
      "z": -2,
      "name": "Nat20_Force_Empty"
    },
    {
      "x": -12,
      "y": 17,
      "z": -2,
      "name": "Nat20_Force_Empty"
    },
    {
      "x": -12,
      "y": 18,
      "z": -2,
      "name": "Nat20_Force_Empty"
    },
    {
      "x": -12,
      "y": 19,
      "z": -2,
      "name": "Plant_Leaves_Oak"
    },
    {
      "x": -12,
      "y": 20,
      "z": -2,
      "name": "Nat20_Force_Empty"
    },
    {
      "x": -12,
      "y": 21,
      "z": -2,
      "name": "Nat20_Force_Empty"
    },
    {
      "x": -12,
      "y": 22,
      "z": -2,
      "name": "Nat20_Force_Empty"
    },
    {
      "x": -12,
      "y": 23,
      "z": -2,
      "name": "Nat20_Force_Empty"
    },
    {
      "x": -12,
      "y": 24,
      "z": -2,
      "name": "Nat20_Force_Empty"
    },
    {
      "x": -12,
      "y": 25,
      "z": -2,
      "name": "Nat20_Force_Empty"
    },
    {
      "x": -12,
      "y": 26,
      "z": -2,
      "name": "Nat20_Force_Empty"
    },
    {
      "x": -12,
      "y": 27,
      "z": -2,
      "name": "Nat20_Force_Empty"
    },
    {
      "x": -12,
      "y": 13,
      "z": -1,
      "name": "Nat20_Force_Empty"
    },
    {
      "x": -12,
      "y": 14,
      "z": -1,
      "name": "Nat20_Force_Empty"
    },
    {
      "x": -12,
      "y": 15,
      "z": -1,
      "name": "Nat20_Force_Empty"
    },
    {
      "x": -12,
      "y": 16,
      "z": -1,
      "name": "Nat20_Force_Empty"
    },
    {
      "x": -12,
      "y": 17,
      "z": -1,
      "name": "Nat20_Force_Empty"
    },
    {
      "x": -12,
      "y": 18,
      "z": -1,
      "name": "Nat20_Force_Empty"
    },
    {
      "x": -12,
      "y": 19,
      "z": -1,
      "name": "Nat20_Force_Empty"
    },
    {
      "x": -12,
      "y": 20,
      "z": -1,
      "name": "Plant_Leaves_Oak"
    },
    {
      "x": -12,
      "y": 21,
      "z": -1,
      "name": "Nat20_Force_Empty"
    },
    {
      "x": -12,
      "y": 22,
      "z": -1,
      "name": "Nat20_Force_Empty"
    },
    {
      "x": -12,
      "y": 23,
      "z": -1,
      "name": "Nat20_Force_Empty"
    },
    {
      "x": -12,
      "y": 24,
      "z": -1,
      "name": "Nat20_Force_Empty"
    },
    {
      "x": -12,
      "y": 25,
      "z": -1,
      "name": "Nat20_Force_Empty"
    },
    {
      "x": -12,
      "y": 26,
      "z": -1,
      "name": "Nat20_Force_Empty"
    },
    {
      "x": -12,
      "y": 27,
      "z": -1,
      "name": "Nat20_Force_Empty"
    },
    {
      "x": -12,
      "y": 13,
      "z": 0,
      "name": "Nat20_Force_Empty"
    },
    {
      "x": -12,
      "y": 14,
      "z": 0,
      "name": "Nat20_Force_Empty"
    },
    {
      "x": -12,
      "y": 15,
      "z": 0,
      "name": "Nat20_Force_Empty"
    },
    {
      "x": -12,
      "y": 16,
      "z": 0,
      "name": "Nat20_Force_Empty"
    },
    {
      "x": -12,
      "y": 17,
      "z": 0,
      "name": "Nat20_Force_Empty"
    },
    {
      "x": -12,
      "y": 18,
      "z": 0,
      "name": "Nat20_Force_Empty"
    },
    {
      "x": -12,
      "y": 19,
      "z": 0,
      "name": "Nat20_Force_Empty"
    },
    {
      "x": -12,
      "y": 20,
      "z": 0,
      "name": "Plant_Leaves_Oak"
    },
    {
      "x": -12,
      "y": 21,
      "z": 0,
      "name": "Nat20_Force_Empty"
    },
    {
      "x": -12,
      "y": 22,
      "z": 0,
      "name": "Nat20_Force_Empty"
    },
    {
      "x": -12,
      "y": 23,
      "z": 0,
      "name": "Nat20_Force_Empty"
    },
    {
      "x": -12,
      "y": 24,
      "z": 0,
      "name": "Nat20_Force_Empty"
    },
    {
      "x": -12,
      "y": 25,
      "z": 0,
      "name": "Nat20_Force_Empty"
    },
    {
      "x": -12,
      "y": 26,
      "z": 0,
      "name": "Nat20_Force_Empty"
    },
    {
      "x": -12,
      "y": 27,
      "z": 0,
      "name": "Nat20_Force_Empty"
    },
    {
      "x": -12,
      "y": 13,
      "z": 1,
      "name": "Nat20_Force_Empty"
    },
    {
      "x": -12,
      "y": 14,
      "z": 1,
      "name": "Nat20_Force_Empty"
    },
    {
      "x": -12,
      "y": 15,
      "z": 1,
      "name": "Nat20_Force_Empty"
    },
    {
      "x": -12,
      "y": 16,
      "z": 1,
      "name": "Nat20_Force_Empty"
    },
    {
      "x": -12,
      "y": 17,
      "z": 1,
      "name": "Nat20_Force_Empty"
    },
    {
      "x": -12,
      "y": 18,
      "z": 1,
      "name": "Nat20_Force_Empty"
    },
    {
      "x": -12,
      "y": 19,
      "z": 1,
      "name": "Nat20_Force_Empty"
    },
    {
      "x": -12,
      "y": 20,
      "z": 1,
      "name": "Plant_Leaves_Oak"
    },
    {
      "x": -12,
      "y": 21,
      "z": 1,
      "name": "Nat20_Force_Empty"
    },
    {
      "x": -12,
      "y": 22,
      "z": 1,
      "name": "Nat20_Force_Empty"
    },
    {
      "x": -12,
      "y": 23,
      "z": 1,
      "name": "Nat20_Force_Empty"
    },
    {
      "x": -12,
      "y": 24,
      "z": 1,
      "name": "Nat20_Force_Empty"
    },
    {
      "x": -12,
      "y": 25,
      "z": 1,
      "name": "Nat20_Force_Empty"
    },
    {
      "x": -12,
      "y": 26,
      "z": 1,
      "name": "Nat20_Force_Empty"
    },
    {
      "x": -12,
      "y": 27,
      "z": 1,
      "name": "Nat20_Force_Empty"
    },
    {
      "x": -12,
      "y": 13,
      "z": 2,
      "name": "Nat20_Force_Empty"
    },
    {
      "x": -12,
      "y": 14,
      "z": 2,
      "name": "Nat20_Force_Empty"
    },
    {
      "x": -12,
      "y": 15,
      "z": 2,
      "name": "Nat20_Force_Empty"
    },
    {
      "x": -12,
      "y": 16,
      "z": 2,
      "name": "Nat20_Force_Empty"
    },
    {
      "x": -12,
      "y": 17,
      "z": 2,
      "name": "Nat20_Force_Empty"
    },
    {
      "x": -12,
      "y": 18,
      "z": 2,
      "name": "Nat20_Force_Empty"
    },
    {
      "x": -12,
      "y": 19,
      "z": 2,
      "name": "Nat20_Force_Empty"
    },
    {
      "x": -12,
      "y": 20,
      "z": 2,
      "name": "Nat20_Force_Empty"
    },
    {
      "x": -12,
      "y": 21,
      "z": 2,
      "name": "Nat20_Force_Empty"
    },
    {
      "x": -12,
      "y": 22,
      "z": 2,
      "name": "Nat20_Force_Empty"
    },
    {
      "x": -12,
      "y": 23,
      "z": 2,
      "name": "Nat20_Force_Empty"
    },
    {
      "x": -12,
      "y": 24,
      "z": 2,
      "name": "Nat20_Force_Empty"
    },
    {
      "x": -12,
      "y": 25,
      "z": 2,
      "name": "Nat20_Force_Empty"
    },
    {
      "x": -12,
      "y": 26,
      "z": 2,
      "name": "Nat20_Force_Empty"
    },
    {
      "x": -12,
      "y": 27,
      "z": 2,
      "name": "Nat20_Force_Empty"
    },
    {
      "x": -12,
      "y": 13,
      "z": 3,
      "name": "Nat20_Force_Empty"
    },
    {
      "x": -12,
      "y": 14,
      "z": 3,
      "name": "Nat20_Force_Empty"
    },
    {
      "x": -12,
      "y": 15,
      "z": 3,
      "name": "Nat20_Force_Empty"
    },
    {
      "x": -12,
      "y": 16,
      "z": 3,
      "name": "Nat20_Force_Empty"
    },
    {
      "x": -12,
      "y": 17,
      "z": 3,
      "name": "Nat20_Force_Empty"
    },
    {
      "x": -12,
      "y": 18,
      "z": 3,
      "name": "Nat20_Force_Empty"
    },
    {
      "x": -12,
      "y": 19,
      "z": 3,
      "name": "Nat20_Force_Empty"
    },
    {
      "x": -12,
      "y": 20,
      "z": 3,
      "name": "Nat20_Force_Empty"
    },
    {
      "x": -12,
      "y": 21,
      "z": 3,
      "name": "Nat20_Force_Empty"
    },
    {
      "x": -12,
      "y": 22,
      "z": 3,
      "name": "Nat20_Force_Empty"
    },
    {
      "x": -12,
      "y": 23,
      "z": 3,
      "name": "Nat20_Force_Empty"
    },
    {
      "x": -12,
      "y": 24,
      "z": 3,
      "name": "Nat20_Force_Empty"
    },
    {
      "x": -12,
      "y": 25,
      "z": 3,
      "name": "Nat20_Force_Empty"
    },
    {
      "x": -12,
      "y": 26,
      "z": 3,
      "name": "Nat20_Force_Empty"
    },
    {
      "x": -12,
      "y": 27,
      "z": 3,
      "name": "Nat20_Force_Empty"
    },
    {
      "x": -12,
      "y": 13,
      "z": 4,
      "name": "Nat20_Force_Empty"
    },
    {
      "x": -12,
      "y": 14,
      "z": 4,
      "name": "Nat20_Force_Empty"
    },
    {
      "x": -12,
      "y": 15,
      "z": 4,
      "name": "Nat20_Force_Empty"
    },
    {
      "x": -12,
      "y": 16,
      "z": 4,
      "name": "Nat20_Force_Empty"
    },
    {
      "x": -12,
      "y": 17,
      "z": 4,
      "name": "Nat20_Force_Empty"
    },
    {
      "x": -12,
      "y": 18,
      "z": 4,
      "name": "Nat20_Force_Empty"
    },
    {
      "x": -12,
      "y": 19,
      "z": 4,
      "name": "Nat20_Force_Empty"
    },
    {
      "x": -12,
      "y": 20,
      "z": 4,
      "name": "Nat20_Force_Empty"
    },
    {
      "x": -12,
      "y": 21,
      "z": 4,
      "name": "Nat20_Force_Empty"
    },
    {
      "x": -12,
      "y": 22,
      "z": 4,
      "name": "Nat20_Force_Empty"
    },
    {
      "x": -12,
      "y": 23,
      "z": 4,
      "name": "Nat20_Force_Empty"
    },
    {
      "x": -12,
      "y": 24,
      "z": 4,
      "name": "Nat20_Force_Empty"
    },
    {
      "x": -12,
      "y": 25,
      "z": 4,
      "name": "Nat20_Force_Empty"
    },
    {
      "x": -12,
      "y": 26,
      "z": 4,
      "name": "Nat20_Force_Empty"
    },
    {
      "x": -12,
      "y": 27,
      "z": 4,
      "name": "Nat20_Force_Empty"
    },
    {
      "x": -12,
      "y": 13,
      "z": 5,
      "name": "Nat20_Force_Empty"
    },
    {
      "x": -12,
      "y": 14,
      "z": 5,
      "name": "Nat20_Force_Empty"
    },
    {
      "x": -12,
      "y": 15,
      "z": 5,
      "name": "Nat20_Force_Empty"
    },
    {
      "x": -12,
      "y": 16,
      "z": 5,
      "name": "Nat20_Force_Empty"
    },
    {
      "x": -12,
      "y": 17,
      "z": 5,
      "name": "Nat20_Force_Empty"
    },
    {
      "x": -12,
      "y": 18,
      "z": 5,
      "name": "Nat20_Force_Empty"
    },
    {
      "x": -12,
      "y": 19,
      "z": 5,
      "name": "Nat20_Force_Empty"
    },
    {
      "x": -12,
      "y": 20,
      "z": 5,
      "name": "Nat20_Force_Empty"
    },
    {
      "x": -12,
      "y": 21,
      "z": 5,
      "name": "Nat20_Force_Empty"
    },
    {
      "x": -12,
      "y": 22,
      "z": 5,
      "name": "Nat20_Force_Empty"
    },
    {
      "x": -12,
      "y": 23,
      "z": 5,
      "name": "Nat20_Force_Empty"
    },
    {
      "x": -12,
      "y": 24,
      "z": 5,
      "name": "Nat20_Force_Empty"
    },
    {
      "x": -12,
      "y": 25,
      "z": 5,
      "name": "Nat20_Force_Empty"
    },
    {
      "x": -12,
      "y": 26,
      "z": 5,
      "name": "Nat20_Force_Empty"
    },
    {
      "x": -12,
      "y": 27,
      "z": 5,
      "name": "Nat20_Force_Empty"
    },
    {
      "x": -12,
      "y": 13,
      "z": 6,
      "name": "Nat20_Force_Empty"
    },
    {
      "x": -12,
      "y": 14,
      "z": 6,
      "name": "Nat20_Force_Empty"
    },
    {
      "x": -12,
      "y": 15,
      "z": 6,
      "name": "Nat20_Force_Empty"
    },
    {
      "x": -12,
      "y": 16,
      "z": 6,
      "name": "Nat20_Force_Empty"
    },
    {
      "x": -12,
      "y": 17,
      "z": 6,
      "name": "Nat20_Force_Empty"
    },
    {
      "x": -12,
      "y": 18,
      "z": 6,
      "name": "Nat20_Force_Empty"
    },
    {
      "x": -12,
      "y": 19,
      "z": 6,
      "name": "Nat20_Force_Empty"
    },
    {
      "x": -12,
      "y": 20,
      "z": 6,
      "name": "Nat20_Force_Empty"
    },
    {
      "x": -12,
      "y": 21,
      "z": 6,
      "name": "Nat20_Force_Empty"
    },
    {
      "x": -12,
      "y": 22,
      "z": 6,
      "name": "Nat20_Force_Empty"
    },
    {
      "x": -12,
      "y": 23,
      "z": 6,
      "name": "Nat20_Force_Empty"
    },
    {
      "x": -12,
      "y": 24,
      "z": 6,
      "name": "Nat20_Force_Empty"
    },
    {
      "x": -12,
      "y": 25,
      "z": 6,
      "name": "Nat20_Force_Empty"
    },
    {
      "x": -12,
      "y": 26,
      "z": 6,
      "name": "Nat20_Force_Empty"
    },
    {
      "x": -12,
      "y": 27,
      "z": 6,
      "name": "Nat20_Force_Empty"
    },
    {
      "x": -12,
      "y": 13,
      "z": 7,
      "name": "Nat20_Force_Empty"
    },
    {
      "x": -12,
      "y": 14,
      "z": 7,
      "name": "Nat20_Force_Empty"
    },
    {
      "x": -12,
      "y": 15,
      "z": 7,
      "name": "Nat20_Force_Empty"
    },
    {
      "x": -12,
      "y": 16,
      "z": 7,
      "name": "Nat20_Force_Empty"
    },
    {
      "x": -12,
      "y": 17,
      "z": 7,
      "name": "Nat20_Force_Empty"
    },
    {
      "x": -12,
      "y": 18,
      "z": 7,
      "name": "Nat20_Force_Empty"
    },
    {
      "x": -12,
      "y": 19,
      "z": 7,
      "name": "Nat20_Force_Empty"
    },
    {
      "x": -12,
      "y": 20,
      "z": 7,
      "name": "Nat20_Force_Empty"
    },
    {
      "x": -12,
      "y": 21,
      "z": 7,
      "name": "Nat20_Force_Empty"
    },
    {
      "x": -12,
      "y": 22,
      "z": 7,
      "name": "Nat20_Force_Empty"
    },
    {
      "x": -12,
      "y": 23,
      "z": 7,
      "name": "Nat20_Force_Empty"
    },
    {
      "x": -12,
      "y": 24,
      "z": 7,
      "name": "Nat20_Force_Empty"
    },
    {
      "x": -12,
      "y": 25,
      "z": 7,
      "name": "Nat20_Force_Empty"
    },
    {
      "x": -12,
      "y": 26,
      "z": 7,
      "name": "Nat20_Force_Empty"
    },
    {
      "x": -12,
      "y": 27,
      "z": 7,
      "name": "Nat20_Force_Empty"
    },
    {
      "x": -12,
      "y": 13,
      "z": 8,
      "name": "Nat20_Force_Empty"
    },
    {
      "x": -12,
      "y": 14,
      "z": 8,
      "name": "Nat20_Force_Empty"
    },
    {
      "x": -12,
      "y": 15,
      "z": 8,
      "name": "Nat20_Force_Empty"
    },
    {
      "x": -12,
      "y": 16,
      "z": 8,
      "name": "Nat20_Force_Empty"
    },
    {
      "x": -12,
      "y": 17,
      "z": 8,
      "name": "Nat20_Force_Empty"
    },
    {
      "x": -12,
      "y": 18,
      "z": 8,
      "name": "Nat20_Force_Empty"
    },
    {
      "x": -12,
      "y": 19,
      "z": 8,
      "name": "Nat20_Force_Empty"
    },
    {
      "x": -12,
      "y": 20,
      "z": 8,
      "name": "Nat20_Force_Empty"
    },
    {
      "x": -12,
      "y": 21,
      "z": 8,
      "name": "Nat20_Force_Empty"
    },
    {
      "x": -12,
      "y": 22,
      "z": 8,
      "name": "Nat20_Force_Empty"
    },
    {
      "x": -12,
      "y": 23,
      "z": 8,
      "name": "Nat20_Force_Empty"
    },
    {
      "x": -12,
      "y": 24,
      "z": 8,
      "name": "Nat20_Force_Empty"
    },
    {
      "x": -12,
      "y": 25,
      "z": 8,
      "name": "Nat20_Force_Empty"
    },
    {
      "x": -12,
      "y": 26,
      "z": 8,
      "name": "Nat20_Force_Empty"
    },
    {
      "x": -12,
      "y": 27,
      "z": 8,
      "name": "Nat20_Force_Empty"
    },
    {
      "x": -12,
      "y": 13,
      "z": 9,
      "name": "Nat20_Force_Empty"
    },
    {
      "x": -12,
      "y": 14,
      "z": 9,
      "name": "Nat20_Force_Empty"
    },
    {
      "x": -12,
      "y": 15,
      "z": 9,
      "name": "Nat20_Force_Empty"
    },
    {
      "x": -12,
      "y": 16,
      "z": 9,
      "name": "Nat20_Force_Empty"
    },
    {
      "x": -12,
      "y": 17,
      "z": 9,
      "name": "Nat20_Force_Empty"
    },
    {
      "x": -12,
      "y": 18,
      "z": 9,
      "name": "Nat20_Force_Empty"
    },
    {
      "x": -12,
      "y": 19,
      "z": 9,
      "name": "Nat20_Force_Empty"
    },
    {
      "x": -12,
      "y": 20,
      "z": 9,
      "name": "Nat20_Force_Empty"
    },
    {
      "x": -12,
      "y": 21,
      "z": 9,
      "name": "Nat20_Force_Empty"
    },
    {
      "x": -12,
      "y": 22,
      "z": 9,
      "name": "Nat20_Force_Empty"
    },
    {
      "x": -12,
      "y": 23,
      "z": 9,
      "name": "Nat20_Force_Empty"
    },
    {
      "x": -12,
      "y": 24,
      "z": 9,
      "name": "Nat20_Force_Empty"
    },
    {
      "x": -12,
      "y": 25,
      "z": 9,
      "name": "Nat20_Force_Empty"
    },
    {
      "x": -12,
      "y": 26,
      "z": 9,
      "name": "Nat20_Force_Empty"
    },
    {
      "x": -12,
      "y": 27,
      "z": 9,
      "name": "Nat20_Force_Empty"
    },
    {
      "x": -12,
      "y": 13,
      "z": 10,
      "name": "Nat20_Force_Empty"
    },
    {
      "x": -12,
      "y": 14,
      "z": 10,
      "name": "Nat20_Force_Empty"
    },
    {
      "x": -12,
      "y": 15,
      "z": 10,
      "name": "Nat20_Force_Empty"
    },
    {
      "x": -12,
      "y": 16,
      "z": 10,
      "name": "Nat20_Force_Empty"
    },
    {
      "x": -12,
      "y": 17,
      "z": 10,
      "name": "Nat20_Force_Empty"
    },
    {
      "x": -12,
      "y": 18,
      "z": 10,
      "name": "Nat20_Force_Empty"
    },
    {
      "x": -12,
      "y": 19,
      "z": 10,
      "name": "Nat20_Force_Empty"
    },
    {
      "x": -12,
      "y": 20,
      "z": 10,
      "name": "Nat20_Force_Empty"
    },
    {
      "x": -12,
      "y": 21,
      "z": 10,
      "name": "Nat20_Force_Empty"
    },
    {
      "x": -12,
      "y": 22,
      "z": 10,
      "name": "Nat20_Force_Empty"
    },
    {
      "x": -12,
      "y": 23,
      "z": 10,
      "name": "Nat20_Force_Empty"
    },
    {
      "x": -12,
      "y": 24,
      "z": 10,
      "name": "Nat20_Force_Empty"
    },
    {
      "x": -12,
      "y": 25,
      "z": 10,
      "name": "Nat20_Force_Empty"
    },
    {
      "x": -12,
      "y": 26,
      "z": 10,
      "name": "Nat20_Force_Empty"
    },
    {
      "x": -12,
      "y": 27,
      "z": 10,
      "name": "Nat20_Force_Empty"
    },
    {
      "x": -12,
      "y": 13,
      "z": 11,
      "name": "Nat20_Force_Empty"
    },
    {
      "x": -12,
      "y": 14,
      "z": 11,
      "name": "Nat20_Force_Empty"
    },
    {
      "x": -12,
      "y": 15,
      "z": 11,
      "name": "Nat20_Force_Empty"
    },
    {
      "x": -12,
      "y": 16,
      "z": 11,
      "name": "Nat20_Force_Empty"
    },
    {
      "x": -12,
      "y": 17,
      "z": 11,
      "name": "Nat20_Force_Empty"
    },
    {
      "x": -12,
      "y": 18,
      "z": 11,
      "name": "Nat20_Force_Empty"
    },
    {
      "x": -12,
      "y": 19,
      "z": 11,
      "name": "Nat20_Force_Empty"
    },
    {
      "x": -12,
      "y": 20,
      "z": 11,
      "name": "Nat20_Force_Empty"
    },
    {
      "x": -12,
      "y": 21,
      "z": 11,
      "name": "Nat20_Force_Empty"
    },
    {
      "x": -12,
      "y": 22,
      "z": 11,
      "name": "Nat20_Force_Empty"
    },
    {
      "x": -12,
      "y": 23,
      "z": 11,
      "name": "Nat20_Force_Empty"
    },
    {
      "x": -12,
      "y": 24,
      "z": 11,
      "name": "Nat20_Force_Empty"
    },
    {
      "x": -12,
      "y": 25,
      "z": 11,
      "name": "Nat20_Force_Empty"
    },
    {
      "x": -12,
      "y": 26,
      "z": 11,
      "name": "Nat20_Force_Empty"
    },
    {
      "x": -12,
      "y": 27,
      "z": 11,
      "name": "Nat20_Force_Empty"
    },
    {
      "x": -12,
      "y": 13,
      "z": 12,
      "name": "Nat20_Force_Empty"
    },
    {
      "x": -12,
      "y": 14,
      "z": 12,
      "name": "Nat20_Force_Empty"
    },
    {
      "x": -12,
      "y": 15,
      "z": 12,
      "name": "Nat20_Force_Empty"
    },
    {
      "x": -12,
      "y": 16,
      "z": 12,
      "name": "Nat20_Force_Empty"
    },
    {
      "x": -12,
      "y": 17,
      "z": 12,
      "name": "Nat20_Force_Empty"
    },
    {
      "x": -12,
      "y": 18,
      "z": 12,
      "name": "Nat20_Force_Empty"
    },
    {
      "x": -12,
      "y": 19,
      "z": 12,
      "name": "Nat20_Force_Empty"
    },
    {
      "x": -12,
      "y": 20,
      "z": 12,
      "name": "Nat20_Force_Empty"
    },
    {
      "x": -12,
      "y": 21,
      "z": 12,
      "name": "Nat20_Force_Empty"
    },
    {
      "x": -12,
      "y": 22,
      "z": 12,
      "name": "Nat20_Force_Empty"
    },
    {
      "x": -12,
      "y": 23,
      "z": 12,
      "name": "Nat20_Force_Empty"
    },
    {
      "x": -12,
      "y": 24,
      "z": 12,
      "name": "Nat20_Force_Empty"
    },
    {
      "x": -12,
      "y": 25,
      "z": 12,
      "name": "Nat20_Force_Empty"
    },
    {
      "x": -12,
      "y": 26,
      "z": 12,
      "name": "Nat20_Force_Empty"
    },
    {
      "x": -12,
      "y": 27,
      "z": 12,
      "name": "Nat20_Force_Empty"
    },
    {
      "x": -11,
      "y": 13,
      "z": -12,
      "name": "Nat20_Force_Empty"
    },
    {
      "x": -11,
      "y": 14,
      "z": -12,
      "name": "Nat20_Force_Empty"
    },
    {
      "x": -11,
      "y": 15,
      "z": -12,
      "name": "Nat20_Force_Empty"
    },
    {
      "x": -11,
      "y": 16,
      "z": -12,
      "name": "Nat20_Force_Empty"
    },
    {
      "x": -11,
      "y": 17,
      "z": -12,
      "name": "Nat20_Force_Empty"
    },
    {
      "x": -11,
      "y": 18,
      "z": -12,
      "name": "Nat20_Force_Empty"
    },
    {
      "x": -11,
      "y": 19,
      "z": -12,
      "name": "Nat20_Force_Empty"
    },
    {
      "x": -11,
      "y": 20,
      "z": -12,
      "name": "Nat20_Force_Empty"
    },
    {
      "x": -11,
      "y": 21,
      "z": -12,
      "name": "Nat20_Force_Empty"
    },
    {
      "x": -11,
      "y": 22,
      "z": -12,
      "name": "Nat20_Force_Empty"
    },
    {
      "x": -11,
      "y": 23,
      "z": -12,
      "name": "Nat20_Force_Empty"
    },
    {
      "x": -11,
      "y": 24,
      "z": -12,
      "name": "Nat20_Force_Empty"
    },
    {
      "x": -11,
      "y": 25,
      "z": -12,
      "name": "Nat20_Force_Empty"
    },
    {
      "x": -11,
      "y": 26,
      "z": -12,
      "name": "Nat20_Force_Empty"
    },
    {
      "x": -11,
      "y": 27,
      "z": -12,
      "name": "Nat20_Force_Empty"
    },
    {
      "x": -11,
      "y": 13,
      "z": -11,
      "name": "Nat20_Force_Empty"
    },
    {
      "x": -11,
      "y": 14,
      "z": -11,
      "name": "Nat20_Force_Empty"
    },
    {
      "x": -11,
      "y": 15,
      "z": -11,
      "name": "Nat20_Force_Empty"
    },
    {
      "x": -11,
      "y": 16,
      "z": -11,
      "name": "Nat20_Force_Empty"
    },
    {
      "x": -11,
      "y": 17,
      "z": -11,
      "name": "Nat20_Force_Empty"
    },
    {
      "x": -11,
      "y": 18,
      "z": -11,
      "name": "Nat20_Force_Empty"
    },
    {
      "x": -11,
      "y": 19,
      "z": -11,
      "name": "Nat20_Force_Empty"
    },
    {
      "x": -11,
      "y": 20,
      "z": -11,
      "name": "Nat20_Force_Empty"
    },
    {
      "x": -11,
      "y": 21,
      "z": -11,
      "name": "Nat20_Force_Empty"
    },
    {
      "x": -11,
      "y": 22,
      "z": -11,
      "name": "Nat20_Force_Empty"
    },
    {
      "x": -11,
      "y": 23,
      "z": -11,
      "name": "Nat20_Force_Empty"
    },
    {
      "x": -11,
      "y": 24,
      "z": -11,
      "name": "Nat20_Force_Empty"
    },
    {
      "x": -11,
      "y": 25,
      "z": -11,
      "name": "Nat20_Force_Empty"
    },
    {
      "x": -11,
      "y": 26,
      "z": -11,
      "name": "Nat20_Force_Empty"
    },
    {
      "x": -11,
      "y": 27,
      "z": -11,
      "name": "Nat20_Force_Empty"
    },
    {
      "x": -11,
      "y": 13,
      "z": -10,
      "name": "Nat20_Force_Empty"
    },
    {
      "x": -11,
      "y": 14,
      "z": -10,
      "name": "Nat20_Force_Empty"
    },
    {
      "x": -11,
      "y": 15,
      "z": -10,
      "name": "Nat20_Force_Empty"
    },
    {
      "x": -11,
      "y": 16,
      "z": -10,
      "name": "Nat20_Force_Empty"
    },
    {
      "x": -11,
      "y": 17,
      "z": -10,
      "name": "Nat20_Force_Empty"
    },
    {
      "x": -11,
      "y": 18,
      "z": -10,
      "name": "Nat20_Force_Empty"
    },
    {
      "x": -11,
      "y": 19,
      "z": -10,
      "name": "Nat20_Force_Empty"
    },
    {
      "x": -11,
      "y": 20,
      "z": -10,
      "name": "Nat20_Force_Empty"
    },
    {
      "x": -11,
      "y": 21,
      "z": -10,
      "name": "Nat20_Force_Empty"
    },
    {
      "x": -11,
      "y": 22,
      "z": -10,
      "name": "Nat20_Force_Empty"
    },
    {
      "x": -11,
      "y": 23,
      "z": -10,
      "name": "Nat20_Force_Empty"
    },
    {
      "x": -11,
      "y": 24,
      "z": -10,
      "name": "Nat20_Force_Empty"
    },
    {
      "x": -11,
      "y": 25,
      "z": -10,
      "name": "Nat20_Force_Empty"
    },
    {
      "x": -11,
      "y": 26,
      "z": -10,
      "name": "Nat20_Force_Empty"
    },
    {
      "x": -11,
      "y": 27,
      "z": -10,
      "name": "Nat20_Force_Empty"
    },
    {
      "x": -11,
      "y": 13,
      "z": -9,
      "name": "Nat20_Force_Empty"
    },
    {
      "x": -11,
      "y": 14,
      "z": -9,
      "name": "Nat20_Force_Empty"
    },
    {
      "x": -11,
      "y": 15,
      "z": -9,
      "name": "Nat20_Force_Empty"
    },
    {
      "x": -11,
      "y": 16,
      "z": -9,
      "name": "Nat20_Force_Empty"
    },
    {
      "x": -11,
      "y": 17,
      "z": -9,
      "name": "Nat20_Force_Empty"
    },
    {
      "x": -11,
      "y": 18,
      "z": -9,
      "name": "Nat20_Force_Empty"
    },
    {
      "x": -11,
      "y": 19,
      "z": -9,
      "name": "Nat20_Force_Empty"
    },
    {
      "x": -11,
      "y": 20,
      "z": -9,
      "name": "Nat20_Force_Empty"
    },
    {
      "x": -11,
      "y": 21,
      "z": -9,
      "name": "Nat20_Force_Empty"
    },
    {
      "x": -11,
      "y": 22,
      "z": -9,
      "name": "Nat20_Force_Empty"
    },
    {
      "x": -11,
      "y": 23,
      "z": -9,
      "name": "Nat20_Force_Empty"
    },
    {
      "x": -11,
      "y": 24,
      "z": -9,
      "name": "Nat20_Force_Empty"
    },
    {
      "x": -11,
      "y": 25,
      "z": -9,
      "name": "Nat20_Force_Empty"
    },
    {
      "x": -11,
      "y": 26,
      "z": -9,
      "name": "Nat20_Force_Empty"
    },
    {
      "x": -11,
      "y": 27,
      "z": -9,
      "name": "Nat20_Force_Empty"
    },
    {
      "x": -11,
      "y": 13,
      "z": -8,
      "name": "Nat20_Force_Empty"
    },
    {
      "x": -11,
      "y": 14,
      "z": -8,
      "name": "Nat20_Force_Empty"
    },
    {
      "x": -11,
      "y": 15,
      "z": -8,
      "name": "Nat20_Force_Empty"
    },
    {
      "x": -11,
      "y": 16,
      "z": -8,
      "name": "Nat20_Force_Empty"
    },
    {
      "x": -11,
      "y": 17,
      "z": -8,
      "name": "Nat20_Force_Empty"
    },
    {
      "x": -11,
      "y": 18,
      "z": -8,
      "name": "Nat20_Force_Empty"
    },
    {
      "x": -11,
      "y": 19,
      "z": -8,
      "name": "Plant_Leaves_Oak"
    },
    {
      "x": -11,
      "y": 20,
      "z": -8,
      "name": "Nat20_Force_Empty"
    },
    {
      "x": -11,
      "y": 21,
      "z": -8,
      "name": "Nat20_Force_Empty"
    },
    {
      "x": -11,
      "y": 22,
      "z": -8,
      "name": "Nat20_Force_Empty"
    },
    {
      "x": -11,
      "y": 23,
      "z": -8,
      "name": "Nat20_Force_Empty"
    },
    {
      "x": -11,
      "y": 24,
      "z": -8,
      "name": "Nat20_Force_Empty"
    },
    {
      "x": -11,
      "y": 25,
      "z": -8,
      "name": "Nat20_Force_Empty"
    },
    {
      "x": -11,
      "y": 26,
      "z": -8,
      "name": "Nat20_Force_Empty"
    },
    {
      "x": -11,
      "y": 27,
      "z": -8,
      "name": "Nat20_Force_Empty"
    },
    {
      "x": -11,
      "y": 13,
      "z": -7,
      "name": "Nat20_Force_Empty"
    },
    {
      "x": -11,
      "y": 14,
      "z": -7,
      "name": "Nat20_Force_Empty"
    },
    {
      "x": -11,
      "y": 15,
      "z": -7,
      "name": "Nat20_Force_Empty"
    },
    {
      "x": -11,
      "y": 16,
      "z": -7,
      "name": "Nat20_Force_Empty"
    },
    {
      "x": -11,
      "y": 17,
      "z": -7,
      "name": "Nat20_Force_Empty"
    },
    {
      "x": -11,
      "y": 18,
      "z": -7,
      "name": "Nat20_Force_Empty"
    },
    {
      "x": -11,
      "y": 19,
      "z": -7,
      "name": "Plant_Leaves_Oak"
    },
    {
      "x": -11,
      "y": 20,
      "z": -7,
      "name": "Plant_Leaves_Oak"
    },
    {
      "x": -11,
      "y": 21,
      "z": -7,
      "name": "Nat20_Force_Empty"
    },
    {
      "x": -11,
      "y": 22,
      "z": -7,
      "name": "Nat20_Force_Empty"
    },
    {
      "x": -11,
      "y": 23,
      "z": -7,
      "name": "Nat20_Force_Empty"
    },
    {
      "x": -11,
      "y": 24,
      "z": -7,
      "name": "Nat20_Force_Empty"
    },
    {
      "x": -11,
      "y": 25,
      "z": -7,
      "name": "Nat20_Force_Empty"
    },
    {
      "x": -11,
      "y": 26,
      "z": -7,
      "name": "Nat20_Force_Empty"
    },
    {
      "x": -11,
      "y": 27,
      "z": -7,
      "name": "Nat20_Force_Empty"
    },
    {
      "x": -11,
      "y": 13,
      "z": -6,
      "name": "Nat20_Force_Empty"
    },
    {
      "x": -11,
      "y": 14,
      "z": -6,
      "name": "Nat20_Force_Empty"
    },
    {
      "x": -11,
      "y": 15,
      "z": -6,
      "name": "Nat20_Force_Empty"
    },
    {
      "x": -11,
      "y": 16,
      "z": -6,
      "name": "Nat20_Force_Empty"
    },
    {
      "x": -11,
      "y": 17,
      "z": -6,
      "name": "Nat20_Force_Empty"
    },
    {
      "x": -11,
      "y": 18,
      "z": -6,
      "name": "Plant_Leaves_Oak"
    },
    {
      "x": -11,
      "y": 19,
      "z": -6,
      "name": "Plant_Leaves_Oak"
    },
    {
      "x": -11,
      "y": 20,
      "z": -6,
      "name": "Plant_Leaves_Oak"
    },
    {
      "x": -11,
      "y": 21,
      "z": -6,
      "name": "Nat20_Force_Empty"
    },
    {
      "x": -11,
      "y": 22,
      "z": -6,
      "name": "Nat20_Force_Empty"
    },
    {
      "x": -11,
      "y": 23,
      "z": -6,
      "name": "Nat20_Force_Empty"
    },
    {
      "x": -11,
      "y": 24,
      "z": -6,
      "name": "Nat20_Force_Empty"
    },
    {
      "x": -11,
      "y": 25,
      "z": -6,
      "name": "Nat20_Force_Empty"
    },
    {
      "x": -11,
      "y": 26,
      "z": -6,
      "name": "Nat20_Force_Empty"
    },
    {
      "x": -11,
      "y": 27,
      "z": -6,
      "name": "Nat20_Force_Empty"
    },
    {
      "x": -11,
      "y": 13,
      "z": -5,
      "name": "Nat20_Force_Empty"
    },
    {
      "x": -11,
      "y": 14,
      "z": -5,
      "name": "Nat20_Force_Empty"
    },
    {
      "x": -11,
      "y": 15,
      "z": -5,
      "name": "Nat20_Force_Empty"
    },
    {
      "x": -11,
      "y": 16,
      "z": -5,
      "name": "Nat20_Force_Empty"
    },
    {
      "x": -11,
      "y": 17,
      "z": -5,
      "name": "Nat20_Force_Empty"
    },
    {
      "x": -11,
      "y": 18,
      "z": -5,
      "name": "Wood_Oak_Branch_Corner",
      "rotation": 3
    },
    {
      "x": -11,
      "y": 19,
      "z": -5,
      "name": "Plant_Leaves_Oak"
    },
    {
      "x": -11,
      "y": 20,
      "z": -5,
      "name": "Plant_Leaves_Oak"
    },
    {
      "x": -11,
      "y": 21,
      "z": -5,
      "name": "Nat20_Force_Empty"
    },
    {
      "x": -11,
      "y": 22,
      "z": -5,
      "name": "Nat20_Force_Empty"
    },
    {
      "x": -11,
      "y": 23,
      "z": -5,
      "name": "Nat20_Force_Empty"
    },
    {
      "x": -11,
      "y": 24,
      "z": -5,
      "name": "Nat20_Force_Empty"
    },
    {
      "x": -11,
      "y": 25,
      "z": -5,
      "name": "Nat20_Force_Empty"
    },
    {
      "x": -11,
      "y": 26,
      "z": -5,
      "name": "Nat20_Force_Empty"
    },
    {
      "x": -11,
      "y": 27,
      "z": -5,
      "name": "Nat20_Force_Empty"
    },
    {
      "x": -11,
      "y": 13,
      "z": -4,
      "name": "Nat20_Force_Empty"
    },
    {
      "x": -11,
      "y": 14,
      "z": -4,
      "name": "Nat20_Force_Empty"
    },
    {
      "x": -11,
      "y": 15,
      "z": -4,
      "name": "Nat20_Force_Empty"
    },
    {
      "x": -11,
      "y": 16,
      "z": -4,
      "name": "Nat20_Force_Empty"
    },
    {
      "x": -11,
      "y": 17,
      "z": -4,
      "name": "Nat20_Force_Empty"
    },
    {
      "x": -11,
      "y": 18,
      "z": -4,
      "name": "Plant_Leaves_Oak"
    },
    {
      "x": -11,
      "y": 19,
      "z": -4,
      "name": "Plant_Leaves_Oak"
    },
    {
      "x": -11,
      "y": 20,
      "z": -4,
      "name": "Plant_Leaves_Oak"
    },
    {
      "x": -11,
      "y": 21,
      "z": -4,
      "name": "Nat20_Force_Empty"
    },
    {
      "x": -11,
      "y": 22,
      "z": -4,
      "name": "Nat20_Force_Empty"
    },
    {
      "x": -11,
      "y": 23,
      "z": -4,
      "name": "Nat20_Force_Empty"
    },
    {
      "x": -11,
      "y": 24,
      "z": -4,
      "name": "Nat20_Force_Empty"
    },
    {
      "x": -11,
      "y": 25,
      "z": -4,
      "name": "Nat20_Force_Empty"
    },
    {
      "x": -11,
      "y": 26,
      "z": -4,
      "name": "Nat20_Force_Empty"
    },
    {
      "x": -11,
      "y": 27,
      "z": -4,
      "name": "Nat20_Force_Empty"
    },
    {
      "x": -11,
      "y": 13,
      "z": -3,
      "name": "Nat20_Force_Empty"
    },
    {
      "x": -11,
      "y": 14,
      "z": -3,
      "name": "Nat20_Force_Empty"
    },
    {
      "x": -11,
      "y": 15,
      "z": -3,
      "name": "Nat20_Force_Empty"
    },
    {
      "x": -11,
      "y": 16,
      "z": -3,
      "name": "Nat20_Force_Empty"
    },
    {
      "x": -11,
      "y": 17,
      "z": -3,
      "name": "Nat20_Force_Empty"
    },
    {
      "x": -11,
      "y": 18,
      "z": -3,
      "name": "Nat20_Force_Empty"
    },
    {
      "x": -11,
      "y": 19,
      "z": -3,
      "name": "Plant_Leaves_Oak"
    },
    {
      "x": -11,
      "y": 20,
      "z": -3,
      "name": "Nat20_Force_Empty"
    },
    {
      "x": -11,
      "y": 21,
      "z": -3,
      "name": "Nat20_Force_Empty"
    },
    {
      "x": -11,
      "y": 22,
      "z": -3,
      "name": "Nat20_Force_Empty"
    },
    {
      "x": -11,
      "y": 23,
      "z": -3,
      "name": "Nat20_Force_Empty"
    },
    {
      "x": -11,
      "y": 24,
      "z": -3,
      "name": "Nat20_Force_Empty"
    },
    {
      "x": -11,
      "y": 25,
      "z": -3,
      "name": "Nat20_Force_Empty"
    },
    {
      "x": -11,
      "y": 26,
      "z": -3,
      "name": "Nat20_Force_Empty"
    },
    {
      "x": -11,
      "y": 27,
      "z": -3,
      "name": "Nat20_Force_Empty"
    },
    {
      "x": -11,
      "y": 13,
      "z": -2,
      "name": "Nat20_Force_Empty"
    },
    {
      "x": -11,
      "y": 14,
      "z": -2,
      "name": "Nat20_Force_Empty"
    },
    {
      "x": -11,
      "y": 15,
      "z": -2,
      "name": "Nat20_Force_Empty"
    },
    {
      "x": -11,
      "y": 16,
      "z": -2,
      "name": "Nat20_Force_Empty"
    },
    {
      "x": -11,
      "y": 17,
      "z": -2,
      "name": "Nat20_Force_Empty"
    },
    {
      "x": -11,
      "y": 18,
      "z": -2,
      "name": "Nat20_Force_Empty"
    },
    {
      "x": -11,
      "y": 19,
      "z": -2,
      "name": "Nat20_Force_Empty"
    },
    {
      "x": -11,
      "y": 20,
      "z": -2,
      "name": "Plant_Leaves_Oak"
    },
    {
      "x": -11,
      "y": 21,
      "z": -2,
      "name": "Nat20_Force_Empty"
    },
    {
      "x": -11,
      "y": 22,
      "z": -2,
      "name": "Nat20_Force_Empty"
    },
    {
      "x": -11,
      "y": 23,
      "z": -2,
      "name": "Nat20_Force_Empty"
    },
    {
      "x": -11,
      "y": 24,
      "z": -2,
      "name": "Nat20_Force_Empty"
    },
    {
      "x": -11,
      "y": 25,
      "z": -2,
      "name": "Nat20_Force_Empty"
    },
    {
      "x": -11,
      "y": 26,
      "z": -2,
      "name": "Nat20_Force_Empty"
    },
    {
      "x": -11,
      "y": 27,
      "z": -2,
      "name": "Nat20_Force_Empty"
    },
    {
      "x": -11,
      "y": 13,
      "z": -1,
      "name": "Nat20_Force_Empty"
    },
    {
      "x": -11,
      "y": 14,
      "z": -1,
      "name": "Nat20_Force_Empty"
    },
    {
      "x": -11,
      "y": 15,
      "z": -1,
      "name": "Nat20_Force_Empty"
    },
    {
      "x": -11,
      "y": 16,
      "z": -1,
      "name": "Nat20_Force_Empty"
    },
    {
      "x": -11,
      "y": 17,
      "z": -1,
      "name": "Nat20_Force_Empty"
    },
    {
      "x": -11,
      "y": 18,
      "z": -1,
      "name": "Nat20_Force_Empty"
    },
    {
      "x": -11,
      "y": 19,
      "z": -1,
      "name": "Nat20_Force_Empty"
    },
    {
      "x": -11,
      "y": 20,
      "z": -1,
      "name": "Plant_Leaves_Oak"
    },
    {
      "x": -11,
      "y": 21,
      "z": -1,
      "name": "Nat20_Force_Empty"
    },
    {
      "x": -11,
      "y": 22,
      "z": -1,
      "name": "Nat20_Force_Empty"
    },
    {
      "x": -11,
      "y": 23,
      "z": -1,
      "name": "Nat20_Force_Empty"
    },
    {
      "x": -11,
      "y": 24,
      "z": -1,
      "name": "Nat20_Force_Empty"
    },
    {
      "x": -11,
      "y": 25,
      "z": -1,
      "name": "Nat20_Force_Empty"
    },
    {
      "x": -11,
      "y": 26,
      "z": -1,
      "name": "Nat20_Force_Empty"
    },
    {
      "x": -11,
      "y": 27,
      "z": -1,
      "name": "Nat20_Force_Empty"
    },
    {
      "x": -11,
      "y": 13,
      "z": 0,
      "name": "Nat20_Force_Empty"
    },
    {
      "x": -11,
      "y": 14,
      "z": 0,
      "name": "Nat20_Force_Empty"
    },
    {
      "x": -11,
      "y": 15,
      "z": 0,
      "name": "Nat20_Force_Empty"
    },
    {
      "x": -11,
      "y": 16,
      "z": 0,
      "name": "Nat20_Force_Empty"
    },
    {
      "x": -11,
      "y": 17,
      "z": 0,
      "name": "Nat20_Force_Empty"
    },
    {
      "x": -11,
      "y": 18,
      "z": 0,
      "name": "Nat20_Force_Empty"
    },
    {
      "x": -11,
      "y": 19,
      "z": 0,
      "name": "Plant_Leaves_Oak"
    },
    {
      "x": -11,
      "y": 20,
      "z": 0,
      "name": "Plant_Leaves_Oak"
    },
    {
      "x": -11,
      "y": 21,
      "z": 0,
      "name": "Plant_Leaves_Oak"
    },
    {
      "x": -11,
      "y": 22,
      "z": 0,
      "name": "Nat20_Force_Empty"
    },
    {
      "x": -11,
      "y": 23,
      "z": 0,
      "name": "Nat20_Force_Empty"
    },
    {
      "x": -11,
      "y": 24,
      "z": 0,
      "name": "Nat20_Force_Empty"
    },
    {
      "x": -11,
      "y": 25,
      "z": 0,
      "name": "Nat20_Force_Empty"
    },
    {
      "x": -11,
      "y": 26,
      "z": 0,
      "name": "Nat20_Force_Empty"
    },
    {
      "x": -11,
      "y": 27,
      "z": 0,
      "name": "Nat20_Force_Empty"
    },
    {
      "x": -11,
      "y": 13,
      "z": 1,
      "name": "Nat20_Force_Empty"
    },
    {
      "x": -11,
      "y": 14,
      "z": 1,
      "name": "Nat20_Force_Empty"
    },
    {
      "x": -11,
      "y": 15,
      "z": 1,
      "name": "Nat20_Force_Empty"
    },
    {
      "x": -11,
      "y": 16,
      "z": 1,
      "name": "Nat20_Force_Empty"
    },
    {
      "x": -11,
      "y": 17,
      "z": 1,
      "name": "Nat20_Force_Empty"
    },
    {
      "x": -11,
      "y": 18,
      "z": 1,
      "name": "Nat20_Force_Empty"
    },
    {
      "x": -11,
      "y": 19,
      "z": 1,
      "name": "Nat20_Force_Empty"
    },
    {
      "x": -11,
      "y": 20,
      "z": 1,
      "name": "Plant_Leaves_Oak"
    },
    {
      "x": -11,
      "y": 21,
      "z": 1,
      "name": "Plant_Leaves_Oak"
    },
    {
      "x": -11,
      "y": 22,
      "z": 1,
      "name": "Nat20_Force_Empty"
    },
    {
      "x": -11,
      "y": 23,
      "z": 1,
      "name": "Nat20_Force_Empty"
    },
    {
      "x": -11,
      "y": 24,
      "z": 1,
      "name": "Plant_Leaves_Oak"
    },
    {
      "x": -11,
      "y": 25,
      "z": 1,
      "name": "Nat20_Force_Empty"
    },
    {
      "x": -11,
      "y": 26,
      "z": 1,
      "name": "Nat20_Force_Empty"
    },
    {
      "x": -11,
      "y": 27,
      "z": 1,
      "name": "Nat20_Force_Empty"
    },
    {
      "x": -11,
      "y": 13,
      "z": 2,
      "name": "Nat20_Force_Empty"
    },
    {
      "x": -11,
      "y": 14,
      "z": 2,
      "name": "Nat20_Force_Empty"
    },
    {
      "x": -11,
      "y": 15,
      "z": 2,
      "name": "Nat20_Force_Empty"
    },
    {
      "x": -11,
      "y": 16,
      "z": 2,
      "name": "Nat20_Force_Empty"
    },
    {
      "x": -11,
      "y": 17,
      "z": 2,
      "name": "Nat20_Force_Empty"
    },
    {
      "x": -11,
      "y": 18,
      "z": 2,
      "name": "Nat20_Force_Empty"
    },
    {
      "x": -11,
      "y": 19,
      "z": 2,
      "name": "Nat20_Force_Empty"
    },
    {
      "x": -11,
      "y": 20,
      "z": 2,
      "name": "Plant_Leaves_Oak"
    },
    {
      "x": -11,
      "y": 21,
      "z": 2,
      "name": "Nat20_Force_Empty"
    },
    {
      "x": -11,
      "y": 22,
      "z": 2,
      "name": "Nat20_Force_Empty"
    },
    {
      "x": -11,
      "y": 23,
      "z": 2,
      "name": "Nat20_Force_Empty"
    },
    {
      "x": -11,
      "y": 24,
      "z": 2,
      "name": "Plant_Leaves_Oak"
    },
    {
      "x": -11,
      "y": 25,
      "z": 2,
      "name": "Nat20_Force_Empty"
    },
    {
      "x": -11,
      "y": 26,
      "z": 2,
      "name": "Nat20_Force_Empty"
    },
    {
      "x": -11,
      "y": 27,
      "z": 2,
      "name": "Nat20_Force_Empty"
    },
    {
      "x": -11,
      "y": 13,
      "z": 3,
      "name": "Nat20_Force_Empty"
    },
    {
      "x": -11,
      "y": 14,
      "z": 3,
      "name": "Nat20_Force_Empty"
    },
    {
      "x": -11,
      "y": 15,
      "z": 3,
      "name": "Nat20_Force_Empty"
    },
    {
      "x": -11,
      "y": 16,
      "z": 3,
      "name": "Nat20_Force_Empty"
    },
    {
      "x": -11,
      "y": 17,
      "z": 3,
      "name": "Nat20_Force_Empty"
    },
    {
      "x": -11,
      "y": 18,
      "z": 3,
      "name": "Nat20_Force_Empty"
    },
    {
      "x": -11,
      "y": 19,
      "z": 3,
      "name": "Nat20_Force_Empty"
    },
    {
      "x": -11,
      "y": 20,
      "z": 3,
      "name": "Plant_Leaves_Oak"
    },
    {
      "x": -11,
      "y": 21,
      "z": 3,
      "name": "Nat20_Force_Empty"
    },
    {
      "x": -11,
      "y": 22,
      "z": 3,
      "name": "Nat20_Force_Empty"
    },
    {
      "x": -11,
      "y": 23,
      "z": 3,
      "name": "Nat20_Force_Empty"
    },
    {
      "x": -11,
      "y": 24,
      "z": 3,
      "name": "Plant_Leaves_Oak"
    },
    {
      "x": -11,
      "y": 25,
      "z": 3,
      "name": "Nat20_Force_Empty"
    },
    {
      "x": -11,
      "y": 26,
      "z": 3,
      "name": "Nat20_Force_Empty"
    },
    {
      "x": -11,
      "y": 27,
      "z": 3,
      "name": "Nat20_Force_Empty"
    },
    {
      "x": -11,
      "y": 13,
      "z": 4,
      "name": "Nat20_Force_Empty"
    },
    {
      "x": -11,
      "y": 14,
      "z": 4,
      "name": "Nat20_Force_Empty"
    },
    {
      "x": -11,
      "y": 15,
      "z": 4,
      "name": "Nat20_Force_Empty"
    },
    {
      "x": -11,
      "y": 16,
      "z": 4,
      "name": "Nat20_Force_Empty"
    },
    {
      "x": -11,
      "y": 17,
      "z": 4,
      "name": "Nat20_Force_Empty"
    },
    {
      "x": -11,
      "y": 18,
      "z": 4,
      "name": "Nat20_Force_Empty"
    },
    {
      "x": -11,
      "y": 19,
      "z": 4,
      "name": "Nat20_Force_Empty"
    },
    {
      "x": -11,
      "y": 20,
      "z": 4,
      "name": "Nat20_Force_Empty"
    },
    {
      "x": -11,
      "y": 21,
      "z": 4,
      "name": "Nat20_Force_Empty"
    },
    {
      "x": -11,
      "y": 22,
      "z": 4,
      "name": "Nat20_Force_Empty"
    },
    {
      "x": -11,
      "y": 23,
      "z": 4,
      "name": "Nat20_Force_Empty"
    },
    {
      "x": -11,
      "y": 24,
      "z": 4,
      "name": "Nat20_Force_Empty"
    },
    {
      "x": -11,
      "y": 25,
      "z": 4,
      "name": "Nat20_Force_Empty"
    },
    {
      "x": -11,
      "y": 26,
      "z": 4,
      "name": "Nat20_Force_Empty"
    },
    {
      "x": -11,
      "y": 27,
      "z": 4,
      "name": "Nat20_Force_Empty"
    },
    {
      "x": -11,
      "y": 13,
      "z": 5,
      "name": "Nat20_Force_Empty"
    },
    {
      "x": -11,
      "y": 14,
      "z": 5,
      "name": "Nat20_Force_Empty"
    },
    {
      "x": -11,
      "y": 15,
      "z": 5,
      "name": "Nat20_Force_Empty"
    },
    {
      "x": -11,
      "y": 16,
      "z": 5,
      "name": "Nat20_Force_Empty"
    },
    {
      "x": -11,
      "y": 17,
      "z": 5,
      "name": "Nat20_Force_Empty"
    },
    {
      "x": -11,
      "y": 18,
      "z": 5,
      "name": "Nat20_Force_Empty"
    },
    {
      "x": -11,
      "y": 19,
      "z": 5,
      "name": "Nat20_Force_Empty"
    },
    {
      "x": -11,
      "y": 20,
      "z": 5,
      "name": "Nat20_Force_Empty"
    },
    {
      "x": -11,
      "y": 21,
      "z": 5,
      "name": "Nat20_Force_Empty"
    },
    {
      "x": -11,
      "y": 22,
      "z": 5,
      "name": "Nat20_Force_Empty"
    },
    {
      "x": -11,
      "y": 23,
      "z": 5,
      "name": "Nat20_Force_Empty"
    },
    {
      "x": -11,
      "y": 24,
      "z": 5,
      "name": "Nat20_Force_Empty"
    },
    {
      "x": -11,
      "y": 25,
      "z": 5,
      "name": "Nat20_Force_Empty"
    },
    {
      "x": -11,
      "y": 26,
      "z": 5,
      "name": "Nat20_Force_Empty"
    },
    {
      "x": -11,
      "y": 27,
      "z": 5,
      "name": "Nat20_Force_Empty"
    },
    {
      "x": -11,
      "y": 13,
      "z": 6,
      "name": "Nat20_Force_Empty"
    },
    {
      "x": -11,
      "y": 14,
      "z": 6,
      "name": "Nat20_Force_Empty"
    },
    {
      "x": -11,
      "y": 15,
      "z": 6,
      "name": "Nat20_Force_Empty"
    },
    {
      "x": -11,
      "y": 16,
      "z": 6,
      "name": "Nat20_Force_Empty"
    },
    {
      "x": -11,
      "y": 17,
      "z": 6,
      "name": "Nat20_Force_Empty"
    },
    {
      "x": -11,
      "y": 18,
      "z": 6,
      "name": "Nat20_Force_Empty"
    },
    {
      "x": -11,
      "y": 19,
      "z": 6,
      "name": "Nat20_Force_Empty"
    },
    {
      "x": -11,
      "y": 20,
      "z": 6,
      "name": "Nat20_Force_Empty"
    },
    {
      "x": -11,
      "y": 21,
      "z": 6,
      "name": "Nat20_Force_Empty"
    },
    {
      "x": -11,
      "y": 22,
      "z": 6,
      "name": "Nat20_Force_Empty"
    },
    {
      "x": -11,
      "y": 23,
      "z": 6,
      "name": "Nat20_Force_Empty"
    },
    {
      "x": -11,
      "y": 24,
      "z": 6,
      "name": "Nat20_Force_Empty"
    },
    {
      "x": -11,
      "y": 25,
      "z": 6,
      "name": "Nat20_Force_Empty"
    },
    {
      "x": -11,
      "y": 26,
      "z": 6,
      "name": "Nat20_Force_Empty"
    },
    {
      "x": -11,
      "y": 27,
      "z": 6,
      "name": "Nat20_Force_Empty"
    },
    {
      "x": -11,
      "y": 13,
      "z": 7,
      "name": "Nat20_Force_Empty"
    },
    {
      "x": -11,
      "y": 14,
      "z": 7,
      "name": "Nat20_Force_Empty"
    },
    {
      "x": -11,
      "y": 15,
      "z": 7,
      "name": "Nat20_Force_Empty"
    },
    {
      "x": -11,
      "y": 16,
      "z": 7,
      "name": "Nat20_Force_Empty"
    },
    {
      "x": -11,
      "y": 17,
      "z": 7,
      "name": "Nat20_Force_Empty"
    },
    {
      "x": -11,
      "y": 18,
      "z": 7,
      "name": "Nat20_Force_Empty"
    },
    {
      "x": -11,
      "y": 19,
      "z": 7,
      "name": "Nat20_Force_Empty"
    },
    {
      "x": -11,
      "y": 20,
      "z": 7,
      "name": "Nat20_Force_Empty"
    },
    {
      "x": -11,
      "y": 21,
      "z": 7,
      "name": "Nat20_Force_Empty"
    },
    {
      "x": -11,
      "y": 22,
      "z": 7,
      "name": "Nat20_Force_Empty"
    },
    {
      "x": -11,
      "y": 23,
      "z": 7,
      "name": "Nat20_Force_Empty"
    },
    {
      "x": -11,
      "y": 24,
      "z": 7,
      "name": "Nat20_Force_Empty"
    },
    {
      "x": -11,
      "y": 25,
      "z": 7,
      "name": "Nat20_Force_Empty"
    },
    {
      "x": -11,
      "y": 26,
      "z": 7,
      "name": "Nat20_Force_Empty"
    },
    {
      "x": -11,
      "y": 27,
      "z": 7,
      "name": "Nat20_Force_Empty"
    },
    {
      "x": -11,
      "y": 13,
      "z": 8,
      "name": "Nat20_Force_Empty"
    },
    {
      "x": -11,
      "y": 14,
      "z": 8,
      "name": "Nat20_Force_Empty"
    },
    {
      "x": -11,
      "y": 15,
      "z": 8,
      "name": "Nat20_Force_Empty"
    },
    {
      "x": -11,
      "y": 16,
      "z": 8,
      "name": "Nat20_Force_Empty"
    },
    {
      "x": -11,
      "y": 17,
      "z": 8,
      "name": "Nat20_Force_Empty"
    },
    {
      "x": -11,
      "y": 18,
      "z": 8,
      "name": "Nat20_Force_Empty"
    },
    {
      "x": -11,
      "y": 19,
      "z": 8,
      "name": "Nat20_Force_Empty"
    },
    {
      "x": -11,
      "y": 20,
      "z": 8,
      "name": "Nat20_Force_Empty"
    },
    {
      "x": -11,
      "y": 21,
      "z": 8,
      "name": "Nat20_Force_Empty"
    },
    {
      "x": -11,
      "y": 22,
      "z": 8,
      "name": "Nat20_Force_Empty"
    },
    {
      "x": -11,
      "y": 23,
      "z": 8,
      "name": "Nat20_Force_Empty"
    },
    {
      "x": -11,
      "y": 24,
      "z": 8,
      "name": "Nat20_Force_Empty"
    },
    {
      "x": -11,
      "y": 25,
      "z": 8,
      "name": "Nat20_Force_Empty"
    },
    {
      "x": -11,
      "y": 26,
      "z": 8,
      "name": "Nat20_Force_Empty"
    },
    {
      "x": -11,
      "y": 27,
      "z": 8,
      "name": "Nat20_Force_Empty"
    },
    {
      "x": -11,
      "y": 13,
      "z": 9,
      "name": "Nat20_Force_Empty"
    },
    {
      "x": -11,
      "y": 14,
      "z": 9,
      "name": "Nat20_Force_Empty"
    },
    {
      "x": -11,
      "y": 15,
      "z": 9,
      "name": "Nat20_Force_Empty"
    },
    {
      "x": -11,
      "y": 16,
      "z": 9,
      "name": "Nat20_Force_Empty"
    },
    {
      "x": -11,
      "y": 17,
      "z": 9,
      "name": "Nat20_Force_Empty"
    },
    {
      "x": -11,
      "y": 18,
      "z": 9,
      "name": "Nat20_Force_Empty"
    },
    {
      "x": -11,
      "y": 19,
      "z": 9,
      "name": "Nat20_Force_Empty"
    },
    {
      "x": -11,
      "y": 20,
      "z": 9,
      "name": "Nat20_Force_Empty"
    },
    {
      "x": -11,
      "y": 21,
      "z": 9,
      "name": "Nat20_Force_Empty"
    },
    {
      "x": -11,
      "y": 22,
      "z": 9,
      "name": "Nat20_Force_Empty"
    },
    {
      "x": -11,
      "y": 23,
      "z": 9,
      "name": "Nat20_Force_Empty"
    },
    {
      "x": -11,
      "y": 24,
      "z": 9,
      "name": "Nat20_Force_Empty"
    },
    {
      "x": -11,
      "y": 25,
      "z": 9,
