{
  "version": 8,
  "blockIdVersion": 11,
  "anchorX": 0,
  "anchorY": 0,
  "anchorZ": 0,
  "blocks": [
    {
      "x": -14,
      "y": 0,
      "z": -9,
      "name": "Nat20_Force_Empty"
    },
    {
      "x": -14,
      "y": 1,
      "z": -9,
      "name": "Nat20_Force_Empty"
    },
    {
      "x": -14,
      "y": 2,
      "z": -9,
      "name": "Nat20_Force_Empty"
    },
    {
      "x": -14,
      "y": 3,
      "z": -9,
      "name": "Nat20_Force_Empty"
    },
    {
      "x": -14,
      "y": 4,
      "z": -9,
      "name": "Nat20_Force_Empty"
    },
    {
      "x": -14,
      "y": 5,
      "z": -9,
      "name": "Nat20_Force_Empty"
    },
    {
      "x": -14,
      "y": 6,
      "z": -9,
      "name": "Nat20_Force_Empty"
    },
    {
      "x": -14,
      "y": 7,
      "z": -9,
      "name": "Nat20_Force_Empty"
    },
    {
      "x": -14,
      "y": 8,
      "z": -9,
      "name": "Nat20_Force_Empty"
    },
    {
      "x": -14,
      "y": 9,
      "z": -9,
      "name": "Nat20_Force_Empty"
    },
    {
      "x": -14,
      "y": 10,
      "z": -9,
      "name": "Nat20_Force_Empty"
    },
    {
      "x": -14,
      "y": 11,
      "z": -9,
      "name": "Nat20_Force_Empty"
    },
    {
      "x": -14,
      "y": 12,
      "z": -9,
      "name": "Nat20_Force_Empty"
    },
    {
      "x": -14,
      "y": 13,
      "z": -9,
      "name": "Nat20_Force_Empty"
    },
    {
      "x": -14,
      "y": 14,
      "z": -9,
      "name": "Nat20_Force_Empty"
    },
    {
      "x": -14,
      "y": 15,
      "z": -9,
      "name": "Nat20_Force_Empty"
    },
    {
      "x": -14,
      "y": 16,
      "z": -9,
      "name": "Nat20_Force_Empty"
    },
    {
      "x": -14,
      "y": 17,
      "z": -9,
      "name": "Nat20_Force_Empty"
    },
    {
      "x": -14,
      "y": 18,
      "z": -9,
      "name": "Nat20_Force_Empty"
    },
    {
      "x": -14,
      "y": 19,
      "z": -9,
      "name": "Nat20_Force_Empty"
    },
    {
      "x": -14,
      "y": 20,
      "z": -9,
      "name": "Nat20_Force_Empty"
    },
    {
      "x": -14,
      "y": 21,
      "z": -9,
      "name": "Nat20_Force_Empty"
    },
    {
      "x": -14,
      "y": 22,
      "z": -9,
      "name": "Nat20_Force_Empty"
    },
    {
      "x": -14,
      "y": 23,
      "z": -9,
      "name": "Nat20_Force_Empty"
    },
    {
      "x": -14,
      "y": 0,
      "z": -8,
      "name": "Nat20_Force_Empty"
    },
    {
      "x": -14,
      "y": 1,
      "z": -8,
      "name": "Nat20_Force_Empty"
    },
    {
      "x": -14,
      "y": 2,
      "z": -8,
      "name": "Nat20_Force_Empty"
    },
    {
      "x": -14,
      "y": 3,
      "z": -8,
      "name": "Nat20_Force_Empty"
    },
    {
      "x": -14,
      "y": 4,
      "z": -8,
      "name": "Nat20_Force_Empty"
    },
    {
      "x": -14,
      "y": 5,
      "z": -8,
      "name": "Nat20_Force_Empty"
    },
    {
      "x": -14,
      "y": 6,
      "z": -8,
      "name": "Nat20_Force_Empty"
    },
    {
      "x": -14,
      "y": 7,
      "z": -8,
      "name": "Nat20_Force_Empty"
    },
    {
      "x": -14,
      "y": 8,
      "z": -8,
      "name": "Nat20_Force_Empty"
    },
    {
      "x": -14,
      "y": 9,
      "z": -8,
      "name": "Nat20_Force_Empty"
    },
    {
      "x": -14,
      "y": 10,
      "z": -8,
      "name": "Nat20_Force_Empty"
    },
    {
      "x": -14,
      "y": 11,
      "z": -8,
      "name": "Nat20_Force_Empty"
    },
    {
      "x": -14,
      "y": 12,
      "z": -8,
      "name": "Nat20_Force_Empty"
    },
    {
      "x": -14,
      "y": 13,
      "z": -8,
      "name": "Nat20_Force_Empty"
    },
    {
      "x": -14,
      "y": 14,
      "z": -8,
      "name": "Nat20_Force_Empty"
    },
    {
      "x": -14,
      "y": 15,
      "z": -8,
      "name": "Nat20_Force_Empty"
    },
    {
      "x": -14,
      "y": 16,
      "z": -8,
      "name": "Nat20_Force_Empty"
    },
    {
      "x": -14,
      "y": 17,
      "z": -8,
      "name": "Nat20_Force_Empty"
    },
    {
      "x": -14,
      "y": 18,
      "z": -8,
      "name": "Nat20_Force_Empty"
    },
    {
      "x": -14,
      "y": 19,
      "z": -8,
      "name": "Nat20_Force_Empty"
    },
    {
      "x": -14,
      "y": 20,
      "z": -8,
      "name": "Nat20_Force_Empty"
    },
    {
      "x": -14,
      "y": 21,
      "z": -8,
      "name": "Nat20_Force_Empty"
    },
    {
      "x": -14,
      "y": 22,
      "z": -8,
      "name": "Nat20_Force_Empty"
    },
    {
      "x": -14,
      "y": 23,
      "z": -8,
      "name": "Nat20_Force_Empty"
    },
    {
      "x": -14,
      "y": 0,
      "z": -7,
      "name": "Nat20_Force_Empty"
    },
    {
      "x": -14,
      "y": 1,
      "z": -7,
      "name": "Nat20_Force_Empty"
    },
    {
      "x": -14,
      "y": 2,
      "z": -7,
      "name": "Nat20_Force_Empty"
    },
    {
      "x": -14,
      "y": 3,
      "z": -7,
      "name": "Nat20_Force_Empty"
    },
    {
      "x": -14,
      "y": 4,
      "z": -7,
      "name": "Nat20_Force_Empty"
    },
    {
      "x": -14,
      "y": 5,
      "z": -7,
      "name": "Nat20_Force_Empty"
    },
    {
      "x": -14,
      "y": 6,
      "z": -7,
      "name": "Nat20_Force_Empty"
    },
    {
      "x": -14,
      "y": 7,
      "z": -7,
      "name": "Nat20_Force_Empty"
    },
    {
      "x": -14,
      "y": 8,
      "z": -7,
      "name": "Nat20_Force_Empty"
    },
    {
      "x": -14,
      "y": 9,
      "z": -7,
      "name": "Nat20_Force_Empty"
    },
    {
      "x": -14,
      "y": 10,
      "z": -7,
      "name": "Nat20_Force_Empty"
    },
    {
      "x": -14,
      "y": 11,
      "z": -7,
      "name": "Nat20_Force_Empty"
    },
    {
      "x": -14,
      "y": 12,
      "z": -7,
      "name": "Nat20_Force_Empty"
    },
    {
      "x": -14,
      "y": 13,
      "z": -7,
      "name": "Nat20_Force_Empty"
    },
    {
      "x": -14,
      "y": 14,
      "z": -7,
      "name": "Nat20_Force_Empty"
    },
    {
      "x": -14,
      "y": 15,
      "z": -7,
      "name": "Nat20_Force_Empty"
    },
    {
      "x": -14,
      "y": 16,
      "z": -7,
      "name": "Nat20_Force_Empty"
    },
    {
      "x": -14,
      "y": 17,
      "z": -7,
      "name": "Nat20_Force_Empty"
    },
    {
      "x": -14,
      "y": 18,
      "z": -7,
      "name": "Nat20_Force_Empty"
    },
    {
      "x": -14,
      "y": 19,
      "z": -7,
      "name": "Nat20_Force_Empty"
    },
    {
      "x": -14,
      "y": 20,
      "z": -7,
      "name": "Nat20_Force_Empty"
    },
    {
      "x": -14,
      "y": 21,
      "z": -7,
      "name": "Nat20_Force_Empty"
    },
    {
      "x": -14,
      "y": 22,
      "z": -7,
      "name": "Nat20_Force_Empty"
    },
    {
      "x": -14,
      "y": 23,
      "z": -7,
      "name": "Nat20_Force_Empty"
    },
    {
      "x": -14,
      "y": 0,
      "z": -6,
      "name": "Nat20_Force_Empty"
    },
    {
      "x": -14,
      "y": 1,
      "z": -6,
      "name": "Nat20_Force_Empty"
    },
    {
      "x": -14,
      "y": 2,
      "z": -6,
      "name": "Nat20_Force_Empty"
    },
    {
      "x": -14,
      "y": 3,
      "z": -6,
      "name": "Nat20_Force_Empty"
    },
    {
      "x": -14,
      "y": 4,
      "z": -6,
      "name": "Nat20_Force_Empty"
    },
    {
      "x": -14,
      "y": 5,
      "z": -6,
      "name": "Nat20_Force_Empty"
    },
    {
      "x": -14,
      "y": 6,
      "z": -6,
      "name": "Nat20_Force_Empty"
    },
    {
      "x": -14,
      "y": 7,
      "z": -6,
      "name": "Nat20_Force_Empty"
    },
    {
      "x": -14,
      "y": 8,
      "z": -6,
      "name": "Nat20_Force_Empty"
    },
    {
      "x": -14,
      "y": 9,
      "z": -6,
      "name": "Nat20_Force_Empty"
    },
    {
      "x": -14,
      "y": 10,
      "z": -6,
      "name": "Nat20_Force_Empty"
    },
    {
      "x": -14,
      "y": 11,
      "z": -6,
      "name": "Nat20_Force_Empty"
    },
    {
      "x": -14,
      "y": 12,
      "z": -6,
      "name": "Nat20_Force_Empty"
    },
    {
      "x": -14,
      "y": 13,
      "z": -6,
      "name": "Nat20_Force_Empty"
    },
    {
      "x": -14,
      "y": 14,
      "z": -6,
      "name": "Nat20_Force_Empty"
    },
    {
      "x": -14,
      "y": 15,
      "z": -6,
      "name": "Nat20_Force_Empty"
    },
    {
      "x": -14,
      "y": 16,
      "z": -6,
      "name": "Nat20_Force_Empty"
    },
    {
      "x": -14,
      "y": 17,
      "z": -6,
      "name": "Nat20_Force_Empty"
    },
    {
      "x": -14,
      "y": 18,
      "z": -6,
      "name": "Nat20_Force_Empty"
    },
    {
      "x": -14,
      "y": 19,
      "z": -6,
      "name": "Nat20_Force_Empty"
    },
    {
      "x": -14,
      "y": 20,
      "z": -6,
      "name": "Nat20_Force_Empty"
    },
    {
      "x": -14,
      "y": 21,
      "z": -6,
      "name": "Nat20_Force_Empty"
    },
    {
      "x": -14,
      "y": 22,
      "z": -6,
      "name": "Nat20_Force_Empty"
    },
    {
      "x": -14,
      "y": 23,
      "z": -6,
      "name": "Nat20_Force_Empty"
    },
    {
      "x": -14,
      "y": 0,
      "z": -5,
      "name": "Nat20_Force_Empty"
    },
    {
      "x": -14,
      "y": 1,
      "z": -5,
      "name": "Nat20_Force_Empty"
    },
    {
      "x": -14,
      "y": 2,
      "z": -5,
      "name": "Nat20_Force_Empty"
    },
    {
      "x": -14,
      "y": 3,
      "z": -5,
      "name": "Nat20_Force_Empty"
    },
    {
      "x": -14,
      "y": 4,
      "z": -5,
      "name": "Nat20_Force_Empty"
    },
    {
      "x": -14,
      "y": 5,
      "z": -5,
      "name": "Nat20_Force_Empty"
    },
    {
      "x": -14,
      "y": 6,
      "z": -5,
      "name": "Nat20_Force_Empty"
    },
    {
      "x": -14,
      "y": 7,
      "z": -5,
      "name": "Nat20_Force_Empty"
    },
    {
      "x": -14,
      "y": 8,
      "z": -5,
      "name": "Nat20_Force_Empty"
    },
    {
      "x": -14,
      "y": 9,
      "z": -5,
      "name": "Nat20_Force_Empty"
    },
    {
      "x": -14,
      "y": 10,
      "z": -5,
      "name": "Nat20_Force_Empty"
    },
    {
      "x": -14,
      "y": 11,
      "z": -5,
      "name": "Nat20_Force_Empty"
    },
    {
      "x": -14,
      "y": 12,
      "z": -5,
      "name": "Nat20_Force_Empty"
    },
    {
      "x": -14,
      "y": 13,
      "z": -5,
      "name": "Nat20_Force_Empty"
    },
    {
      "x": -14,
      "y": 14,
      "z": -5,
      "name": "Nat20_Force_Empty"
    },
    {
      "x": -14,
      "y": 15,
      "z": -5,
      "name": "Nat20_Force_Empty"
    },
    {
      "x": -14,
      "y": 16,
      "z": -5,
      "name": "Nat20_Force_Empty"
    },
    {
      "x": -14,
      "y": 17,
      "z": -5,
      "name": "Nat20_Force_Empty"
    },
    {
      "x": -14,
      "y": 18,
      "z": -5,
      "name": "Nat20_Force_Empty"
    },
    {
      "x": -14,
      "y": 19,
      "z": -5,
      "name": "Nat20_Force_Empty"
    },
    {
      "x": -14,
      "y": 20,
      "z": -5,
      "name": "Nat20_Force_Empty"
    },
    {
      "x": -14,
      "y": 21,
      "z": -5,
      "name": "Nat20_Force_Empty"
    },
    {
      "x": -14,
      "y": 22,
      "z": -5,
      "name": "Nat20_Force_Empty"
    },
    {
      "x": -14,
      "y": 23,
      "z": -5,
      "name": "Nat20_Force_Empty"
    },
    {
      "x": -14,
      "y": 0,
      "z": -4,
      "name": "Nat20_Force_Empty"
    },
    {
      "x": -14,
      "y": 1,
      "z": -4,
      "name": "Nat20_Force_Empty"
    },
    {
      "x": -14,
      "y": 2,
      "z": -4,
      "name": "Nat20_Force_Empty"
    },
    {
      "x": -14,
      "y": 3,
      "z": -4,
      "name": "Nat20_Force_Empty"
    },
    {
      "x": -14,
      "y": 4,
      "z": -4,
      "name": "Nat20_Force_Empty"
    },
    {
      "x": -14,
      "y": 5,
      "z": -4,
      "name": "Nat20_Force_Empty"
    },
    {
      "x": -14,
      "y": 6,
      "z": -4,
      "name": "Nat20_Force_Empty"
    },
    {
      "x": -14,
      "y": 7,
      "z": -4,
      "name": "Nat20_Force_Empty"
    },
    {
      "x": -14,
      "y": 8,
      "z": -4,
      "name": "Nat20_Force_Empty"
    },
    {
      "x": -14,
      "y": 9,
      "z": -4,
      "name": "Nat20_Force_Empty"
    },
    {
      "x": -14,
      "y": 10,
      "z": -4,
      "name": "Nat20_Force_Empty"
    },
    {
      "x": -14,
      "y": 11,
      "z": -4,
      "name": "Nat20_Force_Empty"
    },
    {
      "x": -14,
      "y": 12,
      "z": -4,
      "name": "Nat20_Force_Empty"
    },
    {
      "x": -14,
      "y": 13,
      "z": -4,
      "name": "Nat20_Force_Empty"
    },
    {
      "x": -14,
      "y": 14,
      "z": -4,
      "name": "Nat20_Force_Empty"
    },
    {
      "x": -14,
      "y": 15,
      "z": -4,
      "name": "Nat20_Force_Empty"
    },
    {
      "x": -14,
      "y": 16,
      "z": -4,
      "name": "Nat20_Force_Empty"
    },
    {
      "x": -14,
      "y": 17,
      "z": -4,
      "name": "Nat20_Force_Empty"
    },
    {
      "x": -14,
      "y": 18,
      "z": -4,
      "name": "Nat20_Force_Empty"
    },
    {
      "x": -14,
      "y": 19,
      "z": -4,
      "name": "Nat20_Force_Empty"
    },
    {
      "x": -14,
      "y": 20,
      "z": -4,
      "name": "Nat20_Force_Empty"
    },
    {
      "x": -14,
      "y": 21,
      "z": -4,
      "name": "Nat20_Force_Empty"
    },
    {
      "x": -14,
      "y": 22,
      "z": -4,
      "name": "Nat20_Force_Empty"
    },
    {
      "x": -14,
      "y": 23,
      "z": -4,
      "name": "Nat20_Force_Empty"
    },
    {
      "x": -14,
      "y": 0,
      "z": -3,
      "name": "Nat20_Force_Empty"
    },
    {
      "x": -14,
      "y": 1,
      "z": -3,
      "name": "Nat20_Force_Empty"
    },
    {
      "x": -14,
      "y": 2,
      "z": -3,
      "name": "Nat20_Force_Empty"
    },
    {
      "x": -14,
      "y": 3,
      "z": -3,
      "name": "Nat20_Force_Empty"
    },
    {
      "x": -14,
      "y": 4,
      "z": -3,
      "name": "Nat20_Force_Empty"
    },
    {
      "x": -14,
      "y": 5,
      "z": -3,
      "name": "Nat20_Force_Empty"
    },
    {
      "x": -14,
      "y": 6,
      "z": -3,
      "name": "Nat20_Force_Empty"
    },
    {
      "x": -14,
      "y": 7,
      "z": -3,
      "name": "Nat20_Force_Empty"
    },
    {
      "x": -14,
      "y": 8,
      "z": -3,
      "name": "Nat20_Force_Empty"
    },
    {
      "x": -14,
      "y": 9,
      "z": -3,
      "name": "Nat20_Force_Empty"
    },
    {
      "x": -14,
      "y": 10,
      "z": -3,
      "name": "Nat20_Force_Empty"
    },
    {
      "x": -14,
      "y": 11,
      "z": -3,
      "name": "Nat20_Force_Empty"
    },
    {
      "x": -14,
      "y": 12,
      "z": -3,
      "name": "Nat20_Force_Empty"
    },
    {
      "x": -14,
      "y": 13,
      "z": -3,
      "name": "Nat20_Force_Empty"
    },
    {
      "x": -14,
      "y": 14,
      "z": -3,
      "name": "Nat20_Force_Empty"
    },
    {
      "x": -14,
      "y": 15,
      "z": -3,
      "name": "Nat20_Force_Empty"
    },
    {
      "x": -14,
      "y": 16,
      "z": -3,
      "name": "Nat20_Force_Empty"
    },
    {
      "x": -14,
      "y": 17,
      "z": -3,
      "name": "Nat20_Force_Empty"
    },
    {
      "x": -14,
      "y": 18,
      "z": -3,
      "name": "Nat20_Force_Empty"
    },
    {
      "x": -14,
      "y": 19,
      "z": -3,
      "name": "Nat20_Force_Empty"
    },
    {
      "x": -14,
      "y": 20,
      "z": -3,
      "name": "Nat20_Force_Empty"
    },
    {
      "x": -14,
      "y": 21,
      "z": -3,
      "name": "Nat20_Force_Empty"
    },
    {
      "x": -14,
      "y": 22,
      "z": -3,
      "name": "Nat20_Force_Empty"
    },
    {
      "x": -14,
      "y": 23,
      "z": -3,
      "name": "Nat20_Force_Empty"
    },
    {
      "x": -14,
      "y": 0,
      "z": -2,
      "name": "Nat20_Force_Empty"
    },
    {
      "x": -14,
      "y": 1,
      "z": -2,
      "name": "Nat20_Force_Empty"
    },
    {
      "x": -14,
      "y": 2,
      "z": -2,
      "name": "Nat20_Force_Empty"
    },
    {
      "x": -14,
      "y": 3,
      "z": -2,
      "name": "Nat20_Force_Empty"
    },
    {
      "x": -14,
      "y": 4,
      "z": -2,
      "name": "Nat20_Force_Empty"
    },
    {
      "x": -14,
      "y": 5,
      "z": -2,
      "name": "Nat20_Force_Empty"
    },
    {
      "x": -14,
      "y": 6,
      "z": -2,
      "name": "Nat20_Force_Empty"
    },
    {
      "x": -14,
      "y": 7,
      "z": -2,
      "name": "Nat20_Force_Empty"
    },
    {
      "x": -14,
      "y": 8,
      "z": -2,
      "name": "Nat20_Force_Empty"
    },
    {
      "x": -14,
      "y": 9,
      "z": -2,
      "name": "Nat20_Force_Empty"
    },
    {
      "x": -14,
      "y": 10,
      "z": -2,
      "name": "Nat20_Force_Empty"
    },
    {
      "x": -14,
      "y": 11,
      "z": -2,
      "name": "Nat20_Force_Empty"
    },
    {
      "x": -14,
      "y": 12,
      "z": -2,
      "name": "Nat20_Force_Empty"
    },
    {
      "x": -14,
      "y": 13,
      "z": -2,
      "name": "Nat20_Force_Empty"
    },
    {
      "x": -14,
      "y": 14,
      "z": -2,
      "name": "Nat20_Force_Empty"
    },
    {
      "x": -14,
      "y": 15,
      "z": -2,
      "name": "Nat20_Force_Empty"
    },
    {
      "x": -14,
      "y": 16,
      "z": -2,
      "name": "Nat20_Force_Empty"
    },
    {
      "x": -14,
      "y": 17,
      "z": -2,
      "name": "Nat20_Force_Empty"
    },
    {
      "x": -14,
      "y": 18,
      "z": -2,
      "name": "Nat20_Force_Empty"
    },
    {
      "x": -14,
      "y": 19,
      "z": -2,
      "name": "Nat20_Force_Empty"
    },
    {
      "x": -14,
      "y": 20,
      "z": -2,
      "name": "Nat20_Force_Empty"
    },
    {
      "x": -14,
      "y": 21,
      "z": -2,
      "name": "Nat20_Force_Empty"
    },
    {
      "x": -14,
      "y": 22,
      "z": -2,
      "name": "Nat20_Force_Empty"
    },
    {
      "x": -14,
      "y": 23,
      "z": -2,
      "name": "Nat20_Force_Empty"
    },
    {
      "x": -14,
      "y": 0,
      "z": -1,
      "name": "Nat20_Force_Empty"
    },
    {
      "x": -14,
      "y": 1,
      "z": -1,
      "name": "Nat20_Force_Empty"
    },
    {
      "x": -14,
      "y": 2,
      "z": -1,
      "name": "Nat20_Force_Empty"
    },
    {
      "x": -14,
      "y": 3,
      "z": -1,
      "name": "Nat20_Force_Empty"
    },
    {
      "x": -14,
      "y": 4,
      "z": -1,
      "name": "Nat20_Force_Empty"
    },
    {
      "x": -14,
      "y": 5,
      "z": -1,
      "name": "Nat20_Force_Empty"
    },
    {
      "x": -14,
      "y": 6,
      "z": -1,
      "name": "Nat20_Force_Empty"
    },
    {
      "x": -14,
      "y": 7,
      "z": -1,
      "name": "Nat20_Force_Empty"
    },
    {
      "x": -14,
      "y": 8,
      "z": -1,
      "name": "Nat20_Force_Empty"
    },
    {
      "x": -14,
      "y": 9,
      "z": -1,
      "name": "Nat20_Force_Empty"
    },
    {
      "x": -14,
      "y": 10,
      "z": -1,
      "name": "Nat20_Force_Empty"
    },
    {
      "x": -14,
      "y": 11,
      "z": -1,
      "name": "Nat20_Force_Empty"
    },
    {
      "x": -14,
      "y": 12,
      "z": -1,
      "name": "Nat20_Force_Empty"
    },
    {
      "x": -14,
      "y": 13,
      "z": -1,
      "name": "Nat20_Force_Empty"
    },
    {
      "x": -14,
      "y": 14,
      "z": -1,
      "name": "Nat20_Force_Empty"
    },
    {
      "x": -14,
      "y": 15,
      "z": -1,
      "name": "Nat20_Force_Empty"
    },
    {
      "x": -14,
      "y": 16,
      "z": -1,
      "name": "Nat20_Force_Empty"
    },
    {
      "x": -14,
      "y": 17,
      "z": -1,
      "name": "Nat20_Force_Empty"
    },
    {
      "x": -14,
      "y": 18,
      "z": -1,
      "name": "Nat20_Force_Empty"
    },
    {
      "x": -14,
      "y": 19,
      "z": -1,
      "name": "Nat20_Force_Empty"
    },
    {
      "x": -14,
      "y": 20,
      "z": -1,
      "name": "Nat20_Force_Empty"
    },
    {
      "x": -14,
      "y": 21,
      "z": -1,
      "name": "Nat20_Force_Empty"
    },
    {
      "x": -14,
      "y": 22,
      "z": -1,
      "name": "Nat20_Force_Empty"
    },
    {
      "x": -14,
      "y": 23,
      "z": -1,
      "name": "Nat20_Force_Empty"
    },
    {
      "x": -14,
      "y": 0,
      "z": 0,
      "name": "Nat20_Force_Empty"
    },
    {
      "x": -14,
      "y": 1,
      "z": 0,
      "name": "Nat20_Force_Empty"
    },
    {
      "x": -14,
      "y": 2,
      "z": 0,
      "name": "Nat20_Force_Empty"
    },
    {
      "x": -14,
      "y": 3,
      "z": 0,
      "name": "Nat20_Force_Empty"
    },
    {
      "x": -14,
      "y": 4,
      "z": 0,
      "name": "Nat20_Force_Empty"
    },
    {
      "x": -14,
      "y": 5,
      "z": 0,
      "name": "Nat20_Force_Empty"
    },
    {
      "x": -14,
      "y": 6,
      "z": 0,
      "name": "Nat20_Force_Empty"
    },
    {
      "x": -14,
      "y": 7,
      "z": 0,
      "name": "Nat20_Force_Empty"
    },
    {
      "x": -14,
      "y": 8,
      "z": 0,
      "name": "Nat20_Force_Empty"
    },
    {
      "x": -14,
      "y": 9,
      "z": 0,
      "name": "Nat20_Force_Empty"
    },
    {
      "x": -14,
      "y": 10,
      "z": 0,
      "name": "Nat20_Force_Empty"
    },
    {
      "x": -14,
      "y": 11,
      "z": 0,
      "name": "Nat20_Force_Empty"
    },
    {
      "x": -14,
      "y": 12,
      "z": 0,
      "name": "Nat20_Force_Empty"
    },
    {
      "x": -14,
      "y": 13,
      "z": 0,
      "name": "Nat20_Force_Empty"
    },
    {
      "x": -14,
      "y": 14,
      "z": 0,
      "name": "Nat20_Force_Empty"
    },
    {
      "x": -14,
      "y": 15,
      "z": 0,
      "name": "Nat20_Force_Empty"
    },
    {
      "x": -14,
      "y": 16,
      "z": 0,
      "name": "Nat20_Force_Empty"
    },
    {
      "x": -14,
      "y": 17,
      "z": 0,
      "name": "Nat20_Force_Empty"
    },
    {
      "x": -14,
      "y": 18,
      "z": 0,
      "name": "Nat20_Force_Empty"
    },
    {
      "x": -14,
      "y": 19,
      "z": 0,
      "name": "Nat20_Force_Empty"
    },
    {
      "x": -14,
      "y": 20,
      "z": 0,
      "name": "Nat20_Force_Empty"
    },
    {
      "x": -14,
      "y": 21,
      "z": 0,
      "name": "Nat20_Force_Empty"
    },
    {
      "x": -14,
      "y": 22,
      "z": 0,
      "name": "Nat20_Force_Empty"
    },
    {
      "x": -14,
      "y": 23,
      "z": 0,
      "name": "Nat20_Force_Empty"
    },
    {
      "x": -14,
      "y": 0,
      "z": 1,
      "name": "Nat20_Force_Empty"
    },
    {
      "x": -14,
      "y": 1,
      "z": 1,
      "name": "Nat20_Force_Empty"
    },
    {
      "x": -14,
      "y": 2,
      "z": 1,
      "name": "Nat20_Force_Empty"
    },
    {
      "x": -14,
      "y": 3,
      "z": 1,
      "name": "Nat20_Force_Empty"
    },
    {
      "x": -14,
      "y": 4,
      "z": 1,
      "name": "Nat20_Force_Empty"
    },
    {
      "x": -14,
      "y": 5,
      "z": 1,
      "name": "Nat20_Force_Empty"
    },
    {
      "x": -14,
      "y": 6,
      "z": 1,
      "name": "Nat20_Force_Empty"
    },
    {
      "x": -14,
      "y": 7,
      "z": 1,
      "name": "Nat20_Force_Empty"
    },
    {
      "x": -14,
      "y": 8,
      "z": 1,
      "name": "Nat20_Force_Empty"
    },
    {
      "x": -14,
      "y": 9,
      "z": 1,
      "name": "Nat20_Force_Empty"
    },
    {
      "x": -14,
      "y": 10,
      "z": 1,
      "name": "Nat20_Force_Empty"
    },
    {
      "x": -14,
      "y": 11,
      "z": 1,
      "name": "Nat20_Force_Empty"
    },
    {
      "x": -14,
      "y": 12,
      "z": 1,
      "name": "Nat20_Force_Empty"
    },
    {
      "x": -14,
      "y": 13,
      "z": 1,
      "name": "Nat20_Force_Empty"
    },
    {
      "x": -14,
      "y": 14,
      "z": 1,
      "name": "Nat20_Force_Empty"
    },
    {
      "x": -14,
      "y": 15,
      "z": 1,
      "name": "Nat20_Force_Empty"
    },
    {
      "x": -14,
      "y": 16,
      "z": 1,
      "name": "Nat20_Force_Empty"
    },
    {
      "x": -14,
      "y": 17,
      "z": 1,
      "name": "Nat20_Force_Empty"
    },
    {
      "x": -14,
      "y": 18,
      "z": 1,
      "name": "Nat20_Force_Empty"
    },
    {
      "x": -14,
      "y": 19,
      "z": 1,
      "name": "Nat20_Force_Empty"
    },
    {
      "x": -14,
      "y": 20,
      "z": 1,
      "name": "Nat20_Force_Empty"
    },
    {
      "x": -14,
      "y": 21,
      "z": 1,
      "name": "Nat20_Force_Empty"
    },
    {
      "x": -14,
      "y": 22,
      "z": 1,
      "name": "Nat20_Force_Empty"
    },
    {
      "x": -14,
      "y": 23,
      "z": 1,
      "name": "Nat20_Force_Empty"
    },
    {
      "x": -14,
      "y": 0,
      "z": 2,
      "name": "Nat20_Force_Empty"
    },
    {
      "x": -14,
      "y": 1,
      "z": 2,
      "name": "Nat20_Force_Empty"
    },
    {
      "x": -14,
      "y": 2,
      "z": 2,
      "name": "Nat20_Force_Empty"
    },
    {
      "x": -14,
      "y": 3,
      "z": 2,
      "name": "Nat20_Force_Empty"
    },
    {
      "x": -14,
      "y": 4,
      "z": 2,
      "name": "Nat20_Force_Empty"
    },
    {
      "x": -14,
      "y": 5,
      "z": 2,
      "name": "Nat20_Force_Empty"
    },
    {
      "x": -14,
      "y": 6,
      "z": 2,
      "name": "Nat20_Force_Empty"
    },
    {
      "x": -14,
      "y": 7,
      "z": 2,
      "name": "Nat20_Force_Empty"
    },
    {
      "x": -14,
      "y": 8,
      "z": 2,
      "name": "Nat20_Force_Empty"
    },
    {
      "x": -14,
      "y": 9,
      "z": 2,
      "name": "Nat20_Force_Empty"
    },
    {
      "x": -14,
      "y": 10,
      "z": 2,
      "name": "Nat20_Force_Empty"
    },
    {
      "x": -14,
      "y": 11,
      "z": 2,
      "name": "Nat20_Force_Empty"
    },
    {
      "x": -14,
      "y": 12,
      "z": 2,
      "name": "Nat20_Force_Empty"
    },
    {
      "x": -14,
      "y": 13,
      "z": 2,
      "name": "Nat20_Force_Empty"
    },
    {
      "x": -14,
      "y": 14,
      "z": 2,
      "name": "Nat20_Force_Empty"
    },
    {
      "x": -14,
      "y": 15,
      "z": 2,
      "name": "Nat20_Force_Empty"
    },
    {
      "x": -14,
      "y": 16,
      "z": 2,
      "name": "Nat20_Force_Empty"
    },
    {
      "x": -14,
      "y": 0,
      "z": 3,
      "name": "Nat20_Force_Empty"
    },
    {
      "x": -14,
      "y": 1,
      "z": 3,
      "name": "Nat20_Force_Empty"
    },
    {
      "x": -14,
      "y": 2,
      "z": 3,
      "name": "Nat20_Force_Empty"
    },
    {
      "x": -14,
      "y": 3,
      "z": 3,
      "name": "Nat20_Force_Empty"
    },
    {
      "x": -14,
      "y": 4,
      "z": 3,
      "name": "Nat20_Force_Empty"
    },
    {
      "x": -14,
      "y": 5,
      "z": 3,
      "name": "Nat20_Force_Empty"
    },
    {
      "x": -14,
      "y": 6,
      "z": 3,
      "name": "Nat20_Force_Empty"
    },
    {
      "x": -14,
      "y": 7,
      "z": 3,
      "name": "Nat20_Force_Empty"
    },
    {
      "x": -14,
      "y": 8,
      "z": 3,
      "name": "Nat20_Force_Empty"
    },
    {
      "x": -14,
      "y": 9,
      "z": 3,
      "name": "Nat20_Force_Empty"
    },
    {
      "x": -14,
      "y": 10,
      "z": 3,
      "name": "Nat20_Force_Empty"
    },
    {
      "x": -14,
      "y": 11,
      "z": 3,
      "name": "Nat20_Force_Empty"
    },
    {
      "x": -14,
      "y": 12,
      "z": 3,
      "name": "Nat20_Force_Empty"
    },
    {
      "x": -14,
      "y": 13,
      "z": 3,
      "name": "Nat20_Force_Empty"
    },
    {
      "x": -14,
      "y": 14,
      "z": 3,
      "name": "Nat20_Force_Empty"
    },
    {
      "x": -14,
      "y": 15,
      "z": 3,
      "name": "Nat20_Force_Empty"
    },
    {
      "x": -14,
      "y": 16,
      "z": 3,
      "name": "Nat20_Force_Empty"
    },
    {
      "x": -14,
      "y": 0,
      "z": 4,
      "name": "Nat20_Force_Empty"
    },
    {
      "x": -14,
      "y": 1,
      "z": 4,
      "name": "Nat20_Force_Empty"
    },
    {
      "x": -14,
      "y": 2,
      "z": 4,
      "name": "Nat20_Force_Empty"
    },
    {
      "x": -14,
      "y": 3,
      "z": 4,
      "name": "Nat20_Force_Empty"
    },
    {
      "x": -14,
      "y": 4,
      "z": 4,
      "name": "Nat20_Force_Empty"
    },
    {
      "x": -14,
      "y": 5,
      "z": 4,
      "name": "Nat20_Force_Empty"
    },
    {
      "x": -14,
      "y": 6,
      "z": 4,
      "name": "Nat20_Force_Empty"
    },
    {
      "x": -14,
      "y": 7,
      "z": 4,
      "name": "Nat20_Force_Empty"
    },
    {
      "x": -14,
      "y": 8,
      "z": 4,
      "name": "Nat20_Force_Empty"
    },
    {
      "x": -14,
      "y": 9,
      "z": 4,
      "name": "Nat20_Force_Empty"
    },
    {
      "x": -14,
      "y": 10,
      "z": 4,
      "name": "Nat20_Force_Empty"
    },
    {
      "x": -14,
      "y": 11,
      "z": 4,
      "name": "Nat20_Force_Empty"
    },
    {
      "x": -14,
      "y": 12,
      "z": 4,
      "name": "Nat20_Force_Empty"
    },
    {
      "x": -14,
      "y": 13,
      "z": 4,
      "name": "Nat20_Force_Empty"
    },
    {
      "x": -14,
      "y": 14,
      "z": 4,
      "name": "Nat20_Force_Empty"
    },
    {
      "x": -14,
      "y": 15,
      "z": 4,
      "name": "Nat20_Force_Empty"
    },
    {
      "x": -14,
      "y": 16,
      "z": 4,
      "name": "Nat20_Force_Empty"
    },
    {
      "x": -14,
      "y": 0,
      "z": 5,
      "name": "Nat20_Force_Empty"
    },
    {
      "x": -14,
      "y": 1,
      "z": 5,
      "name": "Nat20_Force_Empty"
    },
    {
      "x": -14,
      "y": 2,
      "z": 5,
      "name": "Nat20_Force_Empty"
    },
    {
      "x": -14,
      "y": 3,
      "z": 5,
      "name": "Nat20_Force_Empty"
    },
    {
      "x": -14,
      "y": 4,
      "z": 5,
      "name": "Nat20_Force_Empty"
    },
    {
      "x": -14,
      "y": 5,
      "z": 5,
      "name": "Nat20_Force_Empty"
    },
    {
      "x": -14,
      "y": 6,
      "z": 5,
      "name": "Nat20_Force_Empty"
    },
    {
      "x": -14,
      "y": 7,
      "z": 5,
      "name": "Nat20_Force_Empty"
    },
    {
      "x": -14,
      "y": 8,
      "z": 5,
      "name": "Nat20_Force_Empty"
    },
    {
      "x": -14,
      "y": 9,
      "z": 5,
      "name": "Nat20_Force_Empty"
    },
    {
      "x": -14,
      "y": 10,
      "z": 5,
      "name": "Nat20_Force_Empty"
    },
    {
      "x": -14,
      "y": 11,
      "z": 5,
      "name": "Nat20_Force_Empty"
    },
    {
      "x": -14,
      "y": 12,
      "z": 5,
      "name": "Nat20_Force_Empty"
    },
    {
      "x": -14,
      "y": 13,
      "z": 5,
      "name": "Nat20_Force_Empty"
    },
    {
      "x": -14,
      "y": 14,
      "z": 5,
      "name": "Nat20_Force_Empty"
    },
    {
      "x": -14,
      "y": 15,
      "z": 5,
      "name": "Nat20_Force_Empty"
    },
    {
      "x": -14,
      "y": 16,
      "z": 5,
      "name": "Nat20_Force_Empty"
    },
    {
      "x": -14,
      "y": 0,
      "z": 6,
      "name": "Nat20_Force_Empty"
    },
    {
      "x": -14,
      "y": 1,
      "z": 6,
      "name": "Nat20_Force_Empty"
    },
    {
      "x": -14,
      "y": 2,
      "z": 6,
      "name": "Nat20_Force_Empty"
    },
    {
      "x": -14,
      "y": 3,
      "z": 6,
      "name": "Nat20_Force_Empty"
    },
    {
      "x": -14,
      "y": 4,
      "z": 6,
      "name": "Nat20_Force_Empty"
    },
    {
      "x": -14,
      "y": 5,
      "z": 6,
      "name": "Nat20_Force_Empty"
    },
    {
      "x": -14,
      "y": 6,
      "z": 6,
      "name": "Nat20_Force_Empty"
    },
    {
      "x": -14,
      "y": 7,
      "z": 6,
      "name": "Nat20_Force_Empty"
    },
    {
      "x": -14,
      "y": 8,
      "z": 6,
      "name": "Nat20_Force_Empty"
    },
    {
      "x": -14,
      "y": 9,
      "z": 6,
      "name": "Nat20_Force_Empty"
    },
    {
      "x": -14,
      "y": 10,
      "z": 6,
      "name": "Nat20_Force_Empty"
    },
    {
      "x": -14,
      "y": 11,
      "z": 6,
      "name": "Nat20_Force_Empty"
    },
    {
      "x": -14,
      "y": 12,
      "z": 6,
      "name": "Nat20_Force_Empty"
    },
    {
      "x": -14,
      "y": 13,
      "z": 6,
      "name": "Nat20_Force_Empty"
    },
    {
      "x": -14,
      "y": 14,
      "z": 6,
      "name": "Nat20_Force_Empty"
    },
    {
      "x": -14,
      "y": 15,
      "z": 6,
      "name": "Nat20_Force_Empty"
    },
    {
      "x": -14,
      "y": 16,
      "z": 6,
      "name": "Nat20_Force_Empty"
    },
    {
      "x": -14,
      "y": 0,
      "z": 7,
      "name": "Nat20_Force_Empty"
    },
    {
      "x": -14,
      "y": 1,
      "z": 7,
      "name": "Nat20_Force_Empty"
    },
    {
      "x": -14,
      "y": 2,
      "z": 7,
      "name": "Nat20_Force_Empty"
    },
    {
      "x": -14,
      "y": 3,
      "z": 7,
      "name": "Nat20_Force_Empty"
    },
    {
      "x": -14,
      "y": 4,
      "z": 7,
      "name": "Nat20_Force_Empty"
    },
    {
      "x": -14,
      "y": 5,
      "z": 7,
      "name": "Nat20_Force_Empty"
    },
    {
      "x": -14,
      "y": 6,
      "z": 7,
      "name": "Nat20_Force_Empty"
    },
    {
      "x": -14,
      "y": 7,
      "z": 7,
      "name": "Nat20_Force_Empty"
    },
    {
      "x": -14,
      "y": 8,
      "z": 7,
      "name": "Nat20_Force_Empty"
    },
    {
      "x": -14,
      "y": 9,
      "z": 7,
      "name": "Nat20_Force_Empty"
    },
    {
      "x": -14,
      "y": 10,
      "z": 7,
      "name": "Nat20_Force_Empty"
    },
    {
      "x": -14,
      "y": 11,
      "z": 7,
      "name": "Nat20_Force_Empty"
    },
    {
      "x": -14,
      "y": 12,
      "z": 7,
      "name": "Nat20_Force_Empty"
    },
    {
      "x": -14,
      "y": 13,
      "z": 7,
      "name": "Nat20_Force_Empty"
    },
    {
      "x": -14,
      "y": 14,
      "z": 7,
      "name": "Nat20_Force_Empty"
    },
    {
      "x": -14,
      "y": 15,
      "z": 7,
      "name": "Nat20_Force_Empty"
    },
    {
      "x": -14,
      "y": 16,
      "z": 7,
      "name": "Nat20_Force_Empty"
    },
    {
      "x": -14,
      "y": 0,
      "z": 8,
      "name": "Nat20_Force_Empty"
    },
    {
      "x": -14,
      "y": 1,
      "z": 8,
      "name": "Nat20_Force_Empty"
    },
    {
      "x": -14,
      "y": 2,
      "z": 8,
      "name": "Nat20_Force_Empty"
    },
    {
      "x": -14,
      "y": 3,
      "z": 8,
      "name": "Nat20_Force_Empty"
    },
    {
      "x": -14,
      "y": 4,
      "z": 8,
      "name": "Nat20_Force_Empty"
    },
    {
      "x": -14,
      "y": 5,
      "z": 8,
      "name": "Nat20_Force_Empty"
    },
    {
      "x": -14,
      "y": 6,
      "z": 8,
      "name": "Nat20_Force_Empty"
    },
    {
      "x": -14,
      "y": 7,
      "z": 8,
      "name": "Nat20_Force_Empty"
    },
    {
      "x": -14,
      "y": 8,
      "z": 8,
      "name": "Nat20_Force_Empty"
    },
    {
      "x": -14,
      "y": 9,
      "z": 8,
      "name": "Nat20_Force_Empty"
    },
    {
      "x": -14,
      "y": 10,
      "z": 8,
      "name": "Nat20_Force_Empty"
    },
    {
      "x": -14,
      "y": 11,
      "z": 8,
      "name": "Nat20_Force_Empty"
    },
    {
      "x": -14,
      "y": 12,
      "z": 8,
      "name": "Nat20_Force_Empty"
    },
    {
      "x": -14,
      "y": 13,
      "z": 8,
      "name": "Nat20_Force_Empty"
    },
    {
      "x": -14,
      "y": 14,
      "z": 8,
      "name": "Nat20_Force_Empty"
    },
    {
      "x": -14,
      "y": 15,
      "z": 8,
      "name": "Nat20_Force_Empty"
    },
    {
      "x": -14,
      "y": 16,
      "z": 8,
      "name": "Nat20_Force_Empty"
    },
    {
      "x": -14,
      "y": 0,
      "z": 9,
      "name": "Nat20_Force_Empty"
    },
    {
      "x": -14,
      "y": 1,
      "z": 9,
      "name": "Nat20_Force_Empty"
    },
    {
      "x": -14,
      "y": 2,
      "z": 9,
      "name": "Nat20_Force_Empty"
    },
    {
      "x": -14,
      "y": 3,
      "z": 9,
      "name": "Nat20_Force_Empty"
    },
    {
      "x": -14,
      "y": 4,
      "z": 9,
      "name": "Nat20_Force_Empty"
    },
    {
      "x": -14,
      "y": 5,
      "z": 9,
      "name": "Nat20_Force_Empty"
    },
    {
      "x": -14,
      "y": 6,
      "z": 9,
      "name": "Nat20_Force_Empty"
    },
    {
      "x": -14,
      "y": 7,
      "z": 9,
      "name": "Nat20_Force_Empty"
    },
    {
      "x": -14,
      "y": 8,
      "z": 9,
      "name": "Nat20_Force_Empty"
    },
    {
      "x": -14,
      "y": 9,
      "z": 9,
      "name": "Nat20_Force_Empty"
    },
    {
      "x": -14,
      "y": 10,
      "z": 9,
      "name": "Nat20_Force_Empty"
    },
    {
      "x": -14,
      "y": 11,
      "z": 9,
      "name": "Nat20_Force_Empty"
    },
    {
      "x": -14,
      "y": 12,
      "z": 9,
      "name": "Nat20_Force_Empty"
    },
    {
      "x": -14,
      "y": 13,
      "z": 9,
      "name": "Nat20_Force_Empty"
    },
    {
      "x": -14,
      "y": 14,
      "z": 9,
      "name": "Nat20_Force_Empty"
    },
    {
      "x": -14,
      "y": 15,
      "z": 9,
      "name": "Nat20_Force_Empty"
    },
    {
      "x": -14,
      "y": 16,
      "z": 9,
      "name": "Nat20_Force_Empty"
    },
    {
      "x": -13,
      "y": 0,
      "z": -9,
      "name": "Nat20_Force_Empty"
    },
    {
      "x": -13,
      "y": 1,
      "z": -9,
      "name": "Nat20_Force_Empty"
    },
    {
      "x": -13,
      "y": 2,
      "z": -9,
      "name": "Nat20_Force_Empty"
    },
    {
      "x": -13,
      "y": 3,
      "z": -9,
      "name": "Nat20_Force_Empty"
    },
    {
      "x": -13,
      "y": 4,
      "z": -9,
      "name": "Nat20_Force_Empty"
    },
    {
      "x": -13,
      "y": 5,
      "z": -9,
      "name": "Nat20_Force_Empty"
    },
    {
      "x": -13,
      "y": 6,
      "z": -9,
      "name": "Nat20_Force_Empty"
    },
    {
      "x": -13,
      "y": 7,
      "z": -9,
      "name": "Nat20_Force_Empty"
    },
    {
      "x": -13,
      "y": 8,
      "z": -9,
      "name": "Nat20_Force_Empty"
    },
    {
      "x": -13,
      "y": 9,
      "z": -9,
      "name": "Nat20_Force_Empty"
    },
    {
      "x": -13,
      "y": 10,
      "z": -9,
      "name": "Nat20_Force_Empty"
    },
    {
      "x": -13,
      "y": 11,
      "z": -9,
      "name": "Nat20_Force_Empty"
    },
    {
      "x": -13,
      "y": 12,
      "z": -9,
      "name": "Nat20_Force_Empty"
    },
    {
      "x": -13,
      "y": 13,
      "z": -9,
      "name": "Nat20_Force_Empty"
    },
    {
      "x": -13,
      "y": 14,
      "z": -9,
      "name": "Nat20_Force_Empty"
    },
    {
      "x": -13,
      "y": 15,
      "z": -9,
      "name": "Nat20_Force_Empty"
    },
    {
      "x": -13,
      "y": 16,
      "z": -9,
      "name": "Nat20_Force_Empty"
    },
    {
      "x": -13,
      "y": 17,
      "z": -9,
      "name": "Nat20_Force_Empty"
    },
    {
      "x": -13,
      "y": 18,
      "z": -9,
      "name": "Nat20_Force_Empty"
    },
    {
      "x": -13,
      "y": 19,
      "z": -9,
      "name": "Nat20_Force_Empty"
    },
    {
      "x": -13,
      "y": 20,
      "z": -9,
      "name": "Nat20_Force_Empty"
    },
    {
      "x": -13,
      "y": 21,
      "z": -9,
      "name": "Nat20_Force_Empty"
    },
    {
      "x": -13,
      "y": 22,
      "z": -9,
      "name": "Nat20_Force_Empty"
    },
    {
      "x": -13,
      "y": 23,
      "z": -9,
      "name": "Nat20_Force_Empty"
    },
    {
      "x": -13,
      "y": 0,
      "z": -8,
      "name": "Nat20_Force_Empty"
    },
    {
      "x": -13,
      "y": 1,
      "z": -8,
      "name": "Nat20_Force_Empty"
    },
    {
      "x": -13,
      "y": 2,
      "z": -8,
      "name": "Nat20_Force_Empty"
    },
    {
      "x": -13,
      "y": 3,
      "z": -8,
      "name": "Nat20_Force_Empty"
    },
    {
      "x": -13,
      "y": 4,
      "z": -8,
      "name": "Nat20_Force_Empty"
    },
    {
      "x": -13,
      "y": 5,
      "z": -8,
      "name": "Nat20_Force_Empty"
    },
    {
      "x": -13,
      "y": 6,
      "z": -8,
      "name": "Nat20_Force_Empty"
    },
    {
      "x": -13,
      "y": 7,
      "z": -8,
      "name": "Nat20_Force_Empty"
    },
    {
      "x": -13,
      "y": 8,
      "z": -8,
      "name": "Nat20_Force_Empty"
    },
    {
      "x": -13,
      "y": 9,
      "z": -8,
      "name": "Nat20_Force_Empty"
    },
    {
      "x": -13,
      "y": 10,
      "z": -8,
      "name": "Nat20_Force_Empty"
    },
    {
      "x": -13,
      "y": 11,
      "z": -8,
      "name": "Nat20_Force_Empty"
    },
    {
      "x": -13,
      "y": 12,
      "z": -8,
      "name": "Nat20_Force_Empty"
    },
    {
      "x": -13,
      "y": 13,
      "z": -8,
      "name": "Nat20_Force_Empty"
    },
    {
      "x": -13,
      "y": 14,
      "z": -8,
      "name": "Nat20_Force_Empty"
    },
    {
      "x": -13,
      "y": 15,
      "z": -8,
      "name": "Nat20_Force_Empty"
    },
    {
      "x": -13,
      "y": 16,
      "z": -8,
      "name": "Nat20_Force_Empty"
    },
    {
      "x": -13,
      "y": 17,
      "z": -8,
      "name": "Nat20_Force_Empty"
    },
    {
      "x": -13,
      "y": 18,
      "z": -8,
      "name": "Nat20_Force_Empty"
    },
    {
      "x": -13,
      "y": 19,
      "z": -8,
      "name": "Nat20_Force_Empty"
    },
    {
      "x": -13,
      "y": 20,
      "z": -8,
      "name": "Nat20_Force_Empty"
    },
    {
      "x": -13,
      "y": 21,
      "z": -8,
      "name": "Nat20_Force_Empty"
    },
    {
      "x": -13,
      "y": 22,
      "z": -8,
      "name": "Nat20_Force_Empty"
    },
    {
      "x": -13,
      "y": 23,
      "z": -8,
      "name": "Nat20_Force_Empty"
    },
    {
      "x": -13,
      "y": 0,
      "z": -7,
      "name": "Nat20_Force_Empty"
    },
    {
      "x": -13,
      "y": 1,
      "z": -7,
      "name": "Nat20_Force_Empty"
    },
    {
      "x": -13,
      "y": 2,
      "z": -7,
      "name": "Nat20_Force_Empty"
    },
    {
      "x": -13,
      "y": 3,
      "z": -7,
      "name": "Nat20_Force_Empty"
    },
    {
      "x": -13,
      "y": 4,
      "z": -7,
      "name": "Nat20_Force_Empty"
    },
    {
      "x": -13,
      "y": 5,
      "z": -7,
      "name": "Nat20_Force_Empty"
    },
    {
      "x": -13,
      "y": 6,
      "z": -7,
      "name": "Nat20_Force_Empty"
    },
    {
      "x": -13,
      "y": 7,
      "z": -7,
      "name": "Nat20_Force_Empty"
    },
    {
      "x": -13,
      "y": 8,
      "z": -7,
      "name": "Nat20_Force_Empty"
    },
    {
      "x": -13,
      "y": 9,
      "z": -7,
      "name": "Nat20_Force_Empty"
    },
    {
      "x": -13,
      "y": 10,
      "z": -7,
      "name": "Nat20_Force_Empty"
    },
    {
      "x": -13,
      "y": 11,
      "z": -7,
      "name": "Nat20_Force_Empty"
    },
    {
      "x": -13,
      "y": 12,
      "z": -7,
      "name": "Nat20_Force_Empty"
    },
    {
      "x": -13,
      "y": 13,
      "z": -7,
      "name": "Nat20_Force_Empty"
    },
    {
      "x": -13,
      "y": 14,
      "z": -7,
      "name": "Nat20_Force_Empty"
    },
    {
      "x": -13,
      "y": 15,
      "z": -7,
      "name": "Nat20_Force_Empty"
    },
    {
      "x": -13,
      "y": 16,
      "z": -7,
      "name": "Nat20_Force_Empty"
    },
    {
      "x": -13,
      "y": 17,
      "z": -7,
      "name": "Nat20_Force_Empty"
    },
    {
      "x": -13,
      "y": 18,
      "z": -7,
      "name": "Nat20_Force_Empty"
    },
    {
      "x": -13,
      "y": 19,
      "z": -7,
      "name": "Nat20_Force_Empty"
    },
    {
      "x": -13,
      "y": 20,
      "z": -7,
      "name": "Nat20_Force_Empty"
    },
    {
      "x": -13,
      "y": 21,
      "z": -7,
      "name": "Nat20_Force_Empty"
    },
    {
      "x": -13,
      "y": 22,
      "z": -7,
      "name": "Nat20_Force_Empty"
    },
    {
      "x": -13,
      "y": 23,
      "z": -7,
      "name": "Nat20_Force_Empty"
    },
    {
      "x": -13,
      "y": 0,
      "z": -6,
      "name": "Nat20_Force_Empty"
    },
    {
      "x": -13,
      "y": 1,
      "z": -6,
      "name": "Nat20_Force_Empty"
    },
    {
      "x": -13,
      "y": 2,
      "z": -6,
      "name": "Nat20_Force_Empty"
    },
    {
      "x": -13,
      "y": 3,
      "z": -6,
      "name": "Nat20_Force_Empty"
    },
    {
      "x": -13,
      "y": 4,
      "z": -6,
      "name": "Nat20_Force_Empty"
    },
    {
      "x": -13,
      "y": 5,
      "z": -6,
      "name": "Nat20_Force_Empty"
    },
    {
      "x": -13,
      "y": 6,
      "z": -6,
      "name": "Nat20_Force_Empty"
    },
    {
      "x": -13,
      "y": 7,
      "z": -6,
      "name": "Nat20_Force_Empty"
    },
    {
      "x": -13,
      "y": 8,
      "z": -6,
      "name": "Nat20_Force_Empty"
    },
    {
      "x": -13,
      "y": 9,
      "z": -6,
      "name": "Nat20_Force_Empty"
    },
    {
      "x": -13,
      "y": 10,
      "z": -6,
      "name": "Nat20_Force_Empty"
    },
    {
      "x": -13,
      "y": 11,
      "z": -6,
      "name": "Nat20_Force_Empty"
    },
    {
      "x": -13,
      "y": 12,
      "z": -6,
      "name": "Nat20_Force_Empty"
    },
    {
      "x": -13,
      "y": 13,
      "z": -6,
      "name": "Nat20_Force_Empty"
    },
    {
      "x": -13,
      "y": 14,
      "z": -6,
      "name": "Nat20_Force_Empty"
    },
    {
      "x": -13,
      "y": 15,
      "z": -6,
      "name": "Nat20_Force_Empty"
    },
    {
      "x": -13,
      "y": 16,
      "z": -6,
      "name": "Nat20_Force_Empty"
    },
    {
      "x": -13,
      "y": 17,
      "z": -6,
      "name": "Nat20_Force_Empty"
    },
    {
      "x": -13,
      "y": 18,
      "z": -6,
      "name": "Nat20_Force_Empty"
    },
    {
      "x": -13,
      "y": 19,
      "z": -6,
      "name": "Nat20_Force_Empty"
    },
    {
      "x": -13,
      "y": 20,
      "z": -6,
      "name": "Nat20_Force_Empty"
    },
    {
      "x": -13,
      "y": 21,
      "z": -6,
      "name": "Nat20_Force_Empty"
    },
    {
      "x": -13,
      "y": 22,
      "z": -6,
      "name": "Nat20_Force_Empty"
    },
    {
      "x": -13,
      "y": 23,
      "z": -6,
      "name": "Nat20_Force_Empty"
    },
    {
      "x": -13,
      "y": 0,
      "z": -5,
      "name": "Nat20_Force_Empty"
    },
    {
      "x": -13,
      "y": 1,
      "z": -5,
      "name": "Nat20_Force_Empty"
    },
    {
      "x": -13,
      "y": 2,
      "z": -5,
      "name": "Nat20_Force_Empty"
    },
    {
      "x": -13,
      "y": 3,
      "z": -5,
      "name": "Nat20_Force_Empty"
    },
    {
      "x": -13,
      "y": 4,
      "z": -5,
      "name": "Nat20_Force_Empty"
    },
    {
      "x": -13,
      "y": 5,
      "z": -5,
      "name": "Nat20_Force_Empty"
    },
    {
      "x": -13,
      "y": 6,
      "z": -5,
      "name": "Nat20_Force_Empty"
    },
    {
      "x": -13,
      "y": 7,
      "z": -5,
      "name": "Nat20_Force_Empty"
    },
    {
      "x": -13,
      "y": 8,
      "z": -5,
      "name": "Nat20_Force_Empty"
    },
    {
      "x": -13,
      "y": 9,
      "z": -5,
      "name": "Nat20_Force_Empty"
    },
    {
      "x": -13,
      "y": 10,
      "z": -5,
      "name": "Nat20_Force_Empty"
    },
    {
      "x": -13,
      "y": 11,
      "z": -5,
      "name": "Nat20_Force_Empty"
    },
    {
      "x": -13,
      "y": 12,
      "z": -5,
      "name": "Nat20_Force_Empty"
    },
    {
      "x": -13,
      "y": 13,
      "z": -5,
      "name": "Nat20_Force_Empty"
    },
    {
      "x": -13,
      "y": 14,
      "z": -5,
      "name": "Nat20_Force_Empty"
    },
    {
      "x": -13,
      "y": 15,
      "z": -5,
      "name": "Nat20_Force_Empty"
    },
    {
      "x": -13,
      "y": 16,
      "z": -5,
      "name": "Nat20_Force_Empty"
    },
    {
      "x": -13,
      "y": 17,
      "z": -5,
      "name": "Nat20_Force_Empty"
    },
    {
      "x": -13,
      "y": 18,
      "z": -5,
      "name": "Nat20_Force_Empty"
    },
    {
      "x": -13,
      "y": 19,
      "z": -5,
      "name": "Nat20_Force_Empty"
    },
    {
      "x": -13,
      "y": 20,
      "z": -5,
      "name": "Nat20_Force_Empty"
    },
    {
      "x": -13,
      "y": 21,
      "z": -5,
      "name": "Nat20_Force_Empty"
    },
    {
      "x": -13,
      "y": 22,
      "z": -5,
      "name": "Nat20_Force_Empty"
    },
    {
      "x": -13,
      "y": 23,
      "z": -5,
      "name": "Nat20_Force_Empty"
    },
    {
      "x": -13,
      "y": 0,
      "z": -4,
      "name": "Nat20_Force_Empty"
    },
    {
      "x": -13,
      "y": 1,
      "z": -4,
      "name": "Nat20_Force_Empty"
    },
    {
      "x": -13,
      "y": 2,
      "z": -4,
      "name": "Nat20_Force_Empty"
    },
    {
      "x": -13,
      "y": 3,
      "z": -4,
      "name": "Nat20_Force_Empty"
    },
    {
      "x": -13,
      "y": 4,
      "z": -4,
      "name": "Wood_Torch_Wall",
      "rotation": 3
    },
    {
      "x": -13,
      "y": 5,
      "z": -4,
      "name": "Nat20_Force_Empty"
    },
    {
      "x": -13,
      "y": 6,
      "z": -4,
      "name": "Nat20_Force_Empty"
    },
    {
      "x": -13,
      "y": 7,
      "z": -4,
      "name": "Nat20_Force_Empty"
    },
    {
      "x": -13,
      "y": 8,
      "z": -4,
      "name": "Nat20_Force_Empty"
    },
    {
      "x": -13,
      "y": 9,
      "z": -4,
      "name": "Nat20_Force_Empty"
    },
    {
      "x": -13,
      "y": 10,
      "z": -4,
      "name": "Nat20_Force_Empty"
    },
    {
      "x": -13,
      "y": 11,
      "z": -4,
      "name": "Nat20_Force_Empty"
    },
    {
      "x": -13,
      "y": 12,
      "z": -4,
      "name": "Nat20_Force_Empty"
    },
    {
      "x": -13,
      "y": 13,
      "z": -4,
      "name": "Nat20_Force_Empty"
    },
    {
      "x": -13,
      "y": 14,
      "z": -4,
      "name": "Nat20_Force_Empty"
    },
    {
      "x": -13,
      "y": 15,
      "z": -4,
      "name": "Nat20_Force_Empty"
    },
    {
      "x": -13,
      "y": 16,
      "z": -4,
      "name": "Nat20_Force_Empty"
    },
    {
      "x": -13,
      "y": 17,
      "z": -4,
      "name": "Nat20_Force_Empty"
    },
    {
      "x": -13,
      "y": 18,
      "z": -4,
      "name": "Nat20_Force_Empty"
    },
    {
      "x": -13,
      "y": 19,
      "z": -4,
      "name": "Nat20_Force_Empty"
    },
    {
      "x": -13,
      "y": 20,
      "z": -4,
      "name": "Nat20_Force_Empty"
    },
    {
      "x": -13,
      "y": 21,
      "z": -4,
      "name": "Nat20_Force_Empty"
    },
    {
      "x": -13,
      "y": 22,
      "z": -4,
      "name": "Nat20_Force_Empty"
    },
    {
      "x": -13,
      "y": 23,
      "z": -4,
      "name": "Nat20_Force_Empty"
    },
    {
      "x": -13,
      "y": 0,
      "z": -3,
      "name": "Nat20_Force_Empty"
    },
    {
      "x": -13,
      "y": 1,
      "z": -3,
      "name": "Nat20_Force_Empty"
    },
    {
      "x": -13,
      "y": 2,
      "z": -3,
      "name": "Nat20_Force_Empty"
    },
    {
      "x": -13,
      "y": 3,
      "z": -3,
      "name": "Nat20_Force_Empty"
    },
    {
      "x": -13,
      "y": 4,
      "z": -3,
      "name": "Nat20_Force_Empty"
    },
    {
      "x": -13,
      "y": 5,
      "z": -3,
      "name": "Nat20_Force_Empty"
    },
    {
      "x": -13,
      "y": 6,
      "z": -3,
      "name": "Nat20_Force_Empty"
    },
    {
      "x": -13,
      "y": 7,
      "z": -3,
      "name": "Nat20_Force_Empty"
    },
    {
      "x": -13,
      "y": 8,
      "z": -3,
      "name": "Nat20_Force_Empty"
    },
    {
      "x": -13,
      "y": 9,
      "z": -3,
      "name": "Nat20_Force_Empty"
    },
    {
      "x": -13,
      "y": 10,
      "z": -3,
      "name": "Nat20_Force_Empty"
    },
    {
      "x": -13,
      "y": 11,
      "z": -3,
      "name": "Nat20_Force_Empty"
    },
    {
      "x": -13,
      "y": 12,
      "z": -3,
      "name": "Nat20_Force_Empty"
    },
    {
      "x": -13,
      "y": 13,
      "z": -3,
      "name": "Nat20_Force_Empty"
    },
    {
      "x": -13,
      "y": 14,
      "z": -3,
      "name": "Nat20_Force_Empty"
    },
    {
      "x": -13,
      "y": 15,
      "z": -3,
      "name": "Nat20_Force_Empty"
    },
    {
      "x": -13,
      "y": 16,
      "z": -3,
      "name": "Nat20_Force_Empty"
    },
    {
      "x": -13,
      "y": 17,
      "z": -3,
      "name": "Nat20_Force_Empty"
    },
    {
      "x": -13,
      "y": 18,
      "z": -3,
      "name": "Nat20_Force_Empty"
    },
    {
      "x": -13,
      "y": 19,
      "z": -3,
      "name": "Nat20_Force_Empty"
    },
    {
      "x": -13,
      "y": 20,
      "z": -3,
      "name": "Nat20_Force_Empty"
    },
    {
      "x": -13,
      "y": 21,
      "z": -3,
      "name": "Nat20_Force_Empty"
    },
    {
      "x": -13,
      "y": 22,
      "z": -3,
      "name": "Nat20_Force_Empty"
    },
    {
      "x": -13,
      "y": 23,
      "z": -3,
      "name": "Nat20_Force_Empty"
    },
    {
      "x": -13,
      "y": 0,
      "z": -2,
      "name": "Nat20_Force_Empty"
    },
    {
      "x": -13,
      "y": 1,
      "z": -2,
      "name": "Nat20_Force_Empty"
    },
    {
      "x": -13,
      "y": 2,
      "z": -2,
      "name": "Nat20_Force_Empty"
    },
    {
      "x": -13,
      "y": 3,
      "z": -2,
      "name": "Nat20_Force_Empty"
    },
    {
      "x": -13,
      "y": 4,
      "z": -2,
      "name": "Nat20_Force_Empty"
    },
    {
      "x": -13,
      "y": 5,
      "z": -2,
      "name": "Nat20_Force_Empty"
    },
    {
      "x": -13,
      "y": 6,
      "z": -2,
      "name": "Nat20_Force_Empty"
    },
    {
      "x": -13,
      "y": 7,
      "z": -2,
      "name": "Nat20_Force_Empty"
    },
    {
      "x": -13,
      "y": 8,
      "z": -2,
      "name": "Nat20_Force_Empty"
    },
    {
      "x": -13,
      "y": 9,
      "z": -2,
      "name": "Nat20_Force_Empty"
    },
    {
      "x": -13,
      "y": 10,
      "z": -2,
      "name": "Nat20_Force_Empty"
    },
    {
      "x": -13,
      "y": 11,
      "z": -2,
      "name": "Nat20_Force_Empty"
    },
    {
      "x": -13,
      "y": 12,
      "z": -2,
      "name": "Nat20_Force_Empty"
    },
    {
      "x": -13,
      "y": 13,
      "z": -2,
      "name": "Nat20_Force_Empty"
    },
    {
      "x": -13,
      "y": 14,
      "z": -2,
      "name": "Nat20_Force_Empty"
    },
    {
      "x": -13,
      "y": 15,
      "z": -2,
      "name": "Nat20_Force_Empty"
    },
    {
      "x": -13,
      "y": 16,
      "z": -2,
      "name": "Nat20_Force_Empty"
    },
    {
      "x": -13,
      "y": 17,
      "z": -2,
      "name": "Nat20_Force_Empty"
    },
    {
      "x": -13,
      "y": 18,
      "z": -2,
      "name": "Nat20_Force_Empty"
    },
    {
      "x": -13,
      "y": 19,
      "z": -2,
      "name": "Nat20_Force_Empty"
    },
    {
      "x": -13,
      "y": 20,
      "z": -2,
      "name": "Nat20_Force_Empty"
    },
    {
      "x": -13,
      "y": 21,
      "z": -2,
      "name": "Nat20_Force_Empty"
    },
    {
      "x": -13,
      "y": 22,
      "z": -2,
      "name": "Nat20_Force_Empty"
    },
    {
      "x": -13,
      "y": 23,
      "z": -2,
      "name": "Nat20_Force_Empty"
    },
    {
      "x": -13,
      "y": 0,
      "z": -1,
      "name": "Nat20_Force_Empty"
    },
    {
      "x": -13,
      "y": 1,
      "z": -1,
      "name": "Nat20_Force_Empty"
    },
    {
      "x": -13,
      "y": 2,
      "z": -1,
      "name": "Nat20_Force_Empty"
    },
    {
      "x": -13,
      "y": 3,
      "z": -1,
      "name": "Nat20_Force_Empty"
    },
    {
      "x": -13,
      "y": 4,
      "z": -1,
      "name": "Nat20_Force_Empty"
    },
    {
      "x": -13,
      "y": 5,
      "z": -1,
      "name": "Nat20_Force_Empty"
    },
    {
      "x": -13,
      "y": 6,
      "z": -1,
      "name": "Nat20_Force_Empty"
    },
    {
      "x": -13,
      "y": 7,
      "z": -1,
      "name": "Nat20_Force_Empty"
    },
    {
      "x": -13,
      "y": 8,
      "z": -1,
      "name": "Nat20_Force_Empty"
    },
    {
      "x": -13,
      "y": 9,
      "z": -1,
      "name": "Nat20_Force_Empty"
    },
    {
      "x": -13,
      "y": 10,
      "z": -1,
      "name": "Nat20_Force_Empty"
    },
    {
      "x": -13,
      "y": 11,
      "z": -1,
      "name": "Nat20_Force_Empty"
    },
    {
      "x": -13,
      "y": 12,
      "z": -1,
      "name": "Nat20_Force_Empty"
    },
    {
      "x": -13,
      "y": 13,
      "z": -1,
      "name": "Nat20_Force_Empty"
    },
    {
      "x": -13,
      "y": 14,
      "z": -1,
      "name": "Nat20_Force_Empty"
    },
    {
      "x": -13,
      "y": 15,
      "z": -1,
      "name": "Nat20_Force_Empty"
    },
    {
      "x": -13,
      "y": 16,
      "z": -1,
      "name": "Nat20_Force_Empty"
    },
    {
      "x": -13,
      "y": 17,
      "z": -1,
      "name": "Nat20_Force_Empty"
    },
    {
      "x": -13,
      "y": 18,
      "z": -1,
      "name": "Nat20_Force_Empty"
    },
    {
      "x": -13,
      "y": 19,
      "z": -1,
      "name": "Nat20_Force_Empty"
    },
    {
      "x": -13,
      "y": 20,
      "z": -1,
      "name": "Nat20_Force_Empty"
    },
    {
      "x": -13,
      "y": 21,
      "z": -1,
      "name": "Nat20_Force_Empty"
    },
    {
      "x": -13,
      "y": 22,
      "z": -1,
      "name": "Nat20_Force_Empty"
    },
    {
      "x": -13,
      "y": 23,
      "z": -1,
      "name": "Nat20_Force_Empty"
    },
    {
      "x": -13,
      "y": 0,
      "z": 0,
      "name": "Nat20_Force_Empty"
    },
    {
      "x": -13,
      "y": 1,
      "z": 0,
      "name": "Nat20_Force_Empty"
    },
    {
      "x": -13,
      "y": 2,
      "z": 0,
      "name": "Nat20_Force_Empty"
    },
    {
      "x": -13,
      "y": 3,
      "z": 0,
      "name": "Nat20_Force_Empty"
    },
    {
      "x": -13,
      "y": 4,
      "z": 0,
      "name": "Nat20_Force_Empty"
    },
    {
      "x": -13,
      "y": 5,
      "z": 0,
      "name": "Nat20_Force_Empty"
    },
    {
      "x": -13,
      "y": 6,
      "z": 0,
      "name": "Nat20_Force_Empty"
    },
    {
      "x": -13,
      "y": 7,
      "z": 0,
      "name": "Nat20_Force_Empty"
    },
    {
      "x": -13,
      "y": 8,
      "z": 0,
      "name": "Nat20_Force_Empty"
    },
    {
      "x": -13,
      "y": 9,
      "z": 0,
      "name": "Nat20_Force_Empty"
    },
    {
      "x": -13,
      "y": 10,
      "z": 0,
      "name": "Nat20_Force_Empty"
    },
    {
      "x": -13,
      "y": 11,
      "z": 0,
      "name": "Nat20_Force_Empty"
    },
    {
      "x": -13,
      "y": 12,
      "z": 0,
      "name": "Nat20_Force_Empty"
    },
    {
      "x": -13,
      "y": 13,
      "z": 0,
      "name": "Nat20_Force_Empty"
    },
    {
      "x": -13,
      "y": 14,
      "z": 0,
      "name": "Nat20_Force_Empty"
    },
    {
      "x": -13,
      "y": 15,
      "z": 0,
      "name": "Nat20_Force_Empty"
    },
    {
      "x": -13,
      "y": 16,
      "z": 0,
      "name": "Nat20_Force_Empty"
    },
    {
      "x": -13,
      "y": 17,
      "z": 0,
      "name": "Nat20_Force_Empty"
    },
    {
      "x": -13,
      "y": 18,
      "z": 0,
      "name": "Nat20_Force_Empty"
    },
    {
      "x": -13,
      "y": 19,
      "z": 0,
      "name": "Nat20_Force_Empty"
    },
    {
      "x": -13,
      "y": 20,
      "z": 0,
      "name": "Nat20_Force_Empty"
    },
    {
      "x": -13,
      "y": 21,
      "z": 0,
      "name": "Nat20_Force_Empty"
    },
    {
      "x": -13,
      "y": 22,
      "z": 0,
      "name": "Nat20_Force_Empty"
    },
    {
      "x": -13,
      "y": 23,
      "z": 0,
      "name": "Nat20_Force_Empty"
    },
    {
      "x": -13,
      "y": 0,
      "z": 1,
      "name": "Nat20_Force_Empty"
    },
    {
      "x": -13,
      "y": 1,
      "z": 1,
      "name": "Nat20_Force_Empty"
    },
    {
      "x": -13,
      "y": 2,
      "z": 1,
      "name": "Nat20_Force_Empty"
    },
    {
      "x": -13,
      "y": 3,
      "z": 1,
      "name": "Nat20_Force_Empty"
    },
    {
      "x": -13,
      "y": 4,
      "z": 1,
      "name": "Wood_Torch_Wall",
      "rotation": 3
    },
    {
      "x": -13,
      "y": 5,
      "z": 1,
      "name": "Nat20_Force_Empty"
    },
    {
      "x": -13,
      "y": 6,
      "z": 1,
      "name": "Nat20_Force_Empty"
    },
    {
      "x": -13,
      "y": 7,
      "z": 1,
      "name": "Nat20_Force_Empty"
    },
    {
      "x": -13,
      "y": 8,
      "z": 1,
      "name": "Nat20_Force_Empty"
    },
    {
      "x": -13,
      "y": 9,
      "z": 1,
      "name": "Nat20_Force_Empty"
    },
    {
      "x": -13,
      "y": 10,
      "z": 1,
      "name": "Nat20_Force_Empty"
    },
    {
      "x": -13,
      "y": 11,
      "z": 1,
      "name": "Nat20_Force_Empty"
    },
    {
      "x": -13,
      "y": 12,
      "z": 1,
      "name": "Nat20_Force_Empty"
    },
    {
      "x": -13,
      "y": 13,
      "z": 1,
      "name": "Nat20_Force_Empty"
    },
    {
      "x": -13,
      "y": 14,
      "z": 1,
      "name": "Nat20_Force_Empty"
    },
    {
      "x": -13,
      "y": 15,
      "z": 1,
      "name": "Nat20_Force_Empty"
    },
    {
      "x": -13,
      "y": 16,
      "z": 1,
      "name": "Nat20_Force_Empty"
    },
    {
      "x": -13,
      "y": 17,
      "z": 1,
      "name": "Nat20_Force_Empty"
    },
    {
      "x": -13,
      "y": 18,
      "z": 1,
      "name": "Nat20_Force_Empty"
    },
    {
      "x": -13,
      "y": 19,
      "z": 1,
      "name": "Nat20_Force_Empty"
    },
    {
      "x": -13,
      "y": 20,
      "z": 1,
      "name": "Nat20_Force_Empty"
    },
    {
      "x": -13,
      "y": 21,
      "z": 1,
      "name": "Nat20_Force_Empty"
    },
    {
      "x": -13,
      "y": 22,
      "z": 1,
      "name": "Nat20_Force_Empty"
    },
    {
      "x": -13,
      "y": 23,
      "z": 1,
      "name": "Nat20_Force_Empty"
    },
    {
      "x": -13,
      "y": 0,
      "z": 2,
      "name": "Nat20_Force_Empty"
    },
    {
      "x": -13,
      "y": 1,
      "z": 2,
      "name": "Nat20_Force_Empty"
    },
    {
      "x": -13,
      "y": 2,
      "z": 2,
      "name": "Nat20_Force_Empty"
    },
    {
      "x": -13,
      "y": 3,
      "z": 2,
      "name": "Nat20_Force_Empty"
    },
    {
      "x": -13,
      "y": 4,
      "z": 2,
      "name": "Nat20_Force_Empty"
    },
    {
      "x": -13,
      "y": 5,
      "z": 2,
      "name": "Nat20_Force_Empty"
    },
    {
      "x": -13,
      "y": 6,
      "z": 2,
      "name": "Nat20_Force_Empty"
    },
    {
      "x": -13,
      "y": 7,
      "z": 2,
      "name": "Nat20_Force_Empty"
    },
    {
      "x": -13,
      "y": 8,
      "z": 2,
      "name": "Nat20_Force_Empty"
    },
    {
      "x": -13,
      "y": 9,
      "z": 2,
      "name": "Nat20_Force_Empty"
    },
    {
      "x": -13,
      "y": 10,
      "z": 2,
      "name": "Nat20_Force_Empty"
    },
    {
      "x": -13,
      "y": 11,
      "z": 2,
      "name": "Nat20_Force_Empty"
    },
    {
      "x": -13,
      "y": 12,
      "z": 2,
      "name": "Nat20_Force_Empty"
    },
    {
      "x": -13,
      "y": 13,
      "z": 2,
      "name": "Nat20_Force_Empty"
    },
    {
      "x": -13,
      "y": 14,
      "z": 2,
      "name": "Nat20_Force_Empty"
    },
    {
      "x": -13,
      "y": 15,
      "z": 2,
      "name": "Nat20_Force_Empty"
    },
    {
      "x": -13,
      "y": 16,
      "z": 2,
      "name": "Nat20_Force_Empty"
    },
    {
      "x": -13,
      "y": 0,
      "z": 3,
      "name": "Nat20_Force_Empty"
    },
    {
      "x": -13,
      "y": 1,
      "z": 3,
      "name": "Nat20_Force_Empty"
    },
    {
      "x": -13,
      "y": 2,
      "z": 3,
      "name": "Nat20_Force_Empty"
    },
    {
      "x": -13,
      "y": 3,
      "z": 3,
      "name": "Nat20_Force_Empty"
    },
    {
      "x": -13,
      "y": 4,
      "z": 3,
      "name": "Nat20_Force_Empty"
    },
    {
      "x": -13,
      "y": 5,
      "z": 3,
      "name": "Nat20_Force_Empty"
    },
    {
      "x": -13,
      "y": 6,
      "z": 3,
      "name": "Nat20_Force_Empty"
    },
    {
      "x": -13,
      "y": 7,
      "z": 3,
      "name": "Nat20_Force_Empty"
    },
    {
      "x": -13,
      "y": 8,
      "z": 3,
      "name": "Nat20_Force_Empty"
    },
    {
      "x": -13,
      "y": 9,
      "z": 3,
      "name": "Nat20_Force_Empty"
    },
    {
      "x": -13,
      "y": 10,
      "z": 3,
      "name": "Nat20_Force_Empty"
    },
    {
      "x": -13,
      "y": 11,
      "z": 3,
      "name": "Nat20_Force_Empty"
    },
    {
      "x": -13,
      "y": 12,
      "z": 3,
      "name": "Nat20_Force_Empty"
    },
    {
      "x": -13,
      "y": 13,
      "z": 3,
      "name": "Nat20_Force_Empty"
    },
    {
      "x": -13,
      "y": 14,
      "z": 3,
      "name": "Nat20_Force_Empty"
    },
    {
      "x": -13,
      "y": 15,
      "z": 3,
      "name": "Nat20_Force_Empty"
    },
    {
      "x": -13,
      "y": 16,
      "z": 3,
      "name": "Nat20_Force_Empty"
    },
    {
      "x": -13,
      "y": 0,
      "z": 4,
      "name": "Nat20_Force_Empty"
    },
    {
      "x": -13,
      "y": 1,
      "z": 4,
      "name": "Nat20_Force_Empty"
    },
    {
      "x": -13,
      "y": 2,
      "z": 4,
      "name": "Nat20_Force_Empty"
    },
    {
      "x": -13,
      "y": 3,
      "z": 4,
      "name": "Nat20_Force_Empty"
    },
    {
      "x": -13,
      "y": 4,
      "z": 4,
      "name": "Nat20_Force_Empty"
    },
    {
      "x": -13,
      "y": 5,
      "z": 4,
      "name": "Nat20_Force_Empty"
    },
    {
      "x": -13,
      "y": 6,
      "z": 4,
      "name": "Nat20_Force_Empty"
    },
    {
      "x": -13,
      "y": 7,
      "z": 4,
      "name": "Nat20_Force_Empty"
    },
    {
      "x": -13,
      "y": 8,
      "z": 4,
      "name": "Nat20_Force_Empty"
    },
    {
      "x": -13,
      "y": 9,
      "z": 4,
      "name": "Nat20_Force_Empty"
    },
    {
      "x": -13,
      "y": 10,
      "z": 4,
      "name": "Nat20_Force_Empty"
    },
    {
      "x": -13,
      "y": 11,
      "z": 4,
      "name": "Nat20_Force_Empty"
    },
    {
      "x": -13,
      "y": 12,
      "z": 4,
      "name": "Nat20_Force_Empty"
    },
    {
      "x": -13,
      "y": 13,
      "z": 4,
      "name": "Nat20_Force_Empty"
    },
    {
      "x": -13,
      "y": 14,
      "z": 4,
      "name": "Nat20_Force_Empty"
    },
    {
      "x": -13,
      "y": 15,
      "z": 4,
      "name": "Nat20_Force_Empty"
    },
    {
      "x": -13,
      "y": 16,
      "z": 4,
      "name": "Nat20_Force_Empty"
    },
    {
      "x": -13,
      "y": 0,
      "z": 5,
      "name": "Nat20_Force_Empty"
    },
    {
      "x": -13,
      "y": 1,
      "z": 5,
      "name": "Nat20_Force_Empty"
    },
    {
      "x": -13,
      "y": 2,
      "z": 5,
      "name": "Nat20_Force_Empty"
    },
    {
      "x": -13,
      "y": 3,
      "z": 5,
      "name": "Nat20_Force_Empty"
    },
    {
      "x": -13,
      "y": 4,
      "z": 5,
      "name": "Nat20_Force_Empty"
    },
    {
      "x": -13,
      "y": 5,
      "z": 5,
      "name": "Nat20_Force_Empty"
    },
    {
      "x": -13,
      "y": 6,
      "z": 5,
      "name": "Nat20_Force_Empty"
    },
    {
      "x": -13,
      "y": 7,
      "z": 5,
      "name": "Nat20_Force_Empty"
    },
    {
      "x": -13,
      "y": 8,
      "z": 5,
      "name": "Nat20_Force_Empty"
    },
    {
      "x": -13,
      "y": 9,
      "z": 5,
      "name": "Nat20_Force_Empty"
    },
    {
      "x": -13,
      "y": 10,
      "z": 5,
      "name": "Nat20_Force_Empty"
    },
    {
      "x": -13,
      "y": 11,
      "z": 5,
      "name": "Nat20_Force_Empty"
    },
    {
      "x": -13,
      "y": 12,
      "z": 5,
      "name": "Nat20_Force_Empty"
    },
    {
      "x": -13,
      "y": 13,
      "z": 5,
      "name": "Nat20_Force_Empty"
    },
    {
      "x": -13,
      "y": 14,
      "z": 5,
      "name": "Nat20_Force_Empty"
    },
    {
      "x": -13,
      "y": 15,
      "z": 5,
      "name": "Nat20_Force_Empty"
    },
    {
      "x": -13,
      "y": 16,
      "z": 5,
      "name": "Nat20_Force_Empty"
    },
    {
      "x": -13,
      "y": 0,
      "z": 6,
      "name": "Nat20_Force_Empty"
    },
    {
      "x": -13,
      "y": 1,
      "z": 6,
      "name": "Nat20_Force_Empty"
    },
    {
      "x": -13,
      "y": 2,
      "z": 6,
      "name": "Nat20_Force_Empty"
    },
    {
      "x": -13,
      "y": 3,
      "z": 6,
      "name": "Nat20_Force_Empty"
    },
    {
      "x": -13,
      "y": 4,
      "z": 6,
      "name": "Nat20_Force_Empty"
    },
    {
      "x": -13,
      "y": 5,
      "z": 6,
      "name": "Nat20_Force_Empty"
    },
    {
      "x": -13,
      "y": 6,
      "z": 6,
      "name": "Nat20_Force_Empty"
    },
    {
      "x": -13,
      "y": 7,
      "z": 6,
      "name": "Nat20_Force_Empty"
    },
    {
      "x": -13,
      "y": 8,
      "z": 6,
      "name": "Nat20_Force_Empty"
    },
    {
      "x": -13,
      "y": 9,
      "z": 6,
      "name": "Nat20_Force_Empty"
    },
    {
      "x": -13,
      "y": 10,
      "z": 6,
      "name": "Nat20_Force_Empty"
    },
    {
      "x": -13,
      "y": 11,
      "z": 6,
      "name": "Nat20_Force_Empty"
    },
    {
      "x": -13,
      "y": 12,
      "z": 6,
      "name": "Nat20_Force_Empty"
    },
    {
      "x": -13,
      "y": 13,
      "z": 6,
      "name": "Nat20_Force_Empty"
    },
    {
      "x": -13,
      "y": 14,
      "z": 6,
      "name": "Nat20_Force_Empty"
    },
    {
      "x": -13,
      "y": 15,
      "z": 6,
      "name": "Nat20_Force_Empty"
    },
    {
      "x": -13,
      "y": 16,
      "z": 6,
      "name": "Nat20_Force_Empty"
    },
    {
      "x": -13,
      "y": 0,
      "z": 7,
      "name": "Nat20_Force_Empty"
    },
    {
      "x": -13,
      "y": 1,
      "z": 7,
      "name": "Nat20_Force_Empty"
    },
    {
      "x": -13,
      "y": 2,
      "z": 7,
      "name": "Nat20_Force_Empty"
    },
    {
      "x": -13,
      "y": 3,
      "z": 7,
      "name": "Nat20_Force_Empty"
    },
    {
      "x": -13,
      "y": 4,
      "z": 7,
      "name": "Nat20_Force_Empty"
    },
    {
      "x": -13,
      "y": 5,
      "z": 7,
      "name": "Nat20_Force_Empty"
    },
    {
      "x": -13,
      "y": 6,
      "z": 7,
      "name": "Nat20_Force_Empty"
    },
    {
      "x": -13,
      "y": 7,
      "z": 7,
      "name": "Nat20_Force_Empty"
    },
    {
      "x": -13,
      "y": 8,
      "z": 7,
      "name": "Nat20_Force_Empty"
    },
    {
      "x": -13,
      "y": 9,
      "z": 7,
      "name": "Nat20_Force_Empty"
    },
    {
      "x": -13,
      "y": 10,
      "z": 7,
      "name": "Nat20_Force_Empty"
    },
    {
      "x": -13,
      "y": 11,
      "z": 7,
      "name": "Nat20_Force_Empty"
    },
    {
      "x": -13,
      "y": 12,
      "z": 7,
      "name": "Nat20_Force_Empty"
    },
    {
      "x": -13,
      "y": 13,
      "z": 7,
      "name": "Nat20_Force_Empty"
    },
    {
      "x": -13,
      "y": 14,
      "z": 7,
      "name": "Nat20_Force_Empty"
    },
    {
      "x": -13,
      "y": 15,
      "z": 7,
      "name": "Nat20_Force_Empty"
    },
    {
      "x": -13,
      "y": 16,
      "z": 7,
      "name": "Nat20_Force_Empty"
    },
    {
      "x": -13,
      "y": 0,
      "z": 8,
      "name": "Nat20_Force_Empty"
    },
    {
      "x": -13,
      "y": 1,
      "z": 8,
      "name": "Nat20_Force_Empty"
    },
    {
      "x": -13,
      "y": 2,
      "z": 8,
      "name": "Nat20_Force_Empty"
    },
    {
      "x": -13,
      "y": 3,
      "z": 8,
      "name": "Nat20_Force_Empty"
    },
    {
      "x": -13,
      "y": 4,
      "z": 8,
      "name": "Nat20_Force_Empty"
    },
    {
      "x": -13,
      "y": 5,
      "z": 8,
      "name": "Nat20_Force_Empty"
    },
    {
      "x": -13,
      "y": 6,
      "z": 8,
      "name": "Nat20_Force_Empty"
    },
    {
      "x": -13,
      "y": 7,
      "z": 8,
      "name": "Nat20_Force_Empty"
    },
    {
      "x": -13,
      "y": 8,
      "z": 8,
      "name": "Nat20_Force_Empty"
    },
    {
      "x": -13,
      "y": 9,
      "z": 8,
      "name": "Nat20_Force_Empty"
    },
    {
      "x": -13,
      "y": 10,
      "z": 8,
      "name": "Nat20_Force_Empty"
    },
    {
      "x": -13,
      "y": 11,
      "z": 8,
      "name": "Nat20_Force_Empty"
    },
    {
      "x": -13,
      "y": 12,
      "z": 8,
      "name": "Nat20_Force_Empty"
    },
    {
      "x": -13,
      "y": 13,
      "z": 8,
      "name": "Nat20_Force_Empty"
    },
    {
      "x": -13,
      "y": 14,
      "z": 8,
      "name": "Nat20_Force_Empty"
    },
    {
      "x": -13,
      "y": 15,
      "z": 8,
      "name": "Nat20_Force_Empty"
    },
    {
      "x": -13,
      "y": 16,
      "z": 8,
      "name": "Nat20_Force_Empty"
    },
    {
      "x": -13,
      "y": 0,
      "z": 9,
      "name": "Nat20_Force_Empty"
    },
    {
      "x": -13,
      "y": 1,
      "z": 9,
      "name": "Nat20_Force_Empty"
    },
    {
      "x": -13,
      "y": 2,
      "z": 9,
      "name": "Nat20_Force_Empty"
    },
    {
      "x": -13,
      "y": 3,
      "z": 9,
      "name": "Nat20_Force_Empty"
    },
    {
      "x": -13,
      "y": 4,
      "z": 9,
      "name": "Nat20_Force_Empty"
    },
    {
      "x": -13,
      "y": 5,
      "z": 9,
      "name": "Nat20_Force_Empty"
    },
    {
      "x": -13,
      "y": 6,
      "z": 9,
      "name": "Nat20_Force_Empty"
    },
    {
      "x": -13,
      "y": 7,
      "z": 9,
      "name": "Nat20_Force_Empty"
    },
    {
      "x": -13,
      "y": 8,
      "z": 9,
      "name": "Nat20_Force_Empty"
    },
    {
      "x": -13,
      "y": 9,
      "z": 9,
      "name": "Nat20_Force_Empty"
    },
    {
      "x": -13,
      "y": 10,
      "z": 9,
      "name": "Nat20_Force_Empty"
    },
    {
      "x": -13,
      "y": 11,
      "z": 9,
      "name": "Nat20_Force_Empty"
    },
    {
      "x": -13,
      "y": 12,
      "z": 9,
      "name": "Nat20_Force_Empty"
    },
    {
      "x": -13,
      "y": 13,
      "z": 9,
      "name": "Nat20_Force_Empty"
    },
    {
      "x": -13,
      "y": 14,
      "z": 9,
      "name": "Nat20_Force_Empty"
    },
    {
      "x": -13,
      "y": 15,
      "z": 9,
      "name": "Nat20_Force_Empty"
    },
    {
      "x": -13,
      "y": 16,
      "z": 9,
      "name": "Nat20_Force_Empty"
    },
    {
      "x": -12,
      "y": 0,
      "z": -9,
      "name": "Nat20_Force_Empty"
    },
    {
      "x": -12,
      "y": 1,
      "z": -9,
      "name": "Nat20_Force_Empty"
    },
    {
      "x": -12,
      "y": 2,
      "z": -9,
      "name": "Nat20_Force_Empty"
    },
    {
      "x": -12,
      "y": 3,
      "z": -9,
      "name": "Nat20_Force_Empty"
    },
    {
      "x": -12,
      "y": 4,
      "z": -9,
      "name": "Nat20_Force_Empty"
    },
    {
      "x": -12,
      "y": 5,
      "z": -9,
      "name": "Nat20_Force_Empty"
    },
    {
      "x": -12,
      "y": 6,
      "z": -9,
      "name": "Nat20_Force_Empty"
    },
    {
      "x": -12,
      "y": 7,
      "z": -9,
      "name": "Nat20_Force_Empty"
    },
    {
      "x": -12,
      "y": 8,
      "z": -9,
      "name": "Nat20_Force_Empty"
    },
    {
      "x": -12,
      "y": 9,
      "z": -9,
      "name": "Nat20_Force_Empty"
    },
    {
      "x": -12,
      "y": 10,
      "z": -9,
      "name": "Nat20_Force_Empty"
    },
    {
      "x": -12,
      "y": 11,
      "z": -9,
      "name": "Nat20_Force_Empty"
    },
    {
      "x": -12,
      "y": 12,
      "z": -9,
      "name": "Nat20_Force_Empty"
    },
    {
      "x": -12,
      "y": 13,
      "z": -9,
      "name": "Nat20_Force_Empty"
    },
    {
      "x": -12,
      "y": 14,
      "z": -9,
      "name": "Nat20_Force_Empty"
    },
    {
      "x": -12,
      "y": 15,
      "z": -9,
      "name": "Nat20_Force_Empty"
    },
    {
      "x": -12,
      "y": 16,
      "z": -9,
      "name": "Nat20_Force_Empty"
    },
    {
      "x": -12,
      "y": 17,
      "z": -9,
      "name": "Nat20_Force_Empty"
    },
    {
      "x": -12,
      "y": 18,
      "z": -9,
      "name": "Nat20_Force_Empty"
    },
    {
      "x": -12,
      "y": 19,
      "z": -9,
      "name": "Nat20_Force_Empty"
    },
    {
      "x": -12,
      "y": 20,
      "z": -9,
      "name": "Nat20_Force_Empty"
    },
    {
      "x": -12,
      "y": 21,
      "z": -9,
      "name": "Nat20_Force_Empty"
    },
    {
      "x": -12,
      "y": 22,
      "z": -9,
      "name": "Nat20_Force_Empty"
    },
    {
      "x": -12,
      "y": 23,
      "z": -9,
      "name": "Nat20_Force_Empty"
    },
    {
      "x": -12,
      "y": 0,
      "z": -8,
      "name": "Nat20_Force_Empty"
    },
    {
      "x": -12,
      "y": 1,
      "z": -8,
      "name": "Nat20_Force_Empty"
    },
    {
      "x": -12,
      "y": 2,
      "z": -8,
      "name": "Nat20_Force_Empty"
    },
    {
      "x": -12,
      "y": 3,
      "z": -8,
      "name": "Nat20_Force_Empty"
    },
    {
      "x": -12,
      "y": 4,
      "z": -8,
      "name": "Nat20_Force_Empty"
    },
    {
      "x": -12,
      "y": 5,
      "z": -8,
      "name": "Nat20_Force_Empty"
    },
    {
      "x": -12,
      "y": 6,
      "z": -8,
      "name": "Nat20_Force_Empty"
    },
    {
      "x": -12,
      "y": 7,
      "z": -8,
      "name": "Nat20_Force_Empty"
    },
    {
      "x": -12,
      "y": 8,
      "z": -8,
      "name": "Nat20_Force_Empty"
    },
    {
      "x": -12,
      "y": 9,
      "z": -8,
      "name": "Nat20_Force_Empty"
    },
    {
      "x": -12,
      "y": 10,
      "z": -8,
      "name": "Nat20_Force_Empty"
    },
    {
      "x": -12,
      "y": 11,
      "z": -8,
      "name": "Nat20_Force_Empty"
    },
    {
      "x": -12,
      "y": 12,
      "z": -8,
      "name": "Nat20_Force_Empty"
    },
    {
      "x": -12,
      "y": 13,
      "z": -8,
      "name": "Nat20_Force_Empty"
    },
    {
      "x": -12,
      "y": 14,
      "z": -8,
      "name": "Nat20_Force_Empty"
    },
    {
      "x": -12,
      "y": 15,
      "z": -8,
      "name": "Nat20_Force_Empty"
    },
    {
      "x": -12,
      "y": 16,
      "z": -8,
      "name": "Nat20_Force_Empty"
    },
    {
      "x": -12,
      "y": 17,
      "z": -8,
      "name": "Nat20_Force_Empty"
    },
    {
      "x": -12,
      "y": 18,
      "z": -8,
      "name": "Nat20_Force_Empty"
    },
    {
      "x": -12,
      "y": 19,
      "z": -8,
      "name": "Nat20_Force_Empty"
    },
    {
      "x": -12,
      "y": 20,
      "z": -8,
      "name": "Nat20_Force_Empty"
    },
    {
      "x": -12,
      "y": 21,
      "z": -8,
      "name": "Nat20_Force_Empty"
    },
    {
      "x": -12,
      "y": 22,
      "z": -8,
      "name": "Nat20_Force_Empty"
    },
    {
      "x": -12,
      "y": 23,
      "z": -8,
      "name": "Nat20_Force_Empty"
    },
    {
      "x": -12,
      "y": 0,
      "z": -7,
      "name": "Nat20_Force_Empty"
    },
    {
      "x": -12,
      "y": 1,
      "z": -7,
      "name": "Nat20_Force_Empty"
    },
    {
      "x": -12,
      "y": 2,
      "z": -7,
      "name": "Nat20_Force_Empty"
    },
    {
      "x": -12,
      "y": 3,
      "z": -7,
      "name": "Nat20_Force_Empty"
    },
    {
      "x": -12,
      "y": 4,
      "z": -7,
      "name": "Nat20_Force_Empty"
    },
    {
      "x": -12,
      "y": 5,
      "z": -7,
      "name": "Nat20_Force_Empty"
    },
    {
      "x": -12,
      "y": 6,
      "z": -7,
      "name": "Nat20_Force_Empty"
    },
    {
      "x": -12,
      "y": 7,
      "z": -7,
      "name": "Nat20_Force_Empty"
    },
    {
      "x": -12,
      "y": 8,
      "z": -7,
      "name": "Nat20_Force_Empty"
    },
    {
      "x": -12,
      "y": 9,
      "z": -7,
      "name": "Nat20_Force_Empty"
    },
    {
      "x": -12,
      "y": 10,
      "z": -7,
      "name": "Nat20_Force_Empty"
    },
    {
      "x": -12,
      "y": 11,
      "z": -7,
      "name": "Nat20_Force_Empty"
    },
    {
      "x": -12,
      "y": 12,
      "z": -7,
      "name": "Nat20_Force_Empty"
    },
    {
      "x": -12,
      "y": 13,
      "z": -7,
      "name": "Nat20_Force_Empty"
    },
    {
      "x": -12,
      "y": 14,
      "z": -7,
      "name": "Nat20_Force_Empty"
    },
    {
      "x": -12,
      "y": 15,
      "z": -7,
      "name": "Nat20_Force_Empty"
    },
    {
      "x": -12,
      "y": 16,
      "z": -7,
      "name": "Nat20_Force_Empty"
    },
    {
      "x": -12,
      "y": 17,
      "z": -7,
      "name": "Nat20_Force_Empty"
    },
    {
      "x": -12,
      "y": 18,
      "z": -7,
      "name": "Nat20_Force_Empty"
    },
    {
      "x": -12,
      "y": 19,
      "z": -7,
      "name": "Nat20_Force_Empty"
    },
    {
      "x": -12,
      "y": 20,
      "z": -7,
      "name": "Nat20_Force_Empty"
    },
    {
      "x": -12,
      "y": 21,
      "z": -7,
      "name": "Nat20_Force_Empty"
    },
    {
      "x": -12,
      "y": 22,
      "z": -7,
      "name": "Nat20_Force_Empty"
    },
    {
      "x": -12,
      "y": 23,
      "z": -7,
      "name": "Nat20_Force_Empty"
    },
    {
      "x": -12,
      "y": 0,
      "z": -6,
      "name": "Nat20_Force_Empty"
    },
    {
      "x": -12,
      "y": 1,
      "z": -6,
      "name": "Nat20_Force_Empty"
    },
    {
      "x": -12,
      "y": 2,
      "z": -6,
      "name": "Nat20_Force_Empty"
    },
    {
      "x": -12,
      "y": 3,
      "z": -6,
      "name": "Nat20_Force_Empty"
    },
    {
      "x": -12,
      "y": 4,
      "z": -6,
      "name": "Nat20_Force_Empty"
    },
    {
      "x": -12,
      "y": 5,
      "z": -6,
      "name": "Nat20_Force_Empty"
    },
    {
      "x": -12,
      "y": 6,
      "z": -6,
      "name": "Wood_Drywood_Planks_Half",
      "rotation": 7
    },
    {
      "x": -12,
      "y": 7,
      "z": -6,
      "name": "Nat20_Force_Empty"
    },
    {
      "x": -12,
      "y": 8,
      "z": -6,
      "name": "Nat20_Force_Empty"
    },
    {
      "x": -12,
      "y": 9,
      "z": -6,
      "name": "Nat20_Force_Empty"
    },
    {
      "x": -12,
      "y": 10,
      "z": -6,
      "name": "Nat20_Force_Empty"
    },
    {
      "x": -12,
      "y": 11,
      "z": -6,
      "name": "Nat20_Force_Empty"
    },
    {
      "x": -12,
      "y": 12,
      "z": -6,
      "name": "Nat20_Force_Empty"
    },
    {
      "x": -12,
      "y": 13,
      "z": -6,
      "name": "Nat20_Force_Empty"
    },
    {
      "x": -12,
      "y": 14,
      "z": -6,
      "name": "Nat20_Force_Empty"
    },
    {
      "x": -12,
      "y": 15,
      "z": -6,
      "name": "Nat20_Force_Empty"
    },
    {
      "x": -12,
      "y": 16,
      "z": -6,
      "name": "Nat20_Force_Empty"
    },
    {
      "x": -12,
      "y": 17,
      "z": -6,
      "name": "Nat20_Force_Empty"
    },
    {
      "x": -12,
      "y": 18,
      "z": -6,
      "name": "Nat20_Force_Empty"
    },
    {
      "x": -12,
      "y": 19,
      "z": -6,
      "name": "Nat20_Force_Empty"
    },
    {
      "x": -12,
      "y": 20,
      "z": -6,
      "name": "Nat20_Force_Empty"
    },
    {
      "x": -12,
      "y": 21,
      "z": -6,
      "name": "Nat20_Force_Empty"
    },
    {
      "x": -12,
      "y": 22,
      "z": -6,
      "name": "Nat20_Force_Empty"
    },
    {
      "x": -12,
      "y": 23,
      "z": -6,
      "name": "Nat20_Force_Empty"
    },
    {
      "x": -12,
      "y": 0,
      "z": -5,
      "name": "Rock_Sandstone_White_Cobble"
    },
    {
      "x": -12,
      "y": 1,
      "z": -5,
      "name": "Rock_Sandstone_White_Cobble"
    },
    {
      "x": -12,
      "y": 2,
      "z": -5,
      "name": "Wood_Dry_Trunk",
      "rotation": 4
    },
    {
      "x": -12,
      "y": 3,
      "z": -5,
      "name": "Nat20_Force_Empty"
    },
    {
      "x": -12,
      "y": 4,
      "z": -5,
      "name": "Nat20_Force_Empty"
    },
    {
      "x": -12,
      "y": 5,
      "z": -5,
      "name": "Nat20_Force_Empty"
    },
    {
      "x": -12,
      "y": 6,
      "z": -5,
      "name": "Wood_Drywood_Planks_Half",
      "rotation": 7
    },
    {
      "x": -12,
      "y": 7,
      "z": -5,
      "name": "Nat20_Force_Empty"
    },
    {
      "x": -12,
      "y": 8,
      "z": -5,
      "name": "Nat20_Force_Empty"
    },
    {
      "x": -12,
      "y": 9,
      "z": -5,
      "name": "Nat20_Force_Empty"
    },
    {
      "x": -12,
      "y": 10,
      "z": -5,
      "name": "Nat20_Force_Empty"
    },
    {
      "x": -12,
      "y": 11,
      "z": -5,
      "name": "Nat20_Force_Empty"
    },
    {
      "x": -12,
      "y": 12,
      "z": -5,
      "name": "Nat20_Force_Empty"
    },
    {
      "x": -12,
      "y": 13,
      "z": -5,
      "name": "Nat20_Force_Empty"
    },
    {
      "x": -12,
      "y": 14,
      "z": -5,
      "name": "Nat20_Force_Empty"
    },
    {
      "x": -12,
      "y": 15,
      "z": -5,
      "name": "Nat20_Force_Empty"
    },
    {
      "x": -12,
      "y": 16,
      "z": -5,
      "name": "Nat20_Force_Empty"
    },
    {
      "x": -12,
      "y": 17,
      "z": -5,
      "name": "Nat20_Force_Empty"
    },
    {
      "x": -12,
      "y": 18,
      "z": -5,
      "name": "Nat20_Force_Empty"
    },
    {
      "x": -12,
      "y": 19,
      "z": -5,
      "name": "Nat20_Force_Empty"
    },
    {
      "x": -12,
      "y": 20,
      "z": -5,
      "name": "Nat20_Force_Empty"
    },
    {
      "x": -12,
      "y": 21,
      "z": -5,
      "name": "Nat20_Force_Empty"
    },
    {
      "x": -12,
      "y": 22,
      "z": -5,
      "name": "Nat20_Force_Empty"
    },
    {
      "x": -12,
      "y": 23,
      "z": -5,
      "name": "Nat20_Force_Empty"
    },
    {
      "x": -12,
      "y": 0,
      "z": -4,
      "name": "Rock_Sandstone_White_Cobble"
    },
    {
      "x": -12,
      "y": 1,
      "z": -4,
      "name": "Rock_Sandstone_White_Cobble"
    },
    {
      "x": -12,
      "y": 2,
      "z": -4,
      "name": "Wood_Dry_Trunk",
      "rotation": 4
    },
    {
      "x": -12,
      "y": 3,
      "z": -4,
      "name": "Wood_Dry_Trunk"
    },
    {
      "x": -12,
      "y": 4,
      "z": -4,
      "name": "Wood_Dry_Trunk"
    },
    {
      "x": -12,
      "y": 5,
      "z": -4,
      "name": "Wood_Dry_Trunk"
    },
    {
      "x": -12,
      "y": 6,
      "z": -4,
      "name": "Wood_Dry_Trunk_Full",
      "rotation": 4
    },
    {
      "x": -12,
      "y": 7,
      "z": -4,
      "name": "Wood_Dry_Branch_Long"
    },
    {
      "x": -12,
      "y": 8,
      "z": -4,
      "name": "Wood_Dry_Branch_Long"
    },
    {
      "x": -12,
      "y": 9,
      "z": -4,
      "name": "Wood_Dry_Branch_Long"
    },
    {
      "x": -12,
      "y": 10,
      "z": -4,
      "name": "Wood_Dry_Trunk_Full",
      "rotation": 4
    },
    {
      "x": -12,
      "y": 11,
      "z": -4,
      "name": "Nat20_Force_Empty"
    },
    {
      "x": -12,
      "y": 12,
      "z": -4,
      "name": "Nat20_Force_Empty"
    },
    {
      "x": -12,
      "y": 13,
      "z": -4,
      "name": "Nat20_Force_Empty"
    },
    {
      "x": -12,
      "y": 14,
      "z": -4,
      "name": "Nat20_Force_Empty"
    },
    {
      "x": -12,
      "y": 15,
      "z": -4,
      "name": "Nat20_Force_Empty"
    },
    {
      "x": -12,
      "y": 16,
      "z": -4,
      "name": "Nat20_Force_Empty"
    },
    {
      "x": -12,
      "y": 17,
      "z": -4,
      "name": "Nat20_Force_Empty"
    },
    {
      "x": -12,
      "y": 18,
      "z": -4,
      "name": "Nat20_Force_Empty"
    },
    {
      "x": -12,
      "y": 19,
      "z": -4,
      "name": "Nat20_Force_Empty"
    },
    {
      "x": -12,
      "y": 20,
      "z": -4,
      "name": "Nat20_Force_Empty"
    },
    {
      "x": -12,
      "y": 21,
      "z": -4,
      "name": "Nat20_Force_Empty"
    },
    {
      "x": -12,
      "y": 22,
      "z": -4,
      "name": "Nat20_Force_Empty"
    },
    {
      "x": -12,
      "y": 23,
      "z": -4,
      "name": "Nat20_Force_Empty"
    },
    {
      "x": -12,
      "y": 0,
      "z": -3,
      "name": "Rock_Sandstone_White_Cobble"
    },
    {
      "x": -12,
      "y": 1,
      "z": -3,
      "name": "Rock_Sandstone_White_Cobble"
    },
    {
      "x": -12,
      "y": 2,
      "z": -3,
      "name": "Wood_Dry_Trunk",
      "rotation": 4
    },
    {
      "x": -12,
      "y": 3,
      "z": -3,
      "name": "Nat20_Force_Empty"
    },
    {
      "x": -12,
      "y": 4,
      "z": -3,
      "name": "Nat20_Force_Empty"
    },
    {
      "x": -12,
      "y": 5,
      "z": -3,
      "name": "Nat20_Force_Empty"
    },
    {
      "x": -12,
      "y": 6,
      "z": -3,
      "name": "Wood_Dry_Trunk",
      "rotation": 4
    },
    {
      "x": -12,
      "y": 7,
      "z": -3,
      "name": "Nat20_Force_Empty"
    },
    {
      "x": -12,
      "y": 8,
      "z": -3,
      "name": "Nat20_Force_Empty"
    },
    {
      "x": -12,
      "y": 9,
      "z": -3,
      "name": "Nat20_Force_Empty"
    },
    {
      "x": -12,
      "y": 10,
      "z": -3,
      "name": "Wood_Dry_Trunk",
      "rotation": 4
    },
    {
      "x": -12,
      "y": 11,
      "z": -3,
      "name": "Nat20_Force_Empty"
    },
    {
      "x": -12,
      "y": 12,
      "z": -3,
      "name": "Nat20_Force_Empty"
    },
    {
      "x": -12,
      "y": 13,
      "z": -3,
      "name": "Nat20_Force_Empty"
    },
    {
      "x": -12,
      "y": 14,
      "z": -3,
      "name": "Nat20_Force_Empty"
    },
    {
      "x": -12,
      "y": 15,
      "z": -3,
      "name": "Nat20_Force_Empty"
    },
    {
      "x": -12,
      "y": 16,
      "z": -3,
      "name": "Nat20_Force_Empty"
    },
    {
      "x": -12,
      "y": 17,
      "z": -3,
      "name": "Nat20_Force_Empty"
    },
    {
      "x": -12,
      "y": 18,
      "z": -3,
      "name": "Nat20_Force_Empty"
    },
    {
      "x": -12,
      "y": 19,
      "z": -3,
      "name": "Nat20_Force_Empty"
    },
    {
      "x": -12,
      "y": 20,
      "z": -3,
      "name": "Nat20_Force_Empty"
    },
    {
      "x": -12,
      "y": 21,
      "z": -3,
      "name": "Nat20_Force_Empty"
    },
    {
      "x": -12,
      "y": 22,
      "z": -3,
      "name": "Nat20_Force_Empty"
    },
    {
      "x": -12,
      "y": 23,
      "z": -3,
      "name": "Nat20_Force_Empty"
    },
    {
      "x": -12,
      "y": 0,
      "z": -2,
      "name": "Rock_Sandstone_White_Cobble"
    },
    {
      "x": -12,
      "y": 1,
      "z": -2,
      "name": "Rock_Sandstone_White_Cobble"
    },
    {
      "x": -12,
      "y": 2,
      "z": -2,
      "name": "Wood_Dry_Trunk",
      "rotation": 4
    },
    {
      "x": -12,
      "y": 3,
      "z": -2,
      "name": "Nat20_Force_Empty"
    },
    {
      "x": -12,
      "y": 4,
      "z": -2,
      "name": "Nat20_Force_Empty"
    },
    {
      "x": -12,
      "y": 5,
      "z": -2,
      "name": "Nat20_Force_Empty"
    },
    {
      "x": -12,
      "y": 6,
      "z": -2,
      "name": "Wood_Dry_Trunk",
      "rotation": 4
    },
    {
      "x": -12,
      "y": 7,
      "z": -2,
      "name": "Nat20_Force_Empty"
    },
    {
      "x": -12,
      "y": 8,
      "z": -2,
      "name": "Nat20_Force_Empty"
    },
    {
      "x": -12,
      "y": 9,
      "z": -2,
      "name": "Nat20_Force_Empty"
    },
    {
      "x": -12,
      "y": 10,
      "z": -2,
      "name": "Wood_Dry_Trunk",
      "rotation": 4
    },
    {
      "x": -12,
      "y": 11,
      "z": -2,
      "name": "Nat20_Force_Empty"
    },
    {
      "x": -12,
      "y": 12,
      "z": -2,
      "name": "Nat20_Force_Empty"
    },
    {
      "x": -12,
      "y": 13,
      "z": -2,
      "name": "Nat20_Force_Empty"
    },
    {
      "x": -12,
      "y": 14,
      "z": -2,
      "name": "Nat20_Force_Empty"
    },
    {
      "x": -12,
      "y": 15,
      "z": -2,
      "name": "Nat20_Force_Empty"
    },
    {
      "x": -12,
      "y": 16,
      "z": -2,
      "name": "Nat20_Force_Empty"
    },
    {
      "x": -12,
      "y": 17,
      "z": -2,
      "name": "Nat20_Force_Empty"
    },
    {
      "x": -12,
      "y": 18,
      "z": -2,
      "name": "Nat20_Force_Empty"
    },
    {
      "x": -12,
      "y": 19,
      "z": -2,
      "name": "Nat20_Force_Empty"
    },
    {
      "x": -12,
      "y": 20,
      "z": -2,
      "name": "Nat20_Force_Empty"
    },
    {
      "x": -12,
      "y": 21,
      "z": -2,
      "name": "Nat20_Force_Empty"
    },
    {
      "x": -12,
      "y": 22,
      "z": -2,
      "name": "Nat20_Force_Empty"
    },
    {
      "x": -12,
      "y": 23,
      "z": -2,
      "name": "Nat20_Force_Empty"
    },
    {
      "x": -12,
      "y": 0,
      "z": -1,
      "name": "Rock_Sandstone_White_Cobble"
    },
    {
      "x": -12,
      "y": 1,
      "z": -1,
      "name": "Rock_Sandstone_White_Cobble"
    },
    {
      "x": -12,
      "y": 2,
      "z": -1,
      "name": "Wood_Dry_Trunk",
      "rotation": 4
    },
    {
      "x": -12,
      "y": 3,
      "z": -1,
      "name": "Nat20_Force_Empty"
    },
    {
      "x": -12,
      "y": 4,
      "z": -1,
      "name": "Nat20_Force_Empty"
    },
    {
      "x": -12,
      "y": 5,
      "z": -1,
      "name": "Nat20_Force_Empty"
    },
    {
      "x": -12,
      "y": 6,
      "z": -1,
      "name": "Wood_Dry_Trunk",
      "rotation": 4
    },
    {
      "x": -12,
      "y": 7,
      "z": -1,
      "name": "Nat20_Force_Empty"
    },
    {
      "x": -12,
      "y": 8,
      "z": -1,
      "name": "Nat20_Force_Empty"
    },
    {
      "x": -12,
      "y": 9,
      "z": -1,
      "name": "Nat20_Force_Empty"
    },
    {
      "x": -12,
      "y": 10,
      "z": -1,
      "name": "Wood_Dry_Trunk",
      "rotation": 4
    },
    {
      "x": -12,
      "y": 11,
      "z": -1,
      "name": "Nat20_Force_Empty"
    },
    {
      "x": -12,
      "y": 12,
      "z": -1,
      "name": "Nat20_Force_Empty"
    },
    {
      "x": -12,
      "y": 13,
      "z": -1,
      "name": "Nat20_Force_Empty"
    },
    {
      "x": -12,
      "y": 14,
      "z": -1,
      "name": "Nat20_Force_Empty"
    },
    {
      "x": -12,
      "y": 15,
      "z": -1,
      "name": "Nat20_Force_Empty"
    },
    {
      "x": -12,
      "y": 16,
      "z": -1,
      "name": "Nat20_Force_Empty"
    },
    {
      "x": -12,
      "y": 17,
      "z": -1,
      "name": "Nat20_Force_Empty"
    },
    {
      "x": -12,
      "y": 18,
      "z": -1,
      "name": "Nat20_Force_Empty"
    },
    {
      "x": -12,
      "y": 19,
      "z": -1,
      "name": "Nat20_Force_Empty"
    },
    {
      "x": -12,
      "y": 20,
      "z": -1,
      "name": "Nat20_Force_Empty"
    },
    {
      "x": -12,
      "y": 21,
      "z": -1,
      "name": "Nat20_Force_Empty"
    },
    {
      "x": -12,
      "y": 22,
      "z": -1,
      "name": "Nat20_Force_Empty"
    },
    {
      "x": -12,
      "y": 23,
      "z": -1,
      "name": "Nat20_Force_Empty"
    },
    {
      "x": -12,
      "y": 0,
      "z": 0,
      "name": "Rock_Sandstone_White_Cobble"
    },
    {
      "x": -12,
      "y": 1,
      "z": 0,
      "name": "Rock_Sandstone_White_Cobble"
    },
    {
      "x": -12,
      "y": 2,
      "z": 0,
      "name": "Wood_Dry_Trunk",
      "rotation": 4
    },
    {
      "x": -12,
      "y": 3,
      "z": 0,
      "name": "Nat20_Force_Empty"
    },
    {
      "x": -12,
      "y": 4,
      "z": 0,
      "name": "Nat20_Force_Empty"
    },
    {
      "x": -12,
      "y": 5,
      "z": 0,
      "name": "Nat20_Force_Empty"
    },
    {
      "x": -12,
      "y": 6,
      "z": 0,
      "name": "Wood_Dry_Trunk",
      "rotation": 4
    },
    {
      "x": -12,
      "y": 7,
      "z": 0,
      "name": "Nat20_Force_Empty"
    },
    {
      "x": -12,
      "y": 8,
      "z": 0,
      "name": "Nat20_Force_Empty"
    },
    {
      "x": -12,
      "y": 9,
      "z": 0,
      "name": "Nat20_Force_Empty"
    },
    {
      "x": -12,
      "y": 10,
      "z": 0,
      "name": "Wood_Dry_Trunk",
      "rotation": 4
    },
    {
      "x": -12,
      "y": 11,
      "z": 0,
      "name": "Nat20_Force_Empty"
    },
    {
      "x": -12,
      "y": 12,
      "z": 0,
      "name": "Nat20_Force_Empty"
    },
    {
      "x": -12,
      "y": 13,
      "z": 0,
      "name": "Nat20_Force_Empty"
    },
    {
      "x": -12,
      "y": 14,
      "z": 0,
      "name": "Nat20_Force_Empty"
    },
    {
      "x": -12,
      "y": 15,
      "z": 0,
      "name": "Nat20_Force_Empty"
    },
    {
      "x": -12,
      "y": 16,
      "z": 0,
      "name": "Nat20_Force_Empty"
    },
    {
      "x": -12,
      "y": 17,
      "z": 0,
      "name": "Nat20_Force_Empty"
    },
    {
      "x": -12,
      "y": 18,
      "z": 0,
      "name": "Nat20_Force_Empty"
    },
    {
      "x": -12,
      "y": 19,
      "z": 0,
      "name": "Nat20_Force_Empty"
    },
    {
      "x": -12,
      "y": 20,
      "z": 0,
      "name": "Nat20_Force_Empty"
    },
    {
      "x": -12,
      "y": 21,
      "z": 0,
      "name": "Nat20_Force_Empty"
    },
    {
      "x": -12,
      "y": 22,
      "z": 0,
      "name": "Nat20_Force_Empty"
    },
    {
      "x": -12,
      "y": 23,
      "z": 0,
      "name": "Nat20_Force_Empty"
    },
    {
      "x": -12,
      "y": 0,
      "z": 1,
      "name": "Rock_Sandstone_White_Cobble"
    },
    {
      "x": -12,
      "y": 1,
      "z": 1,
      "name": "Rock_Sandstone_White_Cobble"
    },
    {
      "x": -12,
      "y": 2,
      "z": 1,
      "name": "Wood_Dry_Trunk",
      "rotation": 4
    },
    {
      "x": -12,
      "y": 3,
      "z": 1,
      "name": "Wood_Dry_Trunk"
    },
    {
      "x": -12,
      "y": 4,
      "z": 1,
      "name": "Wood_Dry_Trunk"
    },
    {
      "x": -12,
      "y": 5,
      "z": 1,
      "name": "Wood_Dry_Trunk"
    },
    {
      "x": -12,
      "y": 6,
      "z": 1,
      "name": "Wood_Dry_Trunk_Full",
      "rotation": 4
    },
    {
      "x": -12,
      "y": 7,
      "z": 1,
      "name": "Wood_Dry_Branch_Long"
    },
    {
      "x": -12,
      "y": 8,
      "z": 1,
      "name": "Wood_Dry_Branch_Long"
    },
    {
      "x": -12,
      "y": 9,
      "z": 1,
      "name": "Wood_Dry_Branch_Long"
    },
    {
      "x": -12,
      "y": 10,
      "z": 1,
      "name": "Wood_Dry_Trunk",
      "rotation": 4
    },
    {
      "x": -12,
      "y": 11,
      "z": 1,
      "name": "Nat20_Force_Empty"
    },
    {
      "x": -12,
      "y": 12,
      "z": 1,
      "name": "Nat20_Force_Empty"
    },
    {
      "x": -12,
      "y": 13,
      "z": 1,
      "name": "Nat20_Force_Empty"
    },
    {
      "x": -12,
      "y": 14,
      "z": 1,
      "name": "Nat20_Force_Empty"
    },
    {
      "x": -12,
      "y": 15,
      "z": 1,
      "name": "Nat20_Force_Empty"
    },
    {
      "x": -12,
      "y": 16,
      "z": 1,
      "name": "Nat20_Force_Empty"
    },
    {
      "x": -12,
      "y": 17,
      "z": 1,
      "name": "Nat20_Force_Empty"
    },
    {
      "x": -12,
      "y": 18,
      "z": 1,
      "name": "Nat20_Force_Empty"
    },
    {
      "x": -12,
      "y": 19,
      "z": 1,
      "name": "Nat20_Force_Empty"
    },
    {
      "x": -12,
      "y": 20,
      "z": 1,
      "name": "Nat20_Force_Empty"
    },
    {
      "x": -12,
      "y": 21,
      "z": 1,
      "name": "Nat20_Force_Empty"
    },
    {
      "x": -12,
      "y": 22,
      "z": 1,
      "name": "Nat20_Force_Empty"
    },
    {
      "x": -12,
      "y": 23,
      "z": 1,
      "name": "Nat20_Force_Empty"
    },
    {
      "x": -12,
      "y": 0,
      "z": 2,
      "name": "Rock_Sandstone_White_Cobble"
    },
    {
      "x": -12,
      "y": 1,
      "z": 2,
      "name": "Rock_Sandstone_White_Cobble"
    },
    {
      "x": -12,
      "y": 2,
      "z": 2,
      "name": "Wood_Dry_Trunk",
      "rotation": 4
    },
    {
      "x": -12,
      "y": 3,
      "z": 2,
      "name": "Nat20_Force_Empty"
    },
    {
      "x": -12,
      "y": 4,
      "z": 2,
      "name": "Nat20_Force_Empty"
    },
    {
      "x": -12,
      "y": 5,
      "z": 2,
      "name": "Nat20_Force_Empty"
    },
    {
      "x": -12,
      "y": 6,
      "z": 2,
      "name": "Wood_Drywood_Planks_Half",
      "rotation": 7
    },
    {
      "x": -12,
      "y": 7,
      "z": 2,
      "name": "Nat20_Force_Empty"
    },
    {
      "x": -12,
      "y": 8,
      "z": 2,
      "name": "Nat20_Force_Empty"
    },
    {
      "x": -12,
      "y": 9,
      "z": 2,
      "name": "Nat20_Force_Empty"
    },
    {
      "x": -12,
      "y": 10,
      "z": 2,
      "name": "Wood_Dry_Trunk_Full",
      "rotation": 4
    },
    {
      "x": -12,
      "y": 11,
      "z": 2,
      "name": "Nat20_Force_Empty"
    },
    {
      "x": -12,
      "y": 12,
      "z": 2,
