{
  "version": 8,
  "blockIdVersion": 11,
  "anchorX": 0,
  "anchorY": 0,
  "anchorZ": 0,
  "blocks": [
    {
      "x": -15,
      "y": 0,
      "z": -14,
      "name": "Soil_Clay_Brick"
    },
    {
      "x": -15,
      "y": 1,
      "z": -14,
      "name": "Soil_Clay_Brick"
    },
    {
      "x": -15,
      "y": 2,
      "z": -14,
      "name": "Soil_Clay_Brick"
    },
    {
      "x": -15,
      "y": 3,
      "z": -14,
      "name": "Rock_Basalt_Brick"
    },
    {
      "x": -15,
      "y": 4,
      "z": -14,
      "name": "Rock_Basalt_Brick"
    },
    {
      "x": -15,
      "y": 5,
      "z": -14,
      "name": "Rock_Basalt_Brick"
    },
    {
      "x": -15,
      "y": 6,
      "z": -14,
      "name": "Rock_Basalt_Brick"
    },
    {
      "x": -15,
      "y": 7,
      "z": -14,
      "name": "Rock_Basalt_Brick"
    },
    {
      "x": -15,
      "y": 8,
      "z": -14,
      "name": "Rock_Basalt_Brick"
    },
    {
      "x": -15,
      "y": 9,
      "z": -14,
      "name": "Soil_Clay_Brick"
    },
    {
      "x": -15,
      "y": 10,
      "z": -14,
      "name": "Soil_Clay_Brick"
    },
    {
      "x": -15,
      "y": 0,
      "z": -13,
      "name": "Soil_Clay_Brick"
    },
    {
      "x": -15,
      "y": 1,
      "z": -13,
      "name": "Soil_Clay_Brick"
    },
    {
      "x": -15,
      "y": 2,
      "z": -13,
      "name": "Soil_Clay_Brick"
    },
    {
      "x": -15,
      "y": 3,
      "z": -13,
      "name": "Rock_Basalt_Brick"
    },
    {
      "x": -15,
      "y": 4,
      "z": -13,
      "name": "Rock_Basalt_Brick"
    },
    {
      "x": -15,
      "y": 5,
      "z": -13,
      "name": "Nat20_Force_Empty"
    },
    {
      "x": -15,
      "y": 6,
      "z": -13,
      "name": "Nat20_Force_Empty"
    },
    {
      "x": -15,
      "y": 7,
      "z": -13,
      "name": "Rock_Basalt_Brick_Half",
      "rotation": 4
    },
    {
      "x": -15,
      "y": 8,
      "z": -13,
      "name": "Rock_Basalt_Brick"
    },
    {
      "x": -15,
      "y": 9,
      "z": -13,
      "name": "Rock_Basalt_Brick"
    },
    {
      "x": -15,
      "y": 10,
      "z": -13,
      "name": "Rock_Basalt_Brick"
    },
    {
      "x": -15,
      "y": 0,
      "z": -12,
      "name": "Soil_Clay_Brick"
    },
    {
      "x": -15,
      "y": 1,
      "z": -12,
      "name": "Rock_Basalt_Brick"
    },
    {
      "x": -15,
      "y": 2,
      "z": -12,
      "name": "Rock_Basalt_Brick"
    },
    {
      "x": -15,
      "y": 3,
      "z": -12,
      "name": "Rock_Basalt_Brick"
    },
    {
      "x": -15,
      "y": 4,
      "z": -12,
      "name": "Rock_Basalt_Brick"
    },
    {
      "x": -15,
      "y": 5,
      "z": -12,
      "name": "Rail",
      "rotation": 1
    },
    {
      "x": -15,
      "y": 6,
      "z": -12,
      "name": "Nat20_Force_Empty"
    },
    {
      "x": -15,
      "y": 7,
      "z": -12,
      "name": "Nat20_Force_Empty"
    },
    {
      "x": -15,
      "y": 8,
      "z": -12,
      "name": "Rock_Basalt_Brick_Half",
      "rotation": 8
    },
    {
      "x": -15,
      "y": 9,
      "z": -12,
      "name": "Rock_Basalt_Brick"
    },
    {
      "x": -15,
      "y": 10,
      "z": -12,
      "name": "Rock_Basalt_Brick"
    },
    {
      "x": -15,
      "y": 0,
      "z": -11,
      "name": "Soil_Clay_Brick"
    },
    {
      "x": -15,
      "y": 1,
      "z": -11,
      "name": "Rock_Basalt_Brick"
    },
    {
      "x": -15,
      "y": 2,
      "z": -11,
      "name": "Rock_Basalt_Brick"
    },
    {
      "x": -15,
      "y": 3,
      "z": -11,
      "name": "Rock_Basalt_Brick"
    },
    {
      "x": -15,
      "y": 4,
      "z": -11,
      "name": "Rock_Basalt_Brick"
    },
    {
      "x": -15,
      "y": 5,
      "z": -11,
      "name": "Nat20_Force_Empty"
    },
    {
      "x": -15,
      "y": 6,
      "z": -11,
      "name": "Nat20_Force_Empty"
    },
    {
      "x": -15,
      "y": 7,
      "z": -11,
      "name": "Nat20_Force_Empty"
    },
    {
      "x": -15,
      "y": 8,
      "z": -11,
      "name": "Nat20_Force_Empty"
    },
    {
      "x": -15,
      "y": 9,
      "z": -11,
      "name": "Rock_Basalt_Brick"
    },
    {
      "x": -15,
      "y": 10,
      "z": -11,
      "name": "Rock_Basalt_Brick"
    },
    {
      "x": -15,
      "y": 0,
      "z": -10,
      "name": "Soil_Clay_Brick"
    },
    {
      "x": -15,
      "y": 1,
      "z": -10,
      "name": "Soil_Dirt_Poisoned"
    },
    {
      "x": -15,
      "y": 2,
      "z": -10,
      "name": "Empty"
    },
    {
      "x": -15,
      "y": 3,
      "z": -10,
      "name": "Empty"
    },
    {
      "x": -15,
      "y": 4,
      "z": -10,
      "name": "Nat20_Force_Empty"
    },
    {
      "x": -15,
      "y": 5,
      "z": -10,
      "name": "Nat20_Force_Empty"
    },
    {
      "x": -15,
      "y": 6,
      "z": -10,
      "name": "Nat20_Force_Empty"
    },
    {
      "x": -15,
      "y": 7,
      "z": -10,
      "name": "Nat20_Force_Empty"
    },
    {
      "x": -15,
      "y": 8,
      "z": -10,
      "name": "Nat20_Force_Empty"
    },
    {
      "x": -15,
      "y": 9,
      "z": -10,
      "name": "Rock_Basalt_Brick_Half",
      "rotation": 8
    },
    {
      "x": -15,
      "y": 10,
      "z": -10,
      "name": "Rock_Basalt_Brick"
    },
    {
      "x": -15,
      "y": 0,
      "z": -9,
      "name": "Soil_Clay_Brick"
    },
    {
      "x": -15,
      "y": 1,
      "z": -9,
      "name": "Soil_Dirt_Poisoned"
    },
    {
      "x": -15,
      "y": 2,
      "z": -9,
      "name": "Empty"
    },
    {
      "x": -15,
      "y": 3,
      "z": -9,
      "name": "Empty"
    },
    {
      "x": -15,
      "y": 4,
      "z": -9,
      "name": "Nat20_Force_Empty"
    },
    {
      "x": -15,
      "y": 5,
      "z": -9,
      "name": "Nat20_Force_Empty"
    },
    {
      "x": -15,
      "y": 6,
      "z": -9,
      "name": "Nat20_Force_Empty"
    },
    {
      "x": -15,
      "y": 7,
      "z": -9,
      "name": "Nat20_Force_Empty"
    },
    {
      "x": -15,
      "y": 8,
      "z": -9,
      "name": "Nat20_Force_Empty"
    },
    {
      "x": -15,
      "y": 9,
      "z": -9,
      "name": "Rock_Basalt_Brick_Half",
      "rotation": 8
    },
    {
      "x": -15,
      "y": 10,
      "z": -9,
      "name": "Rock_Basalt_Brick"
    },
    {
      "x": -15,
      "y": 0,
      "z": -8,
      "name": "Soil_Clay_Brick"
    },
    {
      "x": -15,
      "y": 1,
      "z": -8,
      "name": "Soil_Dirt_Poisoned"
    },
    {
      "x": -15,
      "y": 2,
      "z": -8,
      "name": "Empty"
    },
    {
      "x": -15,
      "y": 3,
      "z": -8,
      "name": "Empty"
    },
    {
      "x": -15,
      "y": 4,
      "z": -8,
      "name": "Nat20_Force_Empty"
    },
    {
      "x": -15,
      "y": 5,
      "z": -8,
      "name": "Nat20_Force_Empty"
    },
    {
      "x": -15,
      "y": 6,
      "z": -8,
      "name": "Nat20_Force_Empty"
    },
    {
      "x": -15,
      "y": 7,
      "z": -8,
      "name": "Nat20_Force_Empty"
    },
    {
      "x": -15,
      "y": 8,
      "z": -8,
      "name": "Nat20_Force_Empty"
    },
    {
      "x": -15,
      "y": 9,
      "z": -8,
      "name": "Rock_Basalt_Brick_Half",
      "rotation": 8
    },
    {
      "x": -15,
      "y": 10,
      "z": -8,
      "name": "Rock_Basalt_Brick"
    },
    {
      "x": -15,
      "y": 0,
      "z": -7,
      "name": "Soil_Clay_Brick"
    },
    {
      "x": -15,
      "y": 1,
      "z": -7,
      "name": "Rock_Basalt_Brick"
    },
    {
      "x": -15,
      "y": 2,
      "z": -7,
      "name": "Rock_Basalt_Brick"
    },
    {
      "x": -15,
      "y": 3,
      "z": -7,
      "name": "Rock_Basalt_Brick"
    },
    {
      "x": -15,
      "y": 4,
      "z": -7,
      "name": "Rock_Basalt_Brick"
    },
    {
      "x": -15,
      "y": 5,
      "z": -7,
      "name": "Nat20_Force_Empty"
    },
    {
      "x": -15,
      "y": 6,
      "z": -7,
      "name": "Nat20_Force_Empty"
    },
    {
      "x": -15,
      "y": 7,
      "z": -7,
      "name": "Nat20_Force_Empty"
    },
    {
      "x": -15,
      "y": 8,
      "z": -7,
      "name": "Nat20_Force_Empty"
    },
    {
      "x": -15,
      "y": 9,
      "z": -7,
      "name": "Rock_Basalt_Brick"
    },
    {
      "x": -15,
      "y": 10,
      "z": -7,
      "name": "Rock_Basalt_Brick"
    },
    {
      "x": -15,
      "y": 0,
      "z": -6,
      "name": "Soil_Clay_Brick"
    },
    {
      "x": -15,
      "y": 1,
      "z": -6,
      "name": "Rock_Basalt_Brick"
    },
    {
      "x": -15,
      "y": 2,
      "z": -6,
      "name": "Rock_Basalt_Brick"
    },
    {
      "x": -15,
      "y": 3,
      "z": -6,
      "name": "Rock_Basalt_Brick"
    },
    {
      "x": -15,
      "y": 4,
      "z": -6,
      "name": "Rock_Basalt_Brick"
    },
    {
      "x": -15,
      "y": 5,
      "z": -6,
      "name": "Nat20_Force_Empty"
    },
    {
      "x": -15,
      "y": 6,
      "z": -6,
      "name": "Nat20_Force_Empty"
    },
    {
      "x": -15,
      "y": 7,
      "z": -6,
      "name": "Nat20_Force_Empty"
    },
    {
      "x": -15,
      "y": 8,
      "z": -6,
      "name": "Rock_Basalt_Brick_Half",
      "rotation": 8
    },
    {
      "x": -15,
      "y": 9,
      "z": -6,
      "name": "Rock_Basalt_Brick"
    },
    {
      "x": -15,
      "y": 10,
      "z": -6,
      "name": "Rock_Basalt_Brick"
    },
    {
      "x": -15,
      "y": 0,
      "z": -5,
      "name": "Soil_Clay_Brick"
    },
    {
      "x": -15,
      "y": 1,
      "z": -5,
      "name": "Soil_Clay_Brick"
    },
    {
      "x": -15,
      "y": 2,
      "z": -5,
      "name": "Soil_Clay_Brick"
    },
    {
      "x": -15,
      "y": 3,
      "z": -5,
      "name": "Rock_Basalt_Brick"
    },
    {
      "x": -15,
      "y": 4,
      "z": -5,
      "name": "Rock_Basalt_Brick"
    },
    {
      "x": -15,
      "y": 5,
      "z": -5,
      "name": "Nat20_Force_Empty"
    },
    {
      "x": -15,
      "y": 6,
      "z": -5,
      "name": "Nat20_Force_Empty"
    },
    {
      "x": -15,
      "y": 7,
      "z": -5,
      "name": "Rock_Basalt_Brick_Half",
      "rotation": 6
    },
    {
      "x": -15,
      "y": 8,
      "z": -5,
      "name": "Rock_Basalt_Brick"
    },
    {
      "x": -15,
      "y": 9,
      "z": -5,
      "name": "Rock_Basalt_Brick"
    },
    {
      "x": -15,
      "y": 10,
      "z": -5,
      "name": "Rock_Basalt_Brick"
    },
    {
      "x": -15,
      "y": 0,
      "z": -4,
      "name": "Soil_Clay_Brick"
    },
    {
      "x": -15,
      "y": 1,
      "z": -4,
      "name": "Soil_Clay_Brick"
    },
    {
      "x": -15,
      "y": 2,
      "z": -4,
      "name": "Soil_Clay_Brick"
    },
    {
      "x": -15,
      "y": 3,
      "z": -4,
      "name": "Rock_Basalt_Brick"
    },
    {
      "x": -15,
      "y": 4,
      "z": -4,
      "name": "Rock_Basalt_Brick"
    },
    {
      "x": -15,
      "y": 5,
      "z": -4,
      "name": "Rock_Basalt_Brick"
    },
    {
      "x": -15,
      "y": 6,
      "z": -4,
      "name": "Rock_Basalt_Brick"
    },
    {
      "x": -15,
      "y": 7,
      "z": -4,
      "name": "Rock_Basalt_Brick"
    },
    {
      "x": -15,
      "y": 8,
      "z": -4,
      "name": "Rock_Basalt_Brick"
    },
    {
      "x": -15,
      "y": 9,
      "z": -4,
      "name": "Rock_Basalt_Brick"
    },
    {
      "x": -15,
      "y": 10,
      "z": -4,
      "name": "Rock_Basalt_Brick"
    },
    {
      "x": -15,
      "y": 0,
      "z": -3,
      "name": "Soil_Clay_Brick"
    },
    {
      "x": -15,
      "y": 1,
      "z": -3,
      "name": "Soil_Clay_Brick"
    },
    {
      "x": -15,
      "y": 2,
      "z": -3,
      "name": "Soil_Clay_Brick"
    },
    {
      "x": -15,
      "y": 3,
      "z": -3,
      "name": "Soil_Clay_Brick"
    },
    {
      "x": -15,
      "y": 4,
      "z": -3,
      "name": "Soil_Clay_Brick"
    },
    {
      "x": -15,
      "y": 5,
      "z": -3,
      "name": "Soil_Clay_Brick"
    },
    {
      "x": -15,
      "y": 6,
      "z": -3,
      "name": "Soil_Clay_Brick"
    },
    {
      "x": -15,
      "y": 7,
      "z": -3,
      "name": "Soil_Clay_Brick"
    },
    {
      "x": -15,
      "y": 8,
      "z": -3,
      "name": "Soil_Clay_Brick"
    },
    {
      "x": -15,
      "y": 9,
      "z": -3,
      "name": "Soil_Clay_Brick"
    },
    {
      "x": -15,
      "y": 0,
      "z": -2,
      "name": "Soil_Clay_Brick"
    },
    {
      "x": -15,
      "y": 1,
      "z": -2,
      "name": "Soil_Clay_Brick"
    },
    {
      "x": -15,
      "y": 2,
      "z": -2,
      "name": "Soil_Clay_Brick"
    },
    {
      "x": -15,
      "y": 3,
      "z": -2,
      "name": "Soil_Clay_Brick"
    },
    {
      "x": -15,
      "y": 4,
      "z": -2,
      "name": "Soil_Clay_Brick"
    },
    {
      "x": -15,
      "y": 5,
      "z": -2,
      "name": "Soil_Mud_Dry"
    },
    {
      "x": -15,
      "y": 6,
      "z": -2,
      "name": "Soil_Clay_Brick"
    },
    {
      "x": -15,
      "y": 7,
      "z": -2,
      "name": "Soil_Mud_Dry"
    },
    {
      "x": -15,
      "y": 8,
      "z": -2,
      "name": "Soil_Mud_Dry"
    },
    {
      "x": -15,
      "y": 9,
      "z": -2,
      "name": "Soil_Dirt_Burnt"
    },
    {
      "x": -15,
      "y": 10,
      "z": -2,
      "name": "Soil_Dirt_Burnt"
    },
    {
      "x": -15,
      "y": 0,
      "z": -1,
      "name": "Soil_Clay_Brick"
    },
    {
      "x": -15,
      "y": 1,
      "z": -1,
      "name": "Soil_Clay_Brick"
    },
    {
      "x": -15,
      "y": 2,
      "z": -1,
      "name": "Soil_Clay_Brick"
    },
    {
      "x": -15,
      "y": 3,
      "z": -1,
      "name": "Soil_Clay_Brick"
    },
    {
      "x": -15,
      "y": 4,
      "z": -1,
      "name": "Soil_Clay_Brick"
    },
    {
      "x": -15,
      "y": 5,
      "z": -1,
      "name": "Soil_Mud_Dry"
    },
    {
      "x": -15,
      "y": 6,
      "z": -1,
      "name": "Soil_Mud_Dry"
    },
    {
      "x": -15,
      "y": 7,
      "z": -1,
      "name": "Soil_Mud_Dry"
    },
    {
      "x": -15,
      "y": 8,
      "z": -1,
      "name": "Soil_Mud_Dry"
    },
    {
      "x": -15,
      "y": 9,
      "z": -1,
      "name": "Soil_Clay_Brick"
    },
    {
      "x": -15,
      "y": 10,
      "z": -1,
      "name": "Soil_Dirt_Burnt"
    },
    {
      "x": -15,
      "y": 0,
      "z": 0,
      "name": "Soil_Clay_Brick"
    },
    {
      "x": -15,
      "y": 1,
      "z": 0,
      "name": "Soil_Clay_Brick"
    },
    {
      "x": -15,
      "y": 2,
      "z": 0,
      "name": "Soil_Clay_Brick"
    },
    {
      "x": -15,
      "y": 3,
      "z": 0,
      "name": "Soil_Clay_Brick"
    },
    {
      "x": -15,
      "y": 4,
      "z": 0,
      "name": "Soil_Clay_Brick"
    },
    {
      "x": -15,
      "y": 5,
      "z": 0,
      "name": "Soil_Clay_Brick"
    },
    {
      "x": -15,
      "y": 6,
      "z": 0,
      "name": "Soil_Clay_Brick"
    },
    {
      "x": -15,
      "y": 7,
      "z": 0,
      "name": "Soil_Clay_Brick"
    },
    {
      "x": -15,
      "y": 8,
      "z": 0,
      "name": "Soil_Clay_Brick"
    },
    {
      "x": -15,
      "y": 9,
      "z": 0,
      "name": "Soil_Clay_Brick"
    },
    {
      "x": -15,
      "y": 0,
      "z": 1,
      "name": "Soil_Clay_Brick"
    },
    {
      "x": -15,
      "y": 1,
      "z": 1,
      "name": "Soil_Clay_Brick"
    },
    {
      "x": -15,
      "y": 2,
      "z": 1,
      "name": "Soil_Clay_Brick"
    },
    {
      "x": -15,
      "y": 3,
      "z": 1,
      "name": "Soil_Clay_Brick"
    },
    {
      "x": -15,
      "y": 4,
      "z": 1,
      "name": "Soil_Clay_Brick"
    },
    {
      "x": -15,
      "y": 5,
      "z": 1,
      "name": "Soil_Dirt_Burnt"
    },
    {
      "x": -15,
      "y": 6,
      "z": 1,
      "name": "Soil_Dirt_Burnt"
    },
    {
      "x": -15,
      "y": 7,
      "z": 1,
      "name": "Soil_Dirt_Burnt"
    },
    {
      "x": -15,
      "y": 8,
      "z": 1,
      "name": "Soil_Clay_Brick"
    },
    {
      "x": -15,
      "y": 9,
      "z": 1,
      "name": "Soil_Clay_Brick"
    },
    {
      "x": -15,
      "y": 0,
      "z": 2,
      "name": "Soil_Clay_Brick"
    },
    {
      "x": -15,
      "y": 1,
      "z": 2,
      "name": "Soil_Clay_Brick"
    },
    {
      "x": -15,
      "y": 2,
      "z": 2,
      "name": "Soil_Clay_Brick"
    },
    {
      "x": -15,
      "y": 3,
      "z": 2,
      "name": "Soil_Clay_Brick"
    },
    {
      "x": -15,
      "y": 4,
      "z": 2,
      "name": "Soil_Clay_Brick"
    },
    {
      "x": -15,
      "y": 5,
      "z": 2,
      "name": "Soil_Dirt_Burnt"
    },
    {
      "x": -15,
      "y": 6,
      "z": 2,
      "name": "Soil_Dirt_Burnt"
    },
    {
      "x": -15,
      "y": 7,
      "z": 2,
      "name": "Soil_Dirt_Burnt"
    },
    {
      "x": -15,
      "y": 8,
      "z": 2,
      "name": "Soil_Clay_Brick"
    },
    {
      "x": -15,
      "y": 9,
      "z": 2,
      "name": "Soil_Clay_Brick"
    },
    {
      "x": -15,
      "y": 0,
      "z": 3,
      "name": "Soil_Clay_Brick"
    },
    {
      "x": -15,
      "y": 1,
      "z": 3,
      "name": "Soil_Clay_Brick"
    },
    {
      "x": -15,
      "y": 2,
      "z": 3,
      "name": "Soil_Clay_Brick"
    },
    {
      "x": -15,
      "y": 3,
      "z": 3,
      "name": "Soil_Clay_Brick"
    },
    {
      "x": -15,
      "y": 4,
      "z": 3,
      "name": "Soil_Clay_Brick"
    },
    {
      "x": -15,
      "y": 5,
      "z": 3,
      "name": "Soil_Dirt_Burnt"
    },
    {
      "x": -15,
      "y": 6,
      "z": 3,
      "name": "Soil_Dirt_Burnt"
    },
    {
      "x": -15,
      "y": 7,
      "z": 3,
      "name": "Soil_Dirt_Burnt"
    },
    {
      "x": -15,
      "y": 8,
      "z": 3,
      "name": "Soil_Clay_Brick"
    },
    {
      "x": -15,
      "y": 9,
      "z": 3,
      "name": "Soil_Clay_Brick"
    },
    {
      "x": -15,
      "y": 0,
      "z": 4,
      "name": "Soil_Clay_Brick"
    },
    {
      "x": -15,
      "y": 1,
      "z": 4,
      "name": "Soil_Clay_Brick"
    },
    {
      "x": -15,
      "y": 2,
      "z": 4,
      "name": "Soil_Clay_Brick"
    },
    {
      "x": -15,
      "y": 3,
      "z": 4,
      "name": "Soil_Clay_Brick"
    },
    {
      "x": -15,
      "y": 4,
      "z": 4,
      "name": "Soil_Clay_Brick"
    },
    {
      "x": -15,
      "y": 5,
      "z": 4,
      "name": "Soil_Dirt_Burnt"
    },
    {
      "x": -15,
      "y": 6,
      "z": 4,
      "name": "Soil_Dirt_Burnt"
    },
    {
      "x": -15,
      "y": 7,
      "z": 4,
      "name": "Soil_Clay_Brick"
    },
    {
      "x": -15,
      "y": 8,
      "z": 4,
      "name": "Soil_Clay_Brick"
    },
    {
      "x": -15,
      "y": 9,
      "z": 4,
      "name": "Soil_Clay_Brick"
    },
    {
      "x": -15,
      "y": 0,
      "z": 5,
      "name": "Soil_Clay_Brick"
    },
    {
      "x": -15,
      "y": 1,
      "z": 5,
      "name": "Soil_Clay_Brick"
    },
    {
      "x": -15,
      "y": 2,
      "z": 5,
      "name": "Soil_Clay_Brick"
    },
    {
      "x": -15,
      "y": 3,
      "z": 5,
      "name": "Soil_Clay_Brick"
    },
    {
      "x": -15,
      "y": 4,
      "z": 5,
      "name": "Soil_Clay_Brick"
    },
    {
      "x": -15,
      "y": 5,
      "z": 5,
      "name": "Soil_Clay_Brick"
    },
    {
      "x": -15,
      "y": 6,
      "z": 5,
      "name": "Soil_Clay_Brick"
    },
    {
      "x": -15,
      "y": 7,
      "z": 5,
      "name": "Soil_Clay_Brick"
    },
    {
      "x": -15,
      "y": 8,
      "z": 5,
      "name": "Soil_Clay_Brick"
    },
    {
      "x": -15,
      "y": 9,
      "z": 5,
      "name": "Soil_Clay_Brick"
    },
    {
      "x": -15,
      "y": 0,
      "z": 6,
      "name": "Soil_Clay_Brick"
    },
    {
      "x": -15,
      "y": 1,
      "z": 6,
      "name": "Soil_Clay_Brick"
    },
    {
      "x": -15,
      "y": 2,
      "z": 6,
      "name": "Soil_Clay_Brick"
    },
    {
      "x": -15,
      "y": 3,
      "z": 6,
      "name": "Soil_Clay_Brick"
    },
    {
      "x": -15,
      "y": 4,
      "z": 6,
      "name": "Soil_Clay_Brick"
    },
    {
      "x": -15,
      "y": 5,
      "z": 6,
      "name": "Soil_Clay_Brick"
    },
    {
      "x": -15,
      "y": 6,
      "z": 6,
      "name": "Soil_Clay_Brick"
    },
    {
      "x": -15,
      "y": 7,
      "z": 6,
      "name": "Soil_Clay_Brick"
    },
    {
      "x": -15,
      "y": 8,
      "z": 6,
      "name": "Soil_Clay_Brick"
    },
    {
      "x": -15,
      "y": 9,
      "z": 6,
      "name": "Soil_Clay_Brick"
    },
    {
      "x": -15,
      "y": 0,
      "z": 7,
      "name": "Soil_Clay_Brick"
    },
    {
      "x": -15,
      "y": 1,
      "z": 7,
      "name": "Soil_Clay_Brick"
    },
    {
      "x": -15,
      "y": 2,
      "z": 7,
      "name": "Soil_Clay_Brick"
    },
    {
      "x": -15,
      "y": 3,
      "z": 7,
      "name": "Soil_Clay_Brick"
    },
    {
      "x": -15,
      "y": 4,
      "z": 7,
      "name": "Soil_Clay_Brick"
    },
    {
      "x": -15,
      "y": 5,
      "z": 7,
      "name": "Soil_Clay_Brick"
    },
    {
      "x": -15,
      "y": 6,
      "z": 7,
      "name": "Soil_Clay_Brick"
    },
    {
      "x": -15,
      "y": 7,
      "z": 7,
      "name": "Soil_Clay_Brick"
    },
    {
      "x": -15,
      "y": 8,
      "z": 7,
      "name": "Soil_Clay_Brick"
    },
    {
      "x": -15,
      "y": 9,
      "z": 7,
      "name": "Soil_Clay_Brick"
    },
    {
      "x": -15,
      "y": 0,
      "z": 8,
      "name": "Soil_Clay_Brick"
    },
    {
      "x": -15,
      "y": 1,
      "z": 8,
      "name": "Soil_Clay_Brick"
    },
    {
      "x": -15,
      "y": 2,
      "z": 8,
      "name": "Soil_Clay_Brick"
    },
    {
      "x": -15,
      "y": 3,
      "z": 8,
      "name": "Soil_Clay_Brick"
    },
    {
      "x": -15,
      "y": 4,
      "z": 8,
      "name": "Soil_Dirt_Burnt"
    },
    {
      "x": -15,
      "y": 5,
      "z": 8,
      "name": "Soil_Clay_Brick"
    },
    {
      "x": -15,
      "y": 6,
      "z": 8,
      "name": "Soil_Dirt_Burnt"
    },
    {
      "x": -15,
      "y": 7,
      "z": 8,
      "name": "Soil_Clay_Brick"
    },
    {
      "x": -15,
      "y": 8,
      "z": 8,
      "name": "Soil_Clay_Brick"
    },
    {
      "x": -15,
      "y": 9,
      "z": 8,
      "name": "Soil_Clay_Brick"
    },
    {
      "x": -15,
      "y": 0,
      "z": 9,
      "name": "Soil_Clay_Brick"
    },
    {
      "x": -15,
      "y": 1,
      "z": 9,
      "name": "Soil_Clay_Brick"
    },
    {
      "x": -15,
      "y": 2,
      "z": 9,
      "name": "Soil_Clay_Brick"
    },
    {
      "x": -15,
      "y": 3,
      "z": 9,
      "name": "Soil_Clay_Brick"
    },
    {
      "x": -15,
      "y": 4,
      "z": 9,
      "name": "Soil_Clay_Brick"
    },
    {
      "x": -15,
      "y": 5,
      "z": 9,
      "name": "Soil_Dirt_Burnt"
    },
    {
      "x": -15,
      "y": 6,
      "z": 9,
      "name": "Soil_Dirt_Burnt"
    },
    {
      "x": -15,
      "y": 7,
      "z": 9,
      "name": "Soil_Dirt_Burnt"
    },
    {
      "x": -15,
      "y": 8,
      "z": 9,
      "name": "Soil_Clay_Brick"
    },
    {
      "x": -15,
      "y": 9,
      "z": 9,
      "name": "Soil_Clay_Brick"
    },
    {
      "x": -15,
      "y": 0,
      "z": 10,
      "name": "Soil_Clay_Brick"
    },
    {
      "x": -15,
      "y": 1,
      "z": 10,
      "name": "Soil_Clay_Brick"
    },
    {
      "x": -15,
      "y": 2,
      "z": 10,
      "name": "Soil_Clay_Brick"
    },
    {
      "x": -15,
      "y": 3,
      "z": 10,
      "name": "Soil_Clay_Brick"
    },
    {
      "x": -15,
      "y": 4,
      "z": 10,
      "name": "Soil_Clay_Brick"
    },
    {
      "x": -15,
      "y": 5,
      "z": 10,
      "name": "Soil_Mud_Dry"
    },
    {
      "x": -15,
      "y": 6,
      "z": 10,
      "name": "Soil_Mud_Dry"
    },
    {
      "x": -15,
      "y": 7,
      "z": 10,
      "name": "Soil_Dirt_Burnt"
    },
    {
      "x": -15,
      "y": 8,
      "z": 10,
      "name": "Soil_Clay_Brick"
    },
    {
      "x": -15,
      "y": 9,
      "z": 10,
      "name": "Soil_Clay_Brick"
    },
    {
      "x": -15,
      "y": 0,
      "z": 11,
      "name": "Soil_Clay_Brick"
    },
    {
      "x": -15,
      "y": 1,
      "z": 11,
      "name": "Soil_Clay_Brick"
    },
    {
      "x": -15,
      "y": 2,
      "z": 11,
      "name": "Soil_Clay_Brick"
    },
    {
      "x": -15,
      "y": 3,
      "z": 11,
      "name": "Soil_Clay_Brick"
    },
    {
      "x": -15,
      "y": 4,
      "z": 11,
      "name": "Soil_Clay_Brick"
    },
    {
      "x": -15,
      "y": 5,
      "z": 11,
      "name": "Soil_Clay_Brick"
    },
    {
      "x": -15,
      "y": 6,
      "z": 11,
      "name": "Soil_Mud_Dry"
    },
    {
      "x": -15,
      "y": 7,
      "z": 11,
      "name": "Soil_Clay_Brick"
    },
    {
      "x": -15,
      "y": 8,
      "z": 11,
      "name": "Soil_Clay_Brick"
    },
    {
      "x": -15,
      "y": 9,
      "z": 11,
      "name": "Soil_Clay_Brick"
    },
    {
      "x": -15,
      "y": 0,
      "z": 12,
      "name": "Soil_Clay_Brick"
    },
    {
      "x": -15,
      "y": 1,
      "z": 12,
      "name": "Soil_Clay_Brick"
    },
    {
      "x": -15,
      "y": 2,
      "z": 12,
      "name": "Soil_Clay_Brick"
    },
    {
      "x": -15,
      "y": 3,
      "z": 12,
      "name": "Soil_Clay_Brick"
    },
    {
      "x": -15,
      "y": 4,
      "z": 12,
      "name": "Soil_Clay_Brick"
    },
    {
      "x": -15,
      "y": 5,
      "z": 12,
      "name": "Soil_Dirt_Burnt"
    },
    {
      "x": -15,
      "y": 6,
      "z": 12,
      "name": "Soil_Clay_Brick"
    },
    {
      "x": -15,
      "y": 7,
      "z": 12,
      "name": "Soil_Clay_Brick"
    },
    {
      "x": -15,
      "y": 8,
      "z": 12,
      "name": "Soil_Clay_Brick"
    },
    {
      "x": -15,
      "y": 9,
      "z": 12,
      "name": "Soil_Clay_Brick"
    },
    {
      "x": -15,
      "y": 0,
      "z": 13,
      "name": "Soil_Clay_Brick"
    },
    {
      "x": -15,
      "y": 1,
      "z": 13,
      "name": "Soil_Clay_Brick"
    },
    {
      "x": -15,
      "y": 2,
      "z": 13,
      "name": "Soil_Clay_Brick"
    },
    {
      "x": -15,
      "y": 3,
      "z": 13,
      "name": "Soil_Clay_Brick"
    },
    {
      "x": -15,
      "y": 4,
      "z": 13,
      "name": "Soil_Clay_Brick"
    },
    {
      "x": -15,
      "y": 5,
      "z": 13,
      "name": "Soil_Dirt_Burnt"
    },
    {
      "x": -15,
      "y": 6,
      "z": 13,
      "name": "Soil_Dirt_Burnt"
    },
    {
      "x": -15,
      "y": 7,
      "z": 13,
      "name": "Soil_Clay_Brick"
    },
    {
      "x": -15,
      "y": 8,
      "z": 13,
      "name": "Soil_Clay_Brick"
    },
    {
      "x": -15,
      "y": 9,
      "z": 13,
      "name": "Soil_Clay_Brick"
    },
    {
      "x": -15,
      "y": 0,
      "z": 14,
      "name": "Soil_Clay_Brick"
    },
    {
      "x": -15,
      "y": 1,
      "z": 14,
      "name": "Soil_Clay_Brick"
    },
    {
      "x": -15,
      "y": 2,
      "z": 14,
      "name": "Soil_Clay_Brick"
    },
    {
      "x": -15,
      "y": 3,
      "z": 14,
      "name": "Soil_Clay_Brick"
    },
    {
      "x": -15,
      "y": 4,
      "z": 14,
      "name": "Soil_Clay_Brick"
    },
    {
      "x": -15,
      "y": 5,
      "z": 14,
      "name": "Soil_Clay_Brick"
    },
    {
      "x": -15,
      "y": 6,
      "z": 14,
      "name": "Soil_Clay_Brick"
    },
    {
      "x": -15,
      "y": 7,
      "z": 14,
      "name": "Soil_Clay_Brick"
    },
    {
      "x": -15,
      "y": 8,
      "z": 14,
      "name": "Soil_Clay_Brick"
    },
    {
      "x": -15,
      "y": 9,
      "z": 14,
      "name": "Soil_Clay_Brick"
    },
    {
      "x": -15,
      "y": 0,
      "z": 15,
      "name": "Soil_Clay_Brick"
    },
    {
      "x": -15,
      "y": 1,
      "z": 15,
      "name": "Soil_Clay_Brick"
    },
    {
      "x": -15,
      "y": 2,
      "z": 15,
      "name": "Soil_Clay_Brick"
    },
    {
      "x": -15,
      "y": 3,
      "z": 15,
      "name": "Soil_Clay_Brick"
    },
    {
      "x": -15,
      "y": 4,
      "z": 15,
      "name": "Soil_Clay_Brick"
    },
    {
      "x": -15,
      "y": 5,
      "z": 15,
      "name": "Soil_Clay_Brick"
    },
    {
      "x": -15,
      "y": 6,
      "z": 15,
      "name": "Soil_Clay_Brick"
    },
    {
      "x": -15,
      "y": 7,
      "z": 15,
      "name": "Soil_Clay_Brick"
    },
    {
      "x": -15,
      "y": 8,
      "z": 15,
      "name": "Soil_Clay_Brick"
    },
    {
      "x": -15,
      "y": 9,
      "z": 15,
      "name": "Soil_Clay_Brick"
    },
    {
      "x": -14,
      "y": 0,
      "z": -14,
      "name": "Soil_Clay_Brick"
    },
    {
      "x": -14,
      "y": 1,
      "z": -14,
      "name": "Soil_Clay_Brick"
    },
    {
      "x": -14,
      "y": 2,
      "z": -14,
      "name": "Soil_Clay_Brick"
    },
    {
      "x": -14,
      "y": 3,
      "z": -14,
      "name": "Soil_Clay_Brick"
    },
    {
      "x": -14,
      "y": 4,
      "z": -14,
      "name": "Soil_Clay_Brick"
    },
    {
      "x": -14,
      "y": 5,
      "z": -14,
      "name": "Rock_Basalt_Brick"
    },
    {
      "x": -14,
      "y": 6,
      "z": -14,
      "name": "Rock_Basalt_Brick"
    },
    {
      "x": -14,
      "y": 7,
      "z": -14,
      "name": "Rock_Basalt_Brick"
    },
    {
      "x": -14,
      "y": 8,
      "z": -14,
      "name": "Rock_Basalt_Brick"
    },
    {
      "x": -14,
      "y": 9,
      "z": -14,
      "name": "Soil_Clay_Brick"
    },
    {
      "x": -14,
      "y": 10,
      "z": -14,
      "name": "Soil_Clay_Brick"
    },
    {
      "x": -14,
      "y": 11,
      "z": -14,
      "name": "Soil_Clay_Brick"
    },
    {
      "x": -14,
      "y": 0,
      "z": -13,
      "name": "Soil_Clay_Brick"
    },
    {
      "x": -14,
      "y": 1,
      "z": -13,
      "name": "Soil_Clay_Brick"
    },
    {
      "x": -14,
      "y": 2,
      "z": -13,
      "name": "Soil_Clay_Brick"
    },
    {
      "x": -14,
      "y": 3,
      "z": -13,
      "name": "Soil_Clay_Brick"
    },
    {
      "x": -14,
      "y": 4,
      "z": -13,
      "name": "Rock_Basalt_Brick"
    },
    {
      "x": -14,
      "y": 5,
      "z": -13,
      "name": "Nat20_Force_Empty"
    },
    {
      "x": -14,
      "y": 6,
      "z": -13,
      "name": "Nat20_Force_Empty"
    },
    {
      "x": -14,
      "y": 7,
      "z": -13,
      "name": "Rock_Basalt_Brick_Half",
      "rotation": 4
    },
    {
      "x": -14,
      "y": 8,
      "z": -13,
      "name": "Rock_Basalt_Brick"
    },
    {
      "x": -14,
      "y": 9,
      "z": -13,
      "name": "Rock_Basalt_Brick"
    },
    {
      "x": -14,
      "y": 10,
      "z": -13,
      "name": "Rock_Basalt_Brick"
    },
    {
      "x": -14,
      "y": 11,
      "z": -13,
      "name": "Soil_Clay_Brick"
    },
    {
      "x": -14,
      "y": 0,
      "z": -12,
      "name": "Soil_Clay_Brick"
    },
    {
      "x": -14,
      "y": 1,
      "z": -12,
      "name": "Rock_Basalt_Brick"
    },
    {
      "x": -14,
      "y": 2,
      "z": -12,
      "name": "Rock_Basalt_Brick"
    },
    {
      "x": -14,
      "y": 3,
      "z": -12,
      "name": "Rock_Basalt_Brick"
    },
    {
      "x": -14,
      "y": 4,
      "z": -12,
      "name": "Rock_Basalt_Brick"
    },
    {
      "x": -14,
      "y": 5,
      "z": -12,
      "name": "Rail",
      "rotation": 1
    },
    {
      "x": -14,
      "y": 6,
      "z": -12,
      "name": "Nat20_Force_Empty"
    },
    {
      "x": -14,
      "y": 7,
      "z": -12,
      "name": "Nat20_Force_Empty"
    },
    {
      "x": -14,
      "y": 8,
      "z": -12,
      "name": "Rock_Basalt_Brick_Half",
      "rotation": 8
    },
    {
      "x": -14,
      "y": 9,
      "z": -12,
      "name": "Rock_Basalt_Brick"
    },
    {
      "x": -14,
      "y": 10,
      "z": -12,
      "name": "Rock_Basalt_Brick"
    },
    {
      "x": -14,
      "y": 11,
      "z": -12,
      "name": "Soil_Clay_Brick"
    },
    {
      "x": -14,
      "y": 0,
      "z": -11,
      "name": "Soil_Clay_Brick"
    },
    {
      "x": -14,
      "y": 1,
      "z": -11,
      "name": "Rock_Basalt_Brick"
    },
    {
      "x": -14,
      "y": 2,
      "z": -11,
      "name": "Rock_Basalt_Brick"
    },
    {
      "x": -14,
      "y": 3,
      "z": -11,
      "name": "Rock_Basalt_Brick"
    },
    {
      "x": -14,
      "y": 4,
      "z": -11,
      "name": "Rock_Basalt_Brick"
    },
    {
      "x": -14,
      "y": 5,
      "z": -11,
      "name": "Nat20_Force_Empty"
    },
    {
      "x": -14,
      "y": 6,
      "z": -11,
      "name": "Nat20_Force_Empty"
    },
    {
      "x": -14,
      "y": 7,
      "z": -11,
      "name": "Nat20_Force_Empty"
    },
    {
      "x": -14,
      "y": 8,
      "z": -11,
      "name": "Nat20_Force_Empty"
    },
    {
      "x": -14,
      "y": 9,
      "z": -11,
      "name": "Rock_Basalt_Brick"
    },
    {
      "x": -14,
      "y": 10,
      "z": -11,
      "name": "Rock_Basalt_Brick"
    },
    {
      "x": -14,
      "y": 11,
      "z": -11,
      "name": "Soil_Clay_Brick"
    },
    {
      "x": -14,
      "y": 0,
      "z": -10,
      "name": "Soil_Clay_Brick"
    },
    {
      "x": -14,
      "y": 1,
      "z": -10,
      "name": "Soil_Dirt_Poisoned"
    },
    {
      "x": -14,
      "y": 2,
      "z": -10,
      "name": "Empty"
    },
    {
      "x": -14,
      "y": 3,
      "z": -10,
      "name": "Empty"
    },
    {
      "x": -14,
      "y": 4,
      "z": -10,
      "name": "Furniture_Crude_Platform"
    },
    {
      "x": -14,
      "y": 5,
      "z": -10,
      "name": "Nat20_Force_Empty"
    },
    {
      "x": -14,
      "y": 6,
      "z": -10,
      "name": "Nat20_Force_Empty"
    },
    {
      "x": -14,
      "y": 7,
      "z": -10,
      "name": "Nat20_Force_Empty"
    },
    {
      "x": -14,
      "y": 8,
      "z": -10,
      "name": "Nat20_Force_Empty"
    },
    {
      "x": -14,
      "y": 9,
      "z": -10,
      "name": "Rock_Basalt_Brick_Half",
      "rotation": 8
    },
    {
      "x": -14,
      "y": 10,
      "z": -10,
      "name": "Rock_Basalt_Brick"
    },
    {
      "x": -14,
      "y": 11,
      "z": -10,
      "name": "Soil_Clay_Brick"
    },
    {
      "x": -14,
      "y": 0,
      "z": -9,
      "name": "Soil_Clay_Brick"
    },
    {
      "x": -14,
      "y": 1,
      "z": -9,
      "name": "Soil_Dirt_Poisoned"
    },
    {
      "x": -14,
      "y": 2,
      "z": -9,
      "name": "Empty"
    },
    {
      "x": -14,
      "y": 3,
      "z": -9,
      "name": "Empty"
    },
    {
      "x": -14,
      "y": 4,
      "z": -9,
      "name": "Furniture_Crude_Platform"
    },
    {
      "x": -14,
      "y": 5,
      "z": -9,
      "name": "Nat20_Force_Empty"
    },
    {
      "x": -14,
      "y": 6,
      "z": -9,
      "name": "Nat20_Force_Empty"
    },
    {
      "x": -14,
      "y": 7,
      "z": -9,
      "name": "Nat20_Force_Empty"
    },
    {
      "x": -14,
      "y": 8,
      "z": -9,
      "name": "Nat20_Force_Empty"
    },
    {
      "x": -14,
      "y": 9,
      "z": -9,
      "name": "Rock_Basalt_Brick_Half",
      "rotation": 8
    },
    {
      "x": -14,
      "y": 10,
      "z": -9,
      "name": "Rock_Basalt_Brick"
    },
    {
      "x": -14,
      "y": 11,
      "z": -9,
      "name": "Soil_Clay_Brick"
    },
    {
      "x": -14,
      "y": 0,
      "z": -8,
      "name": "Soil_Clay_Brick"
    },
    {
      "x": -14,
      "y": 1,
      "z": -8,
      "name": "Soil_Dirt_Poisoned"
    },
    {
      "x": -14,
      "y": 2,
      "z": -8,
      "name": "Empty"
    },
    {
      "x": -14,
      "y": 3,
      "z": -8,
      "name": "Empty"
    },
    {
      "x": -14,
      "y": 4,
      "z": -8,
      "name": "Furniture_Crude_Platform"
    },
    {
      "x": -14,
      "y": 5,
      "z": -8,
      "name": "Nat20_Force_Empty"
    },
    {
      "x": -14,
      "y": 6,
      "z": -8,
      "name": "Nat20_Force_Empty"
    },
    {
      "x": -14,
      "y": 7,
      "z": -8,
      "name": "Nat20_Force_Empty"
    },
    {
      "x": -14,
      "y": 8,
      "z": -8,
      "name": "Nat20_Force_Empty"
    },
    {
      "x": -14,
      "y": 9,
      "z": -8,
      "name": "Rock_Basalt_Brick_Half",
      "rotation": 8
    },
    {
      "x": -14,
      "y": 10,
      "z": -8,
      "name": "Rock_Basalt_Brick"
    },
    {
      "x": -14,
      "y": 11,
      "z": -8,
      "name": "Soil_Clay_Brick"
    },
    {
      "x": -14,
      "y": 0,
      "z": -7,
      "name": "Soil_Clay_Brick"
    },
    {
      "x": -14,
      "y": 1,
      "z": -7,
      "name": "Rock_Basalt_Brick"
    },
    {
      "x": -14,
      "y": 2,
      "z": -7,
      "name": "Rock_Basalt_Brick"
    },
    {
      "x": -14,
      "y": 3,
      "z": -7,
      "name": "Rock_Basalt_Brick"
    },
    {
      "x": -14,
      "y": 4,
      "z": -7,
      "name": "Rock_Basalt_Brick"
    },
    {
      "x": -14,
      "y": 5,
      "z": -7,
      "name": "Nat20_Force_Empty"
    },
    {
      "x": -14,
      "y": 6,
      "z": -7,
      "name": "Nat20_Force_Empty"
    },
    {
      "x": -14,
      "y": 7,
      "z": -7,
      "name": "Nat20_Force_Empty"
    },
    {
      "x": -14,
      "y": 8,
      "z": -7,
      "name": "Nat20_Force_Empty"
    },
    {
      "x": -14,
      "y": 9,
      "z": -7,
      "name": "Rock_Basalt_Brick"
    },
    {
      "x": -14,
      "y": 10,
      "z": -7,
      "name": "Rock_Basalt_Brick"
    },
    {
      "x": -14,
      "y": 11,
      "z": -7,
      "name": "Soil_Clay_Brick"
    },
    {
      "x": -14,
      "y": 0,
      "z": -6,
      "name": "Soil_Clay_Brick"
    },
    {
      "x": -14,
      "y": 1,
      "z": -6,
      "name": "Rock_Basalt_Brick"
    },
    {
      "x": -14,
      "y": 2,
      "z": -6,
      "name": "Rock_Basalt_Brick"
    },
    {
      "x": -14,
      "y": 3,
      "z": -6,
      "name": "Rock_Basalt_Brick"
    },
    {
      "x": -14,
      "y": 4,
      "z": -6,
      "name": "Rock_Basalt_Brick"
    },
    {
      "x": -14,
      "y": 5,
      "z": -6,
      "name": "Nat20_Force_Empty"
    },
    {
      "x": -14,
      "y": 6,
      "z": -6,
      "name": "Nat20_Force_Empty"
    },
    {
      "x": -14,
      "y": 7,
      "z": -6,
      "name": "Nat20_Force_Empty"
    },
    {
      "x": -14,
      "y": 8,
      "z": -6,
      "name": "Rock_Basalt_Brick_Half",
      "rotation": 8
    },
    {
      "x": -14,
      "y": 9,
      "z": -6,
      "name": "Rock_Basalt_Brick"
    },
    {
      "x": -14,
      "y": 10,
      "z": -6,
      "name": "Rock_Basalt_Brick"
    },
    {
      "x": -14,
      "y": 11,
      "z": -6,
      "name": "Soil_Clay_Brick"
    },
    {
      "x": -14,
      "y": 0,
      "z": -5,
      "name": "Soil_Clay_Brick"
    },
    {
      "x": -14,
      "y": 1,
      "z": -5,
      "name": "Soil_Clay_Brick"
    },
    {
      "x": -14,
      "y": 2,
      "z": -5,
      "name": "Soil_Clay_Brick"
    },
    {
      "x": -14,
      "y": 3,
      "z": -5,
      "name": "Soil_Clay_Brick"
    },
    {
      "x": -14,
      "y": 4,
      "z": -5,
      "name": "Rock_Basalt_Brick"
    },
    {
      "x": -14,
      "y": 5,
      "z": -5,
      "name": "Nat20_Force_Empty"
    },
    {
      "x": -14,
      "y": 6,
      "z": -5,
      "name": "Nat20_Force_Empty"
    },
    {
      "x": -14,
      "y": 7,
      "z": -5,
      "name": "Rock_Basalt_Brick_Half",
      "rotation": 6
    },
    {
      "x": -14,
      "y": 8,
      "z": -5,
      "name": "Rock_Basalt_Brick"
    },
    {
      "x": -14,
      "y": 9,
      "z": -5,
      "name": "Rock_Basalt_Brick"
    },
    {
      "x": -14,
      "y": 10,
      "z": -5,
      "name": "Rock_Basalt_Brick"
    },
    {
      "x": -14,
      "y": 11,
      "z": -5,
      "name": "Soil_Clay_Brick"
    },
    {
      "x": -14,
      "y": 0,
      "z": -4,
      "name": "Soil_Clay_Brick"
    },
    {
      "x": -14,
      "y": 1,
      "z": -4,
      "name": "Soil_Clay_Brick"
    },
    {
      "x": -14,
      "y": 2,
      "z": -4,
      "name": "Soil_Clay_Brick"
    },
    {
      "x": -14,
      "y": 3,
      "z": -4,
      "name": "Soil_Clay_Brick"
    },
    {
      "x": -14,
      "y": 4,
      "z": -4,
      "name": "Soil_Clay_Brick"
    },
    {
      "x": -14,
      "y": 5,
      "z": -4,
      "name": "Rock_Basalt_Brick"
    },
    {
      "x": -14,
      "y": 6,
      "z": -4,
      "name": "Rock_Basalt_Brick"
    },
    {
      "x": -14,
      "y": 7,
      "z": -4,
      "name": "Rock_Basalt_Brick"
    },
    {
      "x": -14,
      "y": 8,
      "z": -4,
      "name": "Rock_Basalt_Brick"
    },
    {
      "x": -14,
      "y": 9,
      "z": -4,
      "name": "Rock_Basalt_Brick"
    },
    {
      "x": -14,
      "y": 10,
      "z": -4,
      "name": "Rock_Basalt_Brick"
    },
    {
      "x": -14,
      "y": 11,
      "z": -4,
      "name": "Soil_Clay_Brick"
    },
    {
      "x": -14,
      "y": 0,
      "z": -3,
      "name": "Soil_Clay_Brick"
    },
    {
      "x": -14,
      "y": 1,
      "z": -3,
      "name": "Soil_Clay_Brick"
    },
    {
      "x": -14,
      "y": 2,
      "z": -3,
      "name": "Soil_Clay_Brick"
    },
    {
      "x": -14,
      "y": 3,
      "z": -3,
      "name": "Soil_Clay_Brick"
    },
    {
      "x": -14,
      "y": 4,
      "z": -3,
      "name": "Soil_Clay_Brick"
    },
    {
      "x": -14,
      "y": 5,
      "z": -3,
      "name": "Rock_Basalt_Brick"
    },
    {
      "x": -14,
      "y": 6,
      "z": -3,
      "name": "Rock_Basalt_Brick"
    },
    {
      "x": -14,
      "y": 7,
      "z": -3,
      "name": "Rock_Basalt_Brick"
    },
    {
      "x": -14,
      "y": 8,
      "z": -3,
      "name": "Rock_Basalt_Brick"
    },
    {
      "x": -14,
      "y": 9,
      "z": -3,
      "name": "Soil_Clay_Brick"
    },
    {
      "x": -14,
      "y": 10,
      "z": -3,
      "name": "Soil_Clay_Brick"
    },
    {
      "x": -14,
      "y": 11,
      "z": -3,
      "name": "Soil_Clay_Brick"
    },
    {
      "x": -14,
      "y": 0,
      "z": -2,
      "name": "Soil_Clay_Brick"
    },
    {
      "x": -14,
      "y": 1,
      "z": -2,
      "name": "Soil_Clay_Brick"
    },
    {
      "x": -14,
      "y": 2,
      "z": -2,
      "name": "Soil_Clay_Brick"
    },
    {
      "x": -14,
      "y": 3,
      "z": -2,
      "name": "Soil_Clay_Brick"
    },
    {
      "x": -14,
      "y": 4,
      "z": -2,
      "name": "Soil_Dirt_Burnt"
    },
    {
      "x": -14,
      "y": 5,
      "z": -2,
      "name": "Nat20_Force_Empty"
    },
    {
      "x": -14,
      "y": 6,
      "z": -2,
      "name": "Nat20_Force_Empty"
    },
    {
      "x": -14,
      "y": 7,
      "z": -2,
      "name": "Nat20_Force_Empty"
    },
    {
      "x": -14,
      "y": 8,
      "z": -2,
      "name": "Soil_Mud_Dry"
    },
    {
      "x": -14,
      "y": 9,
      "z": -2,
      "name": "Soil_Dirt_Burnt"
    },
    {
      "x": -14,
      "y": 10,
      "z": -2,
      "name": "Soil_Dirt_Burnt"
    },
    {
      "x": -14,
      "y": 11,
      "z": -2,
      "name": "Soil_Clay_Brick"
    },
    {
      "x": -14,
      "y": 0,
      "z": -1,
      "name": "Soil_Clay_Brick"
    },
    {
      "x": -14,
      "y": 1,
      "z": -1,
      "name": "Soil_Clay_Brick"
    },
    {
      "x": -14,
      "y": 2,
      "z": -1,
      "name": "Soil_Clay_Brick"
    },
    {
      "x": -14,
      "y": 3,
      "z": -1,
      "name": "Soil_Clay_Brick"
    },
    {
      "x": -14,
      "y": 4,
      "z": -1,
      "name": "Soil_Clay_Brick"
    },
    {
      "x": -14,
      "y": 5,
      "z": -1,
      "name": "Soil_Mud_Dry"
    },
    {
      "x": -14,
      "y": 6,
      "z": -1,
      "name": "Nat20_Force_Empty"
    },
    {
      "x": -14,
      "y": 7,
      "z": -1,
      "name": "Nat20_Force_Empty"
    },
    {
      "x": -14,
      "y": 8,
      "z": -1,
      "name": "Nat20_Force_Empty"
    },
    {
      "x": -14,
      "y": 9,
      "z": -1,
      "name": "Soil_Dirt_Burnt"
    },
    {
      "x": -14,
      "y": 10,
      "z": -1,
      "name": "Soil_Dirt_Burnt"
    },
    {
      "x": -14,
      "y": 11,
      "z": -1,
      "name": "Soil_Clay_Brick"
    },
    {
      "x": -14,
      "y": 0,
      "z": 0,
      "name": "Soil_Clay_Brick"
    },
    {
      "x": -14,
      "y": 1,
      "z": 0,
      "name": "Soil_Clay_Brick"
    },
    {
      "x": -14,
      "y": 2,
      "z": 0,
      "name": "Soil_Clay_Brick"
    },
    {
      "x": -14,
      "y": 3,
      "z": 0,
      "name": "Soil_Clay_Brick"
    },
    {
      "x": -14,
      "y": 4,
      "z": 0,
      "name": "Soil_Clay_Brick"
    },
    {
      "x": -14,
      "y": 5,
      "z": 0,
      "name": "Soil_Dirt_Burnt"
    },
    {
      "x": -14,
      "y": 6,
      "z": 0,
      "name": "Soil_Dirt_Burnt"
    },
    {
      "x": -14,
      "y": 7,
      "z": 0,
      "name": "Nat20_Force_Empty"
    },
    {
      "x": -14,
      "y": 8,
      "z": 0,
      "name": "Soil_Clay_Brick_Half",
      "rotation": 5
    },
    {
      "x": -14,
      "y": 9,
      "z": 0,
      "name": "Soil_Clay_Brick"
    },
    {
      "x": -14,
      "y": 10,
      "z": 0,
      "name": "Soil_Clay_Brick"
    },
    {
      "x": -14,
      "y": 11,
      "z": 0,
      "name": "Soil_Clay_Brick"
    },
    {
      "x": -14,
      "y": 0,
      "z": 1,
      "name": "Soil_Clay_Brick"
    },
    {
      "x": -14,
      "y": 1,
      "z": 1,
      "name": "Soil_Clay_Brick"
    },
    {
      "x": -14,
      "y": 2,
      "z": 1,
      "name": "Soil_Clay_Brick"
    },
    {
      "x": -14,
      "y": 3,
      "z": 1,
      "name": "Soil_Clay_Brick"
    },
    {
      "x": -14,
      "y": 4,
      "z": 1,
      "name": "Soil_Dirt_Burnt"
    },
    {
      "x": -14,
      "y": 5,
      "z": 1,
      "name": "Soil_Dirt_Burnt"
    },
    {
      "x": -14,
      "y": 6,
      "z": 1,
      "name": "Soil_Dirt_Burnt"
    },
    {
      "x": -14,
      "y": 7,
      "z": 1,
      "name": "Nat20_Force_Empty"
    },
    {
      "x": -14,
      "y": 8,
      "z": 1,
      "name": "Soil_Clay_Brick_Half",
      "rotation": 5
    },
    {
      "x": -14,
      "y": 9,
      "z": 1,
      "name": "Soil_Clay_Brick"
    },
    {
      "x": -14,
      "y": 10,
      "z": 1,
      "name": "Soil_Clay_Brick"
    },
    {
      "x": -14,
      "y": 11,
      "z": 1,
      "name": "Soil_Clay_Brick"
    },
    {
      "x": -14,
      "y": 0,
      "z": 2,
      "name": "Soil_Clay_Brick"
    },
    {
      "x": -14,
      "y": 1,
      "z": 2,
      "name": "Soil_Clay_Brick"
    },
    {
      "x": -14,
      "y": 2,
      "z": 2,
      "name": "Soil_Clay_Brick"
    },
    {
      "x": -14,
      "y": 3,
      "z": 2,
      "name": "Soil_Clay_Brick"
    },
    {
      "x": -14,
      "y": 4,
      "z": 2,
      "name": "Soil_Dirt_Burnt"
    },
    {
      "x": -14,
      "y": 5,
      "z": 2,
      "name": "Plant_Crop_Mushroom_Block_Red"
    },
    {
      "x": -14,
      "y": 6,
      "z": 2,
      "name": "Nat20_Force_Empty"
    },
    {
      "x": -14,
      "y": 7,
      "z": 2,
      "name": "Nat20_Force_Empty"
    },
    {
      "x": -14,
      "y": 8,
      "z": 2,
      "name": "Soil_Dirt_Burnt"
    },
    {
      "x": -14,
      "y": 9,
      "z": 2,
      "name": "Soil_Mud_Dry"
    },
    {
      "x": -14,
      "y": 10,
      "z": 2,
      "name": "Soil_Clay_Brick"
    },
    {
      "x": -14,
      "y": 11,
      "z": 2,
      "name": "Soil_Clay_Brick"
    },
    {
      "x": -14,
      "y": 0,
      "z": 3,
      "name": "Soil_Clay_Brick"
    },
    {
      "x": -14,
      "y": 1,
      "z": 3,
      "name": "Soil_Clay_Brick"
    },
    {
      "x": -14,
      "y": 2,
      "z": 3,
      "name": "Soil_Clay_Brick"
    },
    {
      "x": -14,
      "y": 3,
      "z": 3,
      "name": "Soil_Clay_Brick"
    },
    {
      "x": -14,
      "y": 4,
      "z": 3,
      "name": "Soil_Dirt_Burnt"
    },
    {
      "x": -14,
      "y": 5,
      "z": 3,
      "name": "Plant_Crop_Mushroom_Block_Red"
    },
    {
      "x": -14,
      "y": 6,
      "z": 3,
      "name": "Plant_Coral_Model_Orange"
    },
    {
      "x": -14,
      "y": 7,
      "z": 3,
      "name": "Nat20_Force_Empty"
    },
    {
      "x": -14,
      "y": 8,
      "z": 3,
      "name": "Soil_Dirt_Burnt"
    },
    {
      "x": -14,
      "y": 9,
      "z": 3,
      "name": "Soil_Mud_Dry"
    },
    {
      "x": -14,
      "y": 10,
      "z": 3,
      "name": "Soil_Clay_Brick"
    },
    {
      "x": -14,
      "y": 11,
      "z": 3,
      "name": "Soil_Clay_Brick"
    },
    {
      "x": -14,
      "y": 0,
      "z": 4,
      "name": "Soil_Clay_Brick"
    },
    {
      "x": -14,
      "y": 1,
      "z": 4,
      "name": "Soil_Clay_Brick"
    },
    {
      "x": -14,
      "y": 2,
      "z": 4,
      "name": "Soil_Clay_Brick"
    },
    {
      "x": -14,
      "y": 3,
      "z": 4,
      "name": "Soil_Clay_Brick"
    },
    {
      "x": -14,
      "y": 4,
      "z": 4,
      "name": "Soil_Dirt_Burnt"
    },
    {
      "x": -14,
      "y": 5,
      "z": 4,
      "name": "Plant_Crop_Mushroom_Block_Red"
    },
    {
      "x": -14,
      "y": 6,
      "z": 4,
      "name": "Plant_Crop_Mushroom_Block_Red"
    },
    {
      "x": -14,
      "y": 7,
      "z": 4,
      "name": "Plant_Coral_Model_Orange"
    },
    {
      "x": -14,
      "y": 8,
      "z": 4,
      "name": "Soil_Clay_Brick_Half",
      "rotation": 5
    },
    {
      "x": -14,
      "y": 9,
      "z": 4,
      "name": "Soil_Mud_Dry"
    },
    {
      "x": -14,
      "y": 10,
      "z": 4,
      "name": "Soil_Mud_Dry"
    },
    {
      "x": -14,
      "y": 11,
      "z": 4,
      "name": "Soil_Clay_Brick"
    },
    {
      "x": -14,
      "y": 0,
      "z": 5,
      "name": "Soil_Clay_Brick"
    },
    {
      "x": -14,
      "y": 1,
      "z": 5,
      "name": "Soil_Clay_Brick"
    },
    {
      "x": -14,
      "y": 2,
      "z": 5,
      "name": "Soil_Clay_Brick"
    },
    {
      "x": -14,
      "y": 3,
      "z": 5,
      "name": "Soil_Clay_Brick"
    },
    {
      "x": -14,
      "y": 4,
      "z": 5,
      "name": "Soil_Clay_Brick"
    },
    {
      "x": -14,
      "y": 5,
      "z": 5,
      "name": "Soil_Dirt_Burnt"
    },
    {
      "x": -14,
      "y": 6,
      "z": 5,
      "name": "Rock_Basalt_Brick"
    },
    {
      "x": -14,
      "y": 7,
      "z": 5,
      "name": "Rock_Basalt_Brick"
    },
    {
      "x": -14,
      "y": 8,
      "z": 5,
      "name": "Rock_Basalt_Brick"
    },
    {
      "x": -14,
      "y": 9,
      "z": 5,
      "name": "Soil_Clay_Brick"
    },
    {
      "x": -14,
      "y": 10,
      "z": 5,
      "name": "Soil_Clay_Brick"
    },
    {
      "x": -14,
      "y": 11,
      "z": 5,
      "name": "Soil_Clay_Brick"
    },
    {
      "x": -14,
      "y": 0,
      "z": 6,
      "name": "Soil_Clay_Brick"
    },
    {
      "x": -14,
      "y": 1,
      "z": 6,
      "name": "Soil_Clay_Brick"
    },
    {
      "x": -14,
      "y": 2,
      "z": 6,
      "name": "Soil_Clay_Brick"
    },
    {
      "x": -14,
      "y": 3,
      "z": 6,
      "name": "Soil_Clay_Brick"
    },
    {
      "x": -14,
      "y": 4,
      "z": 6,
      "name": "Soil_Clay_Brick"
    },
    {
      "x": -14,
      "y": 5,
      "z": 6,
      "name": "Rock_Basalt_Brick"
    },
    {
      "x": -14,
      "y": 6,
      "z": 6,
      "name": "Rock_Basalt_Brick"
    },
    {
      "x": -14,
      "y": 7,
      "z": 6,
      "name": "Rock_Basalt_Brick"
    },
    {
      "x": -14,
      "y": 8,
      "z": 6,
      "name": "Rock_Basalt_Brick"
    },
    {
      "x": -14,
      "y": 9,
      "z": 6,
      "name": "Soil_Clay_Brick"
    },
    {
      "x": -14,
      "y": 10,
      "z": 6,
      "name": "Soil_Clay_Brick"
    },
    {
      "x": -14,
      "y": 11,
      "z": 6,
      "name": "Soil_Clay_Brick"
    },
    {
      "x": -14,
      "y": 0,
      "z": 7,
      "name": "Soil_Clay_Brick"
    },
    {
      "x": -14,
      "y": 1,
      "z": 7,
      "name": "Soil_Clay_Brick"
    },
    {
      "x": -14,
      "y": 2,
      "z": 7,
      "name": "Soil_Clay_Brick"
    },
    {
      "x": -14,
      "y": 3,
      "z": 7,
      "name": "Soil_Clay_Brick"
    },
    {
      "x": -14,
      "y": 4,
      "z": 7,
      "name": "Soil_Dirt_Burnt"
    },
    {
      "x": -14,
      "y": 5,
      "z": 7,
      "name": "Soil_Dirt_Burnt"
    },
    {
      "x": -14,
      "y": 6,
      "z": 7,
      "name": "Soil_Dirt_Burnt"
    },
    {
      "x": -14,
      "y": 7,
      "z": 7,
      "name": "Soil_Dirt_Burnt"
    },
    {
      "x": -14,
      "y": 8,
      "z": 7,
      "name": "Soil_Clay_Brick_Half",
      "rotation": 5
    },
    {
      "x": -14,
      "y": 9,
      "z": 7,
      "name": "Soil_Clay_Brick"
    },
    {
      "x": -14,
      "y": 10,
      "z": 7,
      "name": "Soil_Clay_Brick"
    },
    {
      "x": -14,
      "y": 11,
      "z": 7,
      "name": "Soil_Clay_Brick"
    },
    {
      "x": -14,
      "y": 0,
      "z": 8,
      "name": "Soil_Clay_Brick"
    },
    {
      "x": -14,
      "y": 1,
      "z": 8,
      "name": "Soil_Clay_Brick"
    },
    {
      "x": -14,
      "y": 2,
      "z": 8,
      "name": "Soil_Clay_Brick"
    },
    {
      "x": -14,
      "y": 3,
      "z": 8,
      "name": "Soil_Clay_Brick"
    },
    {
      "x": -14,
      "y": 4,
      "z": 8,
      "name": "Soil_Dirt_Burnt"
    },
    {
      "x": -14,
      "y": 5,
      "z": 8,
      "name": "Soil_Dirt_Burnt"
    },
    {
      "x": -14,
      "y": 6,
      "z": 8,
      "name": "Nat20_Force_Empty"
    },
    {
      "x": -14,
      "y": 7,
      "z": 8,
      "name": "Nat20_Force_Empty"
    },
    {
      "x": -14,
      "y": 8,
      "z": 8,
      "name": "Soil_Clay_Brick_Half",
      "rotation": 5
    },
    {
      "x": -14,
      "y": 9,
      "z": 8,
      "name": "Soil_Clay_Brick"
    },
    {
      "x": -14,
      "y": 10,
      "z": 8,
      "name": "Soil_Clay_Brick"
    },
    {
      "x": -14,
      "y": 11,
      "z": 8,
      "name": "Soil_Clay_Brick"
    },
    {
      "x": -14,
      "y": 0,
      "z": 9,
      "name": "Soil_Clay_Brick"
    },
    {
      "x": -14,
      "y": 1,
      "z": 9,
      "name": "Soil_Clay_Brick"
    },
    {
      "x": -14,
      "y": 2,
      "z": 9,
      "name": "Soil_Clay_Brick"
    },
    {
      "x": -14,
      "y": 3,
      "z": 9,
      "name": "Soil_Clay_Brick"
    },
    {
      "x": -14,
      "y": 4,
      "z": 9,
      "name": "Soil_Mud_Dry"
    },
    {
      "x": -14,
      "y": 5,
      "z": 9,
      "name": "Plant_Bush_Dead_Twisted"
    },
    {
      "x": -14,
      "y": 6,
      "z": 9,
      "name": "Nat20_Force_Empty"
    },
    {
      "x": -14,
      "y": 7,
      "z": 9,
      "name": "Nat20_Force_Empty"
    },
    {
      "x": -14,
      "y": 8,
      "z": 9,
      "name": "Soil_Clay_Brick_Half",
      "rotation": 5
    },
    {
      "x": -14,
      "y": 9,
      "z": 9,
      "name": "Soil_Clay_Brick"
    },
    {
      "x": -14,
      "y": 10,
      "z": 9,
      "name": "Soil_Clay_Brick"
    },
    {
      "x": -14,
      "y": 11,
      "z": 9,
      "name": "Soil_Clay_Brick"
    },
    {
      "x": -14,
      "y": 0,
      "z": 10,
      "name": "Soil_Clay_Brick"
    },
    {
      "x": -14,
      "y": 1,
      "z": 10,
      "name": "Soil_Clay_Brick"
    },
    {
      "x": -14,
      "y": 2,
      "z": 10,
      "name": "Soil_Clay_Brick"
    },
    {
      "x": -14,
      "y": 3,
      "z": 10,
      "name": "Soil_Clay_Brick"
    },
    {
      "x": -14,
      "y": 4,
      "z": 10,
      "name": "Soil_Mud_Dry"
    },
    {
      "x": -14,
      "y": 5,
      "z": 10,
      "name": "Nat20_Force_Empty"
    },
    {
      "x": -14,
      "y": 6,
      "z": 10,
      "name": "Nat20_Force_Empty"
    },
    {
      "x": -14,
      "y": 7,
      "z": 10,
      "name": "Nat20_Force_Empty"
    },
    {
      "x": -14,
      "y": 8,
      "z": 10,
      "name": "Soil_Dirt_Burnt"
    },
    {
      "x": -14,
      "y": 9,
      "z": 10,
      "name": "Soil_Dirt_Burnt"
    },
    {
      "x": -14,
      "y": 10,
      "z": 10,
      "name": "Soil_Clay_Brick"
    },
    {
      "x": -14,
      "y": 11,
      "z": 10,
      "name": "Soil_Clay_Brick"
    },
    {
      "x": -14,
      "y": 0,
      "z": 11,
      "name": "Soil_Clay_Brick"
    },
    {
      "x": -14,
      "y": 1,
      "z": 11,
      "name": "Soil_Clay_Brick"
    },
    {
      "x": -14,
      "y": 2,
      "z": 11,
      "name": "Soil_Clay_Brick"
    },
    {
      "x": -14,
      "y": 3,
      "z": 11,
      "name": "Soil_Clay_Brick"
    },
    {
      "x": -14,
      "y": 4,
      "z": 11,
      "name": "Soil_Clay_Brick"
    },
    {
      "x": -14,
      "y": 5,
      "z": 11,
      "name": "Rail",
      "rotation": 1
    },
    {
      "x": -14,
      "y": 6,
      "z": 11,
      "name": "Nat20_Force_Empty"
    },
    {
      "x": -14,
      "y": 7,
      "z": 11,
      "name": "Nat20_Force_Empty"
    },
    {
      "x": -14,
      "y": 8,
      "z": 11,
      "name": "Soil_Dirt_Burnt"
    },
    {
      "x": -14,
      "y": 9,
      "z": 11,
      "name": "Soil_Dirt_Burnt"
    },
    {
      "x": -14,
      "y": 10,
      "z": 11,
      "name": "Soil_Dirt_Burnt"
    },
    {
      "x": -14,
      "y": 11,
      "z": 11,
      "name": "Soil_Clay_Brick"
    },
    {
      "x": -14,
      "y": 0,
      "z": 12,
      "name": "Soil_Clay_Brick"
    },
    {
      "x": -14,
      "y": 1,
      "z": 12,
      "name": "Soil_Clay_Brick"
    },
    {
      "x": -14,
      "y": 2,
      "z": 12,
      "name": "Soil_Clay_Brick"
    },
    {
      "x": -14,
      "y": 3,
      "z": 12,
      "name": "Soil_Clay_Brick"
    },
    {
      "x": -14,
      "y": 4,
      "z": 12,
      "name": "Soil_Dirt_Burnt"
    },
    {
      "x": -14,
      "y": 5,
      "z": 12,
      "name": "Soil_Dirt_Burnt"
    },
    {
      "x": -14,
      "y": 6,
      "z": 12,
      "name": "Nat20_Force_Empty"
    },
    {
      "x": -14,
      "y": 7,
      "z": 12,
      "name": "Nat20_Force_Empty"
    },
    {
      "x": -14,
      "y": 8,
      "z": 12,
      "name": "Soil_Clay_Brick_Half",
      "rotation": 5
    },
    {
      "x": -14,
      "y": 9,
      "z": 12,
      "name": "Soil_Clay_Brick"
    },
    {
      "x": -14,
      "y": 10,
      "z": 12,
      "name": "Soil_Dirt_Burnt"
    },
    {
      "x": -14,
      "y": 11,
      "z": 12,
      "name": "Soil_Clay_Brick"
    },
    {
      "x": -14,
      "y": 0,
      "z": 13,
      "name": "Soil_Clay_Brick"
    },
    {
      "x": -14,
      "y": 1,
      "z": 13,
      "name": "Soil_Clay_Brick"
    },
    {
      "x": -14,
      "y": 2,
      "z": 13,
      "name": "Soil_Clay_Brick"
    },
    {
      "x": -14,
      "y": 3,
      "z": 13,
      "name": "Soil_Clay_Brick"
    },
    {
      "x": -14,
      "y": 4,
      "z": 13,
      "name": "Soil_Dirt_Burnt"
    },
    {
      "x": -14,
      "y": 5,
      "z": 13,
      "name": "Soil_Dirt_Burnt"
    },
    {
      "x": -14,
      "y": 6,
      "z": 13,
      "name": "Nat20_Force_Empty"
    },
    {
      "x": -14,
      "y": 7,
      "z": 13,
      "name": "Nat20_Force_Empty"
    },
    {
      "x": -14,
      "y": 8,
      "z": 13,
      "name": "Soil_Clay_Brick_Half",
      "rotation": 5
    },
    {
      "x": -14,
      "y": 9,
      "z": 13,
      "name": "Soil_Clay_Brick"
    },
    {
      "x": -14,
      "y": 10,
      "z": 13,
      "name": "Soil_Clay_Brick"
    },
    {
      "x": -14,
      "y": 11,
      "z": 13,
      "name": "Soil_Clay_Brick"
    },
    {
      "x": -14,
      "y": 0,
      "z": 14,
      "name": "Soil_Clay_Brick"
    },
    {
      "x": -14,
      "y": 1,
      "z": 14,
      "name": "Soil_Clay_Brick"
    },
    {
      "x": -14,
      "y": 2,
      "z": 14,
      "name": "Soil_Clay_Brick"
    },
    {
      "x": -14,
      "y": 3,
      "z": 14,
      "name": "Soil_Clay_Brick"
    },
    {
      "x": -14,
      "y": 4,
      "z": 14,
      "name": "Soil_Dirt_Burnt"
    },
    {
      "x": -14,
      "y": 5,
      "z": 14,
      "name": "Rock_Basalt_Brick"
    },
    {
      "x": -14,
      "y": 6,
      "z": 14,
      "name": "Rock_Basalt_Brick"
    },
    {
      "x": -14,
      "y": 7,
      "z": 14,
      "name": "Rock_Basalt_Brick"
    },
    {
      "x": -14,
      "y": 8,
      "z": 14,
      "name": "Rock_Basalt_Brick"
    },
    {
      "x": -14,
      "y": 9,
      "z": 14,
      "name": "Rock_Basalt_Brick"
    },
    {
      "x": -14,
      "y": 10,
      "z": 14,
      "name": "Rock_Basalt_Brick"
    },
    {
      "x": -14,
      "y": 11,
      "z": 14,
      "name": "Soil_Clay_Brick"
    },
    {
      "x": -14,
      "y": 0,
      "z": 15,
      "name": "Soil_Clay_Brick"
    },
    {
      "x": -14,
      "y": 1,
      "z": 15,
      "name": "Soil_Clay_Brick"
    },
    {
      "x": -14,
      "y": 2,
      "z": 15,
      "name": "Soil_Clay_Brick"
    },
    {
      "x": -14,
      "y": 3,
      "z": 15,
      "name": "Rock_Basalt_Brick"
    },
    {
      "x": -14,
      "y": 4,
      "z": 15,
      "name": "Rock_Basalt_Brick"
    },
    {
      "x": -14,
      "y": 5,
      "z": 15,
      "name": "Rock_Basalt_Brick"
    },
    {
      "x": -14,
      "y": 6,
      "z": 15,
      "name": "Rock_Basalt_Brick"
    },
    {
      "x": -14,
      "y": 7,
      "z": 15,
      "name": "Rock_Basalt_Brick"
    },
    {
      "x": -14,
      "y": 8,
      "z": 15,
      "name": "Rock_Basalt_Brick"
    },
    {
      "x": -14,
      "y": 9,
      "z": 15,
      "name": "Rock_Basalt_Brick"
    },
    {
      "x": -14,
      "y": 10,
      "z": 15,
      "name": "Rock_Basalt_Brick"
    },
    {
      "x": -13,
      "y": 0,
      "z": -14,
      "name": "Soil_Clay_Brick"
    },
    {
      "x": -13,
      "y": 1,
      "z": -14,
      "name": "Soil_Clay_Brick"
    },
    {
      "x": -13,
      "y": 2,
      "z": -14,
      "name": "Soil_Clay_Brick"
    },
    {
      "x": -13,
      "y": 3,
      "z": -14,
      "name": "Soil_Clay_Brick"
    },
    {
      "x": -13,
      "y": 4,
      "z": -14,
      "name": "Soil_Dirt_Burnt"
    },
    {
      "x": -13,
      "y": 5,
      "z": -14,
      "name": "Soil_Dirt_Burnt"
    },
    {
      "x": -13,
      "y": 6,
      "z": -14,
      "name": "Nat20_Force_Empty"
    },
    {
      "x": -13,
      "y": 7,
      "z": -14,
      "name": "Nat20_Force_Empty"
    },
    {
      "x": -13,
      "y": 8,
      "z": -14,
      "name": "Soil_Clay_Brick_Half",
      "rotation": 4
    },
    {
      "x": -13,
      "y": 9,
      "z": -14,
      "name": "Soil_Clay_Brick"
    },
    {
      "x": -13,
      "y": 10,
      "z": -14,
      "name": "Soil_Clay_Brick"
    },
    {
      "x": -13,
      "y": 11,
      "z": -14,
      "name": "Soil_Clay_Brick"
    },
    {
      "x": -13,
      "y": 0,
      "z": -13,
      "name": "Soil_Clay_Brick"
    },
    {
      "x": -13,
      "y": 1,
      "z": -13,
      "name": "Soil_Clay_Brick"
    },
    {
      "x": -13,
      "y": 2,
      "z": -13,
      "name": "Soil_Clay_Brick"
    },
    {
      "x": -13,
      "y": 3,
      "z": -13,
      "name": "Soil_Clay_Brick"
    },
    {
      "x": -13,
      "y": 4,
      "z": -13,
      "name": "Rock_Basalt_Brick"
    },
    {
      "x": -13,
      "y": 5,
      "z": -13,
      "name": "*Rail_State_Definitions_Corner_Left"
    },
    {
      "x": -13,
      "y": 6,
      "z": -13,
      "name": "Nat20_Force_Empty"
    },
    {
      "x": -13,
      "y": 7,
      "z": -13,
      "name": "Nat20_Force_Empty"
    },
    {
      "x": -13,
      "y": 8,
      "z": -13,
      "name": "Nat20_Force_Empty"
    },
    {
      "x": -13,
      "y": 9,
      "z": -13,
      "name": "Nat20_Force_Empty"
    },
    {
      "x": -13,
      "y": 10,
      "z": -13,
      "name": "Soil_Clay_Brick_Half",
      "rotation": 8
    },
    {
      "x": -13,
      "y": 11,
      "z": -13,
      "name": "Soil_Clay_Brick"
    },
    {
      "x": -13,
      "y": 12,
      "z": -13,
      "name": "Soil_Clay_Brick"
    },
    {
      "x": -13,
      "y": 0,
      "z": -12,
      "name": "Soil_Clay_Brick"
    },
    {
      "x": -13,
      "y": 1,
      "z": -12,
      "name": "Rock_Basalt_Brick"
    },
    {
      "x": -13,
      "y": 2,
      "z": -12,
      "name": "Rock_Basalt_Brick"
    },
    {
      "x": -13,
      "y": 3,
      "z": -12,
      "name": "Rock_Basalt_Brick"
    },
    {
      "x": -13,
      "y": 4,
      "z": -12,
      "name": "Rock_Basalt_Brick"
    },
    {
      "x": -13,
      "y": 5,
      "z": -12,
      "name": "*Rail_State_Definitions_Cross"
    },
    {
      "x": -13,
      "y": 6,
      "z": -12,
      "name": "Nat20_Force_Empty"
    },
    {
      "x": -13,
      "y": 7,
      "z": -12,
      "name": "Nat20_Force_Empty"
    },
    {
      "x": -13,
      "y": 8,
      "z": -12,
      "name": "Nat20_Force_Empty"
    },
    {
      "x": -13,
      "y": 9,
      "z": -12,
      "name": "Nat20_Force_Empty"
    },
    {
      "x": -13,
      "y": 10,
      "z": -12,
      "name": "Soil_Dirt_Burnt"
    },
    {
      "x": -13,
      "y": 11,
      "z": -12,
      "name": "Soil_Dirt_Burnt"
    },
    {
      "x": -13,
      "y": 12,
      "z": -12,
      "name": "Soil_Clay_Brick"
    },
    {
      "x": -13,
      "y": 0,
      "z": -11,
      "name": "Soil_Clay_Brick"
    },
    {
      "x": -13,
      "y": 1,
      "z": -11,
      "name": "Rock_Basalt_Brick"
    },
    {
      "x": -13,
      "y": 2,
      "z": -11,
      "name": "Rock_Basalt_Brick"
    },
    {
      "x": -13,
      "y": 3,
      "z": -11,
      "name": "Rock_Basalt_Brick"
    },
    {
      "x": -13,
      "y": 4,
      "z": -11,
      "name": "Rock_Basalt_Brick"
    },
    {
      "x": -13,
      "y": 5,
      "z": -11,
      "name": "Rail"
    },
    {
      "x": -13,
      "y": 6,
      "z": -11,
      "name": "Nat20_Force_Empty"
    },
    {
      "x": -13,
      "y": 7,
      "z": -11,
      "name": "Nat20_Force_Empty"
    },
    {
      "x": -13,
      "y": 8,
      "z": -11,
      "name": "Nat20_Force_Empty"
    },
    {
      "x": -13,
      "y": 9,
      "z": -11,
      "name": "Nat20_Force_Empty"
    },
    {
      "x": -13,
      "y": 10,
      "z": -11,
      "name": "Soil_Dirt_Burnt"
    },
    {
      "x": -13,
      "y": 11,
      "z": -11,
      "name": "Soil_Dirt_Burnt"
    },
    {
      "x": -13,
      "y": 12,
      "z": -11,
      "name": "Soil_Clay_Brick"
    },
    {
      "x": -13,
      "y": 0,
      "z": -10,
      "name": "Soil_Clay_Brick"
    },
    {
      "x": -13,
      "y": 1,
      "z": -10,
      "name": "Soil_Dirt_Poisoned"
    },
    {
      "x": -13,
      "y": 2,
      "z": -10,
      "name": "Empty"
    },
    {
      "x": -13,
      "y": 3,
      "z": -10,
      "name": "Empty"
    },
    {
      "x": -13,
      "y": 4,
      "z": -10,
      "name": "Furniture_Crude_Platform"
    },
    {
      "x": -13,
      "y": 5,
      "z": -10,
      "name": "Rail"
    },
    {
      "x": -13,
      "y": 6,
      "z": -10,
      "name": "Nat20_Force_Empty"
    },
    {
      "x": -13,
      "y": 7,
      "z": -10,
      "name": "Nat20_Force_Empty"
    },
    {
      "x": -13,
      "y": 8,
      "z": -10,
      "name": "Nat20_Force_Empty"
    },
    {
      "x": -13,
      "y": 9,
      "z": -10,
      "name": "Nat20_Force_Empty"
    },
    {
      "x": -13,
      "y": 10,
      "z": -10,
      "name": "Soil_Dirt_Burnt"
    },
    {
      "x": -13,
      "y": 11,
      "z": -10,
      "name": "Soil_Dirt_Burnt"
    },
    {
      "x": -13,
      "y": 12,
      "z": -10,
      "name": "Soil_Clay_Brick"
    },
    {
      "x": -13,
      "y": 0,
      "z": -9,
      "name": "Soil_Clay_Brick"
    },
    {
      "x": -13,
      "y": 1,
      "z": -9,
      "name": "Soil_Dirt_Poisoned"
    },
    {
      "x": -13,
      "y": 2,
      "z": -9,
      "name": "Empty"
    },
    {
      "x": -13,
      "y": 3,
      "z": -9,
      "name": "Empty"
    },
    {
      "x": -13,
      "y": 4,
      "z": -9,
      "name": "Furniture_Crude_Platform"
    },
    {
      "x": -13,
      "y": 5,
      "z": -9,
      "name": "Nat20_Force_Empty"
    },
    {
      "x": -13,
      "y": 6,
      "z": -9,
      "name": "Nat20_Force_Empty"
    },
    {
      "x": -13,
      "y": 7,
      "z": -9,
      "name": "Nat20_Force_Empty"
    },
    {
      "x": -13,
      "y": 8,
      "z": -9,
      "name": "Nat20_Force_Empty"
    },
    {
      "x": -13,
      "y": 9,
      "z": -9,
      "name": "Nat20_Force_Empty"
    },
    {
      "x": -13,
      "y": 10,
      "z": -9,
      "name": "Soil_Clay_Brick_Half",
      "rotation": 8
    },
    {
      "x": -13,
      "y": 11,
      "z": -9,
      "name": "Soil_Clay_Brick"
    },
    {
      "x": -13,
      "y": 12,
      "z": -9,
      "name": "Soil_Clay_Brick"
    },
    {
      "x": -13,
      "y": 0,
      "z": -8,
      "name": "Soil_Clay_Brick"
    },
    {
      "x": -13,
      "y": 1,
      "z": -8,
      "name": "Soil_Dirt_Poisoned"
    },
    {
      "x": -13,
      "y": 2,
      "z": -8,
      "name": "Empty"
    },
    {
      "x": -13,
      "y": 3,
      "z": -8,
      "name": "Empty"
    },
    {
      "x": -13,
      "y": 4,
      "z": -8,
      "name": "Furniture_Crude_Platform"
    },
    {
      "x": -13,
      "y": 5,
      "z": -8,
      "name": "Nat20_Force_Empty"
    },
    {
      "x": -13,
      "y": 6,
      "z": -8,
      "name": "Nat20_Force_Empty"
    },
    {
      "x": -13,
      "y": 7,
      "z": -8,
      "name": "Nat20_Force_Empty"
    },
    {
      "x": -13,
      "y": 8,
      "z": -8,
      "name": "Nat20_Force_Empty"
    },
    {
      "x": -13,
      "y": 9,
      "z": -8,
      "name": "Nat20_Force_Empty"
    },
    {
      "x": -13,
      "y": 10,
      "z": -8,
      "name": "Soil_Clay_Brick_Half",
      "rotation": 8
    },
    {
      "x": -13,
      "y": 11,
      "z": -8,
      "name": "Soil_Clay_Brick"
    },
    {
      "x": -13,
      "y": 12,
      "z": -8,
      "name": "Soil_Clay_Brick"
    },
    {
      "x": -13,
      "y": 0,
      "z": -7,
      "name": "Soil_Clay_Brick"
    },
    {
      "x": -13,
      "y": 1,
      "z": -7,
      "name": "Rock_Basalt_Brick"
    },
    {
      "x": -13,
      "y": 2,
      "z": -7,
      "name": "Rock_Basalt_Brick"
    },
    {
      "x": -13,
      "y": 3,
      "z": -7,
      "name": "Rock_Basalt_Brick"
    },
    {
      "x": -13,
      "y": 4,
      "z": -7,
      "name": "Rock_Basalt_Brick"
    },
    {
      "x": -13,
      "y": 5,
      "z": -7,
      "name": "Nat20_Force_Empty"
    },
    {
      "x": -13,
      "y": 6,
      "z": -7,
      "name": "Nat20_Force_Empty"
    },
    {
      "x": -13,
      "y": 7,
      "z": -7,
      "name": "Nat20_Force_Empty"
    },
    {
      "x": -13,
      "y": 8,
      "z": -7,
      "name": "Nat20_Force_Empty"
    },
    {
      "x": -13,
      "y": 9,
      "z": -7,
      "name": "Nat20_Force_Empty"
    },
    {
      "x": -13,
      "y": 10,
      "z": -7,
      "name": "Soil_Dirt_Burnt"
    },
    {
      "x": -13,
      "y": 11,
      "z": -7,
      "name": "Soil_Clay_Brick"
    },
    {
      "x": -13,
      "y": 12,
      "z": -7,
      "name": "Soil_Clay_Brick"
    },
    {
      "x": -13,
      "y": 0,
      "z": -6,
      "name": "Soil_Clay_Brick"
    },
    {
      "x": -13,
      "y": 1,
      "z": -6,
      "name": "Rock_Basalt_Brick"
    },
    {
      "x": -13,
      "y": 2,
      "z": -6,
      "name": "Rock_Basalt_Brick"
    },
    {
      "x": -13,
      "y": 3,
      "z": -6,
      "name": "Rock_Basalt_Brick"
    },
    {
      "x": -13,
      "y": 4,
      "z": -6,
      "name": "Rock_Basalt_Brick"
    },
    {
      "x": -13,
      "y": 5,
      "z": -6,
      "name": "Nat20_Force_Empty"
    },
    {
      "x": -13,
      "y": 6,
      "z": -6,
      "name": "Nat20_Force_Empty"
    },
    {
      "x": -13,
      "y": 7,
      "z": -6,
      "name": "Nat20_Force_Empty"
    },
    {
      "x": -13,
      "y": 8,
      "z": -6,
      "name": "Nat20_Force_Empty"
    },
    {
      "x": -13,
      "y": 9,
      "z": -6,
      "name": "Nat20_Force_Empty"
    },
    {
      "x": -13,
      "y": 10,
      "z": -6,
      "name": "Soil_Dirt_Burnt"
    },
    {
      "x": -13,
      "y": 11,
      "z": -6,
      "name": "Soil_Clay_Brick"
    },
    {
      "x": -13,
      "y": 12,
      "z": -6,
      "name": "Soil_Clay_Brick"
    },
    {
      "x": -13,
      "y": 0,
      "z": -5,
      "name": "Soil_Clay_Brick"
    },
    {
      "x": -13,
      "y": 1,
      "z": -5,
      "name": "Soil_Clay_Brick"
    },
    {
      "x": -13,
      "y": 2,
      "z": -5,
      "name": "Soil_Clay_Brick"
    },
    {
      "x": -13,
      "y": 3,
      "z": -5,
      "name": "Rock_Basalt_Brick"
    },
    {
      "x": -13,
      "y": 4,
      "z": -5,
      "name": "Rock_Basalt_Brick"
    },
    {
      "x": -13,
      "y": 5,
      "z": -5,
      "name": "Nat20_Force_Empty"
    },
    {
      "x": -13,
      "y": 6,
      "z": -5,
      "name": "Nat20_Force_Empty"
    },
    {
      "x": -13,
      "y": 7,
      "z": -5,
      "name": "Nat20_Force_Empty"
    },
    {
      "x": -13,
      "y": 8,
      "z": -5,
      "name": "Nat20_Force_Empty"
    },
    {
      "x": -13,
      "y": 9,
      "z": -5,
      "name": "Soil_Dirt_Burnt"
    },
    {
      "x": -13,
      "y": 10,
      "z": -5,
      "name": "Soil_Dirt_Burnt"
    },
    {
      "x": -13,
      "y": 11,
      "z": -5,
      "name": "Soil_Clay_Brick"
    },
    {
      "x": -13,
      "y": 12,
      "z": -5,
      "name": "Soil_Clay_Brick"
    },
    {
      "x": -13,
      "y": 0,
      "z": -4,
      "name": "Soil_Clay_Brick"
    },
    {
      "x": -13,
      "y": 1,
      "z": -4,
      "name": "Soil_Clay_Brick"
    },
    {
      "x": -13,
      "y": 2,
      "z": -4,
      "name": "Soil_Clay_Brick"
    },
    {
      "x": -13,
      "y": 3,
      "z": -4,
      "name": "Rock_Basalt_Brick"
    },
    {
      "x": -13,
      "y": 4,
      "z": -4,
      "name": "Soil_Dirt_Burnt"
    },
    {
      "x": -13,
      "y": 5,
      "z": -4,
      "name": "Nat20_Force_Empty"
    },
    {
      "x": -13,
      "y": 6,
      "z": -4,
      "name": "Nat20_Force_Empty"
    },
    {
      "x": -13,
      "y": 7,
      "z": -4,
      "name": "Rock_Basalt_Brick_Half",
      "rotation": 5
    },
    {
      "x": -13,
      "y": 8,
      "z": -4,
      "name": "Rock_Basalt_Brick_Half",
      "rotation": 5
    },
    {
      "x": -13,
      "y": 9,
      "z": -4,
      "name": "Rock_Basalt_Brick"
    },
    {
      "x": -13,
      "y": 10,
      "z": -4,
      "name": "Rock_Basalt_Brick"
    },
    {
      "x": -13,
      "y": 11,
      "z": -4,
      "name": "Soil_Clay_Brick"
    },
    {
      "x": -13,
      "y": 12,
      "z": -4,
      "name": "Soil_Clay_Brick"
    },
    {
      "x": -13,
      "y": 0,
      "z": -3,
      "name": "Soil_Clay_Brick"
    },
    {
      "x": -13,
      "y": 1,
      "z": -3,
      "name": "Soil_Clay_Brick"
    },
    {
      "x": -13,
      "y": 2,
      "z": -3,
      "name": "Soil_Clay_Brick"
    },
    {
      "x": -13,
      "y": 3,
      "z": -3,
      "name": "Rock_Basalt_Brick"
    },
    {
      "x": -13,
      "y": 4,
      "z": -3,
      "name": "Soil_Dirt_Burnt"
    },
    {
      "x": -13,
      "y": 5,
      "z": -3,
      "name": "Nat20_Force_Empty"
    },
    {
      "x": -13,
      "y": 6,
      "z": -3,
      "name": "Nat20_Force_Empty"
    },
    {
      "x": -13,
      "y": 7,
      "z": -3,
      "name": "Rock_Basalt_Brick_Half",
      "rotation": 5
    },
    {
      "x": -13,
      "y": 8,
      "z": -3,
      "name": "Rock_Basalt_Brick_Half",
      "rotation": 5
    },
    {
      "x": -13,
      "y": 9,
      "z": -3,
      "name": "Rock_Basalt_Brick"
    },
    {
      "x": -13,
      "y": 10,
      "z": -3,
      "name": "Rock_Basalt_Brick"
    },
    {
      "x": -13,
      "y": 11,
      "z": -3,
      "name": "Soil_Clay_Brick"
    },
    {
      "x": -13,
      "y": 12,
      "z": -3,
      "name": "Soil_Clay_Brick"
    },
    {
      "x": -13,
      "y": 0,
      "z": -2,
      "name": "Soil_Clay_Brick"
    },
    {
      "x": -13,
      "y": 1,
      "z": -2,
      "name": "Soil_Clay_Brick"
    },
    {
      "x": -13,
      "y": 2,
      "z": -2,
      "name": "Soil_Clay_Brick"
    },
    {
      "x": -13,
      "y": 3,
      "z": -2,
      "name": "Rock_Basalt_Brick"
    },
    {
      "x": -13,
      "y": 4,
      "z": -2,
      "name": "Soil_Dirt_Burnt"
    },
    {
      "x": -13,
      "y": 5,
      "z": -2,
      "name": "Plant_Bush_Dead_Twisted"
    },
    {
      "x": -13,
      "y": 6,
      "z": -2,
      "name": "Nat20_Force_Empty"
    },
    {
      "x": -13,
      "y": 7,
      "z": -2,
      "name": "Nat20_Force_Empty"
    },
    {
      "x": -13,
      "y": 8,
      "z": -2,
      "name": "Nat20_Force_Empty"
    },
    {
      "x": -13,
      "y": 9,
      "z": -2,
      "name": "Nat20_Force_Empty"
    },
    {
      "x": -13,
      "y": 10,
      "z": -2,
      "name": "Soil_Dirt_Burnt"
    },
    {
      "x": -13,
      "y": 11,
      "z": -2,
      "name": "Soil_Clay_Brick"
    },
    {
      "x": -13,
      "y": 12,
      "z": -2,
      "name": "Soil_Clay_Brick"
    },
    {
      "x": -13,
      "y": 0,
      "z": -1,
      "name": "Soil_Clay_Brick"
    },
    {
      "x": -13,
      "y": 1,
      "z": -1,
      "name": "Soil_Clay_Brick"
    },
    {
      "x": -13,
      "y": 2,
      "z": -1,
      "name": "Soil_Clay_Brick"
    },
    {
      "x": -13,
      "y": 3,
      "z": -1,
      "name": "Rock_Basalt_Brick"
    },
    {
      "x": -13,
      "y": 4,
      "z": -1,
      "name": "Rock_Basalt_Brick"
    },
    {
      "x": -13,
      "y": 5,
      "z": -1,
      "name": "Nat20_Force_Empty"
    },
    {
      "x": -13,
      "y": 6,
      "z": -1,
      "name": "Nat20_Force_Empty"
    },
    {
      "x": -13,
      "y": 7,
      "z": -1,
      "name": "Nat20_Force_Empty"
    },
    {
      "x": -13,
      "y": 8,
      "z": -1,
      "name": "Nat20_Force_Empty"
    },
    {
      "x": -13,
      "y": 9,
      "z": -1,
      "name": "Nat20_Force_Empty"
    },
    {
      "x": -13,
      "y": 10,
      "z": -1,
      "name": "Soil_Dirt_Burnt"
    },
    {
      "x": -13,
      "y": 11,
      "z": -1,
      "name": "Soil_Clay_Brick"
    },
    {
      "x": -13,
      "y": 12,
      "z": -1,
      "name": "Soil_Clay_Brick"
    },
    {
      "x": -13,
      "y": 0,
      "z": 0,
      "name": "Soil_Clay_Brick"
    },
    {
      "x": -13,
      "y": 1,
      "z": 0,
      "name": "Soil_Clay_Brick"
    },
    {
      "x": -13,
      "y": 2,
      "z": 0,
      "name": "Soil_Clay_Brick"
    },
    {
      "x": -13,
      "y": 3,
      "z": 0,
      "name": "Rock_Basalt_Brick"
    },
    {
      "x": -13,
      "y": 4,
      "z": 0,
      "name": "Rock_Basalt_Brick"
    },
    {
      "x": -13,
      "y": 5,
      "z": 0,
      "name": "Nat20_Force_Empty"
    },
    {
      "x": -13,
      "y": 6,
      "z": 0,
      "name": "Nat20_Force_Empty"
    },
    {
      "x": -13,
      "y": 7,
      "z": 0,
      "name": "Nat20_Force_Empty"
    },
    {
      "x": -13,
      "y": 8,
      "z": 0,
      "name": "Nat20_Force_Empty"
    },
    {
      "x": -13,
      "y": 9,
      "z": 0,
      "name": "Nat20_Force_Empty"
    },
    {
      "x": -13,
      "y": 10,
      "z": 0,
      "name": "Soil_Clay_Brick_Half",
      "rotation": 8
    },
    {
      "x": -13,
      "y": 11,
      "z": 0,
      "name": "Soil_Clay_Brick"
    },
    {
      "x": -13,
      "y": 12,
      "z": 0,
      "name": "Soil_Clay_Brick"
    },
    {
      "x": -13,
      "y": 0,
      "z": 1,
      "name": "Soil_Clay_Brick"
    },
    {
      "x": -13,
      "y": 1,
      "z": 1,
      "name": "Soil_Clay_Brick"
    },
    {
      "x": -13,
      "y": 2,
      "z": 1,
      "name": "Soil_Clay_Brick"
    },
    {
      "x": -13,
      "y": 3,
      "z": 1,
      "name": "Rock_Basalt_Brick"
    },
    {
      "x": -13,
      "y": 4,
      "z": 1,
      "name": "Soil_Dirt_Burnt"
    },
    {
      "x": -13,
      "y": 5,
      "z": 1,
      "name": "Soil_Dirt_Burnt"
    },
    {
      "x": -13,
      "y": 6,
      "z": 1,
      "name": "Nat20_Force_Empty"
    },
    {
      "x": -13,
      "y": 7,
      "z": 1,
      "name": "Nat20_Force_Empty"
    },
    {
      "x": -13,
      "y": 8,
      "z": 1,
      "name": "Nat20_Force_Empty"
    },
    {
      "x": -13,
      "y": 9,
      "z": 1,
      "name": "Nat20_Force_Empty"
    },
    {
      "x": -13,
      "y": 10,
      "z": 1,
      "name": "Soil_Clay_Brick_Half",
      "rotation": 8
    },
    {
      "x": -13,
      "y": 11,
      "z": 1,
      "name": "Soil_Clay_Brick"
    },
    {
      "x": -13,
      "y": 12,
      "z": 1,
      "name": "Soil_Clay_Brick"
    },
    {
      "x": -13,
      "y": 0,
      "z": 2,
      "name": "Soil_Clay_Brick"
    },
    {
      "x": -13,
      "y": 1,
      "z": 2,
      "name": "Soil_Clay_Brick"
    },
    {
      "x": -13,
      "y": 2,
      "z": 2,
      "name": "Soil_Clay_Brick"
    },
    {
      "x": -13,
      "y": 3,
      "z": 2,
      "name": "Rock_Basalt_Brick"
    },
    {
      "x": -13,
      "y": 4,
      "z": 2,
      "name": "Soil_Dirt_Burnt"
    },
    {
      "x": -13,
      "y": 5,
      "z": 2,
      "name": "Nat20_Force_Empty"
    },
    {
      "x": -13,
      "y": 6,
      "z": 2,
      "name": "Nat20_Force_Empty"
    },
    {
      "x": -13,
      "y": 7,
      "z": 2,
      "name": "Nat20_Force_Empty"
    },
    {
      "x": -13,
      "y": 8,
      "z": 2,
      "name": "Nat20_Force_Empty"
    },
    {
      "x": -13,
      "y": 9,
      "z": 2,
      "name": "Nat20_Force_Empty"
    },
    {
      "x": -13,
      "y": 10,
      "z": 2,
      "name": "Soil_Clay_Brick_Half",
      "rotation": 8
    },
    {
      "x": -13,
      "y": 11,
      "z": 2,
      "name": "Soil_Clay_Brick"
    },
    {
      "x": -13,
      "y": 12,
      "z": 2,
      "name": "Soil_Clay_Brick"
    },
    {
      "x": -13,
      "y": 0,
      "z": 3,
      "name": "Soil_Clay_Brick"
    },
    {
      "x": -13,
      "y": 1,
      "z": 3,
      "name": "Soil_Clay_Brick"
    },
    {
      "x": -13,
      "y": 2,
      "z": 3,
      "name": "Soil_Clay_Brick"
    },
    {
      "x": -13,
      "y": 3,
      "z": 3,
      "name": "Rock_Basalt_Brick"
    },
    {
      "x": -13,
      "y": 4,
      "z": 3,
      "name": "Soil_Dirt_Burnt"
    },
    {
      "x": -13,
      "y": 5,
      "z": 3,
      "name": "Plant_Crop_Mushroom_Block_Red"
    },
    {
      "x": -13,
      "y": 6,
      "z": 3,
      "name": "Nat20_Force_Empty"
    },
    {
      "x": -13,
      "y": 7,
      "z": 3,
      "name": "Nat20_Force_Empty"
    },
    {
      "x": -13,
      "y": 8,
      "z": 3,
      "name": "Nat20_Force_Empty"
    },
    {
      "x": -13,
      "y": 9,
      "z": 3,
      "name": "Nat20_Force_Empty"
    },
    {
      "x": -13,
      "y": 10,
      "z": 3,
      "name": "Soil_Clay_Brick_Half",
      "rotation": 8
    },
    {
      "x": -13,
      "y": 11,
      "z": 3,
      "name": "Soil_Clay_Brick"
    },
    {
      "x": -13,
      "y": 12,
      "z": 3,
      "name": "Soil_Clay_Brick"
    },
    {
      "x": -13,
      "y": 0,
      "z": 4,
      "name": "Soil_Clay_Brick"
    },
    {
      "x": -13,
      "y": 1,
      "z": 4,
      "name": "Soil_Clay_Brick"
    },
    {
      "x": -13,
      "y": 2,
      "z": 4,
      "name": "Soil_Clay_Brick"
    },
    {
      "x": -13,
      "y": 3,
      "z": 4,
      "name": "Rock_Basalt_Brick"
    },
    {
      "x": -13,
      "y": 4,
      "z": 4,
      "name": "Soil_Dirt_Burnt"
    },
    {
      "x": -13,
      "y": 5,
      "z": 4,
      "name": "Plant_Crop_Mushroom_Block_Red"
    },
    {
      "x": -13,
      "y": 6,
      "z": 4,
      "name": "Plant_Coral_Model_Orange"
    },
    {
      "x": -13,
      "y": 7,
      "z": 4,
      "name": "Nat20_Force_Empty"
    },
    {
      "x": -13,
      "y": 8,
      "z": 4,
      "name": "Nat20_Force_Empty"
    },
    {
      "x": -13,
      "y": 9,
      "z": 4,
      "name": "Nat20_Force_Empty"
    },
    {
      "x": -13,
      "y": 10,
      "z": 4,
      "name": "Soil_Clay_Brick_Half",
      "rotation": 8
    },
    {
      "x": -13,
      "y": 11,
      "z": 4,
      "name": "Soil_Clay_Brick"
    },
    {
      "x": -13,
      "y": 12,
      "z": 4,
      "name": "Soil_Clay_Brick"
    },
    {
      "x": -13,
      "y": 0,
      "z": 5,
      "name": "Soil_Clay_Brick"
    },
    {
      "x": -13,
      "y": 1,
      "z": 5,
      "name": "Soil_Clay_Brick"
    },
    {
      "x": -13,
      "y": 2,
      "z": 5,
      "name": "Soil_Clay_Brick"
    },
    {
      "x": -13,
      "y": 3,
      "z": 5,
      "name": "Rock_Basalt_Brick"
    },
    {
      "x": -13,
      "y": 4,
      "z": 5,
      "name": "Soil_Dirt_Burnt"
    },
    {
      "x": -13,
      "y": 5,
      "z": 5,
      "name": "Soil_Dirt_Burnt"
    },
    {
      "x": -13,
      "y": 6,
      "z": 5,
      "name": "Nat20_Force_Empty"
    },
    {
      "x": -13,
      "y": 7,
      "z": 5,
      "name": "Rock_Basalt_Brick_Half",
      "rotation": 5
    },
    {
      "x": -13,
      "y": 8,
      "z": 5,
      "name": "Rock_Basalt_Brick_Half",
      "rotation": 5
    },
    {
      "x": -13,
      "y": 9,
      "z": 5,
      "name": "Rock_Basalt_Brick"
    },
    {
      "x": -13,
      "y": 10,
      "z": 5,
      "name": "Rock_Basalt_Brick"
    },
    {
      "x": -13,
      "y": 11,
      "z": 5,
      "name": "Soil_Clay_Brick"
    },
    {
      "x": -13,
      "y": 12,
      "z": 5,
      "name": "Soil_Clay_Brick"
    },
    {
      "x": -13,
      "y": 0,
      "z": 6,
      "name": "Soil_Clay_Brick"
    },
    {
      "x": -13,
      "y": 1,
      "z": 6,
      "name": "Soil_Clay_Brick"
    },
    {
      "x": -13,
      "y": 2,
      "z": 6,
      "name": "Soil_Clay_Brick"
    },
    {
      "x": -13,
      "y": 3,
      "z": 6,
      "name": "Rock_Basalt_Brick"
    },
    {
      "x": -13,
      "y": 4,
      "z": 6,
      "name": "Soil_Dirt_Burnt"
    },
    {
      "x": -13,
      "y": 5,
      "z": 6,
      "name": "Nat20_Force_Empty"
    },
    {
      "x": -13,
      "y": 6,
      "z": 6,
      "name": "Nat20_Force_Empty"
    },
    {
      "x": -13,
      "y": 7,
      "z": 6,
      "name": "Rock_Basalt_Brick_Half",
      "rotation": 5
    },
    {
      "x": -13,
      "y": 8,
      "z": 6,
      "name": "Rock_Basalt_Brick_Half",
      "rotation": 5
    },
    {
      "x": -13,
      "y": 9,
      "z": 6,
      "name": "Rock_Basalt_Brick"
    },
    {
      "x": -13,
      "y": 10,
      "z": 6,
      "name": "Rock_Basalt_Brick"
    },
    {
      "x": -13,
      "y": 11,
      "z": 6,
      "name": "Soil_Clay_Brick"
    },
    {
      "x": -13,
      "y": 12,
      "z": 6,
      "name": "Soil_Clay_Brick"
    },
    {
      "x": -13,
      "y": 0,
      "z": 7,
      "name": "Soil_Clay_Brick"
    },
    {
      "x": -13,
      "y": 1,
      "z": 7,
      "name": "Soil_Clay_Brick"
    },
    {
      "x": -13,
      "y": 2,
      "z": 7,
      "name": "Soil_Clay_Brick"
    },
    {
      "x": -13,
      "y": 3,
      "z": 7,
      "name": "Rock_Basalt_Brick"
    },
    {
      "x": -13,
      "y": 4,
      "z": 7,
      "name": "Soil_Dirt_Burnt"
    },
    {
      "x": -13,
      "y": 5,
      "z": 7,
      "name": "Plant_Bush_Dead_Tall"
    },
    {
      "x": -13,
      "y": 6,
      "z": 7,
      "name": "Nat20_Force_Empty"
    },
    {
      "x": -13,
      "y": 7,
      "z": 7,
      "name": "Nat20_Force_Empty"
    },
    {
      "x": -13,
      "y": 8,
      "z": 7,
      "name": "Nat20_Force_Empty"
    },
    {
      "x": -13,
      "y": 9,
      "z": 7,
      "name": "Nat20_Force_Empty"
    },
    {
      "x": -13,
      "y": 10,
      "z": 7,
      "name": "Soil_Clay_Brick_Half",
      "rotation": 8
    },
    {
      "x": -13,
      "y": 11,
      "z": 7,
      "name": "Soil_Clay_Brick"
    },
    {
      "x": -13,
      "y": 12,
      "z": 7,
      "name": "Soil_Clay_Brick"
    },
    {
      "x": -13,
      "y": 0,
      "z": 8,
      "name": "Soil_Clay_Brick"
    },
    {
      "x": -13,
      "y": 1,
      "z": 8,
      "name": "Soil_Clay_Brick"
    },
    {
      "x": -13,
      "y": 2,
      "z": 8,
      "name": "Soil_Clay_Brick"
    },
    {
      "x": -13,
      "y": 3,
      "z": 8,
      "name": "Rock_Basalt_Brick"
    },
    {
      "x": -13,
      "y": 4,
      "z": 8,
      "name": "Soil_Mud_Dry"
    },
    {
      "x": -13,
      "y": 5,
      "z": 8,
      "name": "Plant_Bush_Dead_Tall"
    },
    {
      "x": -13,
      "y": 6,
      "z": 8,
      "name": "Nat20_Force_Empty"
    },
    {
      "x": -13,
      "y": 7,
      "z": 8,
      "name": "Nat20_Force_Empty"
    },
    {
      "x": -13,
      "y": 8,
      "z": 8,
      "name": "Nat20_Force_Empty"
    },
    {
      "x": -13,
      "y": 9,
      "z": 8,
      "name": "Nat20_Force_Empty"
    },
    {
      "x": -13,
      "y": 10,
      "z": 8,
      "name": "Soil_Clay_Brick_Half",
      "rotation": 8
    },
    {
      "x": -13,
      "y": 11,
      "z": 8,
      "name": "Soil_Clay_Brick"
    },
    {
      "x": -13,
      "y": 12,
      "z": 8,
      "name": "Soil_Clay_Brick"
    },
    {
      "x": -13,
      "y": 0,
      "z": 9,
      "name": "Soil_Clay_Brick"
    },
    {
      "x": -13,
      "y": 1,
      "z": 9,
      "name": "Soil_Clay_Brick"
    },
    {
      "x": -13,
      "y": 2,
      "z": 9,
      "name": "Soil_Clay_Brick"
    },
    {
      "x": -13,
      "y": 3,
      "z": 9,
      "name": "Rock_Basalt_Brick"
    },
    {
      "x": -13,
      "y": 4,
      "z": 9,
      "name": "Soil_Mud_Dry"
    },
    {
      "x": -13,
      "y": 5,
      "z": 9,
      "name": "Nat20_Force_Empty"
    },
    {
      "x": -13,
      "y": 6,
      "z": 9,
      "name": "Nat20_Force_Empty"
    },
    {
      "x": -13,
      "y": 7,
      "z": 9,
      "name": "Nat20_Force_Empty"
    },
    {
      "x": -13,
      "y": 8,
      "z": 9,
      "name": "Nat20_Force_Empty"
    },
    {
      "x": -13,
      "y": 9,
      "z": 9,
      "name": "Nat20_Force_Empty"
    },
    {
      "x": -13,
      "y": 10,
      "z": 9,
      "name": "Soil_Dirt_Burnt"
    },
    {
      "x": -13,
      "y": 11,
      "z": 9,
      "name": "Soil_Clay_Brick"
    },
    {
      "x": -13,
      "y": 12,
      "z": 9,
      "name": "Soil_Clay_Brick"
    },
    {
      "x": -13,
      "y": 0,
      "z": 10,
      "name": "Soil_Clay_Brick"
    },
    {
      "x": -13,
      "y": 1,
      "z": 10,
      "name": "Soil_Clay_Brick"
    },
    {
      "x": -13,
      "y": 2,
      "z": 10,
      "name": "Soil_Clay_Brick"
    },
    {
      "x": -13,
      "y": 3,
      "z": 10,
      "name": "Rock_Basalt_Brick"
    },
    {
      "x": -13,
      "y": 4,
      "z": 10,
      "name": "Soil_Mud_Dry"
    },
    {
      "x": -13,
      "y": 5,
      "z": 10,
      "name": "Nat20_Force_Empty"
    },
    {
      "x": -13,
      "y": 6,
      "z": 10,
      "name": "Nat20_Force_Empty"
    },
    {
      "x": -13,
      "y": 7,
      "z": 10,
      "name": "Nat20_Force_Empty"
    },
    {
      "x": -13,
      "y": 8,
      "z": 10,
      "name": "Nat20_Force_Empty"
    },
    {
      "x": -13,
      "y": 9,
      "z": 10,
      "name": "Nat20_Force_Empty"
    },
    {
      "x": -13,
      "y": 10,
      "z": 10,
      "name": "Soil_Dirt_Burnt"
    },
    {
      "x": -13,
      "y": 11,
      "z": 10,
      "name": "Soil_Dirt_Burnt"
    },
    {
      "x": -13,
      "y": 12,
      "z": 10,
      "name": "Soil_Clay_Brick"
    },
    {
      "x": -13,
      "y": 0,
      "z": 11,
      "name": "Soil_Clay_Brick"
    },
    {
      "x": -13,
      "y": 1,
      "z": 11,
      "name": "Soil_Clay_Brick"
    },
    {
      "x": -13,
      "y": 2,
      "z": 11,
      "name": "Soil_Clay_Brick"
    },
    {
      "x": -13,
      "y": 3,
      "z": 11,
      "name": "Rock_Basalt_Brick"
    },
    {
      "x": -13,
      "y": 4,
      "z": 11,
      "name": "Rock_Basalt_Brick"
    },
    {
      "x": -13,
      "y": 5,
      "z": 11,
      "name": "Rail",
      "rotation": 1
    },
    {
      "x": -13,
      "y": 6,
      "z": 11,
      "name": "Nat20_Force_Empty"
    },
    {
      "x": -13,
      "y": 7,
      "z": 11,
      "name": "Nat20_Force_Empty"
    },
    {
      "x": -13,
      "y": 8,
      "z": 11,
      "name": "Nat20_Force_Empty"
    },
    {
      "x": -13,
      "y": 9,
      "z": 11,
      "name": "Nat20_Force_Empty"
    },
    {
      "x": -13,
      "y": 11,
      "z": 11,
      "name": "Soil_Dirt_Burnt"
    },
    {
      "x": -13,
      "y": 12,
      "z": 11,
      "name": "Soil_Clay_Brick"
    },
    {
      "x": -13,
      "y": 0,
      "z": 12,
      "name": "Soil_Clay_Brick"
    },
    {
      "x": -13,
      "y": 1,
      "z": 12,
      "name": "Soil_Clay_Brick"
    },
    {
      "x": -13,
      "y": 2,
      "z": 12,
      "name": "Soil_Clay_Brick"
    },
    {
      "x": -13,
      "y": 3,
      "z": 12,
      "name": "Rock_Basalt_Brick"
    },
    {
      "x": -13,
      "y": 4,
      "z": 12,
      "name": "Soil_Dirt_Burnt"
    },
    {
      "x": -13,
      "y": 5,
      "z": 12,
      "name": "Nat20_Force_Empty"
    },
    {
      "x": -13,
      "y": 6,
      "z": 12,
      "name": "Nat20_Force_Empty"
    },
    {
      "x": -13,
      "y": 7,
      "z": 12,
      "name": "Nat20_Force_Empty"
    },
    {
      "x": -13,
      "y": 8,
      "z": 12,
      "name": "Nat20_Force_Empty"
    },
    {
      "x": -13,
      "y": 9,
      "z": 12,
      "name": "Nat20_Force_Empty"
    },
    {
      "x": -13,
      "y": 11,
      "z": 12,
      "name": "Soil_Dirt_Burnt"
    },
    {
      "x": -13,
      "y": 12,
      "z": 12,
      "name": "Soil_Clay_Brick"
    },
    {
      "x": -13,
      "y": 0,
      "z": 13,
      "name": "Soil_Clay_Brick"
    },
    {
      "x": -13,
      "y": 1,
      "z": 13,
      "name": "Soil_Clay_Brick"
    },
    {
      "x": -13,
      "y": 2,
      "z": 13,
      "name": "Soil_Clay_Brick"
    },
    {
      "x": -13,
      "y": 3,
      "z": 13,
      "name": "Rock_Basalt_Brick"
    },
    {
      "x": -13,
      "y": 4,
      "z": 13,
      "name": "Soil_Dirt_Burnt"
    },
    {
      "x": -13,
      "y": 5,
      "z": 13,
      "name": "Soil_Dirt_Burnt"
    },
    {
      "x": -13,
      "y": 6,
      "z": 13,
      "name": "Nat20_Force_Empty"
    },
    {
      "x": -13,
      "y": 7,
      "z": 13,
      "name": "Nat20_Force_Empty"
    },
    {
      "x": -13,
      "y": 8,
      "z": 13,
      "name": "Nat20_Force_Empty"
    },
    {
      "x": -13,
      "y": 9,
      "z": 13,
      "name": "Nat20_Force_Empty"
    },
    {
      "x": -13,
      "y": 10,
      "z": 13,
      "name": "Soil_Clay_Brick_Half",
      "rotation": 8
    },
    {
      "x": -13,
      "y": 11,
      "z": 13,
      "name": "Soil_Clay_Brick"
    },
    {
      "x": -13,
      "y": 12,
      "z": 13,
      "name": "Soil_Clay_Brick"
    },
    {
      "x": -13,
      "y": 0,
      "z": 14,
      "name": "Soil_Clay_Brick"
    },
    {
      "x": -13,
      "y": 1,
      "z": 14,
      "name": "Soil_Clay_Brick"
    },
    {
      "x": -13,
      "y": 2,
      "z": 14,
      "name": "Soil_Clay_Brick"
    },
    {
      "x": -13,
      "y": 3,
      "z": 14,
      "name": "Rock_Basalt_Brick"
    },
    {
      "x": -13,
      "y": 4,
      "z": 14,
      "name": "Soil_Dirt_Burnt"
    },
    {
      "x": -13,
      "y": 5,
      "z": 14,
      "name": "Soil_Dirt_Burnt"
    },
    {
      "x": -13,
      "y": 6,
      "z": 14,
      "name": "Nat20_Force_Empty"
    },
    {
      "x": -13,
      "y": 7,
      "z": 14,
      "name": "Rock_Basalt_Brick_Half",
      "rotation": 5
    },
    {
      "x": -13,
      "y": 8,
      "z": 14,
      "name": "Rock_Basalt_Brick"
    },
    {
      "x": -13,
      "y": 9,
      "z": 14,
      "name": "Rock_Basalt_Brick"
    },
    {
      "x": -13,
      "y": 10,
      "z": 14,
      "name": "Rock_Basalt_Brick"
    },
    {
      "x": -13,
      "y": 11,
      "z": 14,
      "name": "Soil_Clay_Brick"
    },
    {
      "x": -13,
      "y": 0,
      "z": 15,
      "name": "Soil_Clay_Brick"
    },
    {
      "x": -13,
      "y": 1,
      "z": 15,
      "name": "Soil_Clay_Brick"
    },
    {
      "x": -13,
      "y": 2,
      "z": 15,
      "name": "Soil_Clay_Brick"
    },
    {
      "x": -13,
      "y": 3,
      "z": 15,
      "name": "Rock_Basalt_Brick"
    },
    {
      "x": -13,
      "y": 4,
      "z": 15,
      "name": "Rock_Basalt_Brick"
    },
    {
      "x": -13,
      "y": 5,
      "z": 15,
      "name": "Nat20_Force_Empty"
    },
    {
      "x": -13,
      "y": 6,
      "z": 15,
      "name": "Nat20_Force_Empty"
    },
    {
      "x": -13,
      "y": 7,
      "z": 15,
      "name": "Rock_Basalt_Brick_Half",
      "rotation": 5
    },
    {
      "x": -13,
      "y": 8,
      "z": 15,
      "name": "Rock_Basalt_Brick"
    },
    {
      "x": -13,
      "y": 9,
      "z": 15,
      "name": "Rock_Basalt_Brick"
    },
    {
      "x": -13,
      "y": 10,
      "z": 15,
      "name": "Rock_Basalt_Brick"
    },
    {
      "x": -12,
      "y": 0,
      "z": -14,
      "name": "Soil_Clay_Brick"
    },
    {
      "x": -12,
      "y": 1,
      "z": -14,
      "name": "Rock_Basalt_Brick"
    },
    {
      "x": -12,
      "y": 2,
      "z": -14,
      "name": "Rock_Basalt_Brick"
    },
    {
      "x": -12,
      "y": 3,
      "z": -14,
      "name": "Rock_Basalt_Brick"
    },
    {
      "x": -12,
      "y": 4,
      "z": -14,
      "name": "Soil_Dirt_Burnt"
    },
    {
      "x": -12,
      "y": 5,
      "z": -14,
      "name": "Soil_Dirt_Burnt"
    },
    {
      "x": -12,
      "y": 6,
      "z": -14,
      "name": "Nat20_Force_Empty"
    },
    {
      "x": -12,
      "y": 7,
      "z": -14,
      "name": "Nat20_Force_Empty"
    },
    {
      "x": -12,
      "y": 8,
      "z": -14,
      "name": "Soil_Clay_Brick_Half",
      "rotation": 4
    },
    {
      "x": -12,
      "y": 9,
      "z": -14,
      "name": "Soil_Clay_Brick"
    },
    {
      "x": -12,
      "y": 10,
      "z": -14,
      "name": "Soil_Clay_Brick"
    },
    {
      "x": -12,
      "y": 11,
      "z": -14,
      "name": "Soil_Clay_Brick"
    },
    {
      "x": -12,
      "y": 0,
      "z": -13,
      "name": "Soil_Clay_Brick"
    },
    {
      "x": -12,
      "y": 1,
      "z": -13,
      "name": "Rock_Basalt_Brick"
    },
    {
      "x": -12,
      "y": 2,
      "z": -13,
      "name": "Rock_Basalt_Brick"
    },
    {
      "x": -12,
      "y": 3,
      "z": -13,
      "name": "Rock_Basalt_Brick"
    },
    {
      "x": -12,
      "y": 4,
      "z": -13,
      "name": "Soil_Dirt_Burnt"
    },
    {
      "x": -12,
      "y": 5,
      "z": -13,
      "name": "Nat20_Force_Empty"
    },
    {
      "x": -12,
      "y": 6,
      "z": -13,
      "name": "Nat20_Force_Empty"
    },
    {
      "x": -12,
      "y": 7,
      "z": -13,
      "name": "Nat20_Force_Empty"
    },
    {
      "x": -12,
      "y": 8,
      "z": -13,
      "name": "Nat20_Force_Empty"
    },
    {
      "x": -12,
      "y": 9,
      "z": -13,
      "name": "Nat20_Force_Empty"
    },
    {
      "x": -12,
      "y": 10,
      "z": -13,
      "name": "Soil_Clay_Brick_Half",
      "rotation": 8
    },
    {
      "x": -12,
      "y": 11,
      "z": -13,
      "name": "Soil_Clay_Brick"
    },
    {
      "x": -12,
      "y": 12,
      "z": -13,
      "name": "Soil_Clay_Brick"
    },
    {
      "x": -12,
      "y": 0,
      "z": -12,
      "name": "Soil_Clay_Brick"
    },
    {
      "x": -12,
      "y": 1,
      "z": -12,
      "name": "Rock_Basalt_Brick"
    },
    {
      "x": -12,
      "y": 2,
      "z": -12,
      "name": "Rock_Basalt_Brick"
    },
    {
      "x": -12,
      "y": 3,
      "z": -12,
      "name": "Rock_Basalt_Brick"
    },
    {
      "x": -12,
      "y": 4,
      "z": -12,
      "name": "Rock_Basalt_Brick"
    },
    {
      "x": -12,
      "y": 5,
      "z": -12,
