{
  "version": 8,
  "blockIdVersion": 11,
  "anchorX": 0,
  "anchorY": 0,
  "anchorZ": 0,
  "blocks": [
    {
      "x": -11,
      "y": 0,
      "z": -11,
      "name": "Rock_Quartzite_Brick"
    },
    {
      "x": -11,
      "y": 1,
      "z": -11,
      "name": "Rock_Quartzite_Brick"
    },
    {
      "x": -11,
      "y": 2,
      "z": -11,
      "name": "Rock_Quartzite_Brick"
    },
    {
      "x": -11,
      "y": 3,
      "z": -11,
      "name": "Rock_Quartzite_Brick"
    },
    {
      "x": -11,
      "y": 4,
      "z": -11,
      "name": "Rock_Quartzite"
    },
    {
      "x": -11,
      "y": 5,
      "z": -11,
      "name": "Rock_Stone"
    },
    {
      "x": -11,
      "y": 6,
      "z": -11,
      "name": "Rock_Stone"
    },
    {
      "x": -11,
      "y": 7,
      "z": -11,
      "name": "Rock_Stone"
    },
    {
      "x": -11,
      "y": 8,
      "z": -11,
      "name": "Rock_Stone"
    },
    {
      "x": -11,
      "y": 9,
      "z": -11,
      "name": "Rock_Stone"
    },
    {
      "x": -11,
      "y": 10,
      "z": -11,
      "name": "Rock_Stone"
    },
    {
      "x": -11,
      "y": 11,
      "z": -11,
      "name": "Rock_Stone"
    },
    {
      "x": -11,
      "y": 12,
      "z": -11,
      "name": "Rock_Stone"
    },
    {
      "x": -11,
      "y": 13,
      "z": -11,
      "name": "Rock_Stone"
    },
    {
      "x": -11,
      "y": 14,
      "z": -11,
      "name": "Rock_Stone"
    },
    {
      "x": -11,
      "y": 15,
      "z": -11,
      "name": "Rock_Stone"
    },
    {
      "x": -11,
      "y": 16,
      "z": -11,
      "name": "Soil_Grass"
    },
    {
      "x": -11,
      "y": 0,
      "z": -10,
      "name": "Rock_Quartzite_Brick"
    },
    {
      "x": -11,
      "y": 1,
      "z": -10,
      "name": "Rock_Quartzite_Brick"
    },
    {
      "x": -11,
      "y": 2,
      "z": -10,
      "name": "Rock_Quartzite_Brick"
    },
    {
      "x": -11,
      "y": 3,
      "z": -10,
      "name": "Rock_Quartzite"
    },
    {
      "x": -11,
      "y": 4,
      "z": -10,
      "name": "Rock_Quartzite"
    },
    {
      "x": -11,
      "y": 5,
      "z": -10,
      "name": "Rock_Stone"
    },
    {
      "x": -11,
      "y": 6,
      "z": -10,
      "name": "Rock_Stone"
    },
    {
      "x": -11,
      "y": 7,
      "z": -10,
      "name": "Rock_Stone"
    },
    {
      "x": -11,
      "y": 8,
      "z": -10,
      "name": "Rock_Stone"
    },
    {
      "x": -11,
      "y": 9,
      "z": -10,
      "name": "Rock_Stone"
    },
    {
      "x": -11,
      "y": 10,
      "z": -10,
      "name": "Rock_Stone"
    },
    {
      "x": -11,
      "y": 11,
      "z": -10,
      "name": "Rock_Stone"
    },
    {
      "x": -11,
      "y": 12,
      "z": -10,
      "name": "Rock_Stone"
    },
    {
      "x": -11,
      "y": 13,
      "z": -10,
      "name": "Rock_Stone"
    },
    {
      "x": -11,
      "y": 14,
      "z": -10,
      "name": "Rock_Stone"
    },
    {
      "x": -11,
      "y": 15,
      "z": -10,
      "name": "Rock_Stone"
    },
    {
      "x": -11,
      "y": 16,
      "z": -10,
      "name": "Rock_Stone"
    },
    {
      "x": -11,
      "y": 17,
      "z": -10,
      "name": "Rock_Stone"
    },
    {
      "x": -11,
      "y": 18,
      "z": -10,
      "name": "Rock_Stone"
    },
    {
      "x": -11,
      "y": 0,
      "z": -9,
      "name": "Rock_Quartzite_Brick"
    },
    {
      "x": -11,
      "y": 1,
      "z": -9,
      "name": "Rock_Quartzite_Brick"
    },
    {
      "x": -11,
      "y": 2,
      "z": -9,
      "name": "Rock_Quartzite_Brick"
    },
    {
      "x": -11,
      "y": 3,
      "z": -9,
      "name": "Rock_Quartzite_Brick"
    },
    {
      "x": -11,
      "y": 4,
      "z": -9,
      "name": "Rock_Quartzite"
    },
    {
      "x": -11,
      "y": 5,
      "z": -9,
      "name": "Rock_Quartzite_Brick"
    },
    {
      "x": -11,
      "y": 6,
      "z": -9,
      "name": "Rock_Stone"
    },
    {
      "x": -11,
      "y": 7,
      "z": -9,
      "name": "Rock_Stone"
    },
    {
      "x": -11,
      "y": 8,
      "z": -9,
      "name": "Rock_Stone"
    },
    {
      "x": -11,
      "y": 9,
      "z": -9,
      "name": "Rock_Stone"
    },
    {
      "x": -11,
      "y": 10,
      "z": -9,
      "name": "Rock_Stone"
    },
    {
      "x": -11,
      "y": 11,
      "z": -9,
      "name": "Rock_Stone"
    },
    {
      "x": -11,
      "y": 12,
      "z": -9,
      "name": "Rock_Stone"
    },
    {
      "x": -11,
      "y": 13,
      "z": -9,
      "name": "Rock_Stone"
    },
    {
      "x": -11,
      "y": 14,
      "z": -9,
      "name": "Rock_Stone"
    },
    {
      "x": -11,
      "y": 15,
      "z": -9,
      "name": "Rock_Stone"
    },
    {
      "x": -11,
      "y": 16,
      "z": -9,
      "name": "Rock_Stone"
    },
    {
      "x": -11,
      "y": 17,
      "z": -9,
      "name": "Rock_Stone"
    },
    {
      "x": -11,
      "y": 18,
      "z": -9,
      "name": "Rock_Stone"
    },
    {
      "x": -11,
      "y": 19,
      "z": -9,
      "name": "Rock_Stone"
    },
    {
      "x": -11,
      "y": 20,
      "z": -9,
      "name": "Rock_Stone"
    },
    {
      "x": -11,
      "y": 21,
      "z": -9,
      "name": "Rock_Stone"
    },
    {
      "x": -11,
      "y": 22,
      "z": -9,
      "name": "Rock_Stone"
    },
    {
      "x": -11,
      "y": 0,
      "z": -8,
      "name": "Rock_Quartzite_Brick"
    },
    {
      "x": -11,
      "y": 1,
      "z": -8,
      "name": "Rock_Quartzite_Brick"
    },
    {
      "x": -11,
      "y": 2,
      "z": -8,
      "name": "Rock_Quartzite_Brick"
    },
    {
      "x": -11,
      "y": 3,
      "z": -8,
      "name": "Rock_Quartzite_Brick"
    },
    {
      "x": -11,
      "y": 4,
      "z": -8,
      "name": "Rock_Quartzite_Brick"
    },
    {
      "x": -11,
      "y": 5,
      "z": -8,
      "name": "Rock_Stone"
    },
    {
      "x": -11,
      "y": 6,
      "z": -8,
      "name": "Rock_Stone"
    },
    {
      "x": -11,
      "y": 7,
      "z": -8,
      "name": "Rock_Stone"
    },
    {
      "x": -11,
      "y": 8,
      "z": -8,
      "name": "Rock_Stone"
    },
    {
      "x": -11,
      "y": 9,
      "z": -8,
      "name": "Rock_Stone"
    },
    {
      "x": -11,
      "y": 10,
      "z": -8,
      "name": "Rock_Stone"
    },
    {
      "x": -11,
      "y": 11,
      "z": -8,
      "name": "Rock_Stone"
    },
    {
      "x": -11,
      "y": 12,
      "z": -8,
      "name": "Rock_Stone"
    },
    {
      "x": -11,
      "y": 13,
      "z": -8,
      "name": "Rock_Stone"
    },
    {
      "x": -11,
      "y": 14,
      "z": -8,
      "name": "Rock_Stone"
    },
    {
      "x": -11,
      "y": 15,
      "z": -8,
      "name": "Rock_Stone"
    },
    {
      "x": -11,
      "y": 16,
      "z": -8,
      "name": "Rock_Stone"
    },
    {
      "x": -11,
      "y": 17,
      "z": -8,
      "name": "Rock_Stone"
    },
    {
      "x": -11,
      "y": 18,
      "z": -8,
      "name": "Rock_Stone"
    },
    {
      "x": -11,
      "y": 19,
      "z": -8,
      "name": "Rock_Stone"
    },
    {
      "x": -11,
      "y": 20,
      "z": -8,
      "name": "Rock_Stone"
    },
    {
      "x": -11,
      "y": 0,
      "z": -7,
      "name": "Rock_Quartzite_Brick"
    },
    {
      "x": -11,
      "y": 1,
      "z": -7,
      "name": "Rock_Quartzite"
    },
    {
      "x": -11,
      "y": 2,
      "z": -7,
      "name": "Rock_Quartzite"
    },
    {
      "x": -11,
      "y": 3,
      "z": -7,
      "name": "Rock_Quartzite"
    },
    {
      "x": -11,
      "y": 4,
      "z": -7,
      "name": "Rock_Quartzite_Brick"
    },
    {
      "x": -11,
      "y": 6,
      "z": -7,
      "name": "Rock_Stone"
    },
    {
      "x": -11,
      "y": 7,
      "z": -7,
      "name": "Rock_Stone"
    },
    {
      "x": -11,
      "y": 8,
      "z": -7,
      "name": "Rock_Stone"
    },
    {
      "x": -11,
      "y": 9,
      "z": -7,
      "name": "Rock_Stone"
    },
    {
      "x": -11,
      "y": 10,
      "z": -7,
      "name": "Rock_Stone"
    },
    {
      "x": -11,
      "y": 11,
      "z": -7,
      "name": "Rock_Stone"
    },
    {
      "x": -11,
      "y": 12,
      "z": -7,
      "name": "Rock_Stone"
    },
    {
      "x": -11,
      "y": 13,
      "z": -7,
      "name": "Rock_Stone"
    },
    {
      "x": -11,
      "y": 14,
      "z": -7,
      "name": "Rock_Stone"
    },
    {
      "x": -11,
      "y": 15,
      "z": -7,
      "name": "Rock_Stone"
    },
    {
      "x": -11,
      "y": 16,
      "z": -7,
      "name": "Rock_Stone"
    },
    {
      "x": -11,
      "y": 17,
      "z": -7,
      "name": "Soil_Grass"
    },
    {
      "x": -11,
      "y": 18,
      "z": -7,
      "name": "Plant_Bush"
    },
    {
      "x": -11,
      "y": 0,
      "z": -6,
      "name": "Rock_Quartzite"
    },
    {
      "x": -11,
      "y": 1,
      "z": -6,
      "name": "Rock_Quartzite"
    },
    {
      "x": -11,
      "y": 2,
      "z": -6,
      "name": "Rock_Quartzite"
    },
    {
      "x": -11,
      "y": 8,
      "z": -6,
      "name": "Rock_Stone"
    },
    {
      "x": -11,
      "y": 9,
      "z": -6,
      "name": "Rock_Stone"
    },
    {
      "x": -11,
      "y": 10,
      "z": -6,
      "name": "Rock_Stone"
    },
    {
      "x": -11,
      "y": 11,
      "z": -6,
      "name": "Rock_Stone"
    },
    {
      "x": -11,
      "y": 12,
      "z": -6,
      "name": "Rock_Stone"
    },
    {
      "x": -11,
      "y": 13,
      "z": -6,
      "name": "Rock_Stone"
    },
    {
      "x": -11,
      "y": 14,
      "z": -6,
      "name": "Rock_Stone"
    },
    {
      "x": -11,
      "y": 15,
      "z": -6,
      "name": "Rock_Quartzite_Brick"
    },
    {
      "x": -11,
      "y": 16,
      "z": -6,
      "name": "Soil_Grass"
    },
    {
      "x": -11,
      "y": 0,
      "z": -5,
      "name": "Rock_Quartzite"
    },
    {
      "x": -11,
      "y": 1,
      "z": -5,
      "name": "Rock_Quartzite"
    },
    {
      "x": -11,
      "y": 2,
      "z": -5,
      "name": "Rock_Quartzite"
    },
    {
      "x": -11,
      "y": 7,
      "z": -5,
      "name": "Rock_Stone"
    },
    {
      "x": -11,
      "y": 8,
      "z": -5,
      "name": "Rock_Stone"
    },
    {
      "x": -11,
      "y": 9,
      "z": -5,
      "name": "Rock_Stone"
    },
    {
      "x": -11,
      "y": 10,
      "z": -5,
      "name": "Rock_Stone"
    },
    {
      "x": -11,
      "y": 11,
      "z": -5,
      "name": "Rock_Stone"
    },
    {
      "x": -11,
      "y": 14,
      "z": -5,
      "name": "Rock_Quartzite_Brick"
    },
    {
      "x": -11,
      "y": 15,
      "z": -5,
      "name": "Rock_Quartzite_Brick"
    },
    {
      "x": -11,
      "y": 16,
      "z": -5,
      "name": "Soil_Grass"
    },
    {
      "x": -11,
      "y": 17,
      "z": -5,
      "name": "Plant_Grass_Sharp_Tall"
    },
    {
      "x": -11,
      "y": 18,
      "z": -5,
      "name": "Plant_Grass_Sharp_Tall",
      "filler": 1024
    },
    {
      "x": -11,
      "y": 14,
      "z": -4,
      "name": "Rock_Quartzite_Brick"
    },
    {
      "x": -11,
      "y": 15,
      "z": -4,
      "name": "Rock_Quartzite_Brick"
    },
    {
      "x": -11,
      "y": 16,
      "z": -4,
      "name": "Soil_Grass"
    },
    {
      "x": -11,
      "y": 17,
      "z": -4,
      "name": "Plant_Grass_Sharp"
    },
    {
      "x": -11,
      "y": 14,
      "z": -3,
      "name": "Rock_Quartzite_Brick"
    },
    {
      "x": -11,
      "y": 15,
      "z": -3,
      "name": "Rock_Quartzite_Brick"
    },
    {
      "x": -11,
      "y": 16,
      "z": -3,
      "name": "Soil_Grass"
    },
    {
      "x": -11,
      "y": 17,
      "z": -3,
      "name": "Plant_Grass_Sharp_Tall"
    },
    {
      "x": -11,
      "y": 18,
      "z": -3,
      "name": "Plant_Grass_Sharp_Tall",
      "filler": 1024
    },
    {
      "x": -11,
      "y": 13,
      "z": -2,
      "name": "Rock_Quartzite_Brick"
    },
    {
      "x": -11,
      "y": 14,
      "z": -2,
      "name": "Rock_Quartzite_Brick"
    },
    {
      "x": -11,
      "y": 15,
      "z": -2,
      "name": "Rock_Quartzite_Brick"
    },
    {
      "x": -11,
      "y": 16,
      "z": -2,
      "name": "Soil_Grass"
    },
    {
      "x": -11,
      "y": 17,
      "z": -2,
      "name": "Plant_Grass_Sharp_Short"
    },
    {
      "x": -11,
      "y": 0,
      "z": -1,
      "name": "Rock_Stone"
    },
    {
      "x": -11,
      "y": 1,
      "z": -1,
      "name": "Rock_Stone"
    },
    {
      "x": -11,
      "y": 2,
      "z": -1,
      "name": "Rock_Stone"
    },
    {
      "x": -11,
      "y": 3,
      "z": -1,
      "name": "Rock_Stone"
    },
    {
      "x": -11,
      "y": 11,
      "z": -1,
      "name": "Rock_Stone_Stalactite_Large",
      "filler": 31744,
      "rotation": 8
    },
    {
      "x": -11,
      "y": 12,
      "z": -1,
      "name": "Rock_Stone_Stalactite_Large",
      "rotation": 8
    },
    {
      "x": -11,
      "y": 13,
      "z": -1,
      "name": "Rock_Quartzite_Brick"
    },
    {
      "x": -11,
      "y": 14,
      "z": -1,
      "name": "Rock_Quartzite_Cobble"
    },
    {
      "x": -11,
      "y": 15,
      "z": -1,
      "name": "Soil_Grass"
    },
    {
      "x": -11,
      "y": 0,
      "z": 0,
      "name": "Rock_Stone"
    },
    {
      "x": -11,
      "y": 1,
      "z": 0,
      "name": "Rock_Stone"
    },
    {
      "x": -11,
      "y": 2,
      "z": 0,
      "name": "Rock_Stone"
    },
    {
      "x": -11,
      "y": 3,
      "z": 0,
      "name": "Rock_Stone"
    },
    {
      "x": -11,
      "y": 4,
      "z": 0,
      "name": "Rock_Stone"
    },
    {
      "x": -11,
      "y": 13,
      "z": 0,
      "name": "Rock_Quartzite_Cobble"
    },
    {
      "x": -11,
      "y": 14,
      "z": 0,
      "name": "Rock_Quartzite_Cobble"
    },
    {
      "x": -11,
      "y": 15,
      "z": 0,
      "name": "Soil_Grass"
    },
    {
      "x": -11,
      "y": 0,
      "z": 1,
      "name": "Rock_Stone"
    },
    {
      "x": -11,
      "y": 1,
      "z": 1,
      "name": "Rock_Stone"
    },
    {
      "x": -11,
      "y": 2,
      "z": 1,
      "name": "Rock_Stone"
    },
    {
      "x": -11,
      "y": 3,
      "z": 1,
      "name": "Rock_Stone"
    },
    {
      "x": -11,
      "y": 4,
      "z": 1,
      "name": "Rock_Stone"
    },
    {
      "x": -11,
      "y": 5,
      "z": 1,
      "name": "Rock_Quartzite_Cobble"
    },
    {
      "x": -11,
      "y": 6,
      "z": 1,
      "name": "Rock_Quartzite_Brick_Smooth"
    },
    {
      "x": -11,
      "y": 7,
      "z": 1,
      "name": "Rock_Quartzite_Brick_Smooth"
    },
    {
      "x": -11,
      "y": 8,
      "z": 1,
      "name": "Rock_Quartzite_Brick"
    },
    {
      "x": -11,
      "y": 9,
      "z": 1,
      "name": "Rock_Quartzite_Brick"
    },
    {
      "x": -11,
      "y": 10,
      "z": 1,
      "name": "Rock_Quartzite_Brick"
    },
    {
      "x": -11,
      "y": 11,
      "z": 1,
      "name": "Rock_Quartzite_Brick"
    },
    {
      "x": -11,
      "y": 12,
      "z": 1,
      "name": "Rock_Quartzite_Brick"
    },
    {
      "x": -11,
      "y": 13,
      "z": 1,
      "name": "Rock_Quartzite_Cobble"
    },
    {
      "x": -11,
      "y": 14,
      "z": 1,
      "name": "Rock_Quartzite_Cobble"
    },
    {
      "x": -11,
      "y": 15,
      "z": 1,
      "name": "Soil_Grass"
    },
    {
      "x": -11,
      "y": 0,
      "z": 2,
      "name": "Rock_Stone"
    },
    {
      "x": -11,
      "y": 1,
      "z": 2,
      "name": "Rock_Stone"
    },
    {
      "x": -11,
      "y": 2,
      "z": 2,
      "name": "Rock_Stone"
    },
    {
      "x": -11,
      "y": 3,
      "z": 2,
      "name": "Rock_Stone"
    },
    {
      "x": -11,
      "y": 4,
      "z": 2,
      "name": "Rock_Stone"
    },
    {
      "x": -11,
      "y": 5,
      "z": 2,
      "name": "Rock_Quartzite_Cobble"
    },
    {
      "x": -11,
      "y": 6,
      "z": 2,
      "name": "Rock_Quartzite_Brick"
    },
    {
      "x": -11,
      "y": 7,
      "z": 2,
      "name": "Rock_Quartzite_Brick"
    },
    {
      "x": -11,
      "y": 8,
      "z": 2,
      "name": "Rock_Quartzite_Brick"
    },
    {
      "x": -11,
      "y": 9,
      "z": 2,
      "name": "Rock_Quartzite"
    },
    {
      "x": -11,
      "y": 10,
      "z": 2,
      "name": "Rock_Quartzite_Brick"
    },
    {
      "x": -11,
      "y": 11,
      "z": 2,
      "name": "Rock_Quartzite_Brick"
    },
    {
      "x": -11,
      "y": 12,
      "z": 2,
      "name": "Rock_Quartzite_Cobble"
    },
    {
      "x": -11,
      "y": 13,
      "z": 2,
      "name": "Rock_Quartzite_Cobble"
    },
    {
      "x": -11,
      "y": 14,
      "z": 2,
      "name": "Rock_Quartzite_Cobble"
    },
    {
      "x": -11,
      "y": 15,
      "z": 2,
      "name": "Rock_Quartzite_Cobble"
    },
    {
      "x": -11,
      "y": 16,
      "z": 2,
      "name": "Rock_Quartzite_Brick"
    },
    {
      "x": -11,
      "y": 17,
      "z": 2,
      "name": "Rock_Quartzite_Brick"
    },
    {
      "x": -11,
      "y": 18,
      "z": 2,
      "name": "Plant_Moss_Rug_Green"
    },
    {
      "x": -11,
      "y": 0,
      "z": 3,
      "name": "Rock_Stone"
    },
    {
      "x": -11,
      "y": 1,
      "z": 3,
      "name": "Rock_Stone"
    },
    {
      "x": -11,
      "y": 2,
      "z": 3,
      "name": "Rock_Quartzite"
    },
    {
      "x": -11,
      "y": 3,
      "z": 3,
      "name": "Rock_Stone"
    },
    {
      "x": -11,
      "y": 4,
      "z": 3,
      "name": "Rock_Quartzite"
    },
    {
      "x": -11,
      "y": 5,
      "z": 3,
      "name": "Rock_Quartzite_Cobble"
    },
    {
      "x": -11,
      "y": 6,
      "z": 3,
      "name": "Rock_Quartzite_Brick"
    },
    {
      "x": -11,
      "y": 7,
      "z": 3,
      "name": "Rock_Quartzite"
    },
    {
      "x": -11,
      "y": 8,
      "z": 3,
      "name": "Rock_Quartzite"
    },
    {
      "x": -11,
      "y": 9,
      "z": 3,
      "name": "Rock_Quartzite"
    },
    {
      "x": -11,
      "y": 10,
      "z": 3,
      "name": "Rock_Quartzite"
    },
    {
      "x": -11,
      "y": 11,
      "z": 3,
      "name": "Rock_Quartzite_Brick"
    },
    {
      "x": -11,
      "y": 12,
      "z": 3,
      "name": "Rock_Quartzite_Cobble"
    },
    {
      "x": -11,
      "y": 13,
      "z": 3,
      "name": "Rock_Quartzite_Cobble"
    },
    {
      "x": -11,
      "y": 14,
      "z": 3,
      "name": "Rock_Quartzite_Cobble"
    },
    {
      "x": -11,
      "y": 15,
      "z": 3,
      "name": "Rock_Quartzite_Brick"
    },
    {
      "x": -11,
      "y": 16,
      "z": 3,
      "name": "Rock_Quartzite_Brick"
    },
    {
      "x": -11,
      "y": 17,
      "z": 3,
      "name": "Rock_Quartzite_Brick"
    },
    {
      "x": -11,
      "y": 18,
      "z": 3,
      "name": "Plant_Moss_Rug_Green"
    },
    {
      "x": -11,
      "y": 0,
      "z": 4,
      "name": "Rock_Quartzite_Brick"
    },
    {
      "x": -11,
      "y": 1,
      "z": 4,
      "name": "Rock_Quartzite_Brick"
    },
    {
      "x": -11,
      "y": 2,
      "z": 4,
      "name": "Rock_Quartzite_Brick"
    },
    {
      "x": -11,
      "y": 3,
      "z": 4,
      "name": "Rock_Quartzite_Brick"
    },
    {
      "x": -11,
      "y": 4,
      "z": 4,
      "name": "Rock_Quartzite_Brick"
    },
    {
      "x": -11,
      "y": 5,
      "z": 4,
      "name": "Rock_Quartzite_Brick"
    },
    {
      "x": -11,
      "y": 6,
      "z": 4,
      "name": "Rock_Quartzite_Brick"
    },
    {
      "x": -11,
      "y": 7,
      "z": 4,
      "name": "Rock_Quartzite"
    },
    {
      "x": -11,
      "y": 8,
      "z": 4,
      "name": "Rock_Quartzite"
    },
    {
      "x": -11,
      "y": 9,
      "z": 4,
      "name": "Rock_Quartzite"
    },
    {
      "x": -11,
      "y": 10,
      "z": 4,
      "name": "Rock_Quartzite"
    },
    {
      "x": -11,
      "y": 11,
      "z": 4,
      "name": "Rock_Quartzite_Brick"
    },
    {
      "x": -11,
      "y": 0,
      "z": 5,
      "name": "Rock_Quartzite_Brick"
    },
    {
      "x": -11,
      "y": 1,
      "z": 5,
      "name": "Rock_Quartzite_Brick"
    },
    {
      "x": -11,
      "y": 2,
      "z": 5,
      "name": "Rock_Quartzite_Brick"
    },
    {
      "x": -11,
      "y": 3,
      "z": 5,
      "name": "Rock_Quartzite_Brick"
    },
    {
      "x": -11,
      "y": 4,
      "z": 5,
      "name": "Rock_Quartzite_Brick"
    },
    {
      "x": -11,
      "y": 5,
      "z": 5,
      "name": "Rock_Quartzite_Brick"
    },
    {
      "x": -11,
      "y": 6,
      "z": 5,
      "name": "Rock_Quartzite_Brick"
    },
    {
      "x": -11,
      "y": 7,
      "z": 5,
      "name": "Rock_Quartzite"
    },
    {
      "x": -11,
      "y": 0,
      "z": 6,
      "name": "Rock_Quartzite_Brick"
    },
    {
      "x": -11,
      "y": 1,
      "z": 6,
      "name": "Rock_Quartzite_Brick"
    },
    {
      "x": -11,
      "y": 2,
      "z": 6,
      "name": "Rock_Quartzite_Brick"
    },
    {
      "x": -11,
      "y": 3,
      "z": 6,
      "name": "Rock_Quartzite_Brick"
    },
    {
      "x": -11,
      "y": 4,
      "z": 6,
      "name": "Rock_Quartzite_Brick"
    },
    {
      "x": -11,
      "y": 5,
      "z": 6,
      "name": "Rock_Quartzite_Brick"
    },
    {
      "x": -10,
      "y": 0,
      "z": -11,
      "name": "Rock_Quartzite_Brick"
    },
    {
      "x": -10,
      "y": 1,
      "z": -11,
      "name": "Rock_Quartzite_Brick"
    },
    {
      "x": -10,
      "y": 2,
      "z": -11,
      "name": "Rock_Quartzite_Brick"
    },
    {
      "x": -10,
      "y": 3,
      "z": -11,
      "name": "Rock_Quartzite"
    },
    {
      "x": -10,
      "y": 4,
      "z": -11,
      "name": "Rock_Quartzite"
    },
    {
      "x": -10,
      "y": 5,
      "z": -11,
      "name": "Rock_Stone"
    },
    {
      "x": -10,
      "y": 6,
      "z": -11,
      "name": "Rock_Stone"
    },
    {
      "x": -10,
      "y": 7,
      "z": -11,
      "name": "Rock_Stone"
    },
    {
      "x": -10,
      "y": 8,
      "z": -11,
      "name": "Rock_Stone"
    },
    {
      "x": -10,
      "y": 9,
      "z": -11,
      "name": "Rock_Stone"
    },
    {
      "x": -10,
      "y": 10,
      "z": -11,
      "name": "Rock_Stone"
    },
    {
      "x": -10,
      "y": 11,
      "z": -11,
      "name": "Rock_Stone"
    },
    {
      "x": -10,
      "y": 12,
      "z": -11,
      "name": "Rock_Stone"
    },
    {
      "x": -10,
      "y": 13,
      "z": -11,
      "name": "Rock_Stone"
    },
    {
      "x": -10,
      "y": 14,
      "z": -11,
      "name": "Rock_Stone"
    },
    {
      "x": -10,
      "y": 15,
      "z": -11,
      "name": "Rock_Stone"
    },
    {
      "x": -10,
      "y": 16,
      "z": -11,
      "name": "Rock_Stone"
    },
    {
      "x": -10,
      "y": 17,
      "z": -11,
      "name": "Rock_Stone"
    },
    {
      "x": -10,
      "y": 0,
      "z": -10,
      "name": "Rock_Quartzite_Brick"
    },
    {
      "x": -10,
      "y": 1,
      "z": -10,
      "name": "Rock_Quartzite_Brick"
    },
    {
      "x": -10,
      "y": 2,
      "z": -10,
      "name": "Rock_Quartzite_Brick"
    },
    {
      "x": -10,
      "y": 3,
      "z": -10,
      "name": "Rock_Quartzite_Brick"
    },
    {
      "x": -10,
      "y": 4,
      "z": -10,
      "name": "Rock_Quartzite"
    },
    {
      "x": -10,
      "y": 5,
      "z": -10,
      "name": "Rock_Quartzite_Brick"
    },
    {
      "x": -10,
      "y": 6,
      "z": -10,
      "name": "Rock_Stone"
    },
    {
      "x": -10,
      "y": 7,
      "z": -10,
      "name": "Rock_Stone"
    },
    {
      "x": -10,
      "y": 8,
      "z": -10,
      "name": "Rock_Stone"
    },
    {
      "x": -10,
      "y": 9,
      "z": -10,
      "name": "Rock_Stone"
    },
    {
      "x": -10,
      "y": 10,
      "z": -10,
      "name": "Rock_Stone"
    },
    {
      "x": -10,
      "y": 11,
      "z": -10,
      "name": "Rock_Stone"
    },
    {
      "x": -10,
      "y": 12,
      "z": -10,
      "name": "Rock_Stone"
    },
    {
      "x": -10,
      "y": 13,
      "z": -10,
      "name": "Rock_Stone"
    },
    {
      "x": -10,
      "y": 14,
      "z": -10,
      "name": "Rock_Stone"
    },
    {
      "x": -10,
      "y": 15,
      "z": -10,
      "name": "Rock_Stone"
    },
    {
      "x": -10,
      "y": 16,
      "z": -10,
      "name": "Rock_Stone"
    },
    {
      "x": -10,
      "y": 17,
      "z": -10,
      "name": "Rock_Stone"
    },
    {
      "x": -10,
      "y": 18,
      "z": -10,
      "name": "Rock_Stone"
    },
    {
      "x": -10,
      "y": 19,
      "z": -10,
      "name": "Rock_Stone"
    },
    {
      "x": -10,
      "y": 20,
      "z": -10,
      "name": "Rock_Stone"
    },
    {
      "x": -10,
      "y": 21,
      "z": -10,
      "name": "Rock_Stone"
    },
    {
      "x": -10,
      "y": 22,
      "z": -10,
      "name": "Rock_Stone"
    },
    {
      "x": -10,
      "y": 0,
      "z": -9,
      "name": "Rock_Quartzite_Brick"
    },
    {
      "x": -10,
      "y": 1,
      "z": -9,
      "name": "Rock_Quartzite_Brick"
    },
    {
      "x": -10,
      "y": 2,
      "z": -9,
      "name": "Rock_Quartzite_Brick"
    },
    {
      "x": -10,
      "y": 3,
      "z": -9,
      "name": "Rock_Quartzite_Brick"
    },
    {
      "x": -10,
      "y": 4,
      "z": -9,
      "name": "Rock_Quartzite_Brick"
    },
    {
      "x": -10,
      "y": 5,
      "z": -9,
      "name": "Rock_Quartzite_Brick"
    },
    {
      "x": -10,
      "y": 6,
      "z": -9,
      "name": "Rock_Quartzite_Brick"
    },
    {
      "x": -10,
      "y": 7,
      "z": -9,
      "name": "Rock_Stone"
    },
    {
      "x": -10,
      "y": 8,
      "z": -9,
      "name": "Rock_Stone"
    },
    {
      "x": -10,
      "y": 9,
      "z": -9,
      "name": "Rock_Stone"
    },
    {
      "x": -10,
      "y": 10,
      "z": -9,
      "name": "Rock_Stone"
    },
    {
      "x": -10,
      "y": 11,
      "z": -9,
      "name": "Rock_Stone"
    },
    {
      "x": -10,
      "y": 12,
      "z": -9,
      "name": "Rock_Stone"
    },
    {
      "x": -10,
      "y": 13,
      "z": -9,
      "name": "Rock_Stone"
    },
    {
      "x": -10,
      "y": 14,
      "z": -9,
      "name": "Rock_Stone"
    },
    {
      "x": -10,
      "y": 15,
      "z": -9,
      "name": "Rock_Stone"
    },
    {
      "x": -10,
      "y": 16,
      "z": -9,
      "name": "Rock_Stone"
    },
    {
      "x": -10,
      "y": 17,
      "z": -9,
      "name": "Rock_Stone"
    },
    {
      "x": -10,
      "y": 18,
      "z": -9,
      "name": "Rock_Stone"
    },
    {
      "x": -10,
      "y": 19,
      "z": -9,
      "name": "Rock_Stone"
    },
    {
      "x": -10,
      "y": 20,
      "z": -9,
      "name": "Rock_Stone"
    },
    {
      "x": -10,
      "y": 21,
      "z": -9,
      "name": "Rock_Stone"
    },
    {
      "x": -10,
      "y": 22,
      "z": -9,
      "name": "Rock_Stone"
    },
    {
      "x": -10,
      "y": 23,
      "z": -9,
      "name": "Rock_Stone"
    },
    {
      "x": -10,
      "y": 0,
      "z": -8,
      "name": "Rock_Quartzite_Brick"
    },
    {
      "x": -10,
      "y": 1,
      "z": -8,
      "name": "Rock_Quartzite_Brick"
    },
    {
      "x": -10,
      "y": 2,
      "z": -8,
      "name": "Rock_Quartzite_Brick"
    },
    {
      "x": -10,
      "y": 3,
      "z": -8,
      "name": "Rock_Quartzite_Brick"
    },
    {
      "x": -10,
      "y": 4,
      "z": -8,
      "name": "Rock_Quartzite_Brick"
    },
    {
      "x": -10,
      "y": 6,
      "z": -8,
      "name": "Rock_Stone"
    },
    {
      "x": -10,
      "y": 7,
      "z": -8,
      "name": "Rock_Stone"
    },
    {
      "x": -10,
      "y": 8,
      "z": -8,
      "name": "Rock_Stone"
    },
    {
      "x": -10,
      "y": 9,
      "z": -8,
      "name": "Rock_Stone"
    },
    {
      "x": -10,
      "y": 10,
      "z": -8,
      "name": "Rock_Stone"
    },
    {
      "x": -10,
      "y": 11,
      "z": -8,
      "name": "Rock_Stone"
    },
    {
      "x": -10,
      "y": 12,
      "z": -8,
      "name": "Rock_Stone"
    },
    {
      "x": -10,
      "y": 13,
      "z": -8,
      "name": "Rock_Stone"
    },
    {
      "x": -10,
      "y": 14,
      "z": -8,
      "name": "Rock_Stone"
    },
    {
      "x": -10,
      "y": 15,
      "z": -8,
      "name": "Rock_Stone"
    },
    {
      "x": -10,
      "y": 16,
      "z": -8,
      "name": "Rock_Stone"
    },
    {
      "x": -10,
      "y": 17,
      "z": -8,
      "name": "Rock_Stone"
    },
    {
      "x": -10,
      "y": 18,
      "z": -8,
      "name": "Rock_Stone"
    },
    {
      "x": -10,
      "y": 19,
      "z": -8,
      "name": "Rock_Stone"
    },
    {
      "x": -10,
      "y": 20,
      "z": -8,
      "name": "Rock_Stone"
    },
    {
      "x": -10,
      "y": 21,
      "z": -8,
      "name": "Rock_Stone"
    },
    {
      "x": -10,
      "y": 22,
      "z": -8,
      "name": "Rock_Stone"
    },
    {
      "x": -10,
      "y": 23,
      "z": -8,
      "name": "Rock_Stone"
    },
    {
      "x": -10,
      "y": 0,
      "z": -7,
      "name": "Rock_Quartzite_Brick"
    },
    {
      "x": -10,
      "y": 1,
      "z": -7,
      "name": "Rock_Quartzite_Brick"
    },
    {
      "x": -10,
      "y": 2,
      "z": -7,
      "name": "Rock_Quartzite"
    },
    {
      "x": -10,
      "y": 3,
      "z": -7,
      "name": "Rock_Quartzite_Brick"
    },
    {
      "x": -10,
      "y": 4,
      "z": -7,
      "name": "Rock_Quartzite_Brick"
    },
    {
      "x": -10,
      "y": 7,
      "z": -7,
      "name": "Rock_Stone"
    },
    {
      "x": -10,
      "y": 8,
      "z": -7,
      "name": "Rock_Stone"
    },
    {
      "x": -10,
      "y": 9,
      "z": -7,
      "name": "Rock_Stone"
    },
    {
      "x": -10,
      "y": 10,
      "z": -7,
      "name": "Rock_Stone"
    },
    {
      "x": -10,
      "y": 11,
      "z": -7,
      "name": "Rock_Stone"
    },
    {
      "x": -10,
      "y": 12,
      "z": -7,
      "name": "Rock_Stone"
    },
    {
      "x": -10,
      "y": 13,
      "z": -7,
      "name": "Rock_Stone"
    },
    {
      "x": -10,
      "y": 14,
      "z": -7,
      "name": "Rock_Stone"
    },
    {
      "x": -10,
      "y": 15,
      "z": -7,
      "name": "Rock_Stone"
    },
    {
      "x": -10,
      "y": 16,
      "z": -7,
      "name": "Rock_Stone"
    },
    {
      "x": -10,
      "y": 17,
      "z": -7,
      "name": "Rock_Stone"
    },
    {
      "x": -10,
      "y": 18,
      "z": -7,
      "name": "Rock_Stone"
    },
    {
      "x": -10,
      "y": 19,
      "z": -7,
      "name": "Rock_Stone"
    },
    {
      "x": -10,
      "y": 20,
      "z": -7,
      "name": "Rock_Stone"
    },
    {
      "x": -10,
      "y": 21,
      "z": -7,
      "name": "Rock_Stone"
    },
    {
      "x": -10,
      "y": 22,
      "z": -7,
      "name": "Rock_Stone"
    },
    {
      "x": -10,
      "y": 23,
      "z": -7,
      "name": "Rock_Stone"
    },
    {
      "x": -10,
      "y": 0,
      "z": -6,
      "name": "Rock_Quartzite_Brick"
    },
    {
      "x": -10,
      "y": 1,
      "z": -6,
      "name": "Rock_Quartzite"
    },
    {
      "x": -10,
      "y": 2,
      "z": -6,
      "name": "Rock_Quartzite"
    },
    {
      "x": -10,
      "y": 8,
      "z": -6,
      "name": "Rock_Stone"
    },
    {
      "x": -10,
      "y": 9,
      "z": -6,
      "name": "Rock_Stone"
    },
    {
      "x": -10,
      "y": 10,
      "z": -6,
      "name": "Rock_Stone"
    },
    {
      "x": -10,
      "y": 11,
      "z": -6,
      "name": "Rock_Stone"
    },
    {
      "x": -10,
      "y": 14,
      "z": -6,
      "name": "Rock_Quartzite_Brick"
    },
    {
      "x": -10,
      "y": 15,
      "z": -6,
      "name": "Rock_Quartzite_Brick"
    },
    {
      "x": -10,
      "y": 16,
      "z": -6,
      "name": "Rock_Stone"
    },
    {
      "x": -10,
      "y": 17,
      "z": -6,
      "name": "Rock_Stone"
    },
    {
      "x": -10,
      "y": 18,
      "z": -6,
      "name": "Rock_Stone"
    },
    {
      "x": -10,
      "y": 0,
      "z": -5,
      "name": "Rock_Quartzite"
    },
    {
      "x": -10,
      "y": 1,
      "z": -5,
      "name": "Rock_Quartzite"
    },
    {
      "x": -10,
      "y": 2,
      "z": -5,
      "name": "Rock_Quartzite"
    },
    {
      "x": -10,
      "y": 15,
      "z": -5,
      "name": "Rock_Quartzite_Brick"
    },
    {
      "x": -10,
      "y": 16,
      "z": -5,
      "name": "Soil_Grass"
    },
    {
      "x": -10,
      "y": 15,
      "z": -4,
      "name": "Rock_Quartzite_Brick"
    },
    {
      "x": -10,
      "y": 16,
      "z": -4,
      "name": "Soil_Grass"
    },
    {
      "x": -10,
      "y": 17,
      "z": -4,
      "name": "Plant_Grass_Sharp_Tall"
    },
    {
      "x": -10,
      "y": 18,
      "z": -4,
      "name": "Plant_Grass_Sharp_Tall",
      "filler": 1024
    },
    {
      "x": -10,
      "y": 14,
      "z": -3,
      "name": "Rock_Quartzite_Brick"
    },
    {
      "x": -10,
      "y": 15,
      "z": -3,
      "name": "Rock_Quartzite_Cobble"
    },
    {
      "x": -10,
      "y": 16,
      "z": -3,
      "name": "Soil_Grass"
    },
    {
      "x": -10,
      "y": 17,
      "z": -3,
      "name": "Plant_Grass_Sharp_Tall"
    },
    {
      "x": -10,
      "y": 18,
      "z": -3,
      "name": "Plant_Grass_Sharp_Tall",
      "filler": 1024
    },
    {
      "x": -10,
      "y": 14,
      "z": -2,
      "name": "Rock_Quartzite_Brick"
    },
    {
      "x": -10,
      "y": 15,
      "z": -2,
      "name": "Rock_Quartzite_Cobble"
    },
    {
      "x": -10,
      "y": 16,
      "z": -2,
      "name": "Soil_Grass"
    },
    {
      "x": -10,
      "y": 0,
      "z": -1,
      "name": "Rubble_Stone_Medium"
    },
    {
      "x": -10,
      "y": 14,
      "z": -1,
      "name": "Rock_Quartzite_Brick"
    },
    {
      "x": -10,
      "y": 15,
      "z": -1,
      "name": "Soil_Grass"
    },
    {
      "x": -10,
      "y": 16,
      "z": -1,
      "name": "Plant_Grass_Sharp"
    },
    {
      "x": -10,
      "y": 0,
      "z": 0,
      "name": "Rock_Stone"
    },
    {
      "x": -10,
      "y": 1,
      "z": 0,
      "name": "Rock_Stone"
    },
    {
      "x": -10,
      "y": 2,
      "z": 0,
      "name": "Rock_Stone"
    },
    {
      "x": -10,
      "y": 3,
      "z": 0,
      "name": "Rock_Stone"
    },
    {
      "x": -10,
      "y": 4,
      "z": 0,
      "name": "Rock_Stone"
    },
    {
      "x": -10,
      "y": 13,
      "z": 0,
      "name": "Rock_Stone_Stalactite_Small",
      "rotation": 8
    },
    {
      "x": -10,
      "y": 14,
      "z": 0,
      "name": "Rock_Quartzite_Cobble"
    },
    {
      "x": -10,
      "y": 15,
      "z": 0,
      "name": "Soil_Grass"
    },
    {
      "x": -10,
      "y": 0,
      "z": 1,
      "name": "Rock_Stone"
    },
    {
      "x": -10,
      "y": 1,
      "z": 1,
      "name": "Rock_Stone"
    },
    {
      "x": -10,
      "y": 2,
      "z": 1,
      "name": "Rock_Stone"
    },
    {
      "x": -10,
      "y": 3,
      "z": 1,
      "name": "Rock_Stone"
    },
    {
      "x": -10,
      "y": 4,
      "z": 1,
      "name": "Rock_Stone"
    },
    {
      "x": -10,
      "y": 5,
      "z": 1,
      "name": "Rock_Quartzite_Cobble"
    },
    {
      "x": -10,
      "y": 6,
      "z": 1,
      "name": "Rock_Quartzite_Brick_Smooth"
    },
    {
      "x": -10,
      "y": 7,
      "z": 1,
      "name": "Rock_Quartzite_Brick_Smooth"
    },
    {
      "x": -10,
      "y": 8,
      "z": 1,
      "name": "Rock_Quartzite_Brick"
    },
    {
      "x": -10,
      "y": 9,
      "z": 1,
      "name": "Rock_Quartzite_Brick"
    },
    {
      "x": -10,
      "y": 10,
      "z": 1,
      "name": "Rock_Quartzite_Brick"
    },
    {
      "x": -10,
      "y": 11,
      "z": 1,
      "name": "Rock_Quartzite_Brick"
    },
    {
      "x": -10,
      "y": 12,
      "z": 1,
      "name": "Rock_Quartzite_Brick"
    },
    {
      "x": -10,
      "y": 13,
      "z": 1,
      "name": "Rock_Quartzite_Brick"
    },
    {
      "x": -10,
      "y": 14,
      "z": 1,
      "name": "Rock_Quartzite_Cobble"
    },
    {
      "x": -10,
      "y": 15,
      "z": 1,
      "name": "Soil_Grass"
    },
    {
      "x": -10,
      "y": 0,
      "z": 2,
      "name": "Rock_Stone"
    },
    {
      "x": -10,
      "y": 1,
      "z": 2,
      "name": "Rock_Stone"
    },
    {
      "x": -10,
      "y": 2,
      "z": 2,
      "name": "Rock_Stone"
    },
    {
      "x": -10,
      "y": 3,
      "z": 2,
      "name": "Rock_Stone"
    },
    {
      "x": -10,
      "y": 4,
      "z": 2,
      "name": "Rock_Stone"
    },
    {
      "x": -10,
      "y": 5,
      "z": 2,
      "name": "Rock_Quartzite_Cobble"
    },
    {
      "x": -10,
      "y": 6,
      "z": 2,
      "name": "Rock_Quartzite_Brick"
    },
    {
      "x": -10,
      "y": 7,
      "z": 2,
      "name": "Rock_Quartzite"
    },
    {
      "x": -10,
      "y": 8,
      "z": 2,
      "name": "Rock_Quartzite_Brick"
    },
    {
      "x": -10,
      "y": 9,
      "z": 2,
      "name": "Rock_Quartzite"
    },
    {
      "x": -10,
      "y": 10,
      "z": 2,
      "name": "Rock_Quartzite_Cobble"
    },
    {
      "x": -10,
      "y": 11,
      "z": 2,
      "name": "Rock_Quartzite_Brick"
    },
    {
      "x": -10,
      "y": 12,
      "z": 2,
      "name": "Rock_Quartzite_Brick"
    },
    {
      "x": -10,
      "y": 13,
      "z": 2,
      "name": "Rock_Quartzite_Cobble"
    },
    {
      "x": -10,
      "y": 14,
      "z": 2,
      "name": "Rock_Quartzite_Cobble"
    },
    {
      "x": -10,
      "y": 15,
      "z": 2,
      "name": "Rock_Quartzite_Brick"
    },
    {
      "x": -10,
      "y": 16,
      "z": 2,
      "name": "Rock_Quartzite_Brick"
    },
    {
      "x": -10,
      "y": 17,
      "z": 2,
      "name": "Rock_Quartzite_Brick"
    },
    {
      "x": -10,
      "y": 18,
      "z": 2,
      "name": "Plant_Moss_Rug_Green"
    },
    {
      "x": -10,
      "y": 0,
      "z": 3,
      "name": "Rock_Stone"
    },
    {
      "x": -10,
      "y": 1,
      "z": 3,
      "name": "Rock_Stone"
    },
    {
      "x": -10,
      "y": 2,
      "z": 3,
      "name": "Rock_Stone"
    },
    {
      "x": -10,
      "y": 3,
      "z": 3,
      "name": "Rock_Stone"
    },
    {
      "x": -10,
      "y": 4,
      "z": 3,
      "name": "Rock_Stone"
    },
    {
      "x": -10,
      "y": 5,
      "z": 3,
      "name": "Rock_Quartzite_Cobble"
    },
    {
      "x": -10,
      "y": 6,
      "z": 3,
      "name": "Rock_Quartzite_Cobble"
    },
    {
      "x": -10,
      "y": 7,
      "z": 3,
      "name": "Rock_Quartzite"
    },
    {
      "x": -10,
      "y": 8,
      "z": 3,
      "name": "Rock_Quartzite"
    },
    {
      "x": -10,
      "y": 9,
      "z": 3,
      "name": "Rock_Quartzite"
    },
    {
      "x": -10,
      "y": 10,
      "z": 3,
      "name": "Rock_Quartzite_Cobble"
    },
    {
      "x": -10,
      "y": 11,
      "z": 3,
      "name": "Rock_Quartzite_Brick"
    },
    {
      "x": -10,
      "y": 12,
      "z": 3,
      "name": "Rock_Quartzite_Brick"
    },
    {
      "x": -10,
      "y": 13,
      "z": 3,
      "name": "Rock_Quartzite_Cobble"
    },
    {
      "x": -10,
      "y": 14,
      "z": 3,
      "name": "Rock_Quartzite_Brick"
    },
    {
      "x": -10,
      "y": 15,
      "z": 3,
      "name": "Rock_Quartzite_Brick"
    },
    {
      "x": -10,
      "y": 16,
      "z": 3,
      "name": "Rock_Quartzite_Brick"
    },
    {
      "x": -10,
      "y": 17,
      "z": 3,
      "name": "Rock_Quartzite_Brick"
    },
    {
      "x": -10,
      "y": 18,
      "z": 3,
      "name": "Plant_Moss_Rug_Green"
    },
    {
      "x": -10,
      "y": 0,
      "z": 4,
      "name": "Rock_Stone_Cobble"
    },
    {
      "x": -10,
      "y": 1,
      "z": 4,
      "name": "Rock_Stone_Cobble"
    },
    {
      "x": -10,
      "y": 2,
      "z": 4,
      "name": "Rock_Stone_Cobble"
    },
    {
      "x": -10,
      "y": 3,
      "z": 4,
      "name": "Rock_Stone_Cobble"
    },
    {
      "x": -10,
      "y": 4,
      "z": 4,
      "name": "Rock_Stone_Cobble"
    },
    {
      "x": -10,
      "y": 5,
      "z": 4,
      "name": "Rock_Stone_Cobble"
    },
    {
      "x": -10,
      "y": 6,
      "z": 4,
      "name": "Rock_Stone_Cobble"
    },
    {
      "x": -10,
      "y": 7,
      "z": 4,
      "name": "Rock_Stone_Cobble"
    },
    {
      "x": -9,
      "y": 0,
      "z": -11,
      "name": "Rock_Quartzite_Brick"
    },
    {
      "x": -9,
      "y": 1,
      "z": -11,
      "name": "Rock_Quartzite_Brick"
    },
    {
      "x": -9,
      "y": 2,
      "z": -11,
      "name": "Rock_Quartzite"
    },
    {
      "x": -9,
      "y": 3,
      "z": -11,
      "name": "Rock_Quartzite"
    },
    {
      "x": -9,
      "y": 4,
      "z": -11,
      "name": "Rock_Stone"
    },
    {
      "x": -9,
      "y": 5,
      "z": -11,
      "name": "Rock_Stone"
    },
    {
      "x": -9,
      "y": 6,
      "z": -11,
      "name": "Rock_Stone"
    },
    {
      "x": -9,
      "y": 7,
      "z": -11,
      "name": "Rock_Stone"
    },
    {
      "x": -9,
      "y": 8,
      "z": -11,
      "name": "Rock_Stone"
    },
    {
      "x": -9,
      "y": 9,
      "z": -11,
      "name": "Rock_Stone"
    },
    {
      "x": -9,
      "y": 10,
      "z": -11,
      "name": "Rock_Stone"
    },
    {
      "x": -9,
      "y": 11,
      "z": -11,
      "name": "Rock_Stone"
    },
    {
      "x": -9,
      "y": 12,
      "z": -11,
      "name": "Rock_Stone"
    },
    {
      "x": -9,
      "y": 13,
      "z": -11,
      "name": "Rock_Stone"
    },
    {
      "x": -9,
      "y": 14,
      "z": -11,
      "name": "Rock_Stone"
    },
    {
      "x": -9,
      "y": 15,
      "z": -11,
      "name": "Rock_Stone"
    },
    {
      "x": -9,
      "y": 16,
      "z": -11,
      "name": "Rock_Stone"
    },
    {
      "x": -9,
      "y": 17,
      "z": -11,
      "name": "Rock_Stone"
    },
    {
      "x": -9,
      "y": 0,
      "z": -10,
      "name": "Rock_Quartzite_Brick"
    },
    {
      "x": -9,
      "y": 1,
      "z": -10,
      "name": "Rock_Quartzite_Brick"
    },
    {
      "x": -9,
      "y": 2,
      "z": -10,
      "name": "Soil_Gravel"
    },
    {
      "x": -9,
      "y": 3,
      "z": -10,
      "name": "Rock_Stone_Cobble"
    },
    {
      "x": -9,
      "y": 4,
      "z": -10,
      "name": "Rock_Stone_Cobble"
    },
    {
      "x": -9,
      "y": 7,
      "z": -10,
      "name": "Rock_Stone"
    },
    {
      "x": -9,
      "y": 8,
      "z": -10,
      "name": "Rock_Stone"
    },
    {
      "x": -9,
      "y": 9,
      "z": -10,
      "name": "Rock_Stone"
    },
    {
      "x": -9,
      "y": 10,
      "z": -10,
      "name": "Rock_Stone"
    },
    {
      "x": -9,
      "y": 11,
      "z": -10,
      "name": "Rock_Stone"
    },
    {
      "x": -9,
      "y": 12,
      "z": -10,
      "name": "Rock_Stone"
    },
    {
      "x": -9,
      "y": 13,
      "z": -10,
      "name": "Rock_Stone"
    },
    {
      "x": -9,
      "y": 14,
      "z": -10,
      "name": "Rock_Stone"
    },
    {
      "x": -9,
      "y": 15,
      "z": -10,
      "name": "Rock_Stone"
    },
    {
      "x": -9,
      "y": 16,
      "z": -10,
      "name": "Rock_Stone"
    },
    {
      "x": -9,
      "y": 17,
      "z": -10,
      "name": "Rock_Stone"
    },
    {
      "x": -9,
      "y": 18,
      "z": -10,
      "name": "Rock_Stone"
    },
    {
      "x": -9,
      "y": 19,
      "z": -10,
      "name": "Rock_Stone"
    },
    {
      "x": -9,
      "y": 20,
      "z": -10,
      "name": "Rock_Stone"
    },
    {
      "x": -9,
      "y": 21,
      "z": -10,
      "name": "Rock_Stone"
    },
    {
      "x": -9,
      "y": 22,
      "z": -10,
      "name": "Rock_Stone"
    },
    {
      "x": -9,
      "y": 0,
      "z": -9,
      "name": "Rock_Quartzite_Brick"
    },
    {
      "x": -9,
      "y": 1,
      "z": -9,
      "name": "Rock_Quartzite_Brick"
    },
    {
      "x": -9,
      "y": 2,
      "z": -9,
      "name": "Soil_Gravel"
    },
    {
      "x": -9,
      "y": 3,
      "z": -9,
      "name": "Rubble_Stone_Medium"
    },
    {
      "x": -9,
      "y": 8,
      "z": -9,
      "name": "Rock_Stone"
    },
    {
      "x": -9,
      "y": 9,
      "z": -9,
      "name": "Rock_Stone"
    },
    {
      "x": -9,
      "y": 10,
      "z": -9,
      "name": "Rock_Stone"
    },
    {
      "x": -9,
      "y": 11,
      "z": -9,
      "name": "Rock_Stone"
    },
    {
      "x": -9,
      "y": 12,
      "z": -9,
      "name": "Rock_Stone"
    },
    {
      "x": -9,
      "y": 13,
      "z": -9,
      "name": "Rock_Stone"
    },
    {
      "x": -9,
      "y": 14,
      "z": -9,
      "name": "Rock_Stone"
    },
    {
      "x": -9,
      "y": 15,
      "z": -9,
      "name": "Rock_Stone"
    },
    {
      "x": -9,
      "y": 16,
      "z": -9,
      "name": "Rock_Stone"
    },
    {
      "x": -9,
      "y": 17,
      "z": -9,
      "name": "Rock_Stone"
    },
    {
      "x": -9,
      "y": 18,
      "z": -9,
      "name": "Rock_Stone"
    },
    {
      "x": -9,
      "y": 19,
      "z": -9,
      "name": "Rock_Stone"
    },
    {
      "x": -9,
      "y": 20,
      "z": -9,
      "name": "Rock_Stone"
    },
    {
      "x": -9,
      "y": 21,
      "z": -9,
      "name": "Rock_Stone"
    },
    {
      "x": -9,
      "y": 22,
      "z": -9,
      "name": "Rock_Stone"
    },
    {
      "x": -9,
      "y": 23,
      "z": -9,
      "name": "Rock_Stone"
    },
    {
      "x": -9,
      "y": 0,
      "z": -8,
      "name": "Rock_Quartzite_Brick"
    },
    {
      "x": -9,
      "y": 1,
      "z": -8,
      "name": "Rock_Quartzite_Brick"
    },
    {
      "x": -9,
      "y": 2,
      "z": -8,
      "name": "Soil_Gravel"
    },
    {
      "x": -9,
      "y": 7,
      "z": -8,
      "name": "Plant_Moss_Cave_Green_Dark",
      "rotation": 8
    },
    {
      "x": -9,
      "y": 8,
      "z": -8,
      "name": "Rock_Stone"
    },
    {
      "x": -9,
      "y": 9,
      "z": -8,
      "name": "Rock_Stone"
    },
    {
      "x": -9,
      "y": 10,
      "z": -8,
      "name": "Rock_Stone"
    },
    {
      "x": -9,
      "y": 11,
      "z": -8,
      "name": "Rock_Stone"
    },
    {
      "x": -9,
      "y": 12,
      "z": -8,
      "name": "Rock_Stone"
    },
    {
      "x": -9,
      "y": 13,
      "z": -8,
      "name": "Rock_Stone"
    },
    {
      "x": -9,
      "y": 14,
      "z": -8,
      "name": "Rock_Quartzite_Brick"
    },
    {
      "x": -9,
      "y": 15,
      "z": -8,
      "name": "Rock_Stone"
    },
    {
      "x": -9,
      "y": 16,
      "z": -8,
      "name": "Rock_Stone"
    },
    {
      "x": -9,
      "y": 17,
      "z": -8,
      "name": "Rock_Stone"
    },
    {
      "x": -9,
      "y": 18,
      "z": -8,
      "name": "Rock_Stone"
    },
    {
      "x": -9,
      "y": 19,
      "z": -8,
      "name": "Rock_Stone"
    },
    {
      "x": -9,
      "y": 20,
      "z": -8,
      "name": "Rock_Stone"
    },
    {
      "x": -9,
      "y": 21,
      "z": -8,
      "name": "Rock_Stone"
    },
    {
      "x": -9,
      "y": 22,
      "z": -8,
      "name": "Rock_Stone"
    },
    {
      "x": -9,
      "y": 23,
      "z": -8,
      "name": "Rock_Stone"
    },
    {
      "x": -9,
      "y": 0,
      "z": -7,
      "name": "Rock_Quartzite_Brick"
    },
    {
      "x": -9,
      "y": 1,
      "z": -7,
      "name": "Rock_Stone_Cobble"
    },
    {
      "x": -9,
      "y": 2,
      "z": -7,
      "name": "Rock_Stone_Cobble_Stairs"
    },
    {
      "x": -9,
      "y": 9,
      "z": -7,
      "name": "Rock_Stone"
    },
    {
      "x": -9,
      "y": 10,
      "z": -7,
      "name": "Rock_Stone"
    },
    {
      "x": -9,
      "y": 11,
      "z": -7,
      "name": "Rock_Stone"
    },
    {
      "x": -9,
      "y": 14,
      "z": -7,
      "name": "Rock_Quartzite_Brick"
    },
    {
      "x": -9,
      "y": 15,
      "z": -7,
      "name": "Rock_Stone"
    },
    {
      "x": -9,
      "y": 16,
      "z": -7,
      "name": "Rock_Stone"
    },
    {
      "x": -9,
      "y": 17,
      "z": -7,
      "name": "Rock_Stone"
    },
    {
      "x": -9,
      "y": 18,
      "z": -7,
      "name": "Rock_Stone"
    },
    {
      "x": -9,
      "y": 19,
      "z": -7,
      "name": "Rock_Stone"
    },
    {
      "x": -9,
      "y": 20,
      "z": -7,
      "name": "Rock_Stone"
    },
    {
      "x": -9,
      "y": 21,
      "z": -7,
      "name": "Rock_Stone"
    },
    {
      "x": -9,
      "y": 22,
      "z": -7,
      "name": "Rock_Stone"
    },
    {
      "x": -9,
      "y": 23,
      "z": -7,
      "name": "Rock_Stone"
    },
    {
      "x": -9,
      "y": 0,
      "z": -6,
      "name": "Rock_Stone_Cobble"
    },
    {
      "x": -9,
      "y": 1,
      "z": -6,
      "name": "Rock_Stone_Cobble_Stairs"
    },
    {
      "x": -9,
      "y": 14,
      "z": -6,
      "name": "Rock_Quartzite_Brick"
    },
    {
      "x": -9,
      "y": 15,
      "z": -6,
      "name": "Rock_Quartzite_Brick"
    },
    {
      "x": -9,
      "y": 16,
      "z": -6,
      "name": "Rock_Stone"
    },
    {
      "x": -9,
      "y": 17,
      "z": -6,
      "name": "Rock_Stone"
    },
    {
      "x": -9,
      "y": 18,
      "z": -6,
      "name": "Rock_Stone"
    },
    {
      "x": -9,
      "y": 19,
      "z": -6,
      "name": "Rock_Stone"
    },
    {
      "x": -9,
      "y": 20,
      "z": -6,
      "name": "Rock_Stone"
    },
    {
      "x": -9,
      "y": 21,
      "z": -6,
      "name": "Rock_Stone"
    },
    {
      "x": -9,
      "y": 0,
      "z": -5,
      "name": "Rock_Stone_Cobble_Stairs"
    },
    {
      "x": -9,
      "y": 15,
      "z": -5,
      "name": "Rock_Quartzite_Brick"
    },
    {
      "x": -9,
      "y": 16,
      "z": -5,
      "name": "Rock_Stone"
    },
    {
      "x": -9,
      "y": 17,
      "z": -5,
      "name": "Soil_Grass"
    },
    {
      "x": -9,
      "y": 15,
      "z": -4,
      "name": "Rock_Quartzite_Cobble"
    },
    {
      "x": -9,
      "y": 16,
      "z": -4,
      "name": "Soil_Grass"
    },
    {
      "x": -9,
      "y": 17,
      "z": -4,
      "name": "Plant_Grass_Sharp_Tall"
    },
    {
      "x": -9,
      "y": 18,
      "z": -4,
      "name": "Plant_Grass_Sharp_Tall",
      "filler": 1024
    },
    {
      "x": -9,
      "y": 14,
      "z": -3,
      "name": "Rock_Quartzite_Brick"
    },
    {
      "x": -9,
      "y": 15,
      "z": -3,
      "name": "Rock_Quartzite_Cobble"
    },
    {
      "x": -9,
      "y": 16,
      "z": -3,
      "name": "Soil_Grass"
    },
    {
      "x": -9,
      "y": 17,
      "z": -3,
      "name": "Plant_Grass_Sharp_Tall"
    },
    {
      "x": -9,
      "y": 18,
      "z": -3,
      "name": "Plant_Grass_Sharp_Tall",
      "filler": 1024
    },
    {
      "x": -9,
      "y": 14,
      "z": -2,
      "name": "Rock_Quartzite_Brick"
    },
    {
      "x": -9,
      "y": 15,
      "z": -2,
      "name": "Rock_Quartzite_Cobble"
    },
    {
      "x": -9,
      "y": 16,
      "z": -2,
      "name": "Soil_Grass"
    },
    {
      "x": -9,
      "y": 14,
      "z": -1,
      "name": "Rock_Quartzite_Brick"
    },
    {
      "x": -9,
      "y": 15,
      "z": -1,
      "name": "Soil_Grass"
    },
    {
      "x": -9,
      "y": 0,
      "z": 0,
      "name": "Rock_Stone"
    },
    {
      "x": -9,
      "y": 1,
      "z": 0,
      "name": "Rock_Stone_Stalactite_Small"
    },
    {
      "x": -9,
      "y": 14,
      "z": 0,
      "name": "Rock_Quartzite_Brick"
    },
    {
      "x": -9,
      "y": 15,
      "z": 0,
      "name": "Rock_Stone"
    },
    {
      "x": -9,
      "y": 16,
      "z": 0,
      "name": "Rock_Stone"
    },
    {
      "x": -9,
      "y": 17,
      "z": 0,
      "name": "Rock_Stone"
    },
    {
      "x": -9,
      "y": 0,
      "z": 1,
      "name": "Rock_Stone"
    },
    {
      "x": -9,
      "y": 1,
      "z": 1,
      "name": "Rock_Stone"
    },
    {
      "x": -9,
      "y": 2,
      "z": 1,
      "name": "Rock_Stone"
    },
    {
      "x": -9,
      "y": 14,
      "z": 1,
      "name": "Rock_Quartzite_Brick"
    },
    {
      "x": -9,
      "y": 15,
      "z": 1,
      "name": "Rock_Stone"
    },
    {
      "x": -9,
      "y": 16,
      "z": 1,
      "name": "Rock_Stone"
    },
    {
      "x": -9,
      "y": 0,
      "z": 2,
      "name": "Rock_Stone"
    },
    {
      "x": -9,
      "y": 1,
      "z": 2,
      "name": "Rock_Stone"
    },
    {
      "x": -9,
      "y": 2,
      "z": 2,
      "name": "Rock_Stone"
    },
    {
      "x": -9,
      "y": 3,
      "z": 2,
      "name": "Rock_Stone"
    },
    {
      "x": -9,
      "y": 4,
      "z": 2,
      "name": "Rock_Quartzite_Cobble"
    },
    {
      "x": -9,
      "y": 5,
      "z": 2,
      "name": "Rock_Quartzite_Cobble"
    },
    {
      "x": -9,
      "y": 6,
      "z": 2,
      "name": "Rock_Stone_Brick_Smooth"
    },
    {
      "x": -9,
      "y": 7,
      "z": 2,
      "name": "Rock_Stone_Brick_Smooth"
    },
    {
      "x": -9,
      "y": 13,
      "z": 2,
      "name": "Rock_Quartzite_Brick"
    },
    {
      "x": -9,
      "y": 14,
      "z": 2,
      "name": "Rock_Quartzite_Brick"
    },
    {
      "x": -9,
      "y": 15,
      "z": 2,
      "name": "Rock_Quartzite_Brick"
    },
    {
      "x": -9,
      "y": 0,
      "z": 3,
      "name": "Rock_Stone"
    },
    {
      "x": -9,
      "y": 1,
      "z": 3,
      "name": "Rock_Stone"
    },
    {
      "x": -9,
      "y": 2,
      "z": 3,
      "name": "Rock_Quartzite"
    },
    {
      "x": -9,
      "y": 3,
      "z": 3,
      "name": "Rock_Stone"
    },
    {
      "x": -9,
      "y": 4,
      "z": 3,
      "name": "Rock_Quartzite_Cobble"
    },
    {
      "x": -9,
      "y": 5,
      "z": 3,
      "name": "Rock_Quartzite_Cobble"
    },
    {
      "x": -9,
      "y": 6,
      "z": 3,
      "name": "Rock_Quartzite"
    },
    {
      "x": -9,
      "y": 7,
      "z": 3,
      "name": "Rock_Quartzite"
    },
    {
      "x": -9,
      "y": 8,
      "z": 3,
      "name": "Rock_Quartzite"
    },
    {
      "x": -9,
      "y": 9,
      "z": 3,
      "name": "Rock_Quartzite_Cobble"
    },
    {
      "x": -9,
      "y": 10,
      "z": 3,
      "name": "Rock_Quartzite_Cobble"
    },
    {
      "x": -9,
      "y": 11,
      "z": 3,
      "name": "Rock_Quartzite_Cobble"
    },
    {
      "x": -9,
      "y": 12,
      "z": 3,
      "name": "Rock_Quartzite_Brick"
    },
    {
      "x": -9,
      "y": 13,
      "z": 3,
      "name": "Rock_Quartzite_Brick"
    },
    {
      "x": -9,
      "y": 14,
      "z": 3,
      "name": "Rock_Quartzite_Brick"
    },
    {
      "x": -9,
      "y": 15,
      "z": 3,
      "name": "Rock_Quartzite_Brick"
    },
    {
      "x": -9,
      "y": 16,
      "z": 3,
      "name": "Plant_Moss_Rug_Green"
    },
    {
      "x": -9,
      "y": 0,
      "z": 4,
      "name": "Rock_Stone_Cobble"
    },
    {
      "x": -9,
      "y": 1,
      "z": 4,
      "name": "Rock_Stone_Cobble"
    },
    {
      "x": -9,
      "y": 2,
      "z": 4,
      "name": "Rock_Stone_Cobble"
    },
    {
      "x": -9,
      "y": 3,
      "z": 4,
      "name": "Rock_Stone_Cobble"
    },
    {
      "x": -9,
      "y": 4,
      "z": 4,
      "name": "Rock_Stone_Brick"
    },
    {
      "x": -9,
      "y": 5,
      "z": 4,
      "name": "Rock_Stone_Brick"
    },
    {
      "x": -9,
      "y": 6,
      "z": 4,
      "name": "Rock_Stone_Brick"
    },
    {
      "x": -9,
      "y": 7,
      "z": 4,
      "name": "Rock_Stone_Brick"
    },
    {
      "x": -8,
      "y": 0,
      "z": -11,
      "name": "Rock_Quartzite_Brick"
    },
    {
      "x": -8,
      "y": 1,
      "z": -11,
      "name": "Rock_Quartzite_Brick"
    },
    {
      "x": -8,
      "y": 2,
      "z": -11,
      "name": "Rock_Quartzite"
    },
    {
      "x": -8,
      "y": 3,
      "z": -11,
      "name": "Rock_Stone_Cobble"
    },
    {
      "x": -8,
      "y": 4,
      "z": -11,
      "name": "Rock_Quartzite_Cobble"
    },
    {
      "x": -8,
      "y": 5,
      "z": -11,
      "name": "Rock_Quartzite_Cobble"
    },
    {
      "x": -8,
      "y": 6,
      "z": -11,
      "name": "Rock_Stone"
    },
    {
      "x": -8,
      "y": 7,
      "z": -11,
      "name": "Rock_Stone"
    },
    {
      "x": -8,
      "y": 8,
      "z": -11,
      "name": "Rock_Stone"
    },
    {
      "x": -8,
      "y": 9,
      "z": -11,
      "name": "Rock_Stone"
    },
    {
      "x": -8,
      "y": 10,
      "z": -11,
      "name": "Rock_Stone"
    },
    {
      "x": -8,
      "y": 11,
      "z": -11,
      "name": "Rock_Stone"
    },
    {
      "x": -8,
      "y": 12,
      "z": -11,
      "name": "Rock_Stone"
    },
    {
      "x": -8,
      "y": 13,
      "z": -11,
      "name": "Rock_Stone"
    },
    {
      "x": -8,
      "y": 14,
      "z": -11,
      "name": "Rock_Stone"
    },
    {
      "x": -8,
      "y": 15,
      "z": -11,
      "name": "Rock_Stone"
    },
    {
      "x": -8,
      "y": 16,
      "z": -11,
      "name": "Soil_Grass"
    },
    {
      "x": -8,
      "y": 0,
      "z": -10,
      "name": "Rock_Quartzite_Brick"
    },
    {
      "x": -8,
      "y": 1,
      "z": -10,
      "name": "Rock_Quartzite_Brick"
    },
    {
      "x": -8,
      "y": 2,
      "z": -10,
      "name": "Soil_Gravel"
    },
    {
      "x": -8,
      "y": 3,
      "z": -10,
      "name": "Nat20_Force_Empty"
    },
    {
      "x": -8,
      "y": 4,
      "z": -10,
      "name": "Nat20_Force_Empty"
    },
    {
      "x": -8,
      "y": 5,
      "z": -10,
      "name": "Nat20_Force_Empty"
    },
    {
      "x": -8,
      "y": 6,
      "z": -10,
      "name": "Nat20_Force_Empty"
    },
    {
      "x": -8,
      "y": 7,
      "z": -10,
      "name": "Nat20_Force_Empty"
    },
    {
      "x": -8,
      "y": 8,
      "z": -10,
      "name": "Rock_Stone"
    },
    {
      "x": -8,
      "y": 9,
      "z": -10,
      "name": "Rock_Stone"
    },
    {
      "x": -8,
      "y": 10,
      "z": -10,
      "name": "Rock_Stone"
    },
    {
      "x": -8,
      "y": 11,
      "z": -10,
      "name": "Rock_Stone"
    },
    {
      "x": -8,
      "y": 12,
      "z": -10,
      "name": "Rock_Stone"
    },
    {
      "x": -8,
      "y": 13,
      "z": -10,
      "name": "Rock_Stone"
    },
    {
      "x": -8,
      "y": 14,
      "z": -10,
      "name": "Rock_Stone"
    },
    {
      "x": -8,
      "y": 15,
      "z": -10,
      "name": "Rock_Stone"
    },
    {
      "x": -8,
      "y": 16,
      "z": -10,
      "name": "Rock_Stone"
    },
    {
      "x": -8,
      "y": 17,
      "z": -10,
      "name": "Rock_Stone"
    },
    {
      "x": -8,
      "y": 18,
      "z": -10,
      "name": "Rock_Stone"
    },
    {
      "x": -8,
      "y": 19,
      "z": -10,
      "name": "Rock_Stone"
    },
    {
      "x": -8,
      "y": 20,
      "z": -10,
      "name": "Rock_Stone"
    },
    {
      "x": -8,
      "y": 21,
      "z": -10,
      "name": "Rock_Stone"
    },
    {
      "x": -8,
      "y": 22,
      "z": -10,
      "name": "Rock_Stone"
    },
    {
      "x": -8,
      "y": 0,
      "z": -9,
      "name": "Rock_Quartzite_Brick"
    },
    {
      "x": -8,
      "y": 1,
      "z": -9,
      "name": "Rock_Quartzite_Brick"
    },
    {
      "x": -8,
      "y": 2,
      "z": -9,
      "name": "Rock_Stone_Cobble"
    },
    {
      "x": -8,
      "y": 3,
      "z": -9,
      "name": "Nat20_Force_Empty"
    },
    {
      "x": -8,
      "y": 4,
      "z": -9,
      "name": "Nat20_Force_Empty"
    },
    {
      "x": -8,
      "y": 5,
      "z": -9,
      "name": "Nat20_Force_Empty"
    },
    {
      "x": -8,
      "y": 6,
      "z": -9,
      "name": "Nat20_Force_Empty"
    },
    {
      "x": -8,
      "y": 7,
      "z": -9,
      "name": "Nat20_Force_Empty"
    },
    {
      "x": -8,
      "y": 8,
      "z": -9,
      "name": "Nat20_Force_Empty"
    },
    {
      "x": -8,
      "y": 9,
      "z": -9,
      "name": "Rock_Stone"
    },
    {
      "x": -8,
      "y": 10,
      "z": -9,
      "name": "Rock_Stone"
    },
    {
      "x": -8,
      "y": 11,
      "z": -9,
      "name": "Rock_Stone"
    },
    {
      "x": -8,
      "y": 12,
      "z": -9,
      "name": "Rock_Stone"
    },
    {
      "x": -8,
      "y": 13,
      "z": -9,
      "name": "Rock_Stone"
    },
    {
      "x": -8,
      "y": 14,
      "z": -9,
      "name": "Rock_Stone"
    },
    {
      "x": -8,
      "y": 15,
      "z": -9,
      "name": "Rock_Stone"
    },
    {
      "x": -8,
      "y": 16,
      "z": -9,
      "name": "Rock_Stone"
    },
    {
      "x": -8,
      "y": 17,
      "z": -9,
      "name": "Rock_Stone"
    },
    {
      "x": -8,
      "y": 18,
      "z": -9,
      "name": "Rock_Stone"
    },
    {
      "x": -8,
      "y": 19,
      "z": -9,
      "name": "Rock_Stone"
    },
    {
      "x": -8,
      "y": 20,
      "z": -9,
      "name": "Rock_Stone"
    },
    {
      "x": -8,
      "y": 21,
      "z": -9,
      "name": "Rock_Stone"
    },
    {
      "x": -8,
      "y": 22,
      "z": -9,
      "name": "Rock_Stone"
    },
    {
      "x": -8,
      "y": 23,
      "z": -9,
      "name": "Rock_Stone"
    },
    {
      "x": -8,
      "y": 0,
      "z": -8,
      "name": "Rock_Quartzite_Brick"
    },
    {
      "x": -8,
      "y": 1,
      "z": -8,
      "name": "Rock_Quartzite_Brick"
    },
    {
      "x": -8,
      "y": 2,
      "z": -8,
      "name": "Soil_Gravel"
    },
    {
      "x": -8,
      "y": 3,
      "z": -8,
      "name": "Nat20_Force_Empty"
    },
    {
      "x": -8,
      "y": 4,
      "z": -8,
      "name": "Nat20_Force_Empty"
    },
    {
      "x": -8,
      "y": 5,
      "z": -8,
      "name": "Nat20_Force_Empty"
    },
    {
      "x": -8,
      "y": 6,
      "z": -8,
      "name": "Nat20_Force_Empty"
    },
    {
      "x": -8,
      "y": 7,
      "z": -8,
      "name": "Nat20_Force_Empty"
    },
    {
      "x": -8,
      "y": 8,
      "z": -8,
      "name": "Nat20_Force_Empty"
    },
    {
      "x": -8,
      "y": 9,
      "z": -8,
      "name": "Rock_Stone_Stalactite_Large",
      "filler": 31744,
      "rotation": 8
    },
    {
      "x": -8,
      "y": 10,
      "z": -8,
      "name": "Rock_Stone_Stalactite_Large",
      "rotation": 8
    },
    {
      "x": -8,
      "y": 11,
      "z": -8,
      "name": "Rock_Stone"
    },
    {
      "x": -8,
      "y": 12,
      "z": -8,
      "name": "Rock_Stone"
    },
    {
      "x": -8,
      "y": 13,
      "z": -8,
      "name": "Rock_Stone"
    },
    {
      "x": -8,
      "y": 14,
      "z": -8,
      "name": "Rock_Stone"
    },
    {
      "x": -8,
      "y": 15,
      "z": -8,
      "name": "Rock_Stone"
    },
    {
      "x": -8,
      "y": 16,
      "z": -8,
      "name": "Rock_Stone"
    },
    {
      "x": -8,
      "y": 17,
      "z": -8,
      "name": "Rock_Stone"
    },
    {
      "x": -8,
      "y": 18,
      "z": -8,
      "name": "Rock_Stone"
    },
    {
      "x": -8,
      "y": 19,
      "z": -8,
      "name": "Rock_Stone"
    },
    {
      "x": -8,
      "y": 20,
      "z": -8,
      "name": "Rock_Stone"
    },
    {
      "x": -8,
      "y": 21,
      "z": -8,
      "name": "Rock_Stone"
    },
    {
      "x": -8,
      "y": 22,
      "z": -8,
      "name": "Rock_Stone"
    },
    {
      "x": -8,
      "y": 23,
      "z": -8,
      "name": "Rock_Stone"
    },
    {
      "x": -8,
      "y": 0,
      "z": -7,
      "name": "Rock_Quartzite_Brick"
    },
    {
      "x": -8,
      "y": 1,
      "z": -7,
      "name": "Rock_Stone_Cobble"
    },
    {
      "x": -8,
      "y": 2,
      "z": -7,
      "name": "Rock_Stone_Cobble_Stairs"
    },
    {
      "x": -8,
      "y": 3,
      "z": -7,
      "name": "Nat20_Force_Empty"
    },
    {
      "x": -8,
      "y": 4,
      "z": -7,
      "name": "Nat20_Force_Empty"
    },
    {
      "x": -8,
      "y": 5,
      "z": -7,
      "name": "Nat20_Force_Empty"
    },
    {
      "x": -8,
      "y": 6,
      "z": -7,
      "name": "Nat20_Force_Empty"
    },
    {
      "x": -8,
      "y": 7,
      "z": -7,
      "name": "Nat20_Force_Empty"
    },
    {
      "x": -8,
      "y": 8,
      "z": -7,
      "name": "Nat20_Force_Empty"
    },
    {
      "x": -8,
      "y": 9,
      "z": -7,
      "name": "Nat20_Force_Empty"
    },
    {
      "x": -8,
      "y": 10,
      "z": -7,
      "name": "Nat20_Force_Empty"
    },
    {
      "x": -8,
      "y": 11,
      "z": -7,
      "name": "Nat20_Force_Empty"
    },
    {
      "x": -8,
      "y": 12,
      "z": -7,
      "name": "Nat20_Force_Empty"
    },
    {
      "x": -8,
      "y": 13,
      "z": -7,
      "name": "Nat20_Force_Empty"
    },
    {
      "x": -8,
      "y": 14,
      "z": -7,
      "name": "Rock_Quartzite_Brick"
    },
    {
      "x": -8,
      "y": 15,
      "z": -7,
      "name": "Rock_Stone"
    },
    {
      "x": -8,
      "y": 16,
      "z": -7,
      "name": "Rock_Stone"
    },
    {
      "x": -8,
      "y": 17,
      "z": -7,
      "name": "Rock_Stone"
    },
    {
      "x": -8,
      "y": 18,
      "z": -7,
      "name": "Rock_Stone"
    },
    {
      "x": -8,
      "y": 19,
      "z": -7,
      "name": "Rock_Stone"
    },
    {
      "x": -8,
      "y": 20,
      "z": -7,
      "name": "Rock_Stone"
    },
    {
      "x": -8,
      "y": 21,
      "z": -7,
      "name": "Rock_Stone"
    },
    {
      "x": -8,
      "y": 22,
      "z": -7,
      "name": "Rock_Stone"
    },
    {
      "x": -8,
      "y": 23,
      "z": -7,
      "name": "Rock_Stone"
    },
    {
      "x": -8,
      "y": 0,
      "z": -6,
      "name": "Rock_Stone_Cobble"
    },
    {
      "x": -8,
      "y": 1,
      "z": -6,
      "name": "Rock_Stone_Cobble_Stairs"
    },
    {
      "x": -8,
      "y": 2,
      "z": -6,
      "name": "Nat20_Force_Empty"
    },
    {
      "x": -8,
      "y": 3,
      "z": -6,
      "name": "Nat20_Force_Empty"
    },
    {
      "x": -8,
      "y": 4,
      "z": -6,
      "name": "Nat20_Force_Empty"
    },
    {
      "x": -8,
      "y": 5,
      "z": -6,
      "name": "Nat20_Force_Empty"
    },
    {
      "x": -8,
      "y": 6,
      "z": -6,
      "name": "Nat20_Force_Empty"
    },
    {
      "x": -8,
      "y": 7,
      "z": -6,
      "name": "Nat20_Force_Empty"
    },
    {
      "x": -8,
      "y": 8,
      "z": -6,
      "name": "Nat20_Force_Empty"
    },
    {
      "x": -8,
      "y": 9,
      "z": -6,
      "name": "Nat20_Force_Empty"
    },
    {
      "x": -8,
      "y": 10,
      "z": -6,
      "name": "Nat20_Force_Empty"
    },
    {
      "x": -8,
      "y": 11,
      "z": -6,
      "name": "Nat20_Force_Empty"
    },
    {
      "x": -8,
      "y": 12,
      "z": -6,
      "name": "Nat20_Force_Empty"
    },
    {
      "x": -8,
      "y": 13,
      "z": -6,
      "name": "Nat20_Force_Empty"
    },
    {
      "x": -8,
      "y": 14,
      "z": -6,
      "name": "Rock_Quartzite_Brick"
    },
    {
      "x": -8,
      "y": 15,
      "z": -6,
      "name": "Rock_Quartzite_Brick"
    },
    {
      "x": -8,
      "y": 16,
      "z": -6,
      "name": "Rock_Stone"
    },
    {
      "x": -8,
      "y": 17,
      "z": -6,
      "name": "Rock_Stone"
    },
    {
      "x": -8,
      "y": 18,
      "z": -6,
      "name": "Rock_Stone"
    },
    {
      "x": -8,
      "y": 19,
      "z": -6,
      "name": "Rock_Stone"
    },
    {
      "x": -8,
      "y": 20,
      "z": -6,
      "name": "Rock_Stone"
    },
    {
      "x": -8,
      "y": 21,
      "z": -6,
      "name": "Rock_Stone"
    },
    {
      "x": -8,
      "y": 0,
      "z": -5,
      "name": "Rock_Stone_Cobble_Stairs"
    },
    {
      "x": -8,
      "y": 1,
      "z": -5,
      "name": "Nat20_Force_Empty"
    },
    {
      "x": -8,
      "y": 2,
      "z": -5,
      "name": "Nat20_Force_Empty"
    },
    {
      "x": -8,
      "y": 3,
      "z": -5,
      "name": "Nat20_Force_Empty"
    },
    {
      "x": -8,
      "y": 4,
      "z": -5,
      "name": "Nat20_Force_Empty"
    },
    {
      "x": -8,
      "y": 5,
      "z": -5,
      "name": "Nat20_Force_Empty"
    },
    {
      "x": -8,
      "y": 6,
      "z": -5,
      "name": "Nat20_Force_Empty"
    },
    {
      "x": -8,
      "y": 7,
      "z": -5,
      "name": "Nat20_Force_Empty"
    },
    {
      "x": -8,
      "y": 8,
      "z": -5,
      "name": "Nat20_Force_Empty"
    },
    {
      "x": -8,
      "y": 9,
      "z": -5,
      "name": "Nat20_Force_Empty"
    },
    {
      "x": -8,
      "y": 10,
      "z": -5,
      "name": "Nat20_Force_Empty"
    },
    {
      "x": -8,
      "y": 11,
      "z": -5,
      "name": "Nat20_Force_Empty"
    },
    {
      "x": -8,
      "y": 12,
      "z": -5,
      "name": "Nat20_Force_Empty"
    },
    {
      "x": -8,
      "y": 13,
      "z": -5,
      "name": "Nat20_Force_Empty"
    },
    {
      "x": -8,
      "y": 14,
      "z": -5,
      "name": "Nat20_Force_Empty"
    },
    {
      "x": -8,
      "y": 15,
      "z": -5,
      "name": "Rock_Quartzite_Brick"
    },
    {
      "x": -8,
      "y": 16,
      "z": -5,
      "name": "Rock_Stone"
    },
    {
      "x": -8,
      "y": 17,
      "z": -5,
      "name": "Rock_Stone"
    },
    {
      "x": -8,
      "y": 18,
      "z": -5,
      "name": "Nat20_Force_Empty"
    },
    {
      "x": -8,
      "y": 19,
      "z": -5,
      "name": "Nat20_Force_Empty"
    },
    {
      "x": -8,
      "y": 20,
      "z": -5,
      "name": "Nat20_Force_Empty"
    },
    {
      "x": -8,
      "y": 0,
      "z": -4,
      "name": "Nat20_Force_Empty"
    },
    {
      "x": -8,
      "y": 1,
      "z": -4,
      "name": "Nat20_Force_Empty"
    },
    {
      "x": -8,
      "y": 2,
      "z": -4,
      "name": "Nat20_Force_Empty"
    },
    {
      "x": -8,
      "y": 3,
      "z": -4,
      "name": "Nat20_Force_Empty"
    },
    {
      "x": -8,
      "y": 4,
      "z": -4,
      "name": "Nat20_Force_Empty"
    },
    {
      "x": -8,
      "y": 5,
      "z": -4,
      "name": "Nat20_Force_Empty"
    },
    {
      "x": -8,
      "y": 6,
      "z": -4,
      "name": "Nat20_Force_Empty"
    },
    {
      "x": -8,
      "y": 7,
      "z": -4,
      "name": "Nat20_Force_Empty"
    },
    {
      "x": -8,
      "y": 8,
      "z": -4,
      "name": "Nat20_Force_Empty"
    },
    {
      "x": -8,
      "y": 9,
      "z": -4,
      "name": "Nat20_Force_Empty"
    },
    {
      "x": -8,
      "y": 10,
      "z": -4,
      "name": "Nat20_Force_Empty"
    },
    {
      "x": -8,
      "y": 11,
      "z": -4,
      "name": "Nat20_Force_Empty"
    },
    {
      "x": -8,
      "y": 12,
      "z": -4,
      "name": "Nat20_Force_Empty"
    },
    {
      "x": -8,
      "y": 13,
      "z": -4,
      "name": "Nat20_Force_Empty"
    },
    {
      "x": -8,
      "y": 14,
      "z": -4,
      "name": "Nat20_Force_Empty"
    },
    {
      "x": -8,
      "y": 15,
      "z": -4,
      "name": "Rock_Quartzite_Cobble"
    },
    {
      "x": -8,
      "y": 16,
      "z": -4,
      "name": "Soil_Dirt"
    },
    {
      "x": -8,
      "y": 17,
      "z": -4,
      "name": "Nat20_Force_Empty"
    },
    {
      "x": -8,
      "y": 18,
      "z": -4,
      "name": "Nat20_Force_Empty"
    },
    {
      "x": -8,
      "y": 19,
      "z": -4,
      "name": "Nat20_Force_Empty"
    },
    {
      "x": -8,
      "y": 20,
      "z": -4,
      "name": "Nat20_Force_Empty"
    },
    {
      "x": -8,
      "y": 0,
      "z": -3,
      "name": "Nat20_Force_Empty"
    },
    {
      "x": -8,
      "y": 1,
      "z": -3,
      "name": "Nat20_Force_Empty"
    },
    {
      "x": -8,
      "y": 2,
      "z": -3,
      "name": "Nat20_Force_Empty"
    },
    {
      "x": -8,
      "y": 3,
      "z": -3,
      "name": "Nat20_Force_Empty"
    },
    {
      "x": -8,
      "y": 4,
      "z": -3,
      "name": "Nat20_Force_Empty"
    },
    {
      "x": -8,
      "y": 5,
      "z": -3,
      "name": "Nat20_Force_Empty"
    },
    {
      "x": -8,
      "y": 6,
      "z": -3,
      "name": "Nat20_Force_Empty"
    },
    {
      "x": -8,
      "y": 7,
      "z": -3,
      "name": "Nat20_Force_Empty"
    },
    {
      "x": -8,
      "y": 8,
      "z": -3,
      "name": "Nat20_Force_Empty"
    },
    {
      "x": -8,
      "y": 9,
      "z": -3,
      "name": "Nat20_Force_Empty"
    },
    {
      "x": -8,
      "y": 10,
      "z": -3,
      "name": "Nat20_Force_Empty"
    },
    {
      "x": -8,
      "y": 11,
      "z": -3,
      "name": "Nat20_Force_Empty"
    },
    {
      "x": -8,
      "y": 12,
      "z": -3,
      "name": "Nat20_Force_Empty"
    },
    {
      "x": -8,
      "y": 13,
      "z": -3,
      "name": "Nat20_Force_Empty"
    },
    {
      "x": -8,
      "y": 14,
      "z": -3,
      "name": "Nat20_Force_Empty"
    },
    {
      "x": -8,
      "y": 15,
      "z": -3,
      "name": "Rock_Quartzite_Cobble"
    },
    {
      "x": -8,
      "y": 16,
      "z": -3,
      "name": "Soil_Grass"
    },
    {
      "x": -8,
      "y": 17,
      "z": -3,
      "name": "Plant_Grass_Sharp"
    },
    {
      "x": -8,
      "y": 18,
      "z": -3,
      "name": "Nat20_Force_Empty"
    },
    {
      "x": -8,
      "y": 19,
      "z": -3,
      "name": "Nat20_Force_Empty"
    },
    {
      "x": -8,
      "y": 20,
      "z": -3,
      "name": "Nat20_Force_Empty"
    },
    {
      "x": -8,
      "y": 0,
      "z": -2,
      "name": "Nat20_Force_Empty"
    },
    {
      "x": -8,
      "y": 1,
      "z": -2,
      "name": "Nat20_Force_Empty"
    },
    {
      "x": -8,
      "y": 2,
      "z": -2,
      "name": "Nat20_Force_Empty"
    },
    {
      "x": -8,
      "y": 3,
      "z": -2,
      "name": "Nat20_Force_Empty"
    },
    {
      "x": -8,
      "y": 4,
      "z": -2,
      "name": "Nat20_Force_Empty"
    },
    {
      "x": -8,
      "y": 5,
      "z": -2,
      "name": "Nat20_Force_Empty"
    },
    {
      "x": -8,
      "y": 6,
      "z": -2,
      "name": "Nat20_Force_Empty"
    },
    {
      "x": -8,
      "y": 7,
      "z": -2,
      "name": "Nat20_Force_Empty"
    },
    {
      "x": -8,
      "y": 8,
      "z": -2,
      "name": "Nat20_Force_Empty"
    },
    {
      "x": -8,
      "y": 9,
      "z": -2,
      "name": "Nat20_Force_Empty"
    },
    {
      "x": -8,
      "y": 10,
      "z": -2,
      "name": "Nat20_Force_Empty"
    },
    {
      "x": -8,
      "y": 11,
      "z": -2,
      "name": "Nat20_Force_Empty"
    },
    {
      "x": -8,
      "y": 12,
      "z": -2,
      "name": "Nat20_Force_Empty"
    },
    {
      "x": -8,
      "y": 13,
      "z": -2,
      "name": "Nat20_Force_Empty"
    },
    {
      "x": -8,
      "y": 14,
      "z": -2,
      "name": "Rock_Quartzite_Brick"
    },
    {
      "x": -8,
      "y": 15,
      "z": -2,
      "name": "Rock_Quartzite_Cobble"
    },
    {
      "x": -8,
      "y": 16,
      "z": -2,
      "name": "Rock_Stone"
    },
    {
      "x": -8,
      "y": 17,
      "z": -2,
      "name": "Nat20_Force_Empty"
    },
    {
      "x": -8,
      "y": 18,
      "z": -2,
      "name": "Nat20_Force_Empty"
    },
    {
      "x": -8,
      "y": 19,
      "z": -2,
      "name": "Nat20_Force_Empty"
    },
    {
      "x": -8,
      "y": 20,
      "z": -2,
      "name": "Nat20_Force_Empty"
    },
    {
      "x": -8,
      "y": 0,
      "z": -1,
      "name": "Nat20_Force_Empty"
    },
    {
      "x": -8,
      "y": 1,
      "z": -1,
      "name": "Nat20_Force_Empty"
    },
    {
      "x": -8,
      "y": 2,
      "z": -1,
      "name": "Nat20_Force_Empty"
    },
    {
      "x": -8,
      "y": 3,
      "z": -1,
      "name": "Nat20_Force_Empty"
    },
    {
      "x": -8,
      "y": 4,
      "z": -1,
      "name": "Nat20_Force_Empty"
    },
    {
      "x": -8,
      "y": 5,
      "z": -1,
      "name": "Nat20_Force_Empty"
    },
    {
      "x": -8,
      "y": 6,
      "z": -1,
      "name": "Nat20_Force_Empty"
    },
    {
      "x": -8,
      "y": 7,
      "z": -1,
      "name": "Nat20_Force_Empty"
    },
    {
      "x": -8,
      "y": 8,
      "z": -1,
      "name": "Nat20_Force_Empty"
    },
    {
      "x": -8,
      "y": 9,
      "z": -1,
      "name": "Nat20_Force_Empty"
    },
    {
      "x": -8,
      "y": 10,
      "z": -1,
      "name": "Nat20_Force_Empty"
    },
    {
      "x": -8,
      "y": 11,
      "z": -1,
      "name": "Nat20_Force_Empty"
    },
    {
      "x": -8,
      "y": 12,
      "z": -1,
      "name": "Nat20_Force_Empty"
    },
    {
      "x": -8,
      "y": 13,
      "z": -1,
      "name": "Nat20_Force_Empty"
    },
    {
      "x": -8,
      "y": 14,
      "z": -1,
      "name": "Rock_Quartzite_Brick"
    },
    {
      "x": -8,
      "y": 15,
      "z": -1,
      "name": "Rock_Stone"
    },
    {
      "x": -8,
      "y": 16,
      "z": -1,
      "name": "Rock_Stone"
    },
    {
      "x": -8,
      "y": 17,
      "z": -1,
      "name": "Rock_Stone"
    },
    {
      "x": -8,
      "y": 18,
      "z": -1,
      "name": "Rock_Stone"
    },
    {
      "x": -8,
      "y": 19,
      "z": -1,
      "name": "Rock_Stone"
    },
    {
      "x": -8,
      "y": 20,
      "z": -1,
      "name": "Nat20_Force_Empty"
    },
    {
      "x": -8,
      "y": 0,
      "z": 0,
      "name": "Nat20_Force_Empty"
    },
    {
      "x": -8,
      "y": 1,
      "z": 0,
      "name": "Nat20_Force_Empty"
    },
    {
      "x": -8,
      "y": 2,
      "z": 0,
      "name": "Nat20_Force_Empty"
    },
    {
      "x": -8,
      "y": 3,
      "z": 0,
      "name": "Nat20_Force_Empty"
    },
    {
      "x": -8,
      "y": 4,
      "z": 0,
      "name": "Nat20_Force_Empty"
    },
    {
      "x": -8,
      "y": 5,
      "z": 0,
      "name": "Nat20_Force_Empty"
    },
    {
      "x": -8,
      "y": 6,
      "z": 0,
      "name": "Nat20_Force_Empty"
    },
    {
      "x": -8,
      "y": 7,
      "z": 0,
      "name": "Nat20_Force_Empty"
    },
    {
      "x": -8,
      "y": 8,
      "z": 0,
      "name": "Nat20_Force_Empty"
    },
    {
      "x": -8,
      "y": 9,
      "z": 0,
      "name": "Nat20_Force_Empty"
    },
    {
      "x": -8,
      "y": 10,
      "z": 0,
      "name": "Nat20_Force_Empty"
    },
    {
      "x": -8,
      "y": 11,
      "z": 0,
      "name": "Nat20_Force_Empty"
    },
    {
      "x": -8,
      "y": 12,
      "z": 0,
      "name": "Nat20_Force_Empty"
    },
    {
      "x": -8,
      "y": 13,
      "z": 0,
      "name": "Nat20_Force_Empty"
    },
    {
      "x": -8,
      "y": 14,
      "z": 0,
      "name": "Rock_Quartzite_Brick"
    },
    {
      "x": -8,
      "y": 15,
      "z": 0,
      "name": "Rock_Stone"
    },
    {
      "x": -8,
      "y": 16,
      "z": 0,
      "name": "Rock_Stone"
    },
    {
      "x": -8,
      "y": 17,
      "z": 0,
      "name": "Rock_Stone"
    },
    {
      "x": -8,
      "y": 18,
      "z": 0,
      "name": "Rock_Stone"
    },
    {
      "x": -8,
      "y": 19,
      "z": 0,
      "name": "Rock_Stone"
    },
    {
      "x": -8,
      "y": 20,
      "z": 0,
      "name": "Nat20_Force_Empty"
    },
    {
      "x": -8,
      "y": 0,
      "z": 1,
      "name": "Rock_Stone"
    },
    {
      "x": -8,
      "y": 1,
      "z": 1,
      "name": "Nat20_Force_Empty"
    },
    {
      "x": -8,
      "y": 2,
      "z": 1,
      "name": "Nat20_Force_Empty"
    },
    {
      "x": -8,
      "y": 3,
      "z": 1,
      "name": "Nat20_Force_Empty"
    },
    {
      "x": -8,
      "y": 4,
      "z": 1,
      "name": "Nat20_Force_Empty"
    },
    {
      "x": -8,
      "y": 5,
      "z": 1,
      "name": "Nat20_Force_Empty"
    },
    {
      "x": -8,
      "y": 6,
      "z": 1,
      "name": "Nat20_Force_Empty"
    },
    {
      "x": -8,
      "y": 7,
      "z": 1,
      "name": "Nat20_Force_Empty"
    },
    {
      "x": -8,
      "y": 8,
      "z": 1,
      "name": "Nat20_Force_Empty"
    },
    {
      "x": -8,
      "y": 9,
      "z": 1,
      "name": "Nat20_Force_Empty"
    },
    {
      "x": -8,
      "y": 10,
      "z": 1,
      "name": "Nat20_Force_Empty"
    },
    {
      "x": -8,
      "y": 11,
      "z": 1,
      "name": "Nat20_Force_Empty"
    },
    {
      "x": -8,
      "y": 12,
      "z": 1,
      "name": "Nat20_Force_Empty"
    },
    {
      "x": -8,
      "y": 13,
      "z": 1,
      "name": "Nat20_Force_Empty"
    },
    {
      "x": -8,
      "y": 14,
      "z": 1,
      "name": "Rock_Quartzite_Brick"
    },
    {
      "x": -8,
      "y": 15,
      "z": 1,
      "name": "Rock_Stone"
    },
    {
      "x": -8,
      "y": 16,
      "z": 1,
      "name": "Rock_Stone"
    },
    {
      "x": -8,
      "y": 17,
      "z": 1,
      "name": "Rock_Stone"
    },
    {
      "x": -8,
      "y": 18,
      "z": 1,
      "name": "Rock_Stone"
    },
    {
      "x": -8,
      "y": 19,
      "z": 1,
      "name": "Nat20_Force_Empty"
    },
    {
      "x": -8,
      "y": 20,
      "z": 1,
      "name": "Nat20_Force_Empty"
    },
    {
      "x": -8,
      "y": 0,
      "z": 2,
      "name": "Rock_Stone"
    },
    {
      "x": -8,
      "y": 1,
      "z": 2,
      "name": "Rock_Stone"
    },
    {
      "x": -8,
      "y": 2,
      "z": 2,
      "name": "Rock_Quartzite_Cobble"
    },
    {
      "x": -8,
      "y": 3,
      "z": 2,
      "name": "Rock_Quartzite_Cobble"
    },
    {
      "x": -8,
      "y": 4,
      "z": 2,
      "name": "Rock_Quartzite_Cobble"
    },
    {
      "x": -8,
      "y": 5,
      "z": 2,
      "name": "Rock_Quartzite_Cobble"
    },
    {
      "x": -8,
      "y": 6,
      "z": 2,
      "name": "Rock_Stone_Brick_Smooth"
    },
    {
      "x": -8,
      "y": 7,
      "z": 2,
      "name": "Rock_Stone_Brick_Smooth"
    },
    {
      "x": -8,
      "y": 8,
      "z": 2,
      "name": "Nat20_Force_Empty"
    },
    {
      "x": -8,
      "y": 9,
      "z": 2,
      "name": "Nat20_Force_Empty"
    },
    {
      "x": -8,
      "y": 10,
      "z": 2,
      "name": "Nat20_Force_Empty"
    },
    {
      "x": -8,
      "y": 11,
      "z": 2,
      "name": "Nat20_Force_Empty"
    },
    {
      "x": -8,
      "y": 12,
      "z": 2,
      "name": "Nat20_Force_Empty"
    },
    {
      "x": -8,
      "y": 13,
      "z": 2,
      "name": "Rock_Quartzite_Brick"
    },
    {
      "x": -8,
      "y": 14,
      "z": 2,
      "name": "Rock_Stone"
    },
    {
      "x": -8,
      "y": 15,
      "z": 2,
      "name": "Rock_Stone"
    },
    {
      "x": -8,
      "y": 16,
      "z": 2,
      "name": "Rock_Stone"
    },
    {
      "x": -8,
      "y": 17,
      "z": 2,
      "name": "Nat20_Force_Empty"
    },
    {
      "x": -8,
      "y": 18,
      "z": 2,
      "name": "Nat20_Force_Empty"
    },
    {
      "x": -8,
      "y": 19,
      "z": 2,
      "name": "Nat20_Force_Empty"
    },
    {
      "x": -8,
      "y": 20,
      "z": 2,
      "name": "Nat20_Force_Empty"
    },
    {
      "x": -8,
      "y": 0,
      "z": 3,
      "name": "Rock_Stone"
    },
    {
      "x": -8,
      "y": 1,
      "z": 3,
      "name": "Rock_Quartzite"
    },
    {
      "x": -8,
      "y": 2,
      "z": 3,
      "name": "Rock_Quartzite_Cobble"
    },
    {
      "x": -8,
      "y": 3,
      "z": 3,
      "name": "Rock_Quartzite_Cobble"
    },
    {
      "x": -8,
      "y": 4,
      "z": 3,
      "name": "Rock_Quartzite_Cobble"
    },
    {
      "x": -8,
      "y": 5,
      "z": 3,
      "name": "Rock_Quartzite_Cobble"
    },
    {
      "x": -8,
      "y": 6,
      "z": 3,
      "name": "Rock_Quartzite_Cobble"
    },
    {
      "x": -8,
      "y": 7,
      "z": 3,
      "name": "Rock_Quartzite"
    },
    {
      "x": -8,
      "y": 8,
      "z": 3,
      "name": "Rock_Quartzite_Cobble"
    },
    {
      "x": -8,
      "y": 9,
      "z": 3,
      "name": "Rock_Quartzite_Cobble"
    },
    {
      "x": -8,
      "y": 10,
      "z": 3,
      "name": "Rock_Quartzite_Cobble"
    },
    {
      "x": -8,
      "y": 11,
      "z": 3,
      "name": "Rock_Quartzite_Cobble"
    },
    {
      "x": -8,
      "y": 12,
      "z": 3,
      "name": "Rock_Quartzite_Brick"
    },
    {
      "x": -8,
      "y": 13,
      "z": 3,
      "name": "Rock_Quartzite_Brick"
    },
    {
      "x": -8,
      "y": 14,
      "z": 3,
      "name": "Rock_Quartzite_Brick"
    },
    {
      "x": -8,
      "y": 15,
      "z": 3,
      "name": "Nat20_Force_Empty"
    },
    {
      "x": -8,
      "y": 16,
      "z": 3,
      "name": "Nat20_Force_Empty"
    },
    {
      "x": -8,
      "y": 17,
      "z": 3,
      "name": "Nat20_Force_Empty"
    },
    {
      "x": -8,
      "y": 18,
      "z": 3,
      "name": "Nat20_Force_Empty"
    },
    {
      "x": -8,
      "y": 19,
      "z": 3,
      "name": "Nat20_Force_Empty"
    },
    {
      "x": -8,
      "y": 20,
      "z": 3,
      "name": "Nat20_Force_Empty"
    },
    {
      "x": -8,
      "y": 0,
      "z": 4,
      "name": "Rock_Stone_Cobble"
    },
    {
      "x": -8,
      "y": 1,
      "z": 4,
      "name": "Rock_Stone_Cobble"
    },
    {
      "x": -8,
      "y": 2,
      "z": 4,
      "name": "Rock_Stone_Cobble"
    },
    {
      "x": -8,
      "y": 3,
      "z": 4,
      "name": "Rock_Stone_Cobble"
    },
    {
      "x": -8,
      "y": 4,
      "z": 4,
      "name": "Rock_Stone_Brick"
    },
    {
      "x": -8,
      "y": 5,
      "z": 4,
      "name": "Rock_Stone_Brick"
    },
    {
      "x": -8,
      "y": 6,
      "z": 4,
      "name": "Rock_Stone_Brick"
    },
    {
      "x": -8,
      "y": 7,
      "z": 4,
      "name": "Rock_Stone_Brick"
    },
    {
      "x": -7,
      "y": 0,
      "z": -11,
      "name": "Rock_Quartzite_Brick"
    },
    {
      "x": -7,
      "y": 1,
      "z": -11,
      "name": "Rock_Quartzite_Brick"
    },
    {
      "x": -7,
      "y": 2,
      "z": -11,
      "name": "Rock_Quartzite"
    },
    {
      "x": -7,
      "y": 3,
      "z": -11,
      "name": "Rock_Quartzite"
    },
    {
      "x": -7,
      "y": 4,
      "z": -11,
      "name": "Rock_Quartzite_Cobble"
    },
    {
      "x": -7,
      "y": 5,
      "z": -11,
      "name": "Rock_Quartzite_Cobble"
    },
    {
      "x": -7,
      "y": 6,
      "z": -11,
      "name": "Rock_Quartzite_Cobble"
    },
    {
      "x": -7,
      "y": 8,
      "z": -11,
      "name": "Rock_Stone"
    },
    {
      "x": -7,
      "y": 9,
      "z": -11,
      "name": "Rock_Stone"
    },
    {
      "x": -7,
      "y": 10,
      "z": -11,
      "name": "Rock_Stone"
    },
    {
      "x": -7,
      "y": 11,
      "z": -11,
      "name": "Rock_Stone"
    },
    {
      "x": -7,
      "y": 12,
      "z": -11,
      "name": "Rock_Stone"
    },
    {
      "x": -7,
      "y": 13,
      "z": -11,
      "name": "Rock_Stone"
    },
    {
      "x": -7,
      "y": 14,
      "z": -11,
      "name": "Rock_Stone"
    },
    {
      "x": -7,
      "y": 15,
      "z": -11,
      "name": "Soil_Grass"
    },
    {
      "x": -7,
      "y": 0,
      "z": -10,
      "name": "Rock_Quartzite_Brick"
    },
    {
      "x": -7,
      "y": 1,
      "z": -10,
      "name": "Rock_Quartzite_Brick"
    },
    {
      "x": -7,
      "y": 2,
      "z": -10,
      "name": "Rock_Stone_Cobble"
    },
    {
      "x": -7,
      "y": 3,
      "z": -10,
      "name": "Nat20_Force_Empty"
    },
    {
      "x": -7,
      "y": 4,
      "z": -10,
      "name": "Nat20_Force_Empty"
    },
    {
      "x": -7,
      "y": 5,
      "z": -10,
      "name": "Nat20_Force_Empty"
    },
    {
      "x": -7,
      "y": 6,
      "z": -10,
      "name": "Nat20_Force_Empty"
    },
    {
      "x": -7,
      "y": 7,
      "z": -10,
      "name": "Nat20_Force_Empty"
    },
    {
      "x": -7,
      "y": 8,
      "z": -10,
      "name": "Nat20_Force_Empty"
    },
    {
      "x": -7,
      "y": 9,
      "z": -10,
      "name": "Plant_Moss_Cave_Green_Dark",
      "rotation": 8
    },
    {
      "x": -7,
      "y": 10,
      "z": -10,
      "name": "Rock_Stone"
    },
    {
      "x": -7,
      "y": 11,
      "z": -10,
      "name": "Rock_Stone"
    },
    {
      "x": -7,
      "y": 12,
      "z": -10,
      "name": "Rock_Stone"
    },
    {
      "x": -7,
      "y": 13,
      "z": -10,
      "name": "Rock_Stone"
    },
    {
      "x": -7,
      "y": 14,
      "z": -10,
      "name": "Rock_Stone"
    },
    {
      "x": -7,
      "y": 15,
      "z": -10,
      "name": "Rock_Stone"
    },
    {
      "x": -7,
      "y": 16,
      "z": -10,
      "name": "Rock_Stone"
    },
    {
      "x": -7,
      "y": 17,
      "z": -10,
      "name": "Rock_Stone"
    },
    {
      "x": -7,
      "y": 18,
      "z": -10,
      "name": "Rock_Stone"
    },
    {
      "x": -7,
      "y": 19,
      "z": -10,
      "name": "Rock_Stone"
    },
    {
      "x": -7,
      "y": 20,
      "z": -10,
      "name": "Rock_Stone"
    },
    {
      "x": -7,
      "y": 0,
      "z": -9,
      "name": "Rock_Quartzite_Brick"
    },
    {
      "x": -7,
      "y": 1,
      "z": -9,
      "name": "Rock_Quartzite_Brick"
    },
    {
      "x": -7,
      "y": 2,
      "z": -9,
      "name": "Rock_Stone_Cobble"
    },
    {
      "x": -7,
      "y": 3,
      "z": -9,
      "name": "Nat20_Force_Empty"
    },
    {
      "x": -7,
      "y": 4,
      "z": -9,
      "name": "Nat20_Force_Empty"
    },
    {
      "x": -7,
      "y": 5,
      "z": -9,
      "name": "Nat20_Force_Empty"
    },
    {
      "x": -7,
      "y": 6,
      "z": -9,
      "name": "Nat20_Force_Empty"
    },
    {
      "x": -7,
      "y": 7,
      "z": -9,
      "name": "Nat20_Force_Empty"
    },
    {
      "x": -7,
      "y": 8,
      "z": -9,
      "name": "Nat20_Force_Empty"
    },
    {
      "x": -7,
      "y": 9,
      "z": -9,
      "name": "Nat20_Force_Empty"
    },
    {
      "x": -7,
      "y": 10,
      "z": -9,
      "name": "Nat20_Force_Empty"
    },
    {
      "x": -7,
      "y": 11,
      "z": -9,
      "name": "Rock_Stone"
    },
    {
      "x": -7,
      "y": 12,
      "z": -9,
      "name": "Rock_Stone"
    },
    {
      "x": -7,
      "y": 13,
      "z": -9,
      "name": "Rock_Stone"
    },
    {
      "x": -7,
      "y": 14,
      "z": -9,
      "name": "Rock_Stone"
    },
    {
      "x": -7,
      "y": 15,
      "z": -9,
      "name": "Rock_Stone"
    },
    {
      "x": -7,
      "y": 16,
      "z": -9,
      "name": "Rock_Stone"
    },
    {
      "x": -7,
      "y": 17,
      "z": -9,
      "name": "Rock_Stone"
    },
    {
      "x": -7,
      "y": 18,
      "z": -9,
      "name": "Rock_Stone"
    },
    {
      "x": -7,
      "y": 19,
      "z": -9,
      "name": "Rock_Stone"
    },
    {
      "x": -7,
      "y": 20,
      "z": -9,
      "name": "Rock_Stone"
    },
    {
      "x": -7,
      "y": 21,
      "z": -9,
      "name": "Rock_Stone"
    },
    {
      "x": -7,
      "y": 22,
      "z": -9,
      "name": "Rock_Stone"
    },
    {
      "x": -7,
      "y": 0,
      "z": -8,
      "name": "Rock_Quartzite_Brick"
    },
    {
      "x": -7,
      "y": 1,
      "z": -8,
      "name": "Rock_Quartzite_Brick"
    },
    {
      "x": -7,
      "y": 2,
      "z": -8,
      "name": "Rock_Stone_Cobble"
    },
    {
      "x": -7,
      "y": 3,
      "z": -8,
      "name": "Nat20_Force_Empty"
    },
    {
      "x": -7,
      "y": 4,
      "z": -8,
      "name": "Nat20_Force_Empty"
    },
    {
      "x": -7,
      "y": 5,
      "z": -8,
      "name": "Nat20_Force_Empty"
    },
    {
      "x": -7,
      "y": 6,
      "z": -8,
      "name": "Nat20_Force_Empty"
    },
    {
      "x": -7,
      "y": 7,
      "z": -8,
      "name": "Nat20_Force_Empty"
    },
    {
      "x": -7,
      "y": 8,
      "z": -8,
      "name": "Nat20_Force_Empty"
    },
    {
      "x": -7,
      "y": 9,
      "z": -8,
      "name": "Nat20_Force_Empty"
    },
    {
      "x": -7,
      "y": 10,
      "z": -8,
      "name": "Nat20_Force_Empty"
    },
    {
      "x": -7,
      "y": 11,
      "z": -8,
      "name": "Nat20_Force_Empty"
    },
    {
      "x": -7,
      "y": 12,
      "z": -8,
      "name": "Nat20_Force_Empty"
    },
    {
      "x": -7,
      "y": 13,
      "z": -8,
      "name": "Rock_Stone_Stalactite_Small",
      "rotation": 8
    },
    {
      "x": -7,
      "y": 14,
      "z": -8,
      "name": "Rock_Quartzite_Brick"
    },
    {
      "x": -7,
      "y": 15,
      "z": -8,
      "name": "Rock_Stone"
    },
    {
      "x": -7,
      "y": 16,
      "z": -8,
      "name": "Rock_Stone"
    },
    {
      "x": -7,
      "y": 17,
      "z": -8,
      "name": "Rock_Stone"
    },
    {
      "x": -7,
      "y": 18,
      "z": -8,
      "name": "Rock_Stone"
    },
    {
      "x": -7,
      "y": 19,
      "z": -8,
      "name": "Rock_Stone"
    },
    {
      "x": -7,
      "y": 20,
      "z": -8,
      "name": "Rock_Stone"
    },
    {
      "x": -7,
      "y": 21,
      "z": -8,
      "name": "Rock_Stone"
    },
    {
      "x": -7,
      "y": 22,
      "z": -8,
      "name": "Rock_Stone"
    },
    {
      "x": -7,
      "y": 0,
      "z": -7,
      "name": "Rock_Quartzite_Brick"
    },
    {
      "x": -7,
      "y": 1,
      "z": -7,
      "name": "Rock_Stone_Cobble"
    },
    {
      "x": -7,
      "y": 2,
      "z": -7,
      "name": "Rock_Stone_Cobble_Stairs"
    },
    {
      "x": -7,
      "y": 3,
      "z": -7,
      "name": "Nat20_Force_Empty"
    },
    {
      "x": -7,
      "y": 4,
      "z": -7,
      "name": "Nat20_Force_Empty"
    },
    {
      "x": -7,
      "y": 5,
      "z": -7,
      "name": "Nat20_Force_Empty"
    },
    {
      "x": -7,
      "y": 6,
      "z": -7,
      "name": "Nat20_Force_Empty"
    },
    {
      "x": -7,
      "y": 7,
      "z": -7,
      "name": "Nat20_Force_Empty"
    },
    {
      "x": -7,
      "y": 8,
      "z": -7,
      "name": "Nat20_Force_Empty"
    },
    {
      "x": -7,
      "y": 9,
      "z": -7,
      "name": "Nat20_Force_Empty"
    },
    {
      "x": -7,
      "y": 10,
      "z": -7,
      "name": "Nat20_Force_Empty"
    },
    {
      "x": -7,
      "y": 11,
      "z": -7,
      "name": "Nat20_Force_Empty"
    },
    {
      "x": -7,
      "y": 12,
      "z": -7,
      "name": "Nat20_Force_Empty"
    },
    {
      "x": -7,
      "y": 13,
      "z": -7,
      "name": "Nat20_Force_Empty"
    },
    {
      "x": -7,
      "y": 14,
      "z": -7,
      "name": "Rock_Quartzite_Brick"
    },
    {
      "x": -7,
      "y": 15,
      "z": -7,
      "name": "Rock_Stone"
    },
    {
      "x": -7,
      "y": 16,
      "z": -7,
      "name": "Rock_Stone"
    },
    {
      "x": -7,
      "y": 17,
      "z": -7,
      "name": "Rock_Stone"
    },
    {
      "x": -7,
      "y": 18,
      "z": -7,
      "name": "Rock_Stone"
    },
    {
      "x": -7,
      "y": 19,
      "z": -7,
      "name": "Rock_Stone"
    },
    {
      "x": -7,
      "y": 20,
      "z": -7,
      "name": "Rock_Stone"
    },
    {
      "x": -7,
      "y": 21,
      "z": -7,
      "name": "Rock_Stone"
    },
    {
      "x": -7,
      "y": 0,
      "z": -6,
      "name": "Rock_Stone_Cobble"
    },
    {
      "x": -7,
      "y": 1,
      "z": -6,
      "name": "Rock_Stone_Cobble_Stairs"
    },
    {
      "x": -7,
      "y": 2,
      "z": -6,
      "name": "Nat20_Force_Empty"
    },
    {
      "x": -7,
      "y": 3,
      "z": -6,
      "name": "Nat20_Force_Empty"
    },
    {
      "x": -7,
      "y": 4,
      "z": -6,
      "name": "Nat20_Force_Empty"
    },
    {
      "x": -7,
      "y": 5,
      "z": -6,
      "name": "Nat20_Force_Empty"
    },
    {
      "x": -7,
      "y": 6,
      "z": -6,
      "name": "Nat20_Force_Empty"
    },
    {
      "x": -7,
      "y": 7,
      "z": -6,
      "name": "Nat20_Force_Empty"
    },
    {
      "x": -7,
      "y": 8,
      "z": -6,
      "name": "Nat20_Force_Empty"
    },
    {
      "x": -7,
      "y": 9,
      "z": -6,
      "name": "Nat20_Force_Empty"
    },
    {
      "x": -7,
      "y": 10,
      "z": -6,
      "name": "Nat20_Force_Empty"
    },
    {
      "x": -7,
      "y": 11,
      "z": -6,
      "name": "Nat20_Force_Empty"
    },
    {
      "x": -7,
      "y": 12,
      "z": -6,
      "name": "Nat20_Force_Empty"
    },
    {
      "x": -7,
      "y": 13,
      "z": -6,
      "name": "Nat20_Force_Empty"
    },
    {
      "x": -7,
      "y": 14,
      "z": -6,
      "name": "Nat20_Force_Empty"
    },
    {
      "x": -7,
      "y": 15,
      "z": -6,
      "name": "Rock_Quartzite_Brick"
    },
    {
      "x": -7,
      "y": 16,
      "z": -6,
      "name": "Rock_Stone"
    },
    {
      "x": -7,
      "y": 17,
      "z": -6,
      "name": "Nat20_Force_Empty"
    },
    {
      "x": -7,
      "y": 18,
      "z": -6,
      "name": "Nat20_Force_Empty"
    },
    {
      "x": -7,
      "y": 19,
      "z": -6,
      "name": "Nat20_Force_Empty"
    },
    {
      "x": -7,
      "y": 20,
      "z": -6,
      "name": "Nat20_Force_Empty"
    },
    {
      "x": -7,
      "y": 0,
      "z": -5,
      "name": "Rock_Stone_Cobble_Stairs"
    },
    {
      "x": -7,
      "y": 1,
      "z": -5,
      "name": "Nat20_Force_Empty"
    },
    {
      "x": -7,
      "y": 2,
      "z": -5,
      "name": "Nat20_Force_Empty"
    },
    {
      "x": -7,
      "y": 3,
      "z": -5,
      "name": "Nat20_Force_Empty"
    },
    {
      "x": -7,
      "y": 4,
      "z": -5,
      "name": "Nat20_Force_Empty"
    },
    {
      "x": -7,
      "y": 5,
      "z": -5,
      "name": "Nat20_Force_Empty"
    },
    {
      "x": -7,
      "y": 6,
      "z": -5,
      "name": "Nat20_Force_Empty"
    },
    {
      "x": -7,
      "y": 7,
      "z": -5,
      "name": "Nat20_Force_Empty"
    },
    {
      "x": -7,
      "y": 8,
      "z": -5,
      "name": "Nat20_Force_Empty"
    },
    {
      "x": -7,
      "y": 9,
      "z": -5,
      "name": "Nat20_Force_Empty"
    },
    {
      "x": -7,
      "y": 10,
      "z": -5,
      "name": "Nat20_Force_Empty"
    },
    {
      "x": -7,
      "y": 11,
      "z": -5,
      "name": "Nat20_Force_Empty"
    },
    {
      "x": -7,
      "y": 12,
      "z": -5,
      "name": "Nat20_Force_Empty"
    },
    {
      "x": -7,
      "y": 13,
      "z": -5,
      "name": "Nat20_Force_Empty"
    },
    {
      "x": -7,
      "y": 14,
      "z": -5,
      "name": "Nat20_Force_Empty"
    },
    {
      "x": -7,
      "y": 15,
      "z": -5,
      "name": "Rock_Quartzite_Brick"
    },
    {
      "x": -7,
      "y": 16,
      "z": -5,
      "name": "Soil_Grass"
    },
    {
      "x": -7,
      "y": 17,
      "z": -5,
      "name": "Nat20_Force_Empty"
    },
    {
      "x": -7,
      "y": 18,
      "z": -5,
      "name": "Nat20_Force_Empty"
    },
    {
      "x": -7,
      "y": 19,
      "z": -5,
      "name": "Nat20_Force_Empty"
    },
    {
      "x": -7,
      "y": 20,
      "z": -5,
      "name": "Nat20_Force_Empty"
    },
    {
      "x": -7,
      "y": 0,
      "z": -4,
      "name": "Nat20_Force_Empty"
    },
    {
      "x": -7,
      "y": 1,
      "z": -4,
      "name": "Nat20_Force_Empty"
    },
    {
      "x": -7,
      "y": 2,
      "z": -4,
      "name": "Nat20_Force_Empty"
    },
    {
      "x": -7,
      "y": 3,
      "z": -4,
      "name": "Nat20_Force_Empty"
    },
    {
      "x": -7,
      "y": 4,
      "z": -4,
      "name": "Nat20_Force_Empty"
    },
    {
      "x": -7,
      "y": 5,
      "z": -4,
      "name": "Nat20_Force_Empty"
    },
    {
      "x": -7,
      "y": 6,
      "z": -4,
      "name": "Nat20_Force_Empty"
    },
    {
      "x": -7,
      "y": 7,
      "z": -4,
      "name": "Nat20_Force_Empty"
    },
    {
      "x": -7,
      "y": 8,
      "z": -4,
      "name": "Nat20_Force_Empty"
    },
    {
      "x": -7,
      "y": 9,
      "z": -4,
      "name": "Nat20_Force_Empty"
    },
    {
      "x": -7,
      "y": 10,
      "z": -4,
      "name": "Nat20_Force_Empty"
    },
    {
      "x": -7,
      "y": 11,
      "z": -4,
      "name": "Nat20_Force_Empty"
    },
    {
      "x": -7,
      "y": 12,
      "z": -4,
      "name": "Nat20_Force_Empty"
    },
    {
      "x": -7,
      "y": 13,
      "z": -4,
      "name": "Nat20_Force_Empty"
    },
    {
      "x": -7,
      "y": 14,
      "z": -4,
      "name": "Nat20_Force_Empty"
    },
    {
      "x": -7,
      "y": 15,
