{
  "version": 8,
  "blockIdVersion": 11,
  "anchorX": 0,
  "anchorY": 0,
  "anchorZ": 0,
  "blocks": [
    {
      "x": -13,
      "y": 0,
      "z": -13,
      "name": "Rock_Stone"
    },
    {
      "x": -13,
      "y": 0,
      "z": -12,
      "name": "Rock_Stone"
    },
    {
      "x": -13,
      "y": 1,
      "z": -12,
      "name": "Rock_Stone"
    },
    {
      "x": -13,
      "y": 2,
      "z": -12,
      "name": "Soil_Dirt"
    },
    {
      "x": -13,
      "y": 3,
      "z": -12,
      "name": "Soil_Grass"
    },
    {
      "x": -13,
      "y": 0,
      "z": -11,
      "name": "Rock_Stone"
    },
    {
      "x": -13,
      "y": 1,
      "z": -11,
      "name": "Rock_Stone"
    },
    {
      "x": -13,
      "y": 2,
      "z": -11,
      "name": "Rock_Stone"
    },
    {
      "x": -13,
      "y": 3,
      "z": -11,
      "name": "Soil_Dirt"
    },
    {
      "x": -13,
      "y": 4,
      "z": -11,
      "name": "Soil_Grass"
    },
    {
      "x": -13,
      "y": 0,
      "z": -10,
      "name": "Rock_Stone"
    },
    {
      "x": -13,
      "y": 1,
      "z": -10,
      "name": "Rock_Stone"
    },
    {
      "x": -13,
      "y": 2,
      "z": -10,
      "name": "Rock_Stone"
    },
    {
      "x": -13,
      "y": 3,
      "z": -10,
      "name": "Soil_Dirt"
    },
    {
      "x": -13,
      "y": 4,
      "z": -10,
      "name": "Soil_Grass"
    },
    {
      "x": -13,
      "y": 0,
      "z": -9,
      "name": "Rock_Stone"
    },
    {
      "x": -13,
      "y": 1,
      "z": -9,
      "name": "Rock_Stone"
    },
    {
      "x": -13,
      "y": 2,
      "z": -9,
      "name": "Rock_Stone"
    },
    {
      "x": -13,
      "y": 3,
      "z": -9,
      "name": "Soil_Dirt"
    },
    {
      "x": -13,
      "y": 4,
      "z": -9,
      "name": "Soil_Grass"
    },
    {
      "x": -13,
      "y": 5,
      "z": -9,
      "name": "Plant_Grass_Sharp_Short"
    },
    {
      "x": -13,
      "y": 0,
      "z": -8,
      "name": "Rock_Stone"
    },
    {
      "x": -13,
      "y": 1,
      "z": -8,
      "name": "Rock_Stone"
    },
    {
      "x": -13,
      "y": 2,
      "z": -8,
      "name": "Rock_Stone"
    },
    {
      "x": -13,
      "y": 3,
      "z": -8,
      "name": "Soil_Dirt"
    },
    {
      "x": -13,
      "y": 4,
      "z": -8,
      "name": "Soil_Dirt"
    },
    {
      "x": -13,
      "y": 5,
      "z": -8,
      "name": "Soil_Grass"
    },
    {
      "x": -13,
      "y": 0,
      "z": -7,
      "name": "Rock_Quartzite_Brick"
    },
    {
      "x": -13,
      "y": 1,
      "z": -7,
      "name": "Rock_Quartzite_Brick"
    },
    {
      "x": -13,
      "y": 2,
      "z": -7,
      "name": "Rock_Quartzite_Brick"
    },
    {
      "x": -13,
      "y": 3,
      "z": -7,
      "name": "Rock_Quartzite_Brick"
    },
    {
      "x": -13,
      "y": 4,
      "z": -7,
      "name": "Rock_Stone"
    },
    {
      "x": -13,
      "y": 5,
      "z": -7,
      "name": "Soil_Grass"
    },
    {
      "x": -13,
      "y": 0,
      "z": -6,
      "name": "Rock_Quartzite_Cobble"
    },
    {
      "x": -13,
      "y": 1,
      "z": -6,
      "name": "Rock_Quartzite_Brick"
    },
    {
      "x": -13,
      "y": 2,
      "z": -6,
      "name": "Rock_Quartzite_Brick"
    },
    {
      "x": -13,
      "y": 3,
      "z": -6,
      "name": "Rock_Quartzite_Brick"
    },
    {
      "x": -13,
      "y": 4,
      "z": -6,
      "name": "Rock_Stone"
    },
    {
      "x": -13,
      "y": 5,
      "z": -6,
      "name": "Soil_Dirt"
    },
    {
      "x": -13,
      "y": 6,
      "z": -6,
      "name": "Soil_Grass"
    },
    {
      "x": -13,
      "y": 0,
      "z": -5,
      "name": "Rock_Quartzite_Cobble"
    },
    {
      "x": -13,
      "y": 1,
      "z": -5,
      "name": "Rock_Quartzite_Brick"
    },
    {
      "x": -13,
      "y": 2,
      "z": -5,
      "name": "Rock_Quartzite_Brick"
    },
    {
      "x": -13,
      "y": 3,
      "z": -5,
      "name": "Rock_Quartzite_Brick"
    },
    {
      "x": -13,
      "y": 4,
      "z": -5,
      "name": "Rock_Quartzite_Brick"
    },
    {
      "x": -13,
      "y": 5,
      "z": -5,
      "name": "Soil_Dirt"
    },
    {
      "x": -13,
      "y": 6,
      "z": -5,
      "name": "Rock_Stone"
    },
    {
      "x": -13,
      "y": 7,
      "z": -5,
      "name": "Rock_Stone"
    },
    {
      "x": -13,
      "y": 8,
      "z": -5,
      "name": "Rock_Stone"
    },
    {
      "x": -13,
      "y": 9,
      "z": -5,
      "name": "Rock_Stone"
    },
    {
      "x": -13,
      "y": 10,
      "z": -5,
      "name": "Rock_Stone"
    },
    {
      "x": -13,
      "y": 0,
      "z": -4,
      "name": "Rock_Quartzite_Cobble"
    },
    {
      "x": -13,
      "y": 1,
      "z": -4,
      "name": "Rock_Quartzite"
    },
    {
      "x": -13,
      "y": 2,
      "z": -4,
      "name": "Rock_Quartzite_Brick"
    },
    {
      "x": -13,
      "y": 3,
      "z": -4,
      "name": "Rock_Quartzite_Brick"
    },
    {
      "x": -13,
      "y": 4,
      "z": -4,
      "name": "Rock_Quartzite_Brick"
    },
    {
      "x": -13,
      "y": 5,
      "z": -4,
      "name": "Soil_Dirt"
    },
    {
      "x": -13,
      "y": 6,
      "z": -4,
      "name": "Rock_Stone"
    },
    {
      "x": -13,
      "y": 7,
      "z": -4,
      "name": "Rock_Stone"
    },
    {
      "x": -13,
      "y": 8,
      "z": -4,
      "name": "Rock_Stone"
    },
    {
      "x": -13,
      "y": 9,
      "z": -4,
      "name": "Rock_Stone"
    },
    {
      "x": -13,
      "y": 10,
      "z": -4,
      "name": "Rock_Stone"
    },
    {
      "x": -13,
      "y": 11,
      "z": -4,
      "name": "Rock_Stone"
    },
    {
      "x": -13,
      "y": 12,
      "z": -4,
      "name": "Rock_Stone"
    },
    {
      "x": -13,
      "y": 0,
      "z": -3,
      "name": "Rock_Quartzite"
    },
    {
      "x": -13,
      "y": 1,
      "z": -3,
      "name": "Rock_Quartzite"
    },
    {
      "x": -13,
      "y": 2,
      "z": -3,
      "name": "Rock_Quartzite_Cobble"
    },
    {
      "x": -13,
      "y": 3,
      "z": -3,
      "name": "Rock_Quartzite_Brick"
    },
    {
      "x": -13,
      "y": 4,
      "z": -3,
      "name": "Rock_Quartzite_Brick"
    },
    {
      "x": -13,
      "y": 5,
      "z": -3,
      "name": "Soil_Dirt"
    },
    {
      "x": -13,
      "y": 6,
      "z": -3,
      "name": "Rock_Stone"
    },
    {
      "x": -13,
      "y": 7,
      "z": -3,
      "name": "Rock_Stone"
    },
    {
      "x": -13,
      "y": 8,
      "z": -3,
      "name": "Rock_Stone"
    },
    {
      "x": -13,
      "y": 9,
      "z": -3,
      "name": "Rock_Stone"
    },
    {
      "x": -13,
      "y": 10,
      "z": -3,
      "name": "Rock_Stone"
    },
    {
      "x": -13,
      "y": 11,
      "z": -3,
      "name": "Rock_Stone"
    },
    {
      "x": -13,
      "y": 12,
      "z": -3,
      "name": "Rock_Stone"
    },
    {
      "x": -13,
      "y": 0,
      "z": -2,
      "name": "Rock_Quartzite"
    },
    {
      "x": -13,
      "y": 1,
      "z": -2,
      "name": "Rock_Quartzite"
    },
    {
      "x": -13,
      "y": 2,
      "z": -2,
      "name": "Rock_Quartzite_Cobble"
    },
    {
      "x": -13,
      "y": 3,
      "z": -2,
      "name": "Rock_Quartzite_Cobble"
    },
    {
      "x": -13,
      "y": 4,
      "z": -2,
      "name": "Rock_Quartzite_Brick"
    },
    {
      "x": -13,
      "y": 5,
      "z": -2,
      "name": "Rock_Stone"
    },
    {
      "x": -13,
      "y": 6,
      "z": -2,
      "name": "Soil_Dirt"
    },
    {
      "x": -13,
      "y": 7,
      "z": -2,
      "name": "Rock_Stone"
    },
    {
      "x": -13,
      "y": 8,
      "z": -2,
      "name": "Rock_Stone"
    },
    {
      "x": -13,
      "y": 9,
      "z": -2,
      "name": "Rock_Stone"
    },
    {
      "x": -13,
      "y": 10,
      "z": -2,
      "name": "Rock_Stone"
    },
    {
      "x": -13,
      "y": 11,
      "z": -2,
      "name": "Rock_Stone"
    },
    {
      "x": -13,
      "y": 0,
      "z": -1,
      "name": "Rock_Quartzite"
    },
    {
      "x": -13,
      "y": 1,
      "z": -1,
      "name": "Rock_Quartzite"
    },
    {
      "x": -13,
      "y": 2,
      "z": -1,
      "name": "Rock_Quartzite_Cobble"
    },
    {
      "x": -13,
      "y": 3,
      "z": -1,
      "name": "Rock_Quartzite_Cobble"
    },
    {
      "x": -13,
      "y": 4,
      "z": -1,
      "name": "Rock_Quartzite_Brick"
    },
    {
      "x": -13,
      "y": 5,
      "z": -1,
      "name": "Rock_Stone"
    },
    {
      "x": -13,
      "y": 6,
      "z": -1,
      "name": "Soil_Dirt"
    },
    {
      "x": -13,
      "y": 7,
      "z": -1,
      "name": "Rock_Stone"
    },
    {
      "x": -13,
      "y": 8,
      "z": -1,
      "name": "Rock_Stone"
    },
    {
      "x": -13,
      "y": 9,
      "z": -1,
      "name": "Rock_Stone"
    },
    {
      "x": -13,
      "y": 10,
      "z": -1,
      "name": "Rock_Stone"
    },
    {
      "x": -13,
      "y": 11,
      "z": -1,
      "name": "Rock_Stone"
    },
    {
      "x": -13,
      "y": 0,
      "z": 0,
      "name": "Rock_Quartzite"
    },
    {
      "x": -13,
      "y": 1,
      "z": 0,
      "name": "Rock_Quartzite"
    },
    {
      "x": -13,
      "y": 2,
      "z": 0,
      "name": "Rock_Quartzite_Cobble"
    },
    {
      "x": -13,
      "y": 3,
      "z": 0,
      "name": "Rock_Quartzite_Cobble"
    },
    {
      "x": -13,
      "y": 4,
      "z": 0,
      "name": "Rock_Quartzite_Brick"
    },
    {
      "x": -13,
      "y": 5,
      "z": 0,
      "name": "Rock_Stone"
    },
    {
      "x": -13,
      "y": 6,
      "z": 0,
      "name": "Soil_Dirt"
    },
    {
      "x": -13,
      "y": 7,
      "z": 0,
      "name": "Rock_Stone"
    },
    {
      "x": -13,
      "y": 8,
      "z": 0,
      "name": "Rock_Stone"
    },
    {
      "x": -13,
      "y": 9,
      "z": 0,
      "name": "Rock_Stone"
    },
    {
      "x": -13,
      "y": 10,
      "z": 0,
      "name": "Rock_Stone"
    },
    {
      "x": -13,
      "y": 11,
      "z": 0,
      "name": "Rock_Stone"
    },
    {
      "x": -13,
      "y": 0,
      "z": 1,
      "name": "Rock_Quartzite"
    },
    {
      "x": -13,
      "y": 1,
      "z": 1,
      "name": "Rock_Quartzite_Cobble"
    },
    {
      "x": -13,
      "y": 2,
      "z": 1,
      "name": "Rock_Quartzite_Cobble"
    },
    {
      "x": -13,
      "y": 3,
      "z": 1,
      "name": "Rock_Quartzite_Brick"
    },
    {
      "x": -13,
      "y": 4,
      "z": 1,
      "name": "Rock_Quartzite_Brick"
    },
    {
      "x": -13,
      "y": 5,
      "z": 1,
      "name": "Rock_Stone"
    },
    {
      "x": -13,
      "y": 6,
      "z": 1,
      "name": "Soil_Grass"
    },
    {
      "x": -13,
      "y": 7,
      "z": 1,
      "name": "Plant_Grass_Sharp"
    },
    {
      "x": -13,
      "y": 8,
      "z": 1,
      "name": "Rock_Stone"
    },
    {
      "x": -13,
      "y": 9,
      "z": 1,
      "name": "Rock_Stone"
    },
    {
      "x": -13,
      "y": 10,
      "z": 1,
      "name": "Rock_Stone"
    },
    {
      "x": -13,
      "y": 11,
      "z": 1,
      "name": "Rock_Stone"
    },
    {
      "x": -13,
      "y": 0,
      "z": 2,
      "name": "Rock_Stone"
    },
    {
      "x": -13,
      "y": 1,
      "z": 2,
      "name": "Rock_Stone"
    },
    {
      "x": -13,
      "y": 2,
      "z": 2,
      "name": "Rock_Quartzite_Brick"
    },
    {
      "x": -13,
      "y": 3,
      "z": 2,
      "name": "Rock_Quartzite_Brick"
    },
    {
      "x": -13,
      "y": 4,
      "z": 2,
      "name": "Rock_Quartzite_Brick"
    },
    {
      "x": -13,
      "y": 5,
      "z": 2,
      "name": "Rock_Stone"
    },
    {
      "x": -13,
      "y": 6,
      "z": 2,
      "name": "Soil_Grass"
    },
    {
      "x": -13,
      "y": 7,
      "z": 2,
      "name": "Plant_Grass_Sharp"
    },
    {
      "x": -13,
      "y": 8,
      "z": 2,
      "name": "Rock_Stone"
    },
    {
      "x": -13,
      "y": 9,
      "z": 2,
      "name": "Rock_Stone"
    },
    {
      "x": -13,
      "y": 10,
      "z": 2,
      "name": "Rock_Stone"
    },
    {
      "x": -13,
      "y": 0,
      "z": 3,
      "name": "Rock_Stone"
    },
    {
      "x": -13,
      "y": 1,
      "z": 3,
      "name": "Rock_Stone"
    },
    {
      "x": -13,
      "y": 2,
      "z": 3,
      "name": "Rock_Quartzite_Brick"
    },
    {
      "x": -13,
      "y": 3,
      "z": 3,
      "name": "Rock_Quartzite_Brick"
    },
    {
      "x": -13,
      "y": 4,
      "z": 3,
      "name": "Rock_Stone"
    },
    {
      "x": -13,
      "y": 5,
      "z": 3,
      "name": "Soil_Dirt"
    },
    {
      "x": -13,
      "y": 6,
      "z": 3,
      "name": "Rock_Stone"
    },
    {
      "x": -13,
      "y": 7,
      "z": 3,
      "name": "Rock_Stone"
    },
    {
      "x": -13,
      "y": 8,
      "z": 3,
      "name": "Rock_Stone"
    },
    {
      "x": -13,
      "y": 9,
      "z": 3,
      "name": "Rock_Stone"
    },
    {
      "x": -13,
      "y": 0,
      "z": 4,
      "name": "Rock_Stone"
    },
    {
      "x": -13,
      "y": 1,
      "z": 4,
      "name": "Rock_Stone"
    },
    {
      "x": -13,
      "y": 2,
      "z": 4,
      "name": "Rock_Quartzite_Brick"
    },
    {
      "x": -13,
      "y": 3,
      "z": 4,
      "name": "Rock_Quartzite_Brick"
    },
    {
      "x": -13,
      "y": 4,
      "z": 4,
      "name": "Rock_Stone"
    },
    {
      "x": -13,
      "y": 5,
      "z": 4,
      "name": "Soil_Grass"
    },
    {
      "x": -13,
      "y": 0,
      "z": 5,
      "name": "Rock_Stone"
    },
    {
      "x": -13,
      "y": 1,
      "z": 5,
      "name": "Rock_Stone"
    },
    {
      "x": -13,
      "y": 2,
      "z": 5,
      "name": "Rock_Quartzite_Brick"
    },
    {
      "x": -13,
      "y": 3,
      "z": 5,
      "name": "Rock_Quartzite_Brick"
    },
    {
      "x": -13,
      "y": 4,
      "z": 5,
      "name": "Rock_Stone"
    },
    {
      "x": -13,
      "y": 5,
      "z": 5,
      "name": "Soil_Grass"
    },
    {
      "x": -13,
      "y": 0,
      "z": 6,
      "name": "Rock_Stone"
    },
    {
      "x": -13,
      "y": 1,
      "z": 6,
      "name": "Rock_Stone"
    },
    {
      "x": -13,
      "y": 2,
      "z": 6,
      "name": "Rock_Stone"
    },
    {
      "x": -13,
      "y": 3,
      "z": 6,
      "name": "Rock_Stone"
    },
    {
      "x": -13,
      "y": 4,
      "z": 6,
      "name": "Soil_Dirt"
    },
    {
      "x": -13,
      "y": 5,
      "z": 6,
      "name": "Soil_Grass"
    },
    {
      "x": -12,
      "y": 0,
      "z": -12,
      "name": "Rock_Stone"
    },
    {
      "x": -12,
      "y": 1,
      "z": -12,
      "name": "Rock_Stone"
    },
    {
      "x": -12,
      "y": 0,
      "z": -11,
      "name": "Rock_Stone"
    },
    {
      "x": -12,
      "y": 1,
      "z": -11,
      "name": "Rock_Stone"
    },
    {
      "x": -12,
      "y": 2,
      "z": -11,
      "name": "Rock_Stone"
    },
    {
      "x": -12,
      "y": 3,
      "z": -11,
      "name": "Soil_Grass"
    },
    {
      "x": -12,
      "y": 0,
      "z": -10,
      "name": "Rock_Stone"
    },
    {
      "x": -12,
      "y": 1,
      "z": -10,
      "name": "Rock_Stone"
    },
    {
      "x": -12,
      "y": 2,
      "z": -10,
      "name": "Rock_Stone"
    },
    {
      "x": -12,
      "y": 3,
      "z": -10,
      "name": "Soil_Dirt"
    },
    {
      "x": -12,
      "y": 4,
      "z": -10,
      "name": "Soil_Grass"
    },
    {
      "x": -12,
      "y": 0,
      "z": -9,
      "name": "Rock_Stone"
    },
    {
      "x": -12,
      "y": 1,
      "z": -9,
      "name": "Rock_Stone"
    },
    {
      "x": -12,
      "y": 2,
      "z": -9,
      "name": "Rock_Stone"
    },
    {
      "x": -12,
      "y": 3,
      "z": -9,
      "name": "Soil_Dirt"
    },
    {
      "x": -12,
      "y": 4,
      "z": -9,
      "name": "Soil_Grass"
    },
    {
      "x": -12,
      "y": 0,
      "z": -8,
      "name": "Rock_Stone"
    },
    {
      "x": -12,
      "y": 1,
      "z": -8,
      "name": "Rock_Stone"
    },
    {
      "x": -12,
      "y": 2,
      "z": -8,
      "name": "Rock_Stone"
    },
    {
      "x": -12,
      "y": 3,
      "z": -8,
      "name": "Soil_Dirt"
    },
    {
      "x": -12,
      "y": 4,
      "z": -8,
      "name": "Soil_Dirt"
    },
    {
      "x": -12,
      "y": 5,
      "z": -8,
      "name": "Soil_Grass"
    },
    {
      "x": -12,
      "y": 0,
      "z": -7,
      "name": "Rock_Quartzite_Cobble"
    },
    {
      "x": -12,
      "y": 1,
      "z": -7,
      "name": "Rock_Quartzite_Brick"
    },
    {
      "x": -12,
      "y": 2,
      "z": -7,
      "name": "Rock_Quartzite_Brick"
    },
    {
      "x": -12,
      "y": 3,
      "z": -7,
      "name": "Rock_Quartzite_Brick"
    },
    {
      "x": -12,
      "y": 4,
      "z": -7,
      "name": "Rock_Stone"
    },
    {
      "x": -12,
      "y": 5,
      "z": -7,
      "name": "Soil_Grass"
    },
    {
      "x": -12,
      "y": 0,
      "z": -6,
      "name": "Deco_Trash_Pile_Large",
      "rotation": 1
    },
    {
      "x": -12,
      "y": 4,
      "z": -6,
      "name": "Rock_Stone"
    },
    {
      "x": -12,
      "y": 5,
      "z": -6,
      "name": "Soil_Grass"
    },
    {
      "x": -12,
      "y": 0,
      "z": -5,
      "name": "Deco_Trash_Pile_Large",
      "rotation": 1
    },
    {
      "x": -12,
      "y": 4,
      "z": -5,
      "name": "Rock_Stone"
    },
    {
      "x": -12,
      "y": 5,
      "z": -5,
      "name": "Soil_Dirt"
    },
    {
      "x": -12,
      "y": 6,
      "z": -5,
      "name": "Rock_Stone"
    },
    {
      "x": -12,
      "y": 7,
      "z": -5,
      "name": "Rock_Stone"
    },
    {
      "x": -12,
      "y": 8,
      "z": -5,
      "name": "Rock_Stone"
    },
    {
      "x": -12,
      "y": 9,
      "z": -5,
      "name": "Rock_Stone"
    },
    {
      "x": -12,
      "y": 10,
      "z": -5,
      "name": "Rock_Stone"
    },
    {
      "x": -12,
      "y": 11,
      "z": -5,
      "name": "Rock_Stone"
    },
    {
      "x": -12,
      "y": 12,
      "z": -5,
      "name": "Rock_Stone"
    },
    {
      "x": -12,
      "y": 6,
      "z": -4,
      "name": "Soil_Dirt"
    },
    {
      "x": -12,
      "y": 7,
      "z": -4,
      "name": "Rock_Stone"
    },
    {
      "x": -12,
      "y": 8,
      "z": -4,
      "name": "Rock_Stone"
    },
    {
      "x": -12,
      "y": 9,
      "z": -4,
      "name": "Rock_Stone"
    },
    {
      "x": -12,
      "y": 10,
      "z": -4,
      "name": "Rock_Stone"
    },
    {
      "x": -12,
      "y": 11,
      "z": -4,
      "name": "Rock_Stone"
    },
    {
      "x": -12,
      "y": 12,
      "z": -4,
      "name": "Rock_Stone"
    },
    {
      "x": -12,
      "y": 4,
      "z": -3,
      "name": "Rock_Quartzite_Brick_Half",
      "rotation": 8
    },
    {
      "x": -12,
      "y": 5,
      "z": -3,
      "name": "Rock_Quartzite_Brick_Smooth"
    },
    {
      "x": -12,
      "y": 6,
      "z": -3,
      "name": "Soil_Dirt"
    },
    {
      "x": -12,
      "y": 7,
      "z": -3,
      "name": "Rock_Stone"
    },
    {
      "x": -12,
      "y": 8,
      "z": -3,
      "name": "Rock_Stone"
    },
    {
      "x": -12,
      "y": 9,
      "z": -3,
      "name": "Rock_Stone"
    },
    {
      "x": -12,
      "y": 10,
      "z": -3,
      "name": "Rock_Stone"
    },
    {
      "x": -12,
      "y": 11,
      "z": -3,
      "name": "Rock_Stone"
    },
    {
      "x": -12,
      "y": 12,
      "z": -3,
      "name": "Rock_Stone"
    },
    {
      "x": -12,
      "y": 0,
      "z": -2,
      "name": "Rock_Quartzite"
    },
    {
      "x": -12,
      "y": 1,
      "z": -2,
      "name": "Rock_Quartzite_Cobble"
    },
    {
      "x": -12,
      "y": 2,
      "z": -2,
      "name": "Rock_Quartzite_Brick"
    },
    {
      "x": -12,
      "y": 3,
      "z": -2,
      "name": "Rock_Quartzite_Brick"
    },
    {
      "x": -12,
      "y": 4,
      "z": -2,
      "name": "Rock_Quartzite_Brick"
    },
    {
      "x": -12,
      "y": 5,
      "z": -2,
      "name": "Rock_Quartzite_Brick"
    },
    {
      "x": -12,
      "y": 6,
      "z": -2,
      "name": "Soil_Dirt"
    },
    {
      "x": -12,
      "y": 7,
      "z": -2,
      "name": "Rock_Stone"
    },
    {
      "x": -12,
      "y": 8,
      "z": -2,
      "name": "Rock_Stone"
    },
    {
      "x": -12,
      "y": 9,
      "z": -2,
      "name": "Rock_Stone"
    },
    {
      "x": -12,
      "y": 10,
      "z": -2,
      "name": "Rock_Stone"
    },
    {
      "x": -12,
      "y": 11,
      "z": -2,
      "name": "Rock_Stone"
    },
    {
      "x": -12,
      "y": 12,
      "z": -2,
      "name": "Rock_Stone"
    },
    {
      "x": -12,
      "y": 0,
      "z": -1,
      "name": "Rock_Quartzite"
    },
    {
      "x": -12,
      "y": 1,
      "z": -1,
      "name": "Rock_Quartzite"
    },
    {
      "x": -12,
      "y": 2,
      "z": -1,
      "name": "Rock_Quartzite_Cobble"
    },
    {
      "x": -12,
      "y": 3,
      "z": -1,
      "name": "Rock_Quartzite_Brick"
    },
    {
      "x": -12,
      "y": 4,
      "z": -1,
      "name": "Rock_Quartzite_Brick"
    },
    {
      "x": -12,
      "y": 5,
      "z": -1,
      "name": "Rock_Quartzite_Brick"
    },
    {
      "x": -12,
      "y": 6,
      "z": -1,
      "name": "Soil_Dirt"
    },
    {
      "x": -12,
      "y": 7,
      "z": -1,
      "name": "Rock_Stone"
    },
    {
      "x": -12,
      "y": 8,
      "z": -1,
      "name": "Rock_Stone"
    },
    {
      "x": -12,
      "y": 9,
      "z": -1,
      "name": "Rock_Stone"
    },
    {
      "x": -12,
      "y": 10,
      "z": -1,
      "name": "Rock_Stone"
    },
    {
      "x": -12,
      "y": 11,
      "z": -1,
      "name": "Rock_Stone"
    },
    {
      "x": -12,
      "y": 0,
      "z": 0,
      "name": "Deco_Book_Pile_Small",
      "rotation": 1
    },
    {
      "x": -12,
      "y": 1,
      "z": 0,
      "name": "Nat20_Force_Empty"
    },
    {
      "x": -12,
      "y": 2,
      "z": 0,
      "name": "Nat20_Force_Empty"
    },
    {
      "x": -12,
      "y": 3,
      "z": 0,
      "name": "Nat20_Force_Empty"
    },
    {
      "x": -12,
      "y": 4,
      "z": 0,
      "name": "Rock_Quartzite_Brick_Half",
      "rotation": 8
    },
    {
      "x": -12,
      "y": 5,
      "z": 0,
      "name": "Rock_Quartzite_Brick"
    },
    {
      "x": -12,
      "y": 6,
      "z": 0,
      "name": "Soil_Grass"
    },
    {
      "x": -12,
      "y": 7,
      "z": 0,
      "name": "Plant_Grass_Sharp_Tall"
    },
    {
      "x": -12,
      "y": 8,
      "z": 0,
      "name": "Plant_Grass_Sharp_Tall",
      "filler": 1024
    },
    {
      "x": -12,
      "y": 9,
      "z": 0,
      "name": "Rock_Stone"
    },
    {
      "x": -12,
      "y": 10,
      "z": 0,
      "name": "Rock_Stone"
    },
    {
      "x": -12,
      "y": 11,
      "z": 0,
      "name": "Rock_Stone"
    },
    {
      "x": -12,
      "y": 0,
      "z": 1,
      "name": "Nat20_Force_Empty"
    },
    {
      "x": -12,
      "y": 1,
      "z": 1,
      "name": "Nat20_Force_Empty"
    },
    {
      "x": -12,
      "y": 2,
      "z": 1,
      "name": "Nat20_Force_Empty"
    },
    {
      "x": -12,
      "y": 3,
      "z": 1,
      "name": "Nat20_Force_Empty"
    },
    {
      "x": -12,
      "y": 4,
      "z": 1,
      "name": "Nat20_Force_Empty"
    },
    {
      "x": -12,
      "y": 5,
      "z": 1,
      "name": "Rock_Quartzite_Brick"
    },
    {
      "x": -12,
      "y": 6,
      "z": 1,
      "name": "Soil_Grass"
    },
    {
      "x": -12,
      "y": 7,
      "z": 1,
      "name": "Plant_Grass_Sharp_Short"
    },
    {
      "x": -12,
      "y": 8,
      "z": 1,
      "name": "Rock_Stone"
    },
    {
      "x": -12,
      "y": 9,
      "z": 1,
      "name": "Rock_Stone"
    },
    {
      "x": -12,
      "y": 10,
      "z": 1,
      "name": "Rock_Stone"
    },
    {
      "x": -12,
      "y": 11,
      "z": 1,
      "name": "Rock_Stone"
    },
    {
      "x": -12,
      "y": 0,
      "z": 2,
      "name": "Rock_Stone"
    },
    {
      "x": -12,
      "y": 1,
      "z": 2,
      "name": "Plant_Crop_Mushroom_Flatcap_Green"
    },
    {
      "x": -12,
      "y": 2,
      "z": 2,
      "name": "Nat20_Force_Empty"
    },
    {
      "x": -12,
      "y": 3,
      "z": 2,
      "name": "Rock_Stone_Stalactite_Large",
      "filler": 31744,
      "rotation": 8
    },
    {
      "x": -12,
      "y": 4,
      "z": 2,
      "name": "Rock_Stone_Stalactite_Large",
      "rotation": 8
    },
    {
      "x": -12,
      "y": 5,
      "z": 2,
      "name": "Rock_Quartzite_Brick"
    },
    {
      "x": -12,
      "y": 6,
      "z": 2,
      "name": "Soil_Grass"
    },
    {
      "x": -12,
      "y": 7,
      "z": 2,
      "name": "Plant_Grass_Sharp"
    },
    {
      "x": -12,
      "y": 8,
      "z": 2,
      "name": "Rock_Stone"
    },
    {
      "x": -12,
      "y": 9,
      "z": 2,
      "name": "Rock_Stone"
    },
    {
      "x": -12,
      "y": 10,
      "z": 2,
      "name": "Rock_Stone"
    },
    {
      "x": -12,
      "y": 11,
      "z": 2,
      "name": "Rock_Stone"
    },
    {
      "x": -12,
      "y": 0,
      "z": 3,
      "name": "Rock_Stone"
    },
    {
      "x": -12,
      "y": 1,
      "z": 3,
      "name": "Rock_Stone"
    },
    {
      "x": -12,
      "y": 2,
      "z": 3,
      "name": "Nat20_Force_Empty"
    },
    {
      "x": -12,
      "y": 3,
      "z": 3,
      "name": "Nat20_Force_Empty"
    },
    {
      "x": -12,
      "y": 4,
      "z": 3,
      "name": "Rock_Stone"
    },
    {
      "x": -12,
      "y": 5,
      "z": 3,
      "name": "Rock_Stone"
    },
    {
      "x": -12,
      "y": 6,
      "z": 3,
      "name": "Soil_Grass"
    },
    {
      "x": -12,
      "y": 7,
      "z": 3,
      "name": "Plant_Grass_Sharp_Short"
    },
    {
      "x": -12,
      "y": 8,
      "z": 3,
      "name": "Rock_Stone"
    },
    {
      "x": -12,
      "y": 9,
      "z": 3,
      "name": "Rock_Stone"
    },
    {
      "x": -12,
      "y": 0,
      "z": 4,
      "name": "Rock_Stone"
    },
    {
      "x": -12,
      "y": 1,
      "z": 4,
      "name": "Rock_Stone"
    },
    {
      "x": -12,
      "y": 2,
      "z": 4,
      "name": "Nat20_Force_Empty"
    },
    {
      "x": -12,
      "y": 3,
      "z": 4,
      "name": "Rock_Stone_Stalactite_Small",
      "rotation": 8
    },
    {
      "x": -12,
      "y": 4,
      "z": 4,
      "name": "Rock_Stone"
    },
    {
      "x": -12,
      "y": 5,
      "z": 4,
      "name": "Rock_Stone"
    },
    {
      "x": -12,
      "y": 6,
      "z": 4,
      "name": "Soil_Grass"
    },
    {
      "x": -12,
      "y": 0,
      "z": 5,
      "name": "Rock_Stone"
    },
    {
      "x": -12,
      "y": 1,
      "z": 5,
      "name": "Rock_Stone"
    },
    {
      "x": -12,
      "y": 2,
      "z": 5,
      "name": "Rock_Quartzite_Brick"
    },
    {
      "x": -12,
      "y": 3,
      "z": 5,
      "name": "Rock_Quartzite_Brick"
    },
    {
      "x": -12,
      "y": 4,
      "z": 5,
      "name": "Rock_Stone"
    },
    {
      "x": -12,
      "y": 5,
      "z": 5,
      "name": "Soil_Grass"
    },
    {
      "x": -12,
      "y": 6,
      "z": 5,
      "name": "Nat20_Force_Empty"
    },
    {
      "x": -12,
      "y": 0,
      "z": 6,
      "name": "Rock_Stone"
    },
    {
      "x": -12,
      "y": 1,
      "z": 6,
      "name": "Rock_Stone"
    },
    {
      "x": -12,
      "y": 2,
      "z": 6,
      "name": "Rock_Stone"
    },
    {
      "x": -12,
      "y": 3,
      "z": 6,
      "name": "Rock_Stone"
    },
    {
      "x": -12,
      "y": 4,
      "z": 6,
      "name": "Soil_Dirt"
    },
    {
      "x": -12,
      "y": 5,
      "z": 6,
      "name": "Soil_Grass"
    },
    {
      "x": -12,
      "y": 6,
      "z": 6,
      "name": "Nat20_Force_Empty"
    },
    {
      "x": -12,
      "y": 0,
      "z": 7,
      "name": "Rock_Stone"
    },
    {
      "x": -12,
      "y": 1,
      "z": 7,
      "name": "Rock_Stone"
    },
    {
      "x": -12,
      "y": 2,
      "z": 7,
      "name": "Rock_Stone"
    },
    {
      "x": -12,
      "y": 3,
      "z": 7,
      "name": "Nat20_Force_Empty"
    },
    {
      "x": -12,
      "y": 4,
      "z": 7,
      "name": "Nat20_Force_Empty"
    },
    {
      "x": -12,
      "y": 5,
      "z": 7,
      "name": "Nat20_Force_Empty"
    },
    {
      "x": -12,
      "y": 6,
      "z": 7,
      "name": "Nat20_Force_Empty"
    },
    {
      "x": -11,
      "y": 0,
      "z": -10,
      "name": "Rock_Stone"
    },
    {
      "x": -11,
      "y": 1,
      "z": -10,
      "name": "Rock_Stone"
    },
    {
      "x": -11,
      "y": 2,
      "z": -10,
      "name": "Rock_Stone"
    },
    {
      "x": -11,
      "y": 0,
      "z": -9,
      "name": "Rock_Stone"
    },
    {
      "x": -11,
      "y": 1,
      "z": -9,
      "name": "Rock_Stone"
    },
    {
      "x": -11,
      "y": 2,
      "z": -9,
      "name": "Rock_Stone"
    },
    {
      "x": -11,
      "y": 3,
      "z": -9,
      "name": "Soil_Dirt"
    },
    {
      "x": -11,
      "y": 4,
      "z": -9,
      "name": "Soil_Grass"
    },
    {
      "x": -11,
      "y": 0,
      "z": -8,
      "name": "Rock_Stone"
    },
    {
      "x": -11,
      "y": 1,
      "z": -8,
      "name": "Rock_Stone"
    },
    {
      "x": -11,
      "y": 2,
      "z": -8,
      "name": "Rock_Stone"
    },
    {
      "x": -11,
      "y": 3,
      "z": -8,
      "name": "Rock_Stone"
    },
    {
      "x": -11,
      "y": 4,
      "z": -8,
      "name": "Soil_Dirt"
    },
    {
      "x": -11,
      "y": 5,
      "z": -8,
      "name": "Soil_Grass"
    },
    {
      "x": -11,
      "y": 0,
      "z": -7,
      "name": "Rock_Quartzite"
    },
    {
      "x": -11,
      "y": 1,
      "z": -7,
      "name": "Rock_Quartzite_Cobble"
    },
    {
      "x": -11,
      "y": 2,
      "z": -7,
      "name": "Rock_Quartzite_Brick"
    },
    {
      "x": -11,
      "y": 3,
      "z": -7,
      "name": "Rock_Quartzite_Brick"
    },
    {
      "x": -11,
      "y": 4,
      "z": -7,
      "name": "Rock_Stone"
    },
    {
      "x": -11,
      "y": 5,
      "z": -7,
      "name": "Soil_Grass"
    },
    {
      "x": -11,
      "y": 0,
      "z": -6,
      "name": "Nat20_Force_Empty"
    },
    {
      "x": -11,
      "y": 1,
      "z": -6,
      "name": "Nat20_Force_Empty"
    },
    {
      "x": -11,
      "y": 2,
      "z": -6,
      "name": "Nat20_Force_Empty"
    },
    {
      "x": -11,
      "y": 3,
      "z": -6,
      "name": "Nat20_Force_Empty"
    },
    {
      "x": -11,
      "y": 4,
      "z": -6,
      "name": "Nat20_Force_Empty"
    },
    {
      "x": -11,
      "y": 5,
      "z": -6,
      "name": "Soil_Dirt"
    },
    {
      "x": -11,
      "y": 6,
      "z": -6,
      "name": "Soil_Grass"
    },
    {
      "x": -11,
      "y": 0,
      "z": -5,
      "name": "Nat20_Force_Empty"
    },
    {
      "x": -11,
      "y": 1,
      "z": -5,
      "name": "Nat20_Force_Empty"
    },
    {
      "x": -11,
      "y": 2,
      "z": -5,
      "name": "Nat20_Force_Empty"
    },
    {
      "x": -11,
      "y": 3,
      "z": -5,
      "name": "Nat20_Force_Empty"
    },
    {
      "x": -11,
      "y": 4,
      "z": -5,
      "name": "Nat20_Force_Empty"
    },
    {
      "x": -11,
      "y": 5,
      "z": -5,
      "name": "Rock_Quartzite_Brick"
    },
    {
      "x": -11,
      "y": 6,
      "z": -5,
      "name": "Soil_Dirt"
    },
    {
      "x": -11,
      "y": 7,
      "z": -5,
      "name": "Rock_Stone"
    },
    {
      "x": -11,
      "y": 8,
      "z": -5,
      "name": "Rock_Stone"
    },
    {
      "x": -11,
      "y": 9,
      "z": -5,
      "name": "Rock_Stone"
    },
    {
      "x": -11,
      "y": 10,
      "z": -5,
      "name": "Rock_Stone"
    },
    {
      "x": -11,
      "y": 11,
      "z": -5,
      "name": "Rock_Stone"
    },
    {
      "x": -11,
      "y": 12,
      "z": -5,
      "name": "Rock_Stone"
    },
    {
      "x": -11,
      "y": 0,
      "z": -4,
      "name": "Furniture_Crude_Bed",
      "components": {
        "Components": {
          "RespawnBlock": {}
        }
      }
    },
    {
      "x": -11,
      "y": 1,
      "z": -4,
      "name": "Nat20_Force_Empty"
    },
    {
      "x": -11,
      "y": 2,
      "z": -4,
      "name": "Nat20_Force_Empty"
    },
    {
      "x": -11,
      "y": 3,
      "z": -4,
      "name": "Nat20_Force_Empty"
    },
    {
      "x": -11,
      "y": 4,
      "z": -4,
      "name": "Nat20_Force_Empty"
    },
    {
      "x": -11,
      "y": 5,
      "z": -4,
      "name": "Rock_Quartzite_Brick"
    },
    {
      "x": -11,
      "y": 6,
      "z": -4,
      "name": "Soil_Dirt"
    },
    {
      "x": -11,
      "y": 7,
      "z": -4,
      "name": "Rock_Stone"
    },
    {
      "x": -11,
      "y": 8,
      "z": -4,
      "name": "Rock_Stone"
    },
    {
      "x": -11,
      "y": 9,
      "z": -4,
      "name": "Rock_Stone"
    },
    {
      "x": -11,
      "y": 10,
      "z": -4,
      "name": "Rock_Stone"
    },
    {
      "x": -11,
      "y": 11,
      "z": -4,
      "name": "Rock_Stone"
    },
    {
      "x": -11,
      "y": 12,
      "z": -4,
      "name": "Rock_Stone"
    },
    {
      "x": -11,
      "y": 0,
      "z": -3,
      "name": "Furniture_Crude_Bed",
      "components": {
        "Components": {
          "RespawnBlock": {}
        }
      },
      "filler": 32
    },
    {
      "x": -11,
      "y": 1,
      "z": -3,
      "name": "Nat20_Force_Empty"
    },
    {
      "x": -11,
      "y": 2,
      "z": -3,
      "name": "Nat20_Force_Empty"
    },
    {
      "x": -11,
      "y": 3,
      "z": -3,
      "name": "Nat20_Force_Empty"
    },
    {
      "x": -11,
      "y": 4,
      "z": -3,
      "name": "Nat20_Force_Empty"
    },
    {
      "x": -11,
      "y": 5,
      "z": -3,
      "name": "Rock_Quartzite_Brick"
    },
    {
      "x": -11,
      "y": 6,
      "z": -3,
      "name": "Soil_Dirt"
    },
    {
      "x": -11,
      "y": 7,
      "z": -3,
      "name": "Rock_Stone"
    },
    {
      "x": -11,
      "y": 8,
      "z": -3,
      "name": "Rock_Stone"
    },
    {
      "x": -11,
      "y": 9,
      "z": -3,
      "name": "Rock_Stone"
    },
    {
      "x": -11,
      "y": 10,
      "z": -3,
      "name": "Rock_Stone"
    },
    {
      "x": -11,
      "y": 11,
      "z": -3,
      "name": "Rock_Stone"
    },
    {
      "x": -11,
      "y": 12,
      "z": -3,
      "name": "Rock_Stone"
    },
    {
      "x": -11,
      "y": 0,
      "z": -2,
      "name": "Furniture_Village_Counter",
      "rotation": 1
    },
    {
      "x": -11,
      "y": 1,
      "z": -2,
      "name": "Nat20_Force_Empty"
    },
    {
      "x": -11,
      "y": 2,
      "z": -2,
      "name": "Nat20_Force_Empty"
    },
    {
      "x": -11,
      "y": 3,
      "z": -2,
      "name": "Nat20_Force_Empty"
    },
    {
      "x": -11,
      "y": 4,
      "z": -2,
      "name": "Nat20_Force_Empty"
    },
    {
      "x": -11,
      "y": 5,
      "z": -2,
      "name": "Rock_Quartzite_Brick"
    },
    {
      "x": -11,
      "y": 6,
      "z": -2,
      "name": "Soil_Dirt"
    },
    {
      "x": -11,
      "y": 7,
      "z": -2,
      "name": "Rock_Stone"
    },
    {
      "x": -11,
      "y": 8,
      "z": -2,
      "name": "Rock_Stone"
    },
    {
      "x": -11,
      "y": 9,
      "z": -2,
      "name": "Rock_Stone"
    },
    {
      "x": -11,
      "y": 10,
      "z": -2,
      "name": "Rock_Stone"
    },
    {
      "x": -11,
      "y": 11,
      "z": -2,
      "name": "Rock_Stone"
    },
    {
      "x": -11,
      "y": 12,
      "z": -2,
      "name": "Rock_Stone"
    },
    {
      "x": -11,
      "y": 0,
      "z": -1,
      "name": "Furniture_Village_Counter",
      "filler": 32,
      "rotation": 1
    },
    {
      "x": -11,
      "y": 1,
      "z": -1,
      "name": "Nat20_Force_Empty"
    },
    {
      "x": -11,
      "y": 2,
      "z": -1,
      "name": "Nat20_Force_Empty"
    },
    {
      "x": -11,
      "y": 3,
      "z": -1,
      "name": "Nat20_Force_Empty"
    },
    {
      "x": -11,
      "y": 4,
      "z": -1,
      "name": "Nat20_Force_Empty"
    },
    {
      "x": -11,
      "y": 5,
      "z": -1,
      "name": "Rock_Quartzite_Brick"
    },
    {
      "x": -11,
      "y": 6,
      "z": -1,
      "name": "Soil_Dirt"
    },
    {
      "x": -11,
      "y": 7,
      "z": -1,
      "name": "Rock_Stone"
    },
    {
      "x": -11,
      "y": 8,
      "z": -1,
      "name": "Rock_Stone"
    },
    {
      "x": -11,
      "y": 9,
      "z": -1,
      "name": "Rock_Stone"
    },
    {
      "x": -11,
      "y": 10,
      "z": -1,
      "name": "Rock_Stone"
    },
    {
      "x": -11,
      "y": 11,
      "z": -1,
      "name": "Rock_Stone"
    },
    {
      "x": -11,
      "y": 12,
      "z": -1,
      "name": "Rock_Stone"
    },
    {
      "x": -11,
      "y": 0,
      "z": 0,
      "name": "Nat20_Force_Empty"
    },
    {
      "x": -11,
      "y": 1,
      "z": 0,
      "name": "Nat20_Force_Empty"
    },
    {
      "x": -11,
      "y": 2,
      "z": 0,
      "name": "Nat20_Force_Empty"
    },
    {
      "x": -11,
      "y": 3,
      "z": 0,
      "name": "Nat20_Force_Empty"
    },
    {
      "x": -11,
      "y": 4,
      "z": 0,
      "name": "Nat20_Force_Empty"
    },
    {
      "x": -11,
      "y": 5,
      "z": 0,
      "name": "Rock_Quartzite_Brick"
    },
    {
      "x": -11,
      "y": 6,
      "z": 0,
      "name": "Soil_Dirt"
    },
    {
      "x": -11,
      "y": 7,
      "z": 0,
      "name": "Rock_Stone"
    },
    {
      "x": -11,
      "y": 8,
      "z": 0,
      "name": "Rock_Stone"
    },
    {
      "x": -11,
      "y": 9,
      "z": 0,
      "name": "Rock_Stone"
    },
    {
      "x": -11,
      "y": 10,
      "z": 0,
      "name": "Rock_Stone"
    },
    {
      "x": -11,
      "y": 11,
      "z": 0,
      "name": "Rock_Stone"
    },
    {
      "x": -11,
      "y": 0,
      "z": 1,
      "name": "Nat20_Force_Empty"
    },
    {
      "x": -11,
      "y": 1,
      "z": 1,
      "name": "Nat20_Force_Empty"
    },
    {
      "x": -11,
      "y": 2,
      "z": 1,
      "name": "Nat20_Force_Empty"
    },
    {
      "x": -11,
      "y": 3,
      "z": 1,
      "name": "Nat20_Force_Empty"
    },
    {
      "x": -11,
      "y": 4,
      "z": 1,
      "name": "Nat20_Force_Empty"
    },
    {
      "x": -11,
      "y": 5,
      "z": 1,
      "name": "Rock_Quartzite_Brick"
    },
    {
      "x": -11,
      "y": 6,
      "z": 1,
      "name": "Soil_Dirt"
    },
    {
      "x": -11,
      "y": 7,
      "z": 1,
      "name": "Rock_Stone"
    },
    {
      "x": -11,
      "y": 8,
      "z": 1,
      "name": "Rock_Stone"
    },
    {
      "x": -11,
      "y": 9,
      "z": 1,
      "name": "Rock_Stone"
    },
    {
      "x": -11,
      "y": 10,
      "z": 1,
      "name": "Rock_Stone"
    },
    {
      "x": -11,
      "y": 11,
      "z": 1,
      "name": "Rock_Stone"
    },
    {
      "x": -11,
      "y": 0,
      "z": 2,
      "name": "Deco_Pot_Clay_Broken"
    },
    {
      "x": -11,
      "y": 1,
      "z": 2,
      "name": "Nat20_Force_Empty"
    },
    {
      "x": -11,
      "y": 2,
      "z": 2,
      "name": "Nat20_Force_Empty"
    },
    {
      "x": -11,
      "y": 3,
      "z": 2,
      "name": "Nat20_Force_Empty"
    },
    {
      "x": -11,
      "y": 4,
      "z": 2,
      "name": "Nat20_Force_Empty"
    },
    {
      "x": -11,
      "y": 5,
      "z": 2,
      "name": "Rock_Quartzite_Brick"
    },
    {
      "x": -11,
      "y": 6,
      "z": 2,
      "name": "Soil_Grass"
    },
    {
      "x": -11,
      "y": 7,
      "z": 2,
      "name": "Plant_Grass_Sharp"
    },
    {
      "x": -11,
      "y": 8,
      "z": 2,
      "name": "Rock_Stone"
    },
    {
      "x": -11,
      "y": 9,
      "z": 2,
      "name": "Rock_Stone"
    },
    {
      "x": -11,
      "y": 10,
      "z": 2,
      "name": "Rock_Stone"
    },
    {
      "x": -11,
      "y": 11,
      "z": 2,
      "name": "Rock_Stone"
    },
    {
      "x": -11,
      "y": 0,
      "z": 3,
      "name": "Rock_Stone"
    },
    {
      "x": -11,
      "y": 1,
      "z": 3,
      "name": "Rock_Stone"
    },
    {
      "x": -11,
      "y": 2,
      "z": 3,
      "name": "Nat20_Force_Empty"
    },
    {
      "x": -11,
      "y": 3,
      "z": 3,
      "name": "Nat20_Force_Empty"
    },
    {
      "x": -11,
      "y": 4,
      "z": 3,
      "name": "Nat20_Force_Empty"
    },
    {
      "x": -11,
      "y": 5,
      "z": 3,
      "name": "Rock_Stone"
    },
    {
      "x": -11,
      "y": 6,
      "z": 3,
      "name": "Soil_Dirt"
    },
    {
      "x": -11,
      "y": 7,
      "z": 3,
      "name": "Rock_Stone"
    },
    {
      "x": -11,
      "y": 8,
      "z": 3,
      "name": "Rock_Stone"
    },
    {
      "x": -11,
      "y": 9,
      "z": 3,
      "name": "Rock_Stone"
    },
    {
      "x": -11,
      "y": 0,
      "z": 4,
      "name": "Rock_Stone"
    },
    {
      "x": -11,
      "y": 1,
      "z": 4,
      "name": "Rock_Stone"
    },
    {
      "x": -11,
      "y": 2,
      "z": 4,
      "name": "Nat20_Force_Empty"
    },
    {
      "x": -11,
      "y": 3,
      "z": 4,
      "name": "Nat20_Force_Empty"
    },
    {
      "x": -11,
      "y": 4,
      "z": 4,
      "name": "Rock_Stone"
    },
    {
      "x": -11,
      "y": 5,
      "z": 4,
      "name": "Rock_Stone"
    },
    {
      "x": -11,
      "y": 6,
      "z": 4,
      "name": "Soil_Grass"
    },
    {
      "x": -11,
      "y": 0,
      "z": 5,
      "name": "Rock_Stone"
    },
    {
      "x": -11,
      "y": 1,
      "z": 5,
      "name": "Rock_Stone"
    },
    {
      "x": -11,
      "y": 2,
      "z": 5,
      "name": "Rock_Quartzite_Brick"
    },
    {
      "x": -11,
      "y": 3,
      "z": 5,
      "name": "Rock_Quartzite_Brick"
    },
    {
      "x": -11,
      "y": 4,
      "z": 5,
      "name": "Rock_Stone"
    },
    {
      "x": -11,
      "y": 5,
      "z": 5,
      "name": "Soil_Grass"
    },
    {
      "x": -11,
      "y": 6,
      "z": 5,
      "name": "Nat20_Force_Empty"
    },
    {
      "x": -11,
      "y": 0,
      "z": 6,
      "name": "Rock_Stone"
    },
    {
      "x": -11,
      "y": 1,
      "z": 6,
      "name": "Rock_Stone"
    },
    {
      "x": -11,
      "y": 2,
      "z": 6,
      "name": "Rock_Stone"
    },
    {
      "x": -11,
      "y": 3,
      "z": 6,
      "name": "Rock_Stone"
    },
    {
      "x": -11,
      "y": 4,
      "z": 6,
      "name": "Rock_Quartzite_Brick"
    },
    {
      "x": -11,
      "y": 5,
      "z": 6,
      "name": "Soil_Dirt"
    },
    {
      "x": -11,
      "y": 6,
      "z": 6,
      "name": "Nat20_Force_Empty"
    },
    {
      "x": -11,
      "y": 0,
      "z": 7,
      "name": "Rock_Stone"
    },
    {
      "x": -11,
      "y": 1,
      "z": 7,
      "name": "Rock_Stone"
    },
    {
      "x": -11,
      "y": 2,
      "z": 7,
      "name": "Rock_Stone"
    },
    {
      "x": -11,
      "y": 3,
      "z": 7,
      "name": "Rock_Stone"
    },
    {
      "x": -11,
      "y": 4,
      "z": 7,
      "name": "Soil_Dirt"
    },
    {
      "x": -11,
      "y": 5,
      "z": 7,
      "name": "Soil_Dirt"
    },
    {
      "x": -11,
      "y": 6,
      "z": 7,
      "name": "Nat20_Force_Empty"
    },
    {
      "x": -10,
      "y": 0,
      "z": -8,
      "name": "Rock_Stone"
    },
    {
      "x": -10,
      "y": 1,
      "z": -8,
      "name": "Rock_Stone"
    },
    {
      "x": -10,
      "y": 2,
      "z": -8,
      "name": "Rock_Stone"
    },
    {
      "x": -10,
      "y": 3,
      "z": -8,
      "name": "Rock_Stone"
    },
    {
      "x": -10,
      "y": 4,
      "z": -8,
      "name": "Soil_Dirt"
    },
    {
      "x": -10,
      "y": 5,
      "z": -8,
      "name": "Soil_Grass"
    },
    {
      "x": -10,
      "y": 0,
      "z": -7,
      "name": "Rock_Quartzite_Cobble"
    },
    {
      "x": -10,
      "y": 1,
      "z": -7,
      "name": "Rock_Quartzite_Cobble"
    },
    {
      "x": -10,
      "y": 2,
      "z": -7,
      "name": "Rock_Quartzite_Brick"
    },
    {
      "x": -10,
      "y": 3,
      "z": -7,
      "name": "Rock_Quartzite_Brick"
    },
    {
      "x": -10,
      "y": 4,
      "z": -7,
      "name": "Rock_Stone"
    },
    {
      "x": -10,
      "y": 5,
      "z": -7,
      "name": "Rock_Stone"
    },
    {
      "x": -10,
      "y": 6,
      "z": -7,
      "name": "Soil_Grass"
    },
    {
      "x": -10,
      "y": 0,
      "z": -6,
      "name": "Furniture_Crude_Chest_Small",
      "components": {
        "Components": {
          "ItemContainerBlock": {
            "ItemContainer": {
              "Capacity": 18,
              "Items": {
                "16": {
                  "Id": "Ore_Iron",
                  "Quantity": 1,
                  "Durability": 0.0,
                  "MaxDurability": 0.0,
                  "OverrideDroppedItemAnimation": false
                },
                "3": {
                  "Id": "Plant_Seeds_Lettuce",
                  "Quantity": 1,
                  "Durability": 0.0,
                  "MaxDurability": 0.0,
                  "OverrideDroppedItemAnimation": false
                },
                "8": {
                  "Id": "Wood_Beech_Trunk",
                  "Quantity": 8,
                  "Durability": 0.0,
                  "MaxDurability": 0.0,
                  "OverrideDroppedItemAnimation": false
                },
                "9": {
                  "Id": "Ingredient_Life_Essence",
                  "Quantity": 3,
                  "Durability": 0.0,
                  "MaxDurability": 0.0,
                  "OverrideDroppedItemAnimation": false
                },
                "4": {
                  "Id": "Ingredient_Hide_Light",
                  "Quantity": 1,
                  "Durability": 0.0,
                  "MaxDurability": 0.0,
                  "OverrideDroppedItemAnimation": false
                }
              }
            },
            "Capacity": 20
          }
        }
      }
    },
    {
      "x": -10,
      "y": 1,
      "z": -6,
      "name": "Nat20_Force_Empty"
    },
    {
      "x": -10,
      "y": 2,
      "z": -6,
      "name": "Nat20_Force_Empty"
    },
    {
      "x": -10,
      "y": 3,
      "z": -6,
      "name": "Nat20_Force_Empty"
    },
    {
      "x": -10,
      "y": 4,
      "z": -6,
      "name": "Rock_Stone"
    },
    {
      "x": -10,
      "y": 5,
      "z": -6,
      "name": "Rock_Stone"
    },
    {
      "x": -10,
      "y": 6,
      "z": -6,
      "name": "Soil_Grass"
    },
    {
      "x": -10,
      "y": 0,
      "z": -5,
      "name": "Nat20_Force_Empty"
    },
    {
      "x": -10,
      "y": 1,
      "z": -5,
      "name": "Nat20_Force_Empty"
    },
    {
      "x": -10,
      "y": 2,
      "z": -5,
      "name": "Nat20_Force_Empty"
    },
    {
      "x": -10,
      "y": 3,
      "z": -5,
      "name": "Nat20_Force_Empty"
    },
    {
      "x": -10,
      "y": 4,
      "z": -5,
      "name": "Nat20_Force_Empty"
    },
    {
      "x": -10,
      "y": 5,
      "z": -5,
      "name": "Rock_Quartzite_Brick"
    },
    {
      "x": -10,
      "y": 6,
      "z": -5,
      "name": "Soil_Grass"
    },
    {
      "x": -10,
      "y": 0,
      "z": -4,
      "name": "Nat20_Force_Empty"
    },
    {
      "x": -10,
      "y": 1,
      "z": -4,
      "name": "Nat20_Force_Empty"
    },
    {
      "x": -10,
      "y": 2,
      "z": -4,
      "name": "Nat20_Force_Empty"
    },
    {
      "x": -10,
      "y": 3,
      "z": -4,
      "name": "Nat20_Force_Empty"
    },
    {
      "x": -10,
      "y": 4,
      "z": -4,
      "name": "Nat20_Force_Empty"
    },
    {
      "x": -10,
      "y": 5,
      "z": -4,
      "name": "Rock_Quartzite_Brick"
    },
    {
      "x": -10,
      "y": 6,
      "z": -4,
      "name": "Soil_Dirt"
    },
    {
      "x": -10,
      "y": 7,
      "z": -4,
      "name": "Rock_Stone"
    },
    {
      "x": -10,
      "y": 8,
      "z": -4,
      "name": "Rock_Stone"
    },
    {
      "x": -10,
      "y": 9,
      "z": -4,
      "name": "Rock_Stone"
    },
    {
      "x": -10,
      "y": 10,
      "z": -4,
      "name": "Rock_Stone"
    },
    {
      "x": -10,
      "y": 11,
      "z": -4,
      "name": "Rock_Stone"
    },
    {
      "x": -10,
      "y": 12,
      "z": -4,
      "name": "Rock_Stone"
    },
    {
      "x": -10,
      "y": 0,
      "z": -3,
      "name": "Nat20_Force_Empty"
    },
    {
      "x": -10,
      "y": 1,
      "z": -3,
      "name": "Nat20_Force_Empty"
    },
    {
      "x": -10,
      "y": 2,
      "z": -3,
      "name": "Nat20_Force_Empty"
    },
    {
      "x": -10,
      "y": 3,
      "z": -3,
      "name": "Nat20_Force_Empty"
    },
    {
      "x": -10,
      "y": 4,
      "z": -3,
      "name": "Nat20_Force_Empty"
    },
    {
      "x": -10,
      "y": 5,
      "z": -3,
      "name": "Rock_Quartzite_Brick"
    },
    {
      "x": -10,
      "y": 6,
      "z": -3,
      "name": "Soil_Dirt"
    },
    {
      "x": -10,
      "y": 7,
      "z": -3,
      "name": "Rock_Stone"
    },
    {
      "x": -10,
      "y": 8,
      "z": -3,
      "name": "Rock_Stone"
    },
    {
      "x": -10,
      "y": 9,
      "z": -3,
      "name": "Rock_Stone"
    },
    {
      "x": -10,
      "y": 10,
      "z": -3,
      "name": "Rock_Stone"
    },
    {
      "x": -10,
      "y": 11,
      "z": -3,
      "name": "Rock_Stone"
    },
    {
      "x": -10,
      "y": 12,
      "z": -3,
      "name": "Rock_Stone"
    },
    {
      "x": -10,
      "y": 0,
      "z": -2,
      "name": "Nat20_Force_Empty"
    },
    {
      "x": -10,
      "y": 1,
      "z": -2,
      "name": "Nat20_Force_Empty"
    },
    {
      "x": -10,
      "y": 2,
      "z": -2,
      "name": "Nat20_Force_Empty"
    },
    {
      "x": -10,
      "y": 3,
      "z": -2,
      "name": "Nat20_Force_Empty"
    },
    {
      "x": -10,
      "y": 4,
      "z": -2,
      "name": "Nat20_Force_Empty"
    },
    {
      "x": -10,
      "y": 5,
      "z": -2,
      "name": "Rock_Quartzite_Brick"
    },
    {
      "x": -10,
      "y": 6,
      "z": -2,
      "name": "Soil_Grass"
    },
    {
      "x": -10,
      "y": 7,
      "z": -2,
      "name": "Plant_Grass_Sharp"
    },
    {
      "x": -10,
      "y": 8,
      "z": -2,
      "name": "Rock_Stone"
    },
    {
      "x": -10,
      "y": 9,
      "z": -2,
      "name": "Rock_Stone"
    },
    {
      "x": -10,
      "y": 10,
      "z": -2,
      "name": "Rock_Stone"
    },
    {
      "x": -10,
      "y": 11,
      "z": -2,
      "name": "Rock_Stone"
    },
    {
      "x": -10,
      "y": 12,
      "z": -2,
      "name": "Rock_Stone"
    },
    {
      "x": -10,
      "y": 0,
      "z": -1,
      "name": "Plant_Crop_Mushroom_Flatcap_Green",
      "components": {
        "Components": {
          "FarmingBlock": {
            "GrowthProgress": 1.0,
            "LastTickGameTime": "0001-01-02T11:30:16.631186165Z",
            "Generation": 1,
            "SpreadRate": 0.5
          }
        }
      }
    },
    {
      "x": -10,
      "y": 1,
      "z": -1,
      "name": "Nat20_Force_Empty"
    },
    {
      "x": -10,
      "y": 2,
      "z": -1,
      "name": "Nat20_Force_Empty"
    },
    {
      "x": -10,
      "y": 3,
      "z": -1,
      "name": "Nat20_Force_Empty"
    },
    {
      "x": -10,
      "y": 4,
      "z": -1,
      "name": "Nat20_Force_Empty"
    },
    {
      "x": -10,
      "y": 5,
      "z": -1,
      "name": "Rock_Quartzite_Brick"
    },
    {
      "x": -10,
      "y": 6,
      "z": -1,
      "name": "Soil_Dirt"
    },
    {
      "x": -10,
      "y": 7,
      "z": -1,
      "name": "Rock_Stone"
    },
    {
      "x": -10,
      "y": 8,
      "z": -1,
      "name": "Rock_Stone"
    },
    {
      "x": -10,
      "y": 9,
      "z": -1,
      "name": "Rock_Stone"
    },
    {
      "x": -10,
      "y": 10,
      "z": -1,
      "name": "Rock_Stone"
    },
    {
      "x": -10,
      "y": 11,
      "z": -1,
      "name": "Rock_Stone"
    },
    {
      "x": -10,
      "y": 12,
      "z": -1,
      "name": "Rock_Stone"
    },
    {
      "x": -10,
      "y": 0,
      "z": 0,
      "name": "Nat20_Force_Empty"
    },
    {
      "x": -10,
      "y": 1,
      "z": 0,
      "name": "Nat20_Force_Empty"
    },
    {
      "x": -10,
      "y": 2,
      "z": 0,
      "name": "Nat20_Force_Empty"
    },
    {
      "x": -10,
      "y": 3,
      "z": 0,
      "name": "Nat20_Force_Empty"
    },
    {
      "x": -10,
      "y": 4,
      "z": 0,
      "name": "Nat20_Force_Empty"
    },
    {
      "x": -10,
      "y": 5,
      "z": 0,
      "name": "Rock_Quartzite_Brick"
    },
    {
      "x": -10,
      "y": 6,
      "z": 0,
      "name": "Soil_Dirt"
    },
    {
      "x": -10,
      "y": 7,
      "z": 0,
      "name": "Rock_Stone"
    },
    {
      "x": -10,
      "y": 8,
      "z": 0,
      "name": "Rock_Stone"
    },
    {
      "x": -10,
      "y": 9,
      "z": 0,
      "name": "Rock_Stone"
    },
    {
      "x": -10,
      "y": 10,
      "z": 0,
      "name": "Rock_Stone"
    },
    {
      "x": -10,
      "y": 11,
      "z": 0,
      "name": "Rock_Stone"
    },
    {
      "x": -10,
      "y": 12,
      "z": 0,
      "name": "Rock_Stone"
    },
    {
      "x": -10,
      "y": 0,
      "z": 1,
      "name": "Nat20_Force_Empty"
    },
    {
      "x": -10,
      "y": 1,
      "z": 1,
      "name": "Nat20_Force_Empty"
    },
    {
      "x": -10,
      "y": 2,
      "z": 1,
      "name": "Nat20_Force_Empty"
    },
    {
      "x": -10,
      "y": 3,
      "z": 1,
      "name": "Nat20_Force_Empty"
    },
    {
      "x": -10,
      "y": 4,
      "z": 1,
      "name": "Nat20_Force_Empty"
    },
    {
      "x": -10,
      "y": 5,
      "z": 1,
      "name": "Rock_Quartzite_Brick"
    },
    {
      "x": -10,
      "y": 6,
      "z": 1,
      "name": "Soil_Dirt"
    },
    {
      "x": -10,
      "y": 7,
      "z": 1,
      "name": "Rock_Stone"
    },
    {
      "x": -10,
      "y": 8,
      "z": 1,
      "name": "Rock_Stone"
    },
    {
      "x": -10,
      "y": 9,
      "z": 1,
      "name": "Rock_Stone"
    },
    {
      "x": -10,
      "y": 10,
      "z": 1,
      "name": "Rock_Stone"
    },
    {
      "x": -10,
      "y": 11,
      "z": 1,
      "name": "Rock_Stone"
    },
    {
      "x": -10,
      "y": 0,
      "z": 2,
      "name": "Nat20_Force_Empty"
    },
    {
      "x": -10,
      "y": 1,
      "z": 2,
      "name": "Nat20_Force_Empty"
    },
    {
      "x": -10,
      "y": 2,
      "z": 2,
      "name": "Nat20_Force_Empty"
    },
    {
      "x": -10,
      "y": 3,
      "z": 2,
      "name": "Nat20_Force_Empty"
    },
    {
      "x": -10,
      "y": 4,
      "z": 2,
      "name": "Nat20_Force_Empty"
    },
    {
      "x": -10,
      "y": 5,
      "z": 2,
      "name": "Rock_Quartzite_Brick"
    },
    {
      "x": -10,
      "y": 6,
      "z": 2,
      "name": "Soil_Dirt"
    },
    {
      "x": -10,
      "y": 7,
      "z": 2,
      "name": "Rock_Stone"
    },
    {
      "x": -10,
      "y": 8,
      "z": 2,
      "name": "Rock_Stone"
    },
    {
      "x": -10,
      "y": 9,
      "z": 2,
      "name": "Rock_Stone"
    },
    {
      "x": -10,
      "y": 10,
      "z": 2,
      "name": "Rock_Stone"
    },
    {
      "x": -10,
      "y": 11,
      "z": 2,
      "name": "Rock_Stone"
    },
    {
      "x": -10,
      "y": 0,
      "z": 3,
      "name": "Rock_Stone"
    },
    {
      "x": -10,
      "y": 1,
      "z": 3,
      "name": "Rock_Stone"
    },
    {
      "x": -10,
      "y": 2,
      "z": 3,
      "name": "Plant_Moss_Rug_Green"
    },
    {
      "x": -10,
      "y": 3,
      "z": 3,
      "name": "Nat20_Force_Empty"
    },
    {
      "x": -10,
      "y": 4,
      "z": 3,
      "name": "Nat20_Force_Empty"
    },
    {
      "x": -10,
      "y": 5,
      "z": 3,
      "name": "Rock_Quartzite_Brick"
    },
    {
      "x": -10,
      "y": 6,
      "z": 3,
      "name": "Soil_Dirt"
    },
    {
      "x": -10,
      "y": 7,
      "z": 3,
      "name": "Rock_Stone"
    },
    {
      "x": -10,
      "y": 8,
      "z": 3,
      "name": "Rock_Stone"
    },
    {
      "x": -10,
      "y": 0,
      "z": 4,
      "name": "Rock_Stone"
    },
    {
      "x": -10,
      "y": 1,
      "z": 4,
      "name": "Rock_Stone"
    },
    {
      "x": -10,
      "y": 2,
      "z": 4,
      "name": "Plant_Moss_Rug_Green"
    },
    {
      "x": -10,
      "y": 3,
      "z": 4,
      "name": "Nat20_Force_Empty"
    },
    {
      "x": -10,
      "y": 4,
      "z": 4,
      "name": "Nat20_Force_Empty"
    },
    {
      "x": -10,
      "y": 5,
      "z": 4,
      "name": "Rock_Stone"
    },
    {
      "x": -10,
      "y": 6,
      "z": 4,
      "name": "Soil_Grass"
    },
    {
      "x": -10,
      "y": 0,
      "z": 5,
      "name": "Rock_Stone"
    },
    {
      "x": -10,
      "y": 1,
      "z": 5,
      "name": "Rock_Stone"
    },
    {
      "x": -10,
      "y": 2,
      "z": 5,
      "name": "Rock_Quartzite"
    },
    {
      "x": -10,
      "y": 3,
      "z": 5,
      "name": "Rock_Quartzite_Brick"
    },
    {
      "x": -10,
      "y": 4,
      "z": 5,
      "name": "Rock_Quartzite_Brick"
    },
    {
      "x": -10,
      "y": 5,
      "z": 5,
      "name": "Soil_Grass"
    },
    {
      "x": -10,
      "y": 6,
      "z": 5,
      "name": "Nat20_Force_Empty"
    },
    {
      "x": -10,
      "y": 0,
      "z": 6,
      "name": "Rock_Stone"
    },
    {
      "x": -10,
      "y": 1,
      "z": 6,
      "name": "Rock_Stone"
    },
    {
      "x": -10,
      "y": 2,
      "z": 6,
      "name": "Rock_Stone"
    },
    {
      "x": -10,
      "y": 3,
      "z": 6,
      "name": "Rock_Stone"
    },
    {
      "x": -10,
      "y": 4,
      "z": 6,
      "name": "Rock_Quartzite_Brick"
    },
    {
      "x": -10,
      "y": 5,
      "z": 6,
      "name": "Soil_Grass"
    },
    {
      "x": -10,
      "y": 6,
      "z": 6,
      "name": "Nat20_Force_Empty"
    },
    {
      "x": -10,
      "y": 0,
      "z": 7,
      "name": "Rock_Stone"
    },
    {
      "x": -10,
      "y": 1,
      "z": 7,
      "name": "Rock_Stone"
    },
    {
      "x": -10,
      "y": 2,
      "z": 7,
      "name": "Rock_Stone"
    },
    {
      "x": -10,
      "y": 3,
      "z": 7,
      "name": "Rock_Stone"
    },
    {
      "x": -10,
      "y": 4,
      "z": 7,
      "name": "Soil_Dirt"
    },
    {
      "x": -10,
      "y": 5,
      "z": 7,
      "name": "Soil_Grass"
    },
    {
      "x": -10,
      "y": 6,
      "z": 7,
      "name": "Nat20_Force_Empty"
    },
    {
      "x": -9,
      "y": 0,
      "z": -8,
      "name": "Rock_Stone"
    },
    {
      "x": -9,
      "y": 1,
      "z": -8,
      "name": "Rock_Stone"
    },
    {
      "x": -9,
      "y": 2,
      "z": -8,
      "name": "Rock_Stone"
    },
    {
      "x": -9,
      "y": 3,
      "z": -8,
      "name": "Rock_Stone"
    },
    {
      "x": -9,
      "y": 4,
      "z": -8,
      "name": "Soil_Dirt"
    },
    {
      "x": -9,
      "y": 5,
      "z": -8,
      "name": "Soil_Grass"
    },
    {
      "x": -9,
      "y": 0,
      "z": -7,
      "name": "Rock_Quartzite_Cobble"
    },
    {
      "x": -9,
      "y": 1,
      "z": -7,
      "name": "Rock_Quartzite_Cobble"
    },
    {
      "x": -9,
      "y": 2,
      "z": -7,
      "name": "Rock_Quartzite_Brick"
    },
    {
      "x": -9,
      "y": 3,
      "z": -7,
      "name": "Rock_Quartzite_Brick"
    },
    {
      "x": -9,
      "y": 4,
      "z": -7,
      "name": "Rock_Stone"
    },
    {
      "x": -9,
      "y": 5,
      "z": -7,
      "name": "Rock_Stone"
    },
    {
      "x": -9,
      "y": 6,
      "z": -7,
      "name": "Soil_Grass"
    },
    {
      "x": -9,
      "y": 0,
      "z": -6,
      "name": "Nat20_Force_Empty"
    },
    {
      "x": -9,
      "y": 1,
      "z": -6,
      "name": "Nat20_Force_Empty"
    },
    {
      "x": -9,
      "y": 2,
      "z": -6,
      "name": "Nat20_Force_Empty"
    },
    {
      "x": -9,
      "y": 3,
      "z": -6,
      "name": "Nat20_Force_Empty"
    },
    {
      "x": -9,
      "y": 4,
      "z": -6,
      "name": "Rock_Quartzite_Brick"
    },
    {
      "x": -9,
      "y": 5,
      "z": -6,
      "name": "Rock_Stone"
    },
    {
      "x": -9,
      "y": 6,
      "z": -6,
      "name": "Soil_Grass"
    },
    {
      "x": -9,
      "y": 0,
      "z": -5,
      "name": "Furniture_Crude_Brazier"
    },
    {
      "x": -9,
      "y": 1,
      "z": -5,
      "name": "Nat20_Force_Empty"
    },
    {
      "x": -9,
      "y": 2,
      "z": -5,
      "name": "Nat20_Force_Empty"
    },
    {
      "x": -9,
      "y": 3,
      "z": -5,
      "name": "Nat20_Force_Empty"
    },
    {
      "x": -9,
      "y": 4,
      "z": -5,
      "name": "Nat20_Force_Empty"
    },
    {
      "x": -9,
      "y": 5,
      "z": -5,
      "name": "Rock_Quartzite_Brick"
    },
    {
      "x": -9,
      "y": 6,
      "z": -5,
      "name": "Soil_Grass"
    },
    {
      "x": -9,
      "y": 0,
      "z": -4,
      "name": "Nat20_Force_Empty"
    },
    {
      "x": -9,
      "y": 1,
      "z": -4,
      "name": "Nat20_Force_Empty"
    },
    {
      "x": -9,
      "y": 2,
      "z": -4,
      "name": "Nat20_Force_Empty"
    },
    {
      "x": -9,
      "y": 3,
      "z": -4,
      "name": "Nat20_Force_Empty"
    },
    {
      "x": -9,
      "y": 4,
      "z": -4,
      "name": "Nat20_Force_Empty"
    },
    {
      "x": -9,
      "y": 5,
      "z": -4,
      "name": "Rock_Quartzite_Brick"
    },
    {
      "x": -9,
      "y": 6,
      "z": -4,
      "name": "Soil_Dirt"
    },
    {
      "x": -9,
      "y": 7,
      "z": -4,
      "name": "Rock_Stone"
    },
    {
      "x": -9,
      "y": 8,
      "z": -4,
      "name": "Rock_Stone"
    },
    {
      "x": -9,
      "y": 9,
      "z": -4,
      "name": "Rock_Stone"
    },
    {
      "x": -9,
      "y": 10,
      "z": -4,
      "name": "Rock_Stone"
    },
    {
      "x": -9,
      "y": 11,
      "z": -4,
      "name": "Rock_Stone"
    },
    {
      "x": -9,
      "y": 0,
      "z": -3,
      "name": "Nat20_Force_Empty"
    },
    {
      "x": -9,
      "y": 1,
      "z": -3,
      "name": "Nat20_Force_Empty"
    },
    {
      "x": -9,
      "y": 2,
      "z": -3,
      "name": "Nat20_Force_Empty"
    },
    {
      "x": -9,
      "y": 3,
      "z": -3,
      "name": "Nat20_Force_Empty"
    },
    {
      "x": -9,
      "y": 4,
      "z": -3,
      "name": "Nat20_Force_Empty"
    },
    {
      "x": -9,
      "y": 5,
      "z": -3,
      "name": "Rock_Quartzite_Brick"
    },
    {
      "x": -9,
      "y": 6,
      "z": -3,
      "name": "Soil_Grass"
    },
    {
      "x": -9,
      "y": 7,
      "z": -3,
      "name": "Plant_Grass_Sharp_Tall"
    },
    {
      "x": -9,
      "y": 8,
      "z": -3,
      "name": "Plant_Grass_Sharp_Tall",
      "filler": 1024
    },
    {
      "x": -9,
      "y": 9,
      "z": -3,
      "name": "Rock_Stone"
    },
    {
      "x": -9,
      "y": 10,
      "z": -3,
      "name": "Rock_Stone"
    },
    {
      "x": -9,
      "y": 11,
      "z": -3,
      "name": "Rock_Stone"
    },
    {
      "x": -9,
      "y": 12,
      "z": -3,
      "name": "Rock_Stone"
    },
    {
      "x": -9,
      "y": 0,
      "z": -2,
      "name": "Nat20_Force_Empty"
    },
    {
      "x": -9,
      "y": 1,
      "z": -2,
      "name": "Nat20_Force_Empty"
    },
    {
      "x": -9,
      "y": 2,
      "z": -2,
      "name": "Nat20_Force_Empty"
    },
    {
      "x": -9,
      "y": 3,
      "z": -2,
      "name": "Nat20_Force_Empty"
    },
    {
      "x": -9,
      "y": 4,
      "z": -2,
      "name": "Nat20_Force_Empty"
    },
    {
      "x": -9,
      "y": 5,
      "z": -2,
      "name": "Rock_Quartzite_Brick"
    },
    {
      "x": -9,
      "y": 6,
      "z": -2,
      "name": "Soil_Grass"
    },
    {
      "x": -9,
      "y": 7,
      "z": -2,
      "name": "Plant_Grass_Sharp"
    },
    {
      "x": -9,
      "y": 8,
      "z": -2,
      "name": "Rock_Stone"
    },
    {
      "x": -9,
      "y": 9,
      "z": -2,
      "name": "Rock_Stone"
    },
    {
      "x": -9,
      "y": 10,
      "z": -2,
      "name": "Rock_Stone"
    },
    {
      "x": -9,
      "y": 11,
      "z": -2,
      "name": "Rock_Stone"
    },
    {
      "x": -9,
      "y": 12,
      "z": -2,
      "name": "Rock_Stone"
    },
    {
      "x": -9,
      "y": 0,
      "z": -1,
      "name": "Nat20_Force_Empty"
    },
    {
      "x": -9,
      "y": 1,
      "z": -1,
      "name": "Nat20_Force_Empty"
    },
    {
      "x": -9,
      "y": 2,
      "z": -1,
      "name": "Nat20_Force_Empty"
    },
    {
      "x": -9,
      "y": 3,
      "z": -1,
      "name": "Nat20_Force_Empty"
    },
    {
      "x": -9,
      "y": 4,
      "z": -1,
      "name": "Nat20_Force_Empty"
    },
    {
      "x": -9,
      "y": 5,
      "z": -1,
      "name": "Rock_Quartzite_Brick"
    },
    {
      "x": -9,
      "y": 6,
      "z": -1,
      "name": "Soil_Grass"
    },
    {
      "x": -9,
      "y": 7,
      "z": -1,
      "name": "Plant_Grass_Sharp_Tall"
    },
    {
      "x": -9,
      "y": 8,
      "z": -1,
      "name": "Plant_Grass_Sharp_Tall",
      "filler": 1024
    },
    {
      "x": -9,
      "y": 9,
      "z": -1,
      "name": "Rock_Stone"
    },
    {
      "x": -9,
      "y": 10,
      "z": -1,
      "name": "Rock_Stone"
    },
    {
      "x": -9,
      "y": 11,
      "z": -1,
      "name": "Rock_Stone"
    },
    {
      "x": -9,
      "y": 12,
      "z": -1,
      "name": "Rock_Stone"
    },
    {
      "x": -9,
      "y": 0,
      "z": 0,
      "name": "Nat20_Force_Empty"
    },
    {
      "x": -9,
      "y": 1,
      "z": 0,
      "name": "Nat20_Force_Empty"
    },
    {
      "x": -9,
      "y": 2,
      "z": 0,
      "name": "Nat20_Force_Empty"
    },
    {
      "x": -9,
      "y": 3,
      "z": 0,
      "name": "Nat20_Force_Empty"
    },
    {
      "x": -9,
      "y": 4,
      "z": 0,
      "name": "Nat20_Force_Empty"
    },
    {
      "x": -9,
      "y": 5,
      "z": 0,
      "name": "Rock_Quartzite_Brick"
    },
    {
      "x": -9,
      "y": 6,
      "z": 0,
      "name": "Soil_Dirt"
    },
    {
      "x": -9,
      "y": 7,
      "z": 0,
      "name": "Rock_Stone"
    },
    {
      "x": -9,
      "y": 8,
      "z": 0,
      "name": "Rock_Stone"
    },
    {
      "x": -9,
      "y": 9,
      "z": 0,
      "name": "Rock_Stone"
    },
    {
      "x": -9,
      "y": 10,
      "z": 0,
      "name": "Rock_Stone"
    },
    {
      "x": -9,
      "y": 11,
      "z": 0,
      "name": "Rock_Stone"
    },
    {
      "x": -9,
      "y": 12,
      "z": 0,
      "name": "Rock_Stone"
    },
    {
      "x": -9,
      "y": 0,
      "z": 1,
      "name": "Nat20_Force_Empty"
    },
    {
      "x": -9,
      "y": 1,
      "z": 1,
      "name": "Nat20_Force_Empty"
    },
    {
      "x": -9,
      "y": 2,
      "z": 1,
      "name": "Nat20_Force_Empty"
    },
    {
      "x": -9,
      "y": 3,
      "z": 1,
      "name": "Nat20_Force_Empty"
    },
    {
      "x": -9,
      "y": 4,
      "z": 1,
      "name": "Nat20_Force_Empty"
    },
    {
      "x": -9,
      "y": 5,
      "z": 1,
      "name": "Rock_Quartzite_Brick"
    },
    {
      "x": -9,
      "y": 6,
      "z": 1,
      "name": "Soil_Dirt"
    },
    {
      "x": -9,
      "y": 7,
      "z": 1,
      "name": "Rock_Stone"
    },
    {
      "x": -9,
      "y": 8,
      "z": 1,
      "name": "Rock_Stone"
    },
    {
      "x": -9,
      "y": 9,
      "z": 1,
      "name": "Rock_Stone"
    },
    {
      "x": -9,
      "y": 10,
      "z": 1,
      "name": "Rock_Stone"
    },
    {
      "x": -9,
      "y": 11,
      "z": 1,
      "name": "Rock_Stone"
    },
    {
      "x": -9,
      "y": 0,
      "z": 2,
      "name": "Nat20_Force_Empty"
    },
    {
      "x": -9,
      "y": 1,
      "z": 2,
      "name": "Nat20_Force_Empty"
    },
    {
      "x": -9,
      "y": 2,
      "z": 2,
      "name": "Nat20_Force_Empty"
    },
    {
      "x": -9,
      "y": 3,
      "z": 2,
      "name": "Nat20_Force_Empty"
    },
    {
      "x": -9,
      "y": 4,
      "z": 2,
      "name": "Nat20_Force_Empty"
    },
    {
      "x": -9,
      "y": 5,
      "z": 2,
      "name": "Rock_Quartzite_Brick"
    },
    {
      "x": -9,
      "y": 6,
      "z": 2,
      "name": "Soil_Dirt"
    },
    {
      "x": -9,
      "y": 7,
      "z": 2,
      "name": "Rock_Stone"
    },
    {
      "x": -9,
      "y": 8,
      "z": 2,
      "name": "Rock_Stone"
    },
    {
      "x": -9,
      "y": 9,
      "z": 2,
      "name": "Rock_Stone"
    },
    {
      "x": -9,
      "y": 0,
      "z": 3,
      "name": "Rock_Stone"
    },
    {
      "x": -9,
      "y": 1,
      "z": 3,
      "name": "Nat20_Force_Empty"
    },
    {
      "x": -9,
      "y": 2,
      "z": 3,
      "name": "Nat20_Force_Empty"
    },
    {
      "x": -9,
      "y": 3,
      "z": 3,
      "name": "Nat20_Force_Empty"
    },
    {
      "x": -9,
      "y": 4,
      "z": 3,
      "name": "Nat20_Force_Empty"
    },
    {
      "x": -9,
      "y": 5,
      "z": 3,
      "name": "Rock_Quartzite_Brick"
    },
    {
      "x": -9,
      "y": 6,
      "z": 3,
      "name": "Soil_Dirt"
    },
    {
      "x": -9,
      "y": 7,
      "z": 3,
      "name": "Rock_Stone"
    },
    {
      "x": -9,
      "y": 0,
      "z": 4,
      "name": "Rock_Stone"
    },
    {
      "x": -9,
      "y": 1,
      "z": 4,
      "name": "Rock_Stone"
    },
    {
      "x": -9,
      "y": 2,
      "z": 4,
      "name": "Plant_Moss_Rug_Green"
    },
    {
      "x": -9,
      "y": 3,
      "z": 4,
      "name": "Nat20_Force_Empty"
    },
    {
      "x": -9,
      "y": 4,
      "z": 4,
      "name": "Nat20_Force_Empty"
    },
    {
      "x": -9,
      "y": 5,
      "z": 4,
      "name": "Rock_Quartzite_Brick"
    },
    {
      "x": -9,
      "y": 6,
      "z": 4,
      "name": "Soil_Grass"
    },
    {
      "x": -9,
      "y": 0,
      "z": 5,
      "name": "Rock_Stone"
    },
    {
      "x": -9,
      "y": 1,
      "z": 5,
      "name": "Rock_Stone"
    },
    {
      "x": -9,
      "y": 2,
      "z": 5,
      "name": "Rock_Quartzite"
    },
    {
      "x": -9,
      "y": 3,
      "z": 5,
      "name": "Rock_Quartzite_Brick"
    },
    {
      "x": -9,
      "y": 4,
      "z": 5,
      "name": "Rock_Quartzite_Brick"
    },
    {
      "x": -9,
      "y": 5,
      "z": 5,
      "name": "Rock_Quartzite_Brick"
    },
    {
      "x": -9,
      "y": 6,
      "z": 5,
      "name": "Soil_Grass"
    },
    {
      "x": -9,
      "y": 0,
      "z": 6,
      "name": "Rock_Stone"
    },
    {
      "x": -9,
      "y": 1,
      "z": 6,
      "name": "Rock_Stone"
    },
    {
      "x": -9,
      "y": 2,
      "z": 6,
      "name": "Rock_Stone"
    },
    {
      "x": -9,
      "y": 3,
      "z": 6,
      "name": "Rock_Stone"
    },
    {
      "x": -9,
      "y": 4,
      "z": 6,
      "name": "Rock_Quartzite_Brick"
    },
    {
      "x": -9,
      "y": 5,
      "z": 6,
      "name": "Soil_Dirt"
    },
    {
      "x": -9,
      "y": 6,
      "z": 6,
      "name": "Nat20_Force_Empty"
    },
    {
      "x": -9,
      "y": 0,
      "z": 7,
      "name": "Rock_Stone"
    },
    {
      "x": -9,
      "y": 1,
      "z": 7,
      "name": "Rock_Stone"
    },
    {
      "x": -9,
      "y": 2,
      "z": 7,
      "name": "Rock_Stone"
    },
    {
      "x": -9,
      "y": 3,
      "z": 7,
      "name": "Rock_Stone"
    },
    {
      "x": -9,
      "y": 4,
      "z": 7,
      "name": "Rock_Stone"
    },
    {
      "x": -9,
      "y": 5,
      "z": 7,
      "name": "Soil_Dirt"
    },
    {
      "x": -9,
      "y": 6,
      "z": 7,
      "name": "Nat20_Force_Empty"
    },
    {
      "x": -9,
      "y": 0,
      "z": 8,
      "name": "Soil_Grass"
    },
    {
      "x": -8,
      "y": 0,
      "z": -8,
      "name": "Rock_Stone"
    },
    {
      "x": -8,
      "y": 1,
      "z": -8,
      "name": "Rock_Stone"
    },
    {
      "x": -8,
      "y": 2,
      "z": -8,
      "name": "Rock_Stone"
    },
    {
      "x": -8,
      "y": 3,
      "z": -8,
      "name": "Rock_Stone"
    },
    {
      "x": -8,
      "y": 4,
      "z": -8,
      "name": "Soil_Dirt"
    },
    {
      "x": -8,
      "y": 5,
      "z": -8,
      "name": "Soil_Dirt"
    },
    {
      "x": -8,
      "y": 6,
      "z": -8,
      "name": "Soil_Grass"
    },
    {
      "x": -8,
      "y": 0,
      "z": -7,
      "name": "Rock_Quartzite"
    },
    {
      "x": -8,
      "y": 1,
      "z": -7,
      "name": "Rock_Quartzite_Cobble"
    },
    {
      "x": -8,
      "y": 2,
      "z": -7,
      "name": "Rock_Quartzite_Brick"
    },
    {
      "x": -8,
      "y": 3,
      "z": -7,
      "name": "Rock_Quartzite_Brick"
    },
    {
      "x": -8,
      "y": 4,
      "z": -7,
      "name": "Rock_Stone"
    },
    {
      "x": -8,
      "y": 5,
      "z": -7,
      "name": "Rock_Stone"
    },
    {
      "x": -8,
      "y": 6,
      "z": -7,
      "name": "Soil_Grass"
    },
    {
      "x": -8,
      "y": 0,
      "z": -6,
      "name": "Furniture_Ancient_Bookshelf"
    },
    {
      "x": -8,
      "y": 1,
      "z": -6,
      "name": "Furniture_Ancient_Bookshelf"
    },
    {
      "x": -8,
      "y": 2,
      "z": -6,
      "name": "Nat20_Force_Empty"
    },
    {
      "x": -8,
      "y": 3,
      "z": -6,
      "name": "Nat20_Force_Empty"
    },
    {
      "x": -8,
      "y": 4,
      "z": -6,
      "name": "Rock_Quartzite_Brick"
    },
    {
      "x": -8,
      "y": 5,
      "z": -6,
      "name": "Rock_Stone"
    },
    {
      "x": -8,
      "y": 6,
      "z": -6,
      "name": "Soil_Grass"
    },
    {
      "x": -8,
      "y": 7,
      "z": -6,
      "name": "Plant_Grass_Sharp_Short"
    },
    {
      "x": -8,
      "y": 0,
      "z": -5,
      "name": "Furniture_Crude_Stool"
    },
    {
      "x": -8,
      "y": 1,
      "z": -5,
      "name": "Nat20_Force_Empty"
    },
    {
      "x": -8,
      "y": 2,
      "z": -5,
      "name": "Nat20_Force_Empty"
    },
    {
      "x": -8,
      "y": 3,
      "z": -5,
      "name": "Nat20_Force_Empty"
    },
    {
      "x": -8,
      "y": 4,
      "z": -5,
      "name": "Nat20_Force_Empty"
    },
    {
      "x": -8,
      "y": 5,
      "z": -5,
      "name": "Rock_Quartzite_Brick"
    },
    {
      "x": -8,
      "y": 6,
      "z": -5,
      "name": "Soil_Grass"
    },
    {
      "x": -8,
      "y": 0,
      "z": -4,
      "name": "Nat20_Force_Empty"
    },
    {
      "x": -8,
      "y": 1,
      "z": -4,
      "name": "Nat20_Force_Empty"
    },
    {
      "x": -8,
      "y": 2,
      "z": -4,
      "name": "Nat20_Force_Empty"
    },
    {
      "x": -8,
      "y": 3,
      "z": -4,
      "name": "Nat20_Force_Empty"
    },
    {
      "x": -8,
      "y": 4,
      "z": -4,
      "name": "Nat20_Force_Empty"
    },
    {
      "x": -8,
      "y": 5,
      "z": -4,
      "name": "Rock_Quartzite_Brick"
    },
    {
      "x": -8,
      "y": 6,
      "z": -4,
      "name": "Soil_Grass"
    },
    {
      "x": -8,
      "y": 7,
      "z": -4,
      "name": "Plant_Grass_Sharp_Short"
    },
    {
      "x": -8,
      "y": 0,
      "z": -3,
      "name": "Nat20_Force_Empty"
    },
    {
      "x": -8,
      "y": 1,
      "z": -3,
      "name": "Nat20_Force_Empty"
    },
    {
      "x": -8,
      "y": 2,
      "z": -3,
      "name": "Nat20_Force_Empty"
    },
    {
      "x": -8,
      "y": 3,
      "z": -3,
      "name": "Nat20_Force_Empty"
    },
    {
      "x": -8,
      "y": 4,
      "z": -3,
      "name": "Nat20_Force_Empty"
    },
    {
      "x": -8,
      "y": 5,
      "z": -3,
      "name": "Rock_Quartzite_Brick"
    },
    {
      "x": -8,
      "y": 6,
      "z": -3,
      "name": "Soil_Grass"
    },
    {
      "x": -8,
      "y": 7,
      "z": -3,
      "name": "Plant_Grass_Sharp"
    },
    {
      "x": -8,
      "y": 8,
      "z": -3,
      "name": "Rock_Stone"
    },
    {
      "x": -8,
      "y": 0,
      "z": -2,
      "name": "Nat20_Force_Empty"
    },
    {
      "x": -8,
      "y": 1,
      "z": -2,
      "name": "Nat20_Force_Empty"
    },
    {
      "x": -8,
      "y": 2,
      "z": -2,
      "name": "Nat20_Force_Empty"
    },
    {
      "x": -8,
      "y": 3,
      "z": -2,
      "name": "Nat20_Force_Empty"
    },
    {
      "x": -8,
      "y": 4,
      "z": -2,
      "name": "Nat20_Force_Empty"
    },
    {
      "x": -8,
      "y": 5,
      "z": -2,
      "name": "Rock_Quartzite_Brick"
    },
    {
      "x": -8,
      "y": 6,
      "z": -2,
      "name": "Soil_Dirt"
    },
    {
      "x": -8,
      "y": 7,
      "z": -2,
      "name": "Rock_Stone"
    },
    {
      "x": -8,
      "y": 8,
      "z": -2,
      "name": "Rock_Stone"
    },
    {
      "x": -8,
      "y": 9,
      "z": -2,
      "name": "Rock_Stone"
    },
    {
      "x": -8,
      "y": 10,
      "z": -2,
      "name": "Rock_Stone"
    },
    {
      "x": -8,
      "y": 11,
      "z": -2,
      "name": "Rock_Stone"
    },
    {
      "x": -8,
      "y": 0,
      "z": -1,
      "name": "Nat20_Force_Empty"
    },
    {
      "x": -8,
      "y": 1,
      "z": -1,
      "name": "Nat20_Force_Empty"
    },
    {
      "x": -8,
      "y": 2,
      "z": -1,
      "name": "Nat20_Force_Empty"
    },
    {
      "x": -8,
      "y": 3,
      "z": -1,
      "name": "Nat20_Force_Empty"
    },
    {
      "x": -8,
      "y": 4,
      "z": -1,
      "name": "Nat20_Force_Empty"
    },
    {
      "x": -8,
      "y": 5,
      "z": -1,
      "name": "Rock_Quartzite_Brick"
    },
    {
      "x": -8,
      "y": 6,
      "z": -1,
      "name": "Soil_Grass"
    },
    {
      "x": -8,
      "y": 7,
      "z": -1,
      "name": "Plant_Grass_Sharp"
    },
    {
      "x": -8,
      "y": 8,
      "z": -1,
      "name": "Rock_Stone"
    },
    {
      "x": -8,
      "y": 9,
      "z": -1,
      "name": "Rock_Stone"
    },
    {
      "x": -8,
      "y": 10,
      "z": -1,
      "name": "Rock_Stone"
    },
    {
      "x": -8,
      "y": 11,
      "z": -1,
      "name": "Rock_Stone"
    },
    {
      "x": -8,
      "y": 0,
      "z": 0,
      "name": "Nat20_Force_Empty"
    },
    {
      "x": -8,
      "y": 1,
      "z": 0,
      "name": "Nat20_Force_Empty"
    },
    {
      "x": -8,
      "y": 2,
      "z": 0,
      "name": "Nat20_Force_Empty"
    },
    {
      "x": -8,
      "y": 3,
      "z": 0,
      "name": "Nat20_Force_Empty"
    },
    {
      "x": -8,
      "y": 4,
      "z": 0,
      "name": "Nat20_Force_Empty"
    },
    {
      "x": -8,
      "y": 5,
      "z": 0,
      "name": "Rock_Quartzite_Brick"
    },
    {
      "x": -8,
      "y": 6,
      "z": 0,
      "name": "Soil_Dirt"
    },
    {
      "x": -8,
      "y": 7,
      "z": 0,
      "name": "Rock_Stone"
    },
    {
      "x": -8,
      "y": 8,
      "z": 0,
      "name": "Rock_Stone"
    },
    {
      "x": -8,
      "y": 9,
      "z": 0,
      "name": "Rock_Stone"
    },
    {
      "x": -8,
      "y": 10,
      "z": 0,
      "name": "Rock_Stone"
    },
    {
      "x": -8,
      "y": 11,
      "z": 0,
      "name": "Rock_Stone"
    },
    {
      "x": -8,
      "y": 0,
      "z": 1,
      "name": "Nat20_Force_Empty"
    },
    {
      "x": -8,
      "y": 1,
      "z": 1,
      "name": "Nat20_Force_Empty"
    },
    {
      "x": -8,
      "y": 2,
      "z": 1,
      "name": "Nat20_Force_Empty"
    },
    {
      "x": -8,
      "y": 3,
      "z": 1,
      "name": "Nat20_Force_Empty"
    },
    {
      "x": -8,
      "y": 4,
      "z": 1,
      "name": "Nat20_Force_Empty"
    },
    {
      "x": -8,
      "y": 5,
      "z": 1,
      "name": "Rock_Quartzite_Brick"
    },
    {
      "x": -8,
      "y": 6,
      "z": 1,
      "name": "Soil_Grass"
    },
    {
      "x": -8,
      "y": 0,
      "z": 2,
      "name": "Nat20_Force_Empty"
    },
    {
      "x": -8,
      "y": 1,
      "z": 2,
      "name": "Nat20_Force_Empty"
    },
    {
      "x": -8,
      "y": 2,
      "z": 2,
      "name": "Nat20_Force_Empty"
    },
    {
      "x": -8,
      "y": 3,
      "z": 2,
      "name": "Nat20_Force_Empty"
    },
    {
      "x": -8,
      "y": 4,
      "z": 2,
      "name": "Nat20_Force_Empty"
    },
    {
      "x": -8,
      "y": 5,
      "z": 2,
      "name": "Rock_Quartzite_Brick"
    },
    {
      "x": -8,
      "y": 6,
      "z": 2,
      "name": "Soil_Grass"
    },
    {
      "x": -8,
      "y": 0,
      "z": 3,
      "name": "Nat20_Force_Empty"
    },
    {
      "x": -8,
      "y": 1,
      "z": 3,
      "name": "Nat20_Force_Empty"
    },
    {
      "x": -8,
      "y": 2,
      "z": 3,
      "name": "Nat20_Force_Empty"
    },
    {
      "x": -8,
      "y": 3,
      "z": 3,
      "name": "Nat20_Force_Empty"
    },
    {
      "x": -8,
      "y": 4,
      "z": 3,
      "name": "Nat20_Force_Empty"
    },
    {
      "x": -8,
      "y": 5,
      "z": 3,
      "name": "Rock_Quartzite_Brick"
    },
    {
      "x": -8,
      "y": 6,
      "z": 3,
      "name": "Soil_Grass"
    },
    {
      "x": -8,
      "y": 0,
      "z": 4,
      "name": "Rock_Stone"
    },
    {
      "x": -8,
      "y": 1,
      "z": 4,
      "name": "Rock_Stone"
    },
    {
      "x": -8,
      "y": 2,
      "z": 4,
      "name": "Plant_Moss_Rug_Green"
    },
    {
      "x": -8,
      "y": 3,
      "z": 4,
      "name": "Nat20_Force_Empty"
    },
    {
      "x": -8,
      "y": 4,
      "z": 4,
      "name": "Nat20_Force_Empty"
    },
    {
      "x": -8,
      "y": 5,
      "z": 4,
      "name": "Rock_Quartzite_Brick"
    },
    {
      "x": -8,
      "y": 6,
      "z": 4,
      "name": "Soil_Grass"
    },
    {
      "x": -8,
      "y": 0,
      "z": 5,
      "name": "Rock_Stone"
    },
    {
      "x": -8,
      "y": 1,
      "z": 5,
      "name": "Rock_Quartzite"
    },
    {
      "x": -8,
      "y": 2,
      "z": 5,
      "name": "Rock_Quartzite"
    },
    {
      "x": -8,
      "y": 3,
      "z": 5,
      "name": "Rock_Quartzite"
    },
    {
      "x": -8,
      "y": 4,
      "z": 5,
      "name": "Rock_Quartzite_Brick"
    },
    {
      "x": -8,
      "y": 5,
      "z": 5,
      "name": "Rock_Quartzite_Brick"
    },
    {
      "x": -8,
      "y": 6,
      "z": 5,
      "name": "Soil_Grass"
    },
    {
      "x": -8,
      "y": 0,
      "z": 6,
      "name": "Rock_Stone"
    },
    {
      "x": -8,
      "y": 1,
      "z": 6,
      "name": "Rock_Stone"
    },
    {
      "x": -8,
      "y": 2,
      "z": 6,
      "name": "Rock_Stone"
    },
    {
      "x": -8,
      "y": 3,
      "z": 6,
      "name": "Rock_Stone"
    },
    {
      "x": -8,
      "y": 4,
      "z": 6,
      "name": "Rock_Quartzite_Brick"
    },
    {
      "x": -8,
      "y": 5,
      "z": 6,
      "name": "Soil_Grass"
    },
    {
      "x": -8,
      "y": 6,
      "z": 6,
      "name": "Nat20_Force_Empty"
    },
    {
      "x": -8,
      "y": 0,
      "z": 7,
      "name": "Rock_Stone"
    },
    {
      "x": -8,
      "y": 1,
      "z": 7,
      "name": "Rock_Stone"
    },
    {
      "x": -8,
      "y": 2,
      "z": 7,
      "name": "Rock_Stone"
    },
    {
      "x": -8,
      "y": 3,
      "z": 7,
      "name": "Rock_Stone"
    },
    {
      "x": -8,
      "y": 4,
      "z": 7,
      "name": "Rock_Stone"
    },
    {
      "x": -8,
      "y": 5,
      "z": 7,
      "name": "Soil_Dirt"
    },
    {
      "x": -8,
      "y": 6,
      "z": 7,
      "name": "Nat20_Force_Empty"
    },
    {
      "x": -8,
      "y": 0,
      "z": 8,
      "name": "Soil_Grass"
    },
    {
      "x": -8,
      "y": 0,
      "z": 9,
      "name": "Soil_Grass"
    },
    {
      "x": -7,
      "y": 0,
      "z": -9,
      "name": "Rock_Stone"
    },
    {
      "x": -7,
      "y": 1,
      "z": -9,
      "name": "Rock_Stone"
    },
    {
      "x": -7,
      "y": 0,
      "z": -8,
      "name": "Rock_Stone"
    },
    {
      "x": -7,
      "y": 1,
      "z": -8,
      "name": "Rock_Stone"
    },
    {
      "x": -7,
      "y": 2,
      "z": -8,
      "name": "Rock_Stone"
    },
    {
      "x": -7,
      "y": 3,
      "z": -8,
      "name": "Rock_Stone"
    },
    {
      "x": -7,
      "y": 4,
      "z": -8,
      "name": "Soil_Dirt"
    },
    {
      "x": -7,
      "y": 5,
      "z": -8,
      "name": "Soil_Dirt"
    },
    {
      "x": -7,
      "y": 6,
      "z": -8,
      "name": "Soil_Grass"
    },
    {
      "x": -7,
      "y": 0,
      "z": -7,
      "name": "Rock_Quartzite"
    },
    {
      "x": -7,
      "y": 1,
      "z": -7,
      "name": "Rock_Quartzite"
    },
    {
      "x": -7,
      "y": 2,
      "z": -7,
      "name": "Rock_Quartzite_Cobble"
    },
    {
      "x": -7,
      "y": 3,
      "z": -7,
      "name": "Rock_Quartzite_Brick"
    },
    {
      "x": -7,
      "y": 4,
      "z": -7,
      "name": "Rock_Quartzite_Brick"
    },
    {
      "x": -7,
      "y": 5,
      "z": -7,
      "name": "Rock_Quartzite_Brick"
    },
    {
      "x": -7,
      "y": 6,
      "z": -7,
      "name": "Soil_Grass"
    },
    {
      "x": -7,
      "y": 0,
      "z": -6,
      "name": "Furniture_Ancient_Bookshelf"
    },
    {
      "x": -7,
      "y": 1,
      "z": -6,
      "name": "Furniture_Ancient_Bookshelf"
    },
    {
      "x": -7,
      "y": 2,
      "z": -6,
      "name": "Nat20_Force_Empty"
    },
    {
      "x": -7,
      "y": 3,
      "z": -6,
      "name": "Nat20_Force_Empty"
    },
    {
      "x": -7,
      "y": 4,
      "z": -6,
      "name": "Nat20_Force_Empty"
    },
    {
      "x": -7,
      "y": 5,
      "z": -6,
      "name": "Rock_Quartzite_Brick"
    },
    {
      "x": -7,
      "y": 6,
      "z": -6,
      "name": "Soil_Grass"
    },
    {
      "x": -7,
      "y": 0,
      "z": -5,
      "name": "Nat20_Force_Empty"
    },
    {
      "x": -7,
      "y": 1,
      "z": -5,
      "name": "Nat20_Force_Empty"
    },
    {
      "x": -7,
      "y": 2,
      "z": -5,
      "name": "Nat20_Force_Empty"
    },
    {
      "x": -7,
      "y": 3,
      "z": -5,
      "name": "Nat20_Force_Empty"
    },
    {
      "x": -7,
      "y": 4,
      "z": -5,
      "name": "Nat20_Force_Empty"
    },
    {
      "x": -7,
      "y": 5,
      "z": -5,
      "name": "Rock_Quartzite_Brick"
    },
    {
      "x": -7,
      "y": 6,
      "z": -5,
      "name": "Soil_Grass"
    },
    {
      "x": -7,
      "y": 0,
      "z": -4,
      "name": "Nat20_Force_Empty"
    },
    {
      "x": -7,
      "y": 1,
      "z": -4,
      "name": "Nat20_Force_Empty"
    },
    {
      "x": -7,
      "y": 2,
      "z": -4,
      "name": "Nat20_Force_Empty"
    },
    {
      "x": -7,
      "y": 3,
      "z": -4,
      "name": "Nat20_Force_Empty"
    },
    {
      "x": -7,
      "y": 4,
      "z": -4,
      "name": "Nat20_Force_Empty"
    },
    {
      "x": -7,
      "y": 5,
      "z": -4,
      "name": "Rock_Quartzite_Brick"
    },
    {
      "x": -7,
      "y": 6,
      "z": -4,
      "name": "Soil_Grass"
    },
    {
      "x": -7,
      "y": 0,
      "z": -3,
      "name": "Nat20_Force_Empty"
    },
    {
      "x": -7,
      "y": 1,
      "z": -3,
      "name": "Nat20_Force_Empty"
    },
    {
      "x": -7,
      "y": 2,
      "z": -3,
      "name": "Nat20_Force_Empty"
    },
    {
      "x": -7,
      "y": 3,
      "z": -3,
      "name": "Nat20_Force_Empty"
    },
    {
      "x": -7,
      "y": 4,
      "z": -3,
      "name": "Nat20_Force_Empty"
    },
    {
      "x": -7,
      "y": 5,
      "z": -3,
      "name": "Rock_Quartzite_Brick"
    },
    {
      "x": -7,
      "y": 6,
      "z": -3,
      "name": "Soil_Grass"
    },
    {
      "x": -7,
      "y": 0,
      "z": -2,
      "name": "Nat20_Force_Empty"
    },
    {
      "x": -7,
      "y": 1,
      "z": -2,
      "name": "Nat20_Force_Empty"
    },
    {
      "x": -7,
      "y": 2,
      "z": -2,
      "name": "Nat20_Force_Empty"
    },
    {
      "x": -7,
      "y": 3,
      "z": -2,
      "name": "Nat20_Force_Empty"
    },
    {
      "x": -7,
      "y": 4,
      "z": -2,
      "name": "Nat20_Force_Empty"
    },
    {
      "x": -7,
      "y": 5,
      "z": -2,
      "name": "Rock_Quartzite_Brick"
    },
    {
      "x": -7,
      "y": 6,
      "z": -2,
      "name": "Soil_Grass"
    },
    {
      "x": -7,
      "y": 0,
      "z": -1,
      "name": "Nat20_Force_Empty"
    },
    {
      "x": -7,
      "y": 1,
      "z": -1,
      "name": "Nat20_Force_Empty"
    },
    {
      "x": -7,
      "y": 2,
      "z": -1,
      "name": "Nat20_Force_Empty"
    },
    {
      "x": -7,
      "y": 3,
      "z": -1,
      "name": "Nat20_Force_Empty"
    },
    {
      "x": -7,
      "y": 4,
      "z": -1,
      "name": "Nat20_Force_Empty"
    },
    {
      "x": -7,
      "y": 5,
      "z": -1,
      "name": "Rock_Quartzite_Brick"
    },
    {
      "x": -7,
      "y": 6,
      "z": -1,
      "name": "Soil_Grass"
    },
    {
      "x": -7,
      "y": 0,
      "z": 0,
      "name": "Nat20_Force_Empty"
    },
    {
      "x": -7,
      "y": 1,
      "z": 0,
      "name": "Nat20_Force_Empty"
    },
    {
      "x": -7,
      "y": 2,
      "z": 0,
      "name": "Nat20_Force_Empty"
    },
    {
      "x": -7,
      "y": 3,
      "z": 0,
      "name": "Nat20_Force_Empty"
    },
    {
      "x": -7,
      "y": 4,
      "z": 0,
      "name": "Nat20_Force_Empty"
    },
    {
      "x": -7,
      "y": 5,
      "z": 0,
      "name": "Rock_Quartzite_Brick"
    },
    {
      "x": -7,
      "y": 6,
      "z": 0,
      "name": "Rock_Quartzite_Brick"
    },
    {
      "x": -7,
      "y": 7,
      "z": 0,
      "name": "Soil_Grass"
    },
    {
      "x": -7,
      "y": 0,
      "z": 1,
      "name": "Nat20_Force_Empty"
    },
    {
      "x": -7,
      "y": 1,
      "z": 1,
      "name": "Nat20_Force_Empty"
    },
    {
      "x": -7,
      "y": 2,
      "z": 1,
      "name": "Nat20_Force_Empty"
    },
    {
      "x": -7,
      "y": 3,
      "z": 1,
      "name": "Nat20_Force_Empty"
    },
    {
      "x": -7,
      "y": 4,
      "z": 1,
      "name": "Nat20_Force_Empty"
    },
    {
      "x": -7,
      "y": 5,
      "z": 1,
      "name": "Rock_Quartzite_Brick"
    },
    {
      "x": -7,
      "y": 6,
      "z": 1,
      "name": "Rock_Quartzite_Brick"
    },
    {
      "x": -7,
      "y": 7,
      "z": 1,
      "name": "Soil_Grass"
    },
    {
      "x": -7,
      "y": 0,
      "z": 2,
      "name": "Nat20_Force_Empty"
    },
    {
      "x": -7,
      "y": 1,
      "z": 2,
      "name": "Nat20_Force_Empty"
    },
    {
      "x": -7,
      "y": 2,
      "z": 2,
      "name": "Nat20_Force_Empty"
    },
    {
      "x": -7,
      "y": 3,
      "z": 2,
      "name": "Nat20_Force_Empty"
    },
    {
      "x": -7,
      "y": 4,
      "z": 2,
      "name": "Nat20_Force_Empty"
    },
    {
      "x": -7,
      "y": 5,
      "z": 2,
      "name": "Rock_Quartzite_Brick"
    },
    {
      "x": -7,
      "y": 6,
      "z": 2,
      "name": "Rock_Quartzite_Brick"
    },
    {
      "x": -7,
      "y": 7,
      "z": 2,
      "name": "Soil_Grass"
    },
    {
      "x": -7,
      "y": 0,
      "z": 3,
      "name": "Nat20_Force_Empty"
    },
    {
      "x": -7,
      "y": 1,
      "z": 3,
      "name": "Nat20_Force_Empty"
    },
    {
      "x": -7,
      "y": 2,
      "z": 3,
      "name": "Nat20_Force_Empty"
    },
    {
      "x": -7,
      "y": 3,
      "z": 3,
      "name": "Nat20_Force_Empty"
    },
    {
      "x": -7,
      "y": 4,
      "z": 3,
      "name": "Nat20_Force_Empty"
    },
    {
      "x": -7,
      "y": 5,
      "z": 3,
      "name": "Rock_Quartzite_Brick"
    },
    {
      "x": -7,
      "y": 6,
      "z": 3,
      "name": "Rock_Quartzite_Brick"
    },
    {
      "x": -7,
      "y": 7,
      "z": 3,
      "name": "Soil_Grass"
    },
    {
      "x": -7,
      "y": 0,
      "z": 4,
      "name": "Rock_Stone"
    },
    {
      "x": -7,
      "y": 1,
      "z": 4,
      "name": "Nat20_Force_Empty"
    },
    {
      "x": -7,
      "y": 2,
      "z": 4,
      "name": "Nat20_Force_Empty"
    },
    {
      "x": -7,
      "y": 3,
      "z": 4,
      "name": "Nat20_Force_Empty"
    },
    {
      "x": -7,
      "y": 4,
      "z": 4,
      "name": "Rock_Quartzite_Brick"
    },
    {
      "x": -7,
      "y": 5,
      "z": 4,
      "name": "Rock_Quartzite_Brick"
    },
    {
      "x": -7,
      "y": 6,
      "z": 4,
      "name": "Rock_Stone"
    },
    {
      "x": -7,
      "y": 7,
      "z": 4,
      "name": "Soil_Grass"
    },
    {
      "x": -7,
      "y": 0,
      "z": 5,
      "name": "Rock_Quartzite"
    },
    {
      "x": -7,
      "y": 1,
      "z": 5,
      "name": "Rock_Quartzite"
    },
    {
      "x": -7,
      "y": 2,
      "z": 5,
      "name": "Rock_Quartzite"
    },
    {
      "x": -7,
      "y": 3,
      "z": 5,
      "name": "Rock_Quartzite_Brick"
    },
    {
      "x": -7,
      "y": 4,
      "z": 5,
      "name": "Rock_Quartzite_Brick"
    },
    {
      "x": -7,
      "y": 5,
      "z": 5,
      "name": "Rock_Quartzite_Brick"
    },
    {
      "x": -7,
      "y": 6,
      "z": 5,
      "name": "Rock_Stone"
    },
    {
      "x": -7,
      "y": 0,
      "z": 6,
      "name": "Rock_Stone"
    },
    {
      "x": -7,
      "y": 1,
      "z": 6,
      "name": "Rock_Stone"
    },
    {
      "x": -7,
      "y": 2,
      "z": 6,
      "name": "Rock_Stone"
    },
    {
      "x": -7,
      "y": 3,
      "z": 6,
      "name": "Rock_Stone"
    },
    {
      "x": -7,
      "y": 4,
      "z": 6,
      "name": "Rock_Stone"
    },
    {
      "x": -7,
      "y": 5,
      "z": 6,
      "name": "Rock_Stone"
    },
    {
      "x": -7,
      "y": 6,
      "z": 6,
      "name": "Rock_Stone"
    },
    {
      "x": -7,
      "y": 0,
      "z": 7,
      "name": "Rock_Stone"
    },
    {
      "x": -7,
      "y": 1,
      "z": 7,
      "name": "Rock_Stone"
    },
    {
      "x": -7,
      "y": 2,
      "z": 7,
      "name": "Rock_Stone"
    },
    {
      "x": -7,
      "y": 3,
      "z": 7,
      "name": "Rock_Stone"
    },
    {
      "x": -7,
      "y": 4,
      "z": 7,
      "name": "Rock_Stone"
    },
    {
      "x": -7,
      "y": 5,
      "z": 7,
      "name": "Rock_Stone"
    },
    {
      "x": -7,
      "y": 6,
      "z": 7,
      "name": "Nat20_Force_Empty"
    },
    {
      "x": -7,
      "y": 0,
      "z": 8,
      "name": "Soil_Grass"
    },
    {
      "x": -7,
      "y": 0,
      "z": 9,
      "name": "Soil_Grass"
    },
    {
      "x": -6,
      "y": 0,
      "z": -9,
      "name": "Rock_Stone"
    },
    {
      "x": -6,
      "y": 1,
      "z": -9,
      "name": "Rock_Stone"
    },
    {
      "x": -6,
      "y": 2,
      "z": -9,
      "name": "Rock_Stone"
    },
    {
      "x": -6,
      "y": 3,
      "z": -9,
      "name": "Rock_Stone"
    },
    {
      "x": -6,
      "y": 4,
      "z": -9,
      "name": "Soil_Dirt"
    },
    {
      "x": -6,
      "y": 5,
      "z": -9,
      "name": "Soil_Grass"
    },
    {
      "x": -6,
      "y": 0,
      "z": -8,
      "name": "Rock_Stone"
    },
    {
      "x": -6,
      "y": 1,
      "z": -8,
      "name": "Rock_Stone"
    },
    {
      "x": -6,
      "y": 2,
      "z": -8,
      "name": "Rock_Stone"
    },
    {
      "x": -6,
      "y": 3,
      "z": -8,
      "name": "Rock_Stone"
    },
    {
      "x": -6,
      "y": 4,
      "z": -8,
      "name": "Rock_Stone"
    },
    {
      "x": -6,
      "y": 5,
      "z": -8,
      "name": "Rock_Stone"
    },
    {
      "x": -6,
      "y": 6,
      "z": -8,
      "name": "Soil_Grass"
    },
    {
      "x": -6,
      "y": 0,
      "z": -7,
      "name": "Rock_Quartzite"
    },
    {
      "x": -6,
      "y": 1,
      "z": -7,
      "name": "Rock_Quartzite"
    },
    {
      "x": -6,
      "y": 2,
      "z": -7,
      "name": "Rock_Quartzite_Cobble"
    },
    {
      "x": -6,
      "y": 3,
      "z": -7,
      "name": "Rock_Quartzite_Brick"
    },
    {
      "x": -6,
      "y": 4,
      "z": -7,
      "name": "Rock_Quartzite_Brick"
    },
    {
      "x": -6,
      "y": 5,
      "z": -7,
      "name": "Rock_Quartzite_Brick"
    },
    {
      "x": -6,
      "y": 6,
      "z": -7,
      "name": "Soil_Grass"
    },
    {
      "x": -6,
      "y": 0,
      "z": -6,
      "name": "Furniture_Ancient_Bookshelf"
    },
    {
      "x": -6,
      "y": 1,
      "z": -6,
      "name": "Nat20_Force_Empty"
    },
    {
      "x": -6,
      "y": 2,
      "z": -6,
      "name": "Nat20_Force_Empty"
    },
    {
      "x": -6,
      "y": 3,
      "z": -6,
      "name": "Nat20_Force_Empty"
    },
    {
      "x": -6,
      "y": 4,
      "z": -6,
      "name": "Nat20_Force_Empty"
    },
    {
      "x": -6,
      "y": 5,
      "z": -6,
      "name": "Rock_Quartzite_Brick"
    },
    {
      "x": -6,
      "y": 6,
      "z": -6,
      "name": "Soil_Grass"
    },
    {
      "x": -6,
      "y": 0,
      "z": -5,
      "name": "Nat20_Force_Empty"
    },
    {
      "x": -6,
      "y": 1,
      "z": -5,
      "name": "Nat20_Force_Empty"
    },
    {
      "x": -6,
      "y": 2,
      "z": -5,
      "name": "Nat20_Force_Empty"
    },
    {
      "x": -6,
      "y": 3,
      "z": -5,
      "name": "Nat20_Force_Empty"
    },
    {
      "x": -6,
      "y": 4,
      "z": -5,
      "name": "Nat20_Force_Empty"
    },
    {
      "x": -6,
      "y": 5,
      "z": -5,
      "name": "Rock_Quartzite_Brick"
    },
    {
      "x": -6,
      "y": 6,
      "z": -5,
      "name": "Soil_Grass"
    },
    {
      "x": -6,
      "y": 0,
      "z": -4,
      "name": "Nat20_Force_Empty"
    },
    {
      "x": -6,
      "y": 1,
      "z": -4,
      "name": "Nat20_Force_Empty"
    },
    {
      "x": -6,
      "y": 2,
      "z": -4,
      "name": "Nat20_Force_Empty"
    },
    {
      "x": -6,
      "y": 3,
      "z": -4,
      "name": "Nat20_Force_Empty"
    },
    {
      "x": -6,
      "y": 4,
      "z": -4,
      "name": "Nat20_Force_Empty"
    },
    {
      "x": -6,
      "y": 5,
      "z": -4,
      "name": "Rock_Quartzite_Brick"
    },
    {
      "x": -6,
      "y": 6,
      "z": -4,
      "name": "Soil_Grass"
    },
    {
      "x": -6,
      "y": 7,
      "z": -4,
      "name": "Plant_Grass_Sharp_Short"
    },
    {
      "x": -6,
      "y": 0,
      "z": -3,
      "name": "Nat20_Force_Empty"
    },
    {
      "x": -6,
      "y": 1,
      "z": -3,
      "name": "Nat20_Force_Empty"
    },
    {
      "x": -6,
      "y": 2,
      "z": -3,
      "name": "Nat20_Force_Empty"
    },
    {
      "x": -6,
      "y": 3,
      "z": -3,
      "name": "Nat20_Force_Empty"
    },
    {
      "x": -6,
      "y": 4,
      "z": -3,
      "name": "Nat20_Force_Empty"
    },
    {
      "x": -6,
      "y": 5,
      "z": -3,
      "name": "Rock_Quartzite_Brick"
    },
    {
      "x": -6,
      "y": 6,
      "z": -3,
      "name": "Rock_Quartzite_Brick"
    },
    {
      "x": -6,
      "y": 7,
      "z": -3,
      "name": "Soil_Grass"
    },
    {
      "x": -6,
      "y": 0,
      "z": -2,
      "name": "Nat20_Force_Empty"
    },
    {
      "x": -6,
      "y": 1,
      "z": -2,
      "name": "Nat20_Force_Empty"
    },
    {
      "x": -6,
      "y": 2,
      "z": -2,
      "name": "Nat20_Force_Empty"
    },
    {
      "x": -6,
      "y": 3,
      "z": -2,
      "name": "Nat20_Force_Empty"
    },
    {
      "x": -6,
      "y": 4,
      "z": -2,
      "name": "Nat20_Force_Empty"
    },
    {
      "x": -6,
      "y": 5,
      "z": -2,
      "name": "Rock_Quartzite_Brick"
    },
    {
      "x": -6,
      "y": 6,
      "z": -2,
      "name": "Rock_Quartzite_Brick"
    },
    {
      "x": -6,
      "y": 7,
      "z": -2,
      "name": "Soil_Grass"
    },
    {
      "x": -6,
      "y": 0,
      "z": -1,
      "name": "Rock_Quartzite_Brick"
    },
    {
      "x": -6,
      "y": 1,
      "z": -1,
      "name": "Rock_Quartzite_Brick"
    },
    {
      "x": -6,
      "y": 2,
      "z": -1,
      "name": "Plant_Moss_Rug_Green"
    },
    {
      "x": -6,
      "y": 3,
      "z": -1,
      "name": "Nat20_Force_Empty"
    },
    {
      "x": -6,
      "y": 4,
      "z": -1,
      "name": "Rock_Quartzite_Brick"
    },
    {
      "x": -6,
