{
  "version": 8,
  "blockIdVersion": 11,
  "anchorX": 0,
  "anchorY": 0,
  "anchorZ": 0,
  "blocks": [
    {
      "x": -16,
      "y": 0,
      "z": -11,
      "name": "Rock_Basalt"
    },
    {
      "x": -16,
      "y": 1,
      "z": -11,
      "name": "Rock_Basalt"
    },
    {
      "x": -16,
      "y": 2,
      "z": -11,
      "name": "Rock_Basalt"
    },
    {
      "x": -16,
      "y": 3,
      "z": -11,
      "name": "Rock_Basalt"
    },
    {
      "x": -16,
      "y": 4,
      "z": -11,
      "name": "Rock_Basalt"
    },
    {
      "x": -16,
      "y": 5,
      "z": -11,
      "name": "Rock_Basalt"
    },
    {
      "x": -16,
      "y": 6,
      "z": -11,
      "name": "Rock_Basalt"
    },
    {
      "x": -16,
      "y": 7,
      "z": -11,
      "name": "Rock_Basalt"
    },
    {
      "x": -16,
      "y": 8,
      "z": -11,
      "name": "Wood_Deadwood_Planks"
    },
    {
      "x": -16,
      "y": 9,
      "z": -11,
      "name": "Wood_Deadwood_Planks"
    },
    {
      "x": -16,
      "y": 10,
      "z": -11,
      "name": "Wood_Softwood_Planks"
    },
    {
      "x": -16,
      "y": 0,
      "z": -10,
      "name": "Rock_Basalt"
    },
    {
      "x": -16,
      "y": 1,
      "z": -10,
      "name": "Rock_Basalt"
    },
    {
      "x": -16,
      "y": 2,
      "z": -10,
      "name": "Rock_Basalt"
    },
    {
      "x": -16,
      "y": 3,
      "z": -10,
      "name": "Rock_Basalt"
    },
    {
      "x": -16,
      "y": 4,
      "z": -10,
      "name": "Rock_Basalt"
    },
    {
      "x": -16,
      "y": 5,
      "z": -10,
      "name": "Rock_Basalt"
    },
    {
      "x": -16,
      "y": 6,
      "z": -10,
      "name": "Plant_Moss_Block_Green"
    },
    {
      "x": -16,
      "y": 7,
      "z": -10,
      "name": "Wood_Deadwood_Planks_Half",
      "rotation": 4
    },
    {
      "x": -16,
      "y": 8,
      "z": -10,
      "name": "Wood_Deadwood_Planks_Half",
      "rotation": 4
    },
    {
      "x": -16,
      "y": 9,
      "z": -10,
      "name": "Wood_Softwood_Planks_Half",
      "rotation": 4
    },
    {
      "x": -16,
      "y": 10,
      "z": -10,
      "name": "Wood_Softwood_Planks_Half",
      "rotation": 4
    },
    {
      "x": -16,
      "y": 0,
      "z": -9,
      "name": "Rock_Basalt"
    },
    {
      "x": -16,
      "y": 1,
      "z": -9,
      "name": "Rock_Basalt"
    },
    {
      "x": -16,
      "y": 2,
      "z": -9,
      "name": "Rock_Basalt"
    },
    {
      "x": -16,
      "y": 3,
      "z": -9,
      "name": "Rock_Basalt"
    },
    {
      "x": -16,
      "y": 4,
      "z": -9,
      "name": "Rock_Basalt"
    },
    {
      "x": -16,
      "y": 5,
      "z": -9,
      "name": "Rock_Basalt"
    },
    {
      "x": -16,
      "y": 6,
      "z": -9,
      "name": "Plant_Moss_Block_Green"
    },
    {
      "x": -16,
      "y": 7,
      "z": -9,
      "name": "Nat20_Force_Empty"
    },
    {
      "x": -16,
      "y": 8,
      "z": -9,
      "name": "Nat20_Force_Empty"
    },
    {
      "x": -16,
      "y": 9,
      "z": -9,
      "name": "Nat20_Force_Empty"
    },
    {
      "x": -16,
      "y": 10,
      "z": -9,
      "name": "Nat20_Force_Empty"
    },
    {
      "x": -16,
      "y": 0,
      "z": -8,
      "name": "Rock_Stone"
    },
    {
      "x": -16,
      "y": 1,
      "z": -8,
      "name": "Rock_Basalt"
    },
    {
      "x": -16,
      "y": 2,
      "z": -8,
      "name": "Rock_Basalt"
    },
    {
      "x": -16,
      "y": 3,
      "z": -8,
      "name": "Rock_Basalt"
    },
    {
      "x": -16,
      "y": 4,
      "z": -8,
      "name": "Rock_Basalt"
    },
    {
      "x": -16,
      "y": 5,
      "z": -8,
      "name": "Rock_Basalt"
    },
    {
      "x": -16,
      "y": 6,
      "z": -8,
      "name": "Nat20_Force_Empty"
    },
    {
      "x": -16,
      "y": 7,
      "z": -8,
      "name": "Nat20_Force_Empty"
    },
    {
      "x": -16,
      "y": 8,
      "z": -8,
      "name": "Nat20_Force_Empty"
    },
    {
      "x": -16,
      "y": 9,
      "z": -8,
      "name": "Nat20_Force_Empty"
    },
    {
      "x": -16,
      "y": 10,
      "z": -8,
      "name": "Nat20_Force_Empty"
    },
    {
      "x": -16,
      "y": 0,
      "z": -7,
      "name": "Rock_Stone"
    },
    {
      "x": -16,
      "y": 1,
      "z": -7,
      "name": "Rock_Basalt"
    },
    {
      "x": -16,
      "y": 2,
      "z": -7,
      "name": "Rock_Basalt"
    },
    {
      "x": -16,
      "y": 3,
      "z": -7,
      "name": "Rock_Basalt"
    },
    {
      "x": -16,
      "y": 4,
      "z": -7,
      "name": "Rock_Basalt"
    },
    {
      "x": -16,
      "y": 5,
      "z": -7,
      "name": "Nat20_Force_Empty"
    },
    {
      "x": -16,
      "y": 6,
      "z": -7,
      "name": "Nat20_Force_Empty"
    },
    {
      "x": -16,
      "y": 7,
      "z": -7,
      "name": "Nat20_Force_Empty"
    },
    {
      "x": -16,
      "y": 8,
      "z": -7,
      "name": "Nat20_Force_Empty"
    },
    {
      "x": -16,
      "y": 9,
      "z": -7,
      "name": "Nat20_Force_Empty"
    },
    {
      "x": -16,
      "y": 10,
      "z": -7,
      "name": "Nat20_Force_Empty"
    },
    {
      "x": -16,
      "y": 0,
      "z": -6,
      "name": "Rock_Stone"
    },
    {
      "x": -16,
      "y": 1,
      "z": -6,
      "name": "Rock_Basalt"
    },
    {
      "x": -16,
      "y": 2,
      "z": -6,
      "name": "Rock_Basalt"
    },
    {
      "x": -16,
      "y": 3,
      "z": -6,
      "name": "Rock_Basalt"
    },
    {
      "x": -16,
      "y": 4,
      "z": -6,
      "name": "Rock_Basalt"
    },
    {
      "x": -16,
      "y": 5,
      "z": -6,
      "name": "Rock_Basalt"
    },
    {
      "x": -16,
      "y": 6,
      "z": -6,
      "name": "Rock_Basalt"
    },
    {
      "x": -16,
      "y": 7,
      "z": -6,
      "name": "Nat20_Force_Empty"
    },
    {
      "x": -16,
      "y": 8,
      "z": -6,
      "name": "Nat20_Force_Empty"
    },
    {
      "x": -16,
      "y": 9,
      "z": -6,
      "name": "Nat20_Force_Empty"
    },
    {
      "x": -16,
      "y": 10,
      "z": -6,
      "name": "Nat20_Force_Empty"
    },
    {
      "x": -16,
      "y": 0,
      "z": -5,
      "name": "Rock_Basalt"
    },
    {
      "x": -16,
      "y": 1,
      "z": -5,
      "name": "Rock_Basalt"
    },
    {
      "x": -16,
      "y": 2,
      "z": -5,
      "name": "Rock_Basalt"
    },
    {
      "x": -16,
      "y": 3,
      "z": -5,
      "name": "Rock_Basalt"
    },
    {
      "x": -16,
      "y": 4,
      "z": -5,
      "name": "Rock_Basalt"
    },
    {
      "x": -16,
      "y": 5,
      "z": -5,
      "name": "Rock_Basalt"
    },
    {
      "x": -16,
      "y": 6,
      "z": -5,
      "name": "Rock_Basalt"
    },
    {
      "x": -16,
      "y": 7,
      "z": -5,
      "name": "Nat20_Force_Empty"
    },
    {
      "x": -16,
      "y": 8,
      "z": -5,
      "name": "Nat20_Force_Empty"
    },
    {
      "x": -16,
      "y": 9,
      "z": -5,
      "name": "Nat20_Force_Empty"
    },
    {
      "x": -16,
      "y": 10,
      "z": -5,
      "name": "Plant_Moss_Wall_Green",
      "rotation": 2
    },
    {
      "x": -16,
      "y": 0,
      "z": -4,
      "name": "Rock_Basalt"
    },
    {
      "x": -16,
      "y": 1,
      "z": -4,
      "name": "Rock_Basalt"
    },
    {
      "x": -16,
      "y": 2,
      "z": -4,
      "name": "Nat20_Force_Empty"
    },
    {
      "x": -16,
      "y": 3,
      "z": -4,
      "name": "Nat20_Force_Empty"
    },
    {
      "x": -16,
      "y": 4,
      "z": -4,
      "name": "Nat20_Force_Empty"
    },
    {
      "x": -16,
      "y": 5,
      "z": -4,
      "name": "Rock_Basalt"
    },
    {
      "x": -16,
      "y": 6,
      "z": -4,
      "name": "Rock_Basalt"
    },
    {
      "x": -16,
      "y": 7,
      "z": -4,
      "name": "Plant_Moss_Block_Green"
    },
    {
      "x": -16,
      "y": 8,
      "z": -4,
      "name": "Plant_Crop_Mushroom_Shelve_Green"
    },
    {
      "x": -16,
      "y": 9,
      "z": -4,
      "name": "Nat20_Force_Empty"
    },
    {
      "x": -16,
      "y": 10,
      "z": -4,
      "name": "Nat20_Force_Empty"
    },
    {
      "x": -16,
      "y": 0,
      "z": -3,
      "name": "Rock_Basalt"
    },
    {
      "x": -16,
      "y": 1,
      "z": -3,
      "name": "Nat20_Force_Empty"
    },
    {
      "x": -16,
      "y": 2,
      "z": -3,
      "name": "Nat20_Force_Empty"
    },
    {
      "x": -16,
      "y": 3,
      "z": -3,
      "name": "Nat20_Force_Empty"
    },
    {
      "x": -16,
      "y": 4,
      "z": -3,
      "name": "Nat20_Force_Empty"
    },
    {
      "x": -16,
      "y": 5,
      "z": -3,
      "name": "Rock_Basalt"
    },
    {
      "x": -16,
      "y": 6,
      "z": -3,
      "name": "Rock_Basalt"
    },
    {
      "x": -16,
      "y": 7,
      "z": -3,
      "name": "Plant_Moss_Block_Green"
    },
    {
      "x": -16,
      "y": 8,
      "z": -3,
      "name": "Plant_Moss_Block_Green"
    },
    {
      "x": -16,
      "y": 9,
      "z": -3,
      "name": "Plant_Moss_Block_Green"
    },
    {
      "x": -16,
      "y": 10,
      "z": -3,
      "name": "Plant_Moss_Rug_Green"
    },
    {
      "x": -16,
      "y": 0,
      "z": -2,
      "name": "Wood_Deadwood_Planks"
    },
    {
      "x": -16,
      "y": 1,
      "z": -2,
      "name": "Nat20_Force_Empty"
    },
    {
      "x": -16,
      "y": 2,
      "z": -2,
      "name": "Nat20_Force_Empty"
    },
    {
      "x": -16,
      "y": 3,
      "z": -2,
      "name": "Nat20_Force_Empty"
    },
    {
      "x": -16,
      "y": 4,
      "z": -2,
      "name": "Nat20_Force_Empty"
    },
    {
      "x": -16,
      "y": 5,
      "z": -2,
      "name": "Rock_Basalt"
    },
    {
      "x": -16,
      "y": 6,
      "z": -2,
      "name": "Rock_Basalt"
    },
    {
      "x": -16,
      "y": 7,
      "z": -2,
      "name": "Rock_Basalt"
    },
    {
      "x": -16,
      "y": 8,
      "z": -2,
      "name": "Rock_Basalt"
    },
    {
      "x": -16,
      "y": 9,
      "z": -2,
      "name": "Rock_Basalt"
    },
    {
      "x": -16,
      "y": 10,
      "z": -2,
      "name": "Plant_Moss_Block_Green"
    },
    {
      "x": -16,
      "y": 0,
      "z": -1,
      "name": "Wood_Deadwood_Planks"
    },
    {
      "x": -16,
      "y": 1,
      "z": -1,
      "name": "Nat20_Force_Empty"
    },
    {
      "x": -16,
      "y": 2,
      "z": -1,
      "name": "Nat20_Force_Empty"
    },
    {
      "x": -16,
      "y": 3,
      "z": -1,
      "name": "Nat20_Force_Empty"
    },
    {
      "x": -16,
      "y": 4,
      "z": -1,
      "name": "Nat20_Force_Empty"
    },
    {
      "x": -16,
      "y": 5,
      "z": -1,
      "name": "Rock_Basalt"
    },
    {
      "x": -16,
      "y": 6,
      "z": -1,
      "name": "Rock_Stone"
    },
    {
      "x": -16,
      "y": 7,
      "z": -1,
      "name": "Rock_Basalt"
    },
    {
      "x": -16,
      "y": 8,
      "z": -1,
      "name": "Rock_Basalt"
    },
    {
      "x": -16,
      "y": 9,
      "z": -1,
      "name": "Rock_Basalt"
    },
    {
      "x": -16,
      "y": 10,
      "z": -1,
      "name": "Rock_Basalt"
    },
    {
      "x": -16,
      "y": 0,
      "z": 0,
      "name": "Rock_Basalt"
    },
    {
      "x": -16,
      "y": 1,
      "z": 0,
      "name": "Nat20_Force_Empty"
    },
    {
      "x": -16,
      "y": 2,
      "z": 0,
      "name": "Nat20_Force_Empty"
    },
    {
      "x": -16,
      "y": 3,
      "z": 0,
      "name": "Nat20_Force_Empty"
    },
    {
      "x": -16,
      "y": 4,
      "z": 0,
      "name": "Nat20_Force_Empty"
    },
    {
      "x": -16,
      "y": 5,
      "z": 0,
      "name": "Rock_Basalt"
    },
    {
      "x": -16,
      "y": 6,
      "z": 0,
      "name": "Rock_Stone"
    },
    {
      "x": -16,
      "y": 7,
      "z": 0,
      "name": "Rock_Basalt"
    },
    {
      "x": -16,
      "y": 8,
      "z": 0,
      "name": "Rock_Basalt"
    },
    {
      "x": -16,
      "y": 9,
      "z": 0,
      "name": "Rock_Basalt"
    },
    {
      "x": -16,
      "y": 10,
      "z": 0,
      "name": "Rock_Basalt"
    },
    {
      "x": -16,
      "y": 0,
      "z": 1,
      "name": "Rock_Basalt"
    },
    {
      "x": -16,
      "y": 1,
      "z": 1,
      "name": "Nat20_Force_Empty"
    },
    {
      "x": -16,
      "y": 2,
      "z": 1,
      "name": "Nat20_Force_Empty"
    },
    {
      "x": -16,
      "y": 3,
      "z": 1,
      "name": "Nat20_Force_Empty"
    },
    {
      "x": -16,
      "y": 4,
      "z": 1,
      "name": "Nat20_Force_Empty"
    },
    {
      "x": -16,
      "y": 5,
      "z": 1,
      "name": "Rock_Basalt"
    },
    {
      "x": -16,
      "y": 6,
      "z": 1,
      "name": "Rock_Stone"
    },
    {
      "x": -16,
      "y": 7,
      "z": 1,
      "name": "Rock_Basalt"
    },
    {
      "x": -16,
      "y": 8,
      "z": 1,
      "name": "Plant_Moss_Block_Green"
    },
    {
      "x": -16,
      "y": 9,
      "z": 1,
      "name": "Plant_Moss_Block_Green"
    },
    {
      "x": -16,
      "y": 10,
      "z": 1,
      "name": "Nat20_Force_Empty"
    },
    {
      "x": -16,
      "y": 0,
      "z": 2,
      "name": "Rock_Basalt"
    },
    {
      "x": -16,
      "y": 1,
      "z": 2,
      "name": "Furniture_Village_Crate"
    },
    {
      "x": -16,
      "y": 2,
      "z": 2,
      "name": "Plant_Crop_Mushroom_Flatcap_Green"
    },
    {
      "x": -16,
      "y": 3,
      "z": 2,
      "name": "Nat20_Force_Empty"
    },
    {
      "x": -16,
      "y": 4,
      "z": 2,
      "name": "Nat20_Force_Empty"
    },
    {
      "x": -16,
      "y": 5,
      "z": 2,
      "name": "Rock_Basalt"
    },
    {
      "x": -16,
      "y": 6,
      "z": 2,
      "name": "Rock_Basalt"
    },
    {
      "x": -16,
      "y": 7,
      "z": 2,
      "name": "Rock_Basalt"
    },
    {
      "x": -16,
      "y": 8,
      "z": 2,
      "name": "Plant_Moss_Rug_Green"
    },
    {
      "x": -16,
      "y": 9,
      "z": 2,
      "name": "Nat20_Force_Empty"
    },
    {
      "x": -16,
      "y": 10,
      "z": 2,
      "name": "Nat20_Force_Empty"
    },
    {
      "x": -16,
      "y": 0,
      "z": 3,
      "name": "Rock_Basalt"
    },
    {
      "x": -16,
      "y": 1,
      "z": 3,
      "name": "Rock_Basalt"
    },
    {
      "x": -16,
      "y": 2,
      "z": 3,
      "name": "Furniture_Village_Crate"
    },
    {
      "x": -16,
      "y": 3,
      "z": 3,
      "name": "Nat20_Force_Empty"
    },
    {
      "x": -16,
      "y": 4,
      "z": 3,
      "name": "Rock_Basalt"
    },
    {
      "x": -16,
      "y": 5,
      "z": 3,
      "name": "Rock_Basalt"
    },
    {
      "x": -16,
      "y": 6,
      "z": 3,
      "name": "Rock_Basalt"
    },
    {
      "x": -16,
      "y": 7,
      "z": 3,
      "name": "Rock_Basalt"
    },
    {
      "x": -16,
      "y": 8,
      "z": 3,
      "name": "Nat20_Force_Empty"
    },
    {
      "x": -16,
      "y": 9,
      "z": 3,
      "name": "Nat20_Force_Empty"
    },
    {
      "x": -16,
      "y": 10,
      "z": 3,
      "name": "Nat20_Force_Empty"
    },
    {
      "x": -16,
      "y": 0,
      "z": 4,
      "name": "Rock_Basalt"
    },
    {
      "x": -16,
      "y": 1,
      "z": 4,
      "name": "Rock_Basalt"
    },
    {
      "x": -16,
      "y": 2,
      "z": 4,
      "name": "Rock_Basalt"
    },
    {
      "x": -16,
      "y": 3,
      "z": 4,
      "name": "Rock_Basalt"
    },
    {
      "x": -16,
      "y": 4,
      "z": 4,
      "name": "Rock_Basalt"
    },
    {
      "x": -16,
      "y": 5,
      "z": 4,
      "name": "Rock_Basalt"
    },
    {
      "x": -16,
      "y": 6,
      "z": 4,
      "name": "Rock_Basalt"
    },
    {
      "x": -16,
      "y": 7,
      "z": 4,
      "name": "Nat20_Force_Empty"
    },
    {
      "x": -16,
      "y": 8,
      "z": 4,
      "name": "Nat20_Force_Empty"
    },
    {
      "x": -16,
      "y": 9,
      "z": 4,
      "name": "Nat20_Force_Empty"
    },
    {
      "x": -16,
      "y": 10,
      "z": 4,
      "name": "Nat20_Force_Empty"
    },
    {
      "x": -16,
      "y": 0,
      "z": 5,
      "name": "Rock_Basalt"
    },
    {
      "x": -16,
      "y": 1,
      "z": 5,
      "name": "Rock_Basalt"
    },
    {
      "x": -16,
      "y": 2,
      "z": 5,
      "name": "Rock_Basalt"
    },
    {
      "x": -16,
      "y": 3,
      "z": 5,
      "name": "Rock_Basalt"
    },
    {
      "x": -16,
      "y": 4,
      "z": 5,
      "name": "Rock_Basalt"
    },
    {
      "x": -16,
      "y": 5,
      "z": 5,
      "name": "Nat20_Force_Empty"
    },
    {
      "x": -16,
      "y": 6,
      "z": 5,
      "name": "Nat20_Force_Empty"
    },
    {
      "x": -16,
      "y": 7,
      "z": 5,
      "name": "Nat20_Force_Empty"
    },
    {
      "x": -16,
      "y": 8,
      "z": 5,
      "name": "Nat20_Force_Empty"
    },
    {
      "x": -16,
      "y": 9,
      "z": 5,
      "name": "Nat20_Force_Empty"
    },
    {
      "x": -16,
      "y": 10,
      "z": 5,
      "name": "Nat20_Force_Empty"
    },
    {
      "x": -16,
      "y": 0,
      "z": 6,
      "name": "Rock_Basalt"
    },
    {
      "x": -16,
      "y": 1,
      "z": 6,
      "name": "Rock_Basalt"
    },
    {
      "x": -16,
      "y": 2,
      "z": 6,
      "name": "Rock_Basalt"
    },
    {
      "x": -16,
      "y": 3,
      "z": 6,
      "name": "Rock_Basalt"
    },
    {
      "x": -16,
      "y": 4,
      "z": 6,
      "name": "Rock_Basalt"
    },
    {
      "x": -16,
      "y": 5,
      "z": 6,
      "name": "Rock_Basalt"
    },
    {
      "x": -16,
      "y": 6,
      "z": 6,
      "name": "Nat20_Force_Empty"
    },
    {
      "x": -16,
      "y": 7,
      "z": 6,
      "name": "Nat20_Force_Empty"
    },
    {
      "x": -16,
      "y": 8,
      "z": 6,
      "name": "Nat20_Force_Empty"
    },
    {
      "x": -16,
      "y": 9,
      "z": 6,
      "name": "Nat20_Force_Empty"
    },
    {
      "x": -16,
      "y": 10,
      "z": 6,
      "name": "Nat20_Force_Empty"
    },
    {
      "x": -16,
      "y": 0,
      "z": 7,
      "name": "Rock_Basalt"
    },
    {
      "x": -16,
      "y": 1,
      "z": 7,
      "name": "Rock_Basalt"
    },
    {
      "x": -16,
      "y": 2,
      "z": 7,
      "name": "Rock_Basalt"
    },
    {
      "x": -16,
      "y": 3,
      "z": 7,
      "name": "Rock_Basalt"
    },
    {
      "x": -16,
      "y": 4,
      "z": 7,
      "name": "Rock_Basalt"
    },
    {
      "x": -16,
      "y": 5,
      "z": 7,
      "name": "Rock_Basalt"
    },
    {
      "x": -16,
      "y": 6,
      "z": 7,
      "name": "Plant_Moss_Block_Green"
    },
    {
      "x": -16,
      "y": 7,
      "z": 7,
      "name": "Nat20_Force_Empty"
    },
    {
      "x": -16,
      "y": 8,
      "z": 7,
      "name": "Nat20_Force_Empty"
    },
    {
      "x": -16,
      "y": 9,
      "z": 7,
      "name": "Nat20_Force_Empty"
    },
    {
      "x": -16,
      "y": 10,
      "z": 7,
      "name": "Plant_Moss_Wall_Green",
      "rotation": 1
    },
    {
      "x": -16,
      "y": 0,
      "z": 8,
      "name": "Rock_Basalt"
    },
    {
      "x": -16,
      "y": 1,
      "z": 8,
      "name": "Rock_Basalt"
    },
    {
      "x": -16,
      "y": 2,
      "z": 8,
      "name": "Rock_Basalt"
    },
    {
      "x": -16,
      "y": 3,
      "z": 8,
      "name": "Rock_Basalt"
    },
    {
      "x": -16,
      "y": 4,
      "z": 8,
      "name": "Rock_Basalt"
    },
    {
      "x": -16,
      "y": 5,
      "z": 8,
      "name": "Rock_Basalt"
    },
    {
      "x": -16,
      "y": 6,
      "z": 8,
      "name": "Plant_Moss_Block_Green"
    },
    {
      "x": -16,
      "y": 7,
      "z": 8,
      "name": "Plant_Moss_Block_Green"
    },
    {
      "x": -16,
      "y": 8,
      "z": 8,
      "name": "Rock_Basalt"
    },
    {
      "x": -16,
      "y": 9,
      "z": 8,
      "name": "Rock_Basalt"
    },
    {
      "x": -16,
      "y": 10,
      "z": 8,
      "name": "Nat20_Force_Empty"
    },
    {
      "x": -16,
      "y": 0,
      "z": 9,
      "name": "Nat20_Force_Empty"
    },
    {
      "x": -16,
      "y": 1,
      "z": 9,
      "name": "Rock_Basalt"
    },
    {
      "x": -16,
      "y": 2,
      "z": 9,
      "name": "Rock_Basalt"
    },
    {
      "x": -16,
      "y": 3,
      "z": 9,
      "name": "Rock_Basalt"
    },
    {
      "x": -16,
      "y": 4,
      "z": 9,
      "name": "Rock_Basalt"
    },
    {
      "x": -16,
      "y": 5,
      "z": 9,
      "name": "Rock_Basalt"
    },
    {
      "x": -16,
      "y": 6,
      "z": 9,
      "name": "Rock_Basalt"
    },
    {
      "x": -16,
      "y": 7,
      "z": 9,
      "name": "Rock_Basalt"
    },
    {
      "x": -16,
      "y": 8,
      "z": 9,
      "name": "Rock_Basalt"
    },
    {
      "x": -16,
      "y": 9,
      "z": 9,
      "name": "Rock_Basalt"
    },
    {
      "x": -16,
      "y": 10,
      "z": 9,
      "name": "Rock_Basalt"
    },
    {
      "x": -16,
      "y": 0,
      "z": 10,
      "name": "Rock_Basalt"
    },
    {
      "x": -16,
      "y": 1,
      "z": 10,
      "name": "Rock_Basalt"
    },
    {
      "x": -16,
      "y": 2,
      "z": 10,
      "name": "Rock_Basalt"
    },
    {
      "x": -16,
      "y": 3,
      "z": 10,
      "name": "Rock_Basalt"
    },
    {
      "x": -16,
      "y": 4,
      "z": 10,
      "name": "Rock_Basalt"
    },
    {
      "x": -16,
      "y": 5,
      "z": 10,
      "name": "Rock_Basalt"
    },
    {
      "x": -16,
      "y": 6,
      "z": 10,
      "name": "Rock_Basalt"
    },
    {
      "x": -16,
      "y": 7,
      "z": 10,
      "name": "Rock_Basalt"
    },
    {
      "x": -16,
      "y": 8,
      "z": 10,
      "name": "Rock_Basalt"
    },
    {
      "x": -16,
      "y": 9,
      "z": 10,
      "name": "Rock_Basalt"
    },
    {
      "x": -16,
      "y": 10,
      "z": 10,
      "name": "Rock_Basalt"
    },
    {
      "x": -16,
      "y": 0,
      "z": 11,
      "name": "Rock_Basalt"
    },
    {
      "x": -16,
      "y": 1,
      "z": 11,
      "name": "Rock_Basalt"
    },
    {
      "x": -16,
      "y": 2,
      "z": 11,
      "name": "Rock_Basalt"
    },
    {
      "x": -16,
      "y": 3,
      "z": 11,
      "name": "Rock_Basalt"
    },
    {
      "x": -16,
      "y": 4,
      "z": 11,
      "name": "Rock_Basalt"
    },
    {
      "x": -16,
      "y": 5,
      "z": 11,
      "name": "Rock_Basalt"
    },
    {
      "x": -16,
      "y": 6,
      "z": 11,
      "name": "Rock_Basalt"
    },
    {
      "x": -16,
      "y": 7,
      "z": 11,
      "name": "Rock_Basalt"
    },
    {
      "x": -16,
      "y": 8,
      "z": 11,
      "name": "Rock_Basalt"
    },
    {
      "x": -16,
      "y": 9,
      "z": 11,
      "name": "Rock_Basalt"
    },
    {
      "x": -16,
      "y": 10,
      "z": 11,
      "name": "Rock_Basalt"
    },
    {
      "x": -15,
      "y": 0,
      "z": -11,
      "name": "Rock_Basalt"
    },
    {
      "x": -15,
      "y": 1,
      "z": -11,
      "name": "Rock_Basalt"
    },
    {
      "x": -15,
      "y": 2,
      "z": -11,
      "name": "Rock_Basalt"
    },
    {
      "x": -15,
      "y": 3,
      "z": -11,
      "name": "Rock_Basalt"
    },
    {
      "x": -15,
      "y": 4,
      "z": -11,
      "name": "Rock_Basalt"
    },
    {
      "x": -15,
      "y": 5,
      "z": -11,
      "name": "Rock_Basalt"
    },
    {
      "x": -15,
      "y": 6,
      "z": -11,
      "name": "Rock_Basalt"
    },
    {
      "x": -15,
      "y": 7,
      "z": -11,
      "name": "Plant_Crop_Mushroom_Block_Brown"
    },
    {
      "x": -15,
      "y": 8,
      "z": -11,
      "name": "Wood_Softwood_Planks_Half",
      "rotation": 5
    },
    {
      "x": -15,
      "y": 9,
      "z": -11,
      "name": "Wood_Softwood_Planks_Half",
      "rotation": 5
    },
    {
      "x": -15,
      "y": 10,
      "z": -11,
      "name": "Nat20_Force_Empty"
    },
    {
      "x": -15,
      "y": 0,
      "z": -10,
      "name": "Rock_Basalt"
    },
    {
      "x": -15,
      "y": 1,
      "z": -10,
      "name": "Rock_Basalt"
    },
    {
      "x": -15,
      "y": 2,
      "z": -10,
      "name": "Rock_Basalt"
    },
    {
      "x": -15,
      "y": 3,
      "z": -10,
      "name": "Rock_Basalt"
    },
    {
      "x": -15,
      "y": 4,
      "z": -10,
      "name": "Rock_Basalt"
    },
    {
      "x": -15,
      "y": 5,
      "z": -10,
      "name": "Rock_Basalt"
    },
    {
      "x": -15,
      "y": 6,
      "z": -10,
      "name": "Rock_Basalt"
    },
    {
      "x": -15,
      "y": 7,
      "z": -10,
      "name": "Rock_Basalt"
    },
    {
      "x": -15,
      "y": 8,
      "z": -10,
      "name": "Plant_Moss_Rug_Green"
    },
    {
      "x": -15,
      "y": 9,
      "z": -10,
      "name": "Nat20_Force_Empty"
    },
    {
      "x": -15,
      "y": 10,
      "z": -10,
      "name": "Nat20_Force_Empty"
    },
    {
      "x": -15,
      "y": 0,
      "z": -9,
      "name": "Rock_Basalt"
    },
    {
      "x": -15,
      "y": 1,
      "z": -9,
      "name": "Rock_Basalt"
    },
    {
      "x": -15,
      "y": 2,
      "z": -9,
      "name": "Rock_Basalt"
    },
    {
      "x": -15,
      "y": 3,
      "z": -9,
      "name": "Rock_Basalt"
    },
    {
      "x": -15,
      "y": 4,
      "z": -9,
      "name": "Rock_Basalt"
    },
    {
      "x": -15,
      "y": 5,
      "z": -9,
      "name": "Plant_Moss_Block_Green"
    },
    {
      "x": -15,
      "y": 6,
      "z": -9,
      "name": "Plant_Moss_Block_Green"
    },
    {
      "x": -15,
      "y": 7,
      "z": -9,
      "name": "Plant_Moss_Wall_Green"
    },
    {
      "x": -15,
      "y": 8,
      "z": -9,
      "name": "Nat20_Force_Empty"
    },
    {
      "x": -15,
      "y": 9,
      "z": -9,
      "name": "Nat20_Force_Empty"
    },
    {
      "x": -15,
      "y": 10,
      "z": -9,
      "name": "Nat20_Force_Empty"
    },
    {
      "x": -15,
      "y": 0,
      "z": -8,
      "name": "Rock_Stone"
    },
    {
      "x": -15,
      "y": 1,
      "z": -8,
      "name": "Rock_Basalt"
    },
    {
      "x": -15,
      "y": 2,
      "z": -8,
      "name": "Rock_Basalt"
    },
    {
      "x": -15,
      "y": 3,
      "z": -8,
      "name": "Rock_Basalt"
    },
    {
      "x": -15,
      "y": 4,
      "z": -8,
      "name": "Rock_Basalt"
    },
    {
      "x": -15,
      "y": 5,
      "z": -8,
      "name": "Rock_Basalt"
    },
    {
      "x": -15,
      "y": 6,
      "z": -8,
      "name": "Plant_Crop_Mushroom_Cap_Brown"
    },
    {
      "x": -15,
      "y": 7,
      "z": -8,
      "name": "Nat20_Force_Empty"
    },
    {
      "x": -15,
      "y": 8,
      "z": -8,
      "name": "Nat20_Force_Empty"
    },
    {
      "x": -15,
      "y": 9,
      "z": -8,
      "name": "Nat20_Force_Empty"
    },
    {
      "x": -15,
      "y": 10,
      "z": -8,
      "name": "Nat20_Force_Empty"
    },
    {
      "x": -15,
      "y": 0,
      "z": -7,
      "name": "Rock_Stone"
    },
    {
      "x": -15,
      "y": 1,
      "z": -7,
      "name": "Rock_Basalt"
    },
    {
      "x": -15,
      "y": 2,
      "z": -7,
      "name": "Rock_Basalt"
    },
    {
      "x": -15,
      "y": 3,
      "z": -7,
      "name": "Rock_Basalt"
    },
    {
      "x": -15,
      "y": 4,
      "z": -7,
      "name": "Rock_Basalt"
    },
    {
      "x": -15,
      "y": 5,
      "z": -7,
      "name": "Nat20_Force_Empty"
    },
    {
      "x": -15,
      "y": 6,
      "z": -7,
      "name": "Nat20_Force_Empty"
    },
    {
      "x": -15,
      "y": 7,
      "z": -7,
      "name": "Nat20_Force_Empty"
    },
    {
      "x": -15,
      "y": 8,
      "z": -7,
      "name": "Nat20_Force_Empty"
    },
    {
      "x": -15,
      "y": 9,
      "z": -7,
      "name": "Nat20_Force_Empty"
    },
    {
      "x": -15,
      "y": 10,
      "z": -7,
      "name": "Nat20_Force_Empty"
    },
    {
      "x": -15,
      "y": 0,
      "z": -6,
      "name": "Rock_Stone"
    },
    {
      "x": -15,
      "y": 1,
      "z": -6,
      "name": "Rock_Basalt"
    },
    {
      "x": -15,
      "y": 2,
      "z": -6,
      "name": "Soil_Mud_Dry"
    },
    {
      "x": -15,
      "y": 3,
      "z": -6,
      "name": "Rock_Basalt"
    },
    {
      "x": -15,
      "y": 4,
      "z": -6,
      "name": "Rock_Basalt"
    },
    {
      "x": -15,
      "y": 5,
      "z": -6,
      "name": "Rock_Basalt"
    },
    {
      "x": -15,
      "y": 6,
      "z": -6,
      "name": "Nat20_Force_Empty"
    },
    {
      "x": -15,
      "y": 7,
      "z": -6,
      "name": "Nat20_Force_Empty"
    },
    {
      "x": -15,
      "y": 8,
      "z": -6,
      "name": "Nat20_Force_Empty"
    },
    {
      "x": -15,
      "y": 9,
      "z": -6,
      "name": "Nat20_Force_Empty"
    },
    {
      "x": -15,
      "y": 10,
      "z": -6,
      "name": "Nat20_Force_Empty"
    },
    {
      "x": -15,
      "y": 0,
      "z": -5,
      "name": "Rock_Stone"
    },
    {
      "x": -15,
      "y": 1,
      "z": -5,
      "name": "Rock_Basalt"
    },
    {
      "x": -15,
      "y": 2,
      "z": -5,
      "name": "Rock_Basalt"
    },
    {
      "x": -15,
      "y": 3,
      "z": -5,
      "name": "Rock_Basalt"
    },
    {
      "x": -15,
      "y": 4,
      "z": -5,
      "name": "Rock_Basalt"
    },
    {
      "x": -15,
      "y": 5,
      "z": -5,
      "name": "Rock_Basalt"
    },
    {
      "x": -15,
      "y": 6,
      "z": -5,
      "name": "Rock_Basalt"
    },
    {
      "x": -15,
      "y": 7,
      "z": -5,
      "name": "Nat20_Force_Empty"
    },
    {
      "x": -15,
      "y": 8,
      "z": -5,
      "name": "Nat20_Force_Empty"
    },
    {
      "x": -15,
      "y": 9,
      "z": -5,
      "name": "Nat20_Force_Empty"
    },
    {
      "x": -15,
      "y": 10,
      "z": -5,
      "name": "Nat20_Force_Empty"
    },
    {
      "x": -15,
      "y": 0,
      "z": -4,
      "name": "Rock_Basalt"
    },
    {
      "x": -15,
      "y": 1,
      "z": -4,
      "name": "Rock_Basalt"
    },
    {
      "x": -15,
      "y": 2,
      "z": -4,
      "name": "Rock_Basalt"
    },
    {
      "x": -15,
      "y": 3,
      "z": -4,
      "name": "Rock_Basalt"
    },
    {
      "x": -15,
      "y": 4,
      "z": -4,
      "name": "Rock_Basalt"
    },
    {
      "x": -15,
      "y": 5,
      "z": -4,
      "name": "Rock_Basalt"
    },
    {
      "x": -15,
      "y": 6,
      "z": -4,
      "name": "Rock_Basalt"
    },
    {
      "x": -15,
      "y": 7,
      "z": -4,
      "name": "Nat20_Force_Empty"
    },
    {
      "x": -15,
      "y": 8,
      "z": -4,
      "name": "Nat20_Force_Empty"
    },
    {
      "x": -15,
      "y": 9,
      "z": -4,
      "name": "Nat20_Force_Empty"
    },
    {
      "x": -15,
      "y": 10,
      "z": -4,
      "name": "Nat20_Force_Empty"
    },
    {
      "x": -15,
      "y": 0,
      "z": -3,
      "name": "Rock_Basalt"
    },
    {
      "x": -15,
      "y": 1,
      "z": -3,
      "name": "Rock_Basalt"
    },
    {
      "x": -15,
      "y": 2,
      "z": -3,
      "name": "Nat20_Force_Empty"
    },
    {
      "x": -15,
      "y": 3,
      "z": -3,
      "name": "Nat20_Force_Empty"
    },
    {
      "x": -15,
      "y": 4,
      "z": -3,
      "name": "Nat20_Force_Empty"
    },
    {
      "x": -15,
      "y": 5,
      "z": -3,
      "name": "Rock_Basalt"
    },
    {
      "x": -15,
      "y": 6,
      "z": -3,
      "name": "Rock_Basalt"
    },
    {
      "x": -15,
      "y": 7,
      "z": -3,
      "name": "Plant_Crop_Mushroom_Shelve_Green"
    },
    {
      "x": -15,
      "y": 8,
      "z": -3,
      "name": "Nat20_Force_Empty"
    },
    {
      "x": -15,
      "y": 9,
      "z": -3,
      "name": "Nat20_Force_Empty"
    },
    {
      "x": -15,
      "y": 10,
      "z": -3,
      "name": "Nat20_Force_Empty"
    },
    {
      "x": -15,
      "y": 0,
      "z": -2,
      "name": "Rock_Basalt"
    },
    {
      "x": -15,
      "y": 1,
      "z": -2,
      "name": "Nat20_Force_Empty"
    },
    {
      "x": -15,
      "y": 2,
      "z": -2,
      "name": "Nat20_Force_Empty"
    },
    {
      "x": -15,
      "y": 3,
      "z": -2,
      "name": "Nat20_Force_Empty"
    },
    {
      "x": -15,
      "y": 4,
      "z": -2,
      "name": "Nat20_Force_Empty"
    },
    {
      "x": -15,
      "y": 5,
      "z": -2,
      "name": "Rock_Basalt"
    },
    {
      "x": -15,
      "y": 6,
      "z": -2,
      "name": "Rock_Stone"
    },
    {
      "x": -15,
      "y": 7,
      "z": -2,
      "name": "Wood_Deadwood_Ornate"
    },
    {
      "x": -15,
      "y": 8,
      "z": -2,
      "name": "Wood_Deadwood_Ornate"
    },
    {
      "x": -15,
      "y": 9,
      "z": -2,
      "name": "Wood_Deadwood_Decorative"
    },
    {
      "x": -15,
      "y": 10,
      "z": -2,
      "name": "Wood_Deadwood_Decorative"
    },
    {
      "x": -15,
      "y": 0,
      "z": -1,
      "name": "Rock_Basalt"
    },
    {
      "x": -15,
      "y": 1,
      "z": -1,
      "name": "Nat20_Force_Empty"
    },
    {
      "x": -15,
      "y": 2,
      "z": -1,
      "name": "Nat20_Force_Empty"
    },
    {
      "x": -15,
      "y": 3,
      "z": -1,
      "name": "Nat20_Force_Empty"
    },
    {
      "x": -15,
      "y": 4,
      "z": -1,
      "name": "Nat20_Force_Empty"
    },
    {
      "x": -15,
      "y": 5,
      "z": -1,
      "name": "Rock_Basalt"
    },
    {
      "x": -15,
      "y": 6,
      "z": -1,
      "name": "Rock_Stone"
    },
    {
      "x": -15,
      "y": 7,
      "z": -1,
      "name": "Wood_Deadwood_Ornate"
    },
    {
      "x": -15,
      "y": 8,
      "z": -1,
      "name": "Wood_Deadwood_Ornate"
    },
    {
      "x": -15,
      "y": 9,
      "z": -1,
      "name": "Deco_Bone_Skulls_Wall",
      "rotation": 1
    },
    {
      "x": -15,
      "y": 10,
      "z": -1,
      "name": "Deco_Bone_Skulls_Wall",
      "rotation": 1
    },
    {
      "x": -15,
      "y": 0,
      "z": 0,
      "name": "Rock_Basalt"
    },
    {
      "x": -15,
      "y": 1,
      "z": 0,
      "name": "Nat20_Force_Empty"
    },
    {
      "x": -15,
      "y": 2,
      "z": 0,
      "name": "Nat20_Force_Empty"
    },
    {
      "x": -15,
      "y": 3,
      "z": 0,
      "name": "Nat20_Force_Empty"
    },
    {
      "x": -15,
      "y": 4,
      "z": 0,
      "name": "Nat20_Force_Empty"
    },
    {
      "x": -15,
      "y": 5,
      "z": 0,
      "name": "Rock_Basalt"
    },
    {
      "x": -15,
      "y": 6,
      "z": 0,
      "name": "Rock_Stone"
    },
    {
      "x": -15,
      "y": 7,
      "z": 0,
      "name": "Wood_Deadwood_Ornate"
    },
    {
      "x": -15,
      "y": 8,
      "z": 0,
      "name": "Wood_Deadwood_Ornate"
    },
    {
      "x": -15,
      "y": 9,
      "z": 0,
      "name": "Wood_Deadwood_Decorative"
    },
    {
      "x": -15,
      "y": 10,
      "z": 0,
      "name": "Wood_Deadwood_Decorative"
    },
    {
      "x": -15,
      "y": 0,
      "z": 1,
      "name": "Rock_Basalt"
    },
    {
      "x": -15,
      "y": 1,
      "z": 1,
      "name": "Nat20_Force_Empty"
    },
    {
      "x": -15,
      "y": 2,
      "z": 1,
      "name": "Nat20_Force_Empty"
    },
    {
      "x": -15,
      "y": 3,
      "z": 1,
      "name": "Nat20_Force_Empty"
    },
    {
      "x": -15,
      "y": 4,
      "z": 1,
      "name": "Nat20_Force_Empty"
    },
    {
      "x": -15,
      "y": 5,
      "z": 1,
      "name": "Rock_Basalt"
    },
    {
      "x": -15,
      "y": 6,
      "z": 1,
      "name": "Rock_Basalt"
    },
    {
      "x": -15,
      "y": 7,
      "z": 1,
      "name": "Nat20_Force_Empty"
    },
    {
      "x": -15,
      "y": 8,
      "z": 1,
      "name": "Nat20_Force_Empty"
    },
    {
      "x": -15,
      "y": 9,
      "z": 1,
      "name": "Nat20_Force_Empty"
    },
    {
      "x": -15,
      "y": 10,
      "z": 1,
      "name": "Nat20_Force_Empty"
    },
    {
      "x": -15,
      "y": 0,
      "z": 2,
      "name": "Rock_Basalt"
    },
    {
      "x": -15,
      "y": 1,
      "z": 2,
      "name": "Rock_Basalt"
    },
    {
      "x": -15,
      "y": 2,
      "z": 2,
      "name": "Furniture_Village_Pot"
    },
    {
      "x": -15,
      "y": 3,
      "z": 2,
      "name": "Nat20_Force_Empty"
    },
    {
      "x": -15,
      "y": 4,
      "z": 2,
      "name": "Rock_Basalt"
    },
    {
      "x": -15,
      "y": 5,
      "z": 2,
      "name": "Rock_Basalt"
    },
    {
      "x": -15,
      "y": 6,
      "z": 2,
      "name": "Rock_Basalt"
    },
    {
      "x": -15,
      "y": 7,
      "z": 2,
      "name": "Deco_Bone_Pile"
    },
    {
      "x": -15,
      "y": 8,
      "z": 2,
      "name": "Nat20_Force_Empty"
    },
    {
      "x": -15,
      "y": 9,
      "z": 2,
      "name": "Nat20_Force_Empty"
    },
    {
      "x": -15,
      "y": 10,
      "z": 2,
      "name": "Nat20_Force_Empty"
    },
    {
      "x": -15,
      "y": 0,
      "z": 3,
      "name": "Rock_Basalt"
    },
    {
      "x": -15,
      "y": 1,
      "z": 3,
      "name": "Rock_Basalt"
    },
    {
      "x": -15,
      "y": 2,
      "z": 3,
      "name": "Rock_Basalt"
    },
    {
      "x": -15,
      "y": 3,
      "z": 3,
      "name": "Rock_Basalt"
    },
    {
      "x": -15,
      "y": 4,
      "z": 3,
      "name": "Rock_Basalt"
    },
    {
      "x": -15,
      "y": 5,
      "z": 3,
      "name": "Rock_Basalt"
    },
    {
      "x": -15,
      "y": 6,
      "z": 3,
      "name": "Nat20_Force_Empty"
    },
    {
      "x": -15,
      "y": 7,
      "z": 3,
      "name": "Nat20_Force_Empty"
    },
    {
      "x": -15,
      "y": 8,
      "z": 3,
      "name": "Nat20_Force_Empty"
    },
    {
      "x": -15,
      "y": 9,
      "z": 3,
      "name": "Nat20_Force_Empty"
    },
    {
      "x": -15,
      "y": 10,
      "z": 3,
      "name": "Nat20_Force_Empty"
    },
    {
      "x": -15,
      "y": 0,
      "z": 4,
      "name": "Rock_Basalt"
    },
    {
      "x": -15,
      "y": 1,
      "z": 4,
      "name": "Rock_Basalt"
    },
    {
      "x": -15,
      "y": 2,
      "z": 4,
      "name": "Rock_Basalt"
    },
    {
      "x": -15,
      "y": 3,
      "z": 4,
      "name": "Rock_Basalt"
    },
    {
      "x": -15,
      "y": 4,
      "z": 4,
      "name": "Rock_Basalt"
    },
    {
      "x": -15,
      "y": 5,
      "z": 4,
      "name": "Nat20_Force_Empty"
    },
    {
      "x": -15,
      "y": 6,
      "z": 4,
      "name": "Nat20_Force_Empty"
    },
    {
      "x": -15,
      "y": 7,
      "z": 4,
      "name": "Nat20_Force_Empty"
    },
    {
      "x": -15,
      "y": 8,
      "z": 4,
      "name": "Nat20_Force_Empty"
    },
    {
      "x": -15,
      "y": 9,
      "z": 4,
      "name": "Nat20_Force_Empty"
    },
    {
      "x": -15,
      "y": 10,
      "z": 4,
      "name": "Nat20_Force_Empty"
    },
    {
      "x": -15,
      "y": 0,
      "z": 5,
      "name": "Rock_Basalt"
    },
    {
      "x": -15,
      "y": 1,
      "z": 5,
      "name": "Rock_Basalt"
    },
    {
      "x": -15,
      "y": 2,
      "z": 5,
      "name": "Rock_Basalt"
    },
    {
      "x": -15,
      "y": 3,
      "z": 5,
      "name": "Rock_Basalt"
    },
    {
      "x": -15,
      "y": 4,
      "z": 5,
      "name": "Nat20_Force_Empty"
    },
    {
      "x": -15,
      "y": 5,
      "z": 5,
      "name": "Nat20_Force_Empty"
    },
    {
      "x": -15,
      "y": 6,
      "z": 5,
      "name": "Nat20_Force_Empty"
    },
    {
      "x": -15,
      "y": 7,
      "z": 5,
      "name": "Nat20_Force_Empty"
    },
    {
      "x": -15,
      "y": 8,
      "z": 5,
      "name": "Nat20_Force_Empty"
    },
    {
      "x": -15,
      "y": 9,
      "z": 5,
      "name": "Nat20_Force_Empty"
    },
    {
      "x": -15,
      "y": 10,
      "z": 5,
      "name": "Nat20_Force_Empty"
    },
    {
      "x": -15,
      "y": 0,
      "z": 6,
      "name": "Rock_Basalt"
    },
    {
      "x": -15,
      "y": 1,
      "z": 6,
      "name": "Rock_Basalt"
    },
    {
      "x": -15,
      "y": 2,
      "z": 6,
      "name": "Rock_Basalt"
    },
    {
      "x": -15,
      "y": 3,
      "z": 6,
      "name": "Rock_Basalt"
    },
    {
      "x": -15,
      "y": 4,
      "z": 6,
      "name": "Rock_Basalt"
    },
    {
      "x": -15,
      "y": 5,
      "z": 6,
      "name": "Nat20_Force_Empty"
    },
    {
      "x": -15,
      "y": 6,
      "z": 6,
      "name": "Nat20_Force_Empty"
    },
    {
      "x": -15,
      "y": 7,
      "z": 6,
      "name": "Nat20_Force_Empty"
    },
    {
      "x": -15,
      "y": 8,
      "z": 6,
      "name": "Nat20_Force_Empty"
    },
    {
      "x": -15,
      "y": 9,
      "z": 6,
      "name": "Nat20_Force_Empty"
    },
    {
      "x": -15,
      "y": 10,
      "z": 6,
      "name": "Nat20_Force_Empty"
    },
    {
      "x": -15,
      "y": 0,
      "z": 7,
      "name": "Rock_Basalt"
    },
    {
      "x": -15,
      "y": 1,
      "z": 7,
      "name": "Rock_Basalt"
    },
    {
      "x": -15,
      "y": 2,
      "z": 7,
      "name": "Rock_Basalt"
    },
    {
      "x": -15,
      "y": 3,
      "z": 7,
      "name": "Rock_Basalt"
    },
    {
      "x": -15,
      "y": 4,
      "z": 7,
      "name": "Rock_Basalt"
    },
    {
      "x": -15,
      "y": 5,
      "z": 7,
      "name": "Rock_Basalt"
    },
    {
      "x": -15,
      "y": 6,
      "z": 7,
      "name": "Plant_Moss_Block_Green"
    },
    {
      "x": -15,
      "y": 7,
      "z": 7,
      "name": "Nat20_Force_Empty"
    },
    {
      "x": -15,
      "y": 8,
      "z": 7,
      "name": "Nat20_Force_Empty"
    },
    {
      "x": -15,
      "y": 9,
      "z": 7,
      "name": "Nat20_Force_Empty"
    },
    {
      "x": -15,
      "y": 10,
      "z": 7,
      "name": "Nat20_Force_Empty"
    },
    {
      "x": -15,
      "y": 0,
      "z": 8,
      "name": "Rock_Basalt"
    },
    {
      "x": -15,
      "y": 1,
      "z": 8,
      "name": "Rock_Basalt"
    },
    {
      "x": -15,
      "y": 2,
      "z": 8,
      "name": "Rock_Basalt"
    },
    {
      "x": -15,
      "y": 3,
      "z": 8,
      "name": "Rock_Basalt"
    },
    {
      "x": -15,
      "y": 4,
      "z": 8,
      "name": "Rock_Basalt"
    },
    {
      "x": -15,
      "y": 5,
      "z": 8,
      "name": "Rock_Basalt"
    },
    {
      "x": -15,
      "y": 6,
      "z": 8,
      "name": "Rock_Basalt"
    },
    {
      "x": -15,
      "y": 7,
      "z": 8,
      "name": "Rock_Basalt"
    },
    {
      "x": -15,
      "y": 8,
      "z": 8,
      "name": "Rock_Basalt"
    },
    {
      "x": -15,
      "y": 9,
      "z": 8,
      "name": "Plant_Moss_Rug_Green"
    },
    {
      "x": -15,
      "y": 10,
      "z": 8,
      "name": "Nat20_Force_Empty"
    },
    {
      "x": -15,
      "y": 0,
      "z": 9,
      "name": "Rock_Basalt"
    },
    {
      "x": -15,
      "y": 1,
      "z": 9,
      "name": "Nat20_Force_Empty"
    },
    {
      "x": -15,
      "y": 2,
      "z": 9,
      "name": "Rock_Basalt"
    },
    {
      "x": -15,
      "y": 3,
      "z": 9,
      "name": "Rock_Basalt"
    },
    {
      "x": -15,
      "y": 4,
      "z": 9,
      "name": "Rock_Basalt"
    },
    {
      "x": -15,
      "y": 5,
      "z": 9,
      "name": "Rock_Basalt"
    },
    {
      "x": -15,
      "y": 6,
      "z": 9,
      "name": "Rock_Basalt"
    },
    {
      "x": -15,
      "y": 7,
      "z": 9,
      "name": "Rock_Basalt"
    },
    {
      "x": -15,
      "y": 8,
      "z": 9,
      "name": "Rock_Basalt"
    },
    {
      "x": -15,
      "y": 9,
      "z": 9,
      "name": "Rock_Basalt"
    },
    {
      "x": -15,
      "y": 10,
      "z": 9,
      "name": "Rock_Basalt"
    },
    {
      "x": -15,
      "y": 0,
      "z": 10,
      "name": "Rock_Basalt"
    },
    {
      "x": -15,
      "y": 1,
      "z": 10,
      "name": "Nat20_Force_Empty"
    },
    {
      "x": -15,
      "y": 2,
      "z": 10,
      "name": "Rock_Basalt"
    },
    {
      "x": -15,
      "y": 3,
      "z": 10,
      "name": "Rock_Basalt"
    },
    {
      "x": -15,
      "y": 4,
      "z": 10,
      "name": "Rock_Basalt"
    },
    {
      "x": -15,
      "y": 5,
      "z": 10,
      "name": "Rock_Basalt"
    },
    {
      "x": -15,
      "y": 6,
      "z": 10,
      "name": "Rock_Basalt"
    },
    {
      "x": -15,
      "y": 7,
      "z": 10,
      "name": "Rock_Basalt"
    },
    {
      "x": -15,
      "y": 8,
      "z": 10,
      "name": "Rock_Basalt"
    },
    {
      "x": -15,
      "y": 9,
      "z": 10,
      "name": "Rock_Basalt"
    },
    {
      "x": -15,
      "y": 10,
      "z": 10,
      "name": "Rock_Basalt"
    },
    {
      "x": -15,
      "y": 0,
      "z": 11,
      "name": "Rock_Basalt"
    },
    {
      "x": -15,
      "y": 1,
      "z": 11,
      "name": "Nat20_Force_Empty"
    },
    {
      "x": -15,
      "y": 2,
      "z": 11,
      "name": "Nat20_Force_Empty"
    },
    {
      "x": -15,
      "y": 3,
      "z": 11,
      "name": "Rock_Basalt"
    },
    {
      "x": -15,
      "y": 4,
      "z": 11,
      "name": "Rock_Basalt"
    },
    {
      "x": -15,
      "y": 5,
      "z": 11,
      "name": "Rock_Basalt"
    },
    {
      "x": -15,
      "y": 6,
      "z": 11,
      "name": "Rock_Basalt"
    },
    {
      "x": -15,
      "y": 7,
      "z": 11,
      "name": "Rock_Basalt"
    },
    {
      "x": -15,
      "y": 8,
      "z": 11,
      "name": "Rock_Basalt"
    },
    {
      "x": -15,
      "y": 9,
      "z": 11,
      "name": "Rock_Basalt"
    },
    {
      "x": -15,
      "y": 10,
      "z": 11,
      "name": "Rock_Basalt"
    },
    {
      "x": -14,
      "y": 0,
      "z": -11,
      "name": "Rock_Basalt"
    },
    {
      "x": -14,
      "y": 1,
      "z": -11,
      "name": "Rock_Basalt"
    },
    {
      "x": -14,
      "y": 2,
      "z": -11,
      "name": "Rock_Basalt"
    },
    {
      "x": -14,
      "y": 3,
      "z": -11,
      "name": "Rock_Basalt"
    },
    {
      "x": -14,
      "y": 4,
      "z": -11,
      "name": "Rock_Basalt"
    },
    {
      "x": -14,
      "y": 5,
      "z": -11,
      "name": "Rock_Basalt"
    },
    {
      "x": -14,
      "y": 6,
      "z": -11,
      "name": "Rock_Basalt"
    },
    {
      "x": -14,
      "y": 7,
      "z": -11,
      "name": "Plant_Crop_Mushroom_Block_Brown"
    },
    {
      "x": -14,
      "y": 8,
      "z": -11,
      "name": "Plant_Crop_Mushroom_Block_Brown"
    },
    {
      "x": -14,
      "y": 9,
      "z": -11,
      "name": "Nat20_Force_Empty"
    },
    {
      "x": -14,
      "y": 10,
      "z": -11,
      "name": "Nat20_Force_Empty"
    },
    {
      "x": -14,
      "y": 0,
      "z": -10,
      "name": "Rock_Basalt"
    },
    {
      "x": -14,
      "y": 1,
      "z": -10,
      "name": "Rock_Basalt"
    },
    {
      "x": -14,
      "y": 2,
      "z": -10,
      "name": "Rock_Basalt"
    },
    {
      "x": -14,
      "y": 3,
      "z": -10,
      "name": "Rock_Basalt"
    },
    {
      "x": -14,
      "y": 4,
      "z": -10,
      "name": "Rock_Basalt"
    },
    {
      "x": -14,
      "y": 5,
      "z": -10,
      "name": "Plant_Moss_Block_Green"
    },
    {
      "x": -14,
      "y": 6,
      "z": -10,
      "name": "Plant_Moss_Block_Green"
    },
    {
      "x": -14,
      "y": 7,
      "z": -10,
      "name": "Plant_Crop_Mushroom_Block_Brown"
    },
    {
      "x": -14,
      "y": 8,
      "z": -10,
      "name": "Plant_Moss_Rug_Green"
    },
    {
      "x": -14,
      "y": 9,
      "z": -10,
      "name": "Nat20_Force_Empty"
    },
    {
      "x": -14,
      "y": 10,
      "z": -10,
      "name": "Nat20_Force_Empty"
    },
    {
      "x": -14,
      "y": 0,
      "z": -9,
      "name": "Rock_Basalt"
    },
    {
      "x": -14,
      "y": 1,
      "z": -9,
      "name": "Rock_Basalt"
    },
    {
      "x": -14,
      "y": 2,
      "z": -9,
      "name": "Rock_Basalt"
    },
    {
      "x": -14,
      "y": 3,
      "z": -9,
      "name": "Rock_Basalt"
    },
    {
      "x": -14,
      "y": 4,
      "z": -9,
      "name": "Rock_Basalt"
    },
    {
      "x": -14,
      "y": 5,
      "z": -9,
      "name": "Plant_Moss_Block_Green"
    },
    {
      "x": -14,
      "y": 6,
      "z": -9,
      "name": "Nat20_Force_Empty"
    },
    {
      "x": -14,
      "y": 7,
      "z": -9,
      "name": "Plant_Moss_Wall_Green"
    },
    {
      "x": -14,
      "y": 8,
      "z": -9,
      "name": "Nat20_Force_Empty"
    },
    {
      "x": -14,
      "y": 9,
      "z": -9,
      "name": "Nat20_Force_Empty"
    },
    {
      "x": -14,
      "y": 10,
      "z": -9,
      "name": "Nat20_Force_Empty"
    },
    {
      "x": -14,
      "y": 0,
      "z": -8,
      "name": "Rock_Stone"
    },
    {
      "x": -14,
      "y": 1,
      "z": -8,
      "name": "Rock_Basalt"
    },
    {
      "x": -14,
      "y": 2,
      "z": -8,
      "name": "Rock_Basalt"
    },
    {
      "x": -14,
      "y": 3,
      "z": -8,
      "name": "Rock_Basalt"
    },
    {
      "x": -14,
      "y": 4,
      "z": -8,
      "name": "Rock_Basalt"
    },
    {
      "x": -14,
      "y": 5,
      "z": -8,
      "name": "Nat20_Force_Empty"
    },
    {
      "x": -14,
      "y": 6,
      "z": -8,
      "name": "Nat20_Force_Empty"
    },
    {
      "x": -14,
      "y": 7,
      "z": -8,
      "name": "Nat20_Force_Empty"
    },
    {
      "x": -14,
      "y": 8,
      "z": -8,
      "name": "Nat20_Force_Empty"
    },
    {
      "x": -14,
      "y": 9,
      "z": -8,
      "name": "Nat20_Force_Empty"
    },
    {
      "x": -14,
      "y": 10,
      "z": -8,
      "name": "Nat20_Force_Empty"
    },
    {
      "x": -14,
      "y": 0,
      "z": -7,
      "name": "Rock_Stone"
    },
    {
      "x": -14,
      "y": 1,
      "z": -7,
      "name": "Rock_Basalt"
    },
    {
      "x": -14,
      "y": 2,
      "z": -7,
      "name": "Soil_Mud_Dry"
    },
    {
      "x": -14,
      "y": 3,
      "z": -7,
      "name": "Rock_Basalt"
    },
    {
      "x": -14,
      "y": 4,
      "z": -7,
      "name": "Plant_Crop_Mushroom_Shelve_Green"
    },
    {
      "x": -14,
      "y": 5,
      "z": -7,
      "name": "Nat20_Force_Empty"
    },
    {
      "x": -14,
      "y": 6,
      "z": -7,
      "name": "Nat20_Force_Empty"
    },
    {
      "x": -14,
      "y": 7,
      "z": -7,
      "name": "Nat20_Force_Empty"
    },
    {
      "x": -14,
      "y": 8,
      "z": -7,
      "name": "Nat20_Force_Empty"
    },
    {
      "x": -14,
      "y": 9,
      "z": -7,
      "name": "Nat20_Force_Empty"
    },
    {
      "x": -14,
      "y": 10,
      "z": -7,
      "name": "Nat20_Force_Empty"
    },
    {
      "x": -14,
      "y": 0,
      "z": -6,
      "name": "Rock_Stone"
    },
    {
      "x": -14,
      "y": 1,
      "z": -6,
      "name": "Soil_Mud_Dry"
    },
    {
      "x": -14,
      "y": 2,
      "z": -6,
      "name": "Soil_Mud_Dry"
    },
    {
      "x": -14,
      "y": 3,
      "z": -6,
      "name": "Rock_Basalt"
    },
    {
      "x": -14,
      "y": 4,
      "z": -6,
      "name": "Rock_Basalt"
    },
    {
      "x": -14,
      "y": 5,
      "z": -6,
      "name": "Rock_Basalt"
    },
    {
      "x": -14,
      "y": 6,
      "z": -6,
      "name": "Nat20_Force_Empty"
    },
    {
      "x": -14,
      "y": 7,
      "z": -6,
      "name": "Nat20_Force_Empty"
    },
    {
      "x": -14,
      "y": 8,
      "z": -6,
      "name": "Nat20_Force_Empty"
    },
    {
      "x": -14,
      "y": 9,
      "z": -6,
      "name": "Nat20_Force_Empty"
    },
    {
      "x": -14,
      "y": 10,
      "z": -6,
      "name": "Nat20_Force_Empty"
    },
    {
      "x": -14,
      "y": 0,
      "z": -5,
      "name": "Rock_Stone"
    },
    {
      "x": -14,
      "y": 1,
      "z": -5,
      "name": "Rock_Basalt"
    },
    {
      "x": -14,
      "y": 2,
      "z": -5,
      "name": "Soil_Mud_Dry"
    },
    {
      "x": -14,
      "y": 3,
      "z": -5,
      "name": "Rock_Basalt"
    },
    {
      "x": -14,
      "y": 4,
      "z": -5,
      "name": "Rock_Basalt"
    },
    {
      "x": -14,
      "y": 5,
      "z": -5,
      "name": "Rock_Basalt"
    },
    {
      "x": -14,
      "y": 6,
      "z": -5,
      "name": "Nat20_Force_Empty"
    },
    {
      "x": -14,
      "y": 7,
      "z": -5,
      "name": "Nat20_Force_Empty"
    },
    {
      "x": -14,
      "y": 8,
      "z": -5,
      "name": "Nat20_Force_Empty"
    },
    {
      "x": -14,
      "y": 9,
      "z": -5,
      "name": "Nat20_Force_Empty"
    },
    {
      "x": -14,
      "y": 10,
      "z": -5,
      "name": "Nat20_Force_Empty"
    },
    {
      "x": -14,
      "y": 0,
      "z": -4,
      "name": "Rock_Stone"
    },
    {
      "x": -14,
      "y": 1,
      "z": -4,
      "name": "Rock_Basalt"
    },
    {
      "x": -14,
      "y": 2,
      "z": -4,
      "name": "Rock_Basalt"
    },
    {
      "x": -14,
      "y": 3,
      "z": -4,
      "name": "Rock_Basalt"
    },
    {
      "x": -14,
      "y": 4,
      "z": -4,
      "name": "Rock_Basalt"
    },
    {
      "x": -14,
      "y": 5,
      "z": -4,
      "name": "Rock_Basalt"
    },
    {
      "x": -14,
      "y": 6,
      "z": -4,
      "name": "Rock_Basalt"
    },
    {
      "x": -14,
      "y": 7,
      "z": -4,
      "name": "Nat20_Force_Empty"
    },
    {
      "x": -14,
      "y": 8,
      "z": -4,
      "name": "Nat20_Force_Empty"
    },
    {
      "x": -14,
      "y": 9,
      "z": -4,
      "name": "Nat20_Force_Empty"
    },
    {
      "x": -14,
      "y": 10,
      "z": -4,
      "name": "Nat20_Force_Empty"
    },
    {
      "x": -14,
      "y": 0,
      "z": -3,
      "name": "Rock_Basalt"
    },
    {
      "x": -14,
      "y": 1,
      "z": -3,
      "name": "Rock_Basalt"
    },
    {
      "x": -14,
      "y": 2,
      "z": -3,
      "name": "Soil_Mud_Dry"
    },
    {
      "x": -14,
      "y": 3,
      "z": -3,
      "name": "Rock_Basalt"
    },
    {
      "x": -14,
      "y": 4,
      "z": -3,
      "name": "Rock_Basalt"
    },
    {
      "x": -14,
      "y": 5,
      "z": -3,
      "name": "Rock_Basalt"
    },
    {
      "x": -14,
      "y": 6,
      "z": -3,
      "name": "Rock_Basalt"
    },
    {
      "x": -14,
      "y": 7,
      "z": -3,
      "name": "Nat20_Force_Empty"
    },
    {
      "x": -14,
      "y": 8,
      "z": -3,
      "name": "Nat20_Force_Empty"
    },
    {
      "x": -14,
      "y": 9,
      "z": -3,
      "name": "Nat20_Force_Empty"
    },
    {
      "x": -14,
      "y": 10,
      "z": -3,
      "name": "Nat20_Force_Empty"
    },
    {
      "x": -14,
      "y": 0,
      "z": -2,
      "name": "Rock_Basalt"
    },
    {
      "x": -14,
      "y": 1,
      "z": -2,
      "name": "Nat20_Force_Empty"
    },
    {
      "x": -14,
      "y": 2,
      "z": -2,
      "name": "Nat20_Force_Empty"
    },
    {
      "x": -14,
      "y": 3,
      "z": -2,
      "name": "Nat20_Force_Empty"
    },
    {
      "x": -14,
      "y": 4,
      "z": -2,
      "name": "Nat20_Force_Empty"
    },
    {
      "x": -14,
      "y": 5,
      "z": -2,
      "name": "Rock_Basalt"
    },
    {
      "x": -14,
      "y": 6,
      "z": -2,
      "name": "Rock_Basalt"
    },
    {
      "x": -14,
      "y": 7,
      "z": -2,
      "name": "Deco_Chair_Scrap",
      "filler": 1023,
      "rotation": 1
    },
    {
      "x": -14,
      "y": 8,
      "z": -2,
      "name": "Deco_Chair_Scrap",
      "filler": 2047,
      "rotation": 1
    },
    {
      "x": -14,
      "y": 9,
      "z": -2,
      "name": "Deco_Chair_Scrap",
      "filler": 3071,
      "rotation": 1
    },
    {
      "x": -14,
      "y": 10,
      "z": -2,
      "name": "Deco_Chair_Scrap",
      "filler": 4095,
      "rotation": 1
    },
    {
      "x": -14,
      "y": 0,
      "z": -1,
      "name": "Rock_Basalt"
    },
    {
      "x": -14,
      "y": 1,
      "z": -1,
      "name": "Nat20_Force_Empty"
    },
    {
      "x": -14,
      "y": 2,
      "z": -1,
      "name": "Nat20_Force_Empty"
    },
    {
      "x": -14,
      "y": 3,
      "z": -1,
      "name": "Nat20_Force_Empty"
    },
    {
      "x": -14,
      "y": 4,
      "z": -1,
      "name": "Nat20_Force_Empty"
    },
    {
      "x": -14,
      "y": 5,
      "z": -1,
      "name": "Rock_Basalt"
    },
    {
      "x": -14,
      "y": 6,
      "z": -1,
      "name": "Rock_Basalt"
    },
    {
      "x": -14,
      "y": 7,
      "z": -1,
      "name": "Deco_Chair_Scrap",
      "filler": 31,
      "rotation": 1
    },
    {
      "x": -14,
      "y": 8,
      "z": -1,
      "name": "Deco_Chair_Scrap",
      "filler": 1055,
      "rotation": 1
    },
    {
      "x": -14,
      "y": 9,
      "z": -1,
      "name": "Deco_Chair_Scrap",
      "filler": 2079,
      "rotation": 1
    },
    {
      "x": -14,
      "y": 10,
      "z": -1,
      "name": "Deco_Chair_Scrap",
      "filler": 3103,
      "rotation": 1
    },
    {
      "x": -14,
      "y": 0,
      "z": 0,
      "name": "Rock_Basalt"
    },
    {
      "x": -14,
      "y": 1,
      "z": 0,
      "name": "Nat20_Force_Empty"
    },
    {
      "x": -14,
      "y": 2,
      "z": 0,
      "name": "Nat20_Force_Empty"
    },
    {
      "x": -14,
      "y": 3,
      "z": 0,
      "name": "Nat20_Force_Empty"
    },
    {
      "x": -14,
      "y": 4,
      "z": 0,
      "name": "Nat20_Force_Empty"
    },
    {
      "x": -14,
      "y": 5,
      "z": 0,
      "name": "Rock_Basalt"
    },
    {
      "x": -14,
      "y": 6,
      "z": 0,
      "name": "Rock_Basalt"
    },
    {
      "x": -14,
      "y": 7,
      "z": 0,
      "name": "Deco_Chair_Scrap",
      "filler": 63,
      "rotation": 1
    },
    {
      "x": -14,
      "y": 8,
      "z": 0,
      "name": "Deco_Chair_Scrap",
      "filler": 1087,
      "rotation": 1
    },
    {
      "x": -14,
      "y": 9,
      "z": 0,
      "name": "Deco_Chair_Scrap",
      "filler": 2111,
      "rotation": 1
    },
    {
      "x": -14,
      "y": 10,
      "z": 0,
      "name": "Deco_Chair_Scrap",
      "filler": 3135,
      "rotation": 1
    },
    {
      "x": -14,
      "y": 0,
      "z": 1,
      "name": "Rock_Basalt"
    },
    {
      "x": -14,
      "y": 1,
      "z": 1,
      "name": "Rock_Basalt"
    },
    {
      "x": -14,
      "y": 2,
      "z": 1,
      "name": "Nat20_Force_Empty"
    },
    {
      "x": -14,
      "y": 3,
      "z": 1,
      "name": "Nat20_Force_Empty"
    },
    {
      "x": -14,
      "y": 4,
      "z": 1,
      "name": "Rock_Basalt"
    },
    {
      "x": -14,
      "y": 5,
      "z": 1,
      "name": "Rock_Basalt"
    },
    {
      "x": -14,
      "y": 6,
      "z": 1,
      "name": "Rock_Basalt"
    },
    {
      "x": -14,
      "y": 7,
      "z": 1,
      "name": "Deco_Bone_Skulls"
    },
    {
      "x": -14,
      "y": 8,
      "z": 1,
      "name": "Nat20_Force_Empty"
    },
    {
      "x": -14,
      "y": 9,
      "z": 1,
      "name": "Nat20_Force_Empty"
    },
    {
      "x": -14,
      "y": 10,
      "z": 1,
      "name": "Nat20_Force_Empty"
    },
    {
      "x": -14,
      "y": 0,
      "z": 2,
      "name": "Rock_Basalt"
    },
    {
      "x": -14,
      "y": 1,
      "z": 2,
      "name": "Rock_Basalt"
    },
    {
      "x": -14,
      "y": 2,
      "z": 2,
      "name": "Soil_Mud_Dry"
    },
    {
      "x": -14,
      "y": 3,
      "z": 2,
      "name": "Rock_Basalt"
    },
    {
      "x": -14,
      "y": 4,
      "z": 2,
      "name": "Rock_Basalt"
    },
    {
      "x": -14,
      "y": 5,
      "z": 2,
      "name": "Rock_Basalt"
    },
    {
      "x": -14,
      "y": 6,
      "z": 2,
      "name": "Rock_Basalt"
    },
    {
      "x": -14,
      "y": 7,
      "z": 2,
      "name": "Nat20_Force_Empty"
    },
    {
      "x": -14,
      "y": 8,
      "z": 2,
      "name": "Nat20_Force_Empty"
    },
    {
      "x": -14,
      "y": 9,
      "z": 2,
      "name": "Nat20_Force_Empty"
    },
    {
      "x": -14,
      "y": 10,
      "z": 2,
      "name": "Nat20_Force_Empty"
    },
    {
      "x": -14,
      "y": 0,
      "z": 3,
      "name": "Rock_Basalt"
    },
    {
      "x": -14,
      "y": 1,
      "z": 3,
      "name": "Rock_Basalt"
    },
    {
      "x": -14,
      "y": 2,
      "z": 3,
      "name": "Soil_Mud_Dry"
    },
    {
      "x": -14,
      "y": 3,
      "z": 3,
      "name": "Rock_Basalt"
    },
    {
      "x": -14,
      "y": 4,
      "z": 3,
      "name": "Rock_Basalt"
    },
    {
      "x": -14,
      "y": 5,
      "z": 3,
      "name": "Rock_Basalt"
    },
    {
      "x": -14,
      "y": 6,
      "z": 3,
      "name": "Nat20_Force_Empty"
    },
    {
      "x": -14,
      "y": 7,
      "z": 3,
      "name": "Nat20_Force_Empty"
    },
    {
      "x": -14,
      "y": 8,
      "z": 3,
      "name": "Nat20_Force_Empty"
    },
    {
      "x": -14,
      "y": 9,
      "z": 3,
      "name": "Nat20_Force_Empty"
    },
    {
      "x": -14,
      "y": 10,
      "z": 3,
      "name": "Nat20_Force_Empty"
    },
    {
      "x": -14,
      "y": 0,
      "z": 4,
      "name": "Rock_Basalt"
    },
    {
      "x": -14,
      "y": 1,
      "z": 4,
      "name": "Rock_Basalt"
    },
    {
      "x": -14,
      "y": 2,
      "z": 4,
      "name": "Soil_Mud_Dry"
    },
    {
      "x": -14,
      "y": 3,
      "z": 4,
      "name": "Rock_Basalt"
    },
    {
      "x": -14,
      "y": 4,
      "z": 4,
      "name": "Nat20_Force_Empty"
    },
    {
      "x": -14,
      "y": 5,
      "z": 4,
      "name": "Nat20_Force_Empty"
    },
    {
      "x": -14,
      "y": 6,
      "z": 4,
      "name": "Nat20_Force_Empty"
    },
    {
      "x": -14,
      "y": 7,
      "z": 4,
      "name": "Nat20_Force_Empty"
    },
    {
      "x": -14,
      "y": 8,
      "z": 4,
      "name": "Nat20_Force_Empty"
    },
    {
      "x": -14,
      "y": 9,
      "z": 4,
      "name": "Nat20_Force_Empty"
    },
    {
      "x": -14,
      "y": 10,
      "z": 4,
      "name": "Nat20_Force_Empty"
    },
    {
      "x": -14,
      "y": 0,
      "z": 5,
      "name": "Rock_Basalt"
    },
    {
      "x": -14,
      "y": 1,
      "z": 5,
      "name": "Rock_Basalt"
    },
    {
      "x": -14,
      "y": 2,
      "z": 5,
      "name": "Rock_Basalt"
    },
    {
      "x": -14,
      "y": 3,
      "z": 5,
      "name": "Rock_Basalt"
    },
    {
      "x": -14,
      "y": 4,
      "z": 5,
      "name": "Nat20_Force_Empty"
    },
    {
      "x": -14,
      "y": 5,
      "z": 5,
      "name": "Nat20_Force_Empty"
    },
    {
      "x": -14,
      "y": 6,
      "z": 5,
      "name": "Nat20_Force_Empty"
    },
    {
      "x": -14,
      "y": 7,
      "z": 5,
      "name": "Nat20_Force_Empty"
    },
    {
      "x": -14,
      "y": 8,
      "z": 5,
      "name": "Nat20_Force_Empty"
    },
    {
      "x": -14,
      "y": 9,
      "z": 5,
      "name": "Nat20_Force_Empty"
    },
    {
      "x": -14,
      "y": 10,
      "z": 5,
      "name": "Nat20_Force_Empty"
    },
    {
      "x": -14,
      "y": 0,
      "z": 6,
      "name": "Rock_Basalt"
    },
    {
      "x": -14,
      "y": 1,
      "z": 6,
      "name": "Rock_Basalt"
    },
    {
      "x": -14,
      "y": 2,
      "z": 6,
      "name": "Rock_Basalt"
    },
    {
      "x": -14,
      "y": 3,
      "z": 6,
      "name": "Rock_Basalt"
    },
    {
      "x": -14,
      "y": 4,
      "z": 6,
      "name": "Nat20_Force_Empty"
    },
    {
      "x": -14,
      "y": 5,
      "z": 6,
      "name": "Nat20_Force_Empty"
    },
    {
      "x": -14,
      "y": 6,
      "z": 6,
      "name": "Nat20_Force_Empty"
    },
    {
      "x": -14,
      "y": 7,
      "z": 6,
      "name": "Nat20_Force_Empty"
    },
    {
      "x": -14,
      "y": 8,
      "z": 6,
      "name": "Nat20_Force_Empty"
    },
    {
      "x": -14,
      "y": 9,
      "z": 6,
      "name": "Nat20_Force_Empty"
    },
    {
      "x": -14,
      "y": 10,
      "z": 6,
      "name": "Nat20_Force_Empty"
    },
    {
      "x": -14,
      "y": 0,
      "z": 7,
      "name": "Rock_Basalt"
    },
    {
      "x": -14,
      "y": 1,
      "z": 7,
      "name": "Rock_Basalt"
    },
    {
      "x": -14,
      "y": 2,
      "z": 7,
      "name": "Rock_Basalt"
    },
    {
      "x": -14,
      "y": 3,
      "z": 7,
      "name": "Rock_Basalt"
    },
    {
      "x": -14,
      "y": 4,
      "z": 7,
      "name": "Rock_Basalt"
    },
    {
      "x": -14,
      "y": 5,
      "z": 7,
      "name": "Nat20_Force_Empty"
    },
    {
      "x": -14,
      "y": 6,
      "z": 7,
      "name": "Nat20_Force_Empty"
    },
    {
      "x": -14,
      "y": 7,
      "z": 7,
      "name": "Nat20_Force_Empty"
    },
    {
      "x": -14,
      "y": 8,
      "z": 7,
      "name": "Nat20_Force_Empty"
    },
    {
      "x": -14,
      "y": 9,
      "z": 7,
      "name": "Nat20_Force_Empty"
    },
    {
      "x": -14,
      "y": 10,
      "z": 7,
      "name": "Nat20_Force_Empty"
    },
    {
      "x": -14,
      "y": 0,
      "z": 8,
      "name": "Rock_Basalt"
    },
    {
      "x": -14,
      "y": 1,
      "z": 8,
      "name": "Rock_Basalt"
    },
    {
      "x": -14,
      "y": 2,
      "z": 8,
      "name": "Rock_Basalt"
    },
    {
      "x": -14,
      "y": 3,
      "z": 8,
      "name": "Rock_Basalt"
    },
    {
      "x": -14,
      "y": 4,
      "z": 8,
      "name": "Rock_Basalt"
    },
    {
      "x": -14,
      "y": 5,
      "z": 8,
      "name": "Rock_Basalt"
    },
    {
      "x": -14,
      "y": 6,
      "z": 8,
      "name": "Nat20_Force_Empty"
    },
    {
      "x": -14,
      "y": 7,
      "z": 8,
      "name": "Nat20_Force_Empty"
    },
    {
      "x": -14,
      "y": 8,
      "z": 8,
      "name": "Nat20_Force_Empty"
    },
    {
      "x": -14,
      "y": 9,
      "z": 8,
      "name": "Nat20_Force_Empty"
    },
    {
      "x": -14,
      "y": 10,
      "z": 8,
      "name": "Nat20_Force_Empty"
    },
    {
      "x": -14,
      "y": 0,
      "z": 9,
      "name": "Rock_Basalt"
    },
    {
      "x": -14,
      "y": 1,
      "z": 9,
      "name": "Nat20_Force_Empty"
    },
    {
      "x": -14,
      "y": 2,
      "z": 9,
      "name": "Nat20_Force_Empty"
    },
    {
      "x": -14,
      "y": 3,
      "z": 9,
      "name": "Rock_Basalt"
    },
    {
      "x": -14,
      "y": 4,
      "z": 9,
      "name": "Rock_Basalt"
    },
    {
      "x": -14,
      "y": 5,
      "z": 9,
      "name": "Rock_Basalt"
    },
    {
      "x": -14,
      "y": 6,
      "z": 9,
      "name": "Rock_Basalt"
    },
    {
      "x": -14,
      "y": 7,
      "z": 9,
      "name": "Rock_Basalt"
    },
    {
      "x": -14,
      "y": 8,
      "z": 9,
      "name": "Rock_Basalt"
    },
    {
      "x": -14,
      "y": 9,
      "z": 9,
      "name": "Plant_Moss_Rug_Green"
    },
    {
      "x": -14,
      "y": 10,
      "z": 9,
      "name": "Nat20_Force_Empty"
    },
    {
      "x": -14,
      "y": 0,
      "z": 10,
      "name": "Rock_Basalt"
    },
    {
      "x": -14,
      "y": 1,
      "z": 10,
      "name": "Nat20_Force_Empty"
    },
    {
      "x": -14,
      "y": 2,
      "z": 10,
      "name": "Nat20_Force_Empty"
    },
    {
      "x": -14,
      "y": 3,
      "z": 10,
      "name": "Nat20_Force_Empty"
    },
    {
      "x": -14,
      "y": 4,
      "z": 10,
      "name": "Nat20_Force_Empty"
    },
    {
      "x": -14,
      "y": 5,
      "z": 10,
      "name": "Rock_Basalt"
    },
    {
      "x": -14,
      "y": 6,
      "z": 10,
      "name": "Rock_Basalt"
    },
    {
      "x": -14,
      "y": 7,
      "z": 10,
      "name": "Rock_Basalt"
    },
    {
      "x": -14,
      "y": 8,
      "z": 10,
      "name": "Rock_Basalt"
    },
    {
      "x": -14,
      "y": 9,
      "z": 10,
      "name": "Rock_Basalt"
    },
    {
      "x": -14,
      "y": 10,
      "z": 10,
      "name": "Rock_Basalt"
    },
    {
      "x": -14,
      "y": 0,
      "z": 11,
      "name": "Rock_Basalt"
    },
    {
      "x": -14,
      "y": 1,
      "z": 11,
      "name": "Nat20_Force_Empty"
    },
    {
      "x": -14,
      "y": 2,
      "z": 11,
      "name": "Nat20_Force_Empty"
    },
    {
      "x": -14,
      "y": 3,
      "z": 11,
      "name": "Nat20_Force_Empty"
    },
    {
      "x": -14,
      "y": 4,
      "z": 11,
      "name": "Nat20_Force_Empty"
    },
    {
      "x": -14,
      "y": 5,
      "z": 11,
      "name": "Rock_Basalt"
    },
    {
      "x": -14,
      "y": 6,
      "z": 11,
      "name": "Rock_Basalt"
    },
    {
      "x": -14,
      "y": 7,
      "z": 11,
      "name": "Rock_Basalt"
    },
    {
      "x": -14,
      "y": 8,
      "z": 11,
      "name": "Rock_Basalt"
    },
    {
      "x": -14,
      "y": 9,
      "z": 11,
      "name": "Rock_Basalt"
    },
    {
      "x": -14,
      "y": 10,
      "z": 11,
      "name": "Rock_Basalt"
    },
    {
      "x": -13,
      "y": 0,
      "z": -11,
      "name": "Rock_Basalt"
    },
    {
      "x": -13,
      "y": 1,
      "z": -11,
      "name": "Plant_Moss_Block_Green"
    },
    {
      "x": -13,
      "y": 2,
      "z": -11,
      "name": "Plant_Crop_Mushroom_Block_Brown_Trunk"
    },
    {
      "x": -13,
      "y": 3,
      "z": -11,
      "name": "Plant_Crop_Mushroom_Block_Brown_Trunk"
    },
    {
      "x": -13,
      "y": 4,
      "z": -11,
      "name": "Rock_Basalt"
    },
    {
      "x": -13,
      "y": 5,
      "z": -11,
      "name": "Plant_Crop_Mushroom_Block_Brown"
    },
    {
      "x": -13,
      "y": 6,
      "z": -11,
      "name": "Plant_Crop_Mushroom_Block_Brown_Trunk"
    },
    {
      "x": -13,
      "y": 7,
      "z": -11,
      "name": "Plant_Crop_Mushroom_Block_Brown"
    },
    {
      "x": -13,
      "y": 8,
      "z": -11,
      "name": "Plant_Crop_Mushroom_Block_Brown"
    },
    {
      "x": -13,
      "y": 9,
      "z": -11,
      "name": "Nat20_Force_Empty"
    },
    {
      "x": -13,
      "y": 10,
      "z": -11,
      "name": "Nat20_Force_Empty"
    },
    {
      "x": -13,
      "y": 0,
      "z": -10,
      "name": "Rock_Basalt"
    },
    {
      "x": -13,
      "y": 1,
      "z": -10,
      "name": "Rock_Basalt"
    },
    {
      "x": -13,
      "y": 2,
      "z": -10,
      "name": "Plant_Moss_Block_Green"
    },
    {
      "x": -13,
      "y": 3,
      "z": -10,
      "name": "Plant_Crop_Mushroom_Block_Brown_Mycelium"
    },
    {
      "x": -13,
      "y": 4,
      "z": -10,
      "name": "Plant_Crop_Mushroom_Block_Brown"
    },
    {
      "x": -13,
      "y": 5,
      "z": -10,
      "name": "Nat20_Force_Empty"
    },
    {
      "x": -13,
      "y": 6,
      "z": -10,
      "name": "Plant_Crop_Mushroom_Block_Brown_Mycelium"
    },
    {
      "x": -13,
      "y": 7,
      "z": -10,
      "name": "Plant_Crop_Mushroom_Block_Brown"
    },
    {
      "x": -13,
      "y": 8,
      "z": -10,
      "name": "Nat20_Force_Empty"
    },
    {
      "x": -13,
      "y": 9,
      "z": -10,
      "name": "Nat20_Force_Empty"
    },
    {
      "x": -13,
      "y": 10,
      "z": -10,
      "name": "Nat20_Force_Empty"
    },
    {
      "x": -13,
      "y": 0,
      "z": -9,
      "name": "Rock_Basalt"
    },
    {
      "x": -13,
      "y": 1,
      "z": -9,
      "name": "Rock_Basalt"
    },
    {
      "x": -13,
      "y": 2,
      "z": -9,
      "name": "Rock_Basalt"
    },
    {
      "x": -13,
      "y": 3,
      "z": -9,
      "name": "Nat20_Force_Empty"
    },
    {
      "x": -13,
      "y": 4,
      "z": -9,
      "name": "Nat20_Force_Empty"
    },
    {
      "x": -13,
      "y": 5,
      "z": -9,
      "name": "Nat20_Force_Empty"
    },
    {
      "x": -13,
      "y": 6,
      "z": -9,
      "name": "Nat20_Force_Empty"
    },
    {
      "x": -13,
      "y": 7,
      "z": -9,
      "name": "Nat20_Force_Empty"
    },
    {
      "x": -13,
      "y": 8,
      "z": -9,
      "name": "Nat20_Force_Empty"
    },
    {
      "x": -13,
      "y": 9,
      "z": -9,
      "name": "Nat20_Force_Empty"
    },
    {
      "x": -13,
      "y": 10,
      "z": -9,
      "name": "Nat20_Force_Empty"
    },
    {
      "x": -13,
      "y": 0,
      "z": -8,
      "name": "Rock_Stone"
    },
    {
      "x": -13,
      "y": 1,
      "z": -8,
      "name": "Rock_Basalt"
    },
    {
      "x": -13,
      "y": 2,
      "z": -8,
      "name": "Soil_Mud_Dry"
    },
    {
      "x": -13,
      "y": 3,
      "z": -8,
      "name": "Rock_Basalt"
    },
    {
      "x": -13,
      "y": 4,
      "z": -8,
      "name": "Plant_Crop_Mushroom_Cap_Brown"
    },
    {
      "x": -13,
      "y": 5,
      "z": -8,
      "name": "Nat20_Force_Empty"
    },
    {
      "x": -13,
      "y": 6,
      "z": -8,
      "name": "Nat20_Force_Empty"
    },
    {
      "x": -13,
      "y": 7,
      "z": -8,
      "name": "Nat20_Force_Empty"
    },
    {
      "x": -13,
      "y": 8,
      "z": -8,
      "name": "Nat20_Force_Empty"
    },
    {
      "x": -13,
      "y": 9,
      "z": -8,
      "name": "Nat20_Force_Empty"
    },
    {
      "x": -13,
      "y": 10,
      "z": -8,
      "name": "Nat20_Force_Empty"
    },
    {
      "x": -13,
      "y": 0,
      "z": -7,
      "name": "Rock_Stone"
    },
    {
      "x": -13,
      "y": 1,
      "z": -7,
      "name": "Soil_Mud_Dry"
    },
    {
      "x": -13,
      "y": 2,
      "z": -7,
      "name": "Soil_Mud_Dry"
    },
    {
      "x": -13,
      "y": 3,
      "z": -7,
      "name": "Rock_Basalt"
    },
    {
      "x": -13,
      "y": 4,
      "z": -7,
      "name": "Nat20_Force_Empty"
    },
    {
      "x": -13,
      "y": 5,
      "z": -7,
      "name": "Nat20_Force_Empty"
    },
    {
      "x": -13,
      "y": 6,
      "z": -7,
      "name": "Nat20_Force_Empty"
    },
    {
      "x": -13,
      "y": 7,
      "z": -7,
      "name": "Nat20_Force_Empty"
    },
    {
      "x": -13,
      "y": 8,
      "z": -7,
      "name": "Nat20_Force_Empty"
    },
    {
      "x": -13,
      "y": 9,
      "z": -7,
      "name": "Nat20_Force_Empty"
    },
    {
      "x": -13,
      "y": 10,
      "z": -7,
      "name": "Nat20_Force_Empty"
    },
    {
      "x": -13,
      "y": 0,
      "z": -6,
      "name": "Rock_Stone"
    },
    {
      "x": -13,
      "y": 1,
      "z": -6,
      "name": "Soil_Mud_Dry"
    },
    {
      "x": -13,
      "y": 2,
      "z": -6,
      "name": "Soil_Mud_Dry"
    },
    {
      "x": -13,
      "y": 3,
      "z": -6,
      "name": "Rock_Basalt"
    },
    {
      "x": -13,
      "y": 4,
      "z": -6,
      "name": "Rock_Basalt"
    },
    {
      "x": -13,
      "y": 5,
      "z": -6,
      "name": "Nat20_Force_Empty"
    },
    {
      "x": -13,
      "y": 6,
      "z": -6,
      "name": "Nat20_Force_Empty"
    },
    {
      "x": -13,
      "y": 7,
      "z": -6,
      "name": "Nat20_Force_Empty"
    },
    {
      "x": -13,
      "y": 8,
      "z": -6,
      "name": "Nat20_Force_Empty"
    },
    {
      "x": -13,
      "y": 9,
      "z": -6,
      "name": "Nat20_Force_Empty"
    },
    {
      "x": -13,
      "y": 10,
      "z": -6,
      "name": "Nat20_Force_Empty"
    },
    {
      "x": -13,
      "y": 0,
      "z": -5,
      "name": "Rock_Stone"
    },
    {
      "x": -13,
      "y": 1,
      "z": -5,
      "name": "Soil_Mud_Dry"
    },
    {
      "x": -13,
      "y": 2,
      "z": -5,
      "name": "Rock_Basalt"
    },
    {
      "x": -13,
      "y": 3,
      "z": -5,
      "name": "Rock_Basalt"
    },
    {
      "x": -13,
      "y": 4,
      "z": -5,
      "name": "Rock_Basalt"
    },
    {
      "x": -13,
      "y": 5,
      "z": -5,
      "name": "Nat20_Force_Empty"
    },
    {
      "x": -13,
      "y": 6,
      "z": -5,
      "name": "Nat20_Force_Empty"
    },
    {
      "x": -13,
      "y": 7,
      "z": -5,
      "name": "Nat20_Force_Empty"
    },
    {
      "x": -13,
      "y": 8,
      "z": -5,
      "name": "Nat20_Force_Empty"
    },
    {
      "x": -13,
      "y": 9,
      "z": -5,
      "name": "Nat20_Force_Empty"
    },
    {
      "x": -13,
      "y": 10,
      "z": -5,
      "name": "Nat20_Force_Empty"
    },
    {
      "x": -13,
      "y": 0,
      "z": -4,
      "name": "Rock_Stone"
    },
    {
      "x": -13,
      "y": 1,
      "z": -4,
      "name": "Rock_Basalt"
    },
    {
      "x": -13,
      "y": 2,
      "z": -4,
      "name": "Rock_Basalt"
    },
    {
      "x": -13,
      "y": 3,
      "z": -4,
      "name": "Rock_Basalt"
    },
    {
      "x": -13,
      "y": 4,
      "z": -4,
      "name": "Rock_Basalt"
    },
    {
      "x": -13,
      "y": 5,
      "z": -4,
      "name": "Rock_Basalt"
    },
    {
      "x": -13,
      "y": 6,
      "z": -4,
      "name": "Nat20_Force_Empty"
    },
    {
      "x": -13,
      "y": 7,
      "z": -4,
      "name": "Nat20_Force_Empty"
    },
    {
      "x": -13,
      "y": 8,
      "z": -4,
      "name": "Nat20_Force_Empty"
    },
    {
      "x": -13,
      "y": 9,
      "z": -4,
      "name": "Nat20_Force_Empty"
    },
    {
      "x": -13,
      "y": 10,
      "z": -4,
      "name": "Nat20_Force_Empty"
    },
    {
      "x": -13,
      "y": 0,
      "z": -3,
      "name": "Rock_Stone"
    },
    {
      "x": -13,
      "y": 1,
      "z": -3,
      "name": "Rock_Basalt"
    },
    {
      "x": -13,
      "y": 2,
      "z": -3,
      "name": "Rock_Basalt"
    },
    {
      "x": -13,
      "y": 3,
      "z": -3,
      "name": "Rock_Basalt"
    },
    {
      "x": -13,
      "y": 4,
      "z": -3,
      "name": "Rock_Basalt"
    },
    {
      "x": -13,
      "y": 5,
      "z": -3,
      "name": "Rock_Basalt"
    },
    {
      "x": -13,
      "y": 6,
      "z": -3,
      "name": "Rock_Basalt"
    },
    {
      "x": -13,
      "y": 7,
      "z": -3,
      "name": "Furniture_Human_Ruins_Torch",
      "rotation": 1
    },
    {
      "x": -13,
      "y": 8,
      "z": -3,
      "name": "Nat20_Force_Empty"
    },
    {
      "x": -13,
      "y": 9,
      "z": -3,
      "name": "Nat20_Force_Empty"
    },
    {
      "x": -13,
      "y": 10,
      "z": -3,
      "name": "Nat20_Force_Empty"
    },
    {
      "x": -13,
      "y": 0,
      "z": -2,
      "name": "Rock_Basalt"
    },
    {
      "x": -13,
      "y": 1,
      "z": -2,
      "name": "Nat20_Force_Empty"
    },
    {
      "x": -13,
      "y": 2,
      "z": -2,
      "name": "Nat20_Force_Empty"
    },
    {
      "x": -13,
      "y": 3,
      "z": -2,
      "name": "Nat20_Force_Empty"
    },
    {
      "x": -13,
      "y": 4,
      "z": -2,
      "name": "Nat20_Force_Empty"
    },
    {
      "x": -13,
      "y": 5,
      "z": -2,
      "name": "Rock_Basalt"
    },
    {
      "x": -13,
      "y": 6,
      "z": -2,
      "name": "Nat20_Force_Empty"
    },
    {
      "x": -13,
      "y": 7,
      "z": -2,
      "name": "Deco_Chair_Scrap",
      "filler": 992,
      "rotation": 1
    },
    {
      "x": -13,
      "y": 8,
      "z": -2,
      "name": "Deco_Chair_Scrap",
      "filler": 2016,
      "rotation": 1
    },
    {
      "x": -13,
      "y": 9,
      "z": -2,
      "name": "Deco_Chair_Scrap",
      "filler": 3040,
      "rotation": 1
    },
    {
      "x": -13,
      "y": 10,
      "z": -2,
      "name": "Deco_Chair_Scrap",
      "filler": 4064,
      "rotation": 1
    },
    {
      "x": -13,
      "y": 0,
      "z": -1,
      "name": "Rock_Basalt"
    },
    {
      "x": -13,
      "y": 1,
      "z": -1,
      "name": "Nat20_Force_Empty"
    },
    {
      "x": -13,
      "y": 2,
      "z": -1,
      "name": "Nat20_Force_Empty"
    },
    {
      "x": -13,
      "y": 3,
      "z": -1,
      "name": "Nat20_Force_Empty"
    },
    {
      "x": -13,
      "y": 4,
      "z": -1,
      "name": "Nat20_Force_Empty"
    },
    {
      "x": -13,
      "y": 5,
      "z": -1,
      "name": "Rock_Basalt"
    },
    {
      "x": -13,
      "y": 6,
      "z": -1,
      "name": "Nat20_Force_Empty"
    },
    {
      "x": -13,
      "y": 7,
      "z": -1,
      "name": "Deco_Chair_Scrap",
      "rotation": 1
    },
    {
      "x": -13,
      "y": 8,
      "z": -1,
      "name": "Deco_Chair_Scrap",
      "filler": 1024,
      "rotation": 1
    },
    {
      "x": -13,
      "y": 9,
      "z": -1,
      "name": "Deco_Chair_Scrap",
      "filler": 2048,
      "rotation": 1
    },
    {
      "x": -13,
      "y": 10,
      "z": -1,
      "name": "Deco_Chair_Scrap",
      "filler": 3072,
      "rotation": 1
    },
    {
      "x": -13,
      "y": 0,
      "z": 0,
      "name": "Rock_Basalt"
    },
    {
      "x": -13,
      "y": 1,
      "z": 0,
      "name": "Deco_Treasure_Pile_Large",
      "rotation": 2
    },
    {
      "x": -13,
      "y": 2,
      "z": 0,
      "name": "Nat20_Force_Empty"
    },
    {
      "x": -13,
      "y": 3,
      "z": 0,
      "name": "Nat20_Force_Empty"
    },
    {
      "x": -13,
      "y": 4,
      "z": 0,
      "name": "Nat20_Force_Empty"
    },
    {
      "x": -13,
      "y": 5,
      "z": 0,
      "name": "Rock_Basalt"
    },
    {
      "x": -13,
      "y": 6,
      "z": 0,
      "name": "Nat20_Force_Empty"
    },
    {
      "x": -13,
      "y": 7,
      "z": 0,
      "name": "Deco_Chair_Scrap",
      "filler": 32,
      "rotation": 1
    },
    {
      "x": -13,
      "y": 8,
      "z": 0,
      "name": "Deco_Chair_Scrap",
      "filler": 1056,
      "rotation": 1
    },
    {
      "x": -13,
      "y": 9,
      "z": 0,
      "name": "Deco_Chair_Scrap",
      "filler": 2080,
      "rotation": 1
    },
    {
      "x": -13,
      "y": 10,
      "z": 0,
      "name": "Deco_Chair_Scrap",
      "filler": 3104,
      "rotation": 1
    },
    {
      "x": -13,
      "y": 0,
      "z": 1,
      "name": "Rock_Basalt"
    },
    {
      "x": -13,
      "y": 1,
      "z": 1,
      "name": "Rock_Basalt"
    },
    {
      "x": -13,
      "y": 2,
      "z": 1,
      "name": "Soil_Mud_Dry"
    },
    {
      "x": -13,
      "y": 3,
      "z": 1,
      "name": "Rock_Basalt"
    },
    {
      "x": -13,
      "y": 4,
      "z": 1,
      "name": "Rock_Basalt"
    },
    {
      "x": -13,
      "y": 5,
      "z": 1,
      "name": "Rock_Basalt"
    },
    {
      "x": -13,
      "y": 6,
      "z": 1,
      "name": "Rock_Basalt"
    },
    {
      "x": -13,
      "y": 7,
      "z": 1,
      "name": "Furniture_Human_Ruins_Torch",
      "rotation": 1
    },
    {
      "x": -13,
      "y": 8,
      "z": 1,
      "name": "Nat20_Force_Empty"
    },
    {
      "x": -13,
      "y": 9,
      "z": 1,
      "name": "Nat20_Force_Empty"
    },
    {
      "x": -13,
      "y": 10,
      "z": 1,
      "name": "Nat20_Force_Empty"
    },
    {
      "x": -13,
      "y": 0,
      "z": 2,
      "name": "Rock_Basalt"
    },
    {
      "x": -13,
      "y": 1,
      "z": 2,
      "name": "Rock_Basalt"
    },
    {
      "x": -13,
      "y": 2,
      "z": 2,
      "name": "Soil_Mud_Dry"
    },
    {
      "x": -13,
      "y": 3,
      "z": 2,
      "name": "Rock_Basalt"
    },
    {
      "x": -13,
      "y": 4,
      "z": 2,
      "name": "Rock_Basalt"
    },
    {
      "x": -13,
      "y": 5,
      "z": 2,
      "name": "Rock_Basalt"
    },
    {
      "x": -13,
      "y": 6,
      "z": 2,
      "name": "Nat20_Force_Empty"
    },
    {
      "x": -13,
      "y": 7,
      "z": 2,
      "name": "Nat20_Force_Empty"
    },
    {
      "x": -13,
      "y": 8,
      "z": 2,
      "name": "Nat20_Force_Empty"
    },
    {
      "x": -13,
      "y": 9,
      "z": 2,
      "name": "Nat20_Force_Empty"
    },
    {
      "x": -13,
      "y": 10,
      "z": 2,
      "name": "Nat20_Force_Empty"
    },
    {
      "x": -13,
      "y": 0,
      "z": 3,
      "name": "Rock_Basalt"
    },
    {
      "x": -13,
      "y": 1,
      "z": 3,
      "name": "Soil_Mud_Dry"
    },
    {
      "x": -13,
      "y": 2,
      "z": 3,
      "name": "Soil_Mud_Dry"
    },
    {
      "x": -13,
      "y": 3,
      "z": 3,
      "name": "Rock_Basalt"
    },
    {
      "x": -13,
      "y": 4,
      "z": 3,
      "name": "Nat20_Force_Empty"
    },
    {
      "x": -13,
      "y": 5,
      "z": 3,
      "name": "Nat20_Force_Empty"
    },
    {
      "x": -13,
      "y": 6,
      "z": 3,
      "name": "Nat20_Force_Empty"
    },
    {
      "x": -13,
      "y": 7,
      "z": 3,
      "name": "Nat20_Force_Empty"
    },
    {
      "x": -13,
      "y": 8,
      "z": 3,
      "name": "Nat20_Force_Empty"
    },
    {
      "x": -13,
      "y": 9,
      "z": 3,
      "name": "Nat20_Force_Empty"
    },
    {
      "x": -13,
      "y": 10,
      "z": 3,
      "name": "Nat20_Force_Empty"
    },
    {
      "x": -13,
      "y": 0,
      "z": 4,
      "name": "Rock_Basalt"
    },
    {
      "x": -13,
      "y": 1,
      "z": 4,
      "name": "Soil_Mud_Dry"
    },
    {
      "x": -13,
      "y": 2,
      "z": 4,
      "name": "Soil_Mud_Dry"
    },
    {
      "x": -13,
      "y": 3,
      "z": 4,
      "name": "Rock_Basalt"
    },
    {
      "x": -13,
      "y": 4,
      "z": 4,
      "name": "Nat20_Force_Empty"
    },
    {
      "x": -13,
      "y": 5,
      "z": 4,
      "name": "Nat20_Force_Empty"
    },
    {
      "x": -13,
      "y": 6,
      "z": 4,
      "name": "Nat20_Force_Empty"
    },
    {
      "x": -13,
      "y": 7,
      "z": 4,
      "name": "Nat20_Force_Empty"
    },
    {
      "x": -13,
      "y": 8,
      "z": 4,
      "name": "Nat20_Force_Empty"
    },
    {
      "x": -13,
      "y": 9,
      "z": 4,
      "name": "Nat20_Force_Empty"
    },
    {
      "x": -13,
      "y": 10,
      "z": 4,
      "name": "Nat20_Force_Empty"
    },
    {
      "x": -13,
      "y": 0,
      "z": 5,
      "name": "Rock_Basalt"
    },
    {
      "x": -13,
      "y": 1,
      "z": 5,
      "name": "Rock_Basalt"
    },
    {
      "x": -13,
      "y": 2,
      "z": 5,
      "name": "Soil_Mud_Dry"
    },
    {
      "x": -13,
      "y": 3,
      "z": 5,
      "name": "Rock_Basalt"
    },
    {
      "x": -13,
      "y": 4,
      "z": 5,
      "name": "Nat20_Force_Empty"
    },
    {
      "x": -13,
      "y": 5,
      "z": 5,
      "name": "Nat20_Force_Empty"
    },
    {
      "x": -13,
      "y": 6,
      "z": 5,
      "name": "Nat20_Force_Empty"
    },
    {
      "x": -13,
      "y": 7,
      "z": 5,
      "name": "Nat20_Force_Empty"
    },
    {
      "x": -13,
      "y": 8,
      "z": 5,
      "name": "Nat20_Force_Empty"
    },
    {
      "x": -13,
      "y": 9,
      "z": 5,
      "name": "Nat20_Force_Empty"
    },
    {
      "x": -13,
      "y": 10,
      "z": 5,
      "name": "Nat20_Force_Empty"
    },
    {
      "x": -13,
      "y": 0,
      "z": 6,
      "name": "Rock_Basalt"
    },
    {
      "x": -13,
      "y": 1,
      "z": 6,
      "name": "Rock_Basalt"
    },
    {
      "x": -13,
      "y": 2,
      "z": 6,
      "name": "Soil_Mud_Dry"
    },
    {
      "x": -13,
      "y": 3,
      "z": 6,
      "name": "Rock_Basalt"
    },
    {
      "x": -13,
      "y": 4,
      "z": 6,
      "name": "Nat20_Force_Empty"
    },
    {
      "x": -13,
      "y": 5,
      "z": 6,
      "name": "Nat20_Force_Empty"
    },
    {
      "x": -13,
      "y": 6,
      "z": 6,
      "name": "Nat20_Force_Empty"
    },
    {
      "x": -13,
      "y": 7,
      "z": 6,
      "name": "Nat20_Force_Empty"
    },
    {
      "x": -13,
      "y": 8,
      "z": 6,
      "name": "Nat20_Force_Empty"
    },
    {
      "x": -13,
      "y": 9,
      "z": 6,
      "name": "Nat20_Force_Empty"
    },
    {
      "x": -13,
      "y": 10,
      "z": 6,
      "name": "Nat20_Force_Empty"
    },
    {
      "x": -13,
      "y": 0,
      "z": 7,
      "name": "Rock_Basalt"
    },
    {
      "x": -13,
      "y": 1,
      "z": 7,
      "name": "Rock_Basalt"
    },
    {
      "x": -13,
      "y": 2,
      "z": 7,
      "name": "Rock_Basalt"
    },
    {
      "x": -13,
      "y": 3,
      "z": 7,
      "name": "Rock_Basalt"
    },
    {
      "x": -13,
      "y": 4,
      "z": 7,
      "name": "Nat20_Force_Empty"
    },
    {
      "x": -13,
      "y": 5,
      "z": 7,
      "name": "Nat20_Force_Empty"
    },
    {
      "x": -13,
      "y": 6,
      "z": 7,
      "name": "Nat20_Force_Empty"
    },
    {
      "x": -13,
      "y": 7,
      "z": 7,
      "name": "Nat20_Force_Empty"
    },
    {
      "x": -13,
      "y": 8,
      "z": 7,
      "name": "Nat20_Force_Empty"
    },
    {
      "x": -13,
      "y": 9,
      "z": 7,
      "name": "Nat20_Force_Empty"
    },
    {
      "x": -13,
      "y": 10,
      "z": 7,
      "name": "Nat20_Force_Empty"
    },
    {
      "x": -13,
      "y": 0,
      "z": 8,
      "name": "Rock_Basalt"
    },
    {
      "x": -13,
      "y": 1,
      "z": 8,
      "name": "Rock_Basalt"
    },
    {
      "x": -13,
      "y": 2,
      "z": 8,
      "name": "Wood_Deadwood_Planks"
    },
    {
      "x": -13,
      "y": 3,
      "z": 8,
      "name": "Wood_Deadwood_Planks"
    },
    {
      "x": -13,
      "y": 4,
      "z": 8,
      "name": "Nat20_Force_Empty"
    },
    {
      "x": -13,
      "y": 5,
      "z": 8,
      "name": "Nat20_Force_Empty"
    },
    {
      "x": -13,
      "y": 6,
      "z": 8,
      "name": "Nat20_Force_Empty"
    },
    {
      "x": -13,
      "y": 7,
      "z": 8,
      "name": "Nat20_Force_Empty"
    },
    {
      "x": -13,
      "y": 8,
      "z": 8,
      "name": "Nat20_Force_Empty"
    },
    {
      "x": -13,
      "y": 9,
      "z": 8,
      "name": "Nat20_Force_Empty"
    },
    {
      "x": -13,
      "y": 10,
      "z": 8,
      "name": "Nat20_Force_Empty"
    },
    {
      "x": -13,
      "y": 0,
      "z": 9,
      "name": "Rock_Basalt"
    },
    {
      "x": -13,
      "y": 1,
      "z": 9,
      "name": "Rock_Basalt"
    },
    {
      "x": -13,
      "y": 2,
      "z": 9,
      "name": "Nat20_Force_Empty"
    },
    {
      "x": -13,
      "y": 3,
      "z": 9,
      "name": "Nat20_Force_Empty"
    },
    {
      "x": -13,
      "y": 4,
      "z": 9,
      "name": "Nat20_Force_Empty"
    },
    {
      "x": -13,
      "y": 5,
      "z": 9,
      "name": "Nat20_Force_Empty"
    },
    {
      "x": -13,
      "y": 6,
      "z": 9,
      "name": "Nat20_Force_Empty"
    },
    {
      "x": -13,
      "y": 7,
      "z": 9,
      "name": "Wood_Deadwood_Planks"
    },
    {
      "x": -13,
      "y": 8,
      "z": 9,
      "name": "Rock_Basalt"
    },
    {
      "x": -13,
      "y": 9,
      "z": 9,
      "name": "Nat20_Force_Empty"
    },
    {
      "x": -13,
      "y": 10,
      "z": 9,
      "name": "Nat20_Force_Empty"
    },
    {
      "x": -13,
      "y": 0,
      "z": 10,
      "name": "Rock_Basalt"
    },
    {
      "x": -13,
      "y": 1,
      "z": 10,
      "name": "Nat20_Force_Empty"
    },
    {
      "x": -13,
      "y": 2,
      "z": 10,
      "name": "Nat20_Force_Empty"
    },
    {
      "x": -13,
      "y": 3,
      "z": 10,
      "name": "Nat20_Force_Empty"
    },
    {
      "x": -13,
      "y": 4,
      "z": 10,
      "name": "Nat20_Force_Empty"
    },
    {
      "x": -13,
      "y": 5,
      "z": 10,
      "name": "Nat20_Force_Empty"
    },
    {
      "x": -13,
      "y": 6,
      "z": 10,
      "name": "Nat20_Force_Empty"
    },
    {
      "x": -13,
      "y": 7,
      "z": 10,
      "name": "Nat20_Force_Empty"
    },
    {
      "x": -13,
      "y": 8,
      "z": 10,
      "name": "Rock_Basalt"
    },
    {
      "x": -13,
      "y": 9,
      "z": 10,
      "name": "Rock_Basalt"
    },
    {
      "x": -13,
      "y": 10,
      "z": 10,
      "name": "Rock_Basalt"
    },
    {
      "x": -13,
      "y": 0,
      "z": 11,
      "name": "Rock_Basalt"
    },
    {
      "x": -13,
      "y": 1,
      "z": 11,
      "name": "Nat20_Force_Empty"
    },
    {
      "x": -13,
      "y": 2,
      "z": 11,
      "name": "Nat20_Force_Empty"
    },
    {
      "x": -13,
      "y": 3,
      "z": 11,
      "name": "Nat20_Force_Empty"
    },
    {
      "x": -13,
      "y": 4,
      "z": 11,
      "name": "Nat20_Force_Empty"
    },
    {
      "x": -13,
      "y": 5,
      "z": 11,
      "name": "Nat20_Force_Empty"
    },
    {
      "x": -13,
      "y": 6,
      "z": 11,
      "name": "Rock_Basalt"
    },
    {
      "x": -13,
      "y": 7,
      "z": 11,
      "name": "Rock_Basalt"
    },
    {
      "x": -13,
      "y": 8,
      "z": 11,
      "name": "Rock_Basalt"
    },
    {
      "x": -13,
      "y": 9,
      "z": 11,
      "name": "Rock_Basalt"
    },
    {
      "x": -13,
      "y": 10,
      "z": 11,
      "name": "Rock_Basalt"
    },
    {
      "x": -12,
      "y": 0,
      "z": -11,
      "name": "Plant_Moss_Block_Green"
    },
    {
      "x": -12,
      "y": 1,
      "z": -11,
      "name": "Nat20_Force_Empty"
    },
    {
      "x": -12,
      "y": 2,
      "z": -11,
      "name": "Nat20_Force_Empty"
    },
    {
      "x": -12,
      "y": 3,
      "z": -11,
      "name": "Plant_Crop_Mushroom_Block_Brown_Mycelium"
    },
    {
      "x": -12,
      "y": 4,
      "z": -11,
      "name": "Plant_Crop_Mushroom_Block_Brown"
    },
    {
      "x": -12,
      "y": 5,
      "z": -11,
      "name": "Nat20_Force_Empty"
    },
    {
      "x": -12,
      "y": 6,
      "z": -11,
      "name": "Plant_Crop_Mushroom_Block_Brown_Mycelium"
    },
    {
      "x": -12,
      "y": 7,
      "z": -11,
      "name": "Plant_Crop_Mushroom_Block_Brown"
    },
    {
      "x": -12,
      "y": 8,
      "z": -11,
      "name": "Nat20_Force_Empty"
    },
    {
      "x": -12,
      "y": 9,
      "z": -11,
      "name": "Nat20_Force_Empty"
    },
    {
      "x": -12,
      "y": 10,
      "z": -11,
      "name": "Nat20_Force_Empty"
    },
    {
      "x": -12,
      "y": 0,
      "z": -10,
      "name": "Rock_Basalt"
    },
    {
      "x": -12,
      "y": 1,
      "z": -10,
      "name": "Plant_Moss_Block_Green"
    },
    {
      "x": -12,
      "y": 2,
      "z": -10,
      "name": "Nat20_Force_Empty"
    },
    {
      "x": -12,
      "y": 3,
      "z": -10,
      "name": "Nat20_Force_Empty"
    },
    {
      "x": -12,
      "y": 4,
      "z": -10,
      "name": "Nat20_Force_Empty"
    },
    {
      "x": -12,
      "y": 5,
      "z": -10,
      "name": "Nat20_Force_Empty"
    },
    {
      "x": -12,
      "y": 6,
      "z": -10,
      "name": "Nat20_Force_Empty"
    },
    {
      "x": -12,
      "y": 7,
      "z": -10,
      "name": "Nat20_Force_Empty"
    },
    {
      "x": -12,
      "y": 8,
      "z": -10,
      "name": "Nat20_Force_Empty"
    },
    {
      "x": -12,
      "y": 9,
      "z": -10,
      "name": "Nat20_Force_Empty"
    },
    {
      "x": -12,
      "y": 10,
      "z": -10,
      "name": "Nat20_Force_Empty"
    },
    {
      "x": -12,
      "y": 0,
      "z": -9,
      "name": "Rock_Basalt"
    },
    {
      "x": -12,
      "y": 1,
      "z": -9,
      "name": "Rock_Basalt"
    },
    {
      "x": -12,
      "y": 2,
      "z": -9,
      "name": "Rock_Basalt"
    },
    {
      "x": -12,
      "y": 3,
      "z": -9,
      "name": "Nat20_Force_Empty"
    },
    {
      "x": -12,
      "y": 4,
      "z": -9,
      "name": "Nat20_Force_Empty"
    },
    {
      "x": -12,
      "y": 5,
      "z": -9,
      "name": "Nat20_Force_Empty"
    },
    {
      "x": -12,
      "y": 6,
      "z": -9,
      "name": "Nat20_Force_Empty"
    },
    {
      "x": -12,
      "y": 7,
      "z": -9,
      "name": "Nat20_Force_Empty"
    },
    {
      "x": -12,
      "y": 8,
      "z": -9,
      "name": "Nat20_Force_Empty"
    },
    {
      "x": -12,
      "y": 9,
      "z": -9,
      "name": "Nat20_Force_Empty"
    },
    {
      "x": -12,
      "y": 10,
      "z": -9,
      "name": "Nat20_Force_Empty"
    },
    {
      "x": -12,
      "y": 0,
      "z": -8,
      "name": "Rock_Stone"
    },
    {
      "x": -12,
      "y": 1,
      "z": -8,
      "name": "Rock_Basalt"
    },
    {
      "x": -12,
      "y": 2,
      "z": -8,
      "name": "Rock_Basalt"
    },
    {
      "x": -12,
      "y": 3,
      "z": -8,
      "name": "Rock_Basalt"
    },
    {
      "x": -12,
      "y": 4,
      "z": -8,
      "name": "Nat20_Force_Empty"
    },
    {
      "x": -12,
      "y": 5,
      "z": -8,
      "name": "Nat20_Force_Empty"
    },
    {
      "x": -12,
      "y": 6,
      "z": -8,
      "name": "Nat20_Force_Empty"
    },
    {
      "x": -12,
      "y": 7,
      "z": -8,
      "name": "Nat20_Force_Empty"
    },
    {
      "x": -12,
      "y": 8,
      "z": -8,
      "name": "Nat20_Force_Empty"
    },
    {
      "x": -12,
      "y": 9,
      "z": -8,
      "name": "Nat20_Force_Empty"
    },
    {
      "x": -12,
      "y": 10,
      "z": -8,
      "name": "Nat20_Force_Empty"
    },
    {
      "x": -12,
      "y": 0,
      "z": -7,
      "name": "Rock_Stone"
    },
    {
      "x": -12,
      "y": 1,
      "z": -7,
      "name": "Rock_Basalt"
    },
    {
      "x": -12,
      "y": 2,
      "z": -7,
      "name": "Rock_Basalt"
    },
    {
      "x": -12,
      "y": 3,
      "z": -7,
      "name": "Plant_Moss_Block_Green"
    },
    {
      "x": -12,
      "y": 4,
      "z": -7,
      "name": "Nat20_Force_Empty"
    },
    {
      "x": -12,
      "y": 5,
      "z": -7,
      "name": "Nat20_Force_Empty"
    },
    {
      "x": -12,
      "y": 6,
      "z": -7,
      "name": "Nat20_Force_Empty"
    },
    {
      "x": -12,
      "y": 7,
      "z": -7,
      "name": "Nat20_Force_Empty"
    },
    {
      "x": -12,
      "y": 8,
      "z": -7,
      "name": "Nat20_Force_Empty"
    },
    {
      "x": -12,
      "y": 9,
      "z": -7,
      "name": "Nat20_Force_Empty"
    },
    {
      "x": -12,
      "y": 10,
      "z": -7,
      "name": "Nat20_Force_Empty"
    },
    {
      "x": -12,
      "y": 0,
      "z": -6,
      "name": "Rock_Stone"
    },
    {
      "x": -12,
      "y": 1,
      "z": -6,
      "name": "Rock_Basalt"
    },
    {
      "x": -12,
      "y": 2,
      "z": -6,
      "name": "Rock_Basalt"
    },
    {
      "x": -12,
      "y": 3,
      "z": -6,
      "name": "Plant_Moss_Block_Green"
    },
    {
      "x": -12,
      "y": 4,
      "z": -6,
      "name": "Nat20_Force_Empty"
    },
    {
      "x": -12,
      "y": 5,
      "z": -6,
      "name": "Nat20_Force_Empty"
    },
    {
      "x": -12,
      "y": 6,
      "z": -6,
      "name": "Nat20_Force_Empty"
    },
    {
      "x": -12,
      "y": 7,
      "z": -6,
      "name": "Nat20_Force_Empty"
    },
    {
      "x": -12,
      "y": 8,
      "z": -6,
      "name": "Nat20_Force_Empty"
    },
    {
      "x": -12,
      "y": 9,
      "z": -6,
      "name": "Nat20_Force_Empty"
    },
    {
      "x": -12,
      "y": 10,
      "z": -6,
      "name": "Nat20_Force_Empty"
    },
    {
      "x": -12,
      "y": 0,
      "z": -5,
      "name": "Soil_Mud_Dry"
    },
    {
      "x": -12,
      "y": 1,
      "z": -5,
      "name": "Soil_Mud_Dry"
    },
    {
      "x": -12,
      "y": 2,
      "z": -5,
      "name": "Soil_Mud_Dry"
    },
    {
      "x": -12,
      "y": 3,
      "z": -5,
      "name": "Rock_Basalt"
    },
    {
      "x": -12,
      "y": 4,
      "z": -5,
      "name": "Rock_Basalt"
    },
    {
      "x": -12,
      "y": 5,
      "z": -5,
      "name": "Nat20_Force_Empty"
    },
    {
      "x": -12,
      "y": 6,
      "z": -5,
      "name": "Nat20_Force_Empty"
    },
    {
      "x": -12,
      "y": 7,
      "z": -5,
      "name": "Nat20_Force_Empty"
    },
    {
      "x": -12,
      "y": 8,
      "z": -5,
      "name": "Nat20_Force_Empty"
    },
    {
      "x": -12,
      "y": 9,
      "z": -5,
      "name": "Nat20_Force_Empty"
    },
    {
      "x": -12,
      "y": 10,
      "z": -5,
      "name": "Nat20_Force_Empty"
    },
    {
      "x": -12,
      "y": 0,
      "z": -4,
      "name": "Rock_Stone"
    },
    {
      "x": -12,
      "y": 1,
      "z": -4,
      "name": "Soil_Mud_Dry"
    },
    {
      "x": -12,
      "y": 2,
      "z": -4,
      "name": "Rock_Basalt"
    },
    {
      "x": -12,
      "y": 3,
      "z": -4,
      "name": "Rock_Basalt"
    },
    {
      "x": -12,
      "y": 4,
      "z": -4,
      "name": "Rock_Basalt"
    },
    {
      "x": -12,
      "y": 5,
      "z": -4,
      "name": "Rock_Basalt"
    },
    {
      "x": -12,
      "y": 6,
      "z": -4,
      "name": "Nat20_Force_Empty"
    },
    {
      "x": -12,
      "y": 7,
      "z": -4,
      "name": "Nat20_Force_Empty"
    },
    {
      "x": -12,
      "y": 8,
      "z": -4,
      "name": "Nat20_Force_Empty"
    },
    {
      "x": -12,
      "y": 9,
      "z": -4,
      "name": "Nat20_Force_Empty"
    },
    {
      "x": -12,
      "y": 10,
      "z": -4,
      "name": "Nat20_Force_Empty"
    },
    {
      "x": -12,
      "y": 0,
      "z": -3,
      "name": "Rock_Stone"
    },
    {
      "x": -12,
